Workbook
Name _: #REF!
Name _: #REF!
Name _: #REF!
Name _: #REF!
Name _: #REF!
Name _: #REF!
Name _: #REF!
Name _: #REF!
Name _: #REF!
Name _?: #N/A
Name ______R3_t: #N/A
Name ______R3_t1: #N/A
Name __DAT10: #REF!
Name __DAT10: #REF!
Name __DAT10: #REF!
Name __DAT10: #REF!
Name __DAT10: #REF!
Name __DAT10: #REF!
Name __DAT10: #REF!
Name __DAT10: #REF!
Name __DAT10: #REF!
Name __DAT4: #REF!
Name __DAT4: #REF!
Name __DAT4: #REF!
Name __DAT4: #REF!
Name __DAT4: #REF!
Name __DAT4: #REF!
Name __DAT4: #REF!
Name __DAT4: #REF!
Name __DAT4: #REF!
Name __DAT6: #REF!
Name __DAT6: #REF!
Name __DAT6: #REF!
Name __DAT6: #REF!
Name __DAT6: #REF!
Name __DAT6: #REF!
Name __DAT6: #REF!
Name __DAT6: #REF!
Name __DAT6: #REF!
Name __DAT7: #REF!
Name __DAT7: #REF!
Name __DAT7: #REF!
Name __DAT7: #REF!
Name __DAT7: #REF!
Name __DAT7: #REF!
Name __DAT7: #REF!
Name __DAT7: #REF!
Name __DAT7: #REF!
Name _￡A￡´1: #N/A
Name _00년: #REF!
Name _00년: #REF!
Name _00년: #REF!
Name _00년: #REF!
Name _00년: #REF!
Name _00년: #REF!
Name _00년: #REF!
Name _00년: #REF!
Name _00년: #REF!
Name _111: #REF!
Name _111: #REF!

Sheet BS(연결)
B3: 재무상태표(연결)
C4: 2012년 | D4: 2013년 | E4: 2014년 | F4: 2015년 | K4: 과 목 | L4: 제 40 기 | M4: 제 41 기 | N4: 제 42 기 | O4: 제 43 기 반기
B5: 백만원 | C5: 12월 31일 | D5: 12월 31일 | E5: 12월 31일 | F5: 6월 30일 | K5: 자산
B6: 유동자산 | C6: =SUM(C7:C11) -> 261377254740 | D6: =SUM(D7:D11) -> 264091049999 | E6: =SUM(E7:E11) -> 286167352689 | F6: =SUM(F7:F11) -> 296318785179 | K6: 유동자산
B7: 현금및현금성자산 | C7: =SUMIF($J$7:$J$52,$B7,L$7:L$52) -> 5544530351 | D7: =SUMIF($J$7:$J$52,$B7,M$7:M$52) -> 4242192463 | E7: =SUMIF($J$7:$J$52,$B7,N$7:N$52) -> 4845599991 | F7: =SUMIF($J$7:$J$52,$B7,O$7:O$52) -> 4244334407 | J7: 현금및현금성자산 | K7: 현금및현금성자산 | L7: 5544530351 | M7: 4242192463 | N7: 4845599991 | O7: 4244334407
B8: 매출채권 | C8: =SUMIF($J$7:$J$52,$B8,L$7:L$52) -> 134027043446 | D8: =SUMIF($J$7:$J$52,$B8,M$7:M$52) -> 121963019140 | E8: =SUMIF($J$7:$J$52,$B8,N$7:N$52) -> 141439063302 | F8: =SUMIF($J$7:$J$52,$B8,O$7:O$52) -> 147684814458 | J8: 매출채권 | K8: 매출채권 | L8: 134027043446 | M8: 121963019140 | N8: 141439063302 | O8: 147684814458
B9: 기타유동채권 | C9: =SUMIF($J$7:$J$52,$B9,L$7:L$52) -> 10499566621 | D9: =SUMIF($J$7:$J$52,$B9,M$7:M$52) -> 11618278163 | E9: =SUMIF($J$7:$J$52,$B9,N$7:N$52) -> 14635562527 | F9: =SUMIF($J$7:$J$52,$B9,O$7:O$52) -> 11204996806 | J9: 기타유동채권 | K9: 기타수취채권 | L9: 10499566621 | M9: 11618278163 | N9: 14635562527 | O9: 11204996806
B10: 재고자산 | C10: =SUMIF($J$7:$J$52,$B10,L$7:L$52) -> 85484663552 | D10: =SUMIF($J$7:$J$52,$B10,M$7:M$52) -> 83641773916 | E10: =SUMIF($J$7:$J$52,$B10,N$7:N$52) -> 95167542674 | F10: =SUMIF($J$7:$J$52,$B10,O$7:O$52) -> 96860821055 | J10: 기타자산 | K10: 기타금융자산 | L10: 2740918526 | M10: 11862329380 | N10: 2051673356 | O10: 1697906040
B11: 기타자산 | C11: =SUMIF($J$7:$J$52,$B11,L$7:L$52) -> 25821450770 | D11: =SUMIF($J$7:$J$52,$B11,M$7:M$52) -> 42625786317 | E11: =SUMIF($J$7:$J$52,$B11,N$7:N$52) -> 30079584195 | F11: =SUMIF($J$7:$J$52,$B11,O$7:O$52) -> 36323818453 | J11: 기타자산 | K11: 기타유동자산 | L11: 23080532244 | M11: 30763456937 | N11: 28027910839 | O11: 34625912413
B12: 비유동자산 | C12: =SUM(C13:C17) -> 234184304425 | D12: =SUM(D13:D17) -> 234439865763 | E12: =SUM(E13:E17) -> 270204201617 | F12: =SUM(F13:F17) -> 291084772593 | J12: 재고자산 | K12: 재고자산 | L12: 85484663552 | M12: 83641773916 | N12: 95167542674 | O12: 96860821055
B13: 유형자산 | C13: =SUMIF($J$7:$J$52,$B13,L$7:L$52) -> 177579210031 | D13: =SUMIF($J$7:$J$52,$B13,M$7:M$52) -> 186123687777 | E13: =SUMIF($J$7:$J$52,$B13,N$7:N$52) -> 208778336913 | F13: =SUMIF($J$7:$J$52,$B13,O$7:O$52) -> 226445724446 | K13: 유동자산 합계 | L13: 261377254740 | M13: 264091049999 | N13: 286167352689 | O13: 296318785179
B14: 무형자산 | C14: =SUMIF($J$7:$J$52,$B14,L$7:L$52) -> 28650256306 | D14: =SUMIF($J$7:$J$52,$B14,M$7:M$52) -> 25716603900 | E14: =SUMIF($J$7:$J$52,$B14,N$7:N$52) -> 27925711452 | F14: =SUMIF($J$7:$J$52,$B14,O$7:O$52) -> 29882456335 | K14: 비유동자산
B15: 기타비유동채권 | C15: =SUMIF($J$7:$J$52,$B15,L$7:L$52) -> 1461979493 | D15: =SUMIF($J$7:$J$52,$B15,M$7:M$52) -> 2549448756 | E15: =SUMIF($J$7:$J$52,$B15,N$7:N$52) -> 1892003938 | F15: =SUMIF($J$7:$J$52,$B15,O$7:O$52) -> 2035011461 | J15: 기타비유동채권 | K15: 기타수취채권 | L15: 1461979493 | M15: 2549448756 | N15: 1892003938 | O15: 2035011461
B16: 관계기업투자 | C16: =SUMIF($J$7:$J$52,$B16,L$7:L$52) -> 1041203397 | D16: =SUMIF($J$7:$J$52,$B16,M$7:M$52) -> 450392393 | E16: =SUMIF($J$7:$J$52,$B16,N$7:N$52) -> 555691371 | F16: =SUMIF($J$7:$J$52,$B16,O$7:O$52) -> 572767736 | J16: 관계기업투자 | K16: 관계기업투자 | L16: 1041203397 | M16: 450392393 | N16: 555691371 | O16: 572767736
B17: 기타비유동자산 | C17: =SUMIF($J$7:$J$52,$B17,L$7:L$52) -> 25451655198 | D17: =SUMIF($J$7:$J$52,$B17,M$7:M$52) -> 19599732937 | E17: =SUMIF($J$7:$J$52,$B17,N$7:N$52) -> 31052457943 | F17: =SUMIF($J$7:$J$52,$B17,O$7:O$52) -> 32148812615 | J17: 기타비유동자산 | K17: 기타금융자산 | L17: 10000684407 | M17: 2305467574 | N17: 9648881832 | O17: 9831951621
B18: 자산총계 | C18: =SUM(C6,C12) -> 495561559165 | D18: =SUM(D6,D12) -> 498530915762 | E18: =SUM(E6,E12) -> 556371554306 | F18: =SUM(F6,F12) -> 587403557772 | J18: 기타비유동자산 | K18: 기타비유동자산 | L18: 4250190497 | M18: 3749916418 | N18: 4001965247 | O18: 4417134793
B19: 유동부채 | C19: =SUM(C20:C24) -> 299019546178 | D19: =SUM(D20:D24) -> 305664657223 | E19: =SUM(E20:E24) -> 318270087163 | F19: =SUM(F20:F24) -> 291619447443 | J19: 유형자산 | K19: 유형자산 | L19: 177579210031 | M19: 186123687777 | N19: 208778336913 | O19: 226445724446
B20: 매입채무 | C20: =SUMIF($J$7:$J$52,$B20,L$7:L$52) -> 102894859202 | D20: =SUMIF($J$7:$J$52,$B20,M$7:M$52) -> 102471380257 | E20: =SUMIF($J$7:$J$52,$B20,N$7:N$52) -> 124685230949 | F20: =SUMIF($J$7:$J$52,$B20,O$7:O$52) -> 116247704145 | J20: 무형자산 | K20: 무형자산 | L20: 28650256306 | M20: 25716603900 | N20: 27925711452 | O20: 29882456335
B21: 유동성차입금 | C21: =SUMIF($J$7:$J$52,$B21,L$7:L$52) -> 149311842286 | D21: =SUMIF($J$7:$J$52,$B21,M$7:M$52) -> 154506362734 | E21: =SUMIF($J$7:$J$52,$B21,N$7:N$52) -> 133507577291 | F21: =SUMIF($J$7:$J$52,$B21,O$7:O$52) -> 102543566496 | J21: 기타비유동자산 | K21: 이연법인세자산 | L21: 11200780294 | M21: 13544348945 | N21: 17401610864 | O21: 17899726201
B22: 기타유동채무 | C22: =SUMIF($J$7:$J$52,$B22,L$7:L$52) -> 32469137975 | D22: =SUMIF($J$7:$J$52,$B22,M$7:M$52) -> 36508298384 | E22: =SUMIF($J$7:$J$52,$B22,N$7:N$52) -> 48955326168 | F22: =SUMIF($J$7:$J$52,$B22,O$7:O$52) -> 60211618620 | K22: 비유동자산 합계 | L22: 234184304425 | M22: 234439865763 | N22: 270204201617 | O22: 291084772593
B23: 기타유동부채 | C23: =SUMIF($J$7:$J$52,$B23,L$7:L$52) -> 6242519371 | D23: =SUMIF($J$7:$J$52,$B23,M$7:M$52) -> 9107419707 | E23: =SUMIF($J$7:$J$52,$B23,N$7:N$52) -> 8294545054 | F23: =SUMIF($J$7:$J$52,$B23,O$7:O$52) -> 9853687570 | K23: 자산 총계 | L23: 495561559165 | M23: 498530915762 | N23: 556371554306 | O23: 587403557772
B24: 유동충당부채 | C24: =SUMIF($J$7:$J$52,$B24,L$7:L$52) -> 8101187344 | D24: =SUMIF($J$7:$J$52,$B24,M$7:M$52) -> 3071196141 | E24: =SUMIF($J$7:$J$52,$B24,N$7:N$52) -> 2827407701 | F24: =SUMIF($J$7:$J$52,$B24,O$7:O$52) -> 2762870612 | K24: 부채 및 자본
B25: 비유동부채 | C25: =SUM(C26:C30) -> 95886027877 | D25: =SUM(D26:D30) -> 81528111339 | E25: =SUM(E26:E30) -> 111898977025 | F25: =SUM(F26:F30) -> 161787435048 | K25: 부채
B26: 장기차입금 | C26: =SUMIF($J$7:$J$52,$B26,L$7:L$52) -> 87812640000 | D26: =SUMIF($J$7:$J$52,$B26,M$7:M$52) -> 73327683244 | E26: =SUMIF($J$7:$J$52,$B26,N$7:N$52) -> 104368114158 | F26: =SUMIF($J$7:$J$52,$B26,O$7:O$52) -> 151924564710 | K26: 유동부채
B27: 장기충당부채 | C27: =SUMIF($J$7:$J$52,$B27,L$7:L$52) -> 3694774530 | D27: =SUMIF($J$7:$J$52,$B27,M$7:M$52) -> 5648636272 | E27: =SUMIF($J$7:$J$52,$B27,N$7:N$52) -> 3807153549 | F27: =SUMIF($J$7:$J$52,$B27,O$7:O$52) -> 4184526164 | J27: 매입채무 | K27: 매입채무 | L27: 102894859202 | M27: 102471380257 | N27: 124685230949 | O27: 116247704145
B28: 확정급여부채 | C28: =SUMIF($J$7:$J$52,$B28,L$7:L$52) -> 2489595196 | D28: =SUMIF($J$7:$J$52,$B28,M$7:M$52) -> 1499045866 | E28: =SUMIF($J$7:$J$52,$B28,N$7:N$52) -> 1631293702 | F28: =SUMIF($J$7:$J$52,$B28,O$7:O$52) -> 3220547296 | J28: 기타유동채무 | K28: 기타지급채무 | L28: 32469137975 | M28: 36508298384 | N28: 48955326168 | O28: 60211618620
B29: 기타비유동채무 | C29: =SUMIF($J$7:$J$52,$B29,L$7:L$52) -> 153000000 | D29: =SUMIF($J$7:$J$52,$B29,M$7:M$52) -> 153500000 | E29: =SUMIF($J$7:$J$52,$B29,N$7:N$52) -> 203500000 | F29: =SUMIF($J$7:$J$52,$B29,O$7:O$52) -> 188000000 | J29: 기타유동부채 | K29: 기타금융부채 | L29: 248156907 | M29: 279060337 | N29: 851520002 | O29: 1461268342
B30: 기타비유동부채 | C30: =SUMIF($J$7:$J$52,$B30,L$7:L$52) -> 1736018151 | D30: =SUMIF($J$7:$J$52,$B30,M$7:M$52) -> 899245957 | E30: =SUMIF($J$7:$J$52,$B30,N$7:N$52) -> 1888915616 | F30: =SUMIF($J$7:$J$52,$B30,O$7:O$52) -> 2269796878 | J30: 유동성차입금 | K30: 차입금 | L30: 149311842286 | M30: 154506362734 | N30: 133507577291 | O30: 102543566496
B31: 부채총계 | C31: =SUM(C25,C19) -> 394905574055 | D31: =SUM(D25,D19) -> 387192768562 | E31: =SUM(E25,E19) -> 430169064188 | F31: =SUM(F25,F19) -> 453406882491 | J31: 기타유동부채 | K31: 기타유동부채 | L31: 5173904274 | M31: 7912481143 | N31: 5986319276 | O31: 6662345190
B32: 자본금 | C32: =SUMIF($J$7:$J$52,$B32,L$7:L$52) -> 49333300000 | D32: =SUMIF($J$7:$J$52,$B32,M$7:M$52) -> 49333300000 | E32: =SUMIF($J$7:$J$52,$B32,N$7:N$52) -> 49333300000 | F32: =SUMIF($J$7:$J$52,$B32,O$7:O$52) -> 49333300000 | J32: 기타유동부채 | K32: 당기법인세부채 | L32: 820458190 | M32: 915878227 | N32: 1456705776 | O32: 1730074038
B33: 이익잉여금 | C33: =SUMIF($J$7:$J$52,$B33,L$7:L$52) -> 48816890244 | D33: =SUMIF($J$7:$J$52,$B33,M$7:M$52) -> 60378173983 | E33: =SUMIF($J$7:$J$52,$B33,N$7:N$52) -> 77164223212 | F33: =SUMIF($J$7:$J$52,$B33,O$7:O$52) -> 84292873023 | J33: 유동충당부채 | K33: 충당부채 | L33: 8101187344 | M33: 3071196141 | N33: 2827407701 | O33: 2762870612
B34: 기타자본 | C34: =SUMIF($J$7:$J$52,$B34,L$7:L$52) -> 2505794866 | D34: =SUMIF($J$7:$J$52,$B34,M$7:M$52) -> 1626673217 | E34: =SUMIF($J$7:$J$52,$B34,N$7:N$52) -> -295033094 | F34: =SUMIF($J$7:$J$52,$B34,O$7:O$52) -> 370502258 | K34: 유동부채 합계 | L34: 299019546178 | M34: 305664657223 | N34: 318270087163 | O34: 291619447443
B35: 자본총계 | C35: =SUM(C32:C34) -> 100655985110 | D35: =SUM(D32:D34) -> 111338147200 | E35: =SUM(E32:E34) -> 126202490118 | F35: =SUM(F32:F34) -> 133996675281 | K35: 비유동부채
B36: 자본과부채총계 | C36: =C31+C35 -> 495561559165 | D36: =D31+D35 -> 498530915762 | E36: =E31+E35 -> 556371554306 | F36: =F31+F35 -> 587403557772 | J36: 기타비유동채무 | K36: 기타지급채무 | L36: 153000000 | M36: 153500000 | N36: 203500000 | O36: 188000000
B37: Source : 감사보고서 | J37: 기타비유동부채 | K37: 기타금융부채 | L37: 21799188 | M37: 2512273 | N37: 980424849 | O37: 1467995424
B38: 총차입금 | C38: =C21+C26 -> 237124482286 | D38: =D21+D26 -> 227834045978 | E38: =E21+E26 -> 237875691449 | F38: =F21+F26 -> 254468131206 | J38: 장기차입금 | K38: 차입금 | L38: 87812640000 | M38: 73327683244 | N38: 104368114158 | O38: 151924564710
B39: 순차입금 | C39: =C38-C7 -> 231579951935 | D39: =D38-D7 -> 223591853515 | E39: =E38-E7 -> 233030091458 | F39: =F38-F7 -> 250223796799 | J39: 기타비유동부채 | K39: 기타비유동부채 | L39: 1250836455 | M39: 491273989 | N39: 908490767 | O39: 801801454
C40: =C6-L13 -> 0 | D40: =D6-M13 -> 0 | E40: =E6-N13 -> 0 | F40: =F6-O13 -> 0 | J40: 확정급여부채 | K40: 확정급여부채 | L40: 2489595196 | M40: 1499045866 | N40: 1631293702 | O40: 3220547296
C41: =C12-L22 -> 0 | D41: =D12-M22 -> 0 | E41: =E12-N22 -> 0 | F41: =F12-O22 -> 0 | J41: 기타비유동부채 | K41: 이연법인세부채 | L41: 463382508 | M41: 405459695 | N41: 0 | O41: 0
C42: =C18-L23 -> 0 | D42: =D18-M23 -> 0 | E42: =E18-N23 -> 0 | F42: =F18-O23 -> 0 | J42: 장기충당부채 | K42: 충당부채 | L42: 3694774530 | M42: 5648636272 | N42: 3807153549 | O42: 4184526164
...

Sheet IS(연결)
J1: >>PL | R1: >>주석 | S1: 21. 매출 및 매출원가
B3: 손익계산서(연결) | O3: 제43기 반기 | P3: 제42기 반기 | S3: 매출 및 매출원가의 구성내역은 다음과 같습니다.
C4: 2012년 | D4: 2013년 | E4: 2014년 | F4: 2015년 | G4: 2014년 | L4: 제 40 기 | M4: 제 41 기 | N4: 제42기 | O4: 누적 | P4: 누적
B5: 백만원 | C5: 12개월 | D5: 12개월 | E5: 12개월 | F5: 6개월 | G5: 6개월 | K5: 매출액 | L5: 630029985686 | M5: 663544930549 | N5: 715524023057 | O5: 395994844226 | P5: 350888124224 | U5: (단위: 천원) | W5: 제43기 반기 | X5: 제42기 반기
B6: 매출액 | C6: =L5 -> 630029985686 | D6: =M5 -> 663544930549 | E6: =N5 -> 715524023057 | F6: =O5 -> 395994844226 | G6: =P5 -> 350888124224 | K6: 매출원가 | L6: -553066763867 | M6: -579821491067 | N6: -622518118746 | O6: -348423501816 | P6: -304107584364 | S6: 구 분 | T6: 40기 | U6: 41기 | V6: 42기 | W6: 누적 | X6: 누적
B7: 제품 | C7: =T8*1000 -> 615876336000 | D7: =U8*1000 -> 635518071000 | E7: =V8*1000 -> 678355903000 | F7: =W8*1000 -> 380479517000 | G7: =X8*1000 -> 335150823000 | K7: 매출총이익 | L7: 76963221819 | M7: 83723439482 | N7: 93005904311 | O7: 47571342410 | P7: 46780539860 | T7: 매 출 | U7: 매 출 | V7: 매 출 | W7: 매출 | X7: 매출
B8: 상품 | C8: =T9*1000 -> 10383056000 | D8: =U9*1000 -> 15210139000 | E8: =V9*1000 -> 18115732000 | F8: =W9*1000 -> 8735931000 | G8: =X9*1000 -> 8866811000 | K8: 판매비와 관리비 | L8: -58366193312 | M8: -56020716937 | N8: -62304729229 | O8: -33278007890 | P8: -31791284647 | S8: 제품 | T8: 615876336 | U8: 635518071 | V8: 678355903 | W8: 380479517 | X8: 335150823
B9: 기타 | C9: =T10*1000 -> 3770594000 | D9: =U10*1000 -> 12816721000 | E9: =V10*1000 -> 19052388000 | F9: =W10*1000 -> 6779396000 | G9: =X10*1000 -> 6870490000 | K9: 영업이익 | L9: 18597028507 | M9: 27702722545 | N9: 30701175082 | O9: 14293334520 | P9: 14989255213 | S9: 상품 | T9: 10383056 | U9: 15210139 | V9: 18115732 | W9: 8735931 | X9: 8866811
B10: 매출원가 | C10: =-L6 -> 553066763867 | D10: =-M6 -> 579821491067 | E10: =-N6 -> 622518118746 | F10: =-O6 -> 348423501816 | G10: =-P6 -> 304107584364 | K10: 기타수익 | L10: 13239968936 | M10: 14230268654 | N10: 10541257569 | O10: 6217643451 | P10: 4435845918 | S10: 기타 | T10: 3770594 | U10: 12816721 | V10: 19052388 | W10: 6779396 | X10: 6870490
B11: 매출총이익 | C11: =L7 -> 76963221819 | D11: =M7 -> 83723439482 | E11: =N7 -> 93005904311 | F11: =O7 -> 47571342410 | G11: =P7 -> 46780539860 | K11: 기타비용 | L11: -13880117986 | M11: -17945651821 | N11: -11258377098 | O11: -5298808385 | P11: -5594656175 | S11: 합 계 | T11: 630029986 | U11: 663544931 | V11: 715524023 | W11: 395994844 | X11: 350888124
B12: 매출총이익률(%) | C12: =C11/C6 -> 0.12215803 | D12: =D11/D6 -> 0.12617599 | E12: =E11/E6 -> 0.12998292 | F12: =F11/F6 -> 0.12013122 | G12: =G11/G6 -> 0.13332039 | K12: 금융수익 | L12: 1239939426 | M12: 1102821813 | N12: 728115463 | O12: 383069856 | P12: 514083633 | T12: 매 출 원 가 | U12: 매 출 원 가 | V12: 매 출 원 가 | W12: 매 출 원 가 | X12: 매 출 원 가
B13: 판매관리비 | C13: =-L8 -> 58366193312 | D13: =-M8 -> 56020716937 | E13: =-N8 -> 62304729229 | F13: =-O8 -> 33278007890 | G13: =-P8 -> 31791284647 | K13: 금융원가 | L13: -16492753645 | M13: -12048493747 | N13: -10452219619 | O13: -4711750873 | P13: -5375889067 | S13: 제품 | T13: 538337008 | U13: 556201802 | V13: 593953652 | W13: 335936674 | X13: 291895647
B14: 인건비 | C14: =SUMIF($R$41:$R$61,$B14,T$41:T$61)*1000 -> 17006439000 | D14: =SUMIF($R$41:$R$61,$B14,U$41:U$61)*1000 -> 18778456000 | E14: =SUMIF($R$41:$R$61,$B14,V$41:V$61)*1000 -> 21736145000 | F14: =SUMIF($R$41:$R$61,$B14,W$41:W$61)*1000 -> 12219122000 | G14: =SUMIF($R$41:$R$61,$B14,X$41:X$61)*1000 -> 11382101000 | K14: 기타영업외수익 | L14: 2896217661 | M14: 3964675848 | N14: 2003977004 | O14: 955193324 | P14: 2035683770 | S14: 상품 | T14: 9881621 | U14: 13364215 | V14: 15892892 | W14: 7645948 | X14: 7744846
B15: 감가상각비 | C15: =SUMIF($R$41:$R$61,$B15,T$41:T$61)*1000 -> 1355553000 | D15: =SUMIF($R$41:$R$61,$B15,U$41:U$61)*1000 -> 1166656000 | E15: =SUMIF($R$41:$R$61,$B15,V$41:V$61)*1000 -> 1109796000 | F15: =SUMIF($R$41:$R$61,$B15,W$41:W$61)*1000 -> 594707000 | G15: =SUMIF($R$41:$R$61,$B15,X$41:X$61)*1000 -> 613767000 | K15: 기타영업외비용 | L15: -1428273667 | M15: -4472718136 | N15: -3126126383 | O15: -2067508256 | P15: -1275481124 | S15: 기타 | T15: 4848135 | U15: 10255474 | V15: 12671575 | W15: 4840880 | X15: 4467091
B16: 무형자산상각비 | C16: =SUMIF($R$41:$R$61,$B16,T$41:T$61)*1000 -> 2614854000 | D16: =SUMIF($R$41:$R$61,$B16,U$41:U$61)*1000 -> 2851846000 | E16: =SUMIF($R$41:$R$61,$B16,V$41:V$61)*1000 -> 3071807000 | F16: =SUMIF($R$41:$R$61,$B16,W$41:W$61)*1000 -> 1283485000 | G16: =SUMIF($R$41:$R$61,$B16,X$41:X$61)*1000 -> 1514298000 | K16: 법인세비용차감전순이익 | L16: 4172009232 | M16: 12533625156 | N16: 19137802018 | O16: 9771173637 | P16: 9728842168 | S16: 합 계 | T16: 553066764 | U16: 579821491 | V16: 622518119 | W16: 348423502 | X16: 304107584
B17: 판매보증비 | C17: =SUMIF($R$41:$R$61,$B17,T$41:T$61)*1000 -> 11958237000 | D17: =SUMIF($R$41:$R$61,$B17,U$41:U$61)*1000 -> 8478016000 | E17: =SUMIF($R$41:$R$61,$B17,V$41:V$61)*1000 -> 8009624000 | F17: =SUMIF($R$41:$R$61,$B17,W$41:W$61)*1000 -> 3609776000 | G17: =SUMIF($R$41:$R$61,$B17,X$41:X$61)*1000 -> 5380269000 | K17: 법인세비용 | L17: 1893814540 | M17: 438342545 | N17: 1186573100 | O17: 2495523826 | P17: 491120397
B18: 지급수수료 | C18: =SUMIF($R$41:$R$61,$B18,T$41:T$61)*1000 -> 6809576000 | D18: =SUMIF($R$41:$R$61,$B18,U$41:U$61)*1000 -> 6711804000 | E18: =SUMIF($R$41:$R$61,$B18,V$41:V$61)*1000 -> 6122827000 | F18: =SUMIF($R$41:$R$61,$B18,W$41:W$61)*1000 -> 3230879000 | G18: =SUMIF($R$41:$R$61,$B18,X$41:X$61)*1000 -> 2613853000 | K18: 당기순이익(손실) | L18: 2278194692 | M18: 12095282611 | N18: 17951228918 | O18: 7275649811 | P18: 9237721771 | S18: 22. 영업이익
B19: 경상개발비 | C19: =SUMIF($R$41:$R$61,$B19,T$41:T$61)*1000 -> 628511000 | D19: =SUMIF($R$41:$R$61,$B19,U$41:U$61)*1000 -> 957991000 | E19: =SUMIF($R$41:$R$61,$B19,V$41:V$61)*1000 -> 1873905000 | F19: =SUMIF($R$41:$R$61,$B19,W$41:W$61)*1000 -> 1357388000 | G19: =SUMIF($R$41:$R$61,$B19,X$41:X$61)*1000 -> 497528000 | K19: 지배기업소유주지분 | L19: 2278194692 | M19: 12095282611 | N19: 17951228918 | O19: 7275649811 | P19: 9237721771
B20: 세금과공과 | C20: =SUMIF($R$41:$R$61,$B20,T$41:T$61)*1000 -> 1700694000 | D20: =SUMIF($R$41:$R$61,$B20,U$41:U$61)*1000 -> 1513848000 | E20: =SUMIF($R$41:$R$61,$B20,V$41:V$61)*1000 -> 1476984000 | F20: =SUMIF($R$41:$R$61,$B20,W$41:W$61)*1000 -> 1141027000 | G20: =SUMIF($R$41:$R$61,$B20,X$41:X$61)*1000 -> 713797000 | K20: 비지배지분 | L20: - | M20: - | N20: - | O20: - | P20: - | S20: 22-1 종업원급여의 내역은 다음과 같습니다.
B21: 임차료 | C21: =SUMIF($R$41:$R$61,$B21,T$41:T$61)*1000 -> 2303696000 | D21: =SUMIF($R$41:$R$61,$B21,U$41:U$61)*1000 -> 2175444000 | E21: =SUMIF($R$41:$R$61,$B21,V$41:V$61)*1000 -> 1983554000 | F21: =SUMIF($R$41:$R$61,$B21,W$41:W$61)*1000 -> 1114943000 | G21: =SUMIF($R$41:$R$61,$B21,X$41:X$61)*1000 -> 973429000 | K21: 기타포괄손익
B22: 여비교통비 | C22: =SUMIF($R$41:$R$61,$B22,T$41:T$61)*1000 -> 1440485000 | D22: =SUMIF($R$41:$R$61,$B22,U$41:U$61)*1000 -> 1334925000 | E22: =SUMIF($R$41:$R$61,$B22,V$41:V$61)*1000 -> 1716085000 | F22: =SUMIF($R$41:$R$61,$B22,W$41:W$61)*1000 -> 899655000 | G22: =SUMIF($R$41:$R$61,$B22,X$41:X$61)*1000 -> 929305000 | K22: 후속적으로 당기손익으로 | S22: (단위: 천원) | W22: 제43기 반기 | X22: 제42기 반기
B23: 기타비용 | C23: =SUMIF($R$41:$R$61,$B23,T$41:T$61)*1000 -> 12548148000 | D23: =SUMIF($R$41:$R$61,$B23,U$41:U$61)*1000 -> 12051731000 | E23: =SUMIF($R$41:$R$61,$B23,V$41:V$61)*1000 -> 15204002000 | F23: =SUMIF($R$41:$R$61,$B23,W$41:W$61)*1000 -> 7827026000 | G23: =SUMIF($R$41:$R$61,$B23,X$41:X$61)*1000 -> 7172939000 | K23: 재분류될 수 있는 항목 | S23: 구 분 | T23: 40기 | U23: 41기 | V23: 42기 | W23: 누적 | X23: 누적
B24: 영업이익 | C24: =L9 -> 18597028507 | D24: =M9 -> 27702722545 | E24: =N9 -> 30701175082 | F24: =O9 -> 14293334520 | G24: =P9 -> 14989255213 | K24: 매도가능금융자산평가 | L24: 6463649 | M24: 47898287 | N24: 34134329 | O24: 494535 | P24: 25600325 | S24: 급여 | T24: 61154623 | U24: 67282344 | V24: 73032007 | W24: 42,847,588 | X24: 37496312
B25: 영업이익(%) | C25: =C24/C6 -> 0.029517688 | D25: =D24/D6 -> 0.041749581 | E25: =E24/E6 -> 0.04290726 | F25: =F24/F6 -> 0.036094749 | G25: =G24/G6 -> 0.042718047 | K25: 손익 | S25: 퇴직급여 | T25: 2825870 | U25: 3124638 | V25: 3781544 | W25: 2,059,328 | X25: 1871434
B26: 금융수익 | C26: =L12 -> 1239939426 | D26: =M12 -> 1102821813 | E26: =N12 -> 728115463 | F26: =O12 -> 383069856 | G26: =P12 -> 514083633 | K26: 파생상품평가손익 | L26: 4495184394 | M26: 1029089110 | N26: -3126264406 | O26: -1021354171 | P26: 2550811422 | S26: 복리후생비 | T26: 6985488 | U26: 8160878 | V26: 8921195 | W26: 5,077,360 | X26: 4453121
B27: 금융비용 | C27: =-L13 -> 16492753645 | D27: =-M13 -> 12048493747 | E27: =-N13 -> 10452219619 | F27: =-O13 -> 4711750873 | G27: =-P13 -> 5375889067 | K27: 해외사업환산손익 | L27: -2204769985 | M27: -1956109046 | N27: 1170423766 | O27: 1539394988 | P27: -3277445051 | S27: 합 계 | T27: 70965981 | U27: 78567860 | V27: 85734746 | W27: 49,984,276 | X27: 43820867
B28: 기타수익 | C28: =L10+L14 -> 16136186597 | D28: =M10+M14 -> 18194944502 | E28: =N10+N14 -> 12545234573 | F28: =O10+O14 -> 7172836775 | G28: =P10+P14 -> 6471529688 | H28: 기타수익+기타영업외수익 | K28: 후속적으로 당기손익으로
B29: 기타비용 | C29: =-(L11+L15) -> 15308391653 | D29: =-(M11+M15) -> 22418369957 | E29: =-(N11+N15) -> 14384503481 | F29: =-(O11+O15) -> 7366316641 | G29: =-(P11+P15) -> 6870137299 | H29: 기타비용+기타영업외비용 | K29: 재분류되지 않는 항목 | S29: 22-2 감가상각비와 무형자산상각비의 내역은 다음과 같습니다.
B30: 법인세비용 | C30: =L17 -> 1893814540 | D30: =M17 -> 438342545 | E30: =N17 -> 1186573100 | F30: =O17 -> 2495523826 | G30: =P17 -> 491120397 | K30: 순확정급여부채의 재측정 | L30: -743596242 | M30: -533998872 | N30: -1165179689 | O30: - | P30: -
B31: 당기순이익 | C31: =L18 -> 2278194692 | D31: =M18 -> 12095282611 | E31: =N18 -> 17951228918 | F31: =O18 -> 7275649811 | G31: =P18 -> 9237721771 | K31: 요소 | S31: (단위: 천원) | W31: 제43기 반기 | X31: 제42기 반기
B32: 당기순이익률(%) | C32: =C31/C6 -> 0.0036160099 | D32: =D31/D6 -> 0.01822828 | E32: =E31/E6 -> 0.025088227 | F32: =F31/F6 -> 0.018373092 | G32: =G31/G6 -> 0.026326687 | K32: 총포괄손익 | L32: 3831476508 | M32: 10682162090 | N32: 14864342918 | O32: 7794185163 | P32: 8536688467 | S32: 구 분 | T32: 40기 | U32: 41기 | V32: 42기 | W32: 누적 | X32: 누적
B33: EBITDA | C33: =C24+C39 -> 54172121980 | D33: =D24+D39 -> 65010014708 | E33: =E24+E39 -> 69121406676 | F33: =F24+F39 -> 34728224867 | G33: =G24+G39 -> 34301816293 | K33: 총포괄손익의 귀속: | S33: 유형자산감가상각비 | T33: 27615340 | U33: 29666486 | V33: 31190193 | W33: 16973713 | X33: 15696912
B34: EBITDA(%) | C34: =C33/C6 -> 0.085983403 | D34: =D33/D6 -> 0.097973795 | E34: =E33/E6 -> 0.096602496 | F34: =F33/F6 -> 0.087698679 | G34: =G33/G6 -> 0.097757131 | K34: 지배기업소유주지분 | L34: 3831476508 | M34: 10682162090 | N34: 14864342918 | O34: 7794185163 | P34: 8536688467 | S34: 무형자산상각비 | T34: 7959753 | U34: 7640807 | V34: 7230038 | W34: 3461177 | X34: 3615649
B35: Source : 감사보고서 | K35: 비지배지분 | L35: - | M35: - | N35: - | O35: - | P35: - | S35: 합 계 | T35: 35575093 | U35: 37307293 | V35: 38420231 | W35: 20434890 | X35: 19312561
K36: 주당손익
B37: 감가상각비 | C37: ='CF(연결)'!B14 -> 27615340495 | D37: ='CF(연결)'!C14 -> 29666485532 | E37: ='CF(연결)'!D14 -> 31190193327 | F37: ='CF(연결)'!E14 -> 16973712924 | G37: ='CF(연결)'!F14 -> 15696912464 | K37: 기본주당손익 | L37: 231 | M37: 1226 | N37: 1819 | O37: 737 | P37: 936 | S37: 22-3 판매비와관리비의 내역은 다음과 같습니다.
B38: 무형자산상각비 | C38: ='CF(연결)'!B15 -> 7959752978 | D38: ='CF(연결)'!C15 -> 7640806631 | E38: ='CF(연결)'!D15 -> 7230038267 | F38: ='CF(연결)'!E15 -> 3461177423 | G38: ='CF(연결)'!F15 -> 3615648616
B39: D&A | C39: =SUM(C37:C38) -> 35575093473 | D39: =SUM(D37:D38) -> 37307292163 | E39: =SUM(E37:E38) -> 38420231594 | F39: =SUM(F37:F38) -> 20434890347 | G39: =SUM(G37:G38) -> 19312561080 | S39: (단위: 천원) | W39: 제43기 반기 | X39: 제42기 반기
C40: =C39-T35*1000 -> 473 | D40: =D39-U35*1000 -> -837 | E40: =E39-V35*1000 -> 594 | F40: =F39-W35*1000 -> 347 | G40: =G39-X35*1000 -> 80 | S40: 구 분 | T40: 40기 | U40: 41기 | V40: 42기 | W40: 누적 | X40: 누적
R41: 인건비 | S41: 급여 | T41: 14133305 | U41: 15847320 | V41: 18094369 | W41: 10132688 | X41: 9568584
...

Sheet BS(별도)
B3: 재무상태표(별도)
C4: 2012년 | D4: 2013년 | E4: 2014년 | F4: 2015년 | K4: 제 40(전) 기 | L4: 제 41 기 | M4: 제42기 | N4: 제43기 반기
B5: 백만원 | C5: 12월 31일 | D5: 12월 31일 | E5: 12월 31일 | F5: 6월 30일 | J5: 자산
B6: 유동자산 | C6: =SUM(C7:C11) -> 211238127888 | D6: =SUM(D7:D11) -> 199622976692 | E6: =SUM(E7:E11) -> 205592191931 | F6: =SUM(F7:F11) -> 220246389494 | J6: 유동자산
B7: 현금및현금성자산 | C7: =SUMIF($I$7:$I$52,$B7,K$7:K$52) -> 1184687591 | D7: =SUMIF($I$7:$I$52,$B7,L$7:L$52) -> 1087185146 | E7: =SUMIF($I$7:$I$52,$B7,M$7:M$52) -> 417039167 | F7: =SUMIF($I$7:$I$52,$B7,N$7:N$52) -> 1461974937 | I7: 현금및현금성자산 | J7: 현금및현금성자산 | K7: 1184687591 | L7: 1087185146 | M7: 417039167 | N7: 1461974937
B8: 매출채권 | C8: =SUMIF($I$7:$I$52,$B8,K$7:K$52) -> 120379543299 | D8: =SUMIF($I$7:$I$52,$B8,L$7:L$52) -> 102474614868 | E8: =SUMIF($I$7:$I$52,$B8,M$7:M$52) -> 115353171617 | F8: =SUMIF($I$7:$I$52,$B8,N$7:N$52) -> 130106672965 | I8: 매출채권 | J8: 매출채권 | K8: 120379543299 | L8: 102474614868 | M8: 115353171617 | N8: 130106672965
B9: 기타유동채권 | C9: =SUMIF($I$7:$I$52,$B9,K$7:K$52) -> 14234388283 | D9: =SUMIF($I$7:$I$52,$B9,L$7:L$52) -> 14336060255 | E9: =SUMIF($I$7:$I$52,$B9,M$7:M$52) -> 16867836496 | F9: =SUMIF($I$7:$I$52,$B9,N$7:N$52) -> 11401302774 | I9: 기타유동채권 | J9: 기타수취채권 | K9: 14234388283 | L9: 14336060255 | M9: 16867836496 | N9: 11401302774
B10: 재고자산 | C10: =SUMIF($I$7:$I$52,$B10,K$7:K$52) -> 55691710382 | D10: =SUMIF($I$7:$I$52,$B10,L$7:L$52) -> 51320265478 | E10: =SUMIF($I$7:$I$52,$B10,M$7:M$52) -> 52799613163 | F10: =SUMIF($I$7:$I$52,$B10,N$7:N$52) -> 53472768284 | I10: 기타자산 | J10: 기타금융자산 | K10: 2740918526 | L10: 11857306080 | M10: 1943290771 | N10: 1697906040
B11: 기타자산 | C11: =SUMIF($I$7:$I$52,$B11,K$7:K$52) -> 19747798333 | D11: =SUMIF($I$7:$I$52,$B11,L$7:L$52) -> 30404850945 | E11: =SUMIF($I$7:$I$52,$B11,M$7:M$52) -> 20154531488 | F11: =SUMIF($I$7:$I$52,$B11,N$7:N$52) -> 23803670534 | I11: 기타자산 | J11: 기타유동자산 | K11: 17006879807 | L11: 18547544865 | M11: 18211240717 | N11: 22105764494
B12: 비유동자산 | C12: =SUM(C13:C17) -> 225811386041 | D12: =SUM(D13:D17) -> 234460843739 | E12: =SUM(E13:E17) -> 252216100401 | F12: =SUM(F13:F17) -> 264696937078 | I12: 재고자산 | J12: 재고자산 | K12: 55691710382 | L12: 51320265478 | M12: 52799613163 | N12: 53472768284
B13: 유형자산 | C13: =SUMIF($I$7:$I$52,$B13,K$7:K$52) -> 134926702287 | D13: =SUMIF($I$7:$I$52,$B13,L$7:L$52) -> 136471693354 | E13: =SUMIF($I$7:$I$52,$B13,M$7:M$52) -> 142852502572 | F13: =SUMIF($I$7:$I$52,$B13,N$7:N$52) -> 152962175674 | J13: 유동자산 합계 | K13: 211238127888 | L13: 199622976692 | M13: 205592191931 | N13: 220246389494
B14: 무형자산 | C14: =SUMIF($I$7:$I$52,$B14,K$7:K$52) -> 25547393194 | D14: =SUMIF($I$7:$I$52,$B14,L$7:L$52) -> 22464615704 | E14: =SUMIF($I$7:$I$52,$B14,M$7:M$52) -> 24698243277 | F14: =SUMIF($I$7:$I$52,$B14,N$7:N$52) -> 26346040695 | J14: 비유동자산
B15: 종속/관계기업투자 | C15: =SUMIF($I$7:$I$52,$B15,K$7:K$52) -> 42802883132 | D15: =SUMIF($I$7:$I$52,$B15,L$7:L$52) -> 59677570199 | E15: =SUMIF($I$7:$I$52,$B15,M$7:M$52) -> 59701592440 | F15: =SUMIF($I$7:$I$52,$B15,N$7:N$52) -> 59701592440 | I15: 기타비유동채권 | J15: 기타수취채권(비유동) | K15: 1003927240 | L15: 1843483490 | M15: 1393483598 | N15: 1454110198
B16: 기타비유동자산 | C16: =SUMIF($I$7:$I$52,$B16,K$7:K$52) -> 21530480188 | D16: =SUMIF($I$7:$I$52,$B16,L$7:L$52) -> 14003480992 | E16: =SUMIF($I$7:$I$52,$B16,M$7:M$52) -> 23570278514 | F16: =SUMIF($I$7:$I$52,$B16,N$7:N$52) -> 24233018071 | I16: 종속/관계기업투자 | J16: 종속기업투자 | K16: 42035573230 | L16: 58910260297 | M16: 58934282538 | N16: 58934282538
B17: 기타비유동채권 | C17: =SUMIF($I$7:$I$52,$B17,K$7:K$52) -> 1003927240 | D17: =SUMIF($I$7:$I$52,$B17,L$7:L$52) -> 1843483490 | E17: =SUMIF($I$7:$I$52,$B17,M$7:M$52) -> 1393483598 | F17: =SUMIF($I$7:$I$52,$B17,N$7:N$52) -> 1454110198 | I17: 종속/관계기업투자 | J17: 관계기업투자 | K17: 767309902 | L17: 767309902 | M17: 767309902 | N17: 767309902
B18: 자산총계 | C18: =SUM(C6,C12) -> 437049513929 | D18: =SUM(D6,D12) -> 434083820431 | E18: =SUM(E6,E12) -> 457808292332 | F18: =SUM(F6,F12) -> 484943326572 | I18: 기타비유동자산 | J18: 기타금융자산(비유동) | K18: 10000684407 | L18: 2232023574 | M18: 9510057792 | N18: 9690725781
B19: 유동부채 | C19: =SUM(C20:C24) -> 243604132305 | D19: =SUM(D20:D24) -> 240396486022 | E19: =SUM(E20:E24) -> 220981013216 | F19: =SUM(F20:F24) -> 189213052315 | I19: 기타비유동자산 | J19: 기타비유동자산 | K19: 362600000 | L19: 245000000 | M19: 127400000 | N19: 68600000
B20: 매입채무 | C20: =SUMIF($I$7:$I$52,$B20,K$7:K$52) -> 85327446900 | D20: =SUMIF($I$7:$I$52,$B20,L$7:L$52) -> 87060497363 | E20: =SUMIF($I$7:$I$52,$B20,M$7:M$52) -> 89756694650 | F20: =SUMIF($I$7:$I$52,$B20,N$7:N$52) -> 86451917731 | I20: 유형자산 | J20: 유형자산 | K20: 134926702287 | L20: 136471693354 | M20: 142852502572 | N20: 152962175674
B21: 유동성차입금 | C21: =SUMIF($I$7:$I$52,$B21,K$7:K$52) -> 118407328966 | D21: =SUMIF($I$7:$I$52,$B21,L$7:L$52) -> 116047831073 | E21: =SUMIF($I$7:$I$52,$B21,M$7:M$52) -> 83755237204 | F21: =SUMIF($I$7:$I$52,$B21,N$7:N$52) -> 47937549078 | I21: 무형자산 | J21: 무형자산 | K21: 25547393194 | L21: 22464615704 | M21: 24698243277 | N21: 26346040695
B22: 기타유동채무 | C22: =SUMIF($I$7:$I$52,$B22,K$7:K$52) -> 27910621869 | D22: =SUMIF($I$7:$I$52,$B22,L$7:L$52) -> 30052768206 | E22: =SUMIF($I$7:$I$52,$B22,M$7:M$52) -> 39226679543 | F22: =SUMIF($I$7:$I$52,$B22,N$7:N$52) -> 45648977245 | I22: 기타비유동자산 | J22: 이연법인세자산 | K22: 11167195781 | L22: 11526457418 | M22: 13932820722 | N22: 14473692290
B23: 기타유동부채 | C23: =SUMIF($I$7:$I$52,$B23,K$7:K$52) -> 3857547226 | D23: =SUMIF($I$7:$I$52,$B23,L$7:L$52) -> 4164193239 | E23: =SUMIF($I$7:$I$52,$B23,M$7:M$52) -> 5414994118 | F23: =SUMIF($I$7:$I$52,$B23,N$7:N$52) -> 6411737649 | J23: 비유동자산 합계 | K23: 225811386041 | L23: 234460843739 | M23: 252216100401 | N23: 264696937078
B24: 유동충당부채 | C24: =SUMIF($I$7:$I$52,$B24,K$7:K$52) -> 8101187344 | D24: =SUMIF($I$7:$I$52,$B24,L$7:L$52) -> 3071196141 | E24: =SUMIF($I$7:$I$52,$B24,M$7:M$52) -> 2827407701 | F24: =SUMIF($I$7:$I$52,$B24,N$7:N$52) -> 2762870612 | J24: 자산 총계 | K24: 437049513929 | L24: 434083820431 | M24: 457808292332 | N24: 484943326572
B25: 비유동부채 | C25: =SUM(C26:C30) -> 90403197736 | D25: =SUM(D26:D30) -> 77877190465 | E25: =SUM(E26:E30) -> 108703653706 | F25: =SUM(F26:F30) -> 158430974248 | J25: 부채 및 자본
B26: 장기차입금 | C26: =SUMIF($I$7:$I$52,$B26,K$7:K$52) -> 83000000000 | D26: =SUMIF($I$7:$I$52,$B26,L$7:L$52) -> 70674159941 | E26: =SUMIF($I$7:$I$52,$B26,M$7:M$52) -> 101663363183 | F26: =SUMIF($I$7:$I$52,$B26,N$7:N$52) -> 149156785150 | J26: 부채
B27: 장기충당부채 | C27: =SUMIF($I$7:$I$52,$B27,K$7:K$52) -> 3559330293 | D27: =SUMIF($I$7:$I$52,$B27,L$7:L$52) -> 5063239907 | E27: =SUMIF($I$7:$I$52,$B27,M$7:M$52) -> 3366299886 | F27: =SUMIF($I$7:$I$52,$B27,N$7:N$52) -> 3654647722 | J27: 유동부채
B28: 확정급여부채 | C28: =SUMIF($I$7:$I$52,$B28,K$7:K$52) -> 2418231800 | D28: =SUMIF($I$7:$I$52,$B28,L$7:L$52) -> 1456725348 | E28: =SUMIF($I$7:$I$52,$B28,M$7:M$52) -> 1558047624 | F28: =SUMIF($I$7:$I$52,$B28,N$7:N$52) -> 3122252019 | I28: 매입채무 | J28: 매입채무 | K28: 85327446900 | L28: 87060497363 | M28: 89756694650 | N28: 86451917731
B29: 기타비유동부채 | C29: =SUMIF($I$7:$I$52,$B29,K$7:K$52) -> 1272635643 | D29: =SUMIF($I$7:$I$52,$B29,L$7:L$52) -> 529565269 | E29: =SUMIF($I$7:$I$52,$B29,M$7:M$52) -> 1912443013 | F29: =SUMIF($I$7:$I$52,$B29,N$7:N$52) -> 2286889357 | I29: 기타유동채무 | J29: 기타지급채무 | K29: 27910621869 | L29: 30052768206 | M29: 39226679543 | N29: 45648977245
B30: 기타비유동채무 | C30: =SUMIF($I$7:$I$52,$B30,K$7:K$52) -> 153000000 | D30: =SUMIF($I$7:$I$52,$B30,L$7:L$52) -> 153500000 | E30: =SUMIF($I$7:$I$52,$B30,M$7:M$52) -> 203500000 | F30: =SUMIF($I$7:$I$52,$B30,N$7:N$52) -> 210400000 | I30: 기타유동부채 | J30: 기타금융부채 | K30: 0 | L30: 151591904 | M30: 953460060 | N30: 1471013766 | O30: 84183844
B31: 부채총계 | C31: =SUM(C25,C19) -> 334007330041 | D31: =SUM(D25,D19) -> 318273676487 | E31: =SUM(E25,E19) -> 329684666922 | F31: =SUM(F25,F19) -> 347644026563 | I31: 유동성차입금 | J31: 차입금 | K31: 118407328966 | L31: 116047831073 | M31: 83755237204 | N31: 47937549078
B32: 자본금 | C32: =SUMIF($I$7:$I$52,$B32,K$7:K$52) -> 49333300000 | D32: =SUMIF($I$7:$I$52,$B32,L$7:L$52) -> 49333300000 | E32: =SUMIF($I$7:$I$52,$B32,M$7:M$52) -> 49333300000 | F32: =SUMIF($I$7:$I$52,$B32,N$7:N$52) -> 49333300000 | I32: 기타유동부채 | J32: 기타유동부채 | K32: 3857547226 | L32: 4012601335 | M32: 4418304399 | N32: 4588917068 | O32: 4080009395
B33: 이익잉여금 | C33: =SUMIF($I$7:$I$52,$B33,K$7:K$52) -> 51009874738 | D33: =SUMIF($I$7:$I$52,$B33,L$7:L$52) -> 62700847397 | E33: =SUMIF($I$7:$I$52,$B33,M$7:M$52) -> 78106458940 | F33: =SUMIF($I$7:$I$52,$B33,N$7:N$52) -> 88155993175 | I33: 기타유동부채 | J33: 당기법인세부채 | K33: 0 | L33: 0 | M33: 43229659 | N33: 351806815
B34: 기타자본 | C34: =SUMIF($I$7:$I$52,$B34,K$7:K$52) -> 2699009150 | D34: =SUMIF($I$7:$I$52,$B34,L$7:L$52) -> 3775996547 | E34: =SUMIF($I$7:$I$52,$B34,M$7:M$52) -> 683866470 | F34: =SUMIF($I$7:$I$52,$B34,N$7:N$52) -> -189993166 | I34: 유동충당부채 | J34: 충당부채 | K34: 8101187344 | L34: 3071196141 | M34: 2827407701 | N34: 2762870612
B35: 자본총계 | C35: =SUM(C32:C34) -> 103042183888 | D35: =SUM(D32:D34) -> 115810143944 | E35: =SUM(E32:E34) -> 128123625410 | F35: =SUM(F32:F34) -> 137299300009 | J35: 유동부채 합계 | K35: 243604132305 | L35: 240396486022 | M35: 220981013216 | N35: 189213052315
B36: 자본과부채총계 | C36: =C31+C35 -> 437049513929 | D36: =D31+D35 -> 434083820431 | E36: =E31+E35 -> 457808292332 | F36: =F31+F35 -> 484943326572 | J36: 비유동부채
B37: Source : 감사보고서 | I37: 기타비유동채무 | J37: 기타지급채무(비유동) | K37: 153000000 | L37: 153500000 | M37: 203500000 | N37: 210400000
B38: 총차입금 | C38: =C21+C26 -> 201407328966 | D38: =D21+D26 -> 186721991014 | E38: =E21+E26 -> 185418600387 | F38: =F21+F26 -> 197094334228 | I38: 기타비유동부채 | J38: 기타금융부채(비유동) | K38: 21799188 | L38: 38291280 | M38: 1003952246 | N38: 1485087903 | O38: 2512273
B39: 순차입금 | C39: =C38-C7 -> 200222641375 | D39: =D38-D7 -> 185634805868 | E39: =E38-E7 -> 185001561220 | F39: =F38-F7 -> 195632359291 | I39: 장기차입금 | J39: 차입금(비유동) | K39: 83000000000 | L39: 70674159941 | M39: 101663363183 | N39: 149156785150
C40: =C6-K13 -> 0 | D40: =D6-L13 -> 0 | E40: =E6-M13 -> 0 | F40: =F6-N13 -> 0 | I40: 기타비유동부채 | J40: 기타비유동부채 | K40: 1250836455 | L40: 491273989 | M40: 908490767 | N40: 801801454 | O40: 527052996
C41: =C6-K13 -> 0 | D41: =D6-L13 -> 0 | E41: =E6-M13 -> 0 | F41: =F6-N13 -> 0 | I41: 확정급여부채 | J41: 확정급여부채 | K41: 2418231800 | L41: 1456725348 | M41: 1558047624 | N41: 3122252019
C42: =C12-K23 -> 0 | D42: =D12-L23 -> 0 | E42: =E12-M23 -> 0 | F42: =F12-N23 -> 0 | I42: 장기충당부채 | J42: 충당부채(비유동) | K42: 3559330293 | L42: 5063239907 | M42: 3366299886 | N42: 3654647722
...

Sheet IS(별도)
J1: >>PL | U1: >>주석
B3: 손익계산서(별도) | M3: 2015년 반기 보고서기준 | O3: 제 43 기 반기 | P3: 제 42 기 반기 | Q3: 2014년 기말 감사보고서기준
C4: 2012년 | D4: 2013년 | E4: 2014년 | F4: 2015년 | G4: 2014년 | K4: 과 목 | L4: 제 40기 | M4: 제 41 기 | N4: 제 42 기 | O4: 누적 | P4: 누적 | Q4: 제 41 기 | R4: 제 42 기 | S4: 41기 차이 | T4: 42기 차이
B5: 백만원 | C5: 12개월 | D5: 12개월 | E5: 12개월 | F5: 6개월 | G5: 6개월 | K5: 매출액 | L5: 528569510350 | M5: 559856533781 | N5: 591196611310 | O5: 303923046949 | P5: 296493708547 | Q5: 555740268125 | R5: 584672320904 | S5: =M5-Q5 -> 4116265656 | T5: =N5-R5 -> 6524290406
B6: 매출액 | C6: =L5 -> 528569510350 | D6: =M5 -> 559856533781 | E6: =N5 -> 591196611310 | F6: =O5 -> 303923046949 | G6: =P5 -> 296493708547 | K6: 매출원가 | L6: -475725626210 | M6: -499445340398 | N6: -524218029958 | O6: -273015109365 | P6: -261870076026 | Q6: -499445340398 | R6: -524218029958 | S6: =M6-Q6 -> 0 | T6: =N6-R6 -> 0
B7: HMI | C7: =Sheet16!P5*1000000 -> 343953000000 | D7: =Sheet16!F5*1000000 -> 387385000000 | E7: =Sheet16!G5*1000000 -> 422384000000 | F7: =Sheet16!H5*1000000 -> 220196000000 | K7: 매출총이익 | L7: 52843884140 | M7: 60411193383 | N7: 66978581352 | O7: 30907937584 | P7: 34623632521 | Q7: 56294927727 | R7: 60454290946 | S7: =M7-Q7 -> 4116265656 | T7: =N7-R7 -> 6524290406
B8: MC | C8: =(Sheet16!P11+Sheet16!P14)*1000000 -> 119987000000 | D8: =Sheet16!F11*1000000 -> 106950000000 | E8: =Sheet16!G11*1000000 -> 96262000000 | F8: =Sheet16!H11*1000000 -> 43272000000 | H8: 2012년 스위치램프 추가 | K8: 판매비와 관리비 | L8: -43792009823 | M8: -41361745470 | N8: -44247827700 | O8: -20978070672 | P8: -23767040887 | Q8: -41361745470 | R8: -44247827700 | S8: =M8-Q8 -> 0 | T8: =N8-R8 -> 0
B9: BCS | C9: =Sheet16!P8*1000000 -> 64629000000 | D9: =Sheet16!F8*1000000 -> 65522000000 | E9: =Sheet16!G8*1000000 -> 72550000000 | F9: =Sheet16!H8*1000000 -> 40455000000 | K9: 영업이익 | L9: 9051874317 | M9: 19049447913 | N9: 22730753652 | O9: 9929866912 | P9: 10856591634 | Q9: 14933182257 | R9: 16206463246 | S9: =M9-Q9 -> 4116265656 | T9: =N9-R9 -> 6524290406
B10: 매출원가 | C10: =-L6 -> 475725626210 | D10: =-M6 -> 499445340398 | E10: =-N6 -> 524218029958 | F10: =-O6 -> 273015109365 | G10: =-P6 -> 261870076026 | K10: 기타수익 | L10: 13026278480 | M10: 8492636959 | N10: 8106806758 | O10: 5213424386 | P10: 3562355144 | Q10: 12608902615 | R10: 14631097164 | S10: =M10-Q10 -> -4116265656 | T10: =N10-R10 -> -6524290406
B11: 매출총이익 | C11: =L7 -> 52843884140 | D11: =M7 -> 60411193383 | E11: =N7 -> 66978581352 | F11: =O7 -> 30907937584 | G11: =P7 -> 34623632521 | K11: 기타비용 | L11: -8610783775 | M11: -9571376805 | N11: -6730976780 | O11: -3743910653 | P11: -4805623865 | Q11: -9571376805 | R11: -6730976780 | S11: =M11-Q11 -> 0 | T11: =N11-R11 -> 0
B12: 매출총이익률(%) | C12: =C11/C6 -> 0.099975279 | D12: =D11/D6 -> 0.10790478 | E12: =E11/E6 -> 0.11329324 | F12: =F11/F6 -> 0.10169659 | G12: =G11/G6 -> 0.11677696 | K12: 금융수익 | L12: 3164239607 | M12: 3794577895 | N12: 2738057029 | O12: 4214581286 | P12: 2592352436 | Q12: 3794577895 | R12: 2738057029 | S12: =M12-Q12 -> 0 | T12: =N12-R12 -> 0
B13: 판매관리비 | C13: =-L8 -> 43792009823 | D13: =-M8 -> 41361745470 | E13: =-N8 -> 44247827700 | F13: =-O8 -> 20978070672 | G13: =-P8 -> 23767040887 | K13: 금융비용 | L13: -13034533243 | M13: -10424964533 | N13: -9110101151 | O13: -3980264818 | P13: -4726004172 | Q13: -10424964533 | R13: -9110101151 | S13: =M13-Q13 -> 0 | T13: =N13-R13 -> 0
B14: 인건비 | C14: =SUMIF($U$52:$U$72,$B14,W$52:W$72)*1000 -> 12090408000 | D14: =SUMIF($U$52:$U$72,$B14,X$52:X$72)*1000 -> 13107754000 | E14: =SUMIF($U$52:$U$72,$B14,Y$52:Y$72)*1000 -> 15759100000 | F14: =SUMIF($U$52:$U$72,$B14,Z$52:Z$72)*1000 -> 8735298000 | G14: =SUMIF($U$52:$U$72,$B14,AA$52:AA$72)*1000 -> 8084205000 | K14: 기타영업외수익 | L14: 2410270709 | M14: 2704255678 | N14: 952009841 | O14: 825116507 | P14: 1181918968 | Q14: 2704255678 | R14: 952009841 | S14: =M14-Q14 -> 0 | T14: =N14-R14 -> 0
B15: 감가상각비 | C15: =SUMIF($U$52:$U$72,$B15,W$52:W$72)*1000 -> 613048000 | D15: =SUMIF($U$52:$U$72,$B15,X$52:X$72)*1000 -> 550311000 | E15: =SUMIF($U$52:$U$72,$B15,Y$52:Y$72)*1000 -> 553004000 | F15: =SUMIF($U$52:$U$72,$B15,Z$52:Z$72)*1000 -> 287627000 | G15: =SUMIF($U$52:$U$72,$B15,AA$52:AA$72)*1000 -> 287454000 | K15: 기타영업외비용 | L15: -985641402 | M15: -1803476575 | N15: -2290914213 | O15: -1614021963 | P15: -583124654 | Q15: -1803476575 | R15: -2290914213 | S15: =M15-Q15 -> 0 | T15: =N15-R15 -> 0
B16: 무형자산상각비 | C16: =SUMIF($U$52:$U$72,$B16,W$52:W$72)*1000 -> 2312602000 | D16: =SUMIF($U$52:$U$72,$B16,X$52:X$72)*1000 -> 2638971000 | E16: =SUMIF($U$52:$U$72,$B16,Y$52:Y$72)*1000 -> 2979017000 | F16: =SUMIF($U$52:$U$72,$B16,Z$52:Z$72)*1000 -> 1224904000 | G16: =SUMIF($U$52:$U$72,$B16,AA$52:AA$72)*1000 -> 1462090000 | K16: 법인세비용차감전순이익 | L16: 5021704693 | M16: 12241100532 | N16: 16395635136 | O16: 10844791657 | P16: 8078465491 | Q16: 12241100532 | R16: 16395635136 | S16: =M16-Q16 -> 0 | T16: =N16-R16 -> 0
B17: 판매보증비 | C17: =SUMIF($U$52:$U$72,$B17,W$52:W$72)*1000 -> 11004711000 | D17: =SUMIF($U$52:$U$72,$B17,X$52:X$72)*1000 -> 7646333000 | E17: =SUMIF($U$52:$U$72,$B17,Y$52:Y$72)*1000 -> 7159190000 | F17: =SUMIF($U$52:$U$72,$B17,Z$52:Z$72)*1000 -> 3121228000 | G17: =SUMIF($U$52:$U$72,$B17,AA$52:AA$72)*1000 -> 5095133000 | K17: 법인세비용(혜택) | L17: 781096574 | M17: 14227147 | N17: -165484440 | O17: 648257422 | P17: -383715942 | Q17: 14227147 | R17: -165484440 | S17: =M17-Q17 -> 0 | T17: =N17-R17 -> 0
B18: 지급수수료 | C18: =SUMIF($U$52:$U$72,$B18,W$52:W$72)*1000 -> 5345304000 | D18: =SUMIF($U$52:$U$72,$B18,X$52:X$72)*1000 -> 5284352000 | E18: =SUMIF($U$52:$U$72,$B18,Y$52:Y$72)*1000 -> 3496597000 | F18: =SUMIF($U$52:$U$72,$B18,Z$52:Z$72)*1000 -> 1405797000 | G18: =SUMIF($U$52:$U$72,$B18,AA$52:AA$72)*1000 -> 1569508000 | K18: 당기순이익 | L18: 4240608119 | M18: 12226873385 | N18: 16561119576 | O18: 10196534235 | P18: 8462181433 | Q18: 12226873385 | R18: 16561119576 | S18: =M18-Q18 -> 0 | T18: =N18-R18 -> 0
B19: 경상개발비 | C19: =SUMIF($U$52:$U$72,$B19,W$52:W$72)*1000 -> 243199000 | D19: =SUMIF($U$52:$U$72,$B19,X$52:X$72)*1000 -> 948237000 | E19: =SUMIF($U$52:$U$72,$B19,Y$52:Y$72)*1000 -> 833108000 | F19: =SUMIF($U$52:$U$72,$B19,Z$52:Z$72)*1000 -> 304128000 | G19: =SUMIF($U$52:$U$72,$B19,AA$52:AA$72)*1000 -> 445060000 | K19: 법인세비용차감후 기타포괄손익 | S19: =M19-Q19 -> 0 | T19: =N19-R19 -> 0 | V19: 매출 및 매출원가의 구성내역은 다음과 같습니다.
B20: 세금과공과 | C20: =SUMIF($U$52:$U$72,$B20,W$52:W$72)*1000 -> 704385000 | D20: =SUMIF($U$52:$U$72,$B20,X$52:X$72)*1000 -> 566459000 | E20: =SUMIF($U$52:$U$72,$B20,Y$52:Y$72)*1000 -> 563143000 | F20: =SUMIF($U$52:$U$72,$B20,Z$52:Z$72)*1000 -> 284982000 | G20: =SUMIF($U$52:$U$72,$B20,AA$52:AA$72)*1000 -> 318150000 | K20: 후속적으로 당기손익으로 재분류될 수 있는 항목 | S20: =M20-Q20 -> 0 | T20: =N20-R20 -> 0 | V20: (단위: 천원) | Z20: 제43기 반기 | AA20: 제42기 반기
B21: 임차료 | C21: =SUMIF($U$52:$U$72,$B21,W$52:W$72)*1000 -> 1378681000 | D21: =SUMIF($U$52:$U$72,$B21,X$52:X$72)*1000 -> 1314861000 | E21: =SUMIF($U$52:$U$72,$B21,Y$52:Y$72)*1000 -> 1123636000 | F21: =SUMIF($U$52:$U$72,$B21,Z$52:Z$72)*1000 -> 556810000 | G21: =SUMIF($U$52:$U$72,$B21,AA$52:AA$72)*1000 -> 558667000 | K21: 매도가능증권평가손익 | L21: 6463649 | M21: 47898287 | N21: 34134329 | O21: 494535 | P21: 25600325 | Q21: 47898287 | R21: 34134329 | S21: =M21-Q21 -> 0 | T21: =N21-R21 -> 0 | V21: 구 분 | W21: 40기 | X21: 41기 | Y21: 42기 | Z21: 누적 | AA21: 누적
B22: 여비교통비 | C22: =SUMIF($U$52:$U$72,$B22,W$52:W$72)*1000 -> 823868000 | D22: =SUMIF($U$52:$U$72,$B22,X$52:X$72)*1000 -> 760129000 | E22: =SUMIF($U$52:$U$72,$B22,Y$52:Y$72)*1000 -> 1201955000 | F22: =SUMIF($U$52:$U$72,$B22,Z$52:Z$72)*1000 -> 613269000 | G22: =SUMIF($U$52:$U$72,$B22,AA$52:AA$72)*1000 -> 649647000 | K22: 파생상품평가손익 | L22: 4495184394 | M22: 1029089110 | N22: -3126264406 | O22: -1021354171 | P22: 2550811422 | Q22: 1029089110 | R22: -3126264406 | S22: =M22-Q22 -> 0 | T22: =N22-R22 -> 0 | W22: 매 출 | X22: 매 출 | Y22: 매 출
B23: 기타비용 | C23: =SUMIF($U$52:$U$72,$B23,W$52:W$72)*1000 -> 9275804000 | D23: =SUMIF($U$52:$U$72,$B23,X$52:X$72)*1000 -> 8544337000 | E23: =SUMIF($U$52:$U$72,$B23,Y$52:Y$72)*1000 -> 10579078000 | F23: =SUMIF($U$52:$U$72,$B23,Z$52:Z$72)*1000 -> 4444028000 | G23: =SUMIF($U$52:$U$72,$B23,AA$52:AA$72)*1000 -> 5297127000 | K23: 후속적으로 당기손익으로 재분류되지 않는 항목 | S23: =M23-Q23 -> 0 | T23: =N23-R23 -> 0 | V23: 제품 | W23: 526517113 | X23: 544246783 | Y23: 566780439 | Z23: 294177848 | AA23: 287076014
B24: 영업이익 | C24: =L9 -> 9051874317 | D24: =M9 -> 19049447913 | E24: =N9 -> 22730753652 | F24: =O9 -> 9929866912 | G24: =P9 -> 10856591634 | K24: 확정급여제도의 재측정요소 | L24: -713736032 | M24: -535900726 | N24: -1155508033 | O24: - | P24: - | Q24: -535900726 | R24: -1155508033 | S24: =M24-Q24 -> 0 | T24: =N24-R24 -> 0 | V24: 기타 | W24: 2052397 | X24: 11493485 | Y24: 17891882 | Z24: 9745199 | AA24: 9417695
B25: 영업이익(%) | C25: =C24/C6 -> 0.01712523 | D25: =D24/D6 -> 0.034025588 | E25: =E24/E6 -> 0.038448721 | F25: =F24/F6 -> 0.032672306 | G25: =G24/G6 -> 0.0366166 | K25: 총포괄이익 | L25: 8028520130 | M25: 12767960056 | N25: 12313481466 | O25: 9175674599 | P25: 11038593180 | Q25: 12767960056 | R25: 12313481466 | S25: =M25-Q25 -> 0 | T25: =N25-R25 -> 0 | V25: 합 계 | W25: 528569510 | X25: 555740268 | Y25: 584672321 | Z25: 303923047 | AA25: 296493709
B26: 금융수익 | C26: =L12 -> 3164239607 | D26: =M12 -> 3794577895 | E26: =N12 -> 2738057029 | F26: =O12 -> 4214581286 | G26: =P12 -> 2592352436 | K26: 주당손익 | S26: =M26-Q26 -> 0 | T26: =N26-R26 -> 0 | W26: 매 출 원 가 | X26: 매 출 원 가 | Y26: 매 출 원 가
B27: 금융비용 | C27: =-L13 -> 13034533243 | D27: =-M13 -> 10424964533 | E27: =-N13 -> 9110101151 | F27: =-O13 -> 3980264818 | G27: =-P13 -> 4726004172 | K27: 기본 및 희석주당손익 | L27: 430 | M27: 1239 | N27: 1678 | O27: 1033 | P27: 858 | Q27: 1239 | R27: 1678 | S27: =M27-Q27 -> 0 | T27: =N27-R27 -> 0 | V27: 제품 | W27: 475725626 | X27: 492941309 | Y27: 514315745 | Z27: 269948747 | AA27: 258838374
B28: 기타수익 | C28: =L10+L14 -> 15436549189 | D28: =M10+M14 -> 11196892637 | E28: =N10+N14 -> 9058816599 | F28: =O10+O14 -> 6038540893 | G28: =P10+P14 -> 4744274112 | H28: 기타수익+기타영업외수익 | V28: 기타 | W28: - | X28: 6504031 | Y28: 9902285 | Z28: 3066362 | AA28: 3031702
B29: 기타비용 | C29: =-(L11+L15) -> 9596425177 | D29: =-(M11+M15) -> 11374853380 | E29: =-(N11+N15) -> 9021890993 | F29: =-(O11+O15) -> 5357932616 | G29: =-(P11+P15) -> 5388748519 | H29: 기타비용+기타영업외비용 | V29: 합 계 | W29: 475725626 | X29: 499445340 | Y29: 524218030 | Z29: 273015109 | AA29: 261870076
B30: 법인세비용 | C30: =L17 -> 781096574 | D30: =M17 -> 14227147 | E30: =N17 -> -165484440 | F30: =O17 -> 648257422 | G30: =P17 -> -383715942
B31: 당기순이익 | C31: =L18 -> 4240608119 | D31: =M18 -> 12226873385 | E31: =N18 -> 16561119576 | F31: =O18 -> 10196534235 | G31: =P18 -> 8462181433 | V31: 22. 영업이익
B32: 당기순이익률(%) | C32: =C31/C6 -> 0.0080228012 | D32: =D31/D6 -> 0.021839297 | E32: =E31/E6 -> 0.02801288 | F32: =F31/F6 -> 0.033549724 | G32: =G31/G6 -> 0.028540847
B33: EBITDA | C33: =C24+C39 -> 37439779939 | D33: =D24+D39 -> 48220330377 | E33: =E24+E39 -> 52741648712 | F33: =F24+F39 -> 25278568327 | G33: =G24+G39 -> 25570961548 | V33: 22-1 종업원급여의 내역은 다음과 같습니다.
B34: EBITDA(%) | C34: =C33/C6 -> 0.070832273 | D34: =D33/D6 -> 0.086129798 | E34: =E33/E6 -> 0.08921169 | F34: =F33/F6 -> 0.08317424 | G34: =G33/G6 -> 0.086244533
B35: Source : 감사보고서 | V35: (단위: 천원) | Z35: 제43기 반기 | AA35: 제42기 반기
V36: 구 분 | W36: 40기 | X36: 41기 | Y36: 42기 | Z36: 누적 | AA36: 누적
B37: 감가상각비 | C37: ='CF(별도)'!B14 -> 20738867867 | D37: ='CF(별도)'!C14 -> 21766783544 | E37: ='CF(별도)'!D14 -> 23080308849 | F37: ='CF(별도)'!E14 -> 12278805441 | G37: ='CF(별도)'!F14 -> 11214198818 | V37: 급여 | W37: 42368676 | X37: 48051854 | Y37: 53158533 | Z37: 29219947 | AA37: 26753807
B38: 무형자산상각비 | C38: ='CF(별도)'!B15 -> 7649037755 | D38: ='CF(별도)'!C15 -> 7404098920 | E38: ='CF(별도)'!D15 -> 6930586211 | F38: ='CF(별도)'!E15 -> 3069895974 | G38: ='CF(별도)'!F15 -> 3500171096 | V38: 퇴직급여 | W38: 2746268 | X38: 3037008 | Y38: 3701975 | Z38: 2041980 | AA38: 1831649
B39: D&A | C39: =SUM(C37:C38) -> 28387905622 | D39: =SUM(D37:D38) -> 29170882464 | E39: =SUM(E37:E38) -> 30010895060 | F39: =SUM(F37:F38) -> 15348701415 | G39: =SUM(G37:G38) -> 14714369914 | V39: 복리후생비 | W39: 5469302 | X39: 6562561 | Y39: 6875849 | Z39: 3893106 | AA39: 3427477
C40: =C39-W48*1000 -> -378 | D40: =D39-X48*1000 -> -536 | E40: =E39-Y48*1000 -> 60 | F40: =F39-Z48*1000 -> 415 | G40: =G39-AA48*1000 -> -86 | V40: 합 계 | W40: 50584246 | X40: 57651423 | Y40: 63736357 | Z40: 35155033 | AA40: 32012933
C42: =SUM(C7:C9)-C6 -> -510350 | D42: =SUM(D7:D9)-D6 -> 466219 | E42: =SUM(E7:E9)-E6 -> -611310 | F42: =SUM(F7:F9)-F6 -> -46949 | G42: =SUM(G7:G9)-G6 -> -296493708547 | V42: 22-2 감가상각비와 무형자산상각비의 내역은 다음과 같습니다.
...

Sheet Sheet16
K1: (단위 : 백만원)
A2: 구분 | B2: 사업부문 | C2: 매출유형 | D2: 품 목 | F2: 2013년 | G2: 2014년 | H2: 2015년 반기 | K2: 구분 | L2: 사업부문 | M2: 매출유형 | N2: 품 목 | P2: 2012년 | Q2: 2013년 | R2: 2014년
A3: 대성전기공업㈜ | B3: 자동차부품 | C3: 제품 | D3: HMI | E3: 수출 | F3: 102861 | G3: 138573 | H3: 74785 | I3: =G3=R3 -> FALSE | J3: =F3=Q3 -> FALSE | K3: 대성전기공업㈜ | L3: 자동차부품 | M3: 제품 | N3: HMI | O3: 수출 | P3: 78129 | Q3: 99181 | R3: 132445
C4: 상품 | E4: 내수 | F4: 284524 | G4: 283811 | H4: 145412 | I4: =G4=R4 -> TRUE | J4: =F4=Q4 -> TRUE | M4: 상품 | O4: 내수 | P4: 265824 | Q4: 284524 | R4: 283811
C5: 용역 | E5: 합계 | F5: 387385 | G5: 422384 | H5: 220196 | I5: =G5=R5 -> FALSE | J5: =F5=Q5 -> FALSE | O5: 합계 | P5: 343953 | Q5: 383705 | R5: 416256
D6: BCS | E6: 수출 | F6: 15044 | G6: 14525 | H6: 8736 | I6: =G6=R6 -> FALSE | J6: =F6=Q6 -> FALSE | N6: BCS | O6: 수출 | P6: 13914 | Q6: 14995 | R6: 14434
E7: 내수 | F7: 50478 | G7: 58025 | H7: 31719 | I7: =G7=R7 -> TRUE | J7: =F7=Q7 -> TRUE | O7: 내수 | P7: 50715 | Q7: 50478 | R7: 58025
E8: 합계 | F8: 65522 | G8: 72550 | H8: 40455 | I8: =G8=R8 -> FALSE | J8: =F8=Q8 -> FALSE | O8: 합계 | P8: 64629 | Q8: 65473 | R8: 72459
D9: MC | E9: 수출 | F9: 52302 | G9: 54375 | H9: 25622 | I9: =G9=R9 -> FALSE | J9: =F9=Q9 -> FALSE | N9: MC | O9: 수출 | P9: 46546 | Q9: 51915 | R9: 54070
E10: 내수 | F10: 54648 | G10: 41887 | H10: 17650 | I10: =G10=R10 -> TRUE | J10: =F10=Q10 -> TRUE | O10: 내수 | P10: 68026 | Q10: 54648 | R10: 41887
E11: 합계 | F11: 106950 | G11: 96262 | H11: 43272 | I11: =G11=R11 -> FALSE | J11: =F11=Q11 -> FALSE | O11: 합계 | P11: 114572 | Q11: 106562 | R11: 95957
B12: 소 계 | E12: 수출 | F12: 170207 | G12: 207473 | H12: 109143 | I12: =G12=R12 -> FALSE | J12: =F12=Q12 -> FALSE | L12: 비자동차부품 | M12: 제품 | N12: 가전용 Switch 등 | O12: 수출 | P12: 547 | Q12: 0 | R12: 0
E13: 내수 | F13: 389650 | G13: 383723 | H13: 194780 | I13: =G13=R13 -> FALSE | J13: =F13=Q13 -> FALSE | M13: 상품 | O13: 내수 | P13: 4868 | Q13: 0 | R13: 0
E14: 합계 | F14: 559857 | G14: 591197 | H14: 303923 | I14: =G14=R14 -> FALSE | J14: =F14=Q14 -> FALSE | O14: 합계 | P14: 5415 | Q14: 0 | R14: 0
A15: 청도대성전자 | B15: 자동차부품 | C15: 제품 | D15: Switch, | E15: 수출 | F15: 8358 | G15: 13998 | H15: 10431 | I15: =G15=R15 -> FALSE | J15: =F15=Q15 -> FALSE | L15: 소 계 | O15: 수출 | P15: 138590 | Q15: 166091 | R15: 200949
A16: 유한공사 | C16: 상품 | D16: Room Lamp 등 | E16: 내수 | F16: 87508 | G16: 91322 | H16: 56054 | I16: =G16=R16 -> FALSE | J16: =F16=Q16 -> FALSE | O16: 내수 | P16: 384565 | Q16: 389649 | R16: 383723
E17: 합계 | F17: 95866 | G17: 105320 | H17: 66485 | I17: =G17=R17 -> FALSE | J17: =F17=Q17 -> FALSE | O17: 합계 | P17: 528570 | Q17: 555740 | R17: 584672
A18: 무석대성전자 | B18: 자동차부품 | C18: 제품 | D18: ABS coil housing,BCM, Switch 등 | E18: 수출 | F18: 11798 | G18: 23398 | H18: 12331 | I18: =G18=R18 -> FALSE | J18: =F18=Q18 -> FALSE | K18: 청도대성전자 | L18: 자동차 및 | M18: 제품 | N18: Switch, Relay 등 | O18: 수출 | P18: 8645 | Q18: 8358 | R18: 13998
A19: 유한공사 | C19: 상품 | E19: 내수 | F19: 40135 | G19: 39505 | H19: 25352 | I19: =G19=R19 -> FALSE | J19: =F19=Q19 -> FALSE | K19: 유한공사 | L19: 비자동차부품 | M19: 상품 | O19: 내수 | P19: 66962 | Q19: 87508 | R19: 91322
E20: 합계 | F20: 51933 | G20: 62904 | H20: 37683 | I20: =G20=R20 -> FALSE | J20: =F20=Q20 -> FALSE | O20: 합계 | P20: 75608 | Q20: 95866 | R20: 105320
A21: Daesung Electric | B21: 자동차부품 | C21: 제품 | D21: Switch, | E21: 수출 | F21: 3049 | G21: 4612 | H21: 3954 | I21: =G21=R21 -> FALSE | J21: =F21=Q21 -> FALSE | K21: 무석대성전자 | L21: 자동차부품 | M21: 제품 | N21: Switch, Relay 등 | O21: 수출 | P21: 7057 | Q21: 11798 | R21: 23398
A22: India Private | C22: 상품 | D22: Audio Panel 등 | E22: 내수 | F22: 30054 | G22: 44372 | H22: 33480 | I22: =G22=R22 -> FALSE | J22: =F22=Q22 -> FALSE | K22: 유한공사 | M22: 상품 | O22: 내수 | P22: 43078 | Q22: 40135 | R22: 39505
A23: Limited | E23: 합계 | F23: 33103 | G23: 48984 | H23: 37433 | I23: =G23=R23 -> FALSE | J23: =F23=Q23 -> FALSE | O23: 합계 | P23: 50134 | Q23: 51933 | R23: 62904
A24: 비고) 대성전기공업㈜ 매출은 Ⅲ.6.가.(1)재무제표 재작성 등 유의사항에 따른 계정과목 재분류에 따라 | K24: 비고) 품목별 매출액은 2014년 제품군 재편에 따라 조정 후 금액임
A25: 재작성함

Sheet CF(연결)
A1: 연 결 현 금 흐 름 표
A2: 제43기 반기 2015년 01월 01일부터 2015년 06월 30일까지
A3: 제42기 반기 2014년 01월 01일부터 2014년 06월 30일까지
A4: 제42기 2014년 01월 01일부터 2014년 12월 31일까지
A5: 제41기 2013년 01월 01일부터 2013년 12월 31일까지
A6: 제40기 2012년 01월 01일부터 2012년 12월 31일까지
A7: 회사명 : 대성전기공업 주식회사와 그 종속기업
B8: 제 40 기 | C8: 제 41 기 | D8: 제42기 | E8: 제43기 반기 | F8: 제42기 반기
A9: Ⅰ.영업활동현금흐름
A10: 1.당기순이익 | B10: 2278194692 | C10: 12095282611 | D10: 17951228918 | E10: 7275649811 | F10: 9237721771
A11: 2.비현금 항목의 조정
A12: 재고자산폐기손실 | B12: 1304314370 | C12: 0 | D12: 0 | E12: 0 | F12: 0
A13: 퇴직급여 | B13: 2825869513 | C13: 3124636778 | D13: 3781544359 | E13: 2075099701 | F13: 1871434141
A14: 감가상각비 | B14: 27615340495 | C14: 29666485532 | D14: 31190193327 | E14: 16973712924 | F14: 15696912464
A15: 무형자산상각비 | B15: 7959752978 | C15: 7640806631 | D15: 7230038267 | E15: 3461177423 | F15: 3615648616
A16: 외화환산이익 | B16: -4063350790 | C16: -7144755369 | D16: -3041578670 | E16: -2447825653 | F16: -2104401417
A17: 외화환산손실 | B17: 5566046633 | C17: 6530627800 | D17: 3924060409 | E17: 1550268036 | F17: 1941670171
A18: 판매보증충당부채전입액 | B18: 11958236601 | C18: 8478016247 | D18: 8009624176 | E18: 3609775726 | F18: 5380269276
A19: 유형자산처분이익 | B19: -402604693 | C19: -555073824 | D19: -468507740 | E19: -294727852 | F19: -73664914
A20: 유형자산처분손실 | B20: 376615133 | C20: 1432122978 | D20: 837206683 | E20: 80626125 | F20: 319674521
A21: 유형자산손상차손 | B21: 0 | C21: 0 | D21: 185325879 | E21: 47258667 | F21: 116036292
A22: 무형자산처분이익 | B22: -71528274 | C22: -117216472 | D22: -3272324 | E22: -1513571 | F22: -3272324
A23: 무형자산손상차손 | B23: 0 | C23: 0 | D23: 530089449 | E23: 4064600 | F23: 434334706
... A25: 대손상각비(환입) | B25: 520839044 | C25: 169657745 | D25: -6745213 | E25: 474167375 | F25: -513045070
A26: 기타의 대손상각비(환입) | B26: - | C26: 1473827476 | D26: -522149911 | E26: - | F26: -
A27: 금융수익 | B27: -1109646265 | C27: -1102821813 | D27: -728115463 | E27: -383069856 | F27: -514083633
A28: 금융원가 | B28: 16492753645 | C28: 12048493747 | D28: 10452219619 | E28: 4711750873 | F28: 5375889067
A29: 파생상품평가손실(이익) | B29: 257830232 | C29: 205678876 | D29: -104778210 | E29: 16544425 | F29: -136664901
A30: 지분법 손실(이익) | B30: -12874266 | C30: 590811004 | D30: -105298978 | E30: -17076365 | F30: -97422003
A31: 잡이익 | B31: -96897634 | C31: - | D31: - | E31: - | F31: -
A32: 법인세비용(혜택) | B32: 1893814540 | C32: 438342545 | D32: 1186573100 | E32: 2495523826 | F32: 491120397
A33: 소 계 | B33: 70884218101 | C33: 62879639881 | D33: 62346428759 | E33: 32355756404 | F33: 31800435389
A34: 3.운전자본 조정
A35: 매출채권 | B35: 24904813783 | C35: 13305408307 | D35: -18707835017 | E35: -5163758612 | F35: 3178257999
A36: 기타수취채권 | B36: 3356349416 | C36: -3973777260 | D36: 5182683347 | E36: 1993630909 | F36: -844554678
A37: 기타유동자산 | B37: -890254646 | C37: -8660324062 | D37: -5492326479 | E37: -8240227052 | F37: 273839072
A38: 기타비유동자산 | B38: 517968904 | C38: -46775921 | D38: -252048829 | E38: -315164563 | F38: 200012726
A39: 재고자산 | B39: 4444880470 | C39: 1842889636 | D39: -11525768758 | E39: -1693278381 | F39: -730589059
A40: 매입채무 | B40: -8049276108 | C40: -2902483390 | D40: 19847831460 | E40: -8759598728 | F40: -5876462219
A41: 기타지급채무 | B41: -5187959756 | C41: -24639002 | D41: 5599410454 | E41: 6924091505 | F41: 4105408210
...

Sheet CF(별도)
A1: 현 금 흐 름 표
A2: 제43기 반기 2015년 01월 01일부터 2015년 06월 30일까지
A3: 제42기 반기 2014년 01월 01일부터 2014년 06월 30일까지
A4: 제42기 2014년 01월 01일부터 2014년 12월 31일까지
A5: 제41기 2013년 01월 01일부터 2013년 12월 31일까지
A6: 제40기 2012년 01월 01일부터 2012년 12월 31일까지
A7: 회사명 : 대성전기공업 주식회사 | E7: (단위 : 원)
A8: 과 목 | B8: 제 40 기 | C8: 제 41 기 | D8: 제 42 기 | E8: 제 43 기 반기 | F8: 제 42 기 반기
A9: Ⅰ.영업활동현금흐름
A10: 1.당기순이익(손실) | B10: 4240608119 | C10: 12226873385 | D10: 16561119576 | E10: 10196534235 | F10: 8462181433
A11: 2.비현금 항목의 조정
A12: 재고자산폐기손실 | B12: 1304314370 | C12: 0 | D12: 0 | E12: 0 | F12: 0
A13: 퇴직급여 | B13: 2746267555 | C13: 3037008358 | D13: 3701974854 | E13: 2041979592 | F13: 1831649389
A14: 감가상각비 | B14: 20738867867 | C14: 21766783544 | D14: 23080308849 | E14: 12278805441 | F14: 11214198818
A15: 무형자산상각비 | B15: 7649037755 | C15: 7404098920 | D15: 6930586211 | E15: 3069895974 | F15: 3500171096
A16: 외화환산이익 | B16: -1634955840 | C16: -2046833941 | D16: -2703406329 | E16: -2325968748 | F16: -1534369091
A17: 외화환산손실 | B17: 2411414967 | C17: 1358670238 | D17: 2499869534 | E17: 1484568862 | F17: 1693301229
A18: 판매보증충당부채전입액 | B18: 11004711400 | C18: 7646332814 | D18: 7159190049 | E18: 3121228000 | F18: 5095132711
A19: 유형자산처분이익 | B19: -1117707277 | C19: -1148930720 | D19: -426705391 | E19: -18391088 | F19: -209320110
A20: 유형자산처분손실 | B20: 225800497 | C20: 823983234 | D20: 566769170 | E20: 14109033 | F20: 152954407
A21: 유형자산손상차손 | B21: - | C21: - | D21: 185325879 | E21: 47258667 | F21: 116036292
A22: 무형자산처분이익 | B22: -71528274 | C22: -117216472 | D22: -3272324 | E22: -1513571 | F22: -3272324
A23: 무형자산손상차손 | B23: - | C23: - | D23: 530089449 | E23: 4064600 | F23: 434334706
A24: 대손상각비(환입) | B24: 476264051 | C24: 60881455 | D24: - | E24: - | F24: -
A25: 기타의 대손상각비(환입) | C25: 1445492145 | D25: -494955312 | E25: - | F25: -494955312
A26: 금융수익 | B26: -3164239607 | C26: -3794577895 | D26: -2738057029 | E26: -4214581286 | F26: -2592352436
A27: 금융원가 | B27: 13034533243 | C27: 10424964533 | D27: 9110101151 | E27: 3980264818 | F27: 4726004172
A28: 파생상품자산/부채평가이익 | B28: 0 | C28: 0 | D28: 0 | E28: -26631230 | F28: 0
A29: 잡이익 | B29: -15690000 | C29: 0 | D29: -1741853 | E29: -54343630 | F29: -34609083
A30: 법인세비용(혜택) | B30: 781096574 | C30: 14227147 | D30: -165484440 | E30: 648257422 | F30: -383715942
A31: 소 계 | B31: 54368187281 | C31: 46874883360 | D31: 47230592468 | E31: 20049002856 | F31: 23511188522
A32: 3.운전자본 조정
A33: 매출채권 | B33: 19391248843 | C33: 16220763394 | D33: -10879950502 | E33: -13339355901 | F33: 1505574318
A34: 기타수취채권 | B34: -1368525160 | C34: -278987959 | D34: -1811950888 | E34: 4721092900 | F34: 1744429319
A35: 기타유동자산 | B35: -59087293 | C35: -4811332679 | D35: -1450282993 | E35: -5537113424 | F35: -1351878817
A36: 기타비유동자산 | B36: 117600000 | C36: 117600000 | D36: 117600000 | E36: 58800000 | F36: 58800000
A37: 재고자산 | B37: 6150461092 | C37: 4371444904 | D37: -1479347685 | E37: -673155121 | F37: -549536017
A38: 매입채무 | B38: -4789671402 | C38: 2117203034 | D38: 2432568592 | E38: -3492869683 | F38: -5236522066
A39: 기타지급채무 | B39: -5449208 | C39: -923270136 | D39: 2193935962 | E39: 2339955007 | F39: 1960497510
A40: 기타유동부채 | B40: -538700816 | C40: 155054109 | D40: 405703064 | E40: 170612669 | F40: -872137990
...

Sheet 무석>>

Sheet FCF
B2: 현금흐름 분석
C3: 2012년 | D3: 2013년 | E3: 2014년 | F3: 2015년
B4: RMB'000 | C4: 12개월 | D4: 12개월 | E4: 12개월 | F4: 6개월
B5: EBITDA | C5: ='IS(RMB)'!C30 -> 13440859 | D5: ='IS(RMB)'!D30 -> 10965573 | E5: ='IS(RMB)'!E30 -> 32850385 | F5: ='IS(RMB)'!F30 -> 19887912
B6: 운전자본 변동 | C6: =C31 -> -16987805 | D6: =D31 -> -2557557.7 | E6: =E31 -> -7499323.1 | F6: =F31 -> -6160829
B7: CAPEX | C7: =SUM(C8:C9) -> -41287318 | D7: =SUM(D8:D9) -> -53925016 | E7: =SUM(E8:E9) -> -74304860 | F7: =SUM(F8:F9) -> -27954641
B8: 취득 | C8: =C22 -> -41294677 | D8: =D22 -> -54137734 | E8: =E22 -> -74431878 | F8: =F22 -> -28205890
B9: 처분 | C9: =C23 -> 7358.98 | D9: =D23 -> 212717.95 | E9: =E23 -> 127018.05 | F9: =F23 -> 251248.88
B10: FCF | C10: =SUM(C5:C7) -> -44834264 | D10: =SUM(D5:D7) -> -45517001 | E10: =SUM(E5:E7) -> -48953798 | F10: =SUM(F5:F7) -> -14227558
B11: 차입(상환) | C11: =C34 -> 9665820 | D11: =D34 -> 45170499 | E11: =E34 -> 28934082 | F11: =F34 -> 13693750
B12: 세금 | C12: =C39 -> -13846362 | D12: =D39 -> -5661467.7 | E12: =E39 -> 14051370
B13: 환율 | C13: =C42 -> -145335.84 | D13: =D42 -> -785804.3 | E13: =E42 -> 532367.29 | F13: =F42 -> -120042.33
B14: 기타 | C14: =C15-SUM(C10:C13) -> 40886901 | D14: =D15-SUM(D10:D13) -> 6007969.9 | E14: =E15-SUM(E10:E13) -> 5968345.7 | F14: =F15-SUM(F10:F13) -> -2777855.6
B15: 현금흐름 | C15: =C17 -> -8273241.3 | D15: =D17 -> -785804.3 | E15: =E17 -> 532367.29 | F15: =F17 -> -3431706.1
B16: source: 감사 보고서
C17: =C21-B21 -> -8273241.3 | D17: =D21-C21 -> -785804.3 | E17: =E21-D21 -> 532367.29 | F17: =F21-E21 -> -3431706.1
A21: 현금 | B21: 14817388 | C21: ='BS(RMB,)'!C6 -> 6544146.5 | D21: ='BS(RMB,)'!D6 -> 5758342.2 | E21: ='BS(RMB,)'!E6 -> 6290709.5 | F21: ='BS(RMB,)'!F6 -> 2859003.5
B22: CAPEX_취득 | C22: -41294677 | D22: -54137734 | E22: -74431878 | F22: -28205890
B23: CAPEX_처분 | C23: 7358.98 | D23: 212717.95 | E23: 127018.05 | F23: 251248.88
B25: 2011년 | C25: 2012년 | D25: 2013년 | E25: 2014년 | F25: 2015년
A26: RMB'000 | B26: 11월31일 | C26: 12월 31일 | D26: 12월 31일 | E26: 12월 31일 | F26: 6월 30일
A27: 매출채권 | B27: 58631323 | C27: 80351270 | D27: 86422336 | E27: 98504881 | F27: 1.2749784e+08
A28: 재고자산 | B28: 63527066 | C28: 61491932 | D28: 64345113 | E28: 70443675 | F28: 71854417
A29: 매입채무 | B29: 45082989 | C29: 47779997 | D29: 54146686 | E29: 64828470 | F29: 89071341
A30: NWC | B30: =B27+B28-B29 -> 77075400 | C30: =C27+C28-C29 -> 94063205 | D30: =D27+D28-D29 -> 96620763 | E30: =E27+E28-E29 -> 1.0412009e+08 | F30: =F27+F28-F29 -> 1.1028091e+08
C31: =B30-C30 -> -16987805 | D31: =C30-D30 -> -2557557.7 | E31: =D30-E30 -> -7499323.1 | F31: =E30-F30 -> -6160829
B32: 차입 | C32: 111059000 | D32: 1.9114237e+08 | E32: 1.9622792e+08 | F32: 48646959
B33: 상환 | C33: -101393180 | D33: -1.4597187e+08 | E33: -1.6729384e+08 | F33: -34953209
C34: =SUM(C32:C33) -> 9665820 | D34: =SUM(D32:D33) -> 45170499 | E34: =SUM(E32:E33) -> 28934082 | F34: =SUM(F32:F33) -> 13693750
B36: 세금 | C36: 2012 | D36: 2013 | E36: 2014 | F36: 2015
B37: refund | D37: 3939851.9 | E37: 16867473
B38: paid | C38: 13846362 | D38: 9601319.6 | E38: 2816102.9
C39: =C37-C38 -> -13846362 | D39: =D37-D38 -> -5661467.7 | E39: =E37-E38 -> 14051370
