Workbook
Name aaa: [2]대구동수금!$A$1:$H$29
Name BBB: [3]대구동수금!$A$1:$H$29
Name jjj: #REF!
Name jjj: #REF!
Name jjj: #REF!
Name jjj: #REF!
Name jjj: #REF!
Name jjj: #REF!
Name jjj: #REF!
Name jjj: #REF!
Name jjj: #REF!
Name jjj: #REF!
Name jjj: #REF!
Name jjj: #REF!
Name pc수불부: [5]상품!$A$1
Name ㄴ: #REF!
Name ㄴ: #REF!
Name ㄴ: #REF!
Name ㄴ: #REF!
Name ㄴ: #REF!
Name ㄴ: #REF!
Name ㄴ: #REF!
Name ㄴ: #REF!
Name ㄴ: #REF!
Name ㄴ: #REF!
Name ㄴ: #REF!
Name ㄴ: #REF!
Name ㄴㅇㄹ: #REF!
Name ㄴㅇㄹ: #REF!
Name ㄴㅇㄹ: #REF!
Name ㄴㅇㄹ: #REF!
Name ㄴㅇㄹ: #REF!
Name ㄴㅇㄹ: #REF!
Name ㄴㅇㄹ: #REF!
Name ㄴㅇㄹ: #REF!
Name ㄴㅇㄹ: #REF!
Name ㄴㅇㄹ: #REF!
Name ㄴㅇㄹ: #REF!
Name ㄴㅇㄹ: #REF!
Name 나는: #REF!
Name 나는: #REF!
Name 나는: #REF!
Name 나는: #REF!
Name 나는: #REF!
Name 나는: #REF!
Name 나는: #REF!
Name 나는: #REF!
Name 나는: #REF!
Name 나는: #REF!
Name 나는: #REF!
Name 나는: #REF!
Name 노무비: #REF!
Name 노무비: #REF!
Name 노무비: #REF!
Name 노무비: #REF!
Name 노무비: #REF!
Name 노무비: #REF!
Name 노무비: #REF!
Name 노무비: #REF!
Name 노무비: #REF!

Sheet ES >>>>>>>>

Sheet TO
B1: 회사개요 | I1: 주주 구성 내역
B2: 설립일 | C2: 39678 | J2: 주식 수 | K2: 지분율
B3: 자본금 | C3: 4,191백만원 (8,382,000주, 1주당 액면가액 500원) | I3: 보통주 | J3: =SUM(J4:J5) -> 8382000 | K3: =SUM(K4:K5) -> 0.5990566
B4: 최대주주 | C4: 동아쏘시오홀딩스주식회사 및 특수관계인(85.74%) | I4: 네오플럭스 | J4: 280500 | K4: =J4/$J$11 -> 0.02004717
B5: 소재지 | C5: (본사) 경기도 시흥시 정왕3동 1241-2 | I5: 동아쏘시오홀딩스와 그 특수관계자 | J5: 8101500 | K5: =J5/$J$11 -> 0.57900943
C6: (서울사무소) 서울시 강남구 대치동 891-43 MSA빌딩 7층 | I6: 우선주 | J6: =SUM(J7:J10) -> 5610000 | K6: =SUM(K7:K10) -> 0.4009434
C7: (반월공장) 경기도 안산시 단원구 목내동 434-5 | I7: 네오플럭스 | J7: 3746556 | K7: =J7/$J$11 -> 0.26776415
B8: 업종명 | C8: 의약용 화합물 및 항생물질 제조업 | I8: 동아쏘시오홀딩스 | J8: 292644 | K8: =J8/$J$11 -> 0.020915094
B9: 인원현황 | C9: 372명(임원10명, 직원 362명) | I9: 동아에스티 | J9: 1399200 | K9: =J9/$J$11 -> 0.1
B10: 공급현황 | C10: 고객사 93개사 (2015년 9월 현재) | I10: 수석문화재단 | J10: 171600 | K10: =J10/$J$11 -> 0.012264151
B11: 주요상품 | C11: 신약CMO, 제네릭, 정밀화학, 바이오 | I11: 총계 | J11: =J3+J6 -> 13992000 | K11: =K3+K6 -> 1
F13: 회사연혁
F14: 1983. 2 | G14: 의약품 제조사 설립
F15: 1985. 2 | G15: 신광약품에서 삼천리제약으로 상호변경
F16: 1987. 9 | G16: 국내최초 에이즈치료제 Zidovudine 공동개발
F17: 1988. 1 | G17: 경기도 화성 공장 준공
F18: 1994. 2 | G18: 시화 1,2공장 준공
F19: 1997. 4 | G19: 시화 3공장 준공
F20: 1998. 5 | G20: 시화 5공장 준공
F21: 2007. 11 | G21: 시화 6공장 준공
F22: 2010. 6 | G22: 유켐과 삼천리제약 합병, 동아쏘시아그룹편입
F23: 2010. 9 | G23: 에스티팜으로사명변경
F24: 2015. 5 | G24: 반월1공장 준공
F25: 2015. 9 | G25: 반월1공장 식약청 승인
F26: 2015. 11 | G26: 동아에스티로부터 반월2공장 510억 원에 영업양수 진행중에 있음

Sheet 매출유형별 bridge
C4: 매출액 | D4: 2012년 | E4: 2013년 | F4: 2014년 | G4: 2015년 12개월 환산 | H4: 2015년 3분기 | J4: FY12 | K4: =D7 -> 82729037197 | M4: =K4 -> 82729037197 | N4: =K4 -> 82729037197
C5: 제품 | D5: =C43 -> 65241045584 | E5: =D43 -> 63262105172 | F5: =E43 -> 81086958711 | G5: =H5/9*12 -> 1.0403114e+11 | H5: =G43 -> 78023354330 | J5: 제품 | K5: =O5 -> 80750096785 | L5: =ABS(M5) -> 1978940412 | M5: =D14 -> -1978940412 | N5: =N4+M5 -> 80750096785 | O5: =IF(N5>N4,N4,N5) -> 80750096785
C6: 상품 | D6: =C44 -> 17487991613 | E6: =D44 -> 19993094965 | F6: =E44 -> 14957892027 | G6: =H6/9*12 -> 19935067884 | H6: =G44 -> 14951300913 | J6: 상품 | K6: =O6 -> 80750096785 | L6: =ABS(M6) -> 2505103352 | M6: =D15 -> 2505103352 | N6: =N5+M6 -> 83255200137 | O6: =IF(N6>N5,N5,N6) -> 80750096785
C7: 합계 | D7: =SUM(D5:D6) -> 82729037197 | E7: =SUM(E5:E6) -> 83255200137 | F7: =SUM(F5:F6) -> 96044850738 | G7: =SUM(G5:G6) -> 1.2396621e+11 | H7: =SUM(H5:H6) -> 92974655243 | J7: FY13 | K7: =O7 -> 83255200137 | N7: =N6+M7 -> 83255200137 | O7: =IF(N7>N6,N6,N7) -> 83255200137
C8: Note: 2015년의 경우, 3분기 실적을 단순 연환산 함. | J8: 제품 | K8: =O8 -> 83255200137 | L8: =ABS(M8) -> 17824853539 | M8: =E14 -> 17824853539 | N8: =N7+M8 -> 101080053676 | O8: =IF(N8>N7,N7,N8) -> 83255200137
J9: 상품 | K9: =O9 -> 96044850738 | L9: =ABS(M9) -> 5035202938 | M9: =E15 -> -5035202938 | N9: =N8+M9 -> 96044850738 | O9: =IF(N9>N8,N8,N9) -> 96044850738
J10: FY14 | K10: =O10 -> 96044850738 | N10: =N9+M10 -> 96044850738 | O10: =IF(N10>N9,N9,N10) -> 96044850738
J11: 제품 | K11: =O11 -> 96044850738 | L11: =ABS(M11) -> 2.294418e+10 | M11: =F14 -> 2.294418e+10 | N11: =N10+M11 -> 1.1898903e+11 | O11: =IF(N11>N10,N10,N11) -> 96044850738
J12: 상품 | K12: =O12 -> 1.1898903e+11 | L12: =ABS(M12) -> 4977175857 | M12: =F15 -> 4977175857 | N12: =N11+M12 -> 1.2396621e+11 | O12: =IF(N12>N11,N11,N12) -> 1.1898903e+11
C13: 연도별 변동 | D13: 2013년 | E13: 2014년 | F13: 2015년 | J13: FY15(E) | K13: =O13 -> 1.2396621e+11 | N13: =N12+M13 -> 1.2396621e+11 | O13: =IF(N13>N12,N12,N13) -> 1.2396621e+11
C14: 제품 | D14: =E5-D5 -> -1978940412 | E14: =F5-E5 -> 17824853539 | F14: =G5-F5 -> 2.294418e+10
C15: 상품 | D15: =E6-D6 -> 2505103352 | E15: =F6-E6 -> -5035202938 | F15: =G6-F6 -> 4977175857
C16: 합계 | D16: =SUM(D14:D15) -> 526162940 | E16: =SUM(E14:E15) -> 12789650601 | F16: =SUM(F14:F15) -> 2.7921356e+10
D17: =E7-D7=D16 -> TRUE | E17: =F7-E7=E16 -> TRUE | F17: =G7-F7=F16 -> TRUE
B39: 손익계산서(별도)
C40: 2012년 | D40: 2013년 | E40: 2014년 | F40: 2015년 | G40: 2015년
B41: 백만원 | C41: 12개월 | D41: 12개월 | E41: 12개월 | F41: 6개월 | G41: 9개월
B42: 매출 | C42: =R40 -> 0 | D42: =S40 -> 0 | E42: =T40 -> 0 | F42: =U40 -> 0 | G42: =V40 -> 0
B43: 제품 | C43: 65241045584 | D43: 63262105172 | E43: 81086958711 | F43: 38080592041 | G43: 78023354330
B44: 상품 | C44: 17487991613 | D44: 19993094965 | E44: 14957892027 | F44: 9866583016 | G44: 14951300913
B45: 기타 | C45: 255006510 | D45: 1000769330 | E45: 495178170 | F45: 271382200 | G45: 977015601

Sheet 사업부별 제품별 bridge 
C4: 매출액 | D4: 2012년 | E4: 2013년 | F4: 2014년 | G4: 2015년 12개월 환산 | H4: 2015년 3분기 | J4: FY12 | K4: =D9 -> 65496000000 | M4: =K4 -> 65496000000 | N4: =K4 -> 65496000000
C5: CMO신약 | D5: 16330000000 | E5: 43185000000 | F5: 53845000000 | G5: =H5/9*12 -> 7.4801333e+10 | H5: 56101000000 | I5: =(G5/D5)^(1/3)-1 -> 0.66076322 | J5: CMO신약 | K5: =O5 -> 65496000000 | L5: =ABS(M5) -> 26855000000 | M5: =D14 -> 26855000000 | N5: =N4+M5 -> 92351000000 | O5: =IF(N5>N4,N4,N5) -> 65496000000
C6: 정밀화학 | D6: 33388000000 | E6: 7242000000 | F6: 10784000000 | G6: =H6/9*12 -> 1.1809333e+10 | H6: 8857000000 | J6: 정밀화학 | K6: =O6 -> 66205000000 | L6: =ABS(M6) -> 26146000000 | M6: =D15 -> -26146000000 | N6: =N5+M6 -> 66205000000 | O6: =IF(N6>N5,N5,N6) -> 66205000000
C7: 제네릭API | D7: 10176000000 | E7: 9445000000 | F7: 11504000000 | G7: =H7/9*12 -> 11372000000 | H7: 8529000000 | J7: 제네릭API | K7: =O7 -> 65474000000 | L7: =ABS(M7) -> 731000000 | M7: =D16 -> -731000000 | N7: =N6+M7 -> 65474000000 | O7: =IF(N7>N6,N6,N7) -> 65474000000
C8: 바이오사업 | D8: 5602000000 | E8: 4400000000 | F8: 5449000000 | G8: =H8/9*12 -> 8.2253333e+09 | H8: 6169000000 | J8: 바이오사업 | K8: =O8 -> 64272000000 | L8: =ABS(M8) -> 1202000000 | M8: =D17 -> -1202000000 | N8: =N7+M8 -> 64272000000 | O8: =IF(N8>N7,N7,N8) -> 64272000000
C9: 합계 | D9: =SUM(D5:D8) -> 65496000000 | E9: =SUM(E5:E8) -> 64272000000 | F9: =SUM(F5:F8) -> 81582000000 | G9: =SUM(G5:G8) -> 106208000000 | J9: FY13 | K9: =O9 -> 64272000000 | N9: =N8+M9 -> 64272000000 | O9: =IF(N9>N8,N8,N9) -> 64272000000
C10: Note: 2015년의 경우, 3분기 실적을 단순 연환산 함. | J10: CMO신약 | K10: =O10 -> 64272000000 | L10: =ABS(M10) -> 10660000000 | M10: =E14 -> 10660000000 | N10: =N9+M10 -> 74932000000 | O10: =IF(N10>N9,N9,N10) -> 64272000000
J11: 정밀화학 | K11: =O11 -> 74932000000 | L11: =ABS(M11) -> 3542000000 | M11: =E15 -> 3542000000 | N11: =N10+M11 -> 78474000000 | O11: =IF(N11>N10,N10,N11) -> 74932000000
J12: 제네릭API | K12: =O12 -> 78474000000 | L12: =ABS(M12) -> 2059000000 | M12: =E16 -> 2059000000 | N12: =N11+M12 -> 80533000000 | O12: =IF(N12>N11,N11,N12) -> 78474000000
C13: 연도별 변동 | D13: 2013년 | E13: 2014년 | F13: 2015년 | J13: 바이오사업 | K13: =O13 -> 80533000000 | L13: =ABS(M13) -> 1049000000 | M13: =E17 -> 1049000000 | N13: =N12+M13 -> 81582000000 | O13: =IF(N13>N12,N12,N13) -> 80533000000
C14: CMO신약 | D14: =E5-D5 -> 26855000000 | E14: =F5-E5 -> 10660000000 | F14: =G5-F5 -> 2.0956333e+10 | J14: FY14 | K14: =O14 -> 81582000000 | N14: =N13+M14 -> 81582000000 | O14: =IF(N14>N13,N13,N14) -> 81582000000
C15: 정밀화학 | D15: =E6-D6 -> -26146000000 | E15: =F6-E6 -> 3542000000 | F15: =G6-F6 -> 1.0253333e+09 | J15: CMO신약 | K15: =O15 -> 81582000000 | L15: =ABS(M15) -> 2.0956333e+10 | M15: =F14 -> 2.0956333e+10 | N15: =N14+M15 -> 1.0253833e+11 | O15: =IF(N15>N14,N14,N15) -> 81582000000
C16: 제네릭API | D16: =E7-D7 -> -731000000 | E16: =F7-E7 -> 2059000000 | F16: =G7-F7 -> -132000000 | J16: 정밀화학 | K16: =O16 -> 1.0253833e+11 | L16: =ABS(M16) -> 1.0253333e+09 | M16: =F15 -> 1.0253333e+09 | N16: =N15+M16 -> 1.0356367e+11 | O16: =IF(N16>N15,N15,N16) -> 1.0253833e+11
C17: 바이오사업 | D17: =E8-D8 -> -1202000000 | E17: =F8-E8 -> 1049000000 | F17: =G8-F8 -> 2.7763333e+09 | J17: 제네릭API | K17: =O17 -> 1.0343167e+11 | L17: =ABS(M17) -> 132000000 | M17: =F16 -> -132000000 | N17: =N16+M17 -> 1.0343167e+11 | O17: =IF(N17>N16,N16,N17) -> 1.0343167e+11
C18: 합계 | D18: =SUM(D14:D17) -> -1224000000 | E18: =SUM(E14:E17) -> 17310000000 | F18: =SUM(F14:F17) -> 2.4626e+10 | J18: 바이오사업 | K18: =O18 -> 1.0343167e+11 | L18: =ABS(M18) -> 2.7763333e+09 | M18: =F17 -> 2.7763333e+09 | N18: =N17+M18 -> 106208000000 | O18: =IF(N18>N17,N17,N18) -> 1.0343167e+11
D19: =E9-D9=D18 -> TRUE | E19: =F9-E9=E18 -> TRUE | F19: =G9-F9=F18 -> TRUE | J19: FY15(E) | K19: =O19 -> 106208000000 | N19: =N18+M19 -> 106208000000 | O19: =IF(N19>N18,N18,N19) -> 106208000000
B39: 매출유형별 사업부별 매출
B40: 백만원 | D40: 2012년 | E40: 2013년 | F40: 2014년 | G40: 2015년
D41: 12개월 | E41: 12개월 | F41: 12개월 | G41: 9개월
B42: 제품 | C42: CMO신약 | D42: 16330000000 | E42: 43185000000 | F42: 53845000000 | G42: 56101000000
C43: 정밀화학 | D43: 33388000000 | E43: 7242000000 | F43: 10784000000 | G43: 8857000000
C44: 제네릭API | D44: 10176000000 | E44: 9445000000 | F44: 11504000000 | G44: 8529000000
C45: 바이오사업 | D45: 5602000000 | E45: 4400000000 | F45: 5449000000 | G45: 6169000000
C46: 소계 | D46: 65496000000 | E46: 64272000000 | F46: 81582000000 | G46: 79656000000
B47: 상품 | C47: 정밀화학 | D47: 7702000000 | E47: 7831000000 | F47: 13445000000 | G47: 12727000000
C48: 제네릭API | D48: 9786000000 | E48: 12153000000 | F48: 1513000000 | G48: 1569000000
C49: 소계 | D49: 17488000000 | E49: 19984000000 | F49: 14958000000 | G49: 14296000000
C50: 총계 | D50: 82984000000 | E50: 84256000000 | F50: 96540000000 | G50: 93952000000

Sheet 사업부별 상품별 bridge 
C4: 매출액 | D4: 2012년 | E4: 2013년 | F4: 2014년 | G4: 2015년 12개월 환산 | H4: 2015년 3분기 | J4: FY12 | K4: =D7 -> 17488000000 | M4: =K4 -> 17488000000 | N4: =K4 -> 17488000000
C5: 정밀화학 | D5: 7702000000 | E5: 7831000000 | F5: 13445000000 | G5: =H5/9*12 -> 1.6969333e+10 | H5: 12727000000 | I5: =G5-F5 -> 3.5243333e+09 | J5: 정밀화학 | K5: =O5 -> 17488000000 | L5: =ABS(M5) -> 129000000 | M5: =D14 -> 129000000 | N5: =N4+M5 -> 17617000000 | O5: =IF(N5>N4,N4,N5) -> 17488000000
C6: 제네릭API | D6: 9786000000 | E6: 12153000000 | F6: 1513000000 | G6: =H6/9*12 -> 2092000000 | H6: 1569000000 | I6: =G6-F6 -> 579000000 | J6: 제네릭API | K6: =O6 -> 17617000000 | L6: =ABS(M6) -> 2367000000 | M6: =D15 -> 2367000000 | N6: =N5+M6 -> 19984000000 | O6: =IF(N6>N5,N5,N6) -> 17617000000
C7: 합계 | D7: =SUM(D5:D6) -> 17488000000 | E7: =SUM(E5:E6) -> 19984000000 | F7: =SUM(F5:F6) -> 14958000000 | G7: =SUM(G5:G6) -> 1.9061333e+10 | H7: =SUM(H5:H6) -> 14296000000 | I7: =G7-F7 -> 4.1033333e+09 | J7: FY13 | K7: =O7 -> 19984000000 | N7: =N6+M7 -> 19984000000 | O7: =IF(N7>N6,N6,N7) -> 19984000000
C8: Note: 2015년의 경우, 3분기 실적을 단순 연환산 함. | J8: 정밀화학 | K8: =O8 -> 19984000000 | L8: =ABS(M8) -> 5614000000 | M8: =E14 -> 5614000000 | N8: =N7+M8 -> 25598000000 | O8: =IF(N8>N7,N7,N8) -> 19984000000
J9: 제네릭API | K9: =O9 -> 14958000000 | L9: =ABS(M9) -> 10640000000 | M9: =E15 -> -10640000000 | N9: =N8+M9 -> 14958000000 | O9: =IF(N9>N8,N8,N9) -> 14958000000
J10: FY14 | K10: =O10 -> 14958000000 | N10: =N9+M10 -> 14958000000 | O10: =IF(N10>N9,N9,N10) -> 14958000000
J11: 정밀화학 | K11: =O11 -> 14958000000 | L11: =ABS(M11) -> 3.5243333e+09 | M11: =F14 -> 3.5243333e+09 | N11: =N10+M11 -> 1.8482333e+10 | O11: =IF(N11>N10,N10,N11) -> 14958000000
J12: 제네릭API | K12: =O12 -> 1.8482333e+10 | L12: =ABS(M12) -> 579000000 | M12: =F15 -> 579000000 | N12: =N11+M12 -> 1.9061333e+10 | O12: =IF(N12>N11,N11,N12) -> 1.8482333e+10
C13: 연도별 변동 | D13: 2013년 | E13: 2014년 | F13: 2015년 | J13: FY15(E) | K13: =O13 -> 1.9061333e+10 | N13: =N12+M13 -> 1.9061333e+10 | O13: =IF(N13>N12,N12,N13) -> 1.9061333e+10
C14: 정밀화학 | D14: =E5-D5 -> 129000000 | E14: =F5-E5 -> 5614000000 | F14: =G5-F5 -> 3.5243333e+09
C15: 제네릭API | D15: =E6-D6 -> 2367000000 | E15: =F6-E6 -> -10640000000 | F15: =G6-F6 -> 579000000
C16: 합계 | D16: =SUM(D14:D15) -> 2496000000 | E16: =SUM(E14:E15) -> -5026000000 | F16: =SUM(F14:F15) -> 4.1033333e+09
D17: =E7-D7=D16 -> TRUE | E17: =F7-E7=E16 -> TRUE | F17: =G7-F7=F16 -> FALSE
B39: 매출유형별 사업부별 매출
B40: 백만원 | D40: 2012년 | E40: 2013년 | F40: 2014년 | G40: 2015년
D41: 12개월 | E41: 12개월 | F41: 12개월 | G41: 9개월
B42: 상품 | C42: 정밀화학 | D42: 7702000000 | E42: 7831000000 | F42: 13445000000 | G42: 12727000000
C43: 제네릭API | D43: 9786000000 | E43: 12153000000 | F43: 1513000000 | G43: 1569000000
C44: 소계 | D44: 17488000000 | E44: 19984000000 | F44: 14958000000 | G44: 14296000000
C45: 총계 | D45: 82984000000 | E45: 84256000000 | F45: 96540000000 | G45: 93952000000

Sheet 매출
A1: 사업부문별 매출 | H1: 사업부문별 매출
C2: 2012년 | D2: 2013년 | E2: 2014년 | F2: 2015년 | G2: 2015년 9개월 | I2: 2012년 | J2: 2013년 | K2: 2014년 | L2: 2015년
A3: 백만원 | C3: 12개월 | D3: 12개월 | E3: 12개월 | F3: 9개월 | H3: 백만원 | I3: 12개월 | J3: 12개월 | K3: 12개월 | L3: 9개월
A4: CMO신약 | B4: 제품 | C4: 16330000000 | D4: 43185000000 | E4: 53845000000 | F4: 56101000000 | G4: 용역매출 일부 있음 | H4: 제품
A5: 정밀화학 | B5: 제품 | C5: 33388000000 | D5: 7242000000 | E5: 10784000000 | F5: 8857000000 | G5: 13년 소발디 판매시작으로 인해 매출증가. 16년 중 3~4년 장기계약 체결 예정. | H5: CMO신약 | I5: 16330000000 | J5: 43185000000 | K5: 53845000000 | L5: 56101000000
B6: 상품 | C6: 7702000000 | D6: 7831000000 | E6: 13445000000 | F6: 12727000000 | G6: 연구개발을 통해 최근 신제품 개발 -> 마진율 개선될 것 | H6: 정밀화학 | I6: 33388000000 | J6: 7242000000 | K6: 10784000000 | L6: 8857000000
B7: 소계 | C7: =SUM(C5:C6) -> 41090000000 | D7: =SUM(D5:D6) -> 15073000000 | E7: =SUM(E5:E6) -> 24229000000 | F7: =SUM(F5:F6) -> 21584000000 | G7: 13년 매출액 261억 감소: 외주가공 대상거래 중단(100억), AIDS치료제 중간체 매출중단(97억) | H7: 제네릭API | I7: 10176000000 | J7: 9445000000 | K7: 11504000000 | L7: 8529000000
A8: 제네릭API | B8: 제품 | C8: 10176000000 | D8: 9445000000 | E8: 11504000000 | F8: 8529000000 | G8: 전자제품부문 마진율 낮음 | H8: 바이오사업 | I8: 5602000000 | J8: 4400000000 | K8: 5449000000 | L8: 6169000000
B9: 상품 | C9: 9786000000 | D9: 12153000000 | E9: 1513000000 | F9: 1569000000 | H9: 제품 매출총이익% | I9: =[9]거래처별매출!C16 -> 0.22734224 | J9: =[9]거래처별매출!D16 -> 0.25679601 | K9: =[9]거래처별매출!E16 -> 0.23088555 | L9: =[9]거래처별매출!G16 -> 0.430192
B10: 소계 | C10: =SUM(C8:C9) -> 19962000000 | D10: =SUM(D8:D9) -> 21598000000 | E10: =SUM(E8:E9) -> 13017000000 | F10: =SUM(F8:F9) -> 10098000000 | H10: 제품 소계 | I10: =SUM(I5:I8) -> 65496000000 | J10: =SUM(J5:J8) -> 64272000000 | K10: =SUM(K5:K8) -> 81582000000 | L10: =SUM(L5:L8) -> 79656000000
A11: 바이오사업 | B11: 제품 | C11: 5602000000 | D11: 4400000000 | E11: 5449000000 | F11: 6169000000 | G11: 14년 동아관련 동아홀딩스 감사 권고사항으로 인해 상품판매 지양(체질개선), 동아의존도 낮추려는 노력 | H11: 상품
A12: 매출 총계 | C12: =SUM(C15,C16) -> 82984000000 | D12: =SUM(D15,D16) -> 84256000000 | E12: =SUM(E15,E16) -> 96540000000 | F12: =SUM(F15,F16) -> 93952000000 | G12: 올리오 business/올해부터 증가할 예정(100억 규모)/용역매출 주요 발생 사업부문 | H12: 정밀화학 | I12: 7702000000 | J12: 7831000000 | K12: 13445000000 | L12: 12727000000
H13: 제네릭API | I13: 9786000000 | J13: 12153000000 | K13: 1513000000 | L13: 1569000000
C14: 2012년 | D14: 2013년 | E14: 2014년 | F14: 2015년 9개월 | H14: 상품 매출총이익% | I14: =[9]거래처별매출!C17 -> 0.20240879 | J14: =[9]거래처별매출!D17 -> 0.22818068 | K14: =[9]거래처별매출!E17 -> 0.11083298 | L14: =[9]거래처별매출!G17 -> 0.10693507
B15: 제품 | C15: =SUM(C4,C5,C8,C11) -> 65496000000 | D15: =SUM(D4,D5,D8,D11) -> 64272000000 | E15: =SUM(E4,E5,E8,E11) -> 81582000000 | F15: =SUM(F4,F5,F8,F11) -> 79656000000 | H15: 상품 소계 | I15: =SUM(I12:I13) -> 17488000000 | J15: =SUM(J12:J13) -> 19984000000 | K15: =SUM(K12:K13) -> 14958000000 | L15: =SUM(L12:L13) -> 14296000000
B16: 상품 | C16: =SUM(C6,C9) -> 17488000000 | D16: =SUM(D6,D9) -> 19984000000 | E16: =SUM(E6,E9) -> 14958000000 | F16: =SUM(F6,F9) -> 14296000000 | G16: 14년 영업이익률 감소: 정밀화학 상품 매출 mix 증가로 인해. | H16: CMO신약 | I16: =SUM(I5) -> 16330000000 | J16: =SUM(J5) -> 43185000000 | K16: =SUM(K5) -> 53845000000 | L16: =SUM(L5) -> 56101000000
A17: * 제품 마진율: CMO신약>바이오>>>제네릭API≥정밀화학 | H17: 정밀화학 | I17: =SUM(I6,I12) -> 41090000000 | J17: =SUM(J6,J12) -> 15073000000 | K17: =SUM(K6,K12) -> 24229000000 | L17: =SUM(L6,L12) -> 21584000000
B18: 제품 | C18: =C15/C$12 -> 0.78926058 | D18: =D15/D$12 -> 0.76281808 | E18: =E15/E$12 -> 0.84505904 | F18: =F15/F$12 -> 0.84783719 | H18: 제네릭API | I18: =SUM(I7,I13) -> 19962000000 | J18: =SUM(J7,J13) -> 21598000000 | K18: =SUM(K7,K13) -> 13017000000 | L18: =SUM(L7,L13) -> 10098000000
B19: 상품 | C19: =C16/C$12 -> 0.21073942 | D19: =D16/D$12 -> 0.23718192 | E19: =E16/E$12 -> 0.15494096 | F19: =F16/F$12 -> 0.15216281 | H19: 바이오사업 | I19: =SUM(I8) -> 5602000000 | J19: =SUM(J8) -> 4400000000 | K19: =SUM(K8) -> 5449000000 | L19: =SUM(L8) -> 6169000000
H20: 매출 총계 | I20: =SUM(I16:I19) -> 82984000000 | J20: =SUM(J16:J19) -> 84256000000 | K20: =SUM(K16:K19) -> 96540000000 | L20: =SUM(L16:L19) -> 93952000000
I21: =I20=I10+I15 -> TRUE | J21: =J20=J10+J15 -> TRUE | K21: =K20=K10+K15 -> TRUE | L21: =L20=L10+L15 -> TRUE
A25: 매출실적
B26: 2014년 | E26: 2015년
A27: 백만원 | B27: 목표 | C27: 실적 | D27: 달성률 | E27: 목표(년간) | F27: 실적(1~9월) | G27: 진도율
A28: CMO신약 | B28: 29845000000 | C28: 53846000000 | D28: =C28/B28 -> 1.8041883 | E28: 66951000000 | F28: 56101000000 | G28: =F28/E28 -> 0.83794118
A29: 정밀화학 | B29: 29148000000 | C29: 24229000000 | D29: =C29/B29 -> 0.83124057 | E29: 27807000000 | F29: 21584000000 | G29: =F29/E29 -> 0.77620743
A30: 제네릭API | B30: 25049000000 | C30: 13017000000 | D30: =C30/B30 -> 0.51966146 | E30: 11970000000 | F30: 10098000000 | G30: =F30/E30 -> 0.84360902
A31: 바이오사업 | B31: 9996000000 | C31: 5448000000 | D31: =C31/B31 -> 0.54501801 | E31: 8800000000 | F31: 6169000000 | G31: =F31/E31 -> 0.70102273
A32: 합계 | B32: =SUM(B28:B31) -> 94038000000 | C32: =SUM(C28:C31) -> 96540000000 | D32: =C32/B32 -> 1.0266063 | E32: =SUM(E28:E31) -> 115528000000 | F32: =SUM(F28:F31) -> 93952000000 | G32: =F32/E32 -> 0.81324008
A34: CMO신약 | C34: =C4/C$15 -> 0.2493282 | D34: =D4/D$15 -> 0.67191001 | E34: =E4/E$15 -> 0.66001079 | F34: =F4/F$15 -> 0.70429095
A35: 정밀화학 | C35: =C5/C$15 -> 0.50977159 | D35: =D5/D$15 -> 0.11267737 | E35: =E5/E$15 -> 0.13218602 | F35: =F5/F$15 -> 0.11119062
A36: 제네릭API | C36: =C8/C$15 -> 0.15536827 | D36: =D8/D$15 -> 0.14695357 | E36: =E8/E$15 -> 0.1410115 | F36: =F8/F$15 -> 0.10707291
A37: 바이오사업 | C37: =C11/C$15 -> 0.085531941 | D37: =D11/D$15 -> 0.068459049 | E37: =E11/E$15 -> 0.066791694 | F37: =F11/F$15 -> 0.077445516

Sheet 매출 (2)
B5: 연도별 사업부별 매출실적
B6: 백만원 | D6: 2012년 | E6: 2013년 | F6: 2014년 | G6: 2015년 | H6: =G13/9*12 -> 11372000000
D7: 12개월 | E7: 12개월 | F7: 12개월 | G7: 9개월
B8: CMO신약 | C8: 제품 | D8: 16330000000 | E8: 43185000000 | F8: 53845000000 | G8: 56101000000 | H8: 13년 소발디 판매시작으로 인해 매출증가. 16년 중 3~4년 장기계약 체결 예정.
C9: 소계 | D9: =SUM(D8:D8) -> 16330000000 | E9: =SUM(E8:E8) -> 43185000000 | F9: =SUM(F8:F8) -> 53845000000 | G9: =SUM(G8:G8) -> 56101000000
B10: 정밀화학 | C10: 제품 | D10: 33388000000 | E10: 7242000000 | F10: 10784000000 | G10: 8857000000 | H10: 13년 매출액 261억 감소: 외주가공 대상거래 중단(100억), AIDS치료제 중간체 매출중단(97억)
C11: 상품 | D11: 7702000000 | E11: 7831000000 | F11: 13445000000 | G11: 12727000000 | H11: 전자제품부문 마진율 낮음
C12: 소계 | D12: =SUM(D10:D11) -> 41090000000 | E12: =SUM(E10:E11) -> 15073000000 | F12: =SUM(F10:F11) -> 24229000000 | G12: =SUM(G10:G11) -> 21584000000 | H12: 연구개발을 통해 최근 신제품 개발 -> 마진율 개선될 것
B13: 제네릭API | C13: 제품 | D13: 10176000000 | E13: 9445000000 | F13: 11504000000 | G13: 8529000000
C14: 상품 | D14: 9786000000 | E14: 12153000000 | F14: 1513000000 | G14: 1569000000 | H14: 14년 동아관련 동아홀딩스 감사 권고사항으로 인해 상품판매 지양(체질개선), 동아의존도 낮추려는 노력
C15: 소계 | D15: =SUM(D13:D14) -> 19962000000 | E15: =SUM(E13:E14) -> 21598000000 | F15: =SUM(F13:F14) -> 13017000000 | G15: =SUM(G13:G14) -> 10098000000
B16: 바이오사업 | C16: 제품 | D16: 5602000000 | E16: 4400000000 | F16: 5449000000 | G16: 6169000000 | H16: 올리오 business/올해부터 증가할 예정(100억 규모)/용역매출 주요 발생 사업부문
C17: 소계 | D17: =SUM(D16:D16) -> 5602000000 | E17: =SUM(E16:E16) -> 4400000000 | F17: =SUM(F16:F16) -> 5449000000 | G17: =SUM(G16:G16) -> 6169000000
B18: 합계 | C18: 제품 | D18: =SUM(D8,D10,D13,D16) -> 65496000000 | E18: =SUM(E8,E10,E13,E16) -> 64272000000 | F18: =SUM(F8,F10,F13,F16) -> 81582000000 | G18: =SUM(G8,G10,G13,G16) -> 79656000000
C19: 상품 | D19: =D11+D14 -> 17488000000 | E19: =E11+E14 -> 19984000000 | F19: =F11+F14 -> 14958000000 | G19: =G11+G14 -> 14296000000
C20: 합계 | D20: =SUM(D9,D12,D15,D17) -> 82984000000 | E20: =SUM(E9,E12,E15,E17) -> 84256000000 | F20: =SUM(F9,F12,F15,F17) -> 96540000000 | G20: =SUM(G9,G12,G15,G17) -> 93952000000 | H20: 14년 영업이익률 감소: 정밀화학 상품 매출 mix 증가로 인해.
B21: * 제품 마진율 : CMO신약>바이오>>>제네릭≥정밀화학
D22: =D18-'[10]FS (2)'!C66 -> 254954416 | E22: =E18-'[10]FS (2)'!D66 -> 1009894828 | F22: =F18-'[10]FS (2)'!E66 -> 495041289 | G22: =G18-'[10]FS (2)'!$G$66 -> 1632645670
B25: 매출유형별 사업부별 매출
B26: 백만원 | D26: 2012년 | E26: 2013년 | F26: 2014년 | G26: 2015년
D27: 12개월 | E27: 12개월 | F27: 12개월 | G27: 9개월
B28: 제품 | C28: CMO신약 | D28: =D8 -> 16330000000 | E28: =E8 -> 43185000000 | F28: =F8 -> 53845000000 | G28: =G8 -> 56101000000
C29: 정밀화학 | D29: =D10 -> 33388000000 | E29: =E10 -> 7242000000 | F29: =F10 -> 10784000000 | G29: =G10 -> 8857000000
C30: 제네릭API | D30: =D13 -> 10176000000 | E30: =E13 -> 9445000000 | F30: =F13 -> 11504000000 | G30: =G13 -> 8529000000
C31: 바이오사업 | D31: =D16 -> 5602000000 | E31: =E16 -> 4400000000 | F31: =F16 -> 5449000000 | G31: =G16 -> 6169000000
C32: 소계 | D32: =SUM(D28:D31) -> 65496000000 | E32: =SUM(E28:E31) -> 64272000000 | F32: =SUM(F28:F31) -> 81582000000 | G32: =SUM(G28:G31) -> 79656000000
B33: 상품 | C33: 정밀화학 | D33: =D11 -> 7702000000 | E33: =E11 -> 7831000000 | F33: =F11 -> 13445000000 | G33: =G11 -> 12727000000
C34: 제네릭API | D34: =D14 -> 9786000000 | E34: =E14 -> 12153000000 | F34: =F14 -> 1513000000 | G34: =G14 -> 1569000000
C35: 소계 | D35: =SUM(D33:D34) -> 17488000000 | E35: =SUM(E33:E34) -> 19984000000 | F35: =SUM(F33:F34) -> 14958000000 | G35: =SUM(G33:G34) -> 14296000000
C36: 총계 | D36: =D32+D35 -> 82984000000 | E36: =E32+E35 -> 84256000000 | F36: =F32+F35 -> 96540000000 | G36: =G32+G35 -> 93952000000
D37: =D20=D36 -> TRUE | E37: =E20=E36 -> TRUE | F37: =F20=F36 -> TRUE | G37: =G20=G36 -> TRUE
C38: 제품매출총이익률 | D38: 0.22734224 | E38: 0.25679601 | F38: 0.23088555 | G38: 0.430192
C39: 상품매출총이익률 | D39: 0.20240879 | E39: 0.22818068 | F39: 0.11083298 | G39: 0.10693507
B59: 사업계획 대비 매출실적
C60: 2014년 | F60: 2015년
B61: 백만원 | C61: 목표 | D61: 실적 | E61: 달성률 | F61: 목표(년간) | G61: 실적(1~9월) | H61: 진도율
B62: CMO신약 | C62: 29845000000 | D62: 53846000000 | E62: =D62/C62 -> 1.8041883 | F62: 66951000000 | G62: 56101000000 | H62: =G62/F62 -> 0.83794118
B63: 정밀화학 | C63: 29148000000 | D63: 24229000000 | E63: =D63/C63 -> 0.83124057 | F63: 27807000000 | G63: 21584000000 | H63: =G63/F63 -> 0.77620743
B64: 제네릭API | C64: 25049000000 | D64: 13017000000 | E64: =D64/C64 -> 0.51966146 | F64: 11970000000 | G64: 10098000000 | H64: =G64/F64 -> 0.84360902
B65: 바이오사업 | C65: 9996000000 | D65: 5448000000 | E65: =D65/C65 -> 0.54501801 | F65: 8800000000 | G65: 6169000000 | H65: =G65/F65 -> 0.70102273
...

Sheet 거래처별매출
B1: 매출 및 매출총이익 overview | I1: 거래처 별 매출액
C2: 2012년 | D2: 2013년 | E2: 2014년 | F2: 2015년 | G2: 2015년 | J2: 2012년 | K2: 2013년 | L2: 2014년 | M2: 2015년
B3: 백만원 | C3: 12개월 | D3: 12개월 | E3: 12개월 | F3: 6개월 | G3: 9개월 | I3: 백만원 | J3: 12개월 | K3: 12개월 | L3: 12개월 | M3: 9개월
B4: 매출 | C4: 82984043707 | D4: 84255969467 | E4: 96540028908 | F4: 48218557257 | G4: 93951670844 | I4: A사 | J4: 16751913767 | K4: 42471974602 | L4: 52583599705 | M4: 55608043985 | N4: Gilead
B5: 제품 | C5: 65241045584 | D5: 63262105172 | E5: 81086958711 | F5: 38080592041 | G5: 78023354330 | I5: G사 | J5: 0 | K5: 3367084800 | L5: 10083391970 | M5: 7823384695 | N5: 동아에스티(?)
B6: 상품 | C6: 17487991613 | D6: 19993094965 | E6: 14957892027 | F6: 9866583016 | G6: 14951300913 | I6: F사 | J6: 0 | K6: 9614270318 | L6: 11330592868 | M6: 7662972256 | N6: 천보(?)
B7: 용역 | C7: 255006510 | D7: 1000769330 | E7: 495178170 | F7: 271382200 | G7: 977015601 | I7: C사 | J7: 13548314530 | K7: 0 | L7: 3596672500 | M7: 6662330026 | N7: BMSI
B8: 매출원가 | C8: 64357268801 | D8: 62447706236 | E8: 75665215911 | F8: 33096040762 | G8: 57810813933 | I8: D사 | J8: 4736407655 | K8: 4582642662 | L8: 4288449781 | M8: 4095519926 | N8: 천보정밀
B9: 제품 | C9: 50409000416 | D9: 47016649282 | E9: 62365151697 | F9: 24649270019 | G9: 44458331428 | I9: B사 | J9: 24342824967 | K9: 10017663535 | L9: 0 | M9: 0 | N9: 동아제약
B10: 상품 | C10: 13948268385 | D10: 15431056954 | E10: 13300064214 | F10: 8446770743 | G10: 13352482505 | I10: E사 | J10: 9726102910 | K10: 0 | L10: 0 | M10: 0 | N10: Novartis
B11: 매출총이익 | C11: 18626774906 | D11: 21808263231 | E11: 20874812997 | F11: 15122516495 | G11: 36140856911 | I11: 기타 | J11: 13878479878 | K11: 14202333550 | L11: 14657322084 | M11: 12099419956
B12: 제품 | C12: =C5-C9 -> 14832045168 | D12: =D5-D9 -> 16245455890 | E12: =E5-E9 -> 18721807014 | F12: =F5-F9 -> 13431322022 | G12: =G5-G9 -> 33565022902 | I12: 매출 총계 | J12: =SUM(J4:J11) -> 82984043707 | K12: =SUM(K4:K11) -> 84255969467 | L12: =SUM(L4:L11) -> 96540028908 | M12: =SUM(M4:M11) -> 93951670844
B13: 상품 | C13: =C6-C10 -> 3539723228 | D13: =D6-D10 -> 4562038011 | E13: =E6-E10 -> 1657827813 | F13: =F6-F10 -> 1419812273 | G13: =G6-G10 -> 1598818408 | I13: TOP 업체 매출% | J13: =SUM(J4:J10)/J12 -> 0.83275725 | K13: =SUM(K4:K10)/K12 -> 0.83143825 | L13: =SUM(L4:L10)/L12 -> 0.84817363 | M13: =SUM(M4:M10)/M12 -> 0.87121655
B14: 용역 | C14: =C7 -> 255006510 | D14: =D7 -> 1000769330 | E14: =E7 -> 495178170 | F14: =F7 -> 271382200 | G14: =G7 -> 977015601 | I14: 연도별 고객 수 | J14: 115 | K14: 125 | L14: 129 | M14: 93
B15: 매출총이익% | C15: =C11/C4 -> 0.22446213 | D15: =D11/D4 -> 0.25883345 | E15: =E11/E4 -> 0.21622961 | F15: =F11/F4 -> 0.31362441 | G15: =G11/G4 -> 0.38467498 | J15: =J11/(J14-7) -> 1.2850444e+08 | K15: =K11/(K14-7) -> 1.2035876e+08 | L15: =L11/(L14-7) -> 1.2014198e+08 | M15: =M11/(M14-7) -> 1.4069093e+08
B16: 제품% | C16: =C12/C5 -> 0.22734224 | D16: =D12/D5 -> 0.25679601 | E16: =E12/E5 -> 0.23088555 | F16: =F12/F5 -> 0.3527078 | G16: =G12/G5 -> 0.430192
B17: 상품% | C17: =C13/C6 -> 0.20240879 | D17: =D13/D6 -> 0.22818068 | E17: =E13/E6 -> 0.11083298 | F17: =F13/F6 -> 0.14390111 | G17: =G13/G6 -> 0.10693507
C19: =SUM(C5:C7)=C4 -> TRUE | D19: =SUM(D5:D7)=D4 -> TRUE | E19: =SUM(E5:E7)=E4 -> TRUE | F19: =SUM(F5:F7)=F4 -> TRUE | G19: =SUM(G5:G7)=G4 -> TRUE
C20: =SUM(C9:C10)=C8 -> TRUE | D20: =SUM(D9:D10)=D8 -> TRUE | E20: =SUM(E9:E10)=E8 -> TRUE | F20: =SUM(F9:F10)=F8 -> TRUE | G20: =SUM(G9:G10)=G8 -> TRUE
C21: =SUM(C12:C14)=C11 -> TRUE | D21: =SUM(D12:D14)=D11 -> TRUE | E21: =SUM(E12:E14)=E11 -> TRUE | F21: =SUM(F12:F14)=F11 -> TRUE | G21: =SUM(G12:G14)=G11 -> TRUE
C22: =C11=C4-C8 -> TRUE | D22: =D11=D4-D8 -> TRUE | E22: =E11=E4-E8 -> TRUE | F22: =F11=F4-F8 -> TRUE | G22: =G11=G4-G8 -> TRUE
B24: 제품 | C24: =SUM(C29:C30) -> 65241045584 | D24: =SUM(D29:D30) -> 63262105172 | E24: =SUM(E29:E30) -> 81086958711 | F24: =SUM(F29:F30) -> 38080592041 | G24: =C24/C$27 -> 0.78618783 | H24: =D24/D$27 -> 0.75083232 | I24: =E24/E$27 -> 0.83993096 | J24: =F24/F$27 -> 0.78974972
B25: 상품 | C25: =SUM(C31,C33) -> 17487991613 | D25: =SUM(D31,D33) -> 19993094965 | E25: =SUM(E31,E33) -> 14957892027 | F25: =SUM(F31,F33) -> 9866583016 | G25: =C25/C$27 -> 0.21073921 | H25: =D25/D$27 -> 0.23728995 | I25: =E25/E$27 -> 0.15493979 | J25: =F25/F$27 -> 0.20462211
B26: 용역 | C26: =SUM(C34:C35) -> 255006510 | D26: =SUM(D34:D35) -> 1000769330 | E26: =SUM(E34:E35) -> 495178170 | F26: =SUM(F34:F35) -> 271382200 | G26: =C26/C$27 -> 0.0030729583 | H26: =D26/D$27 -> 0.011877726 | I26: =E26/E$27 -> 0.0051292523 | J26: =F26/F$27 -> 0.0056281692
B27: 매출 합계 | C27: =SUM(C24,C25,C26) -> 82984043707 | D27: =SUM(D24,D25,D26) -> 84255969467 | E27: =SUM(E24,E25,E26) -> 96540028908 | F27: =SUM(F24,F25,F26) -> 48218557257 | G27: =C27/C$27 -> 1 | H27: =D27/D$27 -> 1 | I27: =E27/E$27 -> 1 | J27: =F27/F$27 -> 1
G28: 2012년 | H28: 2013년 | I28: 2014년 | J28: 2015년 6개월
B29: 제품 국내매출 | C29: 14901071103 | D29: 10140178471 | E29: 16901872652 | F29: 6693735313 | G29: =C29/C$27 -> 0.1795655 | H29: =D29/D$27 -> 0.12034967 | I29: =E29/E$27 -> 0.17507632 | J29: =F29/F$27 -> 0.13882073
B30: 제품 수출 | C30: 50339974481 | D30: 53121926701 | E30: 64185086059 | F30: 31386856728 | G30: =C30/C$27 -> 0.60662234 | H30: =D30/D$27 -> 0.63048265 | I30: =E30/E$27 -> 0.66485464 | J30: =F30/F$27 -> 0.65092899
B31: 상품 국내매출 | C31: 17389816908 | D31: 19746070600 | E31: 14431466993 | F31: 9718470033 | G31: =C31/C$27 -> 0.20955615 | H31: =D31/D$27 -> 0.23435812 | I31: =E31/E$27 -> 0.14948687 | J31: =F31/F$27 -> 0.20155041
B32: 상품수출 및 용역매출 | C32: =C33+C34+C35 -> 353181215 | D32: =D33+D34+D35 -> 1247793695 | E32: =E33+E34+E35 -> 1021603204 | F32: =F33+F34+F35 -> 419495183 | G32: =C32/C$27 -> 0.0042560136 | H32: =D32/D$27 -> 0.014809558 | I32: =E32/E$27 -> 0.010582172 | J32: =F32/F$27 -> 0.0086998701
B33: 상품-해외 | C33: 98174705 | D33: 247024365 | E33: 526425034 | F33: 148112983 | G33: =C33/C$27 -> 0.0011830552 | H33: =D33/D$27 -> 0.0029318322 | I33: =E33/E$27 -> 0.0054529198 | J33: =F33/F$27 -> 0.0030717008
B34: 용역-국내 | C34: 124169200 | D34: 722658330 | E34: 356710100 | F34: 38000000 | G34: =C34/C$27 -> 0.0014963021 | H34: =D34/D$27 -> 0.0085769392 | I34: =E34/E$27 -> 0.003694945 | J34: =F34/F$27 -> 0.00078807833
B35: 용역-해외 | C35: 130837310 | D35: 278111000 | E35: 138468070 | F35: 233382200 | G35: =C35/C$27 -> 0.0015766562 | H35: =D35/D$27 -> 0.0033007869 | I35: =E35/E$27 -> 0.0014343073 | J35: =F35/F$27 -> 0.0048400909
C36: =C27=C4 -> TRUE | D36: =D27=D4 -> TRUE | E36: =E27=E4 -> TRUE | F36: =F27=F4 -> TRUE
B37: 국내매출 | C37: =SUM(C29,C31,C34) -> 32415057211 | D37: =SUM(D29,D31,D34) -> 30608907401 | E37: =SUM(E29,E31,E34) -> 31690049745 | F37: =SUM(F29,F31,F34) -> 16450205346 | G37: =C37/C$27 -> 0.39061795 | H37: =D37/D$27 -> 0.36328473 | I37: =E37/E$27 -> 0.32825813 | J37: =F37/F$27 -> 0.34115922
B38: 수출 | C38: =SUM(C30,C33,C35) -> 50568986496 | D38: =SUM(D30,D33,D35) -> 53647062066 | E38: =SUM(E30,E33,E35) -> 64849979163 | F38: =SUM(F30,F33,F35) -> 31768351911 | G38: =C38/C$27 -> 0.60938205 | H38: =D38/D$27 -> 0.63671527 | I38: =E38/E$27 -> 0.67174187 | J38: =F38/F$27 -> 0.65884078

Sheet 거래처별 매출액
B3: 연도별 매출처 상위 TOP5 | M3: (단위 : 백만원) | O3: 고객별 매출
C4: 2012년 | F4: 2013년 | I4: 2014년 | L4: 2015년 | P4: 2012년 | Q4: 2013년 | R4: 2014년 | S4: 2015년
C5: 12개월 | D5: % | F5: 12개월 | G5: % | I5: 12개월 | J5: % | L5: 9개월 | M5: % | O5: 백만원 | P5: 12개월 | Q5: 12개월 | R5: 12개월 | S5: 9개월
B6: B사 | C6: 24342824967 | D6: =C6/C$12 -> 0.29334344 | E6: A사 | F6: 42471974602 | G6: =F6/F$12 -> 0.50408268 | H6: A사 | I6: 52583599705 | J6: =I6/I$12 -> 0.54468183 | K6: A사 | L6: 55608043985 | M6: =L6/L$12 -> 0.59187924 | O6: Top 5 매출 비중 | P6: =D13 -> 0.83275725 | Q6: =G13 -> 0.83143825 | R6: =J13 -> 0.84817363 | S6: =M13 -> 0.87121655
B7: A사 | C7: 16751913767 | D7: =C7/C$12 -> 0.20186909 | E7: B사 | F7: 10017663535 | G7: =F7/F$12 -> 0.11889559 | H7: F사 | I7: 11330592868 | J7: =I7/I$12 -> 0.11736679 | K7: G사 | L7: 7823384695 | M7: =L7/L$12 -> 0.083270309 | O7: 거래처 수 | P7: 115 | Q7: 125 | R7: 129 | S7: 93
B8: C사 | C8: 13548314530 | D8: =C8/C$12 -> 0.16326409 | E8: F사 | F8: 9614270318 | G8: =F8/F$12 -> 0.11410788 | H8: G사 | I8: 10083391970 | J8: =I8/I$12 -> 0.10444778 | K8: F사 | L8: 7662972256 | M8: =L8/L$12 -> 0.081562916 | O8: Non-Top 5 평균 매출 | P8: =C11/P10 -> 1.26168e+08 | Q8: =F11/Q10 -> 1.1835278e+08 | R8: =I11/R10 -> 1.1820421e+08 | S8: =L11/S10 -> 1.3749341e+08
B9: E사 | C9: 9726102910 | D9: =C9/C$12 -> 0.11720449 | E9: D사 | F9: 4582642662 | G9: =F9/F$12 -> 0.054389531 | H9: D사 | I9: 4288449781 | J9: =I9/I$12 -> 0.044421468 | K9: C사 | L9: 6662330026 | M9: =L9/L$12 -> 0.07091231
B10: D사 | C10: 4736407655 | D10: =C10/C$12 -> 0.057076125 | E10: G사 | F10: 3367084800 | G10: =F10/F$12 -> 0.039962567 | H10: C사 | I10: 3596672500 | J10: =I10/I$12 -> 0.037255764 | K10: D사 | L10: 4095519926 | M10: =L10/L$12 -> 0.043591773 | P10: =P7-5 -> 110 | Q10: =Q7-5 -> 120 | R10: =R7-5 -> 124 | S10: =S7-5 -> 88
B11: 기타 | C11: 13878479878 | D11: =C11/C$12 -> 0.16724275 | E11: 기타 | F11: 14202333550 | G11: =F11/F$12 -> 0.16856175 | H11: 기타 | I11: 14657322084 | J11: =I11/I$12 -> 0.15182637 | K11: 기타 | L11: 12099419956 | M11: =L11/L$12 -> 0.12878345
B12: 합계 | C12: =SUM(C6:C11) -> 82984043707 | D12: =C12/C$12 -> 1 | E12: 합계 | F12: =SUM(F6:F11) -> 84255969467 | G12: =F12/F$12 -> 1 | H12: 합계 | I12: =SUM(I6:I11) -> 96540028908 | J12: =I12/I$12 -> 1 | K12: 합계 | L12: =SUM(L6:L11) -> 93951670844 | M12: =L12/L$12 -> 1
B13: Top 5 | C13: =SUM(C6:C10) -> 69105563829 | D13: =SUM(D6:D10) -> 0.83275725 | E13: Top 5 | F13: =SUM(F6:F10) -> 70053635917 | G13: =SUM(G6:G10) -> 0.83143825 | H13: Top 5 | I13: =SUM(I6:I10) -> 81882706824 | J13: =SUM(J6:J10) -> 0.84817363 | K13: Top 5 | L13: =SUM(L6:L10) -> 81852250888 | M13: =SUM(M6:M10) -> 0.87121655 | N13: =SUM(N6:N10) -> 0

Sheet 특수관계자
B3: 특수관계자 수익 및 비용
C4: 2012년 | D4: 2013년 | E4: 2014년
B5: 백만원 | C5: 12개월 | D5: 12개월 | E5: 12개월
B6: 수익
B7: 동아쏘시오홀딩스 | C7: =[11]Memo!J128*1000 -> 24342825000 | D7: =[11]Memo!G128*1000 -> 3608630000 | E7: =[11]Memo!D128*1000 -> 17200000
B8: 동아에스티 | C8: 0 | D8: =[11]Memo!G129*1000 -> 9266668000 | E8: =[11]Memo!D129*1000 -> 10100742000
B9: 동아제약 | C9: 0 | D9: =[11]Memo!G130*1000 -> 519750000 | E9: =[11]Memo!D130*1000 -> 668250000
B10: 동아오츠카 | C10: 0 | D10: 0 | E10: =[11]Memo!D132*1000 -> 845100000
B11: 합계 | C11: =SUM(C7:C10) -> 24342825000 | D11: =SUM(D7:D10) -> 13395048000 | E11: =SUM(E7:E10) -> 11631292000
B12: 총수익 | C12: 82984043707 | D12: 84255969467 | E12: 96540028908
B13: 관계사비중% | C13: =C11/C12 -> 0.29334344 | D13: =D11/D12 -> 0.1589804 | E13: =E11/E12 -> 0.12048155
B14: 비용
B15: 동아쏘시오홀딩스 | C15: =[11]Memo!K128*1000 -> 801000000 | D15: =[11]Memo!H128*1000 -> 528799000 | E15: =[11]Memo!E128*1000 -> 267195000
B16: 용마로지스 | C16: =[11]Memo!L131*1000 -> 669723000 | D16: =[11]Memo!H131*1000 -> 275301000 | E16: =[11]Memo!E131*1000 -> 324362000
B17: DA인포메이션 | C17: =[11]Memo!L133*1000 -> 94197000 | D17: =[11]Memo!H133*1000 -> 99747000 | E17: =[11]Memo!E133*1000 -> 117492000
B18: 기타 | C18: =[11]Memo!L132*1000+[11]Memo!L134*1000 -> 30502000 | D18: =[11]Memo!H132*1000 -> 1386000 | E18: =[11]Memo!E132*1000 -> 2700000
B19: 합계 | C19: =SUM(C15:C18) -> 1595422000 | D19: =SUM(D15:D18) -> 905233000 | E19: =SUM(E15:E18) -> 711749000
B22: 특수관계자간 자산취득 현황
C23: 2012년 | D23: 2013년 | E23: 2014년
B24: 백만원 | C24: 12개월 | D24: 12개월 | E24: 12개월
B25: 자산취득
B26: 철근종합건설 | C26: 0 | D26: 0 | E26: =[11]Memo!F134*1000 -> 19845500000
B27: 기타 | C27: =[11]Memo!M135*1000 -> 63962000 | D27: =[11]Memo!I135*1000 -> 56534000 | E27: =[11]Memo!F133*1000 -> 188175000
B28: 합계 | C28: =SUM(C26:C27) -> 63962000 | D28: =SUM(D26:D27) -> 56534000 | E28: =SUM(E26:E27) -> 20033675000
B31: 특수관계자간 자산 및 부채 현황
C32: 2012년 | D32: 2013년 | E32: 2014년
B33: 백만원 | C33: 12월31일 | D33: 12월31일 | E33: 12월31일
B34: 매출채권, 미수금
B35: 동아쏘시오홀딩스 | C35: =[11]Memo!D173*1000 -> 1499836000 | D35: =[11]Memo!D162*1000 -> 4730000 | E35: =[11]Memo!D150*1000 -> 9460000
B36: 동아에스티 | C36: 0 | D36: =[11]Memo!D163*1000+[11]Memo!E163*1000 -> 1342295000 | E36: =[11]Memo!D151*1000 -> 2557482000
B37: 동아제약 | C37: 0 | D37: =[11]Memo!D164*1000 -> 81675000 | E37: =[11]Memo!D152*1000 -> 130680000
B38: 동아오츠카 | C38: 0 | D38: 0 | E38: =[11]Memo!D154*1000 -> 210870000
B39: 합계 | C39: =SUM(C35:C38) -> 1499836000 | D39: =SUM(D35:D38) -> 1428700000 | E39: =SUM(E35:E38) -> 2908492000
B40: 매입채무, 미지급금, 미지급비용
B41: 동아쏘시오홀딩스 | C41: =[11]Memo!F173*1999+[11]Memo!H173*1000 -> 150825470 | D41: =[11]Memo!G162*1000 -> 389831000 | E41: =[11]Memo!G150*1000 -> 261000000
B42: 용마로지스 | C42: =[11]Memo!G174*1000 -> 104711000 | D42: =[11]Memo!F165*1000 -> 13509000 | E42: =[11]Memo!F153*1000 -> 41757000
B43: 동아오츠카 | C43: 0 | D43: 0 | E43: 0
B44: DA인포메이션 | C44: =[11]Memo!G176*1000 -> 8240000 | D44: =[11]Memo!F167*1000 -> 9144000 | E44: =[11]Memo!F155*1000 -> 12460000
B45: 철근종합건설 | C45: 0 | D45: 0 | E45: =[11]Memo!F156*1000 -> 1495890000
B46: 합계 | C46: =SUM(C41:C45) -> 263776470 | D46: =SUM(D41:D45) -> 412484000 | E46: =SUM(E41:E45) -> 1811107000
...

Sheet 원가
A1: 제품매출원가 overview
B2: 2012년 | C2: 2013년 | D2: 2014년 | E2: 2015년 | F2: 2012년 | G2: 2013년 | H2: 2014년 | I2: 2015년
A3: 백만원 | B3: 12개월 | C3: 12개월 | D3: 12개월 | E3: 9개월 | F3: % | G3: % | H3: % | I3: %
A4: 원재료비 | B4: =SUM(B5:B9) -> 33844971316 | C4: =SUM(C5:C9) -> 28067696102 | D4: =SUM(D5:D9) -> 45568692488 | E4: =SUM(E5:E9) -> 34616135308 | F4: =B4/B$38 -> 0.51876807 | G4: =C4/C$38 -> 0.44367313 | H4: =D4/D$38 -> 0.56197314 | I4: =E4/E$38 -> 0.44366377
A5: 당기원재료매입액 | B5: 33524692603 | C5: 28732875811 | D5: 47818223916 | E5: 39752554912
A6: 타계정대체입 | B6: 14296584 | C6: 97284955 | D6: 198934783 | E6: 103424415
A7: 타계정대체출 | B7: -2334022461 | C7: -623329560 | D7: -1443725101 | E7: -1613291399
A8: 기초원재료재고액 | B8: 9049664732 | C8: 6409660142 | D8: 6548795246 | E8: 7553536356
A9: 기말원재료재고액 | B9: -6409660142 | C9: -6548795246 | D9: -7553536356 | E9: -11180088976
A10: 노무비 | B10: 7448392707 | C10: 8746928996 | D10: 9584246660 | E10: 9396812422 | F10: =B10/B$38 -> 0.11416728 | G10: =C10/C$38 -> 0.13826491 | H10: =D10/D$38 -> 0.11819714 | I10: =E10/E$38 -> 0.12043589
A11: 제조경비 | B11: 13107564054 | C11: 10983573691 | D11: 10868649490 | E11: 14133568974 | F11: =B11/B$38 -> 0.20090978 | G11: =C11/C$38 -> 0.17362011 | H11: =D11/D$38 -> 0.13403696 | I11: =E11/E$38 -> 0.18114536
A12: 감가상각비 | B12: 3162616157 | C12: 3564085816 | D12: 3743001643 | E12: 4097589679
A13: 소모품비 | B13: 1449306666 | C13: 1565168046 | D13: 1638121434 | E13: 3603915206
A14: 전력비 | B14: 1065651671 | C14: 1160014159 | D14: 1235024388 | E14: 1488668459
A15: 폐기물처리비 | B15: 586522986 | C15: 479639429 | D15: 595641842 | E15: 1002589193
A16: 기타제조경비 | B16: 6843466574 | C16: 4214666241 | D16: 3656860183 | E16: 3940806437
A17: 당기총제조비용 | B17: =B4+B10+B11 -> 54400928077 | C17: =C4+C10+C11 -> 47798198789 | D17: =D4+D10+D11 -> 66021588638 | E17: =E4+E10+E11 -> 58146516704 | F17: =B17/B$38 -> 0.83384513 | G17: =C17/C$38 -> 0.75555814 | H17: =D17/D$38 -> 0.81420724 | I17: =E17/E$38 -> 0.74524503
A18: 당기반제품제조원가 | B18: -21959235397 | C18: -41732621383 | D18: -34199276690 | E18: -60709048341 | F18: =B18/B$38 -> -0.3365862 | G18: =C18/C$38 -> -0.65967804 | H18: =D18/D$38 -> -0.42176051 | I18: =E18/E$38 -> -0.77808816
A19: 반제품 대체 | B19: =B20+B21+B22 -> 37005346021 | C19: =C20+C21+C22 -> 65230442633 | D19: =D20+D21+D22 -> 66658812839 | E19: =E20+E21+E22 -> 101472770474 | F19: =B19/B$38 -> 0.56720958 | G19: =C19/C$38 -> 1.031114 | H19: =D19/D$38 -> 0.82206577 | I19: =E19/E$38 -> 1.3005436
A20: 타계정에서대체 | B20: 36568268181 | C20: 59705530172 | D20: 60096233197 | E20: 100850686725 | F20: =B20/B$38 -> 0.56051015 | G20: =C20/C$38 -> 0.94378032 | H20: =D20/D$38 -> 0.74113315 | I20: =E20/E$38 -> 1.2925705
A21: 반제품에서 제품전환 | B21: 3189643360 | C21: 5619028311 | D21: 6316501594 | E21: 885529860
A22: 반제품평가손실증감 | B22: -2752565520 | C22: -94115850 | D22: 246078048 | E22: -263446111
A23: 타계정으로대체 | B23: -139714140 | C23: 0 | D23: -167418987 | E23: -11665234
A24: 재공품변동 | B24: =B25+B26 -> 555986188 | C24: =C25+C26 -> -62012933 | D24: =D25+D26 -> -2285065830 | E24: =E25+E26 -> 1377388872
A25: 기초재공품대체 | B25: 779466978 | C25: 223480790 | D25: 285493723 | E25: 2570559553
A26: 기말재공품재고액 | B26: -223480790 | C26: -285493723 | D26: -2570559553 | E26: -1193170681
A27: 당기제품제조원가 | B27: =SUM(B17,B18,B19,B23,B24) -> 69863310749 | C27: =SUM(C17,C18,C19,C23,C24) -> 71234007106 | D27: =SUM(D17,D18,D19,D23,D24) -> 96028639970 | E27: =SUM(E17,E18,E19,E23,E24) -> 100275962475 | F27: =B27/B$38 -> 1.070849 | G27: =C27/C$38 -> 1.1260139 | H27: =D27/D$38 -> 1.1842674 | I27: =E27/E$38 -> 1.2852045
A28: 타계정으로대체 | B28: -16336561683 | C28: -28178553410 | D28: -25556239247 | E28: -45600319574 | F28: =B28/B$38 -> -0.25040312 | G28: =C28/C$38 -> -0.44542548 | H28: =D28/D$38 -> -0.31517077 | I28: =E28/E$38 -> -0.58444449
A29: 제품재고변동/관세환급 | B29: =B30+B31+B32 -> -3117748650 | C29: =C30+C31+C32 -> 3961195586 | D29: =D30+D31+D32 -> -8107249026 | E29: =E30+E31+E32 -> -10217311473
A30: 기초제품재고액 | B30: 15130089007 | C30: 17062841238 | D30: 12312261561 | E30: 18677804682 | F30: =B30/B$38 -> 0.23191058 | G30: =C30/C$38 -> 0.26971662 | H30: =D30/D$38 -> 0.15184022 | I30: =E30/E$38 -> 0.23938736
A31: 기말제품재고액 | B31: -17062841238 | C31: -12312261561 | D31: -18677804682 | E31: -27028610081 | F31: =B31/B$38 -> -0.26153537 | G31: =C31/C$38 -> -0.19462301 | H31: =D31/D$38 -> -0.23034289 | I31: =E31/E$38 -> -0.34641692
A32: 관세환급 | B32: -1184996419 | C32: -789384091 | D32: -1741705905 | E32: -1866506074 | F32: =B32/B$38 -> -0.018163357 | G32: =C32/C$38 -> -0.012477993 | H32: =D32/D$38 -> -0.021479482 | I32: =E32/E$38 -> -0.023922402
A33: 제품매출원가 | B33: =SUM(B27,B28,B29) -> 50409000416 | C33: =SUM(C27,C28,C29) -> 47016649282 | D33: =SUM(D27,D28,D29) -> 62365151697 | E33: =SUM(E27,E28,E29) -> 44458331428 | F33: =B33/B$38 -> 0.77265776 | G33: =C33/C$38 -> 0.74320399 | H33: =D33/D$38 -> 0.76911445 | I33: =E33/E$38 -> 0.569808
A34: 제품매출원가% | B34: =B33/B$38 -> 0.77265776 | C34: =C33/C$38 -> 0.74320399 | D34: =D33/D$38 -> 0.76911445 | E34: =E33/E$38 -> 0.569808
A35: 조정후 제품매출원가% | B35: =B37/B38 -> 0.78453779 | C35: =C37/C38 -> 0.71389402 | D35: =D37/D38 -> 0.80316201 | E35: =E37/E38 -> 0.55012106
A36: 재고 평가손익 조정 | B36: =-재고!E27 -> 775065000 | C36: =-재고!F27 -> -1854211000 | D36: =-재고!G27 -> 2760813000 | E36: =-재고!I27 -> -1536041244
A37: 조정후 제품매출원가 | B37: =B33+B36 -> 51184065416 | C37: =C33+C36 -> 45162438282 | D37: =D33+D36 -> 65125964697 | E37: =E33+E36 -> 42922290184
A38: 제품매출 | B38: 65241045584 | C38: 63262105172 | D38: 81086958711 | E38: 78023354330
B39: =B36/B33 -> 0.015375528 | C39: =C36/C33 -> -0.039437328 | D39: =D36/D33 -> 0.044268521 | E39: =E36/E33 -> -0.034550133
A40: 상품매출원가 overview
...

Sheet WC
B2: 운전자본
C3: 2010년 | D3: 2011년 | E3: 2012년 | F3: 2013년 | G3: 2014년 | H3: 2015년 | I3: 2015년
B4: 백만원, 일 | C4: 12개월 | D4: 12개월 | E4: 12개월 | F4: 12개월 | G4: 12개월 | H4: 9개월 | I4: 6개월
B5: 순운전자본
B6: 매출채권 | D6: =(D20+C20)/2 -> 8786664500 | E6: =(E20+D20)/2 -> 14086440500 | F6: =(F20+E20)/2 -> 17928738000 | G6: =(G20+F20)/2 -> 16798310000 | H6: =(H20+G20)/2 -> 20753312316 | I6: =(H20+G20)/2 -> 20753312316
B7: 재고자산 | D7: =(D21+C21)/2 -> 36010374500 | E7: =(E21+D21)/2 -> 37003998500 | F7: =(F21+E21)/2 -> 38423282000 | G7: =(G21+F21)/2 -> 41464048500 | H7: =(H21+G21)/2 -> 50702606725 | I7: =(H21+G21)/2 -> 50702606725
B8: 매입채무 | D8: =(D22+C22)/2 -> 1227268160 | E8: =(E22+D22)/2 -> 3499827490 | F8: =(F22+E22)/2 -> 5.4417391e+09 | G8: =(G22+F22)/2 -> 4.630157e+09 | H8: =(H22+G22)/2 -> 5509267641 | I8: =(I22+G22)/2 -> 4.6810437e+09
B9: 순운전자본 합계 | D9: =D6+D7-D8 -> 43569770840 | E9: =E6+E7-E8 -> 47590611510 | F9: =F6+F7-F8 -> 5.0910281e+10 | G9: =G6+G7-G8 -> 5.3632202e+10 | H9: =H6+H7-H8 -> 65946651400 | I9: =I6+I7-I8 -> 6.6774875e+10
B10: 순운전자본 변동 | E10: =E9-D9 -> 4020840670 | F10: =F9-E9 -> 3.3196694e+09 | G10: =G9-F9 -> 2721920588 | H10: =H9-G9 -> 1.231445e+10 | I10: =I9-G9 -> 13142673855
B11: 매출액% | D11: =D9/D24 -> 0.59541917 | E11: =E9/E24 -> 0.57349111 | F11: =F9/F24 -> 0.60423352 | G11: =G9/G24 -> 0.55554367 | H11: =H9/(H24/0.75) -> 0.52644076 | I11: =I9/(I24/0.5) -> 0.69241884
B12: 회전기일
B13: 매출채권 | E13: =E6/E24*365 -> 61.958306 | F13: =F6/F24*365 -> 77.667961 | G13: =G6/G24*365 -> 63.511304 | H13: =H6/(H24/0.75)*365 -> 60.469592 | I13: =I6/(I24/0.5)*365 -> 78.548171
B14: 재고자산 | E14: =E7/E25*365 -> 209.86688 | F14: =F7/F25*365 -> 224.57987 | G14: =G7/G25*365 -> 200.01764 | H14: =H7/(H25/0.75)*365 -> 240.0907 | I14: =I7/(I25/0.5)*365 -> 279.58709
B15: 매입채무 | E15: =E8/E25*365 -> 19.849149 | F15: =F8/F25*365 -> 31.806369 | G15: =G8/G25*365 -> 22.335326 | H15: =H8/(H25/0.75)*365 -> 26.087888 | I15: =I8/(I25/0.5)*365 -> 25.812467
B16: 매출채권/매출액 | E16: =E6/E24 -> 0.16974878 | F16: =F6/F24 -> 0.21278893 | G16: =G6/G24 -> 0.17400357 | H16: =H6/(H24/0.75) -> 0.16567012
B17: 재고자산/매출원가 | E17: =E7/E25 -> 0.57497776 | F17: =F7/F25 -> 0.61528732 | G17: =G7/G25 -> 0.54799353 | H17: =H7/(H25/0.75) -> 0.65778273
B18: 재고자산/매출액 | E18: =E7/E24 -> 0.44591703 | F18: =F7/F24 -> 0.45603038 | G18: =G7/G24 -> 0.4295011 | H18: =H7/H24 -> 0.5396669
B19: 운전자본 계정 기말잔액 | C19: 2010년 | D19: 2011년 | E19: 2012년 | F19: 2013년 | G19: 2014년 | H19: 2015년 9월 | I19: 2015년 6월
B20: 매출채권 | C20: =[9]매출채권!C17 -> 7245924000 | D20: =[9]매출채권!D17 -> 10327405000 | E20: =[9]매출채권!E17 -> 17845476000 | F20: =[9]매출채권!F17 -> 18012000000 | G20: =[9]매출채권!G17 -> 15584620000 | H20: =[9]매출채권!I17 -> 25922004632 | I20: =[9]매출채권!H17 -> 20113027625
B21: 재고자산 | C21: =[9]재고!C18 -> 34560239000 | D21: =[9]재고!D18 -> 37460510000 | E21: =[9]재고!E18 -> 36547487000 | F21: =[9]재고!F18 -> 40299077000 | G21: =[9]재고!G18 -> 42629020000 | H21: =[9]재고!I18 -> 58776193450 | I21: =[9]재고!H18 -> 52939955244
B22: 매입채무 | C22: 1278068160 | D22: 1176468160 | E22: =[9]overview!H23 -> 5823186820 | F22: =[9]overview!I23 -> 5060291331 | G22: =[9]overview!J23 -> 4200022644 | H22: 6818512638 | I22: 5162064703
B23: 합계 | C23: =C20+C21-C22 -> 40528094840 | D23: =D20+D21-D22 -> 46611446840 | E23: =E20+E21-E22 -> 48569776180 | F23: =F20+F21-F22 -> 53250785669 | G23: =G20+G21-G22 -> 54013617356 | H23: =I20+I21-H22 -> 66234470231 | I23: =H20+H21-I22 -> 79536133379
B24: 매출 | C24: 28920008506 | D24: 73174955363 | E24: =[9]거래처별매출!C4 -> 82984043707 | F24: =[9]거래처별매출!D4 -> 84255969467 | G24: =[9]거래처별매출!E4 -> 96540028908 | H24: =[9]거래처별매출!G4 -> 93951670844 | I24: =[9]거래처별매출!F4 -> 48218557257
B25: 매출원가 | C25: 22284341534 | D25: 57235955038 | E25: =[9]거래처별매출!C8 -> 64357268801 | F25: =[9]거래처별매출!D8 -> 62447706236 | G25: =[9]거래처별매출!E8 -> 75665215911 | H25: =[9]거래처별매출!G8 -> 57810813933 | I25: =[9]거래처별매출!F8 -> 33096040762
B27: <for chart> | E27: 2012년 | F27: 2013년 | G27: 2014년 | H27: 2015년 9개월
B28: 매출채권 | E28: =E6 -> 14086440500 | F28: =F6 -> 17928738000 | G28: =G6 -> 16798310000 | H28: =H6 -> 20753312316
B29: 재고자산 | E29: =E7 -> 37003998500 | F29: =F7 -> 38423282000 | G29: =G7 -> 41464048500 | H29: =H7 -> 50702606725
B30: 매입채무 | E30: =-E8 -> -3499827490 | F30: =-F8 -> -5.4417391e+09 | G30: =-G8 -> -4.630157e+09 | H30: =-H8 -> -5509267641
B31: 순운전자본 | E31: =E9 -> 47590611510 | F31: =F9 -> 5.0910281e+10 | G31: =G9 -> 5.3632202e+10 | H31: =H9 -> 65946651400
B32: 매출액 대비 순운전자본% | E32: =E11 -> 0.57349111 | F32: =F11 -> 0.60423352 | G32: =G11 -> 0.55554367 | H32: =H11 -> 0.52644076

Sheet 인건비
B2: 인건비
C3: 2012년 | D3: 2013년 | E3: 2014년 | F3: 2015년
B4: 백만원 | C4: 12개월 | D4: 12개월 | E4: 12개월 | F4: 6개월
B5: 급여와 상여 | C5: =C6+C9 -> 10469071560 | D5: =D6+D9 -> 12838413737 | E5: =E6+E9 -> 13774282688 | F5: =F6+F9 -> 8135340740
B6: 임원 | C6: =SUM(C7:C8) -> 1238793000 | D6: =SUM(D7:D8) -> 1363931730 | E6: =SUM(E7:E8) -> 1433530540 | F6: =SUM(F7:F8) -> 736425030
B7: 급여 | C7: =[12]Memo!C234 -> 831715870 | D7: =[12]Memo!E234 -> 902689830 | E7: =[12]Memo!G234 -> 861549340 | F7: =[12]Memo!I234 -> 446613360
B8: 상여 | C8: =[12]Memo!C235 -> 407077130 | D8: =[12]Memo!E235 -> 461241900 | E8: =[12]Memo!G235 -> 571981200 | F8: =[12]Memo!I235 -> 289811670
B9: 직원 | C9: =SUM(C10:C11) -> 9230278560 | D9: =SUM(D10:D11) -> 11474482007 | E9: =SUM(E10:E11) -> 12340752148 | F9: =SUM(F10:F11) -> 7398915710
B10: 급여 | C10: =[12]Memo!D234 -> 6451296250 | D10: =[12]Memo!F234 -> 8164830637 | E10: =[12]Memo!H234 -> 8404223938 | F10: =[12]Memo!J234 -> 5048330550
B11: 상여 | C11: =[12]Memo!D235 -> 2778982310 | D11: =[12]Memo!F235 -> 3309651370 | E11: =[12]Memo!H235 -> 3936528210 | F11: =[12]Memo!J235 -> 2350585160
B12: 인건비 총액 | C12: =SUM(C14:C16) -> 12532198553 | D12: =SUM(D14:D16) -> 14938420894 | E12: =SUM(E14:E16) -> 16254238644 | F12: =SUM(F14:F16) -> 9387743467
B13: % of Growth | C13: n/a | D13: =[12]Memo!D242 -> 0.22631827 | E13: =[12]Memo!E242 -> 0.072895996 | F13: =[12]Memo!F242 -> 0.18123621
B14: 제조원가 | C14: =SUM([12]Memo!C273:C275) -> 8016667964 | D14: =SUM([12]Memo!D273:D275) -> 9412275181 | E14: =SUM([12]Memo!E273:E275) -> 10314422384 | F14: =SUM([12]Memo!F273:F275) -> 6302560589
B15: 판관비(연구개발비 외) | C15: =SUM([12]Memo!C263:C265) -> 1523768320 | D15: =SUM([12]Memo!D263:D265) -> 1717201804 | E15: =SUM([12]Memo!E263:E265) -> 1912536006 | F15: =SUM([12]Memo!F263:F265) -> 958874081
B16: 연구개발비 | C16: =SUM([12]Memo!C268:C270) -> 2991762269 | D16: =SUM([12]Memo!D268:D270) -> 3808943909 | E16: =SUM([12]Memo!E268:E270) -> 4027280254 | F16: =SUM([12]Memo!F268:F270) -> 2126308797
B18: 1인당 인건비
C19: 2012년 | D19: 2013년 | E19: 2014년 | F19: 2015년
B20: 백만원 | C20: 12개월 | D20: 12개월 | E20: 12개월 | F20: 6개월
B21: 인원 수(명) | C21: =SUM(C22:C24) -> 231 | D21: =SUM(D22:D24) -> 250 | E21: =SUM(E22:E24) -> 284 | F21: =SUM(F22:F24) -> 372
B22: 임원 | C22: =[12]Memo!D244 -> 10 | D22: =[12]Memo!E244 -> 10 | E22: =[12]Memo!F244 -> 10 | F22: =[12]Memo!G244 -> 10
B23: 생산/관리 직원 | C23: =[12]Memo!D245 -> 167 | D23: =[12]Memo!E245 -> 181 | E23: =[12]Memo!F245 -> 211 | F23: =[12]Memo!G245 -> 284
B24: 연구/개발 직원 | C24: =[12]Memo!D246 -> 54 | D24: =[12]Memo!E246 -> 59 | E24: =[12]Memo!F246 -> 63 | F24: =[12]Memo!G246 -> 78
B25: 1인당 급여와 상여 | C25: =[12]Memo!D250 -> 45320656 | D25: =[12]Memo!E250 -> 51353655 | E25: =[12]Memo!F250 -> 48500995 | F25: =[12]Memo!G250 -> 21869196
B26: % of Growth | C26: n/a | D26: =[12]Memo!C283 -> 0.10141097 | E26: =[12]Memo!D283 -> -0.042180645 | F26: =[12]Memo!E283 -> -0.11813932
B27: 임원 | C27: =[12]Memo!D248 -> 123879300 | D27: =[12]Memo!E248 -> 136393173 | E27: =[12]Memo!F248 -> 143353054 | F27: =[12]Memo!G248 -> 73642503
B28: 직원 | C28: =[12]Memo!D249 -> 41765966 | D28: =[12]Memo!E249 -> 47810342 | E28: =[12]Memo!F249 -> 45039241 | F28: =[12]Memo!G249 -> 20438994
B29: 1인당 인건비 | C29: =[12]Memo!C281 -> 54251942 | D29: =[12]Memo!D281 -> 59753684 | E29: =[12]Memo!E281 -> 57233235 | F29: =[12]Memo!F281 -> 25235870
B30: 생산/관리 인력 | C30: =[12]Memo!C279 -> 53900770 | D30: =[12]Memo!D279 -> 58269513 | E30: =[12]Memo!E279 -> 55325604 | F30: =[12]Memo!F279 -> 24698757
B31: 연구/개발 인력 | C31: =[12]Memo!C280 -> 55403005 | D31: =[12]Memo!D280 -> 64558371 | E31: =[12]Memo!E280 -> 63925083 | F31: =[12]Memo!F280 -> 27260369

Sheet 경상개발비,capex
B2: CAPEX
C3: 2012년 | D3: 2013년 | E3: 2014년 | F3: 2015년
B4: 백만원 | C4: 12개월 | D4: 12개월 | E4: 12개월 | F4: 6개월
B5: 유형자산 취득 관련 현금유출입
B6: 유형자산 취득 | C6: =[11]Memo!C201 -> 8091352253 | D6: =[11]Memo!D201 -> 3103034059 | E6: =[11]Memo!E201 -> 22907165786 | F6: =[11]Memo!C225 -> 15758544882
B7: 차입금 순차입 | C7: =[11]Memo!C205-[11]Memo!C210-[11]Memo!C211++[11]Memo!C206 -> -522054620 | D7: =[11]Memo!D205+[11]Memo!D206-[11]Memo!D210-[11]Memo!D211 -> -6999624424 | E7: =[11]Memo!E205+[11]Memo!E206-[11]Memo!E210-[11]Memo!E211 -> 20216679044 | F7: =[11]Memo!C217 -> 26700458142
B9: 경상연구개발비
C10: 2012년 | D10: 2013년 | E10: 2014년 | F10: 2015년
B11: 백만원 | C11: 12개월 | D11: 12개월 | E11: 12개월 | F11: 6개월
B12: 경상연구개발비 내역 | C12: =[11]Memo!C75 -> 5082642503 | D12: =[11]Memo!D75 -> 6663435159 | E12: =[11]Memo!E75 -> 6782147700 | F12: =[11]Memo!F75 -> 5134487133
B13: 인건비 | C13: =[11]Memo!$C$64+[11]Memo!$C$70 -> 2862802477 | D13: =[11]Memo!$D$64+[11]Memo!$D$70 -> 3654136353 | E13: =[11]Memo!$E$64+[11]Memo!$E$70 -> 3853269916 | F13: =[11]Memo!$F$64+[11]Memo!$F$70 -> 2018805796
B14: 시료,원재료,소모품비 | C14: =[11]Memo!$C$65+[11]Memo!$C$67+[11]Memo!$C$68 -> 1100222685 | D14: =[11]Memo!$D$65+[11]Memo!$D$67+[11]Memo!$D$68 -> 1452118996 | E14: =[11]Memo!$E$65+[11]Memo!$E$67+[11]Memo!$E$68 -> 1461914333 | F14: =[11]Memo!F65+[11]Memo!F67+[11]Memo!F68 -> 1529883684
B15: 감가상각비 | C15: =[11]Memo!$C$66 -> 622657870 | D15: =[11]Memo!$D$66 -> 586572150 | E15: =[11]Memo!$E$66 -> 521391007 | F15: =[11]Memo!F66 -> 233751376
B16: 위탁연구비 | C16: =[11]Memo!$C$69 -> 36346000 | D16: =[11]Memo!$D$69 -> 305408200 | E16: =[11]Memo!$E$69 -> 207246519 | F16: =[11]Memo!F69 -> 818521518
B17: 기타 | C17: =C12-C13-C14-C15-C16 -> 460613471 | D17: =D12-D13-D14-D15-D16 -> 665199460 | E17: =E12-E13-E14-E15-E16 -> 738325925 | F17: =F12-F13-F14-F15-F16 -> 533524759
B18: 구성비율
B19: 인건비% | C19: =C13/C12 -> 0.5632508 | D19: =D13/D12 -> 0.54838627 | E19: =E13/E12 -> 0.56814892 | F19: =F13/F12 -> 0.39318548
B20: 시료,원재료,소모품비% | C20: =C14/C12 -> 0.21646667 | D20: =D14/D12 -> 0.21792348 | E20: =E14/E12 -> 0.2155533 | F20: =F14/F12 -> 0.29796232
B21: 감가상각비% | C21: =C15/C12 -> 0.12250672 | D21: =D15/D12 -> 0.088028492 | E21: =E15/E12 -> 0.076876976 | F21: =F15/F12 -> 0.04552575
B22: 위탁연구비% | C22: =C16/C12 -> 0.0071510046 | D22: =D16/D12 -> 0.045833447 | E22: =E16/E12 -> 0.030557653 | F22: =F16/F12 -> 0.15941641
B23: 기타% | C23: =C17/C12 -> 0.090624802 | D23: =D17/D12 -> 0.099828308 | E23: =E17/E12 -> 0.10886314 | F23: =F17/F12 -> 0.10391004

Sheet Appendices >>>>>>

Sheet 사업계획대비매출실적
A1: 사업계획 대비 매출실적
B2: 2014년 | E2: 2015년
A3: 백만원 | B3: 목표 | C3: 실적 | D3: 달성률 | E3: 목표(년간) | F3: 실적(1~9월) | G3: 진도율
A4: CMO신약 | B4: 29845000000 | C4: 53846000000 | D4: =C4/B4 -> 1.8041883 | E4: 66951000000 | F4: 56101000000 | G4: =F4/E4 -> 0.83794118
A5: 정밀화학 | B5: 29148000000 | C5: 24229000000 | D5: =C5/B5 -> 0.83124057 | E5: 27807000000 | F5: 21584000000 | G5: =F5/E5 -> 0.77620743
A6: 제네릭API | B6: 25049000000 | C6: 13017000000 | D6: =C6/B6 -> 0.51966146 | E6: 11970000000 | F6: 10098000000 | G6: =F6/E6 -> 0.84360902
A7: 바이오사업 | B7: 9996000000 | C7: 5448000000 | D7: =C7/B7 -> 0.54501801 | E7: 8800000000 | F7: 6169000000 | G7: =F7/E7 -> 0.70102273
A8: 합계 | B8: =SUM(B4:B7) -> 94038000000 | C8: =SUM(C4:C7) -> 96540000000 | D8: =C8/B8 -> 1.0266063 | E8: =SUM(E4:E7) -> 115528000000 | F8: =SUM(F4:F7) -> 93952000000 | G8: =F8/E8 -> 0.81324008

Sheet 사업부문별매출
B1: 사업부문별 매출
C2: 2012년 | D2: 2013년 | E2: 2014년 | F2: 2015년
B3: 백만원 | C3: 12개월 | D3: 12개월 | E3: 12개월 | F3: 9개월
B4: 제품
B5: CMO신약 | C5: 16330000000 | D5: 43185000000 | E5: 53845000000 | F5: 56101000000
B6: 정밀화학 | C6: 33388000000 | D6: 7242000000 | E6: 10784000000 | F6: 8857000000
B7: 제네릭API | C7: 10176000000 | D7: 9445000000 | E7: 11504000000 | F7: 8529000000
B8: 바이오사업 | C8: 5602000000 | D8: 4400000000 | E8: 5449000000 | F8: 6169000000
B9: 제품 매출총이익% | C9: 0.22734224 | D9: 0.25679601 | E9: 0.23088555 | F9: 0.430192
B10: 제품 소계 | C10: 65496000000 | D10: 64272000000 | E10: 81582000000 | F10: 79656000000
B11: 상품
B12: 정밀화학 | C12: 7702000000 | D12: 7831000000 | E12: 13445000000 | F12: 12727000000
B13: 제네릭API | C13: 9786000000 | D13: 12153000000 | E13: 1513000000 | F13: 1569000000
B14: 상품 매출총이익% | C14: 0.20240879 | D14: 0.22818068 | E14: 0.11083298 | F14: 0.10693507
B15: 상품 소계 | C15: 17488000000 | D15: 19984000000 | E15: 14958000000 | F15: 14296000000
B16: CMO신약 | C16: 16330000000 | D16: 43185000000 | E16: 53845000000 | F16: 56101000000
B17: 정밀화학 | C17: 41090000000 | D17: 15073000000 | E17: 24229000000 | F17: 21584000000
B18: 제네릭API | C18: 19962000000 | D18: 21598000000 | E18: 13017000000 | F18: 10098000000
B19: 바이오사업 | C19: 5602000000 | D19: 4400000000 | E19: 5449000000 | F19: 6169000000
B20: 매출 총계 | C20: 82984000000 | D20: 84256000000 | E20: 96540000000 | F20: 93952000000

Sheet 제조원가
A1: 제조원가명세서
B2: 2012년 | C2: 2013년 | D2: 2014년 | E2: 2015년 | F2: 2012년 | G2: 2013년 | H2: 2014년 | I2: 2015년
A3: 백만원 | B3: 12개월 | C3: 12개월 | D3: 12개월 | E3: 9개월 | F3: % | G3: % | H3: % | I3: %
A4: 원재료비 | B4: =SUM(B5:B9) -> 33844971316 | C4: =SUM(C5:C9) -> 28067696102 | D4: =SUM(D5:D9) -> 45568692488 | E4: =SUM(E5:E9) -> 34616135308 | F4: =B4/B$38 -> 0.51876807 | G4: =C4/C$38 -> 0.44367313 | H4: =D4/D$38 -> 0.56197314 | I4: =E4/E$38 -> 0.44366377
A5: 당기원재료매입액 | B5: 33524692603 | C5: 28732875811 | D5: 47818223916 | E5: 39752554912
A6: 타계정대체입 | B6: 14296584 | C6: 97284955 | D6: 198934783 | E6: 103424415
A7: 타계정대체출 | B7: -2334022461 | C7: -623329560 | D7: -1443725101 | E7: -1613291399
A8: 기초원재료재고액 | B8: 9049664732 | C8: 6409660142 | D8: 6548795246 | E8: 7553536356
A9: 기말원재료재고액 | B9: -6409660142 | C9: -6548795246 | D9: -7553536356 | E9: -11180088976
A10: 노무비 | B10: 7448392707 | C10: 8746928996 | D10: 9584246660 | E10: 9396812422 | F10: =B10/B$38 -> 0.11416728 | G10: =C10/C$38 -> 0.13826491 | H10: =D10/D$38 -> 0.11819714 | I10: =E10/E$38 -> 0.12043589
A11: 제조경비 | B11: 13107564054 | C11: 10983573691 | D11: 10868649490 | E11: 14133568974 | F11: =B11/B$38 -> 0.20090978 | G11: =C11/C$38 -> 0.17362011 | H11: =D11/D$38 -> 0.13403696 | I11: =E11/E$38 -> 0.18114536
A12: 감가상각비 | B12: 3162616157 | C12: 3564085816 | D12: 3743001643 | E12: 4097589679
A13: 소모품비 | B13: 1449306666 | C13: 1565168046 | D13: 1638121434 | E13: 3603915206
A14: 전력비 | B14: 1065651671 | C14: 1160014159 | D14: 1235024388 | E14: 1488668459
A15: 폐기물처리비 | B15: 586522986 | C15: 479639429 | D15: 595641842 | E15: 1002589193
A16: 기타제조경비 | B16: 6843466574 | C16: 4214666241 | D16: 3656860183 | E16: 3940806437
A17: 당기총제조비용 | B17: =B4+B10+B11 -> 54400928077 | C17: =C4+C10+C11 -> 47798198789 | D17: =D4+D10+D11 -> 66021588638 | E17: =E4+E10+E11 -> 58146516704 | F17: =B17/B$38 -> 0.83384513 | G17: =C17/C$38 -> 0.75555814 | H17: =D17/D$38 -> 0.81420724 | I17: =E17/E$38 -> 0.74524503
A18: 당기반제품제조원가 | B18: -21959235397 | C18: -41732621383 | D18: -34199276690 | E18: -60709048341 | F18: =B18/B$38 -> -0.3365862 | G18: =C18/C$38 -> -0.65967804 | H18: =D18/D$38 -> -0.42176051 | I18: =E18/E$38 -> -0.77808816
A19: 반제품 대체 | B19: =B20+B21+B22 -> 37005346021 | C19: =C20+C21+C22 -> 65230442633 | D19: =D20+D21+D22 -> 66658812839 | E19: =E20+E21+E22 -> 101472770474 | F19: =B19/B$38 -> 0.56720958 | G19: =C19/C$38 -> 1.031114 | H19: =D19/D$38 -> 0.82206577 | I19: =E19/E$38 -> 1.3005436
A20: 타계정에서대체 | B20: 36568268181 | C20: 59705530172 | D20: 60096233197 | E20: 100850686725 | F20: =B20/B$38 -> 0.56051015 | G20: =C20/C$38 -> 0.94378032 | H20: =D20/D$38 -> 0.74113315 | I20: =E20/E$38 -> 1.2925705
A21: 반제품에서 제품전환 | B21: 3189643360 | C21: 5619028311 | D21: 6316501594 | E21: 885529860
A22: 반제품평가손실증감 | B22: -2752565520 | C22: -94115850 | D22: 246078048 | E22: -263446111
A23: 타계정으로대체 | B23: -139714140 | C23: 0 | D23: -167418987 | E23: -11665234
A24: 재공품변동 | B24: =B25+B26 -> 555986188 | C24: =C25+C26 -> -62012933 | D24: =D25+D26 -> -2285065830 | E24: =E25+E26 -> 1377388872
A25: 기초재공품대체 | B25: 779466978 | C25: 223480790 | D25: 285493723 | E25: 2570559553
A26: 기말재공품재고액 | B26: -223480790 | C26: -285493723 | D26: -2570559553 | E26: -1193170681
A27: 당기제품제조원가 | B27: =SUM(B17,B18,B19,B23,B24) -> 69863310749 | C27: =SUM(C17,C18,C19,C23,C24) -> 71234007106 | D27: =SUM(D17,D18,D19,D23,D24) -> 96028639970 | E27: =SUM(E17,E18,E19,E23,E24) -> 100275962475 | F27: =B27/B$38 -> 1.070849 | G27: =C27/C$38 -> 1.1260139 | H27: =D27/D$38 -> 1.1842674 | I27: =E27/E$38 -> 1.2852045
A28: 타계정으로대체 | B28: -16336561683 | C28: -28178553410 | D28: -25556239247 | E28: -45600319574 | F28: =B28/B$38 -> -0.25040312 | G28: =C28/C$38 -> -0.44542548 | H28: =D28/D$38 -> -0.31517077 | I28: =E28/E$38 -> -0.58444449
A29: 제품재고변동/관세환급 | B29: =B30+B31+B32 -> -3117748650 | C29: =C30+C31+C32 -> 3961195586 | D29: =D30+D31+D32 -> -8107249026 | E29: =E30+E31+E32 -> -10217311473
A30: 기초제품재고액 | B30: 15130089007 | C30: 17062841238 | D30: 12312261561 | E30: 18677804682 | F30: =B30/B$38 -> 0.23191058 | G30: =C30/C$38 -> 0.26971662 | H30: =D30/D$38 -> 0.15184022 | I30: =E30/E$38 -> 0.23938736
A31: 기말제품재고액 | B31: -17062841238 | C31: -12312261561 | D31: -18677804682 | E31: -27028610081 | F31: =B31/B$38 -> -0.26153537 | G31: =C31/C$38 -> -0.19462301 | H31: =D31/D$38 -> -0.23034289 | I31: =E31/E$38 -> -0.34641692
A32: 관세환급 | B32: -1184996419 | C32: -789384091 | D32: -1741705905 | E32: -1866506074 | F32: =B32/B$38 -> -0.018163357 | G32: =C32/C$38 -> -0.012477993 | H32: =D32/D$38 -> -0.021479482 | I32: =E32/E$38 -> -0.023922402
A33: 제품매출원가 | B33: =SUM(B27,B28,B29) -> 50409000416 | C33: =SUM(C27,C28,C29) -> 47016649282 | D33: =SUM(D27,D28,D29) -> 62365151697 | E33: =SUM(E27,E28,E29) -> 44458331428 | F33: =B33/B$38 -> 0.77265776 | G33: =C33/C$38 -> 0.74320399 | H33: =D33/D$38 -> 0.76911445 | I33: =E33/E$38 -> 0.569808
A34: 제품매출원가% | B34: =B33/B$38 -> 0.77265776 | C34: =C33/C$38 -> 0.74320399 | D34: =D33/D$38 -> 0.76911445 | E34: =E33/E$38 -> 0.569808
