Workbook

Sheet 총괄
B3: 자재별 매출(본사전체)
C4: 2012년 | D4: 2013년 | E4: 2014년 | F4: 2015년
B5: 백만원 | C5: 12개월 | D5: 12개월 | E5: 12개월 | F5: 6개월
B6: HMI | C6: =KE30_2012년!D55 -> 350442096639 | D6: =KE30_2013년!D56 -> 380508279003 | E6: =KE30_2014년!D57 -> 402019353206 | F6: =KE30_2015년!D56 -> 213180221895
B7: BCS | C7: =KE30_2012년!D56 -> 61089704286 | D7: =KE30_2013년!D57 -> 61363157093 | E7: =KE30_2014년!D58 -> 71219560638 | F7: =KE30_2015년!D57 -> 38745918546
B8: MC | C8: =KE30_2012년!D57 -> 113462074158 | D8: =KE30_2013년!D58 -> 97513231444 | E8: =KE30_2014년!D59 -> 78313283801 | F8: =KE30_2015년!D58 -> 37338408142
B9: 기타 | C9: =KE30_2012년!D58 -> 3575635267 | D9: =KE30_2013년!D59 -> 8347933881 | E9: =KE30_2014년!D60 -> 20594964018 | F9: =KE30_2015년!D59 -> 6529430517
B10: 합계 | C10: =SUM(C6:C9) -> 528569510350 | D10: =SUM(D6:D9) -> 547732601421 | E10: =SUM(E6:E9) -> 572147161663 | F10: =SUM(F6:F9) -> 295793979100
B12: 일시불매출 용역과제 로열티 제외
B14: 자재별 매출(본사 제품매출)
C15: 2012년 | D15: 2013년 | E15: 2014년 | F15: 2015년
B16: 백만원 | C16: 12개월 | D16: 12개월 | E16: 12개월 | F16: 6개월
B17: HMI | C17: =KE30_2012년!AD55 -> 344300425820 | D17: =KE30_2013년!AD56 -> 370110132581 | E17: =KE30_2014년!AD57 -> 386880090767 | F17: =KE30_2015년!R56 -> 203789426654
B18: BCS | C18: =KE30_2012년!AD56 -> 60993142137 | D18: =KE30_2013년!AD57 -> 61301951475 | E18: =KE30_2014년!AD58 -> 70906329634 | F18: =KE30_2015년!R57 -> 38325480789
B19: MC | C19: =KE30_2012년!AD57 -> 113018611634 | D19: =KE30_2013년!AD58 -> 97080812148 | E19: =KE30_2014년!AD59 -> 77934425530 | F19: =KE30_2015년!R58 -> 36927417898
B20: 기타 | C20: =KE30_2012년!AD58 -> 1032359252 | D20: =KE30_2013년!AD59 -> 280216072 | E20: =KE30_2014년!AD60 -> 450482101 | F20: =KE30_2015년!R59 -> 164872829
B21: 합계 | C21: =SUM(C17:C20) -> 519344538843 | D21: =SUM(D17:D20) -> 528773112276 | E21: =SUM(E17:E20) -> 536171328032 | F21: =SUM(F17:F20) -> 279207198170

Sheet 자재별매출단가
M1: 2012년 | S1: 2013 | Y1: 2014년 | AE1: 2015년 반기
B2: 제품군별 매출단가 | M2: 수량 | N2: 매출 | O2: 단가 | S2: 수량 | T2: 매출 | U2: 단가 | Y2: 수량 | Z2: 매출 | AA2: 단가 | AE2: 수량 | AF2: 매출 | AG2: 단가
C3: 2012년 | D3: 2013년 | E3: 2014년 | F3: 2015년 | J3: 1.HMI | K3: AUD | L3: Audio SW Assy | P3: 1.HMI | Q3: AUD | R3: Audio SW Assy | S3: 53765 | T3: 16461322 | U3: =T3/S3 -> 306.17171 | V3: 1.HMI | W3: AUD | X3: Audio SW Assy | Y3: 9564169 | Z3: 2841064046 | AA3: =Z3/Y3 -> 297.05289 | AB3: 1.HMI | AC3: Audio SW Assy | AD3: AUD | AE3: 7194763 | AF3: 2239582516 | AG3: =AF3/AE3 -> 311.27954
B4: 백만원 | C4: 12개월 | D4: 12개월 | E4: 12개월 | F4: 6개월 | J4: 1.HMI | K4: RLP | L4: Interior Lamp | M4: 12985170 | N4: 47712326409 | O4: =N4/M4 -> 3674.3706 | P4: 1.HMI | Q4: RLP | R4: Interior Lamp | S4: 13141046 | T4: 52294228059 | U4: =T4/S4 -> 3979.457 | V4: 1.HMI | W4: RLP | X4: Interior Lamp | Y4: 13730677 | Z4: 57825467801 | AA4: =Z4/Y4 -> 4211.4069 | AB4: 1.HMI | AC4: Interior Lamp | AD4: RLP | AE4: 7483810 | AF4: 29649172036 | AG4: =AF4/AE4 -> 3961.7751
B5: 1.HMI | C5: =O56 -> 417.31547 | D5: =U56 -> 309.19674 | E5: =AA56 -> 293.38131 | F5: =AG56 -> 262.8654 | J5: 1.HMI | K5: SGS | L5: Gear Shift Module | M5: 3782 | N5: 451683356 | O5: =N5/M5 -> 119429.76 | P5: 1.HMI | Q5: SGS | R5: Gear Shift Module | S5: 196 | T5: 34294026 | U5: =T5/S5 -> 174969.52 | V5: 1.HMI | W5: SGS | X5: Gear Shift Module | Y5: 1446 | Z5: 32171610 | AA5: =Z5/Y5 -> 22248.693 | AB5: 1.HMI | AC5: Gear Shift Module | AD5: SGS | AE5: 1366 | AF5: 143575344 | AG5: =AF5/AE5 -> 105106.4
B6: 2.BCS | C6: =O57 -> 5565.1622 | D6: =U57 -> 4807.5991 | E6: =AA57 -> 5206.2963 | F6: =AG57 -> 4692.979 | J6: 1.HMI | K6: SHT | L6: Haptic Switch | M6: 4176 | N6: 198946076 | O6: =N6/M6 -> 47640.344 | P6: 1.HMI | Q6: SHT | R6: Haptic Switch | S6: 7976 | T6: 349302176 | U6: =T6/S6 -> 43794.154 | V6: 1.HMI | W6: SHT | X6: Haptic Switch | Y6: 5419 | Z6: 242516749 | AA6: =Z6/Y6 -> 44753.045 | AB6: 1.HMI | AC6: Haptic Switch | AD6: SHT | AE6: 2607 | AF6: 103972242 | AG6: =AF6/AE6 -> 39881.949
B7: 3.MC | C7: =O58 -> 517.74195 | D7: =U58 -> 469.01406 | E7: =AA58 -> 499.76505 | F7: =AG58 -> 506.68825 | J7: 1.HMI | K7: SIH | L7: Inhibitor Switch | M7: 10379181 | N7: 21020779619 | O7: =N7/M7 -> 2025.2831 | P7: 1.HMI | Q7: SIH | R7: Inhibitor Switch | S7: 22816479 | T7: 23498654145 | U7: =T7/S7 -> 1029.8984 | V7: 1.HMI | W7: SIH | X7: Inhibitor Switch | Y7: 26561020 | Z7: 17133877264 | AA7: =Z7/Y7 -> 645.07603 | AB7: 1.HMI | AC7: Inhibitor Switch | AD7: SIH | AE7: 13964567 | AF7: 8636597129 | AG7: =AF7/AE7 -> 618.46509
J8: 1.HMI | K8: SIP | L8: In Panel Switch | M8: 193278592 | N8: 81809705723 | O8: =N8/M8 -> 423.2735 | P8: 1.HMI | Q8: SIP | R8: In Panel Switch | S8: 265450578 | T8: 88560042103 | U8: =T8/S8 -> 333.62158 | V8: 1.HMI | W8: SIP | X8: In Panel Switch | Y8: 275257222 | Z8: 96539120068 | AA8: =Z8/Y8 -> 350.7233 | AB8: 1.HMI | AC8: In Panel Switch | AD8: SIP | AE8: 165594998 | AF8: 53178346904 | AG8: =AF8/AE8 -> 321.13498
J9: 1.HMI | K9: SMF | L9: Muti Function Switch | M9: 123862757 | N9: 61340570290 | O9: =N9/M9 -> 495.23014 | P9: 1.HMI | Q9: SMF | R9: Muti Function Switch | S9: 187675250 | T9: 63053947057 | U9: =T9/S9 -> 335.97369 | V9: 1.HMI | W9: SMF | X9: Muti Function Switch | Y9: 221548623 | Z9: 67045057389 | AA9: =Z9/Y9 -> 302.62006 | AB9: 1.HMI | AC9: Muti Function Switch | AD9: SMF | AE9: 134621697 | AF9: 33881300453 | AG9: =AF9/AE9 -> 251.67786
J10: 1.HMI | K10: SPW | L10: Power Window Switch | M10: 404281506 | N10: 84763916614 | O10: =N10/M10 -> 209.66558 | P10: 1.HMI | Q10: SPW | R10: Power Window Switch | S10: 682029596 | T10: 88236117189 | U10: =T10/S10 -> 129.37286 | V10: 1.HMI | W10: SPW | X10: Power Window Switch | Y10: 745931574 | Z10: 96351828752 | AA10: =Z10/Y10 -> 129.1698 | AB10: 1.HMI | AC10: Power Window Switch | AD10: SPW | AE10: 431844645 | AF10: 53306389299 | AG10: =AF10/AE10 -> 123.43881
J11: 1.HMI | K11: SRM | L11: Remocon Switch | M11: 13112389 | N11: 41663283327 | O11: =N11/M11 -> 3177.3984 | P11: 1.HMI | Q11: SRM | R11: Remocon Switch | S11: 12872767 | T11: 51035830487 | U11: =T11/S11 -> 3964.6356 | V11: 1.HMI | W11: SRM | X11: Remocon Switch | Y11: 15944313 | Z11: 47614762613 | AA11: =Z11/Y11 -> 2986.3164 | AB11: 1.HMI | AC11: Remocon Switch | AD11: SRM | AE11: 7235419 | AF11: 21480670846 | AG11: =AF11/AE11 -> 2968.822
J12: 1.HMI | K12: SSM | L12: Micro Switch | M12: 2390244 | N12: 409100463 | O12: =N12/M12 -> 171.15427 | P12: 1.HMI | Q12: SSM | R12: Micro Switch | S12: 18161 | T12: 50373 | U12: =T12/S12 -> 2.7736909 | V12: 1.HMI | W12: SSM | X12: Micro Switch | Y12: 438902 | Z12: 13394410 | AA12: =Z12/Y12 -> 30.517997 | AB12: 1.HMI | AC12: Micro Switch | AD12: SSM | AE12: 394923 | AF12: 4233421 | AG12: =AF12/AE12 -> 10.719611
J13: 1.HMI | K13: SSW | L13: General Switch | M13: 64738541 | N13: 4930113943 | O13: =N13/M13 -> 76.154233 | P13: 1.HMI | Q13: SSW | R13: General Switch | S13: 12939474 | T13: 3031205644 | U13: =T13/S13 -> 234.26035 | V13: 1.HMI | W13: SSW | X13: General Switch | Y13: 9710343 | Z13: 1240830065 | AA13: =Z13/Y13 -> 127.78437 | AB13: 1.HMI | AC13: General Switch | AD13: SSW | AE13: 6922711 | AF13: 1165586464 | AG13: =AF13/AE13 -> 168.37139
J14: 2.BCS | K14: ABS | L14: Anti-lock Brake Syst | M14: 0 | N14: 0 | P14: 2.BCS | Q14: BCM | R14: Body Control Module | S14: -9994 | T14: 2158392511 | U14: =T14/S14 -> -215968.83 | V14: 2.BCS | W14: ATS | X14: Anti Theft Alarm Sys | Y14: 597 | Z14: 21950730 | AA14: =Z14/Y14 -> 36768.392 | AB14: 2.BCS | AC14: Anti Theft Alarm Sys | AD14: ATS | AE14: 5222 | AF14: 121313032 | AG14: =AF14/AE14 -> 23231.144
J15: 2.BCS | K15: BCM | L15: Body Control Module | M15: 14573 | N15: 55109982 | O15: =N15/M15 -> 3781.6498 | P15: 2.BCS | Q15: BLT | R15: Ballast | S15: 290863 | T15: 8075465260 | U15: =T15/S15 -> 27763.811 | V15: 2.BCS | W15: BCM | X15: Body Control Module | Y15: -5500 | Z15: 1352678957 | AA15: =Z15/Y15 -> -245941.63 | AB15: 2.BCS | AC15: Body Control Module | AD15: BCM | AE15: 40000 | AF15: 1940866257 | AG15: =AF15/AE15 -> 48521.656
J16: 2.BCS | K16: BLT | L16: Ballast | M16: 196446 | N16: 5679426019 | O16: =N16/M16 -> 28910.876 | P16: 2.BCS | Q16: CTS | R16: Current Sensor | S16: 320 | T16: 613580 | U16: =T16/S16 -> 1917.4375 | V16: 2.BCS | W16: BLT | X16: Ballast | Y16: 390339 | Z16: 10345800233 | AA16: =Z16/Y16 -> 26504.654 | AB16: 2.BCS | AC16: Ballast | AD16: BLT | AE16: 282396 | AF16: 7040741554 | AG16: =AF16/AE16 -> 24932.158
J17: 2.BCS | K17: CTS | L17: Current Sensor | M17: 10036 | N17: 19474732 | O17: =N17/M17 -> 1940.4874 | P17: 2.BCS | Q17: CVT | R17: Converter | S17: 716144 | T17: 12988961761 | U17: =T17/S17 -> 18137.36 | V17: 2.BCS | W17: BTC | X17: Body Control System | Y17: 0 | Z17: 0 | AA17: =Z17/Y17 -> #DIV/0! | AB17: 2.BCS | AC17: Body Control System | AD17: BTC | AE17: 0 | AF17: 0 | AG17: =AF17/AE17 -> #DIV/0!
J18: 2.BCS | K18: CVT | L18: Converter | M18: 621208 | N18: 14800366522 | O18: =N18/M18 -> 23825.138 | P18: 2.BCS | Q18: GAC | R18: Glass Antenna | S18: 892831 | T18: 684717559 | U18: =T18/S18 -> 766.90612 | V18: 2.BCS | W18: CTS | X18: Current Sensor | Y18: 41629 | Z18: 1396956428 | AA18: =Z18/Y18 -> 33557.29 | AB18: 2.BCS | AC18: Current Sensor | AD18: CTS | AE18: 42022 | AF18: 1235206441 | AG18: =AF18/AE18 -> 29394.28
J19: 2.BCS | K19: GAC | L19: Glass Antenna | M19: 541463 | N19: 2690925449 | O19: =N19/M19 -> 4969.731 | P19: 2.BCS | Q19: HFC | R19: Hands Free Unit | S19: 1333847 | T19: 1469091229 | U19: =T19/S19 -> 1101.3941 | V19: 2.BCS | W19: CVT | X19: Converter | Y19: 670861 | Z19: 12732048470 | AA19: =Z19/Y19 -> 18978.668 | AB19: 2.BCS | AC19: Converter | AD19: CVT | AE19: 542610 | AF19: 7160485484 | AG19: =AF19/AE19 -> 13196.376
J20: 2.BCS | K20: HFC | L20: Hands Free Unit | M20: 988498 | N20: 1982852523 | O20: =N20/M20 -> 2005.9247 | P20: 2.BCS | Q20: PSM | R20: Power Seat Module | S20: 435220 | T20: 9995009884 | U20: =T20/S20 -> 22965.42 | V20: 2.BCS | W20: GAC | X20: Glass Antenna | Y20: 150375 | Z20: 529630919 | AA20: =Z20/Y20 -> 3522.0676 | AB20: 2.BCS | AC20: Glass Antenna | AD20: GAC | AE20: 74660 | AF20: 265791342 | AG20: =AF20/AE20 -> 3560.0233
J21: 2.BCS | K21: PSM | L21: Power Seat Module | M21: 271620 | N21: 6660427435 | O21: =N21/M21 -> 24521.123 | P21: 2.BCS | Q21: RER | R21: eRelay | S21: 0 | T21: 21722735 | U21: =T21/S21 -> #DIV/0! | V21: 2.BCS | W21: HFC | X21: Hands Free Unit | Y21: 1101705 | Z21: 1739851024 | AA21: =Z21/Y21 -> 1579.2349 | AB21: 2.BCS | AC21: Hands Free Unit | AD21: HFC | AE21: 448142 | AF21: 582347608 | AG21: =AF21/AE21 -> 1299.4712
J22: 2.BCS | K22: SAS | L22: Steering Angle Senso | M22: 333663 | N22: 3941143276 | O22: =N22/M22 -> 11811.748 | P22: 2.BCS | Q22: SAS | R22: Steering Angle Senso | S22: 303577 | T22: 3639025030 | U22: =T22/S22 -> 11987.157 | V22: 2.BCS | W22: PSM | X22: Power Seat Module | Y22: 464830 | Z22: 10921259368 | AA22: =Z22/Y22 -> 23495.169 | AB22: 2.BCS | AC22: Power Seat Module | AD22: PSM | AE22: 205791 | AF22: 3978255603 | AG22: =AF22/AE22 -> 19331.533
J23: 2.BCS | K23: SEN | L23: Yaw & G Sensor (SYG로 | M23: 359349 | N23: 10456755336 | O23: =N23/M23 -> 29099.164 | P23: 2.BCS | Q23: SEN | R23: Yaw & G Sensor (SYG로 | S23: 108012 | T23: 3027160948 | U23: =T23/S23 -> 28026.154 | V23: 2.BCS | W23: RER | X23: eRelay | Y23: 0 | Z23: 15453819 | AA23: =Z23/Y23 -> #DIV/0! | AB23: 2.BCS | AC23: eRelay | AD23: RER | AE23: 0 | AF23: 3999486 | AG23: =AF23/AE23 -> #DIV/0!
J24: 2.BCS | K24: SYG | L24: Yaw & G Sensor | M24: 109644 | N24: 3128250200 | O24: =N24/M24 -> 28530.975 | P24: 2.BCS | Q24: SYG | R24: Yaw & G Sensor | S24: 100429 | T24: 3080241889 | U24: =T24/S24 -> 30670.841 | V24: 2.BCS | W24: SAS | X24: Steering Angle Senso | Y24: 436034 | Z24: 4626224416 | AA24: =Z24/Y24 -> 10609.779 | AB24: 2.BCS | AC24: Steering Angle Senso | AD24: SAS | AE24: 339156 | AF24: 3635824955 | AG24: =AF24/AE24 -> 10720.214
J25: 2.BCS | K25: TOS | L25: Torque Only Sensor | M25: 103 | N25: 14224839 | O25: =N25/M25 -> 138105.23 | P25: 2.BCS | Q25: TAS | R25: Torque Angle Sensor | S25: 0 | T25: 0 | U25: =T25/S25 -> #DIV/0! | V25: 2.BCS | W25: SEN | X25: Yaw & G Sensor (SYG로 | Y25: 24774 | Z25: 401861703 | AA25: =Z25/Y25 -> 16221.107 | AB25: 2.BCS | AC25: Yaw & G Sensor (SYG로 | AD25: SEN | AE25: 8940 | AF25: 142359753 | AG25: =AF25/AE25 -> 15923.91
J26: 2.BCS | K26: UTC | L26: Control Unit | M26: 7448920 | N26: 9375501824 | O26: =N26/M26 -> 1258.6391 | P26: 2.BCS | Q26: TOS | R26: Torque Only Sensor | S26: 0 | T26: 10102893 | U26: =T26/S26 -> #DIV/0! | V26: 2.BCS | W26: SYG | X26: Yaw & G Sensor | Y26: 15577 | Z26: 634615606 | AA26: =Z26/Y26 -> 40740.554 | AB26: 2.BCS | AC26: Yaw & G Sensor | AD26: SYG | AE26: 585 | AF26: 24961824 | AG26: =AF26/AE26 -> 42669.785
... J50: 4.기타 | K50: MEP | L50: Molding Tool | M50: 33 | N50: 0 | O50: =N50/M50 -> 0 | P50: 4.기타 | Q50: MEP | R50: Molding Tool | S50: 28 | T50: 0 | U50: =T50/S50 -> 0 | V50: 4.기타 | W50: FAC | X50: Machinery | Y50: 25 | Z50: 0 | AA50: =Z50/Y50 -> 0 | AB50: 4.기타 | AC50: Royalty | AD50: ROY | AE50: 0 | AF50: 0 | AG50: =AF50/AE50 -> #DIV/0!
J51: 4.기타 | L51: 미지정 | M51: 1050000 | N51: 0 | O51: =N51/M51 -> 0 | P51: 4.기타 | S51: 204 | T51: 4742184 | U51: =T51/S51 -> 23246 | V51: 4.기타 | W51: MEP | X51: Molding Tool | Y51: 47 | Z51: 0 | AA51: =Z51/Y51 -> 0 | AB51: 4.기타 | AC51: 미지정 | AE51: 0 | AF51: 0 | AG51: =AF51/AE51 -> #DIV/0!
V52: 4.기타 | X52: 미지정 | Y52: 0 | Z52: 0
M54: 2012년 | S54: 2013 | Y54: 2014년 | AE54: 2015년 반기
M55: 수량 | N55: 매출 | O55: 단가 | S55: 수량 | T55: 매출 | U55: 단가 | Y55: 수량 | Z55: 매출 | AA55: 단가 | AE55: 수량 | AF55: 매출 | AG55: 단가
J56: 1.HMI | M56: =SUMIF($J$3:$J$51,$J56,M$3:M$51) -> 825036338 | N56: =SUMIF($J$3:$J$51,$J56,N$3:N$51) -> 344300425820 | O56: =N56/M56 -> 417.31547 | S56: =SUMIF($P$3:$P$50,$J56,S$3:S$50) -> 1197005288 | T56: =SUMIF($P$3:$P$50,$J56,T$3:T$50) -> 370110132581 | U56: =T56/S56 -> 309.19674 | Y56: =SUMIF($V$3:$V$51,$J56,Y$3:Y$51) -> 1318693708 | Z56: =SUMIF($V$3:$V$51,$J56,Z$3:Z$51) -> 386880090767 | AA56: =Z56/Y56 -> 293.38131 | AE56: =SUMIF($AB$3:$AB$51,$J56,AE$3:AE$51) -> 775261506 | AF56: =SUMIF($AB$3:$AB$51,$J56,AF$3:AF$51) -> 203789426654 | AG56: =AF56/AE56 -> 262.8654
J57: 2.BCS | M57: =SUMIF($J$3:$J$51,$J57,M$3:M$51) -> 10959814 | N57: =SUMIF($J$3:$J$51,$J57,N$3:N$51) -> 60993142137 | O57: =N57/M57 -> 5565.1622 | S57: =SUMIF($P$3:$P$50,$J57,S$3:S$50) -> 12751053 | T57: =SUMIF($P$3:$P$50,$J57,T$3:T$50) -> 61301951475 | U57: =T57/S57 -> 4807.5991 | Y57: =SUMIF($V$3:$V$51,$J57,Y$3:Y$51) -> 13619342 | Z57: =SUMIF($V$3:$V$51,$J57,Z$3:Z$51) -> 70906329634 | AA57: =Z57/Y57 -> 5206.2963 | AE57: =SUMIF($AB$3:$AB$51,$J57,AE$3:AE$51) -> 8166557 | AF57: =SUMIF($AB$3:$AB$51,$J57,AF$3:AF$51) -> 38325480789 | AG57: =AF57/AE57 -> 4692.979
J58: 3.MC | M58: =SUMIF($J$3:$J$51,$J58,M$3:M$51) -> 218291395 | N58: =SUMIF($J$3:$J$51,$J58,N$3:N$51) -> 113018611634 | O58: =N58/M58 -> 517.74195 | S58: =SUMIF($P$3:$P$50,$J58,S$3:S$50) -> 206989130 | T58: =SUMIF($P$3:$P$50,$J58,T$3:T$50) -> 97080812148 | U58: =T58/S58 -> 469.01406 | Y58: =SUMIF($V$3:$V$51,$J58,Y$3:Y$51) -> 155942129 | Z58: =SUMIF($V$3:$V$51,$J58,Z$3:Z$51) -> 77934425530 | AA58: =Z58/Y58 -> 499.76505 | AE58: =SUMIF($AB$3:$AB$51,$J58,AE$3:AE$51) -> 72879957 | AF58: =SUMIF($AB$3:$AB$51,$J58,AF$3:AF$51) -> 36927417898 | AG58: =AF58/AE58 -> 506.68825
J59: 4.기타 | M59: =SUMIF($J$3:$J$51,$J59,M$3:M$51) -> 302417823 | N59: =SUMIF($J$3:$J$51,$J59,N$3:N$51) -> 1032359252 | O59: =N59/M59 -> 3.4136852 | S59: =SUMIF($P$3:$P$50,$J59,S$3:S$50) -> 476499209 | T59: =SUMIF($P$3:$P$50,$J59,T$3:T$50) -> 275473888 | U59: =T59/S59 -> 0.57812035 | Y59: =SUMIF($V$3:$V$51,$J59,Y$3:Y$51) -> 636326950 | Z59: =SUMIF($V$3:$V$51,$J59,Z$3:Z$51) -> 450482101 | AA59: =Z59/Y59 -> 0.70794126 | AE59: =SUMIF($AB$3:$AB$51,$J59,AE$3:AE$51) -> 438559993 | AF59: =SUMIF($AB$3:$AB$51,$J59,AF$3:AF$51) -> 164872829 | AG59: =AF59/AE59 -> 0.37594133
M61: 825036338 | N61: 344300425820 | O61: =N61/M61 -> 417.31547 | S61: 1197005288 | T61: 370110132581 | U61: =T61/S61 -> 309.19674 | Y61: 1318693708 | Z61: 386880090767 | AA61: =Z61/Y61 -> 293.38131 | AE61: 775261506 | AF61: 203789426654 | AG61: =AF61/AE61 -> 262.8654
M62: 10959814 | N62: 60993142137 | O62: =N62/M62 -> 5565.1622 | S62: 12751053 | T62: 61301951475 | U62: =T62/S62 -> 4807.5991 | Y62: 13619342 | Z62: 70906329634 | AA62: =Z62/Y62 -> 5206.2963 | AE62: 8166557 | AF62: 38325480789 | AG62: =AF62/AE62 -> 4692.979
M63: 218291395 | N63: 113018611634 | O63: =N63/M63 -> 517.74195 | S63: 206989130 | T63: 97080812148 | U63: =T63/S63 -> 469.01406 | Y63: 155942129 | Z63: 77934425530 | AA63: =Z63/Y63 -> 499.76505 | AE63: 72879957 | AF63: 36927417898 | AG63: =AF63/AE63 -> 506.68825
M64: 302417823 | N64: 1032359252 | O64: =N64/M64 -> 3.4136852 | S64: 476499413 | T64: 280216072 | U64: =T64/S64 -> 0.58807223 | Y64: 636326950 | Z64: 450482101 | AA64: =Z64/Y64 -> 0.70794126 | AE64: 438559993 | AF64: 164872829 | AG64: =AF64/AE64 -> 0.37594133
M65: 1356705370 | N65: 519344538843 | O65: =N65/M65 -> 382.79832 | S65: 1893244884 | T65: 528773112276 | U65: =T65/S65 -> 279.29462 | Y65: 2124582129 | Z65: 536171328032 | AE65: 1294868013 | AF65: 279207198170

Sheet KE30_2012년
A1: 2012년 자재그룹별 월별손익실적 Report
A2: 사업구분 | B2: 자재그룹3 | C2: 재재그룹3내역 | E2: 제품(상품)매출 | AE2: 설비매출 | AR2: 기타매출
D3: 전체 | E3: 1월 | G3: 2월 | I3: 3월 | K3: 4월 | M3: 5월 | O3: 6월 | Q3: 7월 | S3: 8월 | U3: 9월 | W3: 10월 | Y3: 11월 | AA3: 12월 | AC3: 합계
D4: 매출액 | E4: 수량 | F4: 매출액 | G4: 수량 | H4: 매출액 | I4: 수량 | J4: 매출액 | K4: 수량 | L4: 매출액 | M4: 수량 | N4: 매출액 | O4: 수량 | P4: 매출액 | Q4: 수량 | R4: 매출액 | S4: 수량 | T4: 매출액 | U4: 수량 | V4: 매출액 | W4: 수량 | X4: 매출액 | Y4: 수량 | Z4: 매출액 | AA4: 수량 | AB4: 매출액 | AC4: 수량 | AD4: 매출액 | AE4: 1월 | AF4: 2월 | AG4: 3월 | AH4: 4월 | AI4: 5월 | AJ4: 6월 | AK4: 7월 | AL4: 8월 | AM4: 9월 | AN4: 10월 | AO4: 11월 | AP4: 12월 | AQ4: 합계 | AR4: 1월 | AS4: 2월 | AT4: 3월 | AU4: 4월 | AV4: 5월 | AW4: 6월 | AX4: 7월 | AY4: 8월 | AZ4: 9월 | BA4: 10월 | BB4: 11월 | BC4: 12월 | BD4: 합계
A5: 1.HMI | B5: RLP | C5: Interior Lamp | D5: =AD5+AQ5+BD5 -> 47712326409 | E5: 1045019 | F5: 3617195871 | G5: 1198935 | H5: 4203019770 | I5: 1124601 | J5: 4195230940 | K5: 1140715 | L5: 4168909585 | M5: 1037295 | N5: 3904389774 | O5: 1111043 | P5: 4620388686 | Q5: 1053299 | R5: 4027283548 | S5: 856791 | T5: 2927348135 | U5: 1078174 | V5: 3708338544 | W5: 1130235 | X5: 4070084738 | Y5: 1167950 | Z5: 4055053504 | AA5: 1041113 | AB5: 4215083314 | AC5: =SUM(E5,G5,I5,K5,M5,O5,Q5,S5,U5,W5,Y5,AA5) -> 12985170 | AD5: =SUM(F5,H5,J5,L5,N5,P5,R5,T5,V5,X5,Z5,AB5) -> 47712326409 | AE5: 0 | AF5: 0 | AG5: 0 | AH5: 0 | AI5: 0 | AJ5: 0 | AK5: 0 | AL5: 0 | AM5: 0 | AN5: 0 | AO5: 0 | AP5: 0 | AQ5: =SUM(AE5:AP5) -> 0 | AR5: 0 | AS5: 0 | AT5: 0 | AU5: 0 | AV5: 0 | AW5: 0 | AX5: 0 | AY5: 0 | AZ5: 0 | BA5: 0 | BB5: 0 | BC5: 0 | BD5: =SUM(AR5:BC5) -> 0
A6: 1.HMI | B6: SGS | C6: Gear Shift Module | D6: =AD6+AQ6+BD6 -> 451683356 | E6: 412 | F6: 35134289 | G6: 600 | H6: 34412633 | I6: 564 | J6: 136693131 | K6: 475 | L6: -312606769 | M6: 321 | N6: 397973288 | O6: 442 | P6: 44285232 | Q6: 365 | R6: 33017596 | S6: 199 | T6: 33193516 | U6: 294 | V6: 30880440 | W6: 90 | X6: 15300000 | Y6: 10 | Z6: 1700000 | AA6: 10 | AB6: 1700000 | AC6: =SUM(E6,G6,I6,K6,M6,O6,Q6,S6,U6,W6,Y6,AA6) -> 3782 | AD6: =SUM(F6,H6,J6,L6,N6,P6,R6,T6,V6,X6,Z6,AB6) -> 451683356 | AE6: 0 | AF6: 0 | AG6: 0 | AH6: 0 | AI6: 0 | AJ6: 0 | AK6: 0 | AL6: 0 | AM6: 0 | AN6: 0 | AO6: 0 | AP6: 0 | AQ6: =SUM(AE6:AP6) -> 0 | AR6: 0 | AS6: 0 | AT6: 0 | AU6: 0 | AV6: 0 | AW6: 0 | AX6: 0 | AY6: 0 | AZ6: 0 | BA6: 0 | BB6: 0 | BC6: 0 | BD6: =SUM(AR6:BC6) -> 0
A7: 1.HMI | B7: SHT | C7: Haptic Switch | D7: =AD7+AQ7+BD7 -> 198946076 | E7: 0 | F7: 0 | G7: 0 | H7: 0 | I7: 0 | J7: 0 | K7: 1182 | L7: 15957000 | M7: 998 | N7: 92277798 | O7: -90 | P7: -4591998 | Q7: 693 | R7: 34864830 | S7: 192 | T7: 9666450 | U7: -86 | V7: -4324740 | W7: 320 | X7: 16098340 | Y7: -43 | Z7: -2121844 | AA7: 1010 | AB7: 41120240 | AC7: =SUM(E7,G7,I7,K7,M7,O7,Q7,S7,U7,W7,Y7,AA7) -> 4176 | AD7: =SUM(F7,H7,J7,L7,N7,P7,R7,T7,V7,X7,Z7,AB7) -> 198946076 | AE7: 0 | AF7: 0 | AG7: 0 | AH7: 0 | AI7: 0 | AJ7: 0 | AK7: 0 | AL7: 0 | AM7: 0 | AN7: 0 | AO7: 0 | AP7: 0 | AQ7: =SUM(AE7:AP7) -> 0 | AR7: 0 | AS7: 0 | AT7: 0 | AU7: 0 | AV7: 0 | AW7: 0 | AX7: 0 | AY7: 0 | AZ7: 0 | BA7: 0 | BB7: 0 | BC7: 0 | BD7: =SUM(AR7:BC7) -> 0
A8: 1.HMI | B8: SIH | C8: Inhibitor Switch | D8: =AD8+AQ8+BD8 -> 21042114878 | E8: 534115 | F8: 1827401114 | G8: 569032 | H8: 1819745747 | I8: 562115 | J8: 1780111199 | K8: 605588 | L8: 1648605982 | M8: 565222 | N8: 1580908731 | O8: 444901 | P8: 1614461689 | Q8: 566225 | R8: 1510688676 | S8: 878410 | T8: 1627619460 | U8: 399328 | V8: 1736235630 | W8: 1317782 | X8: 1856538770 | Y8: 2049064 | Z8: 1912752235 | AA8: 1887399 | AB8: 2105710386 | AC8: =SUM(E8,G8,I8,K8,M8,O8,Q8,S8,U8,W8,Y8,AA8) -> 10379181 | AD8: =SUM(F8,H8,J8,L8,N8,P8,R8,T8,V8,X8,Z8,AB8) -> 21020779619 | AE8: 0 | AF8: 0 | AG8: 0 | AH8: 0 | AI8: 0 | AJ8: 0 | AK8: 0 | AL8: 0 | AM8: 0 | AN8: 0 | AO8: 0 | AP8: 0 | AQ8: =SUM(AE8:AP8) -> 0 | AR8: 282225 | AS8: 336256 | AT8: 373528 | AU8: 509838 | AV8: 467772 | AW8: 173448 | AX8: 652328 | AY8: 2329774 | AZ8: 0 | BA8: 1401593 | BB8: 7201305 | BC8: 7607192 | BD8: =SUM(AR8:BC8) -> 21335259
A9: 1.HMI | B9: SIP | C9: In Panel Switch | D9: =AD9+AQ9+BD9 -> 84367715472 | E9: 17615386 | F9: 6272014915 | G9: 12958105 | H9: 6394704509 | I9: 16529106 | J9: 7263550295 | K9: 18894037 | L9: 7043417897 | M9: 13809373 | N9: 6648296227 | O9: 7101796 | P9: 7284738896 | Q9: 9340584 | R9: 7246697965 | S9: 8754599 | T9: 5756013659 | U9: 8624607 | V9: 6438778511 | W9: 22690311 | X9: 6890720769 | Y9: 28821041 | Z9: 7248040267 | AA9: 28139647 | AB9: 7322731813 | AC9: =SUM(E9,G9,I9,K9,M9,O9,Q9,S9,U9,W9,Y9,AA9) -> 193278592 | AD9: =SUM(F9,H9,J9,L9,N9,P9,R9,T9,V9,X9,Z9,AB9) -> 81809705723 | AE9: 0 | AF9: 0 | AG9: 0 | AH9: 0 | AI9: 0 | AJ9: 0 | AK9: 0 | AL9: 0 | AM9: 0 | AN9: 0 | AO9: 0 | AP9: 0 | AQ9: =SUM(AE9:AP9) -> 0 | AR9: 192653802 | AS9: 181919454 | AT9: 112306257 | AU9: 124430043 | AV9: 135844569 | AW9: 78029527 | AX9: 89397679 | AY9: 72790654 | AZ9: 89981240 | BA9: 803737638 | BB9: 326476098 | BC9: 350442788 | BD9: =SUM(AR9:BC9) -> 2558009749
A10: 1.HMI | B10: SMF | C10: Muti Function Switch | D10: =AD10+AQ10+BD10 -> 61886048901 | E10: 8409371 | F10: 4706305315 | G10: 10010541 | H10: 5319646822 | I10: 13025742 | J10: 6088899091 | K10: 8344100 | L10: 5905529384 | M10: 10600065 | N10: 5413670247 | O10: 8091590 | P10: 5608799026 | Q10: 9254235 | R10: 4882752985 | S10: 10330420 | T10: 4255931769 | U10: 8810776 | V10: 4622688355 | W10: 13239741 | X10: 4424038550 | Y10: 12192914 | Z10: 4917486980 | AA10: 11553262 | AB10: 5194821766 | AC10: =SUM(E10,G10,I10,K10,M10,O10,Q10,S10,U10,W10,Y10,AA10) -> 123862757 | AD10: =SUM(F10,H10,J10,L10,N10,P10,R10,T10,V10,X10,Z10,AB10) -> 61340570290 | AE10: 0 | AF10: 0 | AG10: 0 | AH10: 0 | AI10: 0 | AJ10: 0 | AK10: 0 | AL10: 0 | AM10: 0 | AN10: 0 | AO10: 0 | AP10: 0 | AQ10: =SUM(AE10:AP10) -> 0 | AR10: 23014884 | AS10: 36689804 | AT10: 42992745 | AU10: 30228253 | AV10: 15473913 | AW10: 24173169 | AX10: 38205572 | AY10: 43234939 | AZ10: 23729506 | BA10: 86829960 | BB10: 110955228 | BC10: 69950638 | BD10: =SUM(AR10:BC10) -> 545478611
A11: 1.HMI | B11: SPW | C11: Power Window Switch | D11: =AD11+AQ11+BD11 -> 87757162794 | E11: 18634205 | F11: 6997179445 | G11: 22104438 | H11: 6830805581 | I11: 25203767 | J11: 6270714160 | K11: 15224570 | L11: 7247815958 | M11: 16961204 | N11: 7665068239 | O11: 19740128 | P11: 7733464190 | Q11: 25740518 | R11: 7125423407 | S11: 20568124 | T11: 5368700168 | U11: 26342946 | V11: 6820829707 | W11: 64245329 | X11: 7085135542 | Y11: 79624852 | Z11: 7897732904 | AA11: 69891425 | AB11: 7721047313 | AC11: =SUM(E11,G11,I11,K11,M11,O11,Q11,S11,U11,W11,Y11,AA11) -> 404281506 | AD11: =SUM(F11,H11,J11,L11,N11,P11,R11,T11,V11,X11,Z11,AB11) -> 84763916614 | AE11: 0 | AF11: 0 | AG11: 0 | AH11: 0 | AI11: 0 | AJ11: 0 | AK11: 0 | AL11: 0 | AM11: 0 | AN11: 0 | AO11: 0 | AP11: 0 | AQ11: =SUM(AE11:AP11) -> 0 | AR11: 156595132 | AS11: 145481873 | AT11: 141853398 | AU11: 63672842 | AV11: 180907728 | AW11: 100207248 | AX11: 117579138 | AY11: 109011305 | AZ11: 109718533 | BA11: 1045911275 | BB11: 424685950 | BC11: 397621758 | BD11: =SUM(AR11:BC11) -> 2993246180
A12: 1.HMI | B12: SRM | C12: Remocon Switch | D12: =AD12+AQ12+BD12 -> 41663951325 | E12: 1096821 | F12: 2733147093 | G12: 1200284 | H12: 3205221439 | I12: 974987 | J12: 3205566356 | K12: 1040733 | L12: 3159478620 | M12: 1021858 | N12: 3447292822 | O12: 836230 | P12: 3567987996 | Q12: 1821941 | R12: 3530567866 | S12: 776429 | T12: 2926080397 | U12: 775782 | V12: 3473961566 | W12: 1070739 | X12: 4207635283 | Y12: 1523849 | Z12: 4556714289 | AA12: 972736 | AB12: 3649629600 | AC12: =SUM(E12,G12,I12,K12,M12,O12,Q12,S12,U12,W12,Y12,AA12) -> 13112389 | AD12: =SUM(F12,H12,J12,L12,N12,P12,R12,T12,V12,X12,Z12,AB12) -> 41663283327 | AE12: 0 | AF12: 0 | AG12: 0 | AH12: 0 | AI12: 0 | AJ12: 0 | AK12: 0 | AL12: 0 | AM12: 0 | AN12: 0 | AO12: 0 | AP12: 0 | AQ12: =SUM(AE12:AP12) -> 0 | AR12: 0 | AS12: 0 | AT12: 0 | AU12: 667998 | AV12: 0 | AW12: 0 | AX12: 0 | AY12: 0 | AZ12: 0 | BA12: 0 | BB12: 0 | BC12: 0 | BD12: =SUM(AR12:BC12) -> 667998
A13: 1.HMI | B13: SSM | C13: Micro Switch | D13: =AD13+AQ13+BD13 -> 409100463 | E13: 744918 | F13: 171927154 | G13: 634393 | H13: 156064451 | I13: 9600 | J13: 2869304 | K13: 819227 | L13: 28378124 | M13: 51570 | N13: 15402600 | O13: 46400 | P13: 14485426 | Q13: 18200 | R13: 5495465 | S13: 66200 | T13: 14880977 | U13: 9 | V13: 29839 | W13: 297 | X13: 501128 | Y13: -695 | Z13: -1137130 | AA13: 125 | AB13: 203125 | AC13: =SUM(E13,G13,I13,K13,M13,O13,Q13,S13,U13,W13,Y13,AA13) -> 2390244 | AD13: =SUM(F13,H13,J13,L13,N13,P13,R13,T13,V13,X13,Z13,AB13) -> 409100463 | AE13: 0 | AF13: 0 | AG13: 0 | AH13: 0 | AI13: 0 | AJ13: 0 | AK13: 0 | AL13: 0 | AM13: 0 | AN13: 0 | AO13: 0 | AP13: 0 | AQ13: =SUM(AE13:AP13) -> 0 | AR13: 0 | AS13: 0 | AT13: 0 | AU13: 0 | AV13: 0 | AW13: 0 | AX13: 0 | AY13: 0 | AZ13: 0 | BA13: 0 | BB13: 0 | BC13: 0 | BD13: =SUM(AR13:BC13) -> 0
A14: 1.HMI | B14: SSW | C14: General Switch | D14: =AD14+AQ14+BD14 -> 4953046965 | E14: 563881 | F14: 342563513 | G14: 11814783 | H14: 950228649 | I14: 30080959 | J14: 936299408 | K14: 2945434 | L14: 183800381 | M14: 2744943 | N14: 241646198 | O14: 1649492 | P14: 182405883 | Q14: 2756337 | R14: 196226603 | S14: 1939907 | T14: 249277773 | U14: 2594767 | V14: 259059438 | W14: 3331603 | X14: 500311281 | Y14: 2312101 | Z14: 449325586 | AA14: 2004334 | AB14: 438969230 | AC14: =SUM(E14,G14,I14,K14,M14,O14,Q14,S14,U14,W14,Y14,AA14) -> 64738541 | AD14: =SUM(F14,H14,J14,L14,N14,P14,R14,T14,V14,X14,Z14,AB14) -> 4930113943 | AE14: 0 | AF14: 0 | AG14: 0 | AH14: 0 | AI14: 0 | AJ14: 0 | AK14: 0 | AL14: 0 | AM14: 0 | AN14: 0 | AO14: 0 | AP14: 0 | AQ14: =SUM(AE14:AP14) -> 0 | AR14: 0 | AS14: 1733916 | AT14: 6049232 | AU14: 0 | AV14: 1825566 | AW14: 205000 | AX14: 2511307 | AY14: 85344 | AZ14: 8744769 | BA14: 1615402 | BB14: 81785 | BC14: 80701 | BD14: =SUM(AR14:BC14) -> 22933022
A15: 2.BCS | B15: ABS | C15: Anti-lock Brake Syst | D15: =AD15+AQ15+BD15 -> 0 | E15: 0 | F15: 0 | G15: 0 | H15: 0 | I15: 0 | J15: 0 | K15: 0 | L15: 0 | M15: 0 | N15: 0 | O15: 0 | P15: 0 | Q15: 0 | R15: 0 | S15: 0 | T15: 0 | U15: 0 | V15: 0 | W15: 0 | X15: 0 | Y15: 0 | Z15: 0 | AA15: 0 | AB15: 0 | AC15: =SUM(E15,G15,I15,K15,M15,O15,Q15,S15,U15,W15,Y15,AA15) -> 0 | AD15: =SUM(F15,H15,J15,L15,N15,P15,R15,T15,V15,X15,Z15,AB15) -> 0 | AE15: 0 | AF15: 0 | AG15: 0 | AH15: 0 | AI15: 0 | AJ15: 0 | AK15: 0 | AL15: 0 | AM15: 0 | AN15: 0 | AO15: 0 | AP15: 0 | AQ15: =SUM(AE15:AP15) -> 0 | AR15: 0 | AS15: 0 | AT15: 0 | AU15: 0 | AV15: 0 | AW15: 0 | AX15: 0 | AY15: 0 | AZ15: 0 | BA15: 0 | BB15: 0 | BC15: 0 | BD15: =SUM(AR15:BC15) -> 0
A16: 2.BCS | B16: BCM | C16: Body Control Module | D16: =AD16+AQ16+BD16 -> 55109982 | E16: 0 | F16: 0 | G16: 0 | H16: 0 | I16: 20 | J16: 392976 | K16: 899 | L16: 5111716 | M16: 1583 | N16: 8670814 | O16: 1797 | P16: 10526160 | Q16: 1759 | R16: 10197004 | S16: 1010 | T16: 5665040 | U16: 1805 | V16: 10129660 | W16: 3800 | X16: 2969032 | Y16: 900 | Z16: 687525 | AA16: 1000 | AB16: 760055 | AC16: =SUM(E16,G16,I16,K16,M16,O16,Q16,S16,U16,W16,Y16,AA16) -> 14573 | AD16: =SUM(F16,H16,J16,L16,N16,P16,R16,T16,V16,X16,Z16,AB16) -> 55109982 | AE16: 0 | AF16: 0 | AG16: 0 | AH16: 0 | AI16: 0 | AJ16: 0 | AK16: 0 | AL16: 0 | AM16: 0 | AN16: 0 | AO16: 0 | AP16: 0 | AQ16: =SUM(AE16:AP16) -> 0 | AR16: 0 | AS16: 0 | AT16: 0 | AU16: 0 | AV16: 0 | AW16: 0 | AX16: 0 | AY16: 0 | AZ16: 0 | BA16: 0 | BB16: 0 | BC16: 0 | BD16: =SUM(AR16:BC16) -> 0
... A51: 4.기타 | B51: MEP | C51: Molding Tool | D51: =AD51+AQ51+BD51 -> 102761343 | E51: 3 | F51: 0 | G51: 3 | H51: 0 | I51: 2 | J51: 0 | K51: 2 | L51: 0 | M51: 3 | N51: 0 | O51: 4 | P51: 0 | Q51: 2 | R51: 0 | S51: 3 | T51: 0 | U51: 3 | V51: 0 | W51: 5 | X51: 0 | Y51: 1 | Z51: 0 | AA51: 2 | AB51: 0 | AC51: =SUM(E51,G51,I51,K51,M51,O51,Q51,S51,U51,W51,Y51,AA51) -> 33 | AD51: =SUM(F51,H51,J51,L51,N51,P51,R51,T51,V51,X51,Z51,AB51) -> 0 | AE51: 11446800 | AF51: 12106998 | AG51: 1540680 | AH51: 2116520 | AI51: 994000 | AJ51: 11490240 | AK51: 2790500 | AL51: 1301050 | AM51: 4338950 | AN51: 49023005 | AO51: 732600 | AP51: 4880000 | AQ51: =SUM(AE51:AP51) -> 102761343 | AR51: 0 | AS51: 0 | AT51: 0 | AU51: 0 | AV51: 0 | AW51: 0 | AX51: 0 | AY51: 0 | AZ51: 0 | BA51: 0 | BB51: 0 | BC51: 0 | BD51: =SUM(AR51:BC51) -> 0
A52: 4.기타 | C52: 미지정 | D52: =AD52+AQ52+BD52 -> -30876300 | E52: 0 | F52: 0 | G52: 0 | H52: 0 | I52: 0 | J52: 0 | K52: 0 | L52: 0 | M52: 0 | N52: 0 | O52: 1050000 | P52: 0 | Q52: 0 | R52: 0 | S52: 0 | T52: 0 | U52: 0 | V52: 0 | W52: 0 | X52: 0 | Y52: 0 | Z52: 0 | AA52: 0 | AB52: 0 | AC52: =SUM(E52,G52,I52,K52,M52,O52,Q52,S52,U52,W52,Y52,AA52) -> 1050000 | AD52: =SUM(F52,H52,J52,L52,N52,P52,R52,T52,V52,X52,Z52,AB52) -> 0 | AE52: 0 | AF52: 0 | AG52: 0 | AH52: 0 | AI52: 0 | AJ52: 0 | AK52: 0 | AL52: 0 | AM52: 0 | AN52: 0 | AO52: 0 | AP52: 0 | AQ52: =SUM(AE52:AP52) -> 0 | AR52: -6029600 | AS52: -27739700 | AT52: -59498100 | AU52: -53553800 | AV52: -145085400 | AW52: -84157900 | AX52: -34000200 | AY52: -3492700 | AZ52: 19925300 | BA52: 88931500 | BB52: 126084100 | BC52: 147740200 | BD52: =SUM(AR52:BC52) -> -30876300
B53: 총계 | D53: =SUBTOTAL(9,D5:D52) -> 528569510350 | E53: =SUBTOTAL(9,E5:E52) -> 86683652 | F53: =SUBTOTAL(9,F5:F52) -> 40708099996 | G53: =SUBTOTAL(9,G5:G52) -> 101549519 | H53: =SUBTOTAL(9,H5:H52) -> 43747582185 | I53: =SUBTOTAL(9,I5:I52) -> 131647549 | J53: =SUBTOTAL(9,J5:J52) -> 45739498620 | K53: =SUBTOTAL(9,K5:K52) -> 84342407 | ... BD53: =SUBTOTAL(9,BD5:BD52) -> 7729216634
A55: 1.HMI | D55: =SUMIF($A$5:$A$52,$A55,D$5:D$52) -> 350442096639 | E55: =SUMIF($A$5:$A$52,$A55,E$5:E$52) -> 48644128 | F55: =SUMIF($A$5:$A$52,$A55,F$5:F$52) -> 26702868709 | G55: =SUMIF($A$5:$A$52,$A55,G$5:G$52) -> 60491111 | H55: =SUMIF($A$5:$A$52,$A55,H$5:H$52) -> 28913849601 | I55: =SUMIF($A$5:$A$52,$A55,I$5:I$52) -> 87511441 | J55: =SUMIF($A$5:$A$52,$A55,J$5:J$52) -> 29879933884 | K55: =SUMIF($A$5:$A$52,$A55,K$5:K$52) -> 49016061 | ... BD55: =SUMIF($A$5:$A$52,$A55,BD$5:BD$52) -> 6141670819
A56: 2.BCS | D56: =SUMIF($A$5:$A$52,$A56,D$5:D$52) -> 61089704286 | E56: =SUMIF($A$5:$A$52,$A56,E$5:E$52) -> 878562 | F56: =SUMIF($A$5:$A$52,$A56,F$5:F$52) -> 5036240325 | G56: =SUMIF($A$5:$A$52,$A56,G$5:G$52) -> 961443 | H56: =SUMIF($A$5:$A$52,$A56,H$5:H$52) -> 5416575401 | I56: =SUMIF($A$5:$A$52,$A56,I$5:I$52) -> 623945 | J56: =SUMIF($A$5:$A$52,$A56,J$5:J$52) -> 4921961955 | K56: =SUMIF($A$5:$A$52,$A56,K$5:K$52) -> 865750 | ... BD56: =SUMIF($A$5:$A$52,$A56,BD$5:BD$52) -> 96562149
A57: 3.MC | D57: =SUMIF($A$5:$A$52,$A57,D$5:D$52) -> 113462074158 | E57: =SUMIF($A$5:$A$52,$A57,E$5:E$52) -> 13120699 | F57: =SUMIF($A$5:$A$52,$A57,F$5:F$52) -> 8883478827 | G57: =SUMIF($A$5:$A$52,$A57,G$5:G$52) -> 17394454 | H57: =SUMIF($A$5:$A$52,$A57,H$5:H$52) -> 9345041174 | I57: =SUMIF($A$5:$A$52,$A57,I$5:I$52) -> 21556495 | J57: =SUMIF($A$5:$A$52,$A57,J$5:J$52) -> 10852348848 | K57: =SUMIF($A$5:$A$52,$A57,K$5:K$52) -> 17602936 | ... BD57: =SUMIF($A$5:$A$52,$A57,BD$5:BD$52) -> 443462524
A58: 4.기타 | D58: =SUMIF($A$5:$A$52,$A58,D$5:D$52) -> 3575635267 | E58: =SUMIF($A$5:$A$52,$A58,E$5:E$52) -> 24040263 | F58: =SUMIF($A$5:$A$52,$A58,F$5:F$52) -> 85512135 | G58: =SUMIF($A$5:$A$52,$A58,G$5:G$52) -> 22702511 | H58: =SUMIF($A$5:$A$52,$A58,H$5:H$52) -> 72116009 | I58: =SUMIF($A$5:$A$52,$A58,I$5:I$52) -> 21955668 | J58: =SUMIF($A$5:$A$52,$A58,J$5:J$52) -> 85253933 | K58: =SUMIF($A$5:$A$52,$A58,K$5:K$52) -> 16857660 | ... BD58: =SUMIF($A$5:$A$52,$A58,BD$5:BD$52) -> 1047521142
A59: 총계 | D59: =SUM(D55:D58) -> 528569510350 | E59: =SUM(E55:E58) -> 86683652 | F59: =SUM(F55:F58) -> 40708099996 | G59: =SUM(G55:G58) -> 101549519 | H59: =SUM(H55:H58) -> 43747582185 | I59: =SUM(I55:I58) -> 131647549 | J59: =SUM(J55:J58) -> 45739498620 | K59: =SUM(K55:K58) -> 84342407 | ... BD59: =SUM(BD55:BD58) -> 7729216634

Sheet KE30_2013년
A1: 2013년 자재그룹별 월별손익실적 Report
A2: 사업구분 | B2: 자재그룹3 | C2: 재재그룹3내역 | E2: 제품(상품)매출 | AE2: 설비매출 | AR2: 기타매출
D3: 전체 | E3: 1월 | G3: 2월 | I3: 3월 | K3: 4월 | M3: 5월 | O3: 6월 | Q3: 7월 | S3: 8월 | U3: 9월 | W3: 10월 | Y3: 11월 | AA3: 12월 | AC3: 합계
D4: 매출액 | E4: 수량 | F4: 매출액 | G4: 수량 | H4: 매출액 | I4: 수량 | J4: 매출액 | K4: 수량 | L4: 매출액 | M4: 수량 | N4: 매출액 | O4: 수량 | P4: 매출액 | Q4: 수량 | R4: 매출액 | S4: 수량 | T4: 매출액 | U4: 수량 | V4: 매출액 | W4: 수량 | X4: 매출액 | Y4: 수량 | Z4: 매출액 | AA4: 수량 | AB4: 매출액 | AC4: 수량 | AD4: 매출액 | AE4: 1월 | AF4: 2월 | AG4: 3월 | AH4: 4월 | AI4: 5월 | AJ4: 6월 | AK4: 7월 | AL4: 8월 | AM4: 9월 | AN4: 10월 | AO4: 11월 | AP4: 12월 | AQ4: 합계 | AR4: 1월 | AS4: 2월 | AT4: 3월 | AU4: 4월 | AV4: 5월 | AW4: 6월 | AX4: 7월 | AY4: 8월 | AZ4: 9월 | BA4: 10월 | BB4: 11월 | BC4: 12월 | BD4: 합계
A5: 1.HMI | B5: AUD | C5: Audio SW Assy | D5: =AD5+AQ5+BD5 -> 16461322 | E5: 0 | F5: 0 | G5: 0 | H5: 0 | I5: 0 | J5: 0 | K5: 0 | L5: 0 | M5: 0 | N5: 0 | O5: 0 | P5: 0 | Q5: 0 | R5: 0 | S5: 0 | T5: 0 | U5: 19748 | V5: 6414814 | W5: 1500 | X5: 74224 | Y5: 29586 | Z5: 8892476 | AA5: 2931 | AB5: 1079808 | AC5: =SUM(E5,G5,I5,K5,M5,O5,Q5,S5,U5,W5,Y5,AA5) -> 53765 | AD5: =SUM(F5,H5,J5,L5,N5,P5,R5,T5,V5,X5,Z5,AB5) -> 16461322 | AE5: 0 | AF5: 0 | AG5: 0 | AH5: 0 | AI5: 0 | AJ5: 0 | AK5: 0 | AL5: 0 | AM5: 0 | AN5: 0 | AO5: 0 | AP5: 0 | AQ5: =SUM(AE5:AP5) -> 0 | AR5: 0 | AS5: 0 | AT5: 0 | AU5: 0 | AV5: 0 | AW5: 0 | AX5: 0 | AY5: 0 | AZ5: 0 | BA5: 0 | BB5: 0 | BC5: 0 | BD5: =SUM(AR5:BC5) -> 0
A6: 1.HMI | B6: RLP | C6: Interior Lamp | D6: =AD6+AQ6+BD6 -> 52294228059 | E6: 1304892 | F6: 4198657606 | G6: 1050090 | H6: 4305059704 | I6: 1135376 | J6: 4232932559 | K6: 1159866 | L6: 4123128031 | M6: 1161115 | N6: 4377901255 | O6: 1154089 | P6: 4305065433 | Q6: 1065468 | R6: 4210677263 | S6: 953500 | T6: 4034339247 | U6: 909860 | V6: 4416025452 | W6: 1086360 | X6: 4761467371 | Y6: 1173653 | Z6: 4731546516 | AA6: 986777 | AB6: 4597427622 | AC6: =SUM(E6,G6,I6,K6,M6,O6,Q6,S6,U6,W6,Y6,AA6) -> 13141046 | AD6: =SUM(F6,H6,J6,L6,N6,P6,R6,T6,V6,X6,Z6,AB6) -> 52294228059 | AE6: 0 | AF6: 0 | AG6: 0 | AH6: 0 | AI6: 0 | AJ6: 0 | AK6: 0 | AL6: 0 | AM6: 0 | AN6: 0 | AO6: 0 | AP6: 0 | AQ6: =SUM(AE6:AP6) -> 0 | AR6: 0 | AS6: 0 | AT6: 0 | AU6: 0 | AV6: 0 | AW6: 0 | AX6: 0 | AY6: 0 | AZ6: 0 | BA6: 0 | BB6: 0 | BC6: 0 | BD6: =SUM(AR6:BC6) -> 0
A7: 1.HMI | B7: SGS | C7: Gear Shift Module | D7: =AD7+AQ7+BD7 -> 34294026 | E7: 10 | F7: 3060000 | G7: 8 | H7: 1360000 | I7: 20 | J7: 3400000 | K7: 20 | L7: 3015000 | M7: 18 | N7: 3418000 | O7: 0 | P7: 2 | Q7: 21 | R7: 3531000 | S7: 10 | T7: 1731006 | U7: 30 | V7: 5100000 | W7: 35 | X7: 5755010 | Y7: 4 | Z7: 524020 | AA7: 20 | AB7: 3399988 | AC7: =SUM(E7,G7,I7,K7,M7,O7,Q7,S7,U7,W7,Y7,AA7) -> 196 | AD7: =SUM(F7,H7,J7,L7,N7,P7,R7,T7,V7,X7,Z7,AB7) -> 34294026 | AE7: 0 | AF7: 0 | AG7: 0 | AH7: 0 | AI7: 0 | AJ7: 0 | AK7: 0 | AL7: 0 | AM7: 0 | AN7: 0 | AO7: 0 | AP7: 0 | AQ7: =SUM(AE7:AP7) -> 0 | AR7: 0 | AS7: 0 | AT7: 0 | AU7: 0 | AV7: 0 | AW7: 0 | AX7: 0 | AY7: 0 | AZ7: 0 | BA7: 0 | BB7: 0 | BC7: 0 | BD7: =SUM(AR7:BC7) -> 0
A8: 1.HMI | B8: SHT | C8: Haptic Switch | D8: =AD8+AQ8+BD8 -> 349302176 | E8: 1203 | F8: 52478970 | G8: 455 | H8: 19266334 | I8: 370 | J8: -3767976 | K8: 736 | L8: 52063432 | M8: 1048 | N8: 41842264 | O8: 676 | P8: 28691712 | Q8: 695 | R8: 44243568 | S8: 499 | T8: 20739252 | U8: 553 | V8: 20744879 | W8: 560 | X8: 22952113 | Y8: 413 | Z8: 17416012 | AA8: 768 | AB8: 32631616 | AC8: =SUM(E8,G8,I8,K8,M8,O8,Q8,S8,U8,W8,Y8,AA8) -> 7976 | AD8: =SUM(F8,H8,J8,L8,N8,P8,R8,T8,V8,X8,Z8,AB8) -> 349302176 | AE8: 0 | AF8: 0 | AG8: 0 | AH8: 0 | AI8: 0 | AJ8: 0 | AK8: 0 | AL8: 0 | AM8: 0 | AN8: 0 | AO8: 0 | AP8: 0 | AQ8: =SUM(AE8:AP8) -> 0 | AR8: 0 | AS8: 0 | AT8: 0 | AU8: 0 | AV8: 0 | AW8: 0 | AX8: 0 | AY8: 0 | AZ8: 0 | BA8: 0 | BB8: 0 | BC8: 0 | BD8: =SUM(AR8:BC8) -> 0
A9: 1.HMI | B9: SIH | C9: Inhibitor Switch | D9: =AD9+AQ9+BD9 -> 23607295007 | E9: 2369692 | F9: 1988896450 | G9: 1005734 | H9: 1510124208 | I9: 1630870 | J9: 1742965627 | K9: 2733717 | L9: 1842453219 | M9: 1042624 | N9: 1943848911 | O9: 748537 | P9: 1867707291 | Q9: 2129381 | R9: 2127029138 | S9: 2520519 | T9: 2666040302 | U9: 1538056 | V9: 2225510877 | W9: 1975111 | X9: 2506726248 | Y9: 2789704 | Z9: 1465620441 | AA9: 2332534 | AB9: 1611731433 | AC9: =SUM(E9,G9,I9,K9,M9,O9,Q9,S9,U9,W9,Y9,AA9) -> 22816479 | AD9: =SUM(F9,H9,J9,L9,N9,P9,R9,T9,V9,X9,Z9,AB9) -> 23498654145 | AE9: 0 | AF9: 0 | AG9: 0 | AH9: 0 | AI9: 0 | AJ9: 0 | AK9: 0 | AL9: 0 | AM9: 0 | AN9: 0 | AO9: 0 | AP9: 0 | AQ9: =SUM(AE9:AP9) -> 0 | AR9: 8831427 | AS9: 3606446 | AT9: 6895110 | AU9: 10352249 | AV9: 4455173 | AW9: 1347638 | AX9: 10777455 | AY9: 15334104 | AZ9: 7667363 | BA9: 8859702 | BB9: 15801843 | BC9: 14712352 | BD9: =SUM(AR9:BC9) -> 108640862
A10: 1.HMI | B10: SIP | C10: In Panel Switch | D10: =AD10+AQ10+BD10 -> 93519027902 | E10: 27125198 | F10: 7330129478 | G10: 16616136 | H10: 5488579776 | I10: 27607414 | J10: 8040233898 | K10: 19622712 | L10: 6910038058 | M10: 21112173 | N10: 7195521210 | O10: 17117665 | P10: 7447103871 | Q10: 18911228 | R10: 7115883040 | S10: 19011817 | T10: 6879090903 | U10: 18793938 | V10: 6874427201 | W10: 24802674 | X10: 8302417168 | Y10: 30060276 | Z10: 8060982402 | AA10: 24669347 | AB10: 8915635098 | AC10: =SUM(E10,G10,I10,K10,M10,O10,Q10,S10,U10,W10,Y10,AA10) -> 265450578 | AD10: =SUM(F10,H10,J10,L10,N10,P10,R10,T10,V10,X10,Z10,AB10) -> 88560042103 | AE10: 0 | AF10: 0 | AG10: 0 | AH10: 0 | AI10: 0 | AJ10: 0 | AK10: 0 | AL10: 0 | AM10: 0 | AN10: 0 | AO10: 0 | AP10: 0 | AQ10: =SUM(AE10:AP10) -> 0 | AR10: 384147210 | AS10: 311861153 | AT10: 300582673 | AU10: 266547198 | AV10: 332928330 | AW10: 350269220 | AX10: 441877271 | AY10: 446305621 | AZ10: 378150459 | BA10: 787164243 | BB10: 495389261 | BC10: 463763160 | BD10: =SUM(AR10:BC10) -> 4958985799
A11: 1.HMI | B11: SMF | C11: Muti Function Switch | D11: =AD11+AQ11+BD11 -> 63953738859 | E11: 14802933 | F11: 5289865072 | G11: 9339032 | H11: 4142389369 | I11: 10792485 | J11: 4345139460 | K11: 14404760 | L11: 5070421802 | M11: 14235142 | N11: 4890012012 | O11: 12760137 | P11: 4927096967 | Q11: 17805969 | R11: 5080950686 | S11: 19177843 | T11: 5799485027 | U11: 21119748 | V11: 5339459981 | W11: 16672946 | X11: 6024609471 | Y11: 16215562 | Z11: 5955384128 | AA11: 20348693 | AB11: 6189133082 | AC11: =SUM(E11,G11,I11,K11,M11,O11,Q11,S11,U11,W11,Y11,AA11) -> 187675250 | AD11: =SUM(F11,H11,J11,L11,N11,P11,R11,T11,V11,X11,Z11,AB11) -> 63053947057 | AE11: 0 | AF11: 0 | AG11: 0 | AH11: 0 | AI11: 0 | AJ11: 0 | AK11: 0 | AL11: 0 | AM11: 0 | AN11: 0 | AO11: 0 | AP11: 0 | AQ11: =SUM(AE11:AP11) -> 0 | AR11: 76929380 | AS11: 53725525 | AT11: 78260835 | AU11: 61125033 | AV11: 63756368 | AW11: 52211182 | AX11: 35639719 | AY11: 67657820 | AZ11: 122268623 | BA11: 89717561 | BB11: 110209126 | BC11: 88290630 | BD11: =SUM(AR11:BC11) -> 899791802
A12: 1.HMI | B12: SPW | C12: Power Window Switch | D12: =AD12+AQ12+BD12 -> 92625554786 | E12: 70777498 | F12: 7811017021 | G12: 34462267 | H12: 7194267113 | I12: 70251233 | J12: 7436666759 | K12: 59658413 | L12: 7704060342 | M12: 48123826 | N12: 7340796375 | O12: 39330354 | P12: 7598389741 | Q12: 55736523 | R12: 7165613757 | S12: 64216378 | T12: 6137206794 | U12: 46168214 | V12: 6074938879 | W12: 69351306 | X12: 7436979422 | Y12: 65519908 | Z12: 7881156510 | AA12: 58433676 | AB12: 8455024476 | AC12: =SUM(E12,G12,I12,K12,M12,O12,Q12,S12,U12,W12,Y12,AA12) -> 682029596 | AD12: =SUM(F12,H12,J12,L12,N12,P12,R12,T12,V12,X12,Z12,AB12) -> 88236117189 | AE12: 0 | AF12: 0 | AG12: 0 | AH12: 0 | AI12: 0 | AJ12: 0 | AK12: 0 | AL12: 0 | AM12: 0 | AN12: 0 | AO12: 0 | AP12: 0 | AQ12: =SUM(AE12:AP12) -> 0 | AR12: 343232165 | AS12: 255795476 | AT12: 375986899 | AU12: 378183763 | AV12: 329752616 | AW12: 269974844 | AX12: 378701845 | AY12: 376108880 | AZ12: 360207058 | BA12: 498913709 | BB12: 444957973 | BC12: 377622369 | BD12: =SUM(AR12:BC12) -> 4389437597
A13: 1.HMI | B13: SRM | C13: Remocon Switch | D13: =AD13+AQ13+BD13 -> 51035830487 | E13: 918298 | F13: 4539980886 | G13: 914110 | H13: 4263796903 | I13: 891917 | J13: 4007592683 | K13: 931767 | L13: 4117581933 | M13: 987939 | N13: 4076029234 | O13: 1217429 | P13: 4447220076 | Q13: 1205267 | R13: 4243028904 | S13: 1192874 | T13: 3688240557 | U13: 1531652 | V13: 3489271860 | W13: 1272254 | X13: 4480646546 | Y13: 735306 | Z13: 4664239249 | AA13: 1073954 | AB13: 5018201656 | AC13: =SUM(E13,G13,I13,K13,M13,O13,Q13,S13,U13,W13,Y13,AA13) -> 12872767 | AD13: =SUM(F13,H13,J13,L13,N13,P13,R13,T13,V13,X13,Z13,AB13) -> 51035830487 | AE13: 0 | AF13: 0 | AG13: 0 | AH13: 0 | AI13: 0 | AJ13: 0 | AK13: 0 | AL13: 0 | AM13: 0 | AN13: 0 | AO13: 0 | AP13: 0 | AQ13: =SUM(AE13:AP13) -> 0 | AR13: 0 | AS13: 0 | AT13: 0 | AU13: 0 | AV13: 0 | AW13: 0 | AX13: 0 | AY13: 0 | AZ13: 0 | BA13: 0 | BB13: 0 | BC13: 0 | BD13: =SUM(AR13:BC13) -> 0
A14: 1.HMI | B14: SSM | C14: Micro Switch | D14: =AD14+AQ14+BD14 -> 140959 | E14: 0 | F14: 0 | G14: 0 | H14: 0 | I14: 0 | J14: 0 | K14: 0 | L14: 0 | M14: 0 | N14: 0 | O14: 0 | P14: 0 | Q14: 0 | R14: 0 | S14: 0 | T14: 0 | U14: 0 | V14: -715500 | W14: 720 | X14: 2432 | Y14: 62 | Z14: 686 | AA14: 17379 | AB14: 762755 | AC14: =SUM(E14,G14,I14,K14,M14,O14,Q14,S14,U14,W14,Y14,AA14) -> 18161 | AD14: =SUM(F14,H14,J14,L14,N14,P14,R14,T14,V14,X14,Z14,AB14) -> 50373 | AE14: 0 | AF14: 0 | AG14: 0 | AH14: 0 | AI14: 0 | AJ14: 0 | AK14: 0 | AL14: 0 | AM14: 0 | AN14: 0 | AO14: 0 | AP14: 0 | AQ14: =SUM(AE14:AP14) -> 0 | AR14: 0 | AS14: 0 | AT14: 0 | AU14: 0 | AV14: 0 | AW14: 0 | AX14: 0 | AY14: 0 | AZ14: 0 | BA14: 0 | BB14: 0 | BC14: 90586 | BD14: =SUM(AR14:BC14) -> 90586
A15: 1.HMI | B15: SSW | C15: General Switch | D15: =AD15+AQ15+BD15 -> 3072405420 | E15: 1864872 | F15: 316248353 | G15: 1464776 | H15: 343234017 | I15: 1361232 | J15: 312653701 | K15: 1247907 | L15: 331927190 | M15: 710413 | N15: 262424847 | O15: 1786247 | P15: 254633393 | Q15: 439827 | R15: 210499545 | S15: 1479448 | T15: 270709017 | U15: 847617 | V15: 237942102 | W15: 431289 | X15: 218751091 | Y15: 668460 | Z15: 157125196 | AA15: 637386 | AB15: 115057192 | AC15: =SUM(E15,G15,I15,K15,M15,O15,Q15,S15,U15,W15,Y15,AA15) -> 12939474 | AD15: =SUM(F15,H15,J15,L15,N15,P15,R15,T15,V15,X15,Z15,AB15) -> 3031205644 | AE15: 0 | AF15: 0 | AG15: 0 | AH15: 0 | AI15: 0 | AJ15: 0 | AK15: 0 | AL15: 0 | AM15: 0 | AN15: 0 | AO15: 0 | AP15: 0 | AQ15: =SUM(AE15:AP15) -> 0 | AR15: 516668 | AS15: 0 | AT15: 0 | AU15: 9585137 | AV15: 1892459 | AW15: 40000 | AX15: 2598551 | AY15: 5184599 | AZ15: 14728596 | BA15: 1834972 | BB15: 4805838 | BC15: 12956 | BD15: =SUM(AR15:BC15) -> 41199776
A16: 2.BCS | B16: BCM | C16: Body Control Module | D16: =AD16+AQ16+BD16 -> 2158392511 | E16: 0 | F16: 0 | G16: 0 | H16: 0 | I16: 0 | J16: 0 | K16: 0 | L16: 0 | M16: -54396 | N16: -959197 | O16: 8400 | P16: 421129980 | Q16: 0 | R16: 0 | S16: 0 | T16: 0 | U16: 12500 | V16: 620582392 | W16: 11506 | X16: 564191122 | Y16: 0 | Z16: 0 | AA16: 11996 | AB16: 553448214 | AC16: =SUM(E16,G16,I16,K16,M16,O16,Q16,S16,U16,W16,Y16,AA16) -> -9994 | AD16: =SUM(F16,H16,J16,L16,N16,P16,R16,T16,V16,X16,Z16,AB16) -> 2158392511 | AE16: 0 | AF16: 0 | AG16: 0 | AH16: 0 | AI16: 0 | AJ16: 0 | AK16: 0 | AL16: 0 | AM16: 0 | AN16: 0 | AO16: 0 | AP16: 0 | AQ16: =SUM(AE16:AP16) -> 0 | AR16: 0 | AS16: 0 | AT16: 0 | AU16: 0 | AV16: 0 | AW16: 0 | AX16: 0 | AY16: 0 | AZ16: 0 | BA16: 0 | BB16: 0 | BC16: 0 | BD16: =SUM(AR16:BC16) -> 0
... A52: 4.기타 | B52: MEP | C52: Molding Tool | D52: =AD52+AQ52+BD52 -> 1006263545 | E52: 1 | F52: 0 | G52: 0 | H52: 0 | I52: 2 | J52: 0 | K52: 1 | L52: 0 | M52: 0 | N52: 0 | O52: 2 | P52: 0 | Q52: 1 | R52: 0 | S52: 7 | T52: 0 | U52: 9 | V52: 0 | W52: 2 | X52: 0 | Y52: 2 | Z52: 0 | AA52: 1 | AB52: 0 | AC52: =SUM(E52,G52,I52,K52,M52,O52,Q52,S52,U52,W52,Y52,AA52) -> 28 | AD52: =SUM(F52,H52,J52,L52,N52,P52,R52,T52,V52,X52,Z52,AB52) -> 0 | AE52: 3038300 | AF52: 0 | AG52: 20011871 | AH52: 257930 | AI52: 0 | AJ52: 464324 | AK52: 424670 | AL52: 355282036 | AM52: 494056918 | AN52: 66857471 | AO52: 20092010 | AP52: 45778015 | AQ52: =SUM(AE52:AP52) -> 1006263545 | AR52: 0 | AS52: 0 | AT52: 0 | AU52: 0 | AV52: 0 | AW52: 0 | AX52: 0 | AY52: 0 | AZ52: 0 | BA52: 0 | BB52: 0 | BC52: 0 | BD52: =SUM(AR52:BC52) -> 0
A53: 4.기타 | C53: 미지정 | D53: =AD53+AQ53+BD53 -> 2097108184 | E53: 0 | F53: 0 | G53: 0 | H53: 0 | I53: 0 | J53: 0 | K53: 0 | L53: 0 | M53: 0 | N53: 0 | O53: 0 | P53: 0 | Q53: 0 | R53: 0 | S53: 0 | T53: 0 | U53: 204 | V53: 4742184 | W53: 0 | X53: 0 | Y53: 0 | Z53: 0 | AA53: 0 | AB53: 0 | AC53: =SUM(E53,G53,I53,K53,M53,O53,Q53,S53,U53,W53,Y53,AA53) -> 204 | AD53: =SUM(F53,H53,J53,L53,N53,P53,R53,T53,V53,X53,Z53,AB53) -> 4742184 | AE53: 0 | AF53: 0 | AG53: 0 | AH53: 0 | AI53: 0 | AJ53: 0 | AK53: 0 | AL53: 0 | AM53: 0 | AN53: 0 | AO53: 0 | AP53: 0 | AQ53: =SUM(AE53:AP53) -> 0 | AR53: 243072000 | AS53: 200267000 | AT53: 130852000 | AU53: 115757000 | AV53: 46667000 | AW53: -75073000 | AX53: 91212000 | AY53: 80332000 | AZ53: 277570000 | BA53: 313260000 | BB53: 335390000 | BC53: 333060000 | BD53: =SUM(AR53:BC53) -> 2092366000
B54: 총계 | D54: =SUBTOTAL(9,D5:D53) -> 547732601421 | E54: =SUBTOTAL(9,E5:E53) -> 193770288 | F54: =SUBTOTAL(9,F5:F53) -> 45333802628 | G54: =SUBTOTAL(9,G5:G53) -> 111533446 | H54: =SUBTOTAL(9,H5:H53) -> 39217568814 | I54: =SUBTOTAL(9,I5:I53) -> 167929361 | J54: =SUBTOTAL(9,J5:J53) -> 43634787801 | K54: =SUBTOTAL(9,K5:K53) -> 158345174 | ... BD54: =SUBTOTAL(9,BD5:BD53) -> 15245418497
A56: 1.HMI | D56: =SUMIF($A$5:$A$53,$A56,D$5:D$53) -> 380508279003 | E56: =SUMIF($A$5:$A$53,$A56,E$5:E$53) -> 119164596 | F56: =SUMIF($A$5:$A$53,$A56,F$5:F$53) -> 31530333836 | G56: =SUMIF($A$5:$A$53,$A56,G$5:G$53) -> 64852608 | H56: =SUMIF($A$5:$A$53,$A56,H$5:H$53) -> 27268077424 | I56: =SUMIF($A$5:$A$53,$A56,I$5:I$53) -> 113670917 | J56: =SUMIF($A$5:$A$53,$A56,J$5:J$53) -> 30117816711 | K56: =SUMIF($A$5:$A$53,$A56,K$5:K$53) -> 99759898 | ... BD56: =SUMIF($A$5:$A$53,$A56,BD$5:BD$53) -> 10398146422
A57: 2.BCS | D57: =SUMIF($A$5:$A$53,$A57,D$5:D$53) -> 61363157093 | E57: =SUMIF($A$5:$A$53,$A57,E$5:E$53) -> 894449 | F57: =SUMIF($A$5:$A$53,$A57,F$5:F$53) -> 4941938252 | G57: =SUMIF($A$5:$A$53,$A57,G$5:G$53) -> 764803 | H57: =SUMIF($A$5:$A$53,$A57,H$5:H$53) -> 4584345638 | I57: =SUMIF($A$5:$A$53,$A57,I$5:I$53) -> 611287 | J57: =SUMIF($A$5:$A$53,$A57,J$5:J$53) -> 5020135704 | K57: =SUMIF($A$5:$A$53,$A57,K$5:K$53) -> 829909 | ... BD57: =SUMIF($A$5:$A$53,$A57,BD$5:BD$53) -> 61205618
A58: 3.MC | D58: =SUMIF($A$5:$A$53,$A58,D$5:D$53) -> 97513231444 | E58: =SUMIF($A$5:$A$53,$A58,E$5:E$53) -> 22343622 | F58: =SUMIF($A$5:$A$53,$A58,F$5:F$53) -> 8800511445 | G58: =SUMIF($A$5:$A$53,$A58,G$5:G$53) -> 18314010 | H58: =SUMIF($A$5:$A$53,$A58,H$5:H$53) -> 7365145752 | I58: =SUMIF($A$5:$A$53,$A58,I$5:I$53) -> 16290150 | J58: =SUMIF($A$5:$A$53,$A58,J$5:J$53) -> 8496835386 | K58: =SUMIF($A$5:$A$53,$A58,K$5:K$53) -> 17403362 | ... BD58: =SUMIF($A$5:$A$53,$A58,BD$5:BD$53) -> 432419296
A59: 4.기타 | D59: =SUMIF($A$5:$A$53,$A59,D$5:D$53) -> 8347933881 | E59: =SUMIF($A$5:$A$53,$A59,E$5:E$53) -> 51367621 | F59: =SUMIF($A$5:$A$53,$A59,F$5:F$53) -> 61019095 | G59: =SUMIF($A$5:$A$53,$A59,G$5:G$53) -> 27602025 | H59: =SUMIF($A$5:$A$53,$A59,H$5:H$53) -> 0 | I59: =SUMIF($A$5:$A$53,$A59,I$5:I$53) -> 37357007 | J59: =SUMIF($A$5:$A$53,$A59,J$5:J$53) -> 0 | K59: =SUMIF($A$5:$A$53,$A59,K$5:K$53) -> 40352005 | ... BD59: =SUMIF($A$5:$A$53,$A59,BD$5:BD$53) -> 4353647161
A60: 총계 | D60: =SUM(D56:D59) -> 547732601421 | E60: =SUM(E56:E59) -> 193770288 | F60: =SUM(F56:F59) -> 45333802628 | G60: =SUM(G56:G59) -> 111533446 | H60: =SUM(H56:H59) -> 39217568814 | I60: =SUM(I56:I59) -> 167929361 | J60: =SUM(J56:J59) -> 43634787801 | K60: =SUM(K56:K59) -> 158345174 | ... BD60: =SUM(BD56:BD59) -> 15245418497

Sheet KE30_2014년
A1: 2014년 자재그룹별 월별손익실적 Report
A2: 사업구분 | B2: 자재그룹3 | C2: 재재그룹3내역 | E2: 제품(상품)매출 | AE2: 설비매출 | AR2: 기타매출
D3: 전체 | E3: 1월 | G3: 2월 | I3: 3월 | K3: 4월 | M3: 5월 | O3: 6월 | Q3: 7월 | S3: 8월 | U3: 9월 | W3: 10월 | Y3: 11월 | AA3: 12월 | AC3: 합계
D4: 매출액 | E4: 수량 | F4: 매출액 | G4: 수량 | H4: 매출액 | I4: 수량 | J4: 매출액 | K4: 수량 | L4: 매출액 | M4: 수량 | N4: 매출액 | O4: 수량 | P4: 매출액 | Q4: 수량 | R4: 매출액 | S4: 수량 | T4: 매출액 | U4: 수량 | V4: 매출액 | W4: 수량 | X4: 매출액 | Y4: 수량 | Z4: 매출액 | AA4: 수량 | AB4: 매출액 | AC4: 수량 | AD4: 매출액 | AE4: 1월 | AF4: 2월 | AG4: 3월 | AH4: 4월 | AI4: 5월 | AJ4: 6월 | AK4: 7월 | AL4: 8월 | AM4: 9월 | AN4: 10월 | AO4: 11월 | AP4: 12월 | AQ4: 합계 | AR4: 1월 | AS4: 2월 | AT4: 3월 | AU4: 4월 | AV4: 5월 | AW4: 6월 | AX4: 7월 | AY4: 8월 | AZ4: 9월 | BA4: 10월 | BB4: 11월 | BC4: 12월 | BD4: 합계
A5: 1.HMI | B5: AUD | C5: Audio SW Assy | D5: =AD5+AQ5+BD5 -> 2972834598 | E5: 47970 | F5: 5124564 | G5: 75043 | H5: 6420908 | I5: 2962 | J5: 1133871 | K5: 8213 | L5: 6525627 | M5: 67284 | N5: 21479617 | O5: 445700 | P5: 138318216 | Q5: 1042390 | R5: 375153245 | S5: 1254683 | T5: 424833840 | U5: 1490087 | V5: 256689907 | W5: 2093442 | X5: 535260643 | Y5: 761547 | Z5: 410534677 | AA5: 2274848 | AB5: 659588931 | AC5: =SUM(E5,G5,I5,K5,M5,O5,Q5,S5,U5,W5,Y5,AA5) -> 9564169 | AD5: =SUM(F5,H5,J5,L5,N5,P5,R5,T5,V5,X5,Z5,AB5) -> 2841064046 | AE5: 0 | AF5: 0 | AG5: 0 | AH5: 0 | AI5: 0 | AJ5: 0 | AK5: 0 | AL5: 0 | AM5: 0 | AN5: 0 | AO5: 0 | AP5: 0 | AQ5: =SUM(AE5:AP5) -> 0 | AR5: 0 | AS5: 7730239 | AT5: 0 | AU5: 0 | AV5: 0 | AW5: 374344 | AX5: 5248876 | AY5: 0 | AZ5: 5030850 | BA5: 48324476 | BB5: 31833848 | BC5: 33227919 | BD5: =SUM(AR5:BC5) -> 131770552
A6: 1.HMI | B6: RLP | C6: Interior Lamp | D6: =AD6+AQ6+BD6 -> 57825467801 | E6: 1110179 | F6: 4312438278 | G6: 994966 | H6: 4004825026 | I6: 1143783 | J6: 4788039246 | K6: 1308554 | L6: 5623348223 | M6: 1095815 | N6: 4203639341 | O6: 1178180 | P6: 5309508145 | Q6: 1297706 | R6: 5679744697 | S6: 906428 | T6: 3990989722 | U6: 1115913 | V6: 4941401218 | W6: 1135275 | X6: 4862391653 | Y6: 1180322 | Z6: 4967514182 | AA6: 1263556 | AB6: 5141628070 | AC6: =SUM(E6,G6,I6,K6,M6,O6,Q6,S6,U6,W6,Y6,AA6) -> 13730677 | AD6: =SUM(F6,H6,J6,L6,N6,P6,R6,T6,V6,X6,Z6,AB6) -> 57825467801 | AE6: 0 | AF6: 0 | AG6: 0 | AH6: 0 | AI6: 0 | AJ6: 0 | AK6: 0 | AL6: 0 | AM6: 0 | AN6: 0 | AO6: 0 | AP6: 0 | AQ6: =SUM(AE6:AP6) -> 0 | AR6: 0 | AS6: 0 | AT6: 0 | AU6: 0 | AV6: 0 | AW6: 0 | AX6: 0 | AY6: 0 | AZ6: 0 | BA6: 0 | BB6: 0 | BC6: 0 | BD6: =SUM(AR6:BC6) -> 0
A7: 1.HMI | B7: SGS | C7: Gear Shift Module | D7: =AD7+AQ7+BD7 -> 32171610 | E7: 158 | F7: 5674720 | G7: 158 | H7: 4054774 | I7: 162 | J7: -4311328 | K7: 153 | L7: 4615517 | M7: 63 | N7: 116407 | O7: 81 | P7: 3171152 | Q7: 0 | R7: 0 | S7: 148 | T7: 4642304 | U7: 16 | V7: 2210000 | W7: 158 | X7: 5662304 | Y7: 141 | Z7: 2772304 | AA7: 208 | AB7: 3563456 | AC7: =SUM(E7,G7,I7,K7,M7,O7,Q7,S7,U7,W7,Y7,AA7) -> 1446 | AD7: =SUM(F7,H7,J7,L7,N7,P7,R7,T7,V7,X7,Z7,AB7) -> 32171610 | AE7: 0 | AF7: 0 | AG7: 0 | AH7: 0 | AI7: 0 | AJ7: 0 | AK7: 0 | AL7: 0 | AM7: 0 | AN7: 0 | AO7: 0 | AP7: 0 | AQ7: =SUM(AE7:AP7) -> 0 | AR7: 0 | AS7: 0 | AT7: 0 | AU7: 0 | AV7: 0 | AW7: 0 | AX7: 0 | AY7: 0 | AZ7: 0 | BA7: 0 | BB7: 0 | BC7: 0 | BD7: =SUM(AR7:BC7) -> 0
A8: 1.HMI | B8: SHT | C8: Haptic Switch | D8: =AD8+AQ8+BD8 -> 242516749 | E8: 349 | F8: 15921708 | G8: 528 | H8: 22482864 | I8: 659 | J8: 26408097 | K8: 336 | L8: 13575944 | M8: 592 | N8: 24952768 | O8: 688 | P8: 28275424 | Q8: 428 | R8: 17684688 | S8: 512 | T8: 20807564 | U8: 304 | V8: 21708956 | W8: 272 | X8: 12003712 | Y8: 399 | Z8: 17306800 | AA8: 352 | AB8: 21388224 | AC8: =SUM(E8,G8,I8,K8,M8,O8,Q8,S8,U8,W8,Y8,AA8) -> 5419 | AD8: =SUM(F8,H8,J8,L8,N8,P8,R8,T8,V8,X8,Z8,AB8) -> 242516749 | AE8: 0 | AF8: 0 | AG8: 0 | AH8: 0 | AI8: 0 | AJ8: 0 | AK8: 0 | AL8: 0 | AM8: 0 | AN8: 0 | AO8: 0 | AP8: 0 | AQ8: =SUM(AE8:AP8) -> 0 | AR8: 0 | AS8: 0 | AT8: 0 | AU8: 0 | AV8: 0 | AW8: 0 | AX8: 0 | AY8: 0 | AZ8: 0 | BA8: 0 | BB8: 0 | BC8: 0 | BD8: =SUM(AR8:BC8) -> 0
A9: 1.HMI | B9: SIH | C9: Inhibitor Switch | D9: =AD9+AQ9+BD9 -> 17286577002 | E9: 1762144 | F9: 1344684578 | G9: 2805081 | H9: 1596811972 | I9: 1832287 | J9: 1610107009 | K9: 1265739 | L9: 1400838584 | M9: 1380235 | N9: 1698381705 | O9: 2028423 | P9: 1284868583 | Q9: 1722593 | R9: 1262184029 | S9: 3080491 | T9: 1254778962 | U9: 1722191 | V9: 1348938490 | W9: 3256476 | X9: 1455577092 | Y9: 3276654 | Z9: 1581082361 | AA9: 2428706 | AB9: 1295623899 | AC9: =SUM(E9,G9,I9,K9,M9,O9,Q9,S9,U9,W9,Y9,AA9) -> 26561020 | AD9: =SUM(F9,H9,J9,L9,N9,P9,R9,T9,V9,X9,Z9,AB9) -> 17133877264 | AE9: 0 | AF9: 0 | AG9: 0 | AH9: 0 | AI9: 0 | AJ9: 0 | AK9: 0 | AL9: 0 | AM9: 0 | AN9: 0 | AO9: 0 | AP9: 0 | AQ9: =SUM(AE9:AP9) -> 0 | AR9: 8839888 | AS9: 13608168 | AT9: 11140678 | AU9: 7268619 | AV9: 5926958 | AW9: 12715062 | AX9: 10685311 | AY9: 14950036 | AZ9: 8283421 | BA9: 19843512 | BB9: 22853905 | BC9: 16584180 | BD9: =SUM(AR9:BC9) -> 152699738
A10: 1.HMI | B10: SIP | C10: In Panel Switch | D10: =AD10+AQ10+BD10 -> 104184153852 | E10: 17480866 | F10: 8241758516 | G10: 24265637 | H10: 7282572018 | I10: 21594433 | J10: 8805169876 | K10: 20251398 | L10: 8535051899 | M10: 27920744 | N10: 7849000783 | O10: 17058501 | P10: 7686221848 | Q10: 20265686 | R10: 7473162929 | S10: 19965526 | T10: 6868490952 | U10: 28216654 | V10: 7544473077 | W10: 24556453 | X10: 8372614637 | Y10: 24364177 | Z10: 8476045190 | AA10: 29317147 | AB10: 9404558343 | AC10: =SUM(E10,G10,I10,K10,M10,O10,Q10,S10,U10,W10,Y10,AA10) -> 275257222 | AD10: =SUM(F10,H10,J10,L10,N10,P10,R10,T10,V10,X10,Z10,AB10) -> 96539120068 | AE10: 0 | AF10: 0 | AG10: 0 | AH10: 0 | AI10: 0 | AJ10: 0 | AK10: 0 | AL10: 0 | AM10: 0 | AN10: 0 | AO10: 0 | AP10: 0 | AQ10: =SUM(AE10:AP10) -> 0 | AR10: 712329940 | AS10: 580543540 | AT10: 401818170 | AU10: 481686278 | AV10: 622674979 | AW10: 522864775 | AX10: 640502919 | AY10: 408618554 | AZ10: 552351697 | BA10: 918451735 | BB10: 830082907 | BC10: 973108290 | BD10: =SUM(AR10:BC10) -> 7645033784
A11: 1.HMI | B11: SMF | C11: Muti Function Switch | D11: =AD11+AQ11+BD11 -> 68555727839 | E11: 15832525 | F11: 5518507206 | G11: 15574890 | H11: 5540769932 | I11: 23520997 | J11: 6294632359 | K11: 13405175 | L11: 5586679508 | M11: 14069206 | N11: 5401867585 | O11: 16521256 | P11: 5349672559 | Q11: 21470014 | R11: 5982640824 | S11: 17217984 | T11: 4560167082 | U11: 20312119 | V11: 4859679961 | W11: 23408316 | X11: 5531262182 | Y11: 19985963 | Z11: 5961573333 | AA11: 20230178 | AB11: 6457604858 | AC11: =SUM(E11,G11,I11,K11,M11,O11,Q11,S11,U11,W11,Y11,AA11) -> 221548623 | AD11: =SUM(F11,H11,J11,L11,N11,P11,R11,T11,V11,X11,Z11,AB11) -> 67045057389 | AE11: 0 | AF11: 0 | AG11: 0 | AH11: 0 | AI11: 0 | AJ11: 0 | AK11: 0 | AL11: 0 | AM11: 0 | AN11: 0 | AO11: 0 | AP11: 0 | AQ11: =SUM(AE11:AP11) -> 0 | AR11: 157434746 | AS11: 128168500 | AT11: 89622189 | AU11: 138054482 | AV11: 98032400 | AW11: 124540149 | AX11: 77196517 | AY11: 46316206 | AZ11: 136233027 | BA11: 200879026 | BB11: 127807481 | BC11: 186385727 | BD11: =SUM(AR11:BC11) -> 1510670450
A12: 1.HMI | B12: SPW | C12: Power Window Switch | D12: =AD12+AQ12+BD12 -> 101997493988 | E12: 39586693 | F12: 7820542369 | G12: 61032782 | H12: 8035352799 | I12: 57078376 | J12: 8458488060 | K12: 69066432 | L12: 8005757953 | M12: 77593263 | N12: 7114148536 | O12: 50657590 | P12: 8377397753 | Q12: 52966454 | R12: 8687089238 | S12: 53147772 | T12: 6465411755 | U12: 61731436 | V12: 6429629839 | W12: 71072904 | X12: 8151640598 | Y12: 78766980 | Z12: 9178410766 | AA12: 73230892 | AB12: 9627959086 | AC12: =SUM(E12,G12,I12,K12,M12,O12,Q12,S12,U12,W12,Y12,AA12) -> 745931574 | AD12: =SUM(F12,H12,J12,L12,N12,P12,R12,T12,V12,X12,Z12,AB12) -> 96351828752 | AE12: 0 | AF12: 0 | AG12: 0 | AH12: 0 | AI12: 0 | AJ12: 0 | AK12: 0 | AL12: 0 | AM12: 0 | AN12: 0 | AO12: 0 | AP12: 0 | AQ12: =SUM(AE12:AP12) -> 0 | AR12: 272676283 | AS12: 450512899 | AT12: 494989595 | AU12: 437570136 | AV12: 518723293 | AW12: 390399402 | AX12: 516830671 | AY12: 355353082 | AZ12: 446074955 | BA12: 523195872 | BB12: 724916223 | BC12: 514422825 | BD12: =SUM(AR12:BC12) -> 5645665236
A13: 1.HMI | B13: SRM | C13: Remocon Switch | D13: =AD13+AQ13+BD13 -> 47617924195 | E13: 1075532 | F13: 4483396863 | G13: 943687 | H13: 4071162304 | I13: 1515687 | J13: 4530471629 | K13: 1091987 | L13: 4833303493 | M13: 1275475 | N13: 4156694525 | O13: 1667887 | P13: 3772584960 | Q13: 1304939 | R13: 4123222554 | S13: 1418111 | T13: 3892489215 | U13: 1740494 | V13: 2969397789 | W13: 1062180 | X13: 3496052344 | Y13: 1159990 | Z13: 3571834651 | AA13: 1688344 | AB13: 3714152286 | AC13: =SUM(E13,G13,I13,K13,M13,O13,Q13,S13,U13,W13,Y13,AA13) -> 15944313 | AD13: =SUM(F13,H13,J13,L13,N13,P13,R13,T13,V13,X13,Z13,AB13) -> 47614762613 | AE13: 0 | AF13: 0 | AG13: 0 | AH13: 0 | AI13: 0 | AJ13: 0 | AK13: 0 | AL13: 0 | AM13: 0 | AN13: 0 | AO13: 0 | AP13: 0 | AQ13: =SUM(AE13:AP13) -> 0 | AR13: 0 | AS13: 0 | AT13: 0 | AU13: 0 | AV13: 0 | AW13: 0 | AX13: 0 | AY13: 0 | AZ13: 0 | BA13: 505795 | BB13: 2655787 | BC13: 0 | BD13: =SUM(AR13:BC13) -> 3161582
A14: 1.HMI | B14: SSM | C14: Micro Switch | D14: =AD14+AQ14+BD14 -> 19493532 | E14: 27367 | F14: 887120 | G14: 0 | H14: 0 | I14: 5 | J14: 1147 | K14: 3608 | L14: 5100311 | M14: 81600 | N14: 629979 | O14: 16100 | P14: 1023288 | Q14: 32503 | R14: 679325 | S14: 93100 | T14: 1758138 | U14: 35300 | V14: 390941 | W14: 46608 | X14: 1379450 | Y14: 65203 | Z14: 747861 | AA14: 37508 | AB14: 796850 | AC14: =SUM(E14,G14,I14,K14,M14,O14,Q14,S14,U14,W14,Y14,AA14) -> 438902 | AD14: =SUM(F14,H14,J14,L14,N14,P14,R14,T14,V14,X14,Z14,AB14) -> 13394410 | AE14: 0 | AF14: 0 | AG14: 0 | AH14: 0 | AI14: 0 | AJ14: 0 | AK14: 0 | AL14: 0 | AM14: 0 | AN14: 0 | AO14: 0 | AP14: 0 | AQ14: =SUM(AE14:AP14) -> 0 | AR14: 479543 | AS14: 0 | AT14: 0 | AU14: 0 | AV14: 381523 | AW14: 660619 | AX14: 1483510 | AY14: 561452 | AZ14: 148218 | BA14: 213373 | BB14: 1203237 | BC14: 967647 | BD14: =SUM(AR14:BC14) -> 6099122
A15: 1.HMI | B15: SSW | C15: General Switch | D15: =AD15+AQ15+BD15 -> 1284992040 | E15: 690723 | F15: 120499872 | G15: 568302 | H15: 126080211 | I15: 761309 | J15: 176883615 | K15: 441335 | L15: 120292691 | M15: 239958 | N15: 90155410 | O15: 767233 | P15: 88560611 | Q15: 810365 | R15: 90401607 | S15: 1224400 | T15: 73931577 | U15: 1050131 | V15: 103017960 | W15: 1046662 | X15: 99417217 | Y15: 1324859 | Z15: 83300802 | AA15: 785066 | AB15: 68288492 | AC15: =SUM(E15,G15,I15,K15,M15,O15,Q15,S15,U15,W15,Y15,AA15) -> 9710343 | AD15: =SUM(F15,H15,J15,L15,N15,P15,R15,T15,V15,X15,Z15,AB15) -> 1240830065 | AE15: 0 | AF15: 0 | AG15: 0 | AH15: 0 | AI15: 0 | AJ15: 0 | AK15: 0 | AL15: 0 | AM15: 0 | AN15: 0 | AO15: 0 | AP15: 0 | AQ15: =SUM(AE15:AP15) -> 0 | AR15: 0 | AS15: 0 | AT15: 0 | AU15: 0 | AV15: 2370718 | AW15: 2504202 | AX15: 4867461 | AY15: 7990307 | AZ15: 6693613 | BA15: 7399075 | BB15: 7748367 | BC15: 4588232 | BD15: =SUM(AR15:BC15) -> 44161975
