Workbook
Name _: #REF!
Name _: #REF!
Name _?: #REF!
Name _?: #REF!
Name _?춑_TOTAL: [1]major!#REF!
Name _?춮t2: [2]현금경비중역!#REF!
Name _?춮ta: [2]현금경비중역!#REF!
Name _?춮tb: [2]현금경비중역!#REF!
Name __: [3]표지!#REF!
Name __?: #REF!
Name __?: #REF!
Name __?춑_TOTAL: [1]major!#REF!
Name __?춮t2: [2]현금경비중역!#REF!
Name __?춮ta: [2]현금경비중역!#REF!
Name __?춮tb: [2]현금경비중역!#REF!
Name ___: [3]표지!#REF!
Name ___?: #REF!
Name ___?: #REF!
Name ___?춑_TOTAL: [1]major!#REF!
Name ___?춮t2: [2]현금경비중역!#REF!
Name ___?춮ta: [2]현금경비중역!#REF!
Name ___?춮tb: [2]현금경비중역!#REF!
Name ____: [3]표지!#REF!
Name ____?: #REF!
Name ____?: #REF!
Name ____?춑_TOTAL: [1]major!#REF!
Name ____?춮t2: [2]현금경비중역!#REF!
Name ____?춮ta: [2]현금경비중역!#REF!
Name ____?춮tb: [2]현금경비중역!#REF!
Name _____: [3]표지!#REF!
Name _____?: #REF!
Name _____?: #REF!
Name _____?춑_TOTAL: [1]major!#REF!
Name _____?춮t2: [2]현금경비중역!#REF!
Name _____?춮ta: [2]현금경비중역!#REF!
Name _____?춮tb: [2]현금경비중역!#REF!
Name _______DAT1: '[4]보증금(기타)'!#REF!
Name _______DAT10: [5]가지급금기타!#REF!
Name _______DAT11: '[4]보증금(기타)'!#REF!
Name _______DAT12: #REF!
Name _______DAT12: #REF!
Name _______DAT13: #REF!
Name _______DAT13: #REF!
Name _______DAT14: #REF!
Name _______DAT14: #REF!
Name _______DAT15: #REF!
Name _______DAT15: #REF!
Name _______DAT16: #REF!
Name _______DAT16: #REF!
Name _______DAT17: #REF!
Name _______DAT17: #REF!
Name _______DAT18: #REF!
Name _______DAT18: #REF!
Name _______DAT19: #REF!
Name _______DAT19: #REF!
Name _______DAT2: '[4]보증금(기타)'!#REF!
Name _______DAT20: #REF!
Name _______DAT20: #REF!
Name _______DAT21: #REF!
Name _______DAT21: #REF!

Sheet Index
B2: Data index
B4: Description | C4: Link
B6: Sales overview | C6: Sales_01
B7: 거래처별 매출 | C7: Sales_02거래처별
B8: 자료간 Recon | C8: Sales_03자료간 차이
B9: 사업부별매출 | C9: Sales_04사업부별
B10: 사업부별매출추세 | C10: Sales_05사업부별추세
B11: 월별매출추세 | C11: Sales_06월별
B12: 제품매출 | C12: Sales_07제품매출
B13: 설비매출 | C13: Sales_08설비매출
B14: 기타매출 | C14: Sales_09기타매출
B16: 사업부별손익 | C16: 사업부별손익

Sheet Sales_01
B4: 결산명세서 및 감사보고서
B5: Sales overview
C6: 2012년 | D6: 2013년 | E6: 2014년 | F6: 2015년
B7: 백만원 | C7: 12개월 | D7: 12개월 | E7: 12개월 | F7: 6개월
B8: 제품 | C8: 526517112721 | D8: 544246783298 | E8: 566780439272 | F8: 294177847835 | H8: 제품매출 vs 기타매출 구분기준
B9: 기타 | C9: 2052397629 | D9: 11493484827 | E9: 17891881632 | F9: 9745199114
B10: 합계 | C10: =SUM(C8:C9) -> 528569510350 | D10: =SUM(D8:D9) -> 555740268125 | E10: =SUM(E8:E9) -> 584672320904 | F10: =SUM(F8:F9) -> 303923046949
B16: Val_8,9 제품별 사업부별 매출액
B17: 사업부별(내부보고) 매출
C18: 2012년 | D18: 2013년 | E18: 2014년 | F18: 2015년
B19: 백만원 | C19: 12개월 | D19: 12개월 | E19: 12개월 | F19: 6개월
B20: 스위치 | C20: 301650469844 | D20: 329529138676 | E20: 357818553490 | F20: 189665157770 | H20: 스위치 | I20: =C20/C$27 -> 0.57069215 | J20: =D20/D$27 -> 0.5929553 | K20: =E20/E$27 -> 0.61199845 | L20: =F20/F$27 -> 0.62405652
B21: 릴레이 | C21: 69649481160 | D21: 63547706707 | E21: 56026768138 | F21: 27146825614 | H21: 릴레이 | I21: =C21/C$27 -> 0.13176977 | J21: =D21/D$27 -> 0.11434785 | K21: =E21/E$27 -> 0.095825929 | L21: =F21/F$27 -> 0.089321379
B22: BCS | C22: 40168769460 | D22: 33386486016 | E22: 26961139273 | F22: 10360925486 | H22: BCS | I22: =C22/C$27 -> 0.075995245 | J22: =D22/D$27 -> 0.060075701 | K22: =E22/E$27 -> 0.046113247 | L22: =F22/F$27 -> 0.034090621
B23: ECU | C23: 43499623320 | D23: 44066949023 | E23: 48731959043 | F23: 25563257442 | H23: ECU | I23: =C23/C$27 -> 0.082296883 | J23: =D23/D$27 -> 0.079294144 | K23: =E23/E$27 -> 0.083349181 | L23: =F23/F$27 -> 0.084110954
B24: 전력제어 | C24: 21129287864 | D24: 21405858496 | E24: 23727187750 | F24: 14891677706 | H24: 전력제어 | I24: =C24/C$27 -> 0.039974473 | J24: =D24/D$27 -> 0.038517739 | K24: =E24/E$27 -> 0.040582027 | L24: =F24/F$27 -> 0.048998185
B25: RoomLamp | C25: 47717791608 | D25: 54174492386 | E25: 58437212647 | F25: 30531103326 | H25: RoomLamp | I25: =C25/C$27 -> 0.090277231 | J25: =D25/D$27 -> 0.097481675 | K25: =E25/E$27 -> 0.099948656 | L25: =F25/F$27 -> 0.10045669
B26: 부품사업팀 | C26: 4754087094 | D26: 9629636821 | E26: 12969500563 | F26: 5764099605 | H26: 부품사업팀 | I26: =C26/C$27 -> 0.0089942515 | J26: =D26/D$27 -> 0.017327585 | K26: =E26/E$27 -> 0.022182512 | L26: =F26/F$27 -> 0.018965655
B27: 합계 | C27: =SUM(C20:C26) -> 528569510350 | D27: =SUM(D20:D26) -> 555740268125 | E27: =SUM(E20:E26) -> 584672320904 | F27: =SUM(F20:F26) -> 303923046949
C29: =C10-C27 -> 0 | D29: =D10-D27 -> 0 | E29: =E10-E27 -> 0 | F29: =F10-F27 -> 0 | H29: HMC | I29: 스위치 | J29: Human Machine Interface (Switch, Lamp)
I30: RoomLamp
H31: BCS | I31: ECU | J31: Body Control System (Core BCM, ECU, Sensor, Converter, VESS 등)
I32: 전력제어
B33: Val_8,9 제품별 사업부별 매출액 | H33: MC | I33: 릴레이 | J33: Mechatronics Components (Relay, J/Box, ABS Coil & Housing, 환형터미널 등)
B34: 사업부별(그룹보고) 매출 | I34: BCS
C35: 2012년 | D35: 2013년 | E35: 2014년 | F35: 2015년 | I35: 부품사업팀
B36: 백만원 | C36: 12개월 | D36: 12개월 | E36: 12개월 | F36: 6개월
B37: HMC | C37: =C20+C25 -> 349368261452 | D37: =D20+D25 -> 383703631062 | E37: =E20+E25 -> 416255766137 | F37: =F20+F25 -> 220196261096 | H37: HMC | I37: =C37/C$40 -> 0.66096938 | J37: =D37/D$40 -> 0.69043698 | K37: =E37/E$40 -> 0.7119471 | L37: =F37/F$40 -> 0.72451321
B38: BCS | C38: =C23+C24 -> 64628911184 | D38: =D23+D24 -> 65472807519 | E38: =E23+E24 -> 72459146793 | F38: =F23+F24 -> 40454935148 | H38: BCS | I38: =C38/C$40 -> 0.12227136 | J38: =D38/D$40 -> 0.11781188 | K38: =E38/E$40 -> 0.12393121 | L38: =F38/F$40 -> 0.13310914
B39: MC | C39: =C21+C22+C26 -> 114572337714 | D39: =D21+D22+D26 -> 106563829544 | E39: =E21+E22+E26 -> 95957407974 | F39: =F21+F22+F26 -> 43271850705 | H39: MC | I39: =C39/C$40 -> 0.21675926 | J39: =D39/D$40 -> 0.19175114 | K39: =E39/E$40 -> 0.16412169 | L39: =F39/F$40 -> 0.14237765
B40: 합계 | C40: =SUM(C37:C39) -> 528569510350 | D40: =SUM(D37:D39) -> 555740268125 | E40: =SUM(E37:E39) -> 584672320904 | F40: =SUM(F37:F39) -> 303923046949
B44: FDD_12,13,18,19,20 2012년 ~ 22015년 6월 매출세부
B45: 매출세부
C46: 2012년 | D46: 2013년 | E46: 2014년 | F46: 2015년
B47: 백만원 | C47: 12개월 | D47: 12개월 | E47: 12개월 | F47: 6개월
B48: 제품매출 | C48: 519344538843 | D48: 528773112276 | E48: 536171328032 | F48: 279207198170
B49: 설비매출 | C49: 1495754873 | D49: 3714070648 | E49: 12641566864 | F49: 2924615380
B50: 기타매출 | C50: 7729216634 | D50: 15245418497 | E50: 23334266767 | F50: 13662165550
B51: 합계 | C51: =SUM(C48:C50) -> 528569510350 | D51: =SUM(D48:D50) -> 547732601421 | E51: =SUM(E48:E50) -> 572147161663 | F51: =SUM(F48:F50) -> 295793979100
C53: =C40-C51 -> 0 | D53: =D40-D51 -> 8007666704 | E53: =E40-E51 -> 12525159241 | F53: =F40-F51 -> 8129067849
...

Sheet Sales_02거래처별
C2: 528569510350 | D2: 547732601421 | E2: 572147161663 | F2: 295793979100
B4: 거래처별 매출(전체매출)
C5: 2012년 | D5: 2013년 | E5: 2014년 | F5: 2015년 | M5: 고객그룹 | N5: 고객그룹명 | O5: 2012년 | P5: 2013년 | Q5: 2014년 | R5: 2015년
B6: 백만원 | C6: 12개월 | D6: 12개월 | E6: 12개월 | F6: 6개월 | G6: % | H6: % | I6: % | J6: % | M6: A0 | N6: 자동차부문 기타 | O6: 5508709041 | P6: 8515581627 | Q6: 7889004607 | R6: 3818383504
B7: 현대자동차 관련 | C7: =O7 -> 226488492053 | D7: =P7 -> 222456007150 | E7: =Q7 -> 233803514273 | F7: =R7 -> 120412738599 | G7: =C7/C$14 -> 0.4284933 | H7: =D7/D$14 -> 0.4061398 | I7: =E7/E$14 -> 0.40864227 | J7: =F7/F$14 -> 0.40708313 | M7: A1 | N7: 현대자동차 관련 | O7: 226488492053 | P7: 222456007150 | Q7: 233803514273 | R7: 120412738599
B8: 기아자동차 관련 | C8: =O8 -> 101397360511 | D8: =P8 -> 106029502497 | E8: =Q8 -> 101560396568 | F8: =R8 -> 57320939655 | G8: =C8/C$14 -> 0.19183354 | H8: =D8/D$14 -> 0.19357895 | I8: =E8/E$14 -> 0.17750747 | J8: =F8/F$14 -> 0.1937867 | M8: A2 | N8: 기아자동차 관련 | O8: 101397360511 | P8: 106029502497 | Q8: 101560396568 | R8: 57320939655
B9: NISSAN 관련 | C9: =O14 -> 25674509505 | D9: =P14 -> 33050176061 | E9: =Q14 -> 35291477347 | F9: =R14 -> 14856051259 | G9: =C9/C$14 -> 0.048573573 | H9: =D9/D$14 -> 0.060339983 | I9: =E9/E$14 -> 0.061682518 | J9: =F9/F$14 -> 0.050224319 | M9: A3 | N9: 지엠대우자동차 관련 | O9: 43177739121 | P9: 37811431903 | Q9: 26440528829 | R9: 10665394980
B10: 지엠대우자동차 관련 | C10: =O9 -> 43177739121 | D10: =P9 -> 37811431903 | E10: =Q9 -> 26440528829 | F10: =R9 -> 10665394980 | G10: =C10/C$14 -> 0.081687911 | H10: =D10/D$14 -> 0.069032648 | I10: =E10/E$14 -> 0.046212811 | J10: =F10/F$14 -> 0.036056836 | M10: A4 | N10: 쌍용자동차 관련 | O10: 8913209537 | P10: 10060946758 | Q10: 9667059616 | R10: 3854875318
B11: GM 관련 | C11: =O15 -> 20877198322 | D11: =P15 -> 18215477625 | E11: =Q15 -> 18362214442 | F11: =R15 -> 7457215514 | G11: =C11/C$14 -> 0.039497546 | H11: =D11/D$14 -> 0.03325615 | I11: =E11/E$14 -> 0.032093517 | J11: =F11/F$14 -> 0.025210843 | M11: A5 | N11: Delphi 관련 | O11: 21975881814 | P11: 18956356779 | Q11: 16396205041 | R11: 8739604405
B12: Delphi 관련 | C12: =O11 -> 21975881814 | D12: =P11 -> 18956356779 | E12: =Q11 -> 16396205041 | F12: =R11 -> 8739604405 | G12: =C12/C$14 -> 0.041576144 | H12: =D12/D$14 -> 0.034608779 | I12: =E12/E$14 -> 0.028657321 | J12: =F12/F$14 -> 0.029546255 | M12: A6 | N12: 르노삼성 관련 | O12: 54615984 | P12: 225730475 | Q12: 1394124046 | R12: 1368333135
B13: 기타 | C13: =C2-SUM(C7:C12) -> 88978329024 | D13: =D2-SUM(D7:D12) -> 111213649406 | E13: =E2-SUM(E7:E12) -> 140292825163 | F13: =F2-SUM(F7:F12) -> 76342034688 | G13: =C13/C$14 -> 0.16833799 | H13: =D13/D$14 -> 0.20304369 | I13: =E13/E$14 -> 0.24520409 | J13: =F13/F$14 -> 0.25809192 | M13: B0 | N13: 해외 기타 | O13: 7494278474 | P13: 12459329255 | Q13: 16620300913 | R13: 13568488058
B14: 합계 | C14: =SUM(C7:C13) -> 528569510350 | D14: =SUM(D7:D13) -> 547732601421 | E14: =SUM(E7:E13) -> 572147161663 | F14: =SUM(F7:F13) -> 295793979100 | G14: =C14/C$14 -> 1 | H14: =D14/D$14 -> 1 | I14: =E14/E$14 -> 1 | J14: =F14/F$14 -> 1 | M14: B1 | N14: NISSAN 관련 | O14: 25674509505 | P14: 33050176061 | Q14: 35291477347 | R14: 14856051259
B15: 해외법인 | C15: 47882786926 | D15: 65477299522 | E15: 82321303895 | F15: 42919585413 | M15: B2 | N15: GM 관련 | O15: 20877198322 | P15: 18215477625 | Q15: 18362214442 | R15: 7457215514
M16: B3 | N16: TATA 관련 | O16: 0 | P16: 0 | Q16: 0 | R16: 0
B17: 거래처별 제품군 필요 | E17: =D7-C7 -> -4032484903 | G17: =E7-D7 -> 11347507123 | M17: B6 | N17: 폭스바겐 | O17: 11622326291 | P17: 10095662285 | Q17: 9417488639 | R17: 3998207341
E18: =D8-C8 -> 4632141986 | G18: =E8-D8 -> -4469105929 | M18: B7 | N18: 크라이슬러 | O18: 181832467 | P18: 80618767 | Q18: 5953486055 | R18: 4419342035
B19: 현대기아차 비중 | C19: =SUM(C7:C8)/C14 -> 0.62032684 | E19: =SUM(D7:D8)/D14 -> 0.59971875 | G19: =SUM(E7:E8)/E14 -> 0.58614974 | I19: =SUM(F7:F8)/F14 -> 0.60086983 | M19: B9 | N19: 삼성전자 관련 | O19: 785686165 | P19: 675826348 | Q19: 481012856 | R19: 0
M20: C1 | N20: LG전자 관련 | O20: 214501753 | P20: 78442109 | Q20: -32582079 | R20: 299215434
M21: D1 | N21: 해외법인 관련 | O21: 47882786926 | P21: 65477299522 | Q21: 82321303895 | R21: 42919585413
M22: E0 | N22: 기타고객(전체) | O22: 4851180024 | P22: 1390418920 | Q22: 1932487888 | R22: 637966130
M23: F1 | N23: 유상사급 관련 | O23: 2538331 | Q23: 0 | R23: 0
N24: 미지정 | O24: 1466664031 | P24: 2153793340 | Q24: 4649138727 | R24: 1457638320
M25: 총계 | O25: 528569510350 | P25: 547732601421 | Q25: 572147161663 | R25: 295793979100
B27: 거래처 그룹별 매출(제품매출)
C28: 2012년 | D28: 2013년 | E28: 2014년 | F28: 2015년
B29: 백만원 | C29: 12개월 | D29: 12개월 | E29: 12개월 | F29: 6개월 | G29: % | H29: % | I29: % | J29: % | O29: 2012년 12개월 | P29: 2013년 12개월 | Q29: 2014년 12개월 | R29: 2015년 6개월
B30: 현대자동차 관련 | C30: 226488492053 | D30: 222456007150 | E30: 232291258213 | F30: 119407969167 | G30: =C30/C$37 -> 0.4361045 | H30: =D30/D$37 -> 0.42070219 | I30: =E30/E$37 -> 0.43324073 | J30: =F30/F$37 -> 0.42766795 | N30: 현대자동차 관련 | O30: 226488492053 | P30: 222456007150 | Q30: 233803514273 | R30: 120412738599
B31: 기아자동차 관련 | C31: 101397364194 | D31: 106029502497 | E31: 101560396568 | F31: 57320939655 | G31: =C31/C$37 -> 0.19524103 | H31: =D31/D$37 -> 0.20051984 | I31: =E31/E$37 -> 0.18941781 | J31: =F31/F$37 -> 0.20529893 | N31: 기아자동차 관련 | O31: 101397360511 | P31: 106029502497 | Q31: 101560396568 | R31: 57320939655
B32: 지엠대우자동차 관련 | C32: 43177739121 | D32: 37811431903 | E32: 26440528829 | F32: 10665394980 | G32: =C32/C$37 -> 0.08313891 | H32: =D32/D$37 -> 0.071507857 | I32: =E32/E$37 -> 0.049313582 | J32: =F32/F$37 -> 0.038198854 | N32: NISSAN 관련 | O32: 25674509505 | P32: 33050176061 | Q32: 35291477347 | R32: 14856051259
B33: NISSAN 관련 | C33: 25674509505 | D33: 33050176061 | E33: 35291477347 | F33: 14856051259 | G33: =C33/C$37 -> 0.049436371 | H33: =D33/D$37 -> 0.062503511 | I33: =E33/E$37 -> 0.065821269 | J33: =F33/F$37 -> 0.053207981 | N33: 지엠대우자동차 관련 | O33: 43177739121 | P33: 37811431903 | Q33: 26440528829 | R33: 10665394980
B34: GM 관련 | C34: 20877198322 | D34: 18215477625 | E34: 18362214442 | F34: 7457215514 | G34: =C34/C$37 -> 0.040199129 | H34: =D34/D$37 -> 0.03444857 | I34: =E34/E$37 -> 0.034246916 | J34: =F34/F$37 -> 0.026708536 | N34: GM 관련 | O34: 20877198322 | P34: 18215477625 | Q34: 18362214442 | R34: 7457215514
B35: Delphi 관련 | C35: 21975881814 | D35: 18956356779 | E35: 16396205041 | F35: 8739604405 | G35: =C35/C$37 -> 0.042314649 | H35: =D35/D$37 -> 0.035849699 | I35: =E35/E$37 -> 0.03058016 | J35: =F35/F$37 -> 0.031301501 | N35: Delphi 관련 | O35: 21975881814 | P35: 18956356779 | Q35: 16396205041 | R35: 8739604405
B36: 기타 | C36: =C37-SUM(C30:C35) -> 79753353834 | D36: =D37-SUM(D30:D35) -> 92254160261 | E36: =E37-SUM(E30:E35) -> 105829247592 | F36: =F37-SUM(F30:F35) -> 60760023190 | G36: =C36/C$37 -> 0.1535654 | H36: =D36/D$37 -> 0.17446833 | I36: =E36/E$37 -> 0.19737954 | J36: =F36/F$37 -> 0.21761625 | N36: 기타 | O36: =O25-SUM(O30:O35) -> 88978329024 | P36: =P25-SUM(P30:P35) -> 111213649406 | Q36: =Q25-SUM(Q30:Q35) -> 140292825163 | R36: =R25-SUM(R30:R35) -> 76342034688
B37: 합계 | C37: 519344538843 | D37: 528773112276 | E37: 536171328032 | F37: 279207198170 | G37: =C37/C$37 -> 1 | H37: =D37/D$37 -> 1 | I37: =E37/E$37 -> 1 | J37: =F37/F$37 -> 1 | N37: 현대기아차비중 | O37: =(O30+O31)/O40 -> 0.62032684 | P37: =(P30+P31)/P40 -> 0.59971875 | Q37: =(Q30+Q31)/Q40 -> 0.58614974 | R37: =(R30+R31)/R40 -> 0.60086983
B38: 해외법인 | C38: 40537018154 | D38: 48669974281 | E38: 52465265503 | F38: 28737903675
N40: 합계 | O40: =SUM(O30:O36) -> 528569510350 | P40: =SUM(P30:P36) -> 547732601421 | Q40: =SUM(Q30:Q36) -> 572147161663 | R40: =SUM(R30:R36) -> 295793979100

Sheet Sales_03자료간 차이
B2: 국내/해외
I3: =C9-I9 -> -1441596000 | J3: =D9-J9 -> -165160928 | K3: =E9-K9 -> 1074865
I4: =C10-I10 -> 1441596000 | J4: =D10-J10 -> 165160928 | K4: =E10-K10 -> -1074865
B5: 결산명세서 | H5: Val21_판매보증충당금_판보충계산 | N5: FDD_12,13,18,19,20 2012년 ~ 22015년 6월 매출세부
B6: 매출세부 | H6: 매출세부 | N6: 매출세부
C7: 2012년 | D7: 2013년 | E7: 2014년 | F7: 2015년 | I7: 2012년 | J7: 2013년 | K7: 2014년 | L7: 2015년 | O7: 2012년 | P7: 2013년 | Q7: 2014년 | R7: 2015년 | S7: 고객코드별로 해외고객과 국내고객 구분
B8: 백만원 | C8: 12개월 | D8: 12개월 | E8: 12개월 | F8: 6개월 | H8: 백만원 | I8: 12개월 | J8: 12개월 | K8: 12개월 | L8: 6개월 | N8: 백만원 | O8: 12개월 | P8: 12개월 | Q8: 12개월 | R8: 6개월
B9: 내수 | C9: =매출2012!E54 -> 389400868163 | D9: =매출2013!E54 -> 391576664022 | E9: =매출2014!E56 -> 388255094124 | F9: 미제공 | H9: 국내매출 | I9: 390842464163 | J9: 391741824950 | K9: 388254019259 | L9: 199896783373 | N9: 국내고객 | O9: 389432794463 | P9: 382939223904 | Q9: 374924699294 | R9: 191309174281
B10: 해외수출 | C10: =매출2012!E92 -> 139168642187 | D10: =매출2013!E90 -> 164163604103 | E10: =매출2014!E98 -> 196417226780 | F10: 미제공 | H10: 해외매출 | I10: 137727046187 | J10: 163998443175 | K10: 196418301645 | L10: 103438463009 | N10: 해외고객 | O10: 139168642187 | P10: 162701011517 | Q10: 192691920369 | R10: 103115696819
B11: 합계 | C11: =C9+C10 -> 528569510350 | D11: =D9+D10 -> 555740268125 | E11: =E9+E10 -> 584672320904 | H11: 합계 | I11: 528569510350 | J11: 555740268125 | K11: 584672320904 | L11: 303335246382 | N11: 기타 | O11: -31926300 | P11: 2092366000 | Q11: 4530542000 | R11: 1369108000 | S11: 파생상품
N12: 합계 | O12: 528569510350 | P12: 547732601421 | Q12: 572147161663 | R12: 295793979100
B13: 증감 | D13: =D9-C9 -> 2175795859 | E13: =E9-D9 -> -3321569898 | J13: =J9-I9 -> 899360787 | K13: =K9-J9 -> -3487805691 | L13: =L9*2-K9 -> 11539547487 | N13: 결산서상 매출과 일시불매출 및 용역과제매출 누락차이
D14: =D10-C10 -> 24994961916 | E14: =E10-D10 -> 32253622677 | J14: =J10-I10 -> 26271396988 | K14: =K10-J10 -> 32419858470 | L14: =L10*2-K10 -> 10458624373 | P14: =P9-O9 -> -6493570559 | Q14: =Q9-P9 -> -8014524610 | R14: =R9*2-Q9 -> 7693649268
P15: =P10-O10 -> 23532369330 | Q15: =Q10-P10 -> 29990908852 | R15: =R10*2-Q10 -> 13539473269
B16: 감사보고서 | P16: =P11-O11 -> 2124292300 | Q16: =Q11-P11 -> 2438176000 | R16: =R11*2-Q11 -> -1792326000
B17: Sales overview | H17: FDD_12,13,18,19,20 2012년 ~ 22015년 6월 매출세부(본사_해외고객)
C18: 2012년 | D18: 2013년 | E18: 2014년 | F18: 2015년 | H18: 매출세부
B19: 백만원 | C19: 12개월 | D19: 12개월 | E19: 12개월 | F19: 6개월 | I19: 2012년 | J19: 2013년 | K19: 2014년 | L19: 2015년
B20: 제품 | C20: 526517112721 | D20: 544246783298 | E20: 566780439272 | F20: 294177847835 | H20: 백만원 | I20: 12개월 | J20: 12개월 | K20: 12개월 | L20: 6개월
B21: 기타 | C21: 2052397629 | D21: 11493484827 | E21: 17891881632 | F21: 9745199114 | H21: 해외고객 | I21: 92181634341 | J21: 102160392988 | K21: 112767894002 | L21: 60467430559
B22: 합계 | C22: 528569510350 | D22: 555740268125 | E22: 584672320904 | F22: 303923046949
J23: =J21-I21 -> 9978758647 | K23: =K21-J21 -> 10607501014
B27: 사업부별
B29: 결산명세서
B30: 사업부별매출
C31: 2012년 | D31: 2013년 | E31: 2014년 | F31: 2015년
B32: 백만원 | C32: 12개월 | D32: 12개월 | E32: 12개월 | F32: 6개월 | H32: 2012년 | I32: 내수 | J32: 해외 | K32: 합계 | M32: 2013년 | N32: 내수 | O32: 해외 | P32: 합계 | R32: 2014년 | S32: 내수 | T32: 해외 | U32: 합계
B33: 스위치 | C33: =K33 -> 350878516578 | D33: =P33 -> 386528485968 | E33: =U33 -> 412472415850 | H33: 스위치 | I33: =매출2012!E16 -> 271089167229 | J33: =매출2012!E63 -> 79789349349 | K33: =I33+J33 -> 350878516578 | M33: 스위치 | N33: =매출2013!E16 -> 284655705741 | O33: =매출2013!E64 -> 101872780227 | P33: =N33+O33 -> 386528485968 | R33: 스위치 | S33: =매출2014!E16 -> 283778460040 | T33: =매출2014!E66 -> 128693955810 | U33: =S33+T33 -> 412472415850
B34: 릴레이 | C34: =K34 -> 66104665928 | D34: =P34 -> 63063271446 | E34: =U34 -> 54980088186 | H34: 릴레이 | I34: =매출2012!E24 -> 43211283198 | J34: =매출2012!E69 -> 22893382730 | K34: =I34+J34 -> 66104665928 | M34: 릴레이 | N34: =매출2013!E23 -> 35917871716 | O34: =매출2013!E70 -> 27145399730 | P34: =N34+O34 -> 63063271446 | R34: 릴레이 | S34: =매출2014!E24 -> 28986267464 | T34: =매출2014!E76 -> 25993820722 | U34: =S34+T34 -> 54980088186
B35: BCS | C35: =K35 -> 46842535195 | D35: =P35 -> 35057371589 | E35: =U35 -> 24015318039 | H35: BCS | I35: =매출2012!E31 -> 26708618200 | J35: =매출2012!E73 -> 20133916995 | K35: =I35+J35 -> 46842535195 | M35: BCS | N35: =매출2013!E30 -> 20448580950 | O35: =매출2013!E72 -> 14608790639 | P35: =N35+O35 -> 35057371589 | R35: BCS | S35: =매출2014!E27 -> 12285888116 | T35: =매출2014!E78 -> 11729429923 | U35: =S35+T35 -> 24015318039
B36: ECU | C36: =K36 -> 40175134997 | D36: =P36 -> 41249500449 | E36: =U36 -> 49123065754 | H36: ECU | I36: =매출2012!E42 -> 37926888573 | J36: =매출2012!E82 -> 2248246424 | K36: =I36+J36 -> 40175134997 | M36: ECU | N36: =매출2013!E42 -> 37337122016 | O36: =매출2013!E80 -> 3912378433 | P36: =N36+O36 -> 41249500449 | R36: ECU | S36: =매출2014!E43 -> 45261922610 | T36: =매출2014!E88 -> 3861143144 | U36: =S36+T36 -> 49123065754
B37: 전력제어 | C37: =K37 -> 20858169628 | D37: =P37 -> 21058119503 | E37: =U37 -> 23312452924 | H37: 전력제어 | I37: =매출2012!E45 -> 9402013971 | J37: =매출2012!E84 -> 11456155657 | K37: =I37+J37 -> 20858169628 | M37: 전력제어 | N37: =매출2013!E45 -> 10746176292 | O37: =매출2013!E82 -> 10311943211 | P37: =N37+O37 -> 21058119503 | R37: 전력제어 | S37: =매출2014!E46 -> 13170638262 | T37: =매출2014!E90 -> 10141814662 | U37: =S37+T37 -> 23312452924
B38: 부품사업 | C38: =K38 -> 3710488024 | D38: =P38 -> 8783519170 | E38: =U38 -> 20768980151 | H38: 부품사업 | I38: =매출2012!E47+매출2012!E53 -> 1062896992 | J38: =매출2012!E86+매출2012!E91 -> 2647591032 | K38: =I38+J38 -> 3710488024 | M38: 부품사업 | N38: =매출2013!E48+매출2013!E53 -> 2471207307 | O38: =매출2013!E84+매출2013!E89 -> 6312311863 | P38: =N38+O38 -> 8783519170 | R38: 부품사업 | S38: =매출2014!E49+매출2014!E55 -> 4771917632 | T38: =매출2014!E92+매출2014!E97 -> 15997062519 | U38: =S38+T38 -> 20768980151
B39: 합계 | C39: =SUM(C33:C38) -> 528569510350 | D39: =SUM(D33:D38) -> 555740268125 | E39: =SUM(E33:E38) -> 584672320904 | F39: =SUM(F33:F38) -> 0 | H39: 합계 | I39: =SUM(I33:I38) -> 389400868163 | J39: =SUM(J33:J38) -> 139168642187 | K39: =I39+J39 -> 528569510350 | M39: 합계 | N39: =SUM(N33:N38) -> 391576664022 | O39: =SUM(O33:O38) -> 164163604103 | P39: =N39+O39 -> 555740268125 | R39: 합계 | S39: =SUM(S33:S38) -> 388255094124 | T39: =SUM(T33:T38) -> 196417226780 | U39: =S39+T39 -> 584672320904
K40: =I40+J40 -> 0
B43: Val_8,9 제품별 사업부별 매출액
B44: 사업부별(내부보고) 매출
C45: 2012년 | D45: 2013년 | E45: 2014년 | F45: 2015년
B46: 백만원 | C46: 12개월 | D46: 12개월 | E46: 12개월 | F46: 6개월 | H46: 차이 | I46: 2012년 | J46: 2013년 | K46: 2014년 | L46: 2015년
B47: 스위치 | C47: 301650469844 | D47: 329529138676 | E47: 357818553490 | F47: 189665157770 | H47: 스위치 | I47: =C33-SUM(C47:C48) -> 1510255126 | J47: =D33-SUM(D47:D48) -> 2824854906 | K47: =E33-SUM(E47:E48) -> -3783350287
...

Sheet Sales_04사업부별
B1: Val_8,9 제품별 사업부별 매출액
B2: 사업부별 매출액
C3: 2012년 | D3: 2013년 | E3: 2014년 | F3: 2015년 | I3: 2012년 | J3: 2013년 | K3: 2014년 | L3: 2015년 | O3: 2012년 | P3: 2013년 | Q3: 2014년 | R3: 2015년
B4: 백만원 | C4: 12개월 | D4: 12개월 | E4: 12개월 | F4: 6개월 | H4: 매출액비중 | I4: 2012년 | J4: 2013년 | K4: 2014년 | L4: 2015년 | N4: 매출액증감 | O4: 2012년 | P4: 2013년 | Q4: 2014년 | R4: 2015년
B5: 스위치 | C5: 301650469844 | D5: 329529138676 | E5: 357818553490 | F5: 189665157770 | H5: 스위치 | I5: =C5/C$12 -> 0.57069215 | J5: =D5/D$12 -> 0.5929553 | K5: =E5/E$12 -> 0.61199845 | L5: =F5/F$12 -> 0.62405652 | N5: 스위치 | P5: =D5-C5 -> 27878668832 | Q5: =E5-D5 -> 28289414814 | R5: =F5*2-E5 -> 21511762050
B6: 릴레이 | C6: 69649481160 | D6: 63547706707 | E6: 56026768138 | F6: 27146825614 | H6: 릴레이 | I6: =C6/C$12 -> 0.13176977 | J6: =D6/D$12 -> 0.11434785 | K6: =E6/E$12 -> 0.095825929 | L6: =F6/F$12 -> 0.089321379 | N6: 릴레이 | P6: =D6-C6 -> -6101774453 | Q6: =E6-D6 -> -7520938569 | R6: =F6*2-E6 -> -1733116910
B7: BCS | C7: 40168769460 | D7: 33386486016 | E7: 26961139273 | F7: 10360925486 | H7: BCS | I7: =C7/C$12 -> 0.075995245 | J7: =D7/D$12 -> 0.060075701 | K7: =E7/E$12 -> 0.046113247 | L7: =F7/F$12 -> 0.034090621 | N7: BCS | P7: =D7-C7 -> -6782283444 | Q7: =E7-D7 -> -6425346743 | R7: =F7*2-E7 -> -6239288301
B8: ECU | C8: 43499623320 | D8: 44066949023 | E8: 48731959043 | F8: 25563257442 | H8: ECU | I8: =C8/C$12 -> 0.082296883 | J8: =D8/D$12 -> 0.079294144 | K8: =E8/E$12 -> 0.083349181 | L8: =F8/F$12 -> 0.084110954 | N8: ECU | P8: =D8-C8 -> 567325703 | Q8: =E8-D8 -> 4665010020 | R8: =F8*2-E8 -> 2394555841
B9: 전력제어 | C9: 21129287864 | D9: 21405858496 | E9: 23727187750 | F9: 14891677706 | H9: 전력제어 | I9: =C9/C$12 -> 0.039974473 | J9: =D9/D$12 -> 0.038517739 | K9: =E9/E$12 -> 0.040582027 | L9: =F9/F$12 -> 0.048998185 | N9: 전력제어 | P9: =D9-C9 -> 276570632 | Q9: =E9-D9 -> 2321329254 | R9: =F9*2-E9 -> 6056167662
B10: Roomlamp | C10: 47717791608 | D10: 54174492386 | E10: 58437212647 | F10: 30531103326 | H10: Roomlamp | I10: =C10/C$12 -> 0.090277231 | J10: =D10/D$12 -> 0.097481675 | K10: =E10/E$12 -> 0.099948656 | L10: =F10/F$12 -> 0.10045669 | N10: Roomlamp | P10: =D10-C10 -> 6456700778 | Q10: =E10-D10 -> 4262720261 | R10: =F10*2-E10 -> 2624994005
B11: 부품사업 | C11: 4754087094 | D11: 9629636821 | E11: 12969500563 | F11: 5764099605 | H11: 부품사업 | I11: =C11/C$12 -> 0.0089942515 | J11: =D11/D$12 -> 0.017327585 | K11: =E11/E$12 -> 0.022182512 | L11: =F11/F$12 -> 0.018965655 | N11: 부품사업 | P11: =D11-C11 -> 4875549727 | Q11: =E11-D11 -> 3339863742 | R11: =F11*2-E11 -> -1441301353
B12: 합계 | C12: =SUM(C5:C11) -> 528569510350 | D12: =SUM(D5:D11) -> 555740268125 | E12: =SUM(E5:E11) -> 584672320904 | F12: =SUM(F5:F11) -> 303923046949
B14: Val_8,9 제품별 사업부별 매출액
B15: 사업부별(그룹보고) 매출
C16: 2012년 | D16: 2013년 | E16: 2014년 | F16: 2015년 | H16: ` | I16: 2012년 | J16: 2013년 | K16: 2014년 | L16: 2015년 | N16: ` | O16: 2012년 | P16: 2013년 | Q16: 2014년 | R16: 2015년
B17: 백만원 | C17: 12개월 | D17: 12개월 | E17: 12개월 | F17: 6개월 | H17: 매출액비중 | I17: 2012년 | J17: 2013년 | K17: 2014년 | L17: 2015년 | N17: 매출액비중 | O17: 2012년 | P17: 2013년 | Q17: 2014년 | R17: 2015년
B18: HMI | C18: 349368261452 | D18: 383703631062 | E18: 416255766137 | F18: 220196261096 | H18: HMI | I18: =C18/C$21 -> 0.66096938 | J18: =D18/D$21 -> 0.69043698 | K18: =E18/E$21 -> 0.7119471 | L18: =F18/F$21 -> 0.72451321 | M18: 스위치 매출의 증가 | N18: HMC | P18: =D18-C18 -> 34335369610 | Q18: =E18-D18 -> 32552135075 | R18: =F18*2-E18 -> 24136756055
B19: BCS | C19: 64628911184 | D19: 65472807519 | E19: 72459146793 | F19: 40454935148 | H19: BCS | I19: =C19/C$21 -> 0.12227136 | J19: =D19/D$21 -> 0.11781188 | K19: =E19/E$21 -> 0.12393121 | L19: =F19/F$21 -> 0.13310914 | M19: ECU 전력제어 증가 | N19: BCS | P19: =D19-C19 -> 843896335 | Q19: =E19-D19 -> 6986339274 | R19: =F19*2-E19 -> 8450723503
B20: MC | C20: 114572337714 | D20: 106563829544 | E20: 95957407974 | F20: 43271850705 | H20: MC | I20: =C20/C$21 -> 0.21675926 | J20: =D20/D$21 -> 0.19175114 | K20: =E20/E$21 -> 0.16412169 | L20: =F20/F$21 -> 0.14237765 | M20: 릴레이 매출의 감소, | N20: MC | P20: =D20-C20 -> -8008508170 | Q20: =E20-D20 -> -10606421570 | R20: =F20*2-E20 -> -9413706564
B21: 합계 | C21: =SUM(C18:C20) -> 528569510350 | D21: =SUM(D18:D20) -> 555740268125 | E21: =SUM(E18:E20) -> 584672320904 | F21: =SUM(F18:F20) -> 303923046949
B31: Val_8,9 제품별 사업부별 매출액
B32: 사업부별 제품매출액
C33: 2012년 | D33: 2013년 | E33: 2014년 | F33: 2015년 | I33: 2012년 | J33: 2013년 | K33: 2014년 | L33: 2015년
B34: 백만원 | C34: 12개월 | D34: 12개월 | E34: 12개월 | F34: 6개월 | H34: 매출액비중 | I34: 2012년 | J34: 2013년 | K34: 2014년 | L34: 2015년
B35: 스위치 | C35: 296691633563 | D35: 317822974827 | E35: 329054293426 | F35: 174195511512 | H35: 스위치 | I35: =C35/C$42 -> 0.57128093 | J35: =D35/D$42 -> 0.60105737 | K35: =E35/E$42 -> 0.6137111 | L35: =F35/F$42 -> 0.62389334
B36: 릴레이 | C36: 69793328452 | D36: 62770593661 | E36: 54726687904 | F36: 26891171748 | H36: 릴레이 | I36: =C36/C$42 -> 0.13438733 | J36: =D36/D$42 -> 0.11870988 | K36: =E36/E$42 -> 0.1020694 | L36: =F36/F$42 -> 0.096312602
B37: BCS | C37: 39771393460 | D37: 32162937072 | E37: 22998719481 | F37: 9749865860 | H37: BCS | I37: =C37/C$42 -> 0.076579978 | J37: =D37/D$42 -> 0.060825591 | K37: =E37/E$42 -> 0.042894348 | L37: =F37/F$42 -> 0.034919823
B38: ECU | C38: 43418777428 | D38: 42307741487 | E38: 47816948703 | F38: 24345319543 | H38: ECU | I38: =C38/C$42 -> 0.083603031 | J38: =D38/D$42 -> 0.080011144 | K38: =E38/E$42 -> 0.089182219 | L38: =F38/F$42 -> 0.087194455
B39: 전력제어 | C39: 20767223864 | D39: 21064695432 | E39: 23077848703 | F39: 14201251235 | H39: 전력제어 | I39: =C39/C$42 -> 0.039987373 | J39: =D39/D$42 -> 0.039836926 | K39: =E39/E$42 -> 0.04304193 | L39: =F39/F$42 -> 0.050862769
B40: Roomlamp | C40: 47711967609 | D40: 52294228059 | E40: 57857539144 | F40: 29633582018 | H40: Roomlamp | I40: =C40/C$42 -> 0.091869586 | J40: =D40/D$42 -> 0.09889729 | K40: =E40/E$42 -> 0.10790868 | L40: =F40/F$42 -> 0.10613474
B41: 부품사업 | C41: 1190214467 | D41: 349941738 | E41: 639290671 | F41: 190496254 | H41: 부품사업 | I41: =C41/C$42 -> 0.0022917627 | J41: =D41/D$42 -> 0.00066179942 | K41: =E41/E$42 -> 0.0011923254 | L41: =F41/F$42 -> 0.00068227558
B42: 합계 | C42: =SUM(C35:C41) -> 519344538843 | D42: =SUM(D35:D41) -> 528773112276 | E42: =SUM(E35:E41) -> 536171328032 | F42: =SUM(F35:F41) -> 279207198170
B44: 전체매출액비중 | C44: =C42/C12 -> 0.98254729 | D44: =D42/D12 -> 0.95147525 | E44: =E42/E12 -> 0.91704585 | F44: =F42/F12 -> 0.91867728
B47: Val_8,9 제품별 사업부별 매출액
B48: 사업부별 매출수량
C49: 2012년 | D49: 2013년 | E49: 2014년 | F49: 2015년
B50: 천개 | C50: 12개월 | D50: 12개월 | E50: 12개월 | F50: 6개월 | I50: 2012년 | J50: 2013년 | K50: 2014년 | L50: 2015년
B51: 스위치 | C51: 427220840 | D51: 412124532 | E51: 467000938 | F51: 282652547 | H51: 스위치 | I51: 427220840 | J51: 412124532 | K51: 467000938 | L51: 282652547
B52: 릴레이 | C52: 173003594 | D52: 168959390 | E52: 129588031 | F52: 61046236 | H52: 릴레이 | I52: 173003594 | J52: 168959390 | K52: 129588031 | L52: 61046236
B53: BCS | C53: 25638111 | D53: 26568581 | E53: 20630669 | F53: 12633454 | H53: BCS | I53: 25638111 | J53: 26568581 | K53: 20630669 | L53: 12633454
...

Sheet Sales_05사업부별추세
B2: 2012년 | C2: 2013년 | D2: 2014년 | E2: 2015년 연환산 | F2: 2015년
A3: 스위치 | B3: 301650469844 | C3: 329529138676 | D3: 357818553490 | E3: =F3*2 -> 379330315540 | F3: 189665157770 | H3: =B3/B$12 -> 0.57069215 | I3: =C3/C$12 -> 0.5929553 | J3: =D3/D$12 -> 0.61199845 | K3: =E3/E$12 -> 0.62405652
A4: 릴레이 | B4: 69649481160 | C4: 63547706707 | D4: 56026768138 | E4: =F4*2 -> 54293651228 | F4: 27146825614 | H4: =B4/B$12 -> 0.13176977 | I4: =C4/C$12 -> 0.11434785 | J4: =D4/D$12 -> 0.095825929 | K4: =E4/E$12 -> 0.089321379
A5: BCS | B5: 40168769460 | C5: 33386486016 | D5: 26961139273 | E5: =F5*2 -> 20721850972 | F5: 10360925486 | H5: =B5/B$12 -> 0.075995245 | I5: =C5/C$12 -> 0.060075701 | J5: =D5/D$12 -> 0.046113247 | K5: =E5/E$12 -> 0.034090621
A6: ECU | B6: 43499623320 | C6: 44066949023 | D6: 48731959043 | E6: =F6*2 -> 51126514884 | F6: 25563257442 | H6: =B6/B$12 -> 0.082296883 | I6: =C6/C$12 -> 0.079294144 | J6: =D6/D$12 -> 0.083349181 | K6: =E6/E$12 -> 0.084110954
A7: 전력제어 | B7: 21129287864 | C7: 21405858496 | D7: 23727187750 | E7: =F7*2 -> 29783355412 | F7: 14891677706 | H7: =B7/B$12 -> 0.039974473 | I7: =C7/C$12 -> 0.038517739 | J7: =D7/D$12 -> 0.040582027 | K7: =E7/E$12 -> 0.048998185
A8: RoomLamp | B8: 47717791608 | C8: 54174492386 | D8: 58437212647 | E8: =F8*2 -> 61062206652 | F8: 30531103326 | H8: =B8/B$12 -> 0.090277231 | I8: =C8/C$12 -> 0.097481675 | J8: =D8/D$12 -> 0.099948656 | K8: =E8/E$12 -> 0.10045669
A9: 부품사업팀 | B9: 4754087094 | C9: 9629636821 | D9: 12969500563 | E9: =F9*2 -> 11528199210 | F9: 5764099605 | H9: =B9/B$12 -> 0.0089942515 | I9: =C9/C$12 -> 0.017327585 | J9: =D9/D$12 -> 0.022182512 | K9: =E9/E$12 -> 0.018965655
A10: 스위치 비중 | B10: =B3/B12 -> 0.57069215 | C10: =C3/C12 -> 0.5929553 | D10: =D3/D12 -> 0.61199845 | E10: =E3/E12 -> 0.62405652
B12: =SUM(B3:B9) -> 528569510350 | C12: =SUM(C3:C9) -> 555740268125 | D12: =SUM(D3:D9) -> 584672320904 | E12: =SUM(E3:E9) -> 607846093898
A34: 사업부별 매출
B35: 2012년 | C35: 2013년 | D35: 2014년 | E35: 2015년 연환산
A36: HMI | B36: 349368261452 | C36: 383703631062 | D36: 416255766137 | E36: =F36*2 -> 440392522192 | F36: 220196261096 | H36: =B36/B$40 -> 0.66096938 | I36: =C36/C$40 -> 0.69043698 | J36: =D36/D$40 -> 0.7119471 | K36: =E36/E$40 -> 0.72451321
A37: BCS | B37: 64628911184 | C37: 65472807519 | D37: 72459146793 | E37: =F37*2 -> 80909870296 | F37: 40454935148 | H37: =B37/B$40 -> 0.12227136 | I37: =C37/C$40 -> 0.11781188 | J37: =D37/D$40 -> 0.12393121 | K37: =E37/E$40 -> 0.13310914
A38: MC | B38: 114572337714 | C38: 106563829544 | D38: 95957407974 | E38: =F38*2 -> 86543701410 | F38: 43271850705 | H38: =B38/B$40 -> 0.21675926 | I38: =C38/C$40 -> 0.19175114 | J38: =D38/D$40 -> 0.16412169 | K38: =E38/E$40 -> 0.14237765
B39: =B36/B40 -> 0.66096938 | C39: =C36/C40 -> 0.69043698 | D39: =D36/D40 -> 0.7119471 | E39: =E36/E40 -> 0.72451321
B40: =SUM(B36:B38) -> 528569510350 | C40: =SUM(C36:C38) -> 555740268125 | D40: =SUM(D36:D38) -> 584672320904 | E40: =SUM(E36:E38) -> 607846093898
B63: 사업부별 제품매출액
C64: 2012년 | D64: 2013년 | E64: 2014년 | F64: 2015년
B65: 백만원 | C65: 12개월 | D65: 12개월 | E65: 12개월 | F65: 6개월
B66: 스위치 | C66: 296691633563 | D66: 317822974827 | E66: 329054293426 | F66: 174195511512
B67: 릴레이 | C67: 69793328452 | D67: 62770593661 | E67: 54726687904 | F67: 26891171748
B68: BCS | C68: 39771393460 | D68: 32162937072 | E68: 22998719481 | F68: 9749865860
B69: ECU | C69: 43418777428 | D69: 42307741487 | E69: 47816948703 | F69: 24345319543
B70: 전력제어 | C70: 20767223864 | D70: 21064695432 | E70: 23077848703 | F70: 14201251235
B71: Roomlamp | C71: 47711967609 | D71: 52294228059 | E71: 57857539144 | F71: 29633582018
B72: 부품사업 | C72: 1190214467 | D72: 349941738 | E72: 639290671 | F72: 190496254
B73: 합계 | C73: 519344538843 | D73: 528773112276 | E73: 536171328032 | F73: 279207198170
B76: 사업부별 설비매출액
C77: 2012년 | D77: 2013년 | E77: 2014년 | F77: 2015년
B78: 백만원 | C78: 12개월 | D78: 12개월 | E78: 12개월 | F78: 6개월
B79: 스위치 | C79: 229455283 | D79: 208390504 | E79: 5232644036 | F79: 2008255774
B80: 릴레이 | C80: 0 | D80: 0 | E80: 0 | F80: 0
B81: BCS | C81: 268700000 | D81: 330685342 | E81: 1748118068 | F81: 0
B82: ECU | C82: 0 | D82: 0 | E82: 0 | F82: 0
B83: 전력제어 | C83: 0 | D83: 0 | E83: 0 | F83: 0
B84: Roomlamp | C84: 0 | D84: 0 | E84: 285638653 | F84: 160586472
B85: 부품사업 | C85: 997599590 | D85: 3174994802 | E85: 5375166107 | F85: 755773134
B86: 합계 | C86: 1495754873 | D86: 3714070648 | E86: 12641566864 | F86: 2924615380
B89: 사업부별 일시불매출액
...

Sheet Sales_06월별
B2: 월별 제품매출
C3: 2012년 1월 | D3: 2012년 2월 | E3: 2012년 3월 | F3: 2012년 4월 | G3: 2012년 5월 | H3: 2012년 6월 | I3: 2012년 7월 | J3: 2012년 8월 | K3: 2012년 9월 | L3: 2012년 10월 | M3: 2012년 11월 | N3: 2012년 12월 | O3: 2013년 1월 | P3: 2013년 2월 | Q3: 2013년 3월 | R3: 2013년 4월 | S3: 2013년 5월 | T3: 2013년 6월 | U3: 2013년 7월 | V3: 2013년 8월 | W3: 2013년 9월 | X3: 2013년 10월 | Y3: 2013년 11월 | Z3: 2013년 12월 | AA3: 2014년 1월 | AB3: 2014년 2월 | AC3: 2014년 3월 | AD3: 2014년 4월 | AE3: 2014년 5월 | AF3: 2014년 6월 | AG3: 2014년 7월 | AH3: 2014년 8월 | AI3: 2014년 9월 | AJ3: 2014년 10월 | AK3: 2014년 11월 | AL3: 2014년 12월 | AM3: 2015년 1월 | AN3: 2015년 2월 | AO3: 2015년 3월 | AP3: 2015년 4월 | AQ3: 2015년 5월 | AR3: 2015년 6월
B4: 제품매출(백만원) | C4: 40708099996 | D4: 43747582185 | E4: 45739498620 | F4: 43411672390 | G4: 45115254938 | H4: 45610093720 | I4: 43670801651 | J4: 36358521155 | K4: 40985890485 | L4: 43202342291 | M4: 45760730688 | N4: 45034050724 | O4: 45333802628 | P4: 39217568814 | Q4: 43634787801 | R4: 44687384478 | S4: 42884882168 | T4: 44484044902 | U4: 43464848706 | V4: 41904980145 | W4: 40627534490 | X4: 48893452332 | Y4: 45503091647 | Z4: 48136734165 | AA4: 44770750863 | AB4: 42701133945 | AC4: 48507255496 | AD4: 47481574847 | AE4: 42789599884 | AF4: 44264170668 | AG4: 46171411455 | AH4: 37947630363 | AI4: 39063582296 | AJ4: 45104593900 | AK4: 46501625261 | AL4: 50867999054 | AM4: 46054466935 | AN4: 41739918782 | AO4: 50461281054 | AP4: 49990226066 | AQ4: 42743687946 | AR4: 48217617387
B5: 수량 | C5: 86683652 | D5: 101549519 | E5: 131647549 | F5: 84342407 | G5: 79709434 | H5: 93428368 | I5: 88251425 | J5: 73993875 | K5: 78041598 | L5: 170141244 | M5: 188141196 | N5: 180775103 | O5: 193770288 | P5: 111533446 | Q5: 167929361 | R5: 158345174 | S5: 137108667 | T5: 115932179 | U5: 139176857 | V5: 167416859 | W5: 140206766 | X5: 193955644 | Y5: 185804038 | Z5: 182065605 | AA5: 116024987 | AB5: 176292403 | AC5: 175043187 | AD5: 173550611 | AE5: 200960669 | AF5: 157301653 | AG5: 142694177 | AH5: 168365532 | AI5: 178625938 | AJ5: 206303224 | AK5: 224340690 | AL5: 205079058 | AM5: 255491327 | AN5: 208908636 | AO5: 234398139 | AP5: 239557798 | AQ5: 185624431 | AR5: 170887682
B6: ASP | C6: =C4/C5 -> 469.61681 | D6: =D4/D5 -> 430.80049 | E6: =E4/E5 -> 347.43904 | F6: =F4/F5 -> 514.70753 | G6: =G4/G5 -> 565.99643 | H6: =H4/H5 -> 488.18249 | I6: =I4/I5 -> 494.84529 | J6: =J4/J5 -> 491.37204 | ... AR6: =AR4/AR5 -> 282.1597

Sheet Sales_07제품매출
B3: 사업부별 제품매출액 | H3: 사업부별 제품매출수량 | N3: 사업부별 제품단가
C4: 2012년 | D4: 2013년 | E4: 2014년 | F4: 2015년 | I4: 2012년 | J4: 2013년 | K4: 2014년 | L4: 2015년 | O4: 2012년 | P4: 2013년 | Q4: 2014년 | R4: 2015년
B5: 백만원 | C5: 12개월 | D5: 12개월 | E5: 12개월 | F5: 6개월 | H5: 천개 | I5: 12개월 | J5: 12개월 | K5: 12개월 | L5: 6개월 | N5: 원 | O5: 12개월 | P5: 12개월 | Q5: 12개월 | R5: 6개월
B6: 스위치 | C6: 296691633563 | D6: 317822974827 | E6: 329054293426 | F6: 174195511512 | H6: 스위치 | I6: 427220840 | J6: 412124532 | K6: 467000938 | L6: 282652547 | N6: 스위치 | O6: =C6/I6 -> 694.46901 | P6: =D6/J6 -> 771.18189 | Q6: =E6/K6 -> 704.61163 | R6: =F6/L6 -> 616.28849
B7: 릴레이 | C7: 69793328452 | D7: 62770593661 | E7: 54726687904 | F7: 26891171748 | H7: 릴레이 | I7: 173003594 | J7: 168959390 | K7: 129588031 | L7: 61046236 | N7: 릴레이 | O7: =C7/I7 -> 403.42126 | P7: =D7/J7 -> 371.5129 | Q7: =E7/K7 -> 422.31283 | R7: =F7/L7 -> 440.50499
B8: BCS | C8: 39771393460 | D8: 32162937072 | E8: 22998719481 | F8: 9749865860 | H8: BCS | I8: 25638111 | J8: 26568581 | K8: 20630669 | L8: 12633454 | N8: BCS | O8: =C8/I8 -> 1551.2607 | P8: =D8/J8 -> 1210.5628 | Q8: =E8/K8 -> 1114.783 | R8: =F8/L8 -> 771.74982
B9: ECU | C9: 43418777428 | D9: 42307741487 | E9: 47816948703 | F9: 24345319543 | H9: ECU | I9: 6756172 | J9: 11367487 | K9: 8385809 | L9: 5279566 | N9: ECU | O9: =C9/I9 -> 6426.5352 | P9: =D9/J9 -> 3721.8201 | Q9: =E9/K9 -> 5702.1271 | R9: =F9/L9 -> 4611.235
B10: 전력제어 | C10: 20767223864 | D10: 21064695432 | E10: 23077848703 | F10: 14201251235 | H10: 전력제어 | I10: 834513 | J10: 900638 | K10: 1278158 | L10: 4475007 | N10: 전력제어 | O10: =C10/I10 -> 24885.441 | P10: =D10/J10 -> 23388.637 | Q10: =E10/K10 -> 18055.552 | R10: =F10/L10 -> 3173.459
B11: Roomlamp | C11: 47711967609 | D11: 52294228059 | E11: 57857539144 | F11: 29633582018 | H11: Roomlamp | I11: 12987815 | J11: 13146796 | K11: 13878612 | L11: 7431203 | N11: Roomlamp | O11: =C11/I11 -> 3673.5946 | P11: =D11/J11 -> 3977.7166 | Q11: =E11/K11 -> 4168.8275 | R11: =F11/L11 -> 3987.7234
B12: 부품사업 | C12: 1190214467 | D12: 349941738 | E12: 639290671 | F12: 190496254 | H12: 부품사업 | I12: 710264325 | J12: 1260177460 | K12: 1483819912 | L12: 921350000 | N12: 부품사업 | O12: =C12/I12 -> 1.6757345 | P12: =D12/J12 -> 0.27769243 | Q12: =E12/K12 -> 0.43084115 | R12: =F12/L12 -> 0.20675775
B13: 합계 | C13: =SUM(C6:C12) -> 519344538843 | D13: =SUM(D6:D12) -> 528773112276 | E13: =SUM(E6:E12) -> 536171328032 | F13: =SUM(F6:F12) -> 279207198170 | H13: 합계 | I13: =SUM(I6:I12) -> 1356705370 | J13: =SUM(J6:J12) -> 1893244884 | K13: =SUM(K6:K12) -> 2124582129 | L13: =SUM(L6:L12) -> 1294868013 | N13: 합계
B17: 사업부별 제품매출액
C18: 2012년 | D18: 2013년 | E18: 2014년 | F18: 2015년
B19: 백만원 | C19: 12개월 | D19: 12개월 | E19: 12개월 | F19: 6개월
B20: HMI | C20: =C6+C11 -> 344403601172 | D20: =D6+D11 -> 370117202886 | E20: =E6+E11 -> 386911832570 | F20: =F6+F11 -> 203829093530
B21: BCS | C21: =C9+C10 -> 64186001292 | D21: =D9+D10 -> 63372436919 | E21: =E9+E10 -> 70894797406 | F21: =F9+F10 -> 38546570778
B22: MC | C22: =C7+C8 -> 109564721912 | D22: =D7+D8 -> 94933530733 | E22: =E7+E8 -> 77725407385 | F22: =F7+F8 -> 36641037608
B23: 부품 | C23: =C12 -> 1190214467 | D23: =D12 -> 349941738 | E23: =E12 -> 639290671 | F23: =F12 -> 190496254
B24: 합계 | C24: =SUM(C20:C23) -> 519344538843 | D24: =SUM(D20:D23) -> 528773112276 | E24: =SUM(E20:E23) -> 536171328032 | F24: =SUM(F20:F23) -> 279207198170

Sheet Sales_08설비매출
B1: Val_8,9 제품별 사업부별 매출액
B2: 사업부별 매출액
C3: 2012년 | D3: 2013년 | E3: 2014년 | F3: 2015년 | I3: 2012년 | J3: 2013년 | K3: 2014년 | L3: 2015년
B4: 백만원 | C4: 12개월 | D4: 12개월 | E4: 12개월 | F4: 6개월 | H4: 매출액비중 | I4: 2012년 | J4: 2013년 | K4: 2014년 | L4: 2015년
B5: 스위치 | C5: 301650469844 | D5: 329529138676 | E5: 357818553490 | F5: 189665157770 | H5: 스위치 | I5: =C5/C$12 -> 0.57069215 | J5: =D5/D$12 -> 0.5929553 | K5: =E5/E$12 -> 0.61199845 | L5: =F5/F$12 -> 0.62405652
B6: 릴레이 | C6: 69649481160 | D6: 63547706707 | E6: 56026768138 | F6: 27146825614 | H6: 릴레이 | I6: =C6/C$12 -> 0.13176977 | J6: =D6/D$12 -> 0.11434785 | K6: =E6/E$12 -> 0.095825929 | L6: =F6/F$12 -> 0.089321379
B7: BCS | C7: 40168769460 | D7: 33386486016 | E7: 26961139273 | F7: 10360925486 | H7: BCS | I7: =C7/C$12 -> 0.075995245 | J7: =D7/D$12 -> 0.060075701 | K7: =E7/E$12 -> 0.046113247 | L7: =F7/F$12 -> 0.034090621
B8: ECU | C8: 43499623320 | D8: 44066949023 | E8: 48731959043 | F8: 25563257442 | H8: ECU | I8: =C8/C$12 -> 0.082296883 | J8: =D8/D$12 -> 0.079294144 | K8: =E8/E$12 -> 0.083349181 | L8: =F8/F$12 -> 0.084110954
B9: 전력제어 | C9: 21129287864 | D9: 21405858496 | E9: 23727187750 | F9: 14891677706 | H9: 전력제어 | I9: =C9/C$12 -> 0.039974473 | J9: =D9/D$12 -> 0.038517739 | K9: =E9/E$12 -> 0.040582027 | L9: =F9/F$12 -> 0.048998185
B10: Roomlamp | C10: 47717791608 | D10: 54174492386 | E10: 58437212647 | F10: 30531103326 | H10: Roomlamp | I10: =C10/C$12 -> 0.090277231 | J10: =D10/D$12 -> 0.097481675 | K10: =E10/E$12 -> 0.099948656 | L10: =F10/F$12 -> 0.10045669
B11: 부품사업 | C11: 4754087094 | D11: 9629636821 | E11: 12969500563 | F11: 5764099605 | H11: 부품사업 | I11: =C11/C$12 -> 0.0089942515 | J11: =D11/D$12 -> 0.017327585 | K11: =E11/E$12 -> 0.022182512 | L11: =F11/F$12 -> 0.018965655
B12: 합계 | C12: =SUM(C5:C11) -> 528569510350 | D12: =SUM(D5:D11) -> 555740268125 | E12: =SUM(E5:E11) -> 584672320904 | F12: =SUM(F5:F11) -> 303923046949
B16: 결산명세서
B17: 사업부별 설비매출액
C18: 2012년 | D18: 2013년 | E18: 2014년 | F18: 2015년
B19: 백만원 | C19: 12개월 | D19: 12개월 | E19: 12개월 | F19: 6개월
B20: 금형 | C20: =SUM(C21:C22) -> 102761343 | D20: =SUM(D21:D22) -> 915776802 | E20: =SUM(E21:E22) -> 7166779519 | F20: =SUM(F21:F22) -> 0
B21: 내수 | C21: =매출2012!E48 -> 43790910 | D21: =매출2013!E51 -> 46130555 | E21: =매출2014!E53 -> 58717920
B22: 해외 | C22: =매출2012!E87 -> 58970433 | D22: =매출2013!E88 -> 869646247 | E22: =매출2014!E95 -> 7108061599
B23: 설비 | C23: =SUM(C24:C25) -> 1392993530 | D23: =SUM(D24:D25) -> 2798293845 | E23: =SUM(E24:E25) -> 5474787345 | F23: =SUM(F24:F25) -> 0
B24: 내수 | C24: =매출2012!E51 -> 20776377 | D24: 0 | E24: =매출2014!E54 -> 2000000
B25: 해외 | C25: =매출2012!E90 -> 1372217153 | D25: =매출2013!E87 -> 2798293845 | E25: =매출2014!E96 -> 5472787345
B26: 합계 | C26: =C20+C23 -> 1495754873 | D26: =D20+D23 -> 3714070647 | E26: =E20+E23 -> 12641566864 | F26: =F20+F23 -> 0
B28: 내수 | C28: =C21+C24 -> 64567287 | D28: =D21+D24 -> 46130555 | E28: =E21+E24 -> 60717920 | F28: =F21+F24 -> 0
B29: 해외 | C29: =C22+C25 -> 1431187586 | D29: =D22+D25 -> 3667940092 | E29: =E22+E25 -> 12580848944 | F29: =F22+F25 -> 0
B31: FDD_12,13,18,19,20 2012년 ~ 22015년 6월 매출세부
B32: 거래처별 설비매출액
C33: 2012년 | D33: 2013년 | E33: 2014년 | F33: 2015년
B34: 백만원 | C34: 12개월 | D34: 12개월 | E34: 12개월 | F34: 6개월
B35: 내수 | C35: =SUM(C36:C40) -> 64567287 | D35: =SUM(D36:D40) -> 46130555 | E35: =SUM(E36:E40) -> 60717920 | F35: =SUM(F36:F40) -> 29171760
B36: 엘에스전선(주) | C36: 24008200 | D36: 3096300 | E36: 9784860 | F36: 26151290
B37: 엘에스엠트론(주) | C37: 14732390 | D37: 0 | E37: 0 | F37: 0
B38: (주)후지쿠라코리아 오토모티브 | C38: 5050320 | D38: 43034255 | E38: 48933060 | F38: 3020470
B39: (주)대성엘텍 | C39: 20776377 | D39: 0 | E39: 0 | F39: 0
B40: (주)충현 | C40: 0 | D40: 0 | E40: 2000000 | F40: 0
B41: 해외 | C41: =SUM(C42:C46) -> 1431187586 | D41: =SUM(D42:D46) -> 3667940093 | E41: =SUM(E42:E46) -> 12580848944 | F41: =SUM(F42:F46) -> 2895443620
B42: QINGDAO DAESUNG ELEC | C42: 677941406 | D42: 1195014226 | E42: 1810593624 | F42: 233740872
B43: DAESUNG WUXI ELECTRO | C43: 171799565 | D43: 1343767423 | E43: 4558938731 | F43: 653446974
B44: DAESUNG ELECTRIC IND | C44: 283746615 | D44: 1129158444 | E44: 4701060529 | F44: 1003486342
B45: Sazeh Pouyesh Compan | C45: 297700000 | D45: 0 | E45: 0 | F45: 0
...

Sheet Sales_09기타매출
B2: FDD_12,13,18,19,20 2012년 ~ 22015년 6월 매출세부
B3: 거래처별 기타매출액
C4: 2012년 | D4: 2013년 | E4: 2014년 | F4: 2015년
B5: 백만원 | C5: 12개월 | D5: 12개월 | E5: 12개월 | F5: 6개월
B6: 내수
B7: 쌍용자동차(주) 경기 | C7: 8200000 | D7: 0 | E7: 0 | F7: 0
B8: 태광물산 | C8: 525229 | D8: 0 | E8: 0 | F8: 0
B9: (주)만도 평택 | C9: -3683 | D9: 0 | E9: 0 | F9: 0
B10: 삼영전자공업(주) | C10: 2538331 | D10: 0 | E10: 0 | F10: 0
B11: 엠에스웨이(주) | C11: 36217954 | D11: 0 | E11: 0 | F11: 0
B12: (주)데스코 | C12: 22629842 | D12: 0 | E12: 0 | F12: 0
B13: (주)친환경에버뷰 | C13: 24100 | D13: 0 | E13: 0 | F13: 0
B14: (주) 에나인더스트리 | C14: 5775000 | D14: 0 | E14: 0 | F14: 0
B15: 삼우에레코 주식회사 | C15: 0 | D15: 1137983 | E15: 0 | F15: 0
B16: 이세전자 | C16: 0 | D16: 12529366 | E16: 0 | F16: 0
B17: 엠에스웨이(주) | C17: 0 | D17: 0 | E17: 14209609 | F17: 0
B18: (주)삼진포리머 | C18: 0 | D18: 0 | E18: 4069650 | F18: 0
B19: (주)대동 | C19: 0 | D19: 0 | E19: 0 | F19: 2050000
B20: 소계 | C20: =SUM(C7:C19) -> 75906773 | D20: =SUM(D7:D19) -> 13667349 | E20: =SUM(E7:E19) -> 18279259 | F20: =SUM(F7:F19) -> 2050000
B21: 해외
B22: QINGDAO DAESUNG ELEC | C22: 3232844833 | D22: 8397951043 | E22: 12448064293 | F22: 7939098393 | H22: 부품
B23: DAESUNG WUXI ELECTRO | C23: 2764595971 | D23: 3797321233 | E23: 4918770623 | F23: 3315809552
B24: DAESUNG ELECTRIC IND | C24: 1527760382 | D24: 944112872 | E24: 1418610592 | F24: 1036099605
B25: Sazeh Pouyesh Compan | C25: 128676000 | D25: 0 | E25: 0 | F25: 0
B26: Piston Trading LLC | C26: 31358975 | D26: 0 | E26: 0 | F26: 0
B27: 파생 | C27: -31926300 | D27: 2092366000 | E27: 4530542000 | F27: 1369108000
B28: 소계 | C28: =SUM(C22:C27) -> 7653309861 | D28: =SUM(D22:D27) -> 15231751148 | E28: =SUM(E22:E27) -> 23315987508 | F28: =SUM(F22:F27) -> 13660115550
B29: 합계 | C29: =C20+C28 -> 7729216634 | D29: =D20+D28 -> 15245418497 | E29: =E20+E28 -> 23334266767 | F29: =F20+F28 -> 13662165550
B31: 자회사 | C31: =SUM(C22:C24) -> 7525201186 | D31: =SUM(D22:D24) -> 13139385148 | E31: =SUM(E22:E24) -> 18785445508 | F31: =SUM(F22:F24) -> 12291007550
B32: 자회사비중% | C32: =C31/C29 -> 0.97360464 | D32: =D31/D29 -> 0.86185795 | E32: =E31/E29 -> 0.80505832 | F32: =F31/F29 -> 0.89963831
B35: 부품
B38: 미파악 매출
C39: 2012년 | D39: 2013년 | E39: 2014년 | F39: 2015년
B40: 백만원 | C40: 12개월 | D40: 12개월 | E40: 12개월 | F40: 6개월
B41: 일시불매출 | C41: 0 | D41: 6868222586 | E41: 11094937572 | F41: 3631721911
B42: 용역과제매출 | C42: 0 | D42: 1139444118 | E42: 1430221669 | F42: 176840000
B43: 자회사로열티매출 | C43: 0 | D43: 0 | E43: 0 | F43: 4320505938
B44: 기타매출 | C44: 7729216634 | D44: 15245418497 | E44: 23334266767 | F44: 13662165550
B47: 자회사로열티매출(기타수익) | C47: 2731350327 | D47: 4116265656 | E47: 6524290406 | F47: 4320505938

Sheet 사업부별손익
E2: =E7-C7 -> 56102810554 | S2: =S7-Q7 -> 56168083646
AC3: 구분 | AD3: 2012년 | AE3: 2013년 | AF3: 2014년 | AG3: 2015년 1~6월 | AH3: 2012년 | AI3: 2013년 | AJ3: 2014년 | AK3: 2015년 1~6월 | AL3: 2012년 | AM3: 2013년 | AN3: 2014년 | AO3: 2015년 1~6월 | AP3: 2012년 | AQ3: 2013년 | AR3: 2014년 | AS3: 2015년 1~6월 | AT3: 2012년 | AU3: 2013년 | AV3: 2014년 | AW3: 2015년 1~6월 | AX3: 2012년 | AY3: 2013년 | AZ3: 2014년 | BA3: 2015년 1~6월 | BB3: 2012년 | BC3: 2013년 | BD3: 2014년 | BE3: 2015년 1~6월 | BF3: 2012년 | BG3: 2013년 | BH3: 2014년 | BI3: 2015년 1~6월
B4: 사업부별 마진분석_전체 | H4: 사업부별 CM분석_전체 | P4: 사업부별 마진분석_스위치 | V4: 사업부별 CM분석_스위치 | AD4: 스위치 | AE4: 스위치 | AF4: 스위치 | AG4: 스위치 | AH4: 릴레이 | AI4: 릴레이 | AJ4: 릴레이 | AK4: 릴레이 | AL4: BCS | AM4: BCS | AN4: BCS | AO4: BCS | AP4: ECU | AQ4: ECU | AR4: ECU | AS4: ECU | AT4: 전력제어 | AU4: 전력제어 | AV4: 전력제어 | AW4: 전력제어 | AX4: RoomLamp | AY4: RoomLamp | AZ4: RoomLamp | BA4: RoomLamp | BB4: 부품사업팀 | BC4: 부품사업팀 | BD4: 부품사업팀 | BE4: 부품사업팀 | BF4: 합계 | BG4: 합계 | BH4: 합계 | BI4: 합계
C5: 2012년 | D5: 2013년 | E5: 2014년 | F5: 2015년 | I5: 2012년 | J5: 2013년 | K5: 2014년 | L5: 2015년 | Q5: 2012년 | R5: 2013년 | S5: 2014년 | T5: 2015년 | W5: 2012년 | X5: 2013년 | Y5: 2014년 | Z5: 2015년 | AC5: 1.매출액 수량 | AD5: 427220840 | AE5: 412124532 | AF5: 467000938 | AG5: 282652547 | AH5: 173003594 | AI5: 168959390 | AJ5: 129588031 | AK5: 61046236 | AL5: 25638111 | AM5: 26568581 | AN5: 20630669 | AO5: 12633454 | AP5: 6756172 | AQ5: 11367487 | AR5: 8385809 | AS5: 5279566 | AT5: 834513 | AU5: 900638 | AV5: 1278158 | AW5: 4475007 | AX5: 12987815 | AY5: 13146796 | AZ5: 13878612 | BA5: 7431203 | BB5: 710264325 | BC5: 1260177460 | BD5: 1483819912 | BE5: 921350000 | BF5: 1356705370 | BG5: 1893244884 | BH5: 2124582129 | BI5: 1294868013
B6: 백만원 | C6: 12개월 | D6: 12개월 | E6: 12개월 | F6: 6개월 | H6: 백만원 | I6: 12개월 | J6: 12개월 | K6: 12개월 | L6: 6개월 | P6: 백만원 | Q6: 12개월 | R6: 12개월 | S6: 12개월 | T6: 6개월 | V6: 백만원 | W6: 12개월 | X6: 12개월 | Y6: 12개월 | Z6: 6개월 | AC6: 제품매출 | AD6: 296691633563 | AE6: 317822974827 | AF6: 329054293426 | AG6: 174195511512 | AH6: 69793328452 | AI6: 62770593661 | AJ6: 54726687904 | AK6: 26891171748 | AL6: 39771393460 | AM6: 32162937072 | AN6: 22998719481 | AO6: 9749865860 | AP6: 43418777428 | AQ6: 42307741487 | AR6: 47816948703 | AS6: 24345319543 | AT6: 20767223864 | AU6: 21064695432 | AV6: 23077848703 | AW6: 14201251235 | AX6: 47711967609 | AY6: 52294228059 | AZ6: 57857539144 | BA6: 29633582018 | BB6: 1190214467 | BC6: 349941738 | BD6: 639290671 | BE6: 190496254 | BF6: 519344538843 | BG6: 528773112276 | BH6: 536171328032 | BI6: 279207198170
B7: 매출 | C7: =BF12 -> 528569510350 | D7: =BG12 -> 555740268125 | E7: =BH12 -> 584672320904 | F7: =BI12 -> 303923046949 | H7: 매출 | I7: =BF12 -> 528569510350 | J7: =BG12 -> 555740268125 | K7: =BH12 -> 584672320904 | L7: =BI12 -> 303923046949 | P7: 매출 | Q7: =AD12 -> 301650469844 | R7: =AE12 -> 329529138676 | S7: =AF12 -> 357818553490 | T7: =AG12 -> 189665157770 | V7: 매출 | W7: =AD12 -> 301650469844 | X7: =AE12 -> 329529138676 | Y7: =AF12 -> 357818553490 | Z7: =AG12 -> 189665157770 | AC7: 설비매출 | AD7: 229455283 | AE7: 208390504 | AF7: 5232644036 | AG7: 2008255774 | AH7: 0 | AI7: 0 | AJ7: 0 | AK7: 0 | AL7: 268700000 | AM7: 330685342 | AN7: 1748118068 | AO7: 0 | AP7: 0 | AQ7: 0 | AR7: 0 | AS7: 0 | AT7: 0 | AU7: 0 | AV7: 0 | AW7: 0 | AX7: 0 | AY7: 0 | AZ7: 285638653 | BA7: 160586472 | BB7: 997599590 | BC7: 3174994802 | BD7: 5375166107 | BE7: 755773134 | BF7: 1495754873 | BG7: 3714070648 | BH7: 12641566864 | BI7: 2924615380
B8: 매출원가 | C8: =BF36 -> 475725626210 | D8: =BG36 -> 499445340398 | E8: =BH36 -> 524218029958 | F8: =BI36 -> 273015109365 | H8: 재료비 | I8: =BF13 -> 352268620252 | J8: =BG13 -> 363893330049 | K8: =BH13 -> 381121250912 | L8: =BI13 -> 195831038107 | M8: =K8/K$7 -> 0.65185444 | P8: 매출원가 | Q8: =AD36 -> 269960864470 | R8: =AE36 -> 296358237035 | S8: =AF36 -> 322622742567 | T8: =AG36 -> 170152050497 | V8: 재료비 | W8: =AD13 -> 194886390241 | X8: =AE13 -> 210800399971 | Y8: =AF13 -> 230758364896 | Z8: =AG13 -> 121304219739 | AA8: =Y8/Y7 -> 0.6449033 | AC8: 일시불 매출 | AD8: 0 | AE8: 4021923644 | AF8: 9301776759 | AG8: 2677331021 | AH8: 0 | AI8: 0 | AJ8: 140185300 | AK8: 0 | AL8: 0 | AM8: 17447048 | AN8: 1082055615 | AO8: 127504320 | AP8: 0 | AQ8: 828003249 | AR8: 258229898 | AS8: 323194000 | AT8: 0 | AU8: -6698680 | AV8: 62630000 | AW8: 101566570 | AX8: 0 | AY8: 1810350000 | AZ8: 250060000 | BA8: 402126000 | BB8: 0 | BC8: 197197325 | BD8: 0 | BE8: 0 | BF8: 0 | BG8: 6868222586 | BH8: 11094937572 | BI8: 3631721911
B9: 매출총이익 | C9: =C7-C8 -> 52843884140 | D9: =D7-D8 -> 56294927727 | E9: =E7-E8 -> 60454290946 | F9: =F7-F8 -> 30907937584 | H9: 직접인건비 | I9: =BF24 -> 3334775091 | J9: =BG24 -> 3716744273 | K9: =BH24 -> 3723298066 | L9: =BI24 -> 2039628825 | M9: =K9/K$7 -> 0.0063681791 | P9: 매출총이익 | Q9: =Q7-Q8 -> 31689605374 | R9: =R7-R8 -> 33170901641 | S9: =S7-S8 -> 35195810923 | T9: =T7-T8 -> 19513107273 | V9: 직접인건비 | W9: =AD24 -> 1445166144 | X9: =AE24 -> 1520208795 | Y9: =AF24 -> 1508590795 | Z9: =AG24 -> 837340604 | AC9: 용역과제매출 | AD9: 0 | AE9: 0 | AF9: 934105408 | AG9: 0 | AH9: 0 | AI9: 0 | AJ9: 0 | AK9: 0 | AL9: 0 | AM9: 270524118 | AN9: 0 | AO9: 0 | AP9: 0 | AQ9: 813920000 | AR9: 324900000 | AS9: 113600000 | AT9: 0 | AU9: 0 | AV9: 171216261 | AW9: 0 | AX9: 0 | AY9: 55000000 | AZ9: 0 | BA9: 63240000 | BB9: 0 | BC9: 0 | BD9: 0 | BE9: 0 | BF9: 0 | BG9: 1139444118 | BH9: 1430221669 | BI9: 176840000
B10: 매출총이익% | C10: =C9/C7 -> 0.099975279 | D10: =D9/D7 -> 0.10129719 | E10: =E9/E7 -> 0.10339859 | F10: =F9/F7 -> 0.10169659 | H10: 외주비 | I10: =SUM(BF27:BF28) -> 42812279442 | J10: =SUM(BG27:BG28) -> 47897101592 | K10: =SUM(BH27:BH28) -> 50304835915 | L10: =SUM(BI27:BI28) -> 27696459923 | M10: =K10/K$7 -> 0.086039366 | P10: 매출총이익% | Q10: =Q9/Q$7 -> 0.10505406 | R10: =R9/R$7 -> 0.10066151 | S10: =S9/S$7 -> 0.098362174 | T10: =T9/T$7 -> 0.10288188 | V10: 외주비 | W10: =SUM(AD27:AD28) -> 31677418810 | X10: =SUM(AE27:AE28) -> 37090176654 | Y10: =SUM(AF27:AF28) -> 38768573600 | Z10: =SUM(AG27:AG28) -> 21389907628 | AC10: 자회사 로열티 매출 | AG10: 3502675094 | AK10: 51367098 | AO10: 16280104 | AS10: 203011697 | AW10: 86726 | BA10: 170455150 | BE10: 376630069 | BI10: 4320505938
B11: 판매관리비 | C11: =BF41 -> 43792009823 | D11: =BG41 -> 41361745470 | E11: =BH41 -> 44247827700 | F11: =BI41 -> 20978070672 | H11: 판매비 | I11: =SUM(BF42:BF45) -> 26799595366 | J11: =SUM(BG42:BG45) -> 26362159667 | K11: =SUM(BH42:BH45) -> 28321154451 | L11: =SUM(BI42:BI45) -> 12844989521 | M11: =K11/K$7 -> 0.048439362 | P11: 판매관리비 | Q11: =AD41 -> 29398219654 | R11: =AE41 -> 29088772983 | S11: =AF41 -> 30757672015 | T11: =AG41 -> 14231381521 | V11: 판매비 | W11: =SUM(AD42:AD45) -> 19377716237 | X11: =SUM(AE42:AE45) -> 19978953777 | Y11: =SUM(AF42:AF45) -> 21171033705 | Z11: =SUM(AG42:AG45) -> 9250225747 | AC11: 기타매출 | AD11: 4729380998 | AE11: 7475849701 | AF11: 13295733861 | AG11: 7281384369 | AH11: -143847292 | AI11: 777113046 | AJ11: 1159894934 | AK11: 204286768 | AL11: 128676000 | AM11: 604892436 | AN11: 1132246109 | AO11: 467275202 | AP11: 80845892 | AQ11: 117284287 | AR11: 331880442 | AS11: 578132202 | AT11: 362064000 | AU11: 347861744 | AV11: 415492786 | AW11: 588773175 | AX11: 5823999 | AY11: 14914327 | AZ11: 43974850 | BA11: 101113686 | BB11: 2566273037 | BC11: 5907502956 | BD11: 6955043785 | BE11: 4441200148 | BF11: 7729216634 | BG11: 15245418497 | BH11: 23334266767 | BI11: 13662165550
B12: 영업이익 | C12: =C9-C11 -> 9051874317 | D12: =D9-D11 -> 14933182257 | E12: =E9-E11 -> 16206463246 | F12: =F9-F11 -> 9929866912 | H12: 공헌이익 | I12: =I7-SUM(I8:I11) -> 103354240199 | J12: =J7-SUM(J8:J11) -> 113870932544 | K12: =K7-SUM(K8:K11) -> 121201781560 | L12: =L7-SUM(L8:L11) -> 65510930573 | P12: 영업이익 | Q12: =Q9-Q11 -> 2291385720 | R12: =R9-R11 -> 4082128658 | S12: =S9-S11 -> 4438138908 | T12: =T9-T11 -> 5281725752 | V12: 공헌이익 | W12: =W7-SUM(W8:W11) -> 54263778412 | X12: =X7-SUM(X8:X11) -> 60139399479 | Y12: =Y7-SUM(Y8:Y11) -> 65611990494 | Z12: =Z7-SUM(Z8:Z11) -> 36883464052 | AC12: 매출액 합계 | AD12: 301650469844 | AE12: 329529138676 | AF12: 357818553490 | AG12: 189665157770 | AH12: 69649481160 | AI12: 63547706707 | AJ12: 56026768138 | AK12: 27146825614 | AL12: 40168769460 | AM12: 33386486016 | AN12: 26961139273 | AO12: 10360925486 | AP12: 43499623320 | AQ12: 44066949023 | AR12: 48731959043 | AS12: 25563257442 | AT12: 21129287864 | AU12: 21405858496 | AV12: 23727187750 | AW12: 14891677706 | AX12: 47717791608 | AY12: 54174492386 | AZ12: 58437212647 | BA12: 30531103326 | BB12: 4754087094 | BC12: 9629636821 | BD12: 12969500563 | BE12: 5764099605 | BF12: 528569510350 | BG12: 555740268125 | BH12: 584672320904 | BI12: 303923046949
B13: 영업이익% | C13: =C12/C7 -> 0.01712523 | D13: =D12/D7 -> 0.026870794 | E13: =E12/E7 -> 0.027718882 | F13: =F12/F7 -> 0.032672306 | H13: 공헌이익% | I13: =I12/I$7 -> 0.19553576 | J13: =J12/J$7 -> 0.20489955 | K13: =K12/K$7 -> 0.20729865 | L13: =L12/L$7 -> 0.21555105 | P13: 영업이익% | Q13: =Q12/Q$7 -> 0.0075961616 | R13: =R12/R$7 -> 0.012387762 | S13: =S12/S$7 -> 0.012403322 | T13: =T12/T$7 -> 0.027847633 | V13: 공헌이익% | W13: =W12/W$7 -> 0.17988959 | X13: =X12/X$7 -> 0.18250101 | Y13: =Y12/Y$7 -> 0.18336665 | Z13: =Z12/Z$7 -> 0.19446621 | AC13: 2.재료비 합계 | AD13: 194886390241 | AE13: 210800399971 | AF13: 230758364896 | AG13: 121304219739 | AH13: 40702372545 | AI13: 37569239939 | AJ13: 30577437749 | AK13: 14033459273 | AL13: 26345154160 | AM13: 21085010054 | AN13: 18075937589 | AO13: 6525375145 | AP13: 28690417143 | AQ13: 27019228816 | AR13: 27482740582 | AS13: 14115100993 | AT13: 14401129395 | AU13: 13913763375 | AV13: 15160225506 | AW13: 9316599172 | AX13: 42998507019 | AY13: 46351454256 | AZ13: 49020488526 | BA13: 26179002174 | BB13: 4244649749 | BC13: 7154233638 | BD13: 10046056064 | BE13: 4357281611 | BF13: 352268620252 | BG13: 363893330049 | BH13: 381121250912 | BI13: 195831038107 | BJ13: =BF13/BF$12 -> 0.66645657 | BK13: =BG13/BG$12 -> 0.65479029 | BL13: =BH13/BH$12 -> 0.65185444 | BM13: =BI13/BI$12 -> 0.64434415
AC14: 사내재료비 | AD14: 111855798147 | AE14: 108788023605 | AF14: 104256303089 | AG14: 55392533398 | AH14: 33482994453 | AI14: 31850651505 | AJ14: 27637981207 | AK14: 13250861383 | AL14: 21829176853 | AM14: 15984895414 | AN14: 12638798385 | AO14: 5020373454 | AP14: 26449993206 | AQ14: 22875535041 | AR14: 23230609982 | AS14: 11918769104 | AT14: 14437286162 | AU14: 13802047227 | AV14: 14606153794 | AW14: 9042124890 | AX14: 43004300061 | AY14: 43938929548 | AZ14: 48348655734 | BA14: 25563156760 | BB14: 989227550 | BC14: 254331007 | BD14: 382842683 | BE14: 129235964 | BF14: 252048776432 | BG14: 237494413347 | BH14: 231101344874 | BI14: 120317054953
H15: 고정매출원가 | I15: =C8-SUM(I8:I10) -> 77309951425 | J15: =D8-SUM(J8:J10) -> 83938164484 | K15: =E8-SUM(K8:K10) -> 89068645065 | L15: =F8-SUM(L8:L10) -> 47447982510
H16: 고정판관비 | I16: =C11-I11 -> 16992414457 | J16: =D11-J11 -> 14999585803 | K16: =E11-K11 -> 15926673249 | L16: =F11-L11 -> 8133081151
H17: 영업이익 | I17: =I12-I15-I16 -> 9051874317 | J17: =J12-J15-J16 -> 14933182257 | K17: =K12-K15-K16 -> 16206463246 | L17: =L12-L15-L16 -> 9929866912 | AC17: 재료비(원자재외) | AD17: 2517688933 | AE17: 4603083969 | AF17: 7049907131 | AG17: 4092836283 | AH17: 219759182 | AI17: 198940782 | AJ17: 73205541 | AK17: 34589287 | AL17: 0 | AM17: 126185779 | AN17: 236343333 | AO17: 307809485 | AP17: 63420644 | AQ17: 211482355 | AR17: 141414834 | AS17: 415545819 | AT17: 0 | AU17: 3903587 | AV17: 910531 | AW17: 4545941 | AX17: 4355501 | AY17: 8679801 | AZ17: 2890847 | BA17: 3332730 | BB17: 2354667753 | BC17: 4328653660 | BD17: 4887011142 | BE17: 3003309984 | BF17: 5159892013 | BG17: 9480929933 | BH17: 12391683359 | BI17: 7861969529
AC18: 재료비(금형/설비) | AD18: 144353380 | AE18: 151487903 | AF18: 5035230767 | AG18: 1885539955 | AH18: 0 | AI18: 0 | AJ18: 0 | AK18: 0 | AL18: 88000000 | AM18: 307500000 | AN18: 1651535597 | AO18: 0 | AP18: 0 | AQ18: 0 | AR18: 0 | AS18: 0 | AT18: 0 | AU18: 0 | AV18: 0 | AW18: 0 | AX18: 0 | AY18: 0 | AZ18: 251346290 | BA18: 129000000 | BB18: 755338050 | BC18: 2238830294 | BD18: 4473291074 | BE18: 523409512 | BF18: 987691430 | BG18: 2697818197 | BH18: 11411403728 | BI18: 2537949467
E19: =E24-C24 -> 66887504685 | K19: =K24-I24 -> 66887504685 | S19: =S24-Q24 -> -13622713022 | AC19: 일시불원가 | AD19: 0 | AE19: 3409448527 | AF19: 7427974124 | AG19: 2199642791 | AH19: 0 | AI19: 0 | AJ19: 59600000 | AK19: 0 | AL19: 0 | AM19: 15375000 | AN19: 835610305 | AO19: 113903873 | AP19: 0 | AQ19: 745605358 | AR19: 143715526 | AS19: 293972038 | AT19: 0 | AU19: 2000000 | AV19: 70500000 | AW19: 44000000 | AX19: 0 | AY19: 1605993576 | AZ19: 202578831 | BA19: 295000000 | BB19: 0 | BC19: 183462500 | BD19: 0 | BE19: 0 | BF19: 0 | BG19: 5961884961 | BH19: 8739978786 | BI19: 2946518702
B20: 스위치, Roomlamp | H20: 스위치, Roomlamp | AC20: 용역과제원가 | AD20: 0 | AE20: 0 | AF20: 753767748 | AG20: 0 | AH20: 0 | AI20: 0 | AJ20: 0 | AK20: 0 | AL20: 0 | AM20: 153951814 | AN20: 0 | AO20: 0 | AP20: 0 | AQ20: 359787811 | AR20: 295622560 | AS20: 71312199 | AT20: 0 | AU20: 0 | AV20: 112916318 | AW20: 0 | AX20: 0 | AY20: 28406661 | AZ20: 0 | BA20: 48531349 | BB20: 0 | BC20: 0 | BD20: 0 | BE20: 0 | BF20: 0 | BG20: 542146286 | BH20: 1162306626 | BI20: 119843548
B21: 사업부별 마진분석_HMI | H21: 사업부별 CM분석_HMI | P21: 사업부별 마진분석_릴레이 | V21: 사업부별 CM분석_릴레이 | AC21: 외주자체재료비 | AD21: 79496339860 | AE21: 91134624165 | AF21: 100635870628 | AG21: 53776074058 | AH21: 6904521680 | AI21: 4638819956 | AJ21: 2329360337 | AK21: 810891375 | AL21: 4306574911 | AM21: 4328243781 | AN21: 2487175993 | AO21: 1024798706 | AP21: 2078310820 | AQ21: 2613312799 | AR21: 2979077688 | AS21: 1168655884 | AT21: 37098437 | AU21: 43843716 | AV21: 114002499 | AW21: 57467814 | AX21: 0 | AY21: 0 | AZ21: 0 | BA21: 0 | BB21: 0 | BC21: 88 | BD21: 76 | BE21: 19 | BF21: 92822845708 | BG21: 102758844505 | BH21: 108545487221 | BI21: 56837887856
C22: 2012년 | D22: 2013년 | E22: 2014년 | F22: 2015년 | I22: 2012년 | J22: 2013년 | K22: 2014년 | L22: 2015년 | Q22: 2012년 | R22: 2013년 | S22: 2014년 | T22: 2015년 | W22: 2012년 | X22: 2013년 | Y22: 2014년 | Z22: 2015년 | AC22: 매출원가조정 | AD22: 872209921 | AE22: 2713731802 | AF22: 5599311409 | AG22: 3957593254 | AH22: 95097230 | AI22: 880827696 | AJ22: 477290664 | AK22: -62882772 | AL22: 121402396 | AM22: 168858266 | AN22: 226473976 | AO22: 58489627 | AP22: 98692473 | AQ22: 213505452 | AR22: 692299992 | AS22: 246845949 | AT22: -73255204 | AU22: 61968845 | AV22: 255742364 | AW22: 168460527 | AX22: -10148543 | AY22: 769444670 | AZ22: 215016824 | BA22: 139981335 | BB22: 145416396 | BC22: 148956089 | BD22: 302911089 | BE22: 701326132 | BF22: 1249414669 | BG22: 4957292820 | BH22: 7769046318 | BI22: 5209814052
