Workbook

Sheet Legend
B2: Title | D2: Project dummy Financial Model
B4: Version | D4: Draft
B6: Date | D6: 46022
B8: Currency | D8: 별도표시가 없는 한 모든통화는 원(KRW)임
B10: Legend
B12: 구분 | D12: 설 명
B13: Value | D13: 상수
B14: Value | D14: Control 변수
B15: Value | D15: 참조값
B16: Value | D16: 수식결과값
B17: Value | D17: 총 합계
B18: Value | D18: 운영기간 합계
B19: VBA | D19: VBA참조셀 [삭제금지]
B20: Text | D20: 출처/설명
B21: Flag | D21: FALSE(논리값)
B22: Flag | D22: TRUE(논리값)
D23: Blank

Sheet Input
B1: =Legend!D2 | N1: DRAFT - For Discussion Purposes Only
B2: Assumptions
B4: Time Period
B6: Actual/Forecast | G6: Actual | H6: Actual | I6: Actual | J6: Forecast | K6: Forecast | L6: Forecast | M6: Forecast | N6: Forecast | O6: Forecast
B7: Period Start | G7: =DATE(G10,1,1) | H7: =DATE(H10,1,1) | I7: =DATE(I10,1,1) | J7: =DATE(J10,1,1) | K7: =DATE(K10,1,1) | L7: =DATE(L10,1,1) | M7: =DATE(M10,1,1) | N7: =DATE(N10,1,1) | O7: TV
B8: Period End | G8: =DATE(G10,12,31) | H8: =DATE(H10,12,31) | I8: =DATE(I10,12,31) | J8: =DATE(J10,12,31) | K8: =DATE(K10,12,31) | L8: =DATE(L10,12,31) | M8: =DATE(M10,12,31) | N8: =DATE(N10,12,31)
B9: Month | G9: =DATEDIF(G7,G8,"m")+1 | H9: =DATEDIF(H7,H8,"m")+1 | I9: =DATEDIF(I7,I8,"m")+1 | J9: =DATEDIF(J7,J8,"m")+1 | K9: =DATEDIF(K7,K8,"m")+1 | L9: =DATEDIF(L7,L8,"m")+1 | M9: =DATEDIF(M7,M8,"m")+1 | N9: =DATEDIF(N7,N8,"m")+1
B10: Year | G10: =H10-1 | H10: =I10-1 | I10: =E16 | J10: =I10+1 | K10: =J10+1 | L10: =K10+1 | M10: =L10+1 | N10: =M10+1
B11: Days | G11: =_xlfn.DAYS(G8,G7) | H11: =_xlfn.DAYS(H8,H7) | I11: =_xlfn.DAYS(I8,I7) | J11: =_xlfn.DAYS(J8,J7) | K11: =_xlfn.DAYS(K8,K7) | L11: =_xlfn.DAYS(L8,L7) | M11: =_xlfn.DAYS(M8,M7) | N11: =_xlfn.DAYS(N8,N7)
B13: 1. General Assumptions
B15: Model Date | E15: =Legend!D6
B16: Model Year | E16: =YEAR(E15)
B17: Unit | E17: 1000000 | F17: KRW
B18: WACC | E18: 0.1 | F18: %
B19: Perpetual Growth | E19: 0.01 | F19: %
B20: Industry Growth | J20: 1.03 | K20: 1.03 | L20: 1.03 | M20: 1.03 | N20: 1.03
B21: Nominal Wage Growth | J21: 1.02 | K21: 1.02 | L21: 1.02 | M21: 1.02 | N21: 1.02
B22: CPI | J22: 1.02 | K22: 1.02 | L22: 1.02 | M22: 1.02 | N22: 1.02
B23: PPI | J23: 1.02 | K23: 1.02 | L23: 1.02 | M23: 1.02 | N23: 1.02
B25: 2. Historical Financials
B27: [Profit & Loss] | G27: ="FY"&G10 | H27: ="FY"&H10 | I27: ="FY"&I10
B28: 매출 | G28: 1000 | H28: 1200 | I28: 1400
B29: 원가 | G29: =SUM(G30:G33) | H29: =SUM(H30:H33) | I29: =SUM(I30:I33)
B30: 재료비 | G30: 200 | H30: 200 | I30: 200
B31: 인건비 | G31: 100 | H31: 100 | I31: 100
B32: 기타경비 -변동비 | G32: 100 | H32: 100 | I32: 100
B33: 기타경비 -고정비 | G33: 200 | H33: 200 | I33: 200
B34: 매출총이익 | G34: =G28-G29 | H34: =H28-H29 | I34: =I28-I29
B35: 판관비 | G35: =SUM(G36:G40) | H35: =SUM(H36:H40) | I35: =SUM(I36:I40)
B36: 인건비 | G36: 100 | H36: 100 | I36: 100
B37: 변동비-#1 | G37: 50 | H37: 50 | I37: 50
B38: 변동비-#2 | G38: 60 | H38: 60 | I38: 60
B39: 변동비-#3 | G39: 70 | H39: 70 | I39: 70
B40: 고정비 | G40: 50 | H40: 50 | I40: 50
B41: 영업이익 | G41: =G34-G35 | H41: =H34-H35 | I41: =I34-I35
B42: 감가상각비 | G42: 10 | H42: 10 | I42: 10
B43: EBITDA | G43: =G41+G42 | H43: =H41+H42 | I43: =I41+I42
B44: 영업외손익 | G44: =G45-G48 | H44: =H45-H48 | I44: =I45-I48
B45: 영업외수익 | G45: =SUM(G46:G47) | H45: =SUM(H46:H47) | I45: =SUM(I46:I47)
B46: 이자손익 | G46: 10 | H46: 10 | I46: 10
...

Sheet Calculation
B1: =Legend!D2
B2: Calculations
B4: Time Period
B6: Actual/Forecast | G6: =Input!G6 | H6: =Input!H6 | I6: =Input!I6 | J6: =Input!J6 | K6: =Input!K6 | L6: =Input!L6 | M6: =Input!M6 | N6: =Input!N6 | O6: =Input!O6
B7: Period Start | G7: =Input!G7 | H7: =Input!H7 | I7: =Input!I7 | J7: =Input!J7 | K7: =Input!K7 | L7: =Input!L7 | M7: =Input!M7 | N7: =Input!N7 | O7: TV
B8: Period End | G8: =Input!G8 | H8: =Input!H8 | I8: =Input!I8 | J8: =Input!J8 | K8: =Input!K8 | L8: =Input!L8 | M8: =Input!M8 | N8: =Input!N8
B9: Month | G9: =Input!G9 | H9: =Input!H9 | I9: =Input!I9 | J9: =Input!J9 | K9: =Input!K9 | L9: =Input!L9 | M9: =Input!M9 | N9: =Input!N9
B10: Year | G10: =Input!G10 | H10: =Input!H10 | I10: =Input!I10 | J10: =Input!J10 | K10: =Input!K10 | L10: =Input!L10 | M10: =Input!M10 | N10: =Input!N10
B11: Days | G11: =Input!G11 | H11: =Input!H11 | I11: =Input!I11 | J11: =Input!J11 | K11: =Input!K11 | L11: =Input!L11 | M11: =Input!M11 | N11: =Input!N11
B13: Revenue
B15: [Total revenue]
B16: Revenue #1 | F16: KRW mn | G16: =G29 | H16: =H29 | I16: =I29 | J16: =J29 | K16: =K29 | L16: =L29 | M16: =M29 | N16: =N29
B17: Revenue #2 | F17: KRW mn | G17: =G36 | H17: =H36 | I17: =I36 | J17: =J36 | K17: =K36 | L17: =L36 | M17: =M36 | N17: =N36
B18: Revenue #3 | F18: KRW mn | G18: =G43 | H18: =H43 | I18: =I43 | J18: =J43 | K18: =K43 | L18: =L43 | M18: =M43 | N18: =N43
B19: Revenue #4 | F19: KRW mn | G19: =G50 | H19: =H50 | I19: =I50 | J19: =J50 | K19: =K50 | L19: =L50 | M19: =M50 | N19: =N50
B20: Revenue #5 | F20: KRW mn | G20: =G57 | H20: =H57 | I20: =I57 | J20: =J57 | K20: =K57 | L20: =L57 | M20: =M57 | N20: =N57
B21: Total Revenue | F21: KRW mn | G21: =SUM(G16:G20) | H21: =SUM(H16:H20) | I21: =SUM(I16:I20) | J21: =SUM(J16:J20) | K21: =SUM(K16:K20) | L21: =SUM(L16:L20) | M21: =SUM(M16:M20) | N21: =SUM(N16:N20)
B22: check | G22: =G21=Input!G28 | H22: =H21=Input!H28 | I22: =I21=Input!I28
B24: [Revenue breakdown] - #1
B25: Price_real | F25: KRW/Kg | G25: =SUMIFS(Input!$G$85:$N$85,Input!$G$7:$N$7,Calculation!G$7) | H25: =SUMIFS(Input!$G$85:$N$85,Input!$G$7:$N$7,Calculation!H$7) | I25: =SUMIFS(Input!$G$85:$N$85,Input!$G$7:$N$7,Calculation!I$7) | J25: =SUMIFS(Input!$G$85:$N$85,Input!$G$7:$N$7,Calculation!J$7) | K25: =SUMIFS(Input!$G$85:$N$85,Input!$G$7:$N$7,Calculation!K$7) | L25: =SUMIFS(Input!$G$85:$N$85,Input!$G$7:$N$7,Calculation!L$7) | M25: =SUMIFS(Input!$G$85:$N$85,Input!$G$7:$N$7,Calculation!M$7) | N25: =SUMIFS(Input!$G$85:$N$85,Input!$G$7:$N$7,Calculation!N$7)
B26: Industry Growth | F26: % | G26: =SUMIFS(Input!$G$20:$N$20,Input!$G$7:$N$7,Calculation!G$7) | H26: =SUMIFS(Input!$G$20:$N$20,Input!$G$7:$N$7,Calculation!H$7) | I26: =SUMIFS(Input!$G$20:$N$20,Input!$G$7:$N$7,Calculation!I$7) | J26: =SUMIFS(Input!$G$20:$N$20,Input!$G$7:$N$7,Calculation!J$7) | K26: =SUMIFS(Input!$G$20:$N$20,Input!$G$7:$N$7,Calculation!K$7) | L26: =SUMIFS(Input!$G$20:$N$20,Input!$G$7:$N$7,Calculation!L$7) | M26: =SUMIFS(Input!$G$20:$N$20,Input!$G$7:$N$7,Calculation!M$7) | N26: =SUMIFS(Input!$G$20:$N$20,Input!$G$7:$N$7,Calculation!N$7)
B27: Price_Nominal | F27: KRW/Kg | G27: =IFERROR(G25*G26,"") | H27: =IFERROR(H25*H26,"") | I27: =IFERROR(I25*I26,"") | J27: =IFERROR(J25*J26,"") | K27: =IFERROR(J27*K26,"") | L27: =IFERROR(K27*L26,"") | M27: =IFERROR(L27*M26,"") | N27: =IFERROR(M27*N26,"")
B28: Quantity | F28: Kg | G28: =SUMIFS(Input!$G$86:$N$86,Input!$G$7:$N$7,Calculation!G$7) | H28: =SUMIFS(Input!$G$86:$N$86,Input!$G$7:$N$7,Calculation!H$7) | I28: =SUMIFS(Input!$G$86:$N$86,Input!$G$7:$N$7,Calculation!I$7) | J28: =SUMIFS(Input!$G$86:$N$86,Input!$G$7:$N$7,Calculation!J$7) | K28: =SUMIFS(Input!$G$86:$N$86,Input!$G$7:$N$7,Calculation!K$7) | L28: =SUMIFS(Input!$G$86:$N$86,Input!$G$7:$N$7,Calculation!L$7) | M28: =SUMIFS(Input!$G$86:$N$86,Input!$G$7:$N$7,Calculation!M$7) | N28: =SUMIFS(Input!$G$86:$N$86,Input!$G$7:$N$7,Calculation!N$7)
B29: Revenue | F29: KRW mn | G29: =G27*G28/mn | H29: =H27*H28/mn | I29: =I27*I28/mn | J29: =J27*J28/mn | K29: =K27*K28/mn | L29: =L27*L28/mn | M29: =M27*M28/mn | N29: =N27*N28/mn
B31: [Revenue breakdown] - #2
B32: Price_real | F32: KRW/Kg | G32: =SUMIFS(Input!$G$91:$N$91,Input!$G$7:$N$7,Calculation!G$7) | H32: =SUMIFS(Input!$G$91:$N$91,Input!$G$7:$N$7,Calculation!H$7) | I32: =SUMIFS(Input!$G$91:$N$91,Input!$G$7:$N$7,Calculation!I$7) | J32: =SUMIFS(Input!$G$91:$N$91,Input!$G$7:$N$7,Calculation!J$7) | K32: =SUMIFS(Input!$G$91:$N$91,Input!$G$7:$N$7,Calculation!K$7) | L32: =SUMIFS(Input!$G$91:$N$91,Input!$G$7:$N$7,Calculation!L$7) | M32: =SUMIFS(Input!$G$91:$N$91,Input!$G$7:$N$7,Calculation!M$7) | N32: =SUMIFS(Input!$G$91:$N$91,Input!$G$7:$N$7,Calculation!N$7)
B33: Industry Growth | F33: % | G33: =SUMIFS(Input!$G$20:$N$20,Input!$G$7:$N$7,Calculation!G$7) | H33: =SUMIFS(Input!$G$20:$N$20,Input!$G$7:$N$7,Calculation!H$7) | I33: =SUMIFS(Input!$G$20:$N$20,Input!$G$7:$N$7,Calculation!I$7) | J33: =SUMIFS(Input!$G$20:$N$20,Input!$G$7:$N$7,Calculation!J$7) | K33: =SUMIFS(Input!$G$20:$N$20,Input!$G$7:$N$7,Calculation!K$7) | L33: =SUMIFS(Input!$G$20:$N$20,Input!$G$7:$N$7,Calculation!L$7) | M33: =SUMIFS(Input!$G$20:$N$20,Input!$G$7:$N$7,Calculation!M$7) | N33: =SUMIFS(Input!$G$20:$N$20,Input!$G$7:$N$7,Calculation!N$7)
B34: Price_Nominal | F34: KRW/Kg | G34: =IFERROR(G32*G33,"") | H34: =IFERROR(H32*H33,"") | I34: =IFERROR(I32*I33,"") | J34: =IFERROR(J32*J33,"") | K34: =IFERROR(J34*K33,"") | L34: =IFERROR(K34*L33,"") | M34: =IFERROR(L34*M33,"") | N34: =IFERROR(M34*N33,"")
B35: Quantity | F35: Kg | G35: =SUMIFS(Input!$G$92:$N$92,Input!$G$7:$N$7,Calculation!G$7) | H35: =SUMIFS(Input!$G$92:$N$92,Input!$G$7:$N$7,Calculation!H$7) | I35: =SUMIFS(Input!$G$92:$N$92,Input!$G$7:$N$7,Calculation!I$7) | J35: =SUMIFS(Input!$G$92:$N$92,Input!$G$7:$N$7,Calculation!J$7) | K35: =SUMIFS(Input!$G$92:$N$92,Input!$G$7:$N$7,Calculation!K$7) | L35: =SUMIFS(Input!$G$92:$N$92,Input!$G$7:$N$7,Calculation!L$7) | M35: =SUMIFS(Input!$G$92:$N$92,Input!$G$7:$N$7,Calculation!M$7) | N35: =SUMIFS(Input!$G$92:$N$92,Input!$G$7:$N$7,Calculation!N$7)
B36: Revenue | F36: KRW mn | G36: =G34*G35/mn | H36: =H34*H35/mn | I36: =I34*I35/mn | J36: =J34*J35/mn | K36: =K34*K35/mn | L36: =L34*L35/mn | M36: =M34*M35/mn | N36: =N34*N35/mn
B38: [Revenue breakdown] - #3
B39: Price_real | F39: KRW/Kg | G39: =SUMIFS(Input!$G$97:$N$97,Input!$G$7:$N$7,Calculation!G$7) | H39: =SUMIFS(Input!$G$97:$N$97,Input!$G$7:$N$7,Calculation!H$7) | I39: =SUMIFS(Input!$G$97:$N$97,Input!$G$7:$N$7,Calculation!I$7) | J39: =SUMIFS(Input!$G$97:$N$97,Input!$G$7:$N$7,Calculation!J$7) | K39: =SUMIFS(Input!$G$97:$N$97,Input!$G$7:$N$7,Calculation!K$7) | L39: =SUMIFS(Input!$G$97:$N$97,Input!$G$7:$N$7,Calculation!L$7) | M39: =SUMIFS(Input!$G$97:$N$97,Input!$G$7:$N$7,Calculation!M$7) | N39: =SUMIFS(Input!$G$97:$N$97,Input!$G$7:$N$7,Calculation!N$7)
B40: Industry Growth | F40: % | G40: =SUMIFS(Input!$G$20:$N$20,Input!$G$7:$N$7,Calculation!G$7) | H40: =SUMIFS(Input!$G$20:$N$20,Input!$G$7:$N$7,Calculation!H$7) | I40: =SUMIFS(Input!$G$20:$N$20,Input!$G$7:$N$7,Calculation!I$7) | J40: =SUMIFS(Input!$G$20:$N$20,Input!$G$7:$N$7,Calculation!J$7) | K40: =SUMIFS(Input!$G$20:$N$20,Input!$G$7:$N$7,Calculation!K$7) | L40: =SUMIFS(Input!$G$20:$N$20,Input!$G$7:$N$7,Calculation!L$7) | M40: =SUMIFS(Input!$G$20:$N$20,Input!$G$7:$N$7,Calculation!M$7) | N40: =SUMIFS(Input!$G$20:$N$20,Input!$G$7:$N$7,Calculation!N$7)
B41: Price_Nominal | F41: KRW/Kg | G41: =IFERROR(G39*G40,"") | H41: =IFERROR(H39*H40,"") | I41: =IFERROR(I39*I40,"") | J41: =IFERROR(J39*J40,"") | K41: =IFERROR(J41*K40,"") | L41: =IFERROR(K41*L40,"") | M41: =IFERROR(L41*M40,"") | N41: =IFERROR(M41*N40,"")
B42: Quantity | F42: Kg | G42: =SUMIFS(Input!$G$98:$N$98,Input!$G$7:$N$7,Calculation!G$7) | H42: =SUMIFS(Input!$G$98:$N$98,Input!$G$7:$N$7,Calculation!H$7) | I42: =SUMIFS(Input!$G$98:$N$98,Input!$G$7:$N$7,Calculation!I$7) | J42: =SUMIFS(Input!$G$98:$N$98,Input!$G$7:$N$7,Calculation!J$7) | K42: =SUMIFS(Input!$G$98:$N$98,Input!$G$7:$N$7,Calculation!K$7) | L42: =SUMIFS(Input!$G$98:$N$98,Input!$G$7:$N$7,Calculation!L$7) | M42: =SUMIFS(Input!$G$98:$N$98,Input!$G$7:$N$7,Calculation!M$7) | N42: =SUMIFS(Input!$G$98:$N$98,Input!$G$7:$N$7,Calculation!N$7)
B43: Revenue | F43: KRW mn | G43: =G41*G42/mn | H43: =H41*H42/mn | I43: =I41*I42/mn | J43: =J41*J42/mn | K43: =K41*K42/mn | L43: =L41*L42/mn | M43: =M41*M42/mn | N43: =N41*N42/mn
B45: [Revenue breakdown] - #4
B46: Price_real | F46: KRW/Kg | G46: =SUMIFS(Input!$G$103:$N$103,Input!$G$7:$N$7,Calculation!G$7) | H46: =SUMIFS(Input!$G$103:$N$103,Input!$G$7:$N$7,Calculation!H$7) | I46: =SUMIFS(Input!$G$103:$N$103,Input!$G$7:$N$7,Calculation!I$7) | J46: =SUMIFS(Input!$G$103:$N$103,Input!$G$7:$N$7,Calculation!J$7) | K46: =SUMIFS(Input!$G$103:$N$103,Input!$G$7:$N$7,Calculation!K$7) | L46: =SUMIFS(Input!$G$103:$N$103,Input!$G$7:$N$7,Calculation!L$7) | M46: =SUMIFS(Input!$G$103:$N$103,Input!$G$7:$N$7,Calculation!M$7) | N46: =SUMIFS(Input!$G$103:$N$103,Input!$G$7:$N$7,Calculation!N$7)
B47: Industry Growth | F47: % | G47: =SUMIFS(Input!$G$20:$N$20,Input!$G$7:$N$7,Calculation!G$7) | H47: =SUMIFS(Input!$G$20:$N$20,Input!$G$7:$N$7,Calculation!H$7) | I47: =SUMIFS(Input!$G$20:$N$20,Input!$G$7:$N$7,Calculation!I$7) | J47: =SUMIFS(Input!$G$20:$N$20,Input!$G$7:$N$7,Calculation!J$7) | K47: =SUMIFS(Input!$G$20:$N$20,Input!$G$7:$N$7,Calculation!K$7) | L47: =SUMIFS(Input!$G$20:$N$20,Input!$G$7:$N$7,Calculation!L$7) | M47: =SUMIFS(Input!$G$20:$N$20,Input!$G$7:$N$7,Calculation!M$7) | N47: =SUMIFS(Input!$G$20:$N$20,Input!$G$7:$N$7,Calculation!N$7)
B48: Price_Nominal | F48: KRW/Kg | G48: =IFERROR(G46*G47,"") | H48: =IFERROR(H46*H47,"") | I48: =IFERROR(I46*I47,"") | J48: =IFERROR(J46*J47,"") | K48: =IFERROR(J48*K47,"") | L48: =IFERROR(K48*L47,"") | M48: =IFERROR(L48*M47,"") | N48: =IFERROR(M48*N47,"")
...

Sheet DCF
B1: =Legend!D2
B2: DCF
B4: Time Period
B6: Actual/Forecast | G6: =Input!G6 | H6: =Input!H6 | I6: =Input!I6 | J6: =Input!J6 | K6: =Input!K6 | L6: =Input!L6 | M6: =Input!M6 | N6: =Input!N6 | O6: =Input!O6
B7: Period Start | G7: =Input!G7 | H7: =Input!H7 | I7: =Input!I7 | J7: =Input!J7 | K7: =Input!K7 | L7: =Input!L7 | M7: =Input!M7 | N7: =Input!N7 | O7: TV
B8: Period End | G8: =Input!G8 | H8: =Input!H8 | I8: =Input!I8 | J8: =Input!J8 | K8: =Input!K8 | L8: =Input!L8 | M8: =Input!M8 | N8: =Input!N8
B9: Month | G9: =Input!G9 | H9: =Input!H9 | I9: =Input!I9 | J9: =Input!J9 | K9: =Input!K9 | L9: =Input!L9 | M9: =Input!M9 | N9: =Input!N9
B10: Year | G10: =Input!G10 | H10: =Input!H10 | I10: =Input!I10 | J10: =Input!J10 | K10: =Input!K10 | L10: =Input!L10 | M10: =Input!M10 | N10: =Input!N10
B11: Days | G11: =Input!G11 | H11: =Input!H11 | I11: =Input!I11 | J11: =Input!J11 | K11: =Input!K11 | L11: =Input!L11 | M11: =Input!M11 | N11: =Input!N11
B13: DCF
B15: WACC | E15: =Input!E18
B16: Perptual Growth | E16: =Input!E19
G18: Actual | J18: Forecast
B19: Currency: KRW mn | G19: ="FY"&G10 | H19: ="FY"&H10 | I19: ="FY"&I10 | J19: ="FY"&J10 | K19: ="FY"&K10 | L19: ="FY"&L10 | M19: ="FY"&M10 | N19: ="FY"&N10 | O19: TV
B20: Revenue | G20: =Input!G28 | H20: =Input!H28 | I20: =Input!I28 | J20: =Calculation!J21 | K20: =Calculation!K21 | L20: =Calculation!L21 | M20: =Calculation!M21 | N20: =Calculation!N21 | O20: =N20*(1+$E$16)
B21: Growth% | H21: =H20/G20-1 | I21: =I20/H20-1 | J21: =J20/I20-1 | K21: =K20/J20-1 | L21: =L20/K20-1 | M21: =M20/L20-1 | N21: =N20/M20-1 | O21: =O20/N20-1
B22: COGS | G22: =Input!G29 | H22: =Input!H29 | I22: =Input!I29 | J22: =Calculation!J70 | K22: =Calculation!K70 | L22: =Calculation!L70 | M22: =Calculation!M70 | N22: =Calculation!N70 | O22: =N22*(1+$E$16)
B23: Gross profit | G23: =G20-G22 | H23: =H20-H22 | I23: =I20-I22 | J23: =J20-J22 | K23: =K20-K22 | L23: =L20-L22 | M23: =M20-M22 | N23: =N20-N22 | O23: =O20-O22
B24: Gross margin | G24: =G23/G20 | H24: =H23/H20 | I24: =I23/I20 | J24: =J23/J20 | K24: =K23/K20 | L24: =L23/L20 | M24: =M23/M20 | N24: =N23/N20 | O24: =O23/O20
B25: SG&A | G25: =Input!G35 | H25: =Input!H35 | I25: =Input!I35 | J25: =Calculation!J113 | K25: =Calculation!K113 | L25: =Calculation!L113 | M25: =Calculation!M113 | N25: =Calculation!N113 | O25: =N25*(1+$E$16)
B26: SG&A% | G26: =G25/G20 | H26: =H25/H20 | I26: =I25/I20 | J26: =J25/J20 | K26: =K25/K20 | L26: =L25/L20 | M26: =M25/M20 | N26: =N25/N20 | O26: =O25/O20
B27: EBIT | G27: =G23-G25 | H27: =H23-H25 | I27: =I23-I25 | J27: =J23-J25 | K27: =K23-K25 | L27: =L23-L25 | M27: =M23-M25 | N27: =N23-N25 | O27: =O23-O25
B28: EBIT% | G28: =G27/G20 | H28: =H27/H20 | I28: =I27/I20 | J28: =J27/J20 | K28: =K27/K20 | L28: =L27/L20 | M28: =M27/M20 | N28: =N27/N20 | O28: =O27/O20
B29: Dep&Amor. | G29: =Input!G42 | H29: =Input!H42 | I29: =Input!I42
B30: EBITDA | G30: =G27+G29 | H30: =H27+H29 | I30: =I27+I29 | J30: =J27+J29 | K30: =K27+K29 | L30: =L27+L29 | M30: =M27+M29 | N30: =N27+N29 | O30: =O27+O29
B31: EBITDA % | G31: =G30/G20 | H31: =H30/H23 | I31: =I30/I23 | J31: =J30/J23 | K31: =K30/K23 | L31: =L30/L23 | M31: =M30/M23 | N31: =N30/N23 | O31: =O30/O23
B32: CIT | G32: =Input!G52 | H32: =Input!H52 | I32: =Input!I52 | J32: =IF(J27<=200, J27*0.1*1.1, IF(J27<=30000, ((J27-200)*0.2 + 200*0.1)*1.1, IF(J27<=300000, ((J27-30000)*0.22 + (30000-200)*0.2 + 200*0.1)*1.1, ((J27-300000)*0.24 + (300000-30000)*0.22 + (30000-200)*0.2 + 200*0.1)*1.1))) | K32: =IF(K27<=200, K27*0.1*1.1, IF(K27<=30000, ((K27-200)*0.2 + 200*0.1)*1.1, IF(K27<=300000, ((K27-30000)*0.22 + (30000-200)*0.2 + 200*0.1)*1.1, ((K27-300000)*0.24 + (300000-30000)*0.22 + (30000-200)*0.2 + 200*0.1)*1.1))) | L32: =IF(L27<=200, L27*0.1*1.1, IF(L27<=30000, ((L27-200)*0.2 + 200*0.1)*1.1, IF(L27<=300000, ((L27-30000)*0.22 + (30000-200)*0.2 + 200*0.1)*1.1, ((L27-300000)*0.24 + (300000-30000)*0.22 + (30000-200)*0.2 + 200*0.1)*1.1))) | M32: =IF(M27<=200, M27*0.1*1.1, IF(M27<=30000, ((M27-200)*0.2 + 200*0.1)*1.1, IF(M27<=300000, ((M27-30000)*0.22 + (30000-200)*0.2 + 200*0.1)*1.1, ((M27-300000)*0.24 + (300000-30000)*0.22 + (30000-200)*0.2 + 200*0.1)*1.1))) | N32: =IF(N27<=200, N27*0.1*1.1, IF(N27<=30000, ((N27-200)*0.2 + 200*0.1)*1.1, IF(N27<=300000, ((N27-30000)*0.22 + (30000-200)*0.2 + 200*0.1)*1.1, ((N27-300000)*0.24 + (300000-30000)*0.22 + (30000-200)*0.2 + 200*0.1)*1.1))) | O32: =IF(O27<=200, O27*0.1*1.1, IF(O27<=30000, ((O27-200)*0.2 + 200*0.1)*1.1, IF(O27<=300000, ((O27-30000)*0.22 + (30000-200)*0.2 + 200*0.1)*1.1, ((O27-300000)*0.24 + (300000-30000)*0.22 + (30000-200)*0.2 + 200*0.1)*1.1)))
B33: NOPLAT | G33: =G30-G32 | H33: =H30-H32 | I33: =I30-I32 | J33: =J30-J32 | K33: =K30-K32 | L33: =L30-L32 | M33: =M30-M32 | N33: =N30-N32 | O33: =O30-O32
B34: Dep&Amor. | G34: =G29 | H34: =H29 | I34: =I29
B35: △Net working capital | G35: =Input!G203 | H35: =Input!H203 | I35: =Input!I203 | J35: =Calculation!J170 | K35: =Calculation!K170 | L35: =Calculation!L170 | M35: =Calculation!M170 | N35: =Calculation!N170 | O35: =Calculation!O170
B36: CAPEX
B37: Free cash flow | G37: =SUM(G33:G36) | H37: =SUM(H33:H36) | I37: =SUM(I33:I36) | J37: =SUM(J33:J36) | K37: =SUM(K33:K36) | L37: =SUM(L33:L36) | M37: =SUM(M33:M36) | N37: =SUM(N33:N36) | O37: =SUM(O33:O36)
B38: Discount period | J38: =(J8-Input!E15)/DCF!J11/2 | K38: =J38+1 | L38: =K38+1 | M38: =L38+1 | N38: =M38+1 | O38: =N38
B39: PV factor | J39: =1/(1+$E$15)^DCF!J38 | K39: =1/(1+$E$15)^DCF!K38 | L39: =1/(1+$E$15)^DCF!L38 | M39: =1/(1+$E$15)^DCF!M38 | N39: =1/(1+$E$15)^DCF!N38 | O39: =1/(1+$E$15)^DCF!O38
B40: PV of FCF | J40: =J37*J39 | K40: =K37*K39 | L40: =L37*L39 | M40: =M37*M39 | N40: =N37*N39 | O40: =O37*O39
B41: Operating value | O41: =SUM(J40:O40)
B42: Non-operating assets | O42: =Input!I253
B43: Enterprise value | O43: =O41+O42
B44: Net debt | O44: =Input!I248
B45: Equity value (100%) | O45: =O43-O44
...

Sheet WACC
B1: =Legend!D2
B2: WACC Analysis
B4: Time Period
B6: Actual/Forecast | G6: =Input!G6 | H6: =Input!H6 | I6: =Input!I6 | J6: =Input!J6 | K6: =Input!K6 | L6: =Input!L6 | M6: =Input!M6 | N6: =Input!N6 | O6: =Input!O6
B7: Period Start | G7: =Input!G7 | H7: =Input!H7 | I7: =Input!I7 | J7: =Input!J7 | K7: =Input!K7 | L7: =Input!L7 | M7: =Input!M7 | N7: =Input!N7 | O7: TV
B8: Period End | G8: =Input!G8 | H8: =Input!H8 | I8: =Input!I8 | J8: =Input!J8 | K8: =Input!K8 | L8: =Input!L8 | M8: =Input!M8 | N8: =Input!N8
B9: Month | G9: =Input!G9 | H9: =Input!H9 | I9: =Input!I9 | J9: =Input!J9 | K9: =Input!K9 | L9: =Input!L9 | M9: =Input!M9 | N9: =Input!N9
B10: Year | G10: =Input!G10 | H10: =Input!H10 | I10: =Input!I10 | J10: =Input!J10 | K10: =Input!K10 | L10: =Input!L10 | M10: =Input!M10 | N10: =Input!N10 | O10: =Input!O10
B11: Days | G11: =Input!G11 | H11: =Input!H11 | I11: =Input!I11 | J11: =Input!J11 | K11: =Input!K11 | L11: =Input!L11 | M11: =Input!M11 | N11: =Input!N11
B13: Weighted Average Cost of Capital (WACC)
B15: [Cost of Equity - CAPM]
B17: Risk-free Rate (Rf) | E17: 0.035 | F17: %
B18: Equity Risk Premium (ERP) | E18: 0.06 | F18: %
B19: Beta (β) | E19: 1 | F19: x
B20: Size Premium | E20: 0.02 | F20: %
B21: Country Risk Premium | E21: 0.01 | F21: %
B22: Cost of Equity (Ke) | E22: =E17+E19*E18+E20+E21 | F22: %
B24: [Cost of Debt]
B26: Pre-tax Cost of Debt | E26: =Input!E217 | F26: %
B27: Effective Tax Rate | E27: 0.22 | F27: %
B28: After-tax Cost of Debt (Kd) | E28: =E26*(1-E27) | F28: %
B30: [Capital Structure]
B32: Equity Value (Market Cap) | E32: =DCF!O45 | F32: KRW mn
B33: Debt Value (Book Value) | E33: =Input!I248 | F33: KRW mn
B34: Total Capital | E34: =E32+E33 | F34: KRW mn
B35: Equity Weight (We) | E35: =IFERROR(E32/E34,0) | F35: %
B36: Debt Weight (Wd) | E36: =IFERROR(E33/E34,0) | F36: %
B38: WACC Calculation
B40: WACC | E40: =E35*E22+E36*E28 | F40: %
B42: vs Input WACC | E42: =Input!E18
B45: WACC Sensitivity Analysis
B47: Cost of Equity (Ke)
D48: ERP → | E48: 0.04 | F48: 0.05 | G48: 0.06 | H48: 0.07 | I48: 0.08
C49: β ↓ | D49: 0.8 | E49: =$E$17+$D49*E$48+$E$20+$E$21 | F49: =$E$17+$D49*F$48+$E$20+$E$21 | G49: =$E$17+$D49*G$48+$E$20+$E$21 | H49: =$E$17+$D49*H$48+$E$20+$E$21 | I49: =$E$17+$D49*I$48+$E$20+$E$21
D50: 0.9 | E50: =$E$17+$D50*E$48+$E$20+$E$21 | F50: =$E$17+$D50*F$48+$E$20+$E$21 | G50: =$E$17+$D50*G$48+$E$20+$E$21 | H50: =$E$17+$D50*H$48+$E$20+$E$21 | I50: =$E$17+$D50*I$48+$E$20+$E$21
D51: 1 | E51: =$E$17+$D51*E$48+$E$20+$E$21 | F51: =$E$17+$D51*F$48+$E$20+$E$21 | G51: =$E$17+$D51*G$48+$E$20+$E$21 | H51: =$E$17+$D51*H$48+$E$20+$E$21 | I51: =$E$17+$D51*I$48+$E$20+$E$21
D52: 1.1 | E52: =$E$17+$D52*E$48+$E$20+$E$21 | F52: =$E$17+$D52*F$48+$E$20+$E$21 | G52: =$E$17+$D52*G$48+$E$20+$E$21 | H52: =$E$17+$D52*H$48+$E$20+$E$21 | I52: =$E$17+$D52*I$48+$E$20+$E$21
D53: 1.2 | E53: =$E$17+$D53*E$48+$E$20+$E$21 | F53: =$E$17+$D53*F$48+$E$20+$E$21 | G53: =$E$17+$D53*G$48+$E$20+$E$21 | H53: =$E$17+$D53*H$48+$E$20+$E$21 | I53: =$E$17+$D53*I$48+$E$20+$E$21

Sheet GPCM
B1: =Legend!D2
B2: Guideline Public Company Method (GPCM)
B4: Time Period
B6: Actual/Forecast | G6: =Input!G6 | H6: =Input!H6 | I6: =Input!I6 | J6: =Input!J6 | K6: =Input!K6 | L6: =Input!L6 | M6: =Input!M6 | N6: =Input!N6 | O6: =Input!O6
B7: Period Start | G7: =Input!G7 | H7: =Input!H7 | I7: =Input!I7 | J7: =Input!J7 | K7: =Input!K7 | L7: =Input!L7 | M7: =Input!M7 | N7: =Input!N7 | O7: TV
B8: Period End | G8: =Input!G8 | H8: =Input!H8 | I8: =Input!I8 | J8: =Input!J8 | K8: =Input!K8 | L8: =Input!L8 | M8: =Input!M8 | N8: =Input!N8
B9: Month | G9: =Input!G9 | H9: =Input!H9 | I9: =Input!I9 | J9: =Input!J9 | K9: =Input!K9 | L9: =Input!L9 | M9: =Input!M9 | N9: =Input!N9
B10: Year | G10: =Input!G10 | H10: =Input!H10 | I10: =Input!I10 | J10: =Input!J10 | K10: =Input!K10 | L10: =Input!L10 | M10: =Input!M10 | N10: =Input!N10 | O10: =Input!O10
B11: Days | G11: =Input!G11 | H11: =Input!H11 | I11: =Input!I11 | J11: =Input!J11 | K11: =Input!K11 | L11: =Input!L11 | M11: =Input!M11 | N11: =Input!N11
B13: Comparable Company Analysis
B15: [Comparable Companies]
B17: Company | C17: Ticker | D17: Market Cap (KRW mn) | E17: EV (KRW mn) | F17: Revenue (KRW mn) | G17: EBITDA (KRW mn) | H17: EBIT (KRW mn) | I17: Net Income (KRW mn) | J17: EV/Revenue | K17: EV/EBITDA | L17: EV/EBIT | M17: P/E
B18: Comp #1 | K18: =IFERROR(E18/G18,"-") | L18: =IFERROR(E18/H18,"-") | M18: =IFERROR(E18/I18,"-") | N18: =IFERROR(D18/J18,"-")
B19: Comp #2 | K19: =IFERROR(E19/G19,"-") | L19: =IFERROR(E19/H19,"-") | M19: =IFERROR(E19/I19,"-") | N19: =IFERROR(D19/J19,"-")
B20: Comp #3 | K20: =IFERROR(E20/G20,"-") | L20: =IFERROR(E20/H20,"-") | M20: =IFERROR(E20/I20,"-") | N20: =IFERROR(D20/J20,"-")
B21: Comp #4 | K21: =IFERROR(E21/G21,"-") | L21: =IFERROR(E21/H21,"-") | M21: =IFERROR(E21/I21,"-") | N21: =IFERROR(D21/J21,"-")
B22: Comp #5 | K22: =IFERROR(E22/G22,"-") | L22: =IFERROR(E22/H22,"-") | M22: =IFERROR(E22/I22,"-") | N22: =IFERROR(D22/J22,"-")
B24: [Multiple Summary Statistics]
K26: EV/Revenue | L26: EV/EBITDA | M26: EV/EBIT | N26: P/E
B27: Mean | K27: =IFERROR(AVERAGE(K18:K22),"-") | L27: =IFERROR(AVERAGE(L18:L22),"-") | M27: =IFERROR(AVERAGE(M18:M22),"-") | N27: =IFERROR(AVERAGE(N18:N22),"-")
B28: Median | K28: =IFERROR(MEDIAN(K18:K22),"-") | L28: =IFERROR(MEDIAN(L18:L22),"-") | M28: =IFERROR(MEDIAN(M18:M22),"-") | N28: =IFERROR(MEDIAN(N18:N22),"-")
B29: Max | K29: =IFERROR(MAX(K18:K22),"-") | L29: =IFERROR(MAX(L18:L22),"-") | M29: =IFERROR(MAX(M18:M22),"-") | N29: =IFERROR(MAX(N18:N22),"-")
B30: Min | K30: =IFERROR(MIN(K18:K22),"-") | L30: =IFERROR(MIN(L18:L22),"-") | M30: =IFERROR(MIN(M18:M22),"-") | N30: =IFERROR(MIN(N18:N22),"-")
B32: [Selected Multiples & Valuation]
B34: Selected Multiple
B36: Target Company Financials
B37: Revenue | F37: KRW mn | G37: =DCF!N20
B38: EBITDA | F38: KRW mn | G38: =DCF!N30
B39: EBIT | F39: KRW mn | G39: =DCF!N27
B40: Net Income | F40: KRW mn | G40: =DCF!N80
B42: Implied Enterprise Value
B43: EV (Revenue multiple) | F43: KRW mn | G43: =K34*G37
B44: EV (EBITDA multiple) | F44: KRW mn | G44: =L34*G38
B45: EV (EBIT multiple) | F45: KRW mn | G45: =M34*G39
B47: Implied Equity Value
B48: Equity (P/E multiple) | F48: KRW mn | G48: =N34*G40
B49: Equity (EV-based, EBITDA) | F49: KRW mn | G49: =G44-Input!I248

Sheet GTM
B1: =Legend!D2
B2: Guideline Transaction Method (GTM)
B4: Time Period
B6: Actual/Forecast | G6: =Input!G6 | H6: =Input!H6 | I6: =Input!I6 | J6: =Input!J6 | K6: =Input!K6 | L6: =Input!L6 | M6: =Input!M6 | N6: =Input!N6 | O6: =Input!O6
B7: Period Start | G7: =Input!G7 | H7: =Input!H7 | I7: =Input!I7 | J7: =Input!J7 | K7: =Input!K7 | L7: =Input!L7 | M7: =Input!M7 | N7: =Input!N7 | O7: TV
B8: Period End | G8: =Input!G8 | H8: =Input!H8 | I8: =Input!I8 | J8: =Input!J8 | K8: =Input!K8 | L8: =Input!L8 | M8: =Input!M8 | N8: =Input!N8
B9: Month | G9: =Input!G9 | H9: =Input!H9 | I9: =Input!I9 | J9: =Input!J9 | K9: =Input!K9 | L9: =Input!L9 | M9: =Input!M9 | N9: =Input!N9
B10: Year | G10: =Input!G10 | H10: =Input!H10 | I10: =Input!I10 | J10: =Input!J10 | K10: =Input!K10 | L10: =Input!L10 | M10: =Input!M10 | N10: =Input!N10 | O10: =Input!O10
B11: Days | G11: =Input!G11 | H11: =Input!H11 | I11: =Input!I11 | J11: =Input!J11 | K11: =Input!K11 | L11: =Input!L11 | M11: =Input!M11 | N11: =Input!N11
B13: Comparable Transaction Analysis
B15: [Comparable Transactions]
B17: Date | C17: Target | D17: Acquirer | E17: Deal Value (KRW mn) | F17: Revenue (KRW mn) | G17: EBITDA (KRW mn) | H17: EBIT (KRW mn) | I17: EV/Revenue | J17: EV/EBITDA | K17: EV/EBIT | L17: Control Premium
C18: Target #1 | D18: Acquirer #1 | J18: =IFERROR(E18/G18,"-") | K18: =IFERROR(E18/H18,"-") | L18: =IFERROR(E18/I18,"-")
C19: Target #2 | D19: Acquirer #2 | J19: =IFERROR(E19/G19,"-") | K19: =IFERROR(E19/H19,"-") | L19: =IFERROR(E19/I19,"-")
C20: Target #3 | D20: Acquirer #3 | J20: =IFERROR(E20/G20,"-") | K20: =IFERROR(E20/H20,"-") | L20: =IFERROR(E20/I20,"-")
C21: Target #4 | D21: Acquirer #4 | J21: =IFERROR(E21/G21,"-") | K21: =IFERROR(E21/H21,"-") | L21: =IFERROR(E21/I21,"-")
C22: Target #5 | D22: Acquirer #5 | J22: =IFERROR(E22/G22,"-") | K22: =IFERROR(E22/H22,"-") | L22: =IFERROR(E22/I22,"-")
B24: [Transaction Multiple Summary]
J26: EV/Revenue | K26: EV/EBITDA | L26: EV/EBIT
B27: Mean | J27: =IFERROR(AVERAGE(J18:J22),"-") | K27: =IFERROR(AVERAGE(K18:K22),"-") | L27: =IFERROR(AVERAGE(L18:L22),"-") | M27: =IFERROR(AVERAGE(M18:M22),"-")
B28: Median | J28: =IFERROR(MEDIAN(J18:J22),"-") | K28: =IFERROR(MEDIAN(K18:K22),"-") | L28: =IFERROR(MEDIAN(L18:L22),"-")
B29: Max | J29: =IFERROR(MAX(J18:J22),"-") | K29: =IFERROR(MAX(K18:K22),"-") | L29: =IFERROR(MAX(L18:L22),"-")
B30: Min | J30: =IFERROR(MIN(J18:J22),"-") | K30: =IFERROR(MIN(K18:K22),"-") | L30: =IFERROR(MIN(L18:L22),"-")
B32: [Selected Transaction Multiples & Valuation]
B34: Selected Multiple
B35: Control Premium Applied | E35: 0
B37: Target Company Financials
B38: Revenue | F38: KRW mn | G38: =DCF!N20
B39: EBITDA | F39: KRW mn | G39: =DCF!N30
B40: EBIT | F40: KRW mn | G40: =DCF!N27
B42: Implied Enterprise Value
B43: EV (Revenue multiple) | F43: KRW mn | G43: =J34*G38*(1+$E$35)
B44: EV (EBITDA multiple) | F44: KRW mn | G44: =K34*G39*(1+$E$35)
B45: EV (EBIT multiple) | F45: KRW mn | G45: =L34*G40*(1+$E$35)
B47: Implied Equity Value
B48: Equity (EV/EBITDA-based) | F48: KRW mn | G48: =G44-Input!I248
B49: Equity (EV/EBIT-based) | F49: KRW mn | G49: =G45-Input!I248
B51: Valuation Summary (Cross-Method)
B53: DCF Equity Value | F53: KRW mn | G53: =DCF!O45
B54: GPCM Equity Value (EV/EBITDA) | F54: KRW mn | G54: =GPCM!G49
...
