Workbook

Sheet 1. Results▶
B8: Section <1>
B9: <Results>

Sheet Control
B1: Control Panel - 주요 가정 조정
B4: 구분 | C4: Driver | D4: 2026 | E4: 2027 | F4: 2028 | G4: 2029 | H4: 2030 | J4: 비고
B5: 1. 트라우마 (TRAUMA)
B6: 음반 발매수 | C6: 개 | D6: 1 | E6: 2 | F6: 2 | G6: 3 | H6: 3 | J6: 데뷔 1개→점진증가
B7: 음반 당 판매량 | C7: 장 | D7: 130000 | E7: 155000 | F7: 210000 | G7: 250000 | H7: 300000 | J7: BM: ILLIT 82K~NJ 169K
B8: 스트리밍 (M streams) | C8: 백만 | D8: 50 | E8: 80 | F8: 150 | G8: 250 | H8: 400 | J8: BM: NJ 2.3B/yr
B9: 콘서트 관객수 | C9: 명 | D9: 0 | E9: 12000 | F9: 40000 | G9: 95000 | H9: 155000 | J9: Hall→Arena→Dome
B10: 팬플랫폼 가입자 | C10: 명 | D10: 80000 | E10: 140000 | F10: 220000 | G10: 310000 | H10: 400000
B11: 아티스트 정산율 | C11: % | D11: 0.15 | E11: 0.15 | F11: 0.15 | G11: 0.15 | H11: 0.15 | J11: SM/JYP 12-18% 범위
B13: 2. 드랍잇 (Drop It) - US
B14: 음반 발매수 | C14: 개 | D14: 0 | E14: 1 | F14: 2 | G14: 2 | H14: 3 | J14: 2027년 데뷔
B15: 음반 당 판매량 | C15: 장 | D15: 0 | E15: 80000 | F15: 100000 | G15: 130000 | H15: 145000 | J15: BM: FIFTY FIFTY 수준
B16: 스트리밍 (M streams) | C16: 백만 | D16: 0 | E16: 55 | F16: 90 | G16: 120 | H16: 150
B17: 콘서트 관객수 | C17: 명 | D17: 0 | E17: 8000 | F17: 25000 | G17: 50000 | H17: 80000
B18: 팬플랫폼 가입자 | C18: 명 | D18: 20000 | E18: 60000 | F18: 110000 | G18: 170000 | H18: 220000
B19: 로열티율 | C19: % | D19: 0.3 | E19: 0.3 | F19: 0.3 | G19: 0.3 | H19: 0.3 | J19: IR Pitch: 30%
B21: 3. 찰리 (Charlie) - Asia
B22: 음반 발매수 | C22: 개 | D22: 0 | E22: 1 | F22: 2 | G22: 2 | H22: 3 | J22: 2027년 데뷔
B23: 음반 당 판매량 | C23: 장 | D23: 0 | E23: 75000 | F23: 95000 | G23: 125000 | H23: 140000 | J23: BM: ILLIT JP데뷔
B24: 스트리밍 (M streams) | C24: 백만 | D24: 0 | E24: 50 | F24: 80 | G24: 110 | H24: 140
B25: 콘서트 관객수 | C25: 명 | D25: 0 | E25: 7000 | F25: 22000 | G25: 45000 | H25: 75000
B26: 팬플랫폼 가입자 | C26: 명 | D26: 15000 | E26: 50000 | F26: 100000 | G26: 150000 | H26: 210000
B27: 로열티율 | C27: % | D27: 0.3 | E27: 0.3 | F27: 0.3 | G27: 0.3 | H27: 0.3
B29: 4. 태깅 (Tagging) - IP/애니메이션
B30: IP 라이선싱 | C30: 백만원 | D30: 1000 | E30: 1500 | F30: 2500 | G30: 3800 | H30: 6500
B31: 캐릭터 MD | C31: 백만원 | D31: 200 | E31: 600 | F31: 1500 | G31: 2800 | H31: 5500
B32: 애니메이션 콘텐츠 | C32: 백만원 | D32: 500 | E32: 1000 | F32: 1500 | G32: 2300 | H32: 4200
B33: 팬플랫폼 (캐릭터) | C33: 백만원 | D33: 400 | E33: 800 | F33: 1200 | G33: 2200 | H33: 4500
B34: 로열티율 | C34: % | D34: 0.3 | E34: 0.3 | F34: 0.3 | G34: 0.3 | H34: 0.3
B36: 5. 라이트 (Light) - 콘텐츠
B37: 유튜브 매출 | C37: 백만원 | D37: 400 | E37: 900 | F37: 1800 | G37: 3000 | H37: 5500
B38: 방송 매출 | C38: 백만원 | D38: 800 | E38: 1400 | F38: 2500 | G38: 4200 | H38: 7500
B39: 콘텐츠 라이선싱 | C39: 백만원 | D39: 500 | E39: 1200 | F39: 2500 | G39: 4500 | H39: 9500
B40: 로열티율 | C40: % | D40: 0.3 | E40: 0.3 | F40: 0.3 | G40: 0.3 | H40: 0.3
B42: 6. 원가/판관비 주요 가정
B43: TRAUMA 음반원가율 | C43: % | D43: 0.6 | E43: 0.52 | F43: 0.48 | G43: 0.45 | H43: 0.43 | J43: 규모경제 반영
B44: TRAUMA 공연원가율 | C44: % | D44: 0.8 | E44: 0.72 | F44: 0.64 | G44: 0.58 | H44: 0.55 | J44: 규모경제 반영
B45: Drop It/Charlie 원가율 | C45: % | D45: 0.42 | E45: 0.38 | F45: 0.35 | G45: 0.35 | H45: 0.34
B46: 인당 매출액 | C46: 백만원 | D46: 1135 | E46: 1135 | F46: 1135 | G46: 1135 | H46: 1135 | J46: SM FY24 기준
B47: CAPEX | C47: 백만원 | D47: 200 | E47: 300 | F47: 400 | G47: 500 | H47: =G47 -> 500
...

Sheet Model
B1: Financial Model
B2: Value analysis as of Feb, 2026
B3: KRW in millions
I5: Actual | M5: Projection
B6: KRW in millions | I6: 2022 | J6: 2023 | K6: 2024 | L6: 2025 | M6: 2026 | N6: 2027 | O6: 2028 | P6: 2029 | Q6: 2030
B7: Sales | M7: =M36 -> 14148.6 | N7: =N36 -> 35740.285 | O7: =O36 -> 67959.627 | P7: =P36 -> 114419.38 | Q7: =Q36 -> 178981.66
B8: Cost of Sales | M8: =M45 -> 10586.8 | N8: =N45 -> 25809.51 | O8: =O45 -> 49511.603 | P8: =P45 -> 81896.336 | Q8: =Q45 -> 124804.06
B9: Gross Profit | M9: =M7-M8 -> 3561.8 | N9: =N7-N8 -> 9930.775 | O9: =O7-O8 -> 18448.024 | P9: =P7-P8 -> 32523.044 | Q9: =Q7-Q8 -> 54177.593
B10: SG&A (w/o D&A) | M10: =M256 -> 1545.5494 | N10: =N256 -> 4034.9671 | O10: =O256 -> 7929.842 | P10: =P256 -> 13630.98 | Q10: =Q256 -> 21805.741
B11: EBITDA | M11: =M9-M10 -> 2016.2506 | N11: =N9-N10 -> 5895.8079 | O11: =O9-O10 -> 10518.182 | P11: =P9-P10 -> 18892.064 | Q11: =Q9-Q10 -> 32371.852
B12: D&A | M12: =M263 -> 200 | N12: =N263 -> 300 | O12: =O263 -> 400 | P12: =P263 -> 500 | Q12: =Q263 -> 500
B13: EBIT | M13: =M11-M12 -> 1816.2506 | N13: =N11-N12 -> 5595.8079 | O13: =O11-O12 -> 10118.182 | P13: =P11-P12 -> 18392.064 | Q13: =Q11-Q12 -> 31871.852
B15: Sales Growth % | N15: =N7/M7-1 -> 1.5260651 | O15: =O7/N7-1 -> 0.90148531 | P15: =P7/O7-1 -> 0.68363756 | Q15: =Q7/P7-1 -> 0.56425996
B16: EBITDA % | M16: =IF(M7=0,0,M11/M7) -> 0.14250531 | N16: =IF(N7=0,0,N11/N7) -> 0.16496253 | O16: =IF(O7=0,0,O11/O7) -> 0.15477104 | P16: =IF(P7=0,0,P11/P7) -> 0.16511245 | Q16: =IF(Q7=0,0,Q11/Q7) -> 0.18086687
B17: EBIT % | M17: =IF(M7=0,0,M13/M7) -> 0.12836964 | N17: =IF(N7=0,0,N13/N7) -> 0.15656864 | O17: =IF(O7=0,0,O13/O7) -> 0.14888519 | P17: =IF(P7=0,0,P13/P7) -> 0.16074256 | Q17: =IF(Q7=0,0,Q13/Q7) -> 0.17807329
B19: Macro Indicator_South Korea
B20: Growth in Average Wages (LCU; % pa) | M20: 0.028 | N20: 0.036 | O20: 0.035 | P20: 0.035 | Q20: 0.035 | R20: Source: EIU Korea, Average Wage Growth forecast
B21: Consumer Prices (% change pa; av) | M21: 0.015 | N21: 0.015 | O21: 0.018 | P21: 0.017 | Q21: 0.018 | R21: Source: EIU Korea, CPI forecast 2026-2030
B24: Key Performance Indicators
B25: Trainees | M25: 33 | N25: 33 | O25: 33 | P25: 33 | Q25: 33 | R25: IR Pitch: 33명 연습생 운영 계획
B28: Revenue & Cost Consolidation by Project
B29: Revenue by Project
M30: 2026 | N30: 2027 | O30: 2028 | P30: 2029 | Q30: 2030
B31: 트라우마 (TRAUMA) | M31: =M107 -> 8373.6 | N31: =N107 -> 17358.96 | O31: =O107 -> 27677.865 | P31: =P107 -> 49345.841 | Q31: =Q107 -> 67091.059
B32: 드랍잇 (Drop It) | M32: =M153 -> 1050 | N32: =N153 -> 5837.74 | O32: =O153 -> 14015.205 | P32: =P153 -> 22183.202 | Q32: =Q153 -> 35459.125
B33: 찰리 (Charlie) | M33: =M189 -> 925 | N33: =N189 -> 5143.585 | O33: =O189 -> 12766.557 | P33: =P189 -> 20090.337 | Q33: =Q189 -> 33231.471
B34: 태깅 (Tagging) | M34: =M209 -> 2100 | N34: =N209 -> 3900 | O34: =O209 -> 6700 | P34: =P209 -> 11100 | Q34: =Q209 -> 20700
B35: 라이트 (Light) | M35: =M226 -> 1700 | N35: =N226 -> 3500 | O35: =O226 -> 6800 | P35: =P226 -> 11700 | Q35: =Q226 -> 22500
B36: Total Revenue | M36: =M31+M32+M33+M34+M35 -> 14148.6 | N36: =N31+N32+N33+N34+N35 -> 35740.285 | O36: =O31+O32+O33+O34+O35 -> 67959.627 | P36: =P31+P32+P33+P34+P35 -> 114419.38 | Q36: =Q31+Q32+Q33+Q34+Q35 -> 178981.66
B38: Cost of Sales by Project (incl. Royalty)
M39: 2026 | N39: 2027 | O39: 2028 | P39: 2029 | Q39: 2030
B40: 트라우마 (TRAUMA) | M40: =M122 -> 6246.8 | N40: =N122 -> 12109.45 | O40: =O122 -> 20113.646 | P40: =P122 -> 34975.711 | Q40: =Q122 -> 46229.208
B41: 드랍잇 (Drop It) | M41: =M158 -> 882 | N41: =N158 -> 4670.192 | O41: =O158 -> 10791.708 | P41: =P158 -> 17081.066 | Q41: =Q158 -> 26948.935
B42: 찰리 (Charlie) | M42: =M194 -> 777 | N42: =N194 -> 4114.868 | O42: =O194 -> 9830.2492 | P42: =P194 -> 15469.559 | Q42: =Q194 -> 25255.918
B43: 태깅 (Tagging) | M43: =M213 -> 1491 | N43: =N213 -> 2535 | O43: =O213 -> 4288 | P43: =P213 -> 6882 | Q43: =Q213 -> 12420
B44: 라이트 (Light) | M44: =M230 -> 1190 | N44: =N230 -> 2380 | O44: =O230 -> 4488 | P44: =P230 -> 7488 | Q44: =Q230 -> 13950
B45: Total COS | M45: =M40+M41+M42+M43+M44 -> 10586.8 | N45: =N40+N41+N42+N43+N44 -> 25809.51 | O45: =O40+O41+O42+O43+O44 -> 49511.603 | P45: =P40+P41+P42+P43+P44 -> 81896.336 | Q45: =Q40+Q41+Q42+Q43+Q44 -> 124804.06
B47: 1. 트라우마 (TRAUMA) - 메인 걸그룹 Full Group | R47: TRAUMA = 메인 걸그룹, Full Group 활동
B48: KRW in millions | M48: 2026 | N48: 2027 | O48: 2028 | P48: 2029 | Q48: 2030
B50: 음반 매출 | R50: BM: NewJeans 데뷔앨범 1개, ILLIT 1개 (걸그룹 시트)
...

Sheet IS
B1: 손익계산서 (Income Statement)
B2: KRW in millions
B3: 구분 | D3: 2026 | E3: 2027 | F3: 2028 | G3: 2029 | H3: 2030
B4: 매출액 (Revenue) | D4: =Model!M7 -> 14148.6 | E4: =Model!N7 -> 35740.285 | F4: =Model!O7 -> 67959.627 | G4: =Model!P7 -> 114419.38 | H4: =Model!Q7 -> 178981.66
B5: 트라우마 (TRAUMA) | D5: =Model!M31 -> 8373.6 | E5: =Model!N31 -> 17358.96 | F5: =Model!O31 -> 27677.865 | G5: =Model!P31 -> 49345.841 | H5: =Model!Q31 -> 67091.059
B6: 드랍잇 (Drop It) | D6: =Model!M32 -> 1050 | E6: =Model!N32 -> 5837.74 | F6: =Model!O32 -> 14015.205 | G6: =Model!P32 -> 22183.202 | H6: =Model!Q32 -> 35459.125
B7: 찰리 (Charlie) | D7: =Model!M33 -> 925 | E7: =Model!N33 -> 5143.585 | F7: =Model!O33 -> 12766.557 | G7: =Model!P33 -> 20090.337 | H7: =Model!Q33 -> 33231.471
B8: 태깅 (Tagging) | D8: =Model!M34 -> 2100 | E8: =Model!N34 -> 3900 | F8: =Model!O34 -> 6700 | G8: =Model!P34 -> 11100 | H8: =Model!Q34 -> 20700
B9: 라이트 (Light) | D9: =Model!M35 -> 1700 | E9: =Model!N35 -> 3500 | F9: =Model!O35 -> 6800 | G9: =Model!P35 -> 11700 | H9: =Model!Q35 -> 22500
B10: 매출원가 (COGS) | D10: =Model!M8 -> 10586.8 | E10: =Model!N8 -> 25809.51 | F10: =Model!O8 -> 49511.603 | G10: =Model!P8 -> 81896.336 | H10: =Model!Q8 -> 124804.06
B11: 매출총이익 (Gross Profit) | D11: =Model!M9 -> 3561.8 | E11: =Model!N9 -> 9930.775 | F11: =Model!O9 -> 18448.024 | G11: =Model!P9 -> 32523.044 | H11: =Model!Q9 -> 54177.593
B12: GP Margin % | D12: =IF(D4=0,0,D11/D4) -> 0.25174222 | E12: =IF(E4=0,0,E11/E4) -> 0.27785942 | F12: =IF(F4=0,0,F11/F4) -> 0.27145564 | G12: =IF(G4=0,0,G11/G4) -> 0.28424419 | H12: =IF(H4=0,0,H11/H4) -> 0.30269914
B13: 판관비 (SG&A) | D13: =Model!M10 -> 1545.5494 | E13: =Model!N10 -> 4034.9671 | F13: =Model!O10 -> 7929.842 | G13: =Model!P10 -> 13630.98 | H13: =Model!Q10 -> 21805.741
B14: EBITDA | D14: =Model!M11 -> 2016.2506 | E14: =Model!N11 -> 5895.8079 | F14: =Model!O11 -> 10518.182 | G14: =Model!P11 -> 18892.064 | H14: =Model!Q11 -> 32371.852
B15: EBITDA Margin % | D15: =IF(D4=0,0,D14/D4) -> 0.14250531 | E15: =IF(E4=0,0,E14/E4) -> 0.16496253 | F15: =IF(F4=0,0,F14/F4) -> 0.15477104 | G15: =IF(G4=0,0,G14/G4) -> 0.16511245 | H15: =IF(H4=0,0,H14/H4) -> 0.18086687
B16: 감가상각비 (D&A) | D16: =Model!M12 -> 200 | E16: =Model!N12 -> 300 | F16: =Model!O12 -> 400 | G16: =Model!P12 -> 500 | H16: =Model!Q12 -> 500
B17: 영업이익 (EBIT) | D17: =Model!M13 -> 1816.2506 | E17: =Model!N13 -> 5595.8079 | F17: =Model!O13 -> 10118.182 | G17: =Model!P13 -> 18392.064 | H17: =Model!Q13 -> 31871.852
B18: EBIT Margin % | D18: =IF(D4=0,0,D17/D4) -> 0.12836964 | E18: =IF(E4=0,0,E17/E4) -> 0.15656864 | F18: =IF(F4=0,0,F17/F4) -> 0.14888519 | G18: =IF(G4=0,0,G17/G4) -> 0.16074256 | H18: =IF(H4=0,0,H17/H4) -> 0.17807329
B19: 영업외수익 | D19: 0 | E19: 0 | F19: 0 | G19: 0 | H19: 0
B20: 영업외비용 | D20: 0 | E20: 0 | F20: 0 | G20: 0 | H20: 0
B21: 세전이익 (EBT) | D21: =D17+D19-D20 -> 1816.2506 | E21: =E17+E19-E20 -> 5595.8079 | F21: =F17+F19-F20 -> 10118.182 | G21: =G17+G19-G20 -> 18392.064 | H21: =H17+H19-H20 -> 31871.852
B22: 법인세 | D22: =IF(D21<=0,0,IF(D21<=200,D21*0.099,IF(D21<=20000,200*0.099+(D21-200)*0.209,IF(D21<=300000,200*0.099+19800*0.209+(D21-20000)*0.231,200*0.099+19800*0.209+280000*0.231+(D21-300000)*0.264)))) -> 357.59638 | E22: =IF(E21<=0,0,IF(E21<=200,E21*0.099,IF(E21<=20000,200*0.099+(E21-200)*0.209,IF(E21<=300000,200*0.099+19800*0.209+(E21-20000)*0.231,200*0.099+19800*0.209+280000*0.231+(E21-300000)*0.264)))) -> 1147.5238 | F22: =IF(F21<=0,0,IF(F21<=200,F21*0.099,IF(F21<=20000,200*0.099+(F21-200)*0.209,IF(F21<=300000,200*0.099+19800*0.209+(F21-20000)*0.231,200*0.099+19800*0.209+280000*0.231+(F21-300000)*0.264)))) -> 2092.7 | G22: =IF(G21<=0,0,IF(G21<=200,G21*0.099,IF(G21<=20000,200*0.099+(G21-200)*0.209,IF(G21<=300000,200*0.099+19800*0.209+(G21-20000)*0.231,200*0.099+19800*0.209+280000*0.231+(G21-300000)*0.264)))) -> 3821.9413 | H22: =IF(H21<=0,0,IF(H21<=200,H21*0.099,IF(H21<=20000,200*0.099+(H21-200)*0.209,IF(H21<=300000,200*0.099+19800*0.209+(H21-20000)*0.231,200*0.099+19800*0.209+280000*0.231+(H21-300000)*0.264)))) -> 6900.3978
B23: 당기순이익 (Net Income) | D23: =D21-D22 -> 1458.6543 | E23: =E21-E22 -> 4448.284 | F23: =F21-F22 -> 8025.4819 | G23: =G21-G22 -> 14570.122 | H23: =H21-H22 -> 24971.454

Sheet BS
B1: 재무상태표 (Balance Sheet)
B2: KRW in millions
B3: 구분 | D3: 2026 | E3: 2027 | F3: 2028 | G3: 2029 | H3: 2030
B4: 자산 (Assets)
B5: 현금및현금성자산 | D5: =CF!D27 -> 3823.9043 | E5: =CF!E27 -> 6376.4129 | F5: =CF!F27 -> 11894.766 | G5: =CF!G27 -> 22769.688 | H5: =CF!H27 -> 42344.229
B6: 매출채권 | D6: =IS!D4/12*2 -> 2358.1 | E6: =IS!E4/12*2 -> 5956.7142 | F6: =IS!F4/12*2 -> 11326.604 | G6: =IS!G4/12*2 -> 19069.897 | H6: =IS!H4/12*2 -> 29830.276
B7: 기타유동자산 | D7: 500 | E7: 500 | F7: 500 | G7: 500 | H7: 500
B8: 유동자산 합계 | D8: =D5+D6+D7 -> 6682.0043 | E8: =E5+E6+E7 -> 12833.127 | F8: =F5+F6+F7 -> 23721.371 | G8: =G5+G6+G7 -> 42339.585 | H8: =H5+H6+H7 -> 72674.505
B10: 유형자산 | D10: 1000 | E10: 1000 | F10: 1000 | G10: 1000 | H10: 1000
B11: 무형자산 (프로그램) | D11: 0 | E11: 0 | F11: 0 | G11: 0 | H11: 0
B12: 기타비유동자산 | D12: 200 | E12: 200 | F12: 200 | G12: 200 | H12: 200
B13: 비유동자산 합계 | D13: =D10+D11+D12 -> 1200 | E13: =E10+E11+E12 -> 1200 | F13: =F10+F11+F12 -> 1200 | G13: =G10+G11+G12 -> 1200 | H13: =H10+H11+H12 -> 1200
B15: 자산총계 | D15: =D8+D13 -> 7882.0043 | E15: =E8+E13 -> 14033.127 | F15: =F8+F13 -> 24921.371 | G15: =G8+G13 -> 43539.585 | H15: =H8+H13 -> 73874.505
B17: 부채 및 자본 (Liabilities & Equity)
B18: 매입채무 | D18: =Model!M8/12*1.5 -> 1323.35 | E18: =Model!N8/12*1.5 -> 3226.1888 | F18: =Model!O8/12*1.5 -> 6188.9504 | G18: =Model!P8/12*1.5 -> 10237.042 | H18: =Model!Q8/12*1.5 -> 15600.508
B19: 기타유동부채 | D19: 300 | E19: 300 | F19: 300 | G19: 300 | H19: 300
B20: 유동부채 합계 | D20: =D18+D19 -> 1623.35 | E20: =E18+E19 -> 3526.1888 | F20: =F18+F19 -> 6488.9504 | G20: =G18+G19 -> 10537.042 | H20: =H18+H19 -> 15900.508
B22: 장기차입금 | D22: 0 | E22: 0 | F22: 0 | G22: 0 | H22: 0
B23: 기타비유동부채 | D23: 100 | E23: 100 | F23: 100 | G23: 100 | H23: 100
B24: 비유동부채 합계 | D24: =D22+D23 -> 100 | E24: =E22+E23 -> 100 | F24: =F22+F23 -> 100 | G24: =G22+G23 -> 100 | H24: =H22+H23 -> 100
B26: 부채총계 | D26: =D20+D24 -> 1723.35 | E26: =E20+E24 -> 3626.1888 | F26: =F20+F24 -> 6588.9504 | G26: =G20+G24 -> 10637.042 | H26: =H20+H24 -> 16000.508
B28: 자본금 | D28: 5000 | E28: 5000 | F28: 5000 | G28: 5000 | H28: 5000
B29: 이익잉여금 | D29: =IS!D23 -> 1458.6543 | E29: =D29+IS!E23 -> 5906.9383 | F29: =E29+IS!F23 -> 13932.42 | G29: =F29+IS!G23 -> 28502.543 | H29: =G29+IS!H23 -> 53473.997
B30: 자본총계 | D30: =D28+D29 -> 6458.6543 | E30: =E28+E29 -> 10906.938 | F30: =F28+F29 -> 18932.42 | G30: =G28+G29 -> 33502.543 | H30: =H28+H29 -> 58473.997
B32: 부채+자본총계 | D32: =D26+D30 -> 8182.0043 | E32: =E26+E30 -> 14533.127 | F32: =F26+F30 -> 25521.371 | G32: =G26+G30 -> 44139.585 | H32: =H26+H30 -> 74474.505

Sheet CF
B1: 현금흐름표 (Cash Flow Statement)
B2: KRW in millions
B3: 구분 | D3: 2026 | E3: 2027 | F3: 2028 | G3: 2029 | H3: 2030
B4: I. 영업활동 현금흐름
B5: 당기순이익 | D5: =IS!D23 -> 1458.6543 | E5: =IS!E23 -> 4448.284 | F5: =IS!F23 -> 8025.4819 | G5: =IS!G23 -> 14570.122 | H5: =IS!H23 -> 24971.454
B6: 감가상각비 (가산) | D6: =Model!M12 -> 200 | E6: =Model!N12 -> 300 | F6: =Model!O12 -> 400 | G6: =Model!P12 -> 500 | H6: =Model!Q12 -> 500
B7: 매출채권 증감 | D7: =-BS!D6 -> -2358.1 | E7: =-(BS!E6-BS!D6) -> -3598.6142 | F7: =-(BS!F6-BS!E6) -> -5369.8903 | G7: =-(BS!G6-BS!F6) -> -7743.2922 | H7: =-(BS!H6-BS!G6) -> -10760.379
B8: 매입채무 증감 | D8: =BS!D18 -> 1323.35 | E8: =BS!E18-BS!D18 -> 1902.8388 | F8: =BS!F18-BS!E18 -> 2962.7616 | G8: =BS!G18-BS!F18 -> 4048.0917 | H8: =BS!H18-BS!G18 -> 5363.4657
B9: 기타유동자산 증감 | D9: =-BS!D7 -> -500 | E9: =-(BS!E7-BS!D7) -> 0 | F9: =-(BS!F7-BS!E7) -> 0 | G9: =-(BS!G7-BS!F7) -> 0 | H9: =-(BS!H7-BS!G7) -> 0
B10: 기타유동부채 증감 | D10: =BS!D19 -> 300 | E10: =BS!E19-BS!D19 -> 0 | F10: =BS!F19-BS!E19 -> 0 | G10: =BS!G19-BS!F19 -> 0 | H10: =BS!H19-BS!G19 -> 0
B11: 영업활동 현금흐름 | D11: =SUM(D5:D10) -> 423.90426 | E11: =SUM(E5:E10) -> 3052.5086 | F11: =SUM(F5:F10) -> 6018.3533 | G11: =SUM(G5:G10) -> 11374.922 | H11: =SUM(H5:H10) -> 20074.541
B13: II. 투자활동 현금흐름
B14: CAPEX | D14: =-Model!M264 -> -500 | E14: =-Model!N264 -> -500 | F14: =-Model!O264 -> -500 | G14: =-Model!P264 -> -500 | H14: =-Model!Q264 -> -500
B15: 유형자산 증감 | D15: =-BS!D10 -> -1000 | E15: =-(BS!E10-BS!D10) -> 0 | F15: =-(BS!F10-BS!E10) -> 0 | G15: =-(BS!G10-BS!F10) -> 0 | H15: =-(BS!H10-BS!G10) -> 0
B16: 기타비유동자산 증감 | D16: =-BS!D12 -> -200 | E16: =-(BS!E12-BS!D12) -> 0 | F16: =-(BS!F12-BS!E12) -> 0 | G16: =-(BS!G12-BS!F12) -> 0 | H16: =-(BS!H12-BS!G12) -> 0
B17: 투자활동 현금흐름 | D17: =SUM(D14:D16) -> -1700 | E17: =SUM(E14:E16) -> -500 | F17: =SUM(F14:F16) -> -500 | G17: =SUM(G14:G16) -> -500 | H17: =SUM(H14:H16) -> -500
B19: III. 재무활동 현금흐름
B20: 신규 투자유치 | D20: 5000 | E20: 0 | F20: 0 | G20: 0 | H20: 0
B21: 차입금 증감 | D21: 0 | E21: 0 | F21: 0 | G21: 0 | H21: 0
B22: 기타비유동부채 증감 | D22: =BS!D23 -> 100 | E22: =BS!E23-BS!D23 -> 0 | F22: =BS!F23-BS!E23 -> 0 | G22: =BS!G23-BS!F23 -> 0 | H22: =BS!H23-BS!G23 -> 0
B23: 재무활동 현금흐름 | D23: =SUM(D20:D22) -> 5100 | E23: =SUM(E20:E22) -> 0 | F23: =SUM(F20:F22) -> 0 | G23: =SUM(G20:G22) -> 0 | H23: =SUM(H20:H22) -> 0
B25: 현금 순증감 | D25: =D11+D17+D23 -> 3823.9043 | E25: =E11+E17+E23 -> 2552.5086 | F25: =F11+F17+F23 -> 5518.3533 | G25: =G11+G17+G23 -> 10874.922 | H25: =H11+H17+H23 -> 19574.541
B26: 기초 현금 | D26: 0 | E26: =D27 -> 3823.9043 | F26: =E27 -> 6376.4129 | G26: =F27 -> 11894.766 | H26: =G27 -> 22769.688
B27: 기말 현금 | D27: =D26+D25 -> 3823.9043 | E27: =E26+E25 -> 6376.4129 | F27: =F26+F25 -> 11894.766 | G27: =G26+G25 -> 22769.688 | H27: =H26+H25 -> 42344.229

Sheet Investment Flow
B1: 투자금 흐름 분석 (Investment Flow Analysis)
B2: KRW in millions
B3: 구분 | D3: 2026 | E3: 2027 | F3: 2028 | G3: 2029 | H3: 2030
B4: 1. 투자금 집행 계획 (운영비)
B5: 투자금 유입 (50억) | D5: 5000 | E5: 0 | F5: 0 | G5: 0 | H5: 0
B7: 집행 항목:
B8: 인건비 (초기인력 9명) | D8: 1800 | E8: 0 | F8: 0 | G8: 0 | H8: 0
B9: 사무실 임차/보증금 | D9: 600 | E9: 0 | F9: 0 | G9: 0 | H9: 0
B10: 아티스트 트레이닝비 | D10: 1200 | E10: 0 | F10: 0 | G10: 0 | H10: 0
B11: 마케팅/프로모션 | D11: 800 | E11: 0 | F11: 0 | G11: 0 | H11: 0
B12: 기타 운영비 | D12: 600 | E12: 0 | F12: 0 | G12: 0 | H12: 0
B13: 투자 집행 합계 | D13: =D8+D9+D10+D11+D12 -> 5000 | E13: =E8+E9+E10+E11+E12 -> 0 | F13: =F8+F9+F10+F11+F12 -> 0 | G13: =G8+G9+G10+G11+G12 -> 0 | H13: =H8+H9+H10+H11+H12 -> 0
B14: 잔여 투자금 | D14: =D5-D13 -> 0 | E14: =E5-E13 -> 0 | F14: =F5-F13 -> 0 | G14: =G5-G13 -> 0 | H14: =H5-H13 -> 0
B16: 2. 투자 수익 분석
B17: 매출액 | D17: =Model!M7 -> 14148.6 | E17: =Model!N7 -> 35740.285 | F17: =Model!O7 -> 67959.627 | G17: =Model!P7 -> 114419.38 | H17: =Model!Q7 -> 178981.66
B18: 영업이익 (EBIT) | D18: =Model!M13 -> 1816.2506 | E18: =Model!N13 -> 5595.8079 | F18: =Model!O13 -> 10118.182 | G18: =Model!P13 -> 18392.064 | H18: =Model!Q13 -> 31871.852
B19: 당기순이익 | D19: =IS!D23 -> 1458.6543 | E19: =IS!E23 -> 4448.284 | F19: =IS!F23 -> 8025.4819 | G19: =IS!G23 -> 14570.122 | H19: =IS!H23 -> 24971.454
B20: 누적 순이익 | D20: =D19 -> 1458.6543 | E20: =D20+E19 -> 5906.9383 | F20: =E20+F19 -> 13932.42 | G20: =F20+G19 -> 28502.543 | H20: =G20+H19 -> 53473.997
B21: 투자금 회수율 (누적NI/투자금) | D21: =D20/5000 -> 0.29173085 | E21: =E20/5000 -> 1.1813877 | F21: =F20/5000 -> 2.786484 | G21: =G20/5000 -> 5.7005085 | H21: =H20/5000 -> 10.694799
B23: FCFF | D23: =#REF! -> #REF! | E23: =#REF! -> #REF! | F23: =#REF! -> #REF! | G23: =#REF! -> #REF! | H23: =#REF! -> #REF!
B24: 누적 FCFF | D24: =D23 -> #REF! | E24: =D24+E23 -> #REF! | F24: =E24+F23 -> #REF! | G24: =F24+G23 -> #REF! | H24: =G24+H23 -> #REF!
B25: 투자금 대비 FCFF 회수율 | D25: =D24*0.25/5000 -> #REF! | E25: =E24*0.25/5000 -> #REF! | F25: =F24*0.25/5000 -> #REF! | G25: =G24*0.25/5000 -> #REF! | H25: =H24*0.25/5000 -> #REF!
B28: 3. 투자 가치 요약
B29: 투자금액 | D29: 5,000M KRW (50억원)
B30: 투자 시점 | D30: 2026년 초
B31: 자금 용도 | D31: 인건비 36%, 트레이닝 24%, 마케팅 16%, 임차 12%, 기타 12%
B32: BEP 도달 예상 | D32: 2027년 (EBIT 기준, 당기순이익 기준)
B33: 5년 누적 FCFF | D33: =D23+E23+F23+G23+H23 -> #REF!
B34: 투자배수 (MOIC) | D34: =H24*0.25/5000 -> #REF!
B35: 지분율 | D35: 25% (50억/200억)

Sheet KPI
B1: Key Performance Indicator
B3: KRW in millions
E6: 추정
B7: 구분 | E7: 2026 | F7: 2027 | G7: 2028 | H7: 2029 | I7: 2030
B8: 음반 발매수 (전체) | E8: =Model!M52+Model!M129+Model!M165 -> 1 | F8: =Model!N52+Model!N129+Model!N165 -> 4 | G8: =Model!O52+Model!O129+Model!O165 -> 6 | H8: =Model!P52+Model!P129+Model!P165 -> 7 | I8: =Model!Q52+Model!Q129+Model!Q165 -> 9
B9: 음반 판매수 (전체) | E9: =Model!M52*Model!M53+Model!M129*Model!M130+Model!M165*Model!M166 -> 130000 | F9: =Model!N52*Model!N53+Model!N129*Model!N130+Model!N165*Model!N166 -> 465000 | G9: =Model!O52*Model!O53+Model!O129*Model!O130+Model!O165*Model!O166 -> 810000 | H9: =Model!P52*Model!P53+Model!P129*Model!P130+Model!P165*Model!P166 -> 1260000 | I9: =Model!Q52*Model!Q53+Model!Q129*Model!Q130+Model!Q165*Model!Q166 -> 1755000
B10: 스트리밍 수 (백만, TRAUMA) | E10: =Model!M59+Model!M133+Model!M169 -> 80 | F10: =Model!N59+Model!N133+Model!N169 -> 235 | G10: =Model!O59+Model!O133+Model!O169 -> 340 | H10: =Model!P59+Model!P133+Model!P169 -> 440 | I10: =Model!Q59+Model!Q133+Model!Q169 -> 540
B11: 콘서트 관객 수 (전체) | E11: =Model!M68+Model!M138+Model!M174 -> 0 | F11: =Model!N68+Model!N138+Model!N174 -> 27000 | G11: =Model!O68+Model!O138+Model!O174 -> 87000 | H11: =Model!P68+Model!P138+Model!P174 -> 190000 | I11: =Model!Q68+Model!Q138+Model!Q174 -> 310000
B12: 광고 촬영수 (TRAUMA) | E12: =Model!M74 -> 1 | F12: =Model!N74 -> 1.5 | G12: =Model!O74 -> 2 | H12: =Model!P74 -> 2.5 | I12: =Model!Q74 -> 3
B13: 행사 수 (TRAUMA) | E13: =Model!M86 -> 30 | F13: =Model!N86 -> 35 | G13: =Model!O86 -> 38 | H13: =Model!P86 -> 40 | I13: =Model!Q86 -> 45
B14: 팬 플랫폼 가입자 (전체) | E14: =Model!M100+Model!M148+Model!M184 -> 115000 | F14: =Model!N100+Model!N148+Model!N184 -> 250000 | G14: =Model!O100+Model!O148+Model!O184 -> 430000 | H14: =Model!P100+Model!P148+Model!P184 -> 630000 | I14: =Model!Q100+Model!Q148+Model!Q184 -> 830000
B15: 직원 수 | E15: =Model!M239 -> 12 | F15: =Model!N239 -> 31 | G15: =Model!O239 -> 60 | H15: =Model!P239 -> 101 | I15: =Model!Q239 -> 158
B16: 매출액 (백만원) | E16: =Model!M7 -> 14148.6 | F16: =Model!N7 -> 35740.285 | G16: =Model!O7 -> 67959.627 | H16: =Model!P7 -> 114419.38 | I16: =Model!Q7 -> 178981.66
B17: 영업이익 (백만원) | E17: =Model!M13 -> 1816.2506 | F17: =Model!N13 -> 5595.8079 | G17: =Model!O13 -> 10118.182 | H17: =Model!P13 -> 18392.064 | I17: =Model!Q13 -> 31871.852
B18: 영업이익률 | E18: =Model!M17 -> 0.12836964 | F18: =Model!N17 -> 0.15656864 | G18: =Model!O17 -> 0.14888519 | H18: =Model!P17 -> 0.16074256 | I18: =Model!Q17 -> 0.17807329

Sheet 2. Reference▶
B8: Section <2>
B9: <Reference>

Sheet 음반원
B1: 음반/음원 매출
B2: Value analysis as of August 31, 2025
B3: KRW in millions
E4: 4 | F4: 5
B7: 걸그룹 음반 판매량
B9: 걸그룹 | D9: 2021 | E9: 2022 | F9: 2023 | G9: 2024 | H9: 합계 | I9: 판매량합계 | J9: 평균 판매량 | K9: 구분 | M9: 구분 | N9: 판매량
B10: 아이브 | D10: =COUNTA(D26:D31) -> 1 | E10: =COUNTA(E26:E31) -> 2 | F10: =COUNTA(F26:F31) -> 2 | G10: =COUNTA(G26:G31) -> 1 | H10: =SUM(D10:G10) -> 6 | I10: =SUM(D26:G31) -> 8957249 | J10: =I10/H10 -> 1492874.8 | K10: BEST | M10: BEST | N10: =AVERAGEIF($K$10:$K$17,M10,$J$10:$J$17) -> 1565413.4
B11: 에스파 | D11: =COUNTA(D33:D38) -> 1 | E11: =COUNTA(E33:E38) -> 1 | F11: =COUNTA(F33:F38) -> 2 | G11: =COUNTA(G33:G38) -> 2 | H11: =SUM(D11:G11) -> 6 | I11: =SUM(D33:G38) -> 8744139 | J11: =I11/H11 -> 1457356.5 | K11: BEST | M11: BASE | N11: =AVERAGEIF($K$10:$K$17,M11,$J$10:$J$17) -> 647810
B12: 뉴진스 | D12: =COUNTA(D40:D43) -> 0 | E12: =COUNTA(E40:E43) -> 1 | F12: =COUNTA(F40:F43) -> 2 | G12: =COUNTA(G40:G43) -> 1 | H12: =SUM(D12:G12) -> 4 | I12: =SUM(D40:G43) -> 6984036 | J12: =I12/H12 -> 1746009 | K12: BEST | M12: WORST | N12: =AVERAGEIF($K$10:$K$17,M12,$J$10:$J$17) -> 140503.01
B13: 엔믹스 | D13: =COUNTA(D45:D50) -> 0 | E13: =COUNTA(E45:E50) -> 2 | F13: =COUNTA(F45:F50) -> 2 | G13: =COUNTA(G45:G50) -> 2 | H13: =SUM(D13:G13) -> 6 | I13: =SUM(D45:G50) -> 4317723 | J13: =I13/H13 -> 719620.5 | K13: BASE
B14: 아일릿 | D14: =COUNTA(D52:D53) -> 0 | E14: =COUNTA(E52:E53) -> 0 | F14: =COUNTA(F52:F53) -> 0 | G14: =COUNTA(G52:G53) -> 2 | H14: =SUM(D14:G14) -> 2 | I14: =SUM(D52:G53) -> 1151999 | J14: =I14/H14 -> 575999.5 | K14: BASE
B15: 케플러 | D15: =COUNTA(D55:D61) -> 0 | E15: =COUNTA(E55:E61) -> 3 | F15: =COUNTA(F55:F61) -> 2 | G15: =COUNTA(G55:G61) -> 2 | H15: =SUM(D15:G15) -> 7 | I15: =SUM(D55:G61) -> 1651555 | J15: =I15/H15 -> 235936.43 | K15: WORST
B16: 트리플에스 | D16: =COUNTA(D63:D69) -> 0 | E16: =COUNTA(E63:E69) -> 1 | F16: =COUNTA(F63:F69) -> 4 | G16: =COUNTA(G63:G69) -> 2 | H16: =SUM(D16:G16) -> 7 | I16: =SUM(D63:G69) -> 729546 | J16: =I16/H16 -> 104220.86 | K16: WORST
B17: 키스오브라이프 | D17: =COUNTA(D71:D74) -> 0 | E17: =COUNTA(E71:E74) -> 0 | F17: =COUNTA(F71:F74) -> 2 | G17: =COUNTA(G71:G74) -> 2 | H17: =SUM(D17:G17) -> 4 | I17: =SUM(D71:G74) -> 325407 | J17: =I17/H17 -> 81351.75 | K17: WORST
B18: Total | D18: =SUBTOTAL(9,D10:D17) -> 2 | E18: =SUBTOTAL(9,E10:E17) -> 10 | F18: =SUBTOTAL(9,F10:F17) -> 16 | G18: =SUBTOTAL(9,G10:G17) -> 14 | H18: =SUBTOTAL(9,H10:H17) -> 42
B20: Source : https://chartndata.tistory.com/8
B22: 써클차트
B24: 구분 | D24: 2021 | E24: 2022 | F24: 2023 | G24: 2024
B25: 아이브
B26: ELEVEN | D26: 574061
B27: LOVE DIVE | E27: 1041801
B28: I've IVE | F28: 1720057
B29: IVE SWITCH | G29: 1745222
B30: After Like | E30: 1768220
B31: I've MINE | F31: 2107888
B32: 에스파
B33: Savage | D33: 822655
B34: Girls | E34: 1880677
B35: Drama | F35: 1355469
B36: My World | F36: 2172570
B37: Whiplash | G37: 1103799
B38: Armageddon | G38: 1408969
B39: 뉴진스
B40: New Jeans | E40: 1732952
B41: OMG | F41: 1774798
B42: Get Up | F42: 2232598
B43: How Sweet | G43: 1243688
B44: 엔믹스
B45: AD MARE | E45: 500543
B46: ENTWURF | E46: 569763
...

Sheet 콘서트
B1: 콘서트(공연) 매출
B2: Value analysis as of August 31, 2025
B3: KRW in millions
E4: 4 | F4: 5
E6: Business Plan | P6: PwC_Base | AA6: PwC_Worst
E7: 개최 수 | J7: 관객 수 | P7: 개최 수_사업계획 50% | U7: 관객 수 | AA7: 개최 수_사업계획 70%, 스타디움 제외 | AF7: 관객 수
B8: 구분 | C8: 콘서트분류 | D8: 좌석수 | E8: 2026 | F8: 2027 | G8: 2028 | H8: 2029 | I8: 2030 | J8: 2026 | K8: 2027 | L8: 2028 | M8: 2029 | N8: 2030 | P8: 2026 | Q8: 2027 | R8: 2028 | S8: 2029 | T8: 2030 | U8: 2026 | V8: 2027 | W8: 2028 | X8: 2029 | Y8: 2030 | AA8: 2026 | AB8: 2027 | AC8: 2028 | AD8: 2029 | AE8: 2030 | AF8: 2026 | AG8: 2027 | AH8: 2028 | AI8: 2029 | AJ8: 2030
B9: JTOPT | C9: 홀급 | D9: 5000 | E9: 0 | F9: 1 | G9: 1 | H9: 3 | I9: 20 | J9: =SUMPRODUCT($D9,E9) -> 0 | K9: =SUMPRODUCT($D9,F9) -> 5000 | L9: =SUMPRODUCT($D9,G9) -> 5000 | M9: =SUMPRODUCT($D9,H9) -> 15000 | N9: =SUMPRODUCT($D9,I9) -> 100000 | P9: =ROUND(E9/2,) -> 0 | Q9: =ROUND(F9/2,) -> 1 | R9: =ROUND(G9/2,) -> 1 | S9: =ROUND(H9/2,) -> 2 | T9: =ROUND(I9/2,) -> 10 | U9: =SUMPRODUCT($D9,P9) -> 0 | V9: =SUMPRODUCT($D9,Q9) -> 5000 | W9: =SUMPRODUCT($D9,R9) -> 5000 | X9: =SUMPRODUCT($D9,S9) -> 10000 | Y9: =SUMPRODUCT($D9,T9) -> 50000 | AA9: =IF(E9=0,0,IF(ROUND(E9*0.3,)<1,1,ROUND(E9*0.3,))) -> 0 | AB9: =IF(F9=0,0,IF(ROUND(F9*0.3,)<1,1,ROUND(F9*0.3,))) -> 1 | AC9: =IF(G9=0,0,IF(ROUND(G9*0.3,)<1,1,ROUND(G9*0.3,))) -> 1 | AD9: =IF(H9=0,0,IF(ROUND(H9*0.3,)<1,1,ROUND(H9*0.3,))) -> 1 | AE9: =IF(I9=0,0,IF(ROUND(I9*0.3,)<1,1,ROUND(I9*0.3,))) -> 6 | AF9: =SUMPRODUCT($D9,AA9) -> 0 | AG9: =SUMPRODUCT($D9,AB9) -> 5000 | AH9: =SUMPRODUCT($D9,AC9) -> 5000 | AI9: =SUMPRODUCT($D9,AD9) -> 5000 | AJ9: =SUMPRODUCT($D9,AE9) -> 30000
B10: JTOPT | C10: 아레나급 | D10: 15000 | E10: 0 | F10: 0 | G10: 2 | H10: 5 | I10: 10 | J10: =SUMPRODUCT($D10,E10) -> 0 | K10: =SUMPRODUCT($D10,F10) -> 0 | L10: =SUMPRODUCT($D10,G10) -> 30000 | M10: =SUMPRODUCT($D10,H10) -> 75000 | N10: =SUMPRODUCT($D10,I10) -> 150000 | P10: =ROUND(E10/2,) -> 0 | Q10: =ROUND(F10/2,) -> 0 | R10: =ROUND(G10/2,) -> 1 | S10: =ROUND(H10/2,) -> 3 | T10: =ROUND(I10/2,) -> 5 | U10: =SUMPRODUCT($D10,P10) -> 0 | V10: =SUMPRODUCT($D10,Q10) -> 0 | W10: =SUMPRODUCT($D10,R10) -> 15000 | X10: =SUMPRODUCT($D10,S10) -> 45000 | Y10: =SUMPRODUCT($D10,T10) -> 75000 | AA10: =IF(E10=0,0,IF(ROUND(E10*0.3,)<1,1,ROUND(E10*0.3,))) -> 0 | AB10: =IF(F10=0,0,IF(ROUND(F10*0.3,)<1,1,ROUND(F10*0.3,))) -> 0 | AC10: =IF(G10=0,0,IF(ROUND(G10*0.3,)<1,1,ROUND(G10*0.3,))) -> 1 | AD10: =IF(H10=0,0,IF(ROUND(H10*0.3,)<1,1,ROUND(H10*0.3,))) -> 2 | AE10: =IF(I10=0,0,IF(ROUND(I10*0.3,)<1,1,ROUND(I10*0.3,))) -> 3 | AF10: =SUMPRODUCT($D10,AA10) -> 0 | AG10: =SUMPRODUCT($D10,AB10) -> 0 | AH10: =SUMPRODUCT($D10,AC10) -> 15000 | AI10: =SUMPRODUCT($D10,AD10) -> 30000 | AJ10: =SUMPRODUCT($D10,AE10) -> 45000
B11: JTOPT | C11: 돔급 | D11: 50000 | E11: 0 | F11: 0 | G11: 0 | H11: 5 | I11: 10 | J11: =SUMPRODUCT($D11,E11) -> 0 | K11: =SUMPRODUCT($D11,F11) -> 0 | L11: =SUMPRODUCT($D11,G11) -> 0 | M11: =SUMPRODUCT($D11,H11) -> 250000 | N11: =SUMPRODUCT($D11,I11) -> 500000 | P11: =ROUND(E11/2,) -> 0 | Q11: =ROUND(F11/2,) -> 0 | R11: =ROUND(G11/2,) -> 0 | S11: =ROUND(H11/2,) -> 3 | T11: =ROUND(I11/2,) -> 5 | U11: =SUMPRODUCT($D11,P11) -> 0 | V11: =SUMPRODUCT($D11,Q11) -> 0 | W11: =SUMPRODUCT($D11,R11) -> 0 | X11: =SUMPRODUCT($D11,S11) -> 150000 | Y11: =SUMPRODUCT($D11,T11) -> 250000 | AA11: =IF(E11=0,0,IF(ROUND(E11*0.3,)<1,1,ROUND(E11*0.3,))) -> 0 | AB11: =IF(F11=0,0,IF(ROUND(F11*0.3,)<1,1,ROUND(F11*0.3,))) -> 0 | AC11: =IF(G11=0,0,IF(ROUND(G11*0.3,)<1,1,ROUND(G11*0.3,))) -> 0 | AD11: =IF(H11=0,0,IF(ROUND(H11*0.3,)<1,1,ROUND(H11*0.3,))) -> 2 | AE11: =IF(I11=0,0,IF(ROUND(I11*0.3,)<1,1,ROUND(I11*0.3,))) -> 3 | AF11: =SUMPRODUCT($D11,AA11) -> 0 | AG11: =SUMPRODUCT($D11,AB11) -> 0 | AH11: =SUMPRODUCT($D11,AC11) -> 0 | AI11: =SUMPRODUCT($D11,AD11) -> 100000 | AJ11: =SUMPRODUCT($D11,AE11) -> 150000
B12: JTOPT | C12: 스타디움급 | D12: 80000 | E12: 0 | F12: 0 | G12: 0 | H12: 0 | I12: 5 | J12: =SUMPRODUCT($D12,E12) -> 0 | K12: =SUMPRODUCT($D12,F12) -> 0 | L12: =SUMPRODUCT($D12,G12) -> 0 | M12: =SUMPRODUCT($D12,H12) -> 0 | N12: =SUMPRODUCT($D12,I12) -> 400000 | P12: =ROUND(E12/2,) -> 0 | Q12: =ROUND(F12/2,) -> 0 | R12: =ROUND(G12/2,) -> 0 | S12: =ROUND(H12/2,) -> 0 | T12: =ROUND(I12/2,) -> 3 | U12: =SUMPRODUCT($D12,P12) -> 0 | V12: =SUMPRODUCT($D12,Q12) -> 0 | W12: =SUMPRODUCT($D12,R12) -> 0 | X12: =SUMPRODUCT($D12,S12) -> 0 | Y12: =SUMPRODUCT($D12,T12) -> 240000 | AA12: 0 | AB12: 0 | AC12: 0 | AD12: 0 | AE12: 0 | AF12: =SUMPRODUCT($D12,AA12) -> 0 | AG12: =SUMPRODUCT($D12,AB12) -> 0 | AH12: =SUMPRODUCT($D12,AC12) -> 0 | AI12: =SUMPRODUCT($D12,AD12) -> 0 | AJ12: =SUMPRODUCT($D12,AE12) -> 0
B13: 한국 | C13: 홀급 | D13: 5000 | E13: 0 | F13: 1 | G13: 0 | H13: 0 | I13: 0 | J13: =SUMPRODUCT($D13,E13) -> 0 | K13: =SUMPRODUCT($D13,F13) -> 5000 | L13: =SUMPRODUCT($D13,G13) -> 0 | M13: =SUMPRODUCT($D13,H13) -> 0 | N13: =SUMPRODUCT($D13,I13) -> 0 | P13: =ROUND(E13/2,) -> 0 | Q13: =ROUND(F13/2,) -> 1 | R13: =ROUND(G13/2,) -> 0 | S13: =ROUND(H13/2,) -> 0 | T13: =ROUND(I13/2,) -> 0 | U13: =SUMPRODUCT($D13,P13) -> 0 | V13: =SUMPRODUCT($D13,Q13) -> 5000 | W13: =SUMPRODUCT($D13,R13) -> 0 | X13: =SUMPRODUCT($D13,S13) -> 0 | Y13: =SUMPRODUCT($D13,T13) -> 0 | AA13: =IF(E13=0,0,IF(ROUND(E13*0.3,)<1,1,ROUND(E13*0.3,))) -> 0 | AB13: =IF(F13=0,0,IF(ROUND(F13*0.3,)<1,1,ROUND(F13*0.3,))) -> 1 | AC13: =IF(G13=0,0,IF(ROUND(G13*0.3,)<1,1,ROUND(G13*0.3,))) -> 0 | AD13: =IF(H13=0,0,IF(ROUND(H13*0.3,)<1,1,ROUND(H13*0.3,))) -> 0 | AE13: =IF(I13=0,0,IF(ROUND(I13*0.3,)<1,1,ROUND(I13*0.3,))) -> 0 | AF13: =SUMPRODUCT($D13,AA13) -> 0 | AG13: =SUMPRODUCT($D13,AB13) -> 5000 | AH13: =SUMPRODUCT($D13,AC13) -> 0 | AI13: =SUMPRODUCT($D13,AD13) -> 0 | AJ13: =SUMPRODUCT($D13,AE13) -> 0
B14: 한국 | C14: 아레나급 | D14: 15000 | E14: 0 | F14: 0 | G14: 2 | H14: 2 | I14: 2 | J14: =SUMPRODUCT($D14,E14) -> 0 | K14: =SUMPRODUCT($D14,F14) -> 0 | L14: =SUMPRODUCT($D14,G14) -> 30000 | M14: =SUMPRODUCT($D14,H14) -> 30000 | N14: =SUMPRODUCT($D14,I14) -> 30000 | P14: =ROUND(E14/2,) -> 0 | Q14: =ROUND(F14/2,) -> 0 | R14: =ROUND(G14/2,) -> 1 | S14: =ROUND(H14/2,) -> 1 | T14: =ROUND(I14/2,) -> 1 | U14: =SUMPRODUCT($D14,P14) -> 0 | V14: =SUMPRODUCT($D14,Q14) -> 0 | W14: =SUMPRODUCT($D14,R14) -> 15000 | X14: =SUMPRODUCT($D14,S14) -> 15000 | Y14: =SUMPRODUCT($D14,T14) -> 15000 | AA14: =IF(E14=0,0,IF(ROUND(E14*0.3,)<1,1,ROUND(E14*0.3,))) -> 0 | AB14: =IF(F14=0,0,IF(ROUND(F14*0.3,)<1,1,ROUND(F14*0.3,))) -> 0 | AC14: =IF(G14=0,0,IF(ROUND(G14*0.3,)<1,1,ROUND(G14*0.3,))) -> 1 | AD14: =IF(H14=0,0,IF(ROUND(H14*0.3,)<1,1,ROUND(H14*0.3,))) -> 1 | AE14: =IF(I14=0,0,IF(ROUND(I14*0.3,)<1,1,ROUND(I14*0.3,))) -> 1 | AF14: =SUMPRODUCT($D14,AA14) -> 0 | AG14: =SUMPRODUCT($D14,AB14) -> 0 | AH14: =SUMPRODUCT($D14,AC14) -> 15000 | AI14: =SUMPRODUCT($D14,AD14) -> 15000 | AJ14: =SUMPRODUCT($D14,AE14) -> 15000
B15: 한국 | C15: 돔급 | D15: 50000 | E15: 0 | F15: 0 | G15: 0 | H15: 0 | I15: 1 | J15: =SUMPRODUCT($D15,E15) -> 0 | K15: =SUMPRODUCT($D15,F15) -> 0 | L15: =SUMPRODUCT($D15,G15) -> 0 | M15: =SUMPRODUCT($D15,H15) -> 0 | N15: =SUMPRODUCT($D15,I15) -> 50000 | P15: =ROUND(E15/2,) -> 0 | Q15: =ROUND(F15/2,) -> 0 | R15: =ROUND(G15/2,) -> 0 | S15: =ROUND(H15/2,) -> 0 | T15: =ROUND(I15/2,) -> 1 | U15: =SUMPRODUCT($D15,P15) -> 0 | V15: =SUMPRODUCT($D15,Q15) -> 0 | W15: =SUMPRODUCT($D15,R15) -> 0 | X15: =SUMPRODUCT($D15,S15) -> 0 | Y15: =SUMPRODUCT($D15,T15) -> 50000 | AA15: =IF(E15=0,0,IF(ROUND(E15*0.3,)<1,1,ROUND(E15*0.3,))) -> 0 | AB15: =IF(F15=0,0,IF(ROUND(F15*0.3,)<1,1,ROUND(F15*0.3,))) -> 0 | AC15: =IF(G15=0,0,IF(ROUND(G15*0.3,)<1,1,ROUND(G15*0.3,))) -> 0 | AD15: =IF(H15=0,0,IF(ROUND(H15*0.3,)<1,1,ROUND(H15*0.3,))) -> 0 | AE15: =IF(I15=0,0,IF(ROUND(I15*0.3,)<1,1,ROUND(I15*0.3,))) -> 1 | AF15: =SUMPRODUCT($D15,AA15) -> 0 | AG15: =SUMPRODUCT($D15,AB15) -> 0 | AH15: =SUMPRODUCT($D15,AC15) -> 0 | AI15: =SUMPRODUCT($D15,AD15) -> 0 | AJ15: =SUMPRODUCT($D15,AE15) -> 50000
B16: 한국 | C16: 스타디움급 | D16: 80000 | E16: 0 | F16: 0 | G16: 0 | H16: 0 | I16: 1 | J16: =SUMPRODUCT($D16,E16) -> 0 | K16: =SUMPRODUCT($D16,F16) -> 0 | L16: =SUMPRODUCT($D16,G16) -> 0 | M16: =SUMPRODUCT($D16,H16) -> 0 | N16: =SUMPRODUCT($D16,I16) -> 80000 | P16: =ROUND(E16/2,) -> 0 | Q16: =ROUND(F16/2,) -> 0 | R16: =ROUND(G16/2,) -> 0 | S16: =ROUND(H16/2,) -> 0 | T16: =ROUND(I16/2,) -> 1 | U16: =SUMPRODUCT($D16,P16) -> 0 | V16: =SUMPRODUCT($D16,Q16) -> 0 | W16: =SUMPRODUCT($D16,R16) -> 0 | X16: =SUMPRODUCT($D16,S16) -> 0 | Y16: =SUMPRODUCT($D16,T16) -> 80000 | AA16: 0 | AB16: 0 | AC16: 0 | AD16: 0 | AE16: 0 | AF16: =SUMPRODUCT($D16,AA16) -> 0 | AG16: =SUMPRODUCT($D16,AB16) -> 0 | AH16: =SUMPRODUCT($D16,AC16) -> 0 | AI16: =SUMPRODUCT($D16,AD16) -> 0 | AJ16: =SUMPRODUCT($D16,AE16) -> 0
B17: 일본 | C17: 홀급 | D17: 5000 | E17: 0 | F17: 1 | G17: 3 | H17: 3 | I17: 3 | J17: =SUMPRODUCT($D17,E17) -> 0 | K17: =SUMPRODUCT($D17,F17) -> 5000 | L17: =SUMPRODUCT($D17,G17) -> 15000 | M17: =SUMPRODUCT($D17,H17) -> 15000 | N17: =SUMPRODUCT($D17,I17) -> 15000 | P17: =ROUND(E17/2,) -> 0 | Q17: =ROUND(F17/2,) -> 1 | R17: =ROUND(G17/2,) -> 2 | S17: =ROUND(H17/2,) -> 2 | T17: =ROUND(I17/2,) -> 2 | U17: =SUMPRODUCT($D17,P17) -> 0 | V17: =SUMPRODUCT($D17,Q17) -> 5000 | W17: =SUMPRODUCT($D17,R17) -> 10000 | X17: =SUMPRODUCT($D17,S17) -> 10000 | Y17: =SUMPRODUCT($D17,T17) -> 10000 | AA17: =IF(E17=0,0,IF(ROUND(E17*0.3,)<1,1,ROUND(E17*0.3,))) -> 0 | AB17: =IF(F17=0,0,IF(ROUND(F17*0.3,)<1,1,ROUND(F17*0.3,))) -> 1 | AC17: =IF(G17=0,0,IF(ROUND(G17*0.3,)<1,1,ROUND(G17*0.3,))) -> 1 | AD17: =IF(H17=0,0,IF(ROUND(H17*0.3,)<1,1,ROUND(H17*0.3,))) -> 1 | AE17: =IF(I17=0,0,IF(ROUND(I17*0.3,)<1,1,ROUND(I17*0.3,))) -> 1 | AF17: =SUMPRODUCT($D17,AA17) -> 0 | AG17: =SUMPRODUCT($D17,AB17) -> 5000 | AH17: =SUMPRODUCT($D17,AC17) -> 5000 | AI17: =SUMPRODUCT($D17,AD17) -> 5000 | AJ17: =SUMPRODUCT($D17,AE17) -> 5000
B18: 일본 | C18: 아레나급 | D18: 15000 | E18: 0 | F18: 0 | G18: 2 | H18: 3 | I18: 5 | J18: =SUMPRODUCT($D18,E18) -> 0 | K18: =SUMPRODUCT($D18,F18) -> 0 | L18: =SUMPRODUCT($D18,G18) -> 30000 | M18: =SUMPRODUCT($D18,H18) -> 45000 | N18: =SUMPRODUCT($D18,I18) -> 75000 | P18: =ROUND(E18/2,) -> 0 | Q18: =ROUND(F18/2,) -> 0 | R18: =ROUND(G18/2,) -> 1 | S18: =ROUND(H18/2,) -> 2 | T18: =ROUND(I18/2,) -> 3 | U18: =SUMPRODUCT($D18,P18) -> 0 | V18: =SUMPRODUCT($D18,Q18) -> 0 | W18: =SUMPRODUCT($D18,R18) -> 15000 | X18: =SUMPRODUCT($D18,S18) -> 30000 | Y18: =SUMPRODUCT($D18,T18) -> 45000 | AA18: =IF(E18=0,0,IF(ROUND(E18*0.3,)<1,1,ROUND(E18*0.3,))) -> 0 | AB18: =IF(F18=0,0,IF(ROUND(F18*0.3,)<1,1,ROUND(F18*0.3,))) -> 0 | AC18: =IF(G18=0,0,IF(ROUND(G18*0.3,)<1,1,ROUND(G18*0.3,))) -> 1 | AD18: =IF(H18=0,0,IF(ROUND(H18*0.3,)<1,1,ROUND(H18*0.3,))) -> 1 | AE18: =IF(I18=0,0,IF(ROUND(I18*0.3,)<1,1,ROUND(I18*0.3,))) -> 2 | AF18: =SUMPRODUCT($D18,AA18) -> 0 | AG18: =SUMPRODUCT($D18,AB18) -> 0 | AH18: =SUMPRODUCT($D18,AC18) -> 15000 | AI18: =SUMPRODUCT($D18,AD18) -> 15000 | AJ18: =SUMPRODUCT($D18,AE18) -> 30000
B19: 일본 | C19: 돔급 | D19: 50000 | E19: 0 | F19: 0 | G19: 0 | H19: 0 | I19: 2 | J19: =SUMPRODUCT($D19,E19) -> 0 | K19: =SUMPRODUCT($D19,F19) -> 0 | L19: =SUMPRODUCT($D19,G19) -> 0 | M19: =SUMPRODUCT($D19,H19) -> 0 | N19: =SUMPRODUCT($D19,I19) -> 100000 | P19: =ROUND(E19/2,) -> 0 | Q19: =ROUND(F19/2,) -> 0 | R19: =ROUND(G19/2,) -> 0 | S19: =ROUND(H19/2,) -> 0 | T19: =ROUND(I19/2,) -> 1 | U19: =SUMPRODUCT($D19,P19) -> 0 | V19: =SUMPRODUCT($D19,Q19) -> 0 | W19: =SUMPRODUCT($D19,R19) -> 0 | X19: =SUMPRODUCT($D19,S19) -> 0 | Y19: =SUMPRODUCT($D19,T19) -> 50000 | AA19: =IF(E19=0,0,IF(ROUND(E19*0.3,)<1,1,ROUND(E19*0.3,))) -> 0 | AB19: =IF(F19=0,0,IF(ROUND(F19*0.3,)<1,1,ROUND(F19*0.3,))) -> 0 | AC19: =IF(G19=0,0,IF(ROUND(G19*0.3,)<1,1,ROUND(G19*0.3,))) -> 0 | AD19: =IF(H19=0,0,IF(ROUND(H19*0.3,)<1,1,ROUND(H19*0.3,))) -> 0 | AE19: =IF(I19=0,0,IF(ROUND(I19*0.3,)<1,1,ROUND(I19*0.3,))) -> 1 | AF19: =SUMPRODUCT($D19,AA19) -> 0 | AG19: =SUMPRODUCT($D19,AB19) -> 0 | AH19: =SUMPRODUCT($D19,AC19) -> 0 | AI19: =SUMPRODUCT($D19,AD19) -> 0 | AJ19: =SUMPRODUCT($D19,AE19) -> 50000
B20: 일본 | C20: 스타디움급 | D20: 80000 | E20: 0 | F20: 0 | G20: 0 | H20: 0 | I20: 0 | J20: =SUMPRODUCT($D20,E20) -> 0 | K20: =SUMPRODUCT($D20,F20) -> 0 | L20: =SUMPRODUCT($D20,G20) -> 0 | M20: =SUMPRODUCT($D20,H20) -> 0 | N20: =SUMPRODUCT($D20,I20) -> 0 | P20: =ROUND(E20/2,) -> 0 | Q20: =ROUND(F20/2,) -> 0 | R20: =ROUND(G20/2,) -> 0 | S20: =ROUND(H20/2,) -> 0 | T20: =ROUND(I20/2,) -> 0 | U20: =SUMPRODUCT($D20,P20) -> 0 | V20: =SUMPRODUCT($D20,Q20) -> 0 | W20: =SUMPRODUCT($D20,R20) -> 0 | X20: =SUMPRODUCT($D20,S20) -> 0 | Y20: =SUMPRODUCT($D20,T20) -> 0 | AA20: =IF(E20=0,0,IF(ROUND(E20*0.3,)<1,1,ROUND(E20*0.3,))) -> 0 | AB20: =IF(F20=0,0,IF(ROUND(F20*0.3,)<1,1,ROUND(F20*0.3,))) -> 0 | AC20: =IF(G20=0,0,IF(ROUND(G20*0.3,)<1,1,ROUND(G20*0.3,))) -> 0 | AD20: =IF(H20=0,0,IF(ROUND(H20*0.3,)<1,1,ROUND(H20*0.3,))) -> 0 | AE20: =IF(I20=0,0,IF(ROUND(I20*0.3,)<1,1,ROUND(I20*0.3,))) -> 0 | AF20: =SUMPRODUCT($D20,AA20) -> 0 | AG20: =SUMPRODUCT($D20,AB20) -> 0 | AH20: =SUMPRODUCT($D20,AC20) -> 0 | AI20: =SUMPRODUCT($D20,AD20) -> 0 | AJ20: =SUMPRODUCT($D20,AE20) -> 0
B21: 동남아 | C21: 홀급 | D21: 5000 | E21: 0 | F21: 1 | G21: 5 | H21: 10 | I21: 10 | J21: =SUMPRODUCT($D21,E21) -> 0 | K21: =SUMPRODUCT($D21,F21) -> 5000 | L21: =SUMPRODUCT($D21,G21) -> 25000 | M21: =SUMPRODUCT($D21,H21) -> 50000 | N21: =SUMPRODUCT($D21,I21) -> 50000 | P21: =ROUND(E21/2,) -> 0 | Q21: =ROUND(F21/2,) -> 1 | R21: =ROUND(G21/2,) -> 3 | S21: =ROUND(H21/2,) -> 5 | T21: =ROUND(I21/2,) -> 5 | U21: =SUMPRODUCT($D21,P21) -> 0 | V21: =SUMPRODUCT($D21,Q21) -> 5000 | W21: =SUMPRODUCT($D21,R21) -> 15000 | X21: =SUMPRODUCT($D21,S21) -> 25000 | Y21: =SUMPRODUCT($D21,T21) -> 25000 | AA21: =IF(E21=0,0,IF(ROUND(E21*0.3,)<1,1,ROUND(E21*0.3,))) -> 0 | AB21: =IF(F21=0,0,IF(ROUND(F21*0.3,)<1,1,ROUND(F21*0.3,))) -> 1 | AC21: =IF(G21=0,0,IF(ROUND(G21*0.3,)<1,1,ROUND(G21*0.3,))) -> 2 | AD21: =IF(H21=0,0,IF(ROUND(H21*0.3,)<1,1,ROUND(H21*0.3,))) -> 3 | AE21: =IF(I21=0,0,IF(ROUND(I21*0.3,)<1,1,ROUND(I21*0.3,))) -> 3 | AF21: =SUMPRODUCT($D21,AA21) -> 0 | AG21: =SUMPRODUCT($D21,AB21) -> 5000 | AH21: =SUMPRODUCT($D21,AC21) -> 10000 | AI21: =SUMPRODUCT($D21,AD21) -> 15000 | AJ21: =SUMPRODUCT($D21,AE21) -> 15000
B22: 동남아 | C22: 아레나급 | D22: 15000 | E22: 0 | F22: 0 | G22: 0 | H22: 0 | I22: 5 | J22: =SUMPRODUCT($D22,E22) -> 0 | K22: =SUMPRODUCT($D22,F22) -> 0 | L22: =SUMPRODUCT($D22,G22) -> 0 | M22: =SUMPRODUCT($D22,H22) -> 0 | N22: =SUMPRODUCT($D22,I22) -> 75000 | P22: =ROUND(E22/2,) -> 0 | Q22: =ROUND(F22/2,) -> 0 | R22: =ROUND(G22/2,) -> 0 | S22: =ROUND(H22/2,) -> 0 | T22: =ROUND(I22/2,) -> 3 | U22: =SUMPRODUCT($D22,P22) -> 0 | V22: =SUMPRODUCT($D22,Q22) -> 0 | W22: =SUMPRODUCT($D22,R22) -> 0 | X22: =SUMPRODUCT($D22,S22) -> 0 | Y22: =SUMPRODUCT($D22,T22) -> 45000 | AA22: =IF(E22=0,0,IF(ROUND(E22*0.3,)<1,1,ROUND(E22*0.3,))) -> 0 | AB22: =IF(F22=0,0,IF(ROUND(F22*0.3,)<1,1,ROUND(F22*0.3,))) -> 0 | AC22: =IF(G22=0,0,IF(ROUND(G22*0.3,)<1,1,ROUND(G22*0.3,))) -> 0 | AD22: =IF(H22=0,0,IF(ROUND(H22*0.3,)<1,1,ROUND(H22*0.3,))) -> 0 | AE22: =IF(I22=0,0,IF(ROUND(I22*0.3,)<1,1,ROUND(I22*0.3,))) -> 2 | AF22: =SUMPRODUCT($D22,AA22) -> 0 | AG22: =SUMPRODUCT($D22,AB22) -> 0 | AH22: =SUMPRODUCT($D22,AC22) -> 0 | AI22: =SUMPRODUCT($D22,AD22) -> 0 | AJ22: =SUMPRODUCT($D22,AE22) -> 30000
B23: 동남아 | C23: 돔급 | D23: 50000 | E23: 0 | F23: 0 | G23: 0 | H23: 0 | I23: 0 | J23: =SUMPRODUCT($D23,E23) -> 0 | K23: =SUMPRODUCT($D23,F23) -> 0 | L23: =SUMPRODUCT($D23,G23) -> 0 | M23: =SUMPRODUCT($D23,H23) -> 0 | N23: =SUMPRODUCT($D23,I23) -> 0 | P23: =ROUND(E23/2,) -> 0 | Q23: =ROUND(F23/2,) -> 0 | R23: =ROUND(G23/2,) -> 0 | S23: =ROUND(H23/2,) -> 0 | T23: =ROUND(I23/2,) -> 0 | U23: =SUMPRODUCT($D23,P23) -> 0 | V23: =SUMPRODUCT($D23,Q23) -> 0 | W23: =SUMPRODUCT($D23,R23) -> 0 | X23: =SUMPRODUCT($D23,S23) -> 0 | Y23: =SUMPRODUCT($D23,T23) -> 0 | AA23: =IF(E23=0,0,IF(ROUND(E23*0.3,)<1,1,ROUND(E23*0.3,))) -> 0 | AB23: =IF(F23=0,0,IF(ROUND(F23*0.3,)<1,1,ROUND(F23*0.3,))) -> 0 | AC23: =IF(G23=0,0,IF(ROUND(G23*0.3,)<1,1,ROUND(G23*0.3,))) -> 0 | AD23: =IF(H23=0,0,IF(ROUND(H23*0.3,)<1,1,ROUND(H23*0.3,))) -> 0 | AE23: =IF(I23=0,0,IF(ROUND(I23*0.3,)<1,1,ROUND(I23*0.3,))) -> 0 | AF23: =SUMPRODUCT($D23,AA23) -> 0 | AG23: =SUMPRODUCT($D23,AB23) -> 0 | AH23: =SUMPRODUCT($D23,AC23) -> 0 | AI23: =SUMPRODUCT($D23,AD23) -> 0 | AJ23: =SUMPRODUCT($D23,AE23) -> 0
B24: 동남아 | C24: 스타디움급 | D24: 80000 | E24: 0 | F24: 0 | G24: 0 | H24: 0 | I24: 0 | J24: =SUMPRODUCT($D24,E24) -> 0 | K24: =SUMPRODUCT($D24,F24) -> 0 | L24: =SUMPRODUCT($D24,G24) -> 0 | M24: =SUMPRODUCT($D24,H24) -> 0 | N24: =SUMPRODUCT($D24,I24) -> 0 | P24: =ROUND(E24/2,) -> 0 | Q24: =ROUND(F24/2,) -> 0 | R24: =ROUND(G24/2,) -> 0 | S24: =ROUND(H24/2,) -> 0 | T24: =ROUND(I24/2,) -> 0 | U24: =SUMPRODUCT($D24,P24) -> 0 | V24: =SUMPRODUCT($D24,Q24) -> 0 | W24: =SUMPRODUCT($D24,R24) -> 0 | X24: =SUMPRODUCT($D24,S24) -> 0 | Y24: =SUMPRODUCT($D24,T24) -> 0 | AA24: =IF(E24=0,0,IF(ROUND(E24*0.3,)<1,1,ROUND(E24*0.3,))) -> 0 | AB24: =IF(F24=0,0,IF(ROUND(F24*0.3,)<1,1,ROUND(F24*0.3,))) -> 0 | AC24: =IF(G24=0,0,IF(ROUND(G24*0.3,)<1,1,ROUND(G24*0.3,))) -> 0 | AD24: =IF(H24=0,0,IF(ROUND(H24*0.3,)<1,1,ROUND(H24*0.3,))) -> 0 | AE24: =IF(I24=0,0,IF(ROUND(I24*0.3,)<1,1,ROUND(I24*0.3,))) -> 0 | AF24: =SUMPRODUCT($D24,AA24) -> 0 | AG24: =SUMPRODUCT($D24,AB24) -> 0 | AH24: =SUMPRODUCT($D24,AC24) -> 0 | AI24: =SUMPRODUCT($D24,AD24) -> 0 | AJ24: =SUMPRODUCT($D24,AE24) -> 0
B25: 프랑스 | C25: 홀급 | D25: 5000 | E25: 0 | F25: 1 | G25: 5 | H25: 10 | I25: 10 | J25: =SUMPRODUCT($D25,E25) -> 0 | K25: =SUMPRODUCT($D25,F25) -> 5000 | L25: =SUMPRODUCT($D25,G25) -> 25000 | M25: =SUMPRODUCT($D25,H25) -> 50000 | N25: =SUMPRODUCT($D25,I25) -> 50000 | P25: =ROUND(E25/2,) -> 0 | Q25: =ROUND(F25/2,) -> 1 | R25: =ROUND(G25/2,) -> 3 | S25: =ROUND(H25/2,) -> 5 | T25: =ROUND(I25/2,) -> 5 | U25: =SUMPRODUCT($D25,P25) -> 0 | V25: =SUMPRODUCT($D25,Q25) -> 5000 | W25: =SUMPRODUCT($D25,R25) -> 15000 | X25: =SUMPRODUCT($D25,S25) -> 25000 | Y25: =SUMPRODUCT($D25,T25) -> 25000 | AA25: =IF(E25=0,0,IF(ROUND(E25*0.3,)<1,1,ROUND(E25*0.3,))) -> 0 | AB25: =IF(F25=0,0,IF(ROUND(F25*0.3,)<1,1,ROUND(F25*0.3,))) -> 1 | AC25: =IF(G25=0,0,IF(ROUND(G25*0.3,)<1,1,ROUND(G25*0.3,))) -> 2 | AD25: =IF(H25=0,0,IF(ROUND(H25*0.3,)<1,1,ROUND(H25*0.3,))) -> 3 | AE25: =IF(I25=0,0,IF(ROUND(I25*0.3,)<1,1,ROUND(I25*0.3,))) -> 3 | AF25: =SUMPRODUCT($D25,AA25) -> 0 | AG25: =SUMPRODUCT($D25,AB25) -> 5000 | AH25: =SUMPRODUCT($D25,AC25) -> 10000 | AI25: =SUMPRODUCT($D25,AD25) -> 15000 | AJ25: =SUMPRODUCT($D25,AE25) -> 15000
B26: 프랑스 | C26: 아레나급 | D26: 15000 | E26: 0 | F26: 0 | G26: 0 | H26: 0 | I26: 1 | J26: =SUMPRODUCT($D26,E26) -> 0 | K26: =SUMPRODUCT($D26,F26) -> 0 | L26: =SUMPRODUCT($D26,G26) -> 0 | M26: =SUMPRODUCT($D26,H26) -> 0 | N26: =SUMPRODUCT($D26,I26) -> 15000 | P26: =ROUND(E26/2,) -> 0 | Q26: =ROUND(F26/2,) -> 0 | R26: =ROUND(G26/2,) -> 0 | S26: =ROUND(H26/2,) -> 0 | T26: =ROUND(I26/2,) -> 1 | U26: =SUMPRODUCT($D26,P26) -> 0 | V26: =SUMPRODUCT($D26,Q26) -> 0 | W26: =SUMPRODUCT($D26,R26) -> 0 | X26: =SUMPRODUCT($D26,S26) -> 0 | Y26: =SUMPRODUCT($D26,T26) -> 15000 | AA26: =IF(E26=0,0,IF(ROUND(E26*0.3,)<1,1,ROUND(E26*0.3,))) -> 0 | AB26: =IF(F26=0,0,IF(ROUND(F26*0.3,)<1,1,ROUND(F26*0.3,))) -> 0 | AC26: =IF(G26=0,0,IF(ROUND(G26*0.3,)<1,1,ROUND(G26*0.3,))) -> 0 | AD26: =IF(H26=0,0,IF(ROUND(H26*0.3,)<1,1,ROUND(H26*0.3,))) -> 0 | AE26: =IF(I26=0,0,IF(ROUND(I26*0.3,)<1,1,ROUND(I26*0.3,))) -> 1 | AF26: =SUMPRODUCT($D26,AA26) -> 0 | AG26: =SUMPRODUCT($D26,AB26) -> 0 | AH26: =SUMPRODUCT($D26,AC26) -> 0 | AI26: =SUMPRODUCT($D26,AD26) -> 0 | AJ26: =SUMPRODUCT($D26,AE26) -> 15000
B27: 프랑스 | C27: 돔급 | D27: 50000 | E27: 0 | F27: 0 | G27: 0 | H27: 0 | I27: 0 | J27: =SUMPRODUCT($D27,E27) -> 0 | K27: =SUMPRODUCT($D27,F27) -> 0 | L27: =SUMPRODUCT($D27,G27) -> 0 | M27: =SUMPRODUCT($D27,H27) -> 0 | N27: =SUMPRODUCT($D27,I27) -> 0 | P27: =ROUND(E27/2,) -> 0 | Q27: =ROUND(F27/2,) -> 0 | R27: =ROUND(G27/2,) -> 0 | S27: =ROUND(H27/2,) -> 0 | T27: =ROUND(I27/2,) -> 0 | U27: =SUMPRODUCT($D27,P27) -> 0 | V27: =SUMPRODUCT($D27,Q27) -> 0 | W27: =SUMPRODUCT($D27,R27) -> 0 | X27: =SUMPRODUCT($D27,S27) -> 0 | Y27: =SUMPRODUCT($D27,T27) -> 0 | AA27: =IF(E27=0,0,IF(ROUND(E27*0.3,)<1,1,ROUND(E27*0.3,))) -> 0 | AB27: =IF(F27=0,0,IF(ROUND(F27*0.3,)<1,1,ROUND(F27*0.3,))) -> 0 | AC27: =IF(G27=0,0,IF(ROUND(G27*0.3,)<1,1,ROUND(G27*0.3,))) -> 0 | AD27: =IF(H27=0,0,IF(ROUND(H27*0.3,)<1,1,ROUND(H27*0.3,))) -> 0 | AE27: =IF(I27=0,0,IF(ROUND(I27*0.3,)<1,1,ROUND(I27*0.3,))) -> 0 | AF27: =SUMPRODUCT($D27,AA27) -> 0 | AG27: =SUMPRODUCT($D27,AB27) -> 0 | AH27: =SUMPRODUCT($D27,AC27) -> 0 | AI27: =SUMPRODUCT($D27,AD27) -> 0 | AJ27: =SUMPRODUCT($D27,AE27) -> 0
B28: 프랑스 | C28: 스타디움급 | D28: 80000 | E28: 0 | F28: 0 | G28: 0 | H28: 0 | I28: 0 | J28: =SUMPRODUCT($D28,E28) -> 0 | K28: =SUMPRODUCT($D28,F28) -> 0 | L28: =SUMPRODUCT($D28,G28) -> 0 | M28: =SUMPRODUCT($D28,H28) -> 0 | N28: =SUMPRODUCT($D28,I28) -> 0 | P28: =ROUND(E28/2,) -> 0 | Q28: =ROUND(F28/2,) -> 0 | R28: =ROUND(G28/2,) -> 0 | S28: =ROUND(H28/2,) -> 0 | T28: =ROUND(I28/2,) -> 0 | U28: =SUMPRODUCT($D28,P28) -> 0 | V28: =SUMPRODUCT($D28,Q28) -> 0 | W28: =SUMPRODUCT($D28,R28) -> 0 | X28: =SUMPRODUCT($D28,S28) -> 0 | Y28: =SUMPRODUCT($D28,T28) -> 0 | AA28: =IF(E28=0,0,IF(ROUND(E28*0.3,)<1,1,ROUND(E28*0.3,))) -> 0 | AB28: =IF(F28=0,0,IF(ROUND(F28*0.3,)<1,1,ROUND(F28*0.3,))) -> 0 | AC28: =IF(G28=0,0,IF(ROUND(G28*0.3,)<1,1,ROUND(G28*0.3,))) -> 0 | AD28: =IF(H28=0,0,IF(ROUND(H28*0.3,)<1,1,ROUND(H28*0.3,))) -> 0 | AE28: =IF(I28=0,0,IF(ROUND(I28*0.3,)<1,1,ROUND(I28*0.3,))) -> 0 | AF28: =SUMPRODUCT($D28,AA28) -> 0 | AG28: =SUMPRODUCT($D28,AB28) -> 0 | AH28: =SUMPRODUCT($D28,AC28) -> 0 | AI28: =SUMPRODUCT($D28,AD28) -> 0 | AJ28: =SUMPRODUCT($D28,AE28) -> 0
... B40: 호주 | C40: 스타디움급 | D40: 80000 | E40: 0 | F40: 0 | G40: 0 | H40: 0 | I40: 0 | J40: =SUMPRODUCT($D40,E40) -> 0 | K40: =SUMPRODUCT($D40,F40) -> 0 | L40: =SUMPRODUCT($D40,G40) -> 0 | M40: =SUMPRODUCT($D40,H40) -> 0 | N40: =SUMPRODUCT($D40,I40) -> 0 | P40: =ROUND(E40/2,) -> 0 | Q40: =ROUND(F40/2,) -> 0 | R40: =ROUND(G40/2,) -> 0 | S40: =ROUND(H40/2,) -> 0 | T40: =ROUND(I40/2,) -> 0 | U40: =SUMPRODUCT($D40,P40) -> 0 | V40: =SUMPRODUCT($D40,Q40) -> 0 | W40: =SUMPRODUCT($D40,R40) -> 0 | X40: =SUMPRODUCT($D40,S40) -> 0 | Y40: =SUMPRODUCT($D40,T40) -> 0 | AA40: =IF(E40=0,0,IF(ROUND(E40*0.3,)<1,1,ROUND(E40*0.3,))) -> 0 | AB40: =IF(F40=0,0,IF(ROUND(F40*0.3,)<1,1,ROUND(F40*0.3,))) -> 0 | AC40: =IF(G40=0,0,IF(ROUND(G40*0.3,)<1,1,ROUND(G40*0.3,))) -> 0 | AD40: =IF(H40=0,0,IF(ROUND(H40*0.3,)<1,1,ROUND(H40*0.3,))) -> 0 | AE40: =IF(I40=0,0,IF(ROUND(I40*0.3,)<1,1,ROUND(I40*0.3,))) -> 0 | AF40: =SUMPRODUCT($D40,AA40) -> 0 | AG40: =SUMPRODUCT($D40,AB40) -> 0 | AH40: =SUMPRODUCT($D40,AC40) -> 0 | AI40: =SUMPRODUCT($D40,AD40) -> 0 | AJ40: =SUMPRODUCT($D40,AE40) -> 0
B41: 합계 | E41: =SUBTOTAL(9,E9:E40) -> 0 | F41: =SUBTOTAL(9,F9:F40) -> 8 | G41: =SUBTOTAL(9,G9:G40) -> 35 | H41: =SUBTOTAL(9,H9:H40) -> 71 | I41: =SUBTOTAL(9,I9:I40) -> 118 | J41: =SUBTOTAL(9,J9:J40) -> 0 | K41: =SUBTOTAL(9,K9:K40) -> 40000 | L41: =SUBTOTAL(9,L9:L40) -> 235000 | ... N41: =SUBTOTAL(9,N9:N40) -> 1885000 | P41: =SUBTOTAL(9,P9:P40) -> 0 | Q41: =SUBTOTAL(9,Q9:Q40) -> 8 | R41: =SUBTOTAL(9,R9:R40) -> 21 | S41: =SUBTOTAL(9,S9:S40) -> 38 | T41: =SUBTOTAL(9,T9:T40) -> 64 | U41: =SUBTOTAL(9,U9:U40) -> 0 | V41: =SUBTOTAL(9,V9:V40) -> 40000 | W41: =SUBTOTAL(9,W9:W40) -> 135000 | ... Y41: =SUBTOTAL(9,Y9:Y40) -> 1095000 | AA41: =SUBTOTAL(9,AA9:AA40) -> 0 | AB41: =SUBTOTAL(9,AB9:AB40) -> 8 | AC41: =SUBTOTAL(9,AC9:AC40) -> 15 | AD41: =SUBTOTAL(9,AD9:AD40) -> 23 | AE41: =SUBTOTAL(9,AE9:AE40) -> 39 | AF41: =SUBTOTAL(9,AF9:AF40) -> 0 | AG41: =SUBTOTAL(9,AG9:AG40) -> 40000 | AH41: =SUBTOTAL(9,AH9:AH40) -> 105000 | ... AJ41: =SUBTOTAL(9,AJ9:AJ40) -> 540000
B42: 공연 당 관객 수 | K42: =K41/F41 -> 5000 | L42: =L41/G41 -> 6714.2857 | M42: =M41/H41 -> 9577.4648 | N42: =N41/I41 -> 15974.576 | V42: =V41/Q41 -> 5000 | W42: =W41/R41 -> 6428.5714 | X42: =X41/S41 -> 10131.579 | Y42: =Y41/T41 -> 17109.375 | AG42: =AG41/AB41 -> 5000 | AH42: =AH41/AC41 -> 7000 | AI42: =AI41/AD41 -> 10652.174 | AJ42: =AJ41/AE41 -> 13846.154
B45: 걸그룹 공연
B47: 구분 | C47: 공연명 | D47: 시기 | E47: 공연횟수 | F47: 관객수 | G47: 공연/관객
B48: 에스파 | C48: SYNK : PARALLEL LINE | D48: 24년 6월~25년 3월 | E48: 43 | F48: 520000 | G48: =F48/E48 -> 12093.023
B49: 에스파 | C49: SYNK : HYPER LINE | D49: 23년 2월~23년 9월 | E49: 31 | F49: 356000 | G49: =F49/E49 -> 11483.871
B50: 블랙핑크 | C50: BORN PINK | D50: 22년 10월~23년 9월 | E50: 38 | F50: 1815183 | G50: =F50/E50 -> 47767.974
B51: 트와이스 | C51: READY TO BE | D51: 23년 4월~ | E51: 51 | F51: 1500000 | G51: =F51/E51 -> 29411.765
B52: 아이브 | C52: SHOW WHAT I HAVE | D52: 23년 10월~24년9월 | E52: 29 | F52: 420000 | G52: =F52/E52 -> 14482.759

Sheet 유튜브
B1: 유튜브 광고매출
B2: Value analysis as of August 31, 2025
B3: KRW in millions
E4: 4 | F4: 5
B6: Source: https://socialblade.com/youtube
B8: 뉴진스 (데뷔 2022년 7월)
B10: 동영상 수 | C10: 705
B11: 업로드 수(월간) | C11: =C10/COUNTA(C14:AG14) -> 22.741935
B12: 조회수 평균 | C12: =AVERAGE(E17:AG17) -> 40.577612
B14: 구분 | C14: 44743 | D14: 44774 | E14: =EOMONTH(D14,1) -> 44834 | F14: =EOMONTH(E14,1) -> 44865 | G14: =EOMONTH(F14,1) -> 44895 | H14: =EOMONTH(G14,1) -> 44926 | I14: =EOMONTH(H14,1) -> 44957 | J14: =EOMONTH(I14,1) -> 44985 | K14: =EOMONTH(J14,1) -> 45016 | L14: =EOMONTH(K14,1) -> 45046 | ... AG14: =EOMONTH(AF14,1) -> 45688 | AH14: Total
B15: 명 수(누적) | C15: 10000 | D15: 57000 | E15: 633000 | F15: 873000 | G15: 1080000 | H15: 1230000 | I15: 1710000 | J15: 2430000 | K15: 2870000 | L15: 3210000 | M15: 3540000 | N15: 3690000 | O15: 3840000 | P15: 5060000 | Q15: 5530000 | R15: 5800000 | S15: 6040000 | T15: 6190000 | U15: 6380000 | V15: 6550000 | W15: 6650000 | X15: 6750000 | Y15: 6910000 | Z15: 7100000 | AA15: 7360000 | AB15: 7530000 | AC15: 7640000 | AD15: 7750000 | AE15: 7810000 | AF15: 7890000 | AG15: 7930000 | AH15: =AG15 -> 7930000
B16: 조회수(월간) | D16: 72868635 | E16: 72375161 | F16: 53655503 | G16: 60920309 | H16: 104830316 | I16: 240216450 | J16: 175292287 | K16: 147738401 | L16: 143013815 | M16: 100947342 | N16: 85979996 | O16: 453434834 | P16: 281060679 | Q16: 176909863 | R16: 171031247 | S16: 100327958 | T16: 132892288 | U16: 138375481 | V16: 88053478 | W16: 120575852 | X16: 92406177 | Y16: 173610613 | Z16: 212268281 | AA16: 192999650 | AB16: 154156549 | AC16: 115996030 | AD16: 80586976 | AE16: 79990932 | AF16: 82058363 | AG16: 85460435 | AH16: =SUBTOTAL(9,C16:AG16) -> 4190033901
B17: 인당 조회수 | D17: =D16/D15 -> 1278.3971 | E17: =E16/E15 -> 114.33675 | F17: =F16/F15 -> 61.461057 | G17: =G16/G15 -> 56.407694 | H17: =H16/H15 -> 85.227899 | I17: =I16/I15 -> 140.47746 | J17: =J16/J15 -> 72.136744 | K17: =K16/K15 -> 51.476795 | ... AH17: =AH16/AH15 -> 528.37754
B20: 엔믹스 (데뷔 2022년 2월)
B22: 동영상 수 | C22: 1100
B23: 업로드 수(월간) | C23: =C22/COUNTA(C26:AL26) -> 30.555556
B24: 조회수 평균 | C24: =AVERAGE(D30:AL30) -> 19.240615
B26: 구분 | C26: 44593 | D26: 44621 | E26: =EOMONTH(D26,1) -> 44681 | F26: =EOMONTH(E26,1) -> 44712 | G26: =EOMONTH(F26,1) -> 44742 | H26: =EOMONTH(G26,1) -> 44773 | I26: =EOMONTH(H26,1) -> 44804 | J26: =EOMONTH(I26,1) -> 44834 | K26: =EOMONTH(J26,1) -> 44865 | L26: =EOMONTH(K26,1) -> 44895 | ... AL26: =EOMONTH(AK26,1) -> 45688 | AM26: 45698 | AN26: Total
B27: 증감수 | D27: 336000 | E27: 176000 | F27: 136000 | G27: 80000 | H27: 60000 | I27: 50000 | J27: 80000 | K27: 100000 | L27: 50000 | M27: 60000 | N27: 50000 | O27: 40000 | P27: 130000 | Q27: 90000 | R27: 60000 | S27: 50000 | T27: 90000 | U27: 60000 | V27: 30000 | W27: 30000 | X27: 30000 | Y27: 90000 | Z27: 100000 | AA27: 50000 | AB27: 40000 | AC27: 70000 | AD27: 40000 | AE27: 40000 | AF27: 30000 | AG27: 70000 | AH27: 70000 | AI27: 50000 | AJ27: 80000 | AK27: 70000 | AL27: 70000
B28: 명 수(누적) | C28: 10000 | D28: 482000 | E28: 818000 | F28: 994000 | G28: 1130000 | H28: 1210000 | I28: 1270000 | J28: 1320000 | K28: 1400000 | L28: 1500000 | M28: 1550000 | N28: 1610000 | O28: 1660000 | P28: 1700000 | Q28: 1830000 | R28: 1920000 | S28: 1980000 | T28: 2030000 | U28: 2120000 | V28: 2180000 | W28: 2210000 | X28: 2240000 | Y28: 2270000 | Z28: 2360000 | AA28: 2460000 | AB28: 2510000 | AC28: 2550000 | AD28: 2620000 | AE28: 2660000 | AF28: 2700000 | AG28: 2730000 | AH28: 2800000 | AI28: 2870000 | AJ28: 2920000 | AK28: 3000000 | AL28: 3070000 | AM28: 3140000 | AN28: =AM28 -> 3140000
B29: 조회수(월간) | D29: 36185866 | E29: 30452602 | F29: 25480129 | G29: 20653970 | H29: 17107544 | I29: 14214375 | J29: 16792319 | K29: 45675174 | L29: 17085321 | M29: 24198450 | N29: 19319004 | O29: 15819918 | P29: 55698649 | Q29: 66606035 | R29: 34990436 | S29: 25055313 | T29: 60873877 | U29: 40039324 | V29: 22518440 | W29: 19808804 | X29: 13576429 | Y29: 75486271 | Z29: 70977929 | AA29: 53348519 | AB29: 36123377 | AC29: 29308305 | AD29: 40072644 | AE29: 30586039 | AF29: 31827833 | AG29: 45518330 | AH29: 46115890 | AI29: 35363602 | AJ29: 36313221 | AK29: 24788286 | AL29: 24822437 | AN29: =SUBTOTAL(9,I29:AM29) -> 1072924551
B30: 인당 조회수 | D30: =D29/D28 -> 75.074411 | E30: =E29/E28 -> 37.22812 | F30: =F29/F28 -> 25.633933 | G30: =G29/G28 -> 18.27785 | H30: =H29/H28 -> 14.138466 | I30: =I29/I28 -> 11.192421 | J30: =J29/J28 -> 12.721454 | K30: =K29/K28 -> 32.625124 | ... AL30: =AL29/AL28 -> 8.0854844 | AN30: =AN29/AN28 -> 341.69572
B32: 트리플에스 (데뷔 2022년 8월)
B34: 동영상 수 | C34: 2200
B35: 업로드 수(월간) | C35: =C34/COUNTA(C38:AF38) -> 73.333333
B36: 조회수 평균 | C36: =AVERAGE(D42:AF42) -> 17.193231
B38: 구분 | C38: 44774 | D38: 44805 | E38: =EOMONTH(D38,1) -> 44865 | F38: =EOMONTH(E38,1) -> 44895 | G38: =EOMONTH(F38,1) -> 44926 | H38: =EOMONTH(G38,1) -> 44957 | I38: =EOMONTH(H38,1) -> 44985 | J38: =EOMONTH(I38,1) -> 45016 | K38: =EOMONTH(J38,1) -> 45046 | L38: =EOMONTH(K38,1) -> 45077 | ... AF38: =EOMONTH(AE38,1) -> 45688 | AG38: 45698 | AH38: Total
B39: 증감수 | D39: 43000 | E39: 111000 | F39: 201000 | G39: 80000 | H39: 27000 | I39: 314000 | J39: 241000 | K39: 80000 | L39: 370000 | M39: 10000 | N39: 30000 | O39: 30000 | P39: 10000 | Q39: 20000 | R39: 50000 | S39: 90000 | T39: 320000 | U39: 80000 | V39: 10000 | W39: 0 | X39: 260000 | Y39: 20000 | Z39: 20000 | AA39: 10000 | AB39: 10000 | AC39: 150000 | AD39: 10000 | AE39: 0 | AF39: 0
B40: 명 수(누적) | C40: 10000 | D40: =E40-D39 -> 183000 | E40: =F40-E39 -> 226000 | F40: =G40-F39 -> 337000 | G40: =H40-G39 -> 538000 | H40: =I40-H39 -> 618000 | I40: =J40-I39 -> 645000 | J40: =K40-J39 -> 959000 | K40: =L40-K39 -> 1200000 | ... AF40: =AG40-AF39 -> 2780000 | AG40: 2780000 | AH40: =AG40 -> 2780000
B41: 조회수(월간) | D41: 9097769 | E41: 15848370 | F41: 42422017 | G41: 8438597 | H41: 5057746 | I41: 24431034 | J41: 22959013 | K41: 9778878 | L41: 23113151 | M41: 10057544 | N41: 7277968 | O41: 20791553 | P41: 10837835 | Q41: 24317352 | R41: 5733998 | S41: 8769789 | T41: 9400413 | U41: 6037993 | V41: 6132122 | W41: 6208959 | X41: 34906749 | Y41: 23820183 | Z41: 20497834 | AA41: 17078012 | AB41: 13158222 | AC41: 31028650 | AD41: 32056178 | AE41: 9974762 | AF41: 15503685 | AH41: =SUBTOTAL(9,C41:AG41) -> 474736376
B42: 인당 조회수 | D42: =D41/D40 -> 49.714585 | E42: =E41/E40 -> 70.125531 | F42: =F41/F40 -> 125.88136 | G42: =G41/G40 -> 15.685125 | H42: =H41/H40 -> 8.184055 | I42: =I41/I40 -> 37.877572 | J42: =J41/J40 -> 23.940577 | K42: =K41/K40 -> 8.149065 | ... AF42: =AF41/AF40 -> 5.5768651 | AH42: =AH41/AH40 -> 170.76848
B45: 피프티피프티 (데뷔 2022년 11월)
B47: 동영상 수 | C47: 276
B48: 업로드 수(월간) | C48: =C47/COUNTA(C50:AC50) -> 10.222222
B50: 구분 | C50: 44866 | D50: 44926 | E50: 44957 | F50: 44985 | G50: 45016 | H50: 45046 | I50: 45077 | J50: 45107 | K50: 45138 | L50: 45169 | M50: 45199 | N50: 45230 | O50: 45260 | P50: 45291 | Q50: 45322 | R50: 45351 | S50: 45382 | T50: 45412 | U50: 45443 | V50: 45473 | W50: 45504 | X50: 45535 | Y50: 45565 | Z50: 45596 | AA50: 45626 | AB50: 45657 | AC50: 45688 | AD50: 45716
B51: 명 수 | C51: 10000 | D51: 52500 | I51: 785000 | P51: 1590000 | Q51: 1610000 | AB51: 1880000 | AC51: 1900000
B54: 키스오브라이프/키오라 (데뷔 2023년 7월)
B56: 동영상 수 | C56: 1047
B57: 업로드 수(월간) | C57: =C56/COUNTA(C59:V59) -> 52.35
B59: 구분 | C59: 45078 | D59: 45108 | E59: =EOMONTH(D59,1) -> 45169 | F59: =EOMONTH(E59,1) -> 45199 | G59: =EOMONTH(F59,1) -> 45230 | H59: =EOMONTH(G59,1) -> 45260 | I59: =EOMONTH(H59,1) -> 45291 | J59: =EOMONTH(I59,1) -> 45322 | K59: =EOMONTH(J59,1) -> 45351 | L59: =EOMONTH(K59,1) -> 45382 | ... AG59: =EOMONTH(AF59,1) -> 46022
...

Sheet MD,팬클럽
B1: MD/팬클럽, 매출/비용
B2: Value analysis as of August 31, 2025
B3: KRW in millions
E4: 4 | F4: 5
B7: 4대 기획사 대표 그룹 굿즈 현황
C9: 하이브 | D9: SM | E9: YG | F9: JYP
B10: 가격 | C10: BTS | D10: NCT | E10: 블랙핑크 | F10: 트와이스
B11: 응원봉 | C11: 39000 | D11: 38000 | E11: 39000 | F11: 49000 | G11: 제작단가 (1만원)
B12: 앨범 | C12: 30465 | D12: 25554 | E12: 30465 | F12: 20421
B13: 포토북/포토 | C13: 27243 | D13: 14448 | E13: 21867 | F13: 24357
B14: 키링 | C14: 18689 | D14: 18091 | E14: 18667 | F14: 17350
B16: 평균(앨범 제외) | C16: =ROUND(AVERAGE(C11:F11,C13:F14),-3) -> 27000
B18: Source : https://www.newstomato.com/ReadNews.aspx?no=1217571
B21: 코어, 라이트 팬덤 연간 주요 활동 내용 및 예상 비용
B23: 구분 | C23: 주요 내용 | G23: 예상 비용
B24: 음원 | C24: 스트리밍 지원 | G24: 월 평균 6,900~8,900원
B25: 초동 음반 지원 | C25: 초동 음반 판매량 증진 위함 | G25: 1~100만원
B26: 팬사인회 | C26: 음반 구매를 통해 추첨권 획득 | G26: 걸그룹 30~200만원 (인기도에 따라 20장~150장 추정)
B27: 콘서트/팬미팅 | C27: 콘서트 연 2~4회, 팬미팅 연 1~2회 참여 | G27: 콘서트 평균 15.4만원, 팬미팅 평균 9.9만원
B28: MD | C28: 시즌 그리팅 및 공식 MD 등 | G28: 공식 MD 0.5~20만원
B29: 플랫폼 구독료 | C29: 버블, 위버스 | G29: 4,500원
B30: 팬클럽 가입 | C30: 위버스, JYP 등 연 평균 1회 가입 | G30: 위버스 2.2~3만원, JYP 3.5만원
B32: 월 환산 평균 예상 비용 | G32: 라이트 팬덤 : 월 9만원 미만
G33: 로얄 팬덤 : 월 18~150 만원
B35: Source : 대신증권 리포트_해가 지지 않는 팬덤

Sheet 걸그룹
B1: 걸그룹 성과지표
B2: Value analysis as of August 31, 2025
B3: KRW in millions
E4: 4 | G4: 5
D8: 에스파 | E8: 뉴진스 | F8: 엔믹스 | G8: 아일릿 | H8: 케플러 | I8: 트리플에스
B9: 구분 | C9: 데뷔일 | D9: 44152 | E9: 44764 | F9: 44614 | G9: 45010 | H9: 44564 | I9: 44939
C10: 소속사 | D10: SM | E10: HYBE | F10: JYP | G10: HYBE | H10: 웨이크원, 클렙 | I10: 모드하우스
C11: 데뷔 이후 기간 | D11: 4.0833333 | E11: 2.4166667 | F11: 2.8333333 | G11: 1.75 | H11: 2.9166667 | I11: 1.9166667
B12: 음반 | C12: 앨범 발매 횟수 | D12: 6 | E12: 5 | F12: 6 | G12: 2 | H12: 12 | I12: 9
C13: 앨범 판매량 | D13: =음반원!I11 -> 8744139 | E13: =음반원!I12 -> 6984036 | F13: =음반원!I13 -> 4317723 | G13: =음반원!I14 -> 1151999 | H13: =음반원!I15 -> 1651555 | I13: =음반원!I14 -> 1151999
C14: 뮤직비디오 조회수 | D14: 2105228350 | E14: 836531475 | F14: 608066452 | G14: 273077894 | H14: N/A | I14: 508643836
B15: 공연 | C15: 콘서트 | D15: 74 | E15: N/A | F15: 25 | G15: N/A | H15: 20 | I15: 27
C16: 공연장 규모 | D16: 8258.0645 | E16: N/A | F16: 1500 | G16: N/A | H16: 800 | I16: 1500
C17: 행사 | D17: 75 | E17: 30 | F17: 24 | G17: 21 | H17: N/A | I17: 108
C18: 행사 가격 (1회) | D18: 44230769 | E18: 44230769 | F18: 26538462 | G18: 26538462 | H18: 13269231 | I18: 13269231
C19: 콘서트 티켓 가격 (KRW) | D19: 154000 | E19: 140000 | F19: 110000 | G19: 110000 | H19: 130000 | I19: 110000
