Workbook

Sheet  Report
B2: 적용환율 : | C2: 1 USD k = | D2: =1131.6/10^3 -> 1.1316
B3: EV/EBIT, EV/EBITDA over 20x and P/E over 40x are presented as NM, and excluded from calculation of mean and median
B5: 1. LG-Hitachi Water Solutions
B6: 18A, LTM, 19E, 20E 적용 예정
C8: Share Price(USD) | F8: Maket Cap | G8: Enterprise Value | I8: EV/EBITDA | M8: P/E | Q8: P/B | R8: Gross Margin (18A) | S8: EBITDA (18A) | T8: Net Income (18A) | U8: PEG (16-18)
B9: (USD m) | C9: Latest | D9: 52W High | E9: 52W Low | I9: 16A | J9: 17A | K9: 18A | M9: 16A | N9: 17A | O9: 18A | Q9: 18A
B10: Korea
B11: 웰크론한텍 | C11: =Summary!C31/' Report'!$D$2/1000 -> 1.9823439 | D11: 3.2211029 | E11: 1.5243902 | F11: =Summary!E31/$D$2/1000 -> 38.383278 | G11: =(Summary!J31/' Report'!$D$2)/1000 -> 20.420831 | I11: =IF('2016'!T31>20,"NM",IF('2016'!T31<0,"NM",'2016'!T31)) -> NM | J11: =IF('2017'!T31>20,"NM",IF('2017'!T31<0,"NM",'2017'!T31)) -> 13.937054 | K11: =IF('2018'!T31>20,"NM",IF('2018'!T31<0,"NM",'2018'!T31)) -> 5.2391951 | M11: =IF('2016'!U31>40,"NM",IF('2016'!U31<0,"NM",'2016'!U31)) -> NM | N11: =IF('2017'!U31>40,"NM",IF('2017'!U31<0,"NM",'2017'!U31)) -> NM | O11: =IF('2018'!U31>40,"NM",IF('2018'!U31<0,"NM",'2018'!U31)) -> NM | Q11: ='2018'!Q31 -> 0.43368761 | R11: =12858.6784614705/D2/1000 -> 11.363272 | S11: ='2018'!O31/$D$2/1000 -> 3.8977039 | T11: ='2018'!P31/$D$2/1000 -> 0.21459593 | U11: =IFERROR(Summary!W31,"NM") -> NM
B12: 우원개발 | C12: =Summary!C33/' Report'!$D$2/1000 -> 4.4846505 | D12: 8.3863556 | E12: 2.7129728 | F12: =Summary!E33/$D$2/1000 -> 76.798191 | G12: =(Summary!J33/' Report'!$D$2)/1000 -> 31.218541 | I12: =IF('2016'!T33>20,"NM",IF('2016'!T33<0,"NM",'2016'!T33)) -> 3.6983242 | J12: =IF('2017'!T33>20,"NM",IF('2017'!T33<0,"NM",'2017'!T33)) -> 7.1005297 | K12: =IF('2018'!T33>20,"NM",IF('2018'!T33<0,"NM",'2018'!T33)) -> 12.843634 | M12: =IF('2016'!U33>40,"NM",IF('2016'!U33<0,"NM",'2016'!U33)) -> 9.971164 | N12: =IF('2017'!U33>40,"NM",IF('2017'!U33<0,"NM",'2017'!U33)) -> NM | O12: =IF('2018'!U33>40,"NM",IF('2018'!U33<0,"NM",'2018'!U33)) -> NM | Q12: ='2018'!Q33 -> 1.4041481 | R12: =20792.4304241782/D2/1000 -> 18.374364 | S12: ='2018'!O33/$D$2/1000 -> 2.4306627 | T12: ='2018'!P33/$D$2/1000 -> -1.2766374 | U12: =IFERROR(Summary!W33,"NM") -> NM
B13: Mean | I13: =AVERAGE(I11:I12) -> 3.6983242 | J13: =AVERAGE(J11:J12) -> 10.518792 | K13: =AVERAGE(K11:K12) -> 9.0414143 | M13: =AVERAGE(M11:M12) -> 9.971164 | N13: NM | O13: NM | Q13: =AVERAGE(Q11:Q12) -> 0.91891784
B14: Median | I14: =MEDIAN(I11:I12) -> 3.6983242 | J14: =MEDIAN(J11:J12) -> 10.518792 | K14: =MEDIAN(K11:K12) -> 9.0414143 | M14: =MEDIAN(M11:M12) -> 9.971164 | N14: NM | O14: NM | Q14: =MEDIAN(Q11:Q12) -> 0.91891784
B15: Global
B16: CITIC Envirotech Ltd | C16: 0.34738 | D16: 0.51988 | E16: 0.23828 | F16: ='Summary (2)'!D8/' Report'!$D$2/1000 -> 766.65718 | G16: ='Summary (2)'!I8/' Report'!D2/1000 -> 1631.9136 | I16: 11.372488 | J16: 12.285238 | K16: =G16/S16 -> 8.2493461 | M16: 26.240082 | N16: 16.81435 | O16: =F16/T16 -> 10.115953 | Q16: 0.9985181 | R16: 285.5 | S16: ='Summary (2)'!N8/' Report'!D2/1000 -> 197.82338 | T16: ='Summary (2)'!O8/' Report'!D2/1000 -> 75.786946 | U16: NM | W16: NM
B17: Nihon Trim Co Ltd | C17: 52.18019 | D17: 55.14467 | E17: 39.2999 | F17: ='Summary (2)'!D11/' Report'!$D$2/1000 -> 239.13749 | G17: ='Summary (2)'!I11/' Report'!$D$2/1000 -> 156.10708 | I17: 10.2 | J17: 16.283582 | K17: =G17/S17 -> 8.0392782 | M17: 22.2547 | N17: 38.960175 | O17: =F17/T17 -> 21.697585 | Q17: 2.9274951 | R17: 94.9 | S17: ='Summary (2)'!N11/' Report'!$D$2/1000 -> 19.418047 | T17: ='Summary (2)'!O11/' Report'!$D$2/1000 -> 11.021387 | U17: NM | W17: NM
B18: AECOM | C18: 29.67 | D18: 36.75 | E18: 24.92 | F18: ='Summary (2)'!D12/' Report'!$D$2/1000 -> 5527.7097 | G18: ='Summary (2)'!I12/' Report'!$D$2/1000 -> 8730.2977 | I18: 10.653434 | J18: 11.433953 | K18: =G18/S18 -> 10.376722 | M18: 33.787771 | N18: 14.055008 | O18: NM | Q18: 1.1357432 | R18: 685.1 | S18: ='Summary (2)'!N12/' Report'!$D$2/1000 -> 841.33484 | T18: ='Summary (2)'!O12/' Report'!$D$2/1000 -> 74.568785 | U18: NM | W18: 0.099242163
B19: Xylem Inc/NY | C19: 79.04 | D19: 81.3374 | E19: 61.1779 | F19: ='Summary (2)'!D13/' Report'!$D$2/1000 -> 4633.6774 | G19: ='Summary (2)'!I13/' Report'!$D$2/1000 -> 6730.1195 | I19: 16.649137 | J19: 18.428248 | K19: =G19/S19 -> 7.0493835 | M19: 34.707367 | N19: NM | O19: =F19/T19 -> 8.5753835 | Q19: 5.1271117 | R19: 2031 | S19: ='Summary (2)'!N13/' Report'!$D$2/1000 -> 954.71036 | T19: ='Summary (2)'!O13/' Report'!$D$2/1000 -> 540.34638 | U19: =O19/W19 -> 17.817191 | W19: 0.48129828
B20: Mean | I20: =AVERAGE(I16:I19) -> 12.218765 | J20: =AVERAGE(J16:J19) -> 14.607755 | K20: =AVERAGE(K16:K19) -> 8.4286824 | M20: =AVERAGE(M16:M19) -> 29.24748 | N20: =AVERAGE(N16:N19) -> 23.276511 | O20: =AVERAGE(O16:O19) -> 13.462974 | Q20: =AVERAGE(Q16:Q19) -> 2.547217
B21: Median | I21: =MEDIAN(I16:I19) -> 11.012961 | J21: =MEDIAN(J16:J19) -> 14.28441 | K21: =MEDIAN(K16:K19) -> 8.1443121 | M21: =MEDIAN(M16:M19) -> 30.013927 | N21: =MEDIAN(N16:N19) -> 16.81435 | O21: =MEDIAN(O16:O19) -> 10.115953 | Q21: =MEDIAN(Q16:Q19) -> 2.0316192
B23: Mean | I23: =AVERAGE(I16:I19,I11:I12) -> 10.514677 | J23: =AVERAGE(J16:J19,J11:J12) -> 13.244767 | K23: =AVERAGE(K16:K19,K11:K12) -> 8.6329264 | M23: =AVERAGE(M16:M19,M11:M12) -> 25.392217 | N23: =AVERAGE(N16:N19,N11:N12) -> 23.276511 | O23: =AVERAGE(O16:O19,O11:O12) -> 13.462974 | Q23: =AVERAGE(Q16:Q19,Q11:Q12) -> 2.0044506
B24: Median | I24: =MEDIAN(,I16:I19,I11:I12) -> 10.426717 | J24: =MEDIAN(,J16:J19,J11:J12) -> 12.285238 | K24: =MEDIAN(,K16:K19,K11:K12) -> 8.0392782 | M24: =MEDIAN(,M16:M19,M11:M12) -> 24.247391 | N24: =MEDIAN(,N16:N19,N11:N12) -> 15.434679 | O24: =MEDIAN(,O16:O19,O11:O12) -> 9.3456682 | Q24: =MEDIAN(,Q16:Q19,Q11:Q12) -> 1.1357432
B26: 한국거래소 기업공시채널 KIND 시스템 상 수도, 하수 및 폐기물 처리, 원료 재생업으로 등록된 상장회사로 조회함.
B27: 국내의 경우 한국거래소 기업공시채널 KIND 시스템 상 수도, 하수 및 폐기물 처리, 원료 재생업으로 등록된 상장회사로 조회하여, 산업상 유사성을 기준으로 선정함.
B28: 해외의 경우, FACTIVA Dow Jones Industry 분류상 "Water Utilities", "Water Treatment Plant Construction" 산업으로 조회함.
B30: 2. HiEntech
C32: Share Price(USD) | F32: Maket Cap | G32: Enterprise Value | I32: EV/EBITDA | M32: P/E | Q32: P/B | R32: Gross Margin (18A) | S32: EBITDA (18A) | T32: Net Income (18A) | U32: PEG (16-18)
B33: (USD m) | C33: Latest | D33: 52W High | E33: 52W Low | I33: 16A | J33: 17A | K33: 18A | M33: 16A | N33: 17A | O33: 18A | Q33: 18A
B34: Korea
B35: KOENTEC CO LTD | C35: =Summary!C9/' Report'!$D$2/1000 -> 6.9613447 | D35: 8.7751856 | E35: 4.5510781 | F35: =Summary!E9/$D$2/1000 -> 348.06723 | G35: =Summary!J9/' Report'!$D$2/1000 -> 287.08454 | I35: =IF('2016'!T9>20,"NM",IF('2016'!T9<0,"NM",'2016'!T9)) -> 6.2632297 | J35: =IF('2017'!T9>20,"NM",IF('2017'!T9<0,"NM",'2017'!T9)) -> 7.8230567 | K35: =IF('2018'!T9>20,"NM",IF('2018'!T9<0,"NM",'2018'!T9)) -> 8.2446291 | M35: =IF('2016'!U9>40,"NM",IF('2016'!U9<0,"NM",'2016'!U9)) -> 9.8045042 | N35: =IF('2017'!U9>40,"NM",IF('2017'!U9<0,"NM",'2017'!U9)) -> 15.709858 | O35: =IF('2018'!U9>40,"NM",IF('2018'!U9<0,"NM",'2018'!U9)) -> 16.08353 | Q35: =Summary!Q9 -> 2.6490179 | R35: 30.039675 | S35: =(Summary!O9/$D$2)/1000 -> 34.820795 | T35: =(Summary!P9/$D$2)/1000 -> 21.641221 | U35: =O35/W35 -> 55.485763 | W35: =Summary!W9 -> 0.28986769
B36: INSUN ENT CO LTD | C36: =Summary!C10/' Report'!$D$2/1000 -> 6.1826363 | D36: 7.6882291 | E36: 4.7720042 | F36: =Summary!E10/$D$2/1000 -> 226.31567 | G36: =Summary!J10/' Report'!$D$2/1000 -> 284.13717 | I36: =IF('2016'!T10>20,"NM",IF('2016'!T10<0,"NM",'2016'!T10)) -> 12.74856 | J36: =IF('2017'!T10>20,"NM",IF('2017'!T10<0,"NM",'2017'!T10)) -> 12.481963 | K36: =IF('2018'!T10>20,"NM",IF('2018'!T10<0,"NM",'2018'!T10)) -> 10.606944 | M36: =IF('2016'!U10>40,"NM",IF('2016'!U10<0,"NM",'2016'!U10)) -> 29.097275 | N36: =IF('2017'!U10>40,"NM",IF('2017'!U10<0,"NM",'2017'!U10)) -> NM | O36: =IF('2018'!U10>40,"NM",IF('2018'!U10<0,"NM",'2018'!U10)) -> 12.827476 | Q36: =Summary!Q10 -> 1.3699514 | R36: 35.754921 | S36: =(Summary!O10/$D$2)/1000 -> 26.787845 | T36: =(Summary!P10/$D$2)/1000 -> 17.643039 | U36: =O36/W36 -> 21.735305 | W36: =Summary!W10 -> 0.59016774
B37: Mean | I37: =AVERAGE(I35:I36) -> 9.5058947 | J37: =AVERAGE(J35:J36) -> 10.15251 | K37: =AVERAGE(K35:K36) -> 9.4257866 | M37: =AVERAGE(M35:M36) -> 19.45089 | N37: =AVERAGE(N35:N36) -> 15.709858 | O37: =AVERAGE(O35:O36) -> 14.455503 | Q37: =AVERAGE(Q35:Q36) -> 2.0094847 | W37: =AVERAGE(W35:W36) -> 0.44001772 | X37: 12배~14배
B38: Median | I38: =MEDIAN(I35:I36) -> 9.5058947 | J38: =MEDIAN(J35:J36) -> 10.15251 | K38: =MEDIAN(K35:K36) -> 9.4257866 | M38: =MEDIAN(M35:M36) -> 19.45089 | N38: =MEDIAN(N35:N36) -> 15.709858 | O38: =MEDIAN(O35:O36) -> 14.455503 | Q38: =MEDIAN(Q35:Q36) -> 2.0094847 | W38: =MEDIAN(W35:W36) -> 0.44001772
B40: Global
B41: Beijing Enterprises Water Group Ltd | C41: 0.61784 | D41: 0.63059 | E41: 0.46067 | F41: ='Summary (2)'!D32/' Report'!$D$2/1000 -> 5494.1125 | G41: ='Summary (2)'!I32/' Report'!$D$2/1000 -> 11342.377 | I41: 16.896862 | J41: 15.288163 | K41: =G41/S41 -> 11.469971 | M41: 15.485728 | N41: 10.232948 | O41: =F41/T41 -> 9.3858368 | Q41: 1.9049761 | R41: 1118 | S41: ='Summary (2)'!N32/' Report'!$D$2/1000 -> 988.8759 | T41: ='Summary (2)'!O32/' Report'!$D$2/1000 -> 585.36203 | U41: =O41/W41 -> 98.337529 | W41: 0.095445115
B42: American Water Works Co Inc | C42: 103.7695 | D42: 106.6957 | E42: 76.8206 | F42: ='Summary (2)'!D34/' Report'!$D$2/1000 -> 17606.045 | G42: ='Summary (2)'!I34/' Report'!$D$2/1000 -> 25951.465 | I42: 12.591589 | J42: 12.911896 | K42: =G42/S42 -> 16.171985 | M42: 29.53378 | N42: 34.324697 | O42: =F42/T42 -> 31.927442 | Q42: 3.2094277 | R42: 1941 | S42: ='Summary (2)'!N34/' Report'!$D$2/1000 -> 1604.7174 | T42: ='Summary (2)'!O34/' Report'!$D$2/1000 -> 551.43924 | U42: NM | W42: 0.087270037
B43: Severn Trent PLC | C43: 25.67417 | D43: 27.53318 | E43: 22.36926 | F43: ='Summary (2)'!D35/' Report'!D2/1000 -> 6076.1532 | G43: ='Summary (2)'!I35/' Report'!D2/1000 -> 13227.529 | I43: 12.695226 | J43: 12.57197 | K43: =G43/S43 -> 11.701069 | M43: 16.132538 | N43: 18.901348 | O43: =F43/T43 -> 18.39305 | Q43: 4.2850393 | R43: 1712.2 | S43: ='Summary (2)'!N35/' Report'!$D$2/1000 -> 1130.4547 | T43: ='Summary (2)'!O35/' Report'!$D$2/1000 -> 330.3505 | U43: NM | W43: NM
B44: Mean | I44: =AVERAGE(I41:I43) -> 14.061226 | J44: =AVERAGE(J41:J43) -> 13.590677 | K44: =AVERAGE(K41:K43) -> 13.114342 | M44: =AVERAGE(M41:M43) -> 20.384015 | N44: =AVERAGE(N41:N43) -> 21.152998 | O44: =AVERAGE(O41:O43) -> 19.90211 | Q44: =AVERAGE(Q41:Q43) -> 3.1331477
B45: Median | I45: =MEDIAN(I41:I43) -> 12.695226 | J45: =MEDIAN(J41:J43) -> 12.911896 | K45: =MEDIAN(K41:K43) -> 11.701069 | M45: =MEDIAN(M41:M43) -> 16.132538 | N45: =MEDIAN(N41:N43) -> 18.901348 | O45: =MEDIAN(O41:O43) -> 18.39305 | Q45: =MEDIAN(Q41:Q43) -> 3.2094277
B47: Mean | I47: =AVERAGE(I35:I36,I41:I43) -> 12.239093 | J47: =AVERAGE(J35:J36,J41:J43) -> 12.21541 | K47: =AVERAGE(K35:K36,K41:K43) -> 11.63892 | M47: =AVERAGE(M35:M36,M41:M43) -> 20.010765 | N47: =AVERAGE(N35:N36,N41:N43) -> 19.792213 | O47: =AVERAGE(O35:O36,O41:O43) -> 17.723467 | Q47: =AVERAGE(Q35:Q36,Q41:Q43) -> 2.6836825
B48: Median | I48: =MEDIAN(I35:I36,I41:I43) -> 12.695226 | J48: =MEDIAN(J35:J36,J41:J43) -> 12.57197 | K48: =MEDIAN(K35:K36,K41:K43) -> 11.469971 | M48: =MEDIAN(M35:M36,M41:M43) -> 16.132538 | N48: =MEDIAN(N35:N36,N41:N43) -> 17.305603 | O48: =MEDIAN(O35:O36,O41:O43) -> 16.08353 | Q48: =MEDIAN(Q35:Q36,Q41:Q43) -> 2.6490179
B50: 국내의 경우 한국거래소 기업공시채널 KIND 시스템 상 주요 제품을 '건설업' 으로 조회하여, 산업상 유사성(수처리 건설업)을 기준으로 선정함.

Sheet Summary (2)
B1: Project AII
B2: Trading Multiple - 해외
A5: 1 | B5: 1. LG-Hitachi Water Solutions
B6: Guideline Public Company | C6: Country | D6: MKT Cap[1] (백만원) | E6: Debt | F6: Cash[2] | G6: NOA[3] | H6: Accumulated Minority Interest | I6: Enterprise Value | J6: LTM[4] | P6: Multiples
I7: of Equity(MM) | J7: BV | K7: Sales | L7: EBIT | M7: Dep. | N7: EBITDA | O7: Net Income | P7: PBR | Q7: EV/Sales | R7: EV/EBIT | S7: EV/EBITDA | T7: PER
A8: =INDEX([59]GPCM!$D$6:$D$24,MATCH(B8,[59]GPCM!$B$6:$B$24,0)) -> 1 | B8: CITIC Envirotech Ltd | C8: SINGAPORE | D8: =[59]GPCM!G7 -> 867549.26 | E8: =[59]유사BS!F5 -> 1130433.2 | F8: =[59]유사BS!G5 -> 307600.81 | G8: =[59]유사BS!E5-[59]유사BS!G5 -> 0 | H8: =[59]GPCM!I7 -> 156291.71 | I8: =D8+E8-F8-G8+H8 -> 1846673.4 | J8: =[59]GPCM!K7 -> 1122584.7 | K8: =[59]GPCM!L7 -> 811157.49 | L8: =[59]GPCM!M7 -> 192015.58 | M8: =[59]GPCM!N7 -> 31841.365 | N8: =[59]GPCM!O7 -> 223856.94 | O8: =[59]GPCM!P7 -> 85760.509 | P8: =IFERROR(IF(OR(ISERROR(D8/J8),D8/J8<0),"n.a.",D8/J8),"") -> 0.77281405 | Q8: =IFERROR(IF(OR(ISERROR(I8/K8),I8/K8<0),"n.a.",I8/K8),"") -> 2.2765904 | R8: =IFERROR(IF(OR(ISERROR(I8/L8),I8/L8<0),"n.a.",I8/L8),"") -> 9.6173103 | S8: =IFERROR(IF(OR(ISERROR(I8/N8),I8/N8<0),"n.a.",I8/N8),"") -> 8.2493461 | T8: =IFERROR(IF(OR(ISERROR(D8/O8),D8/O8<0),"n.a.",D8/O8),"") -> 10.115953
A9: =INDEX([59]GPCM!$D$6:$D$24,MATCH(B9,[59]GPCM!$B$6:$B$24,0)) -> 1 | B9: Kurita Water Industries Ltd | C9: JAPAN | D9: =[59]GPCM!G14 -> 3300191.4 | E9: =[59]유사BS!F12 -> 0 | F9: =[59]유사BS!G12 -> 745430.26 | G9: =[59]유사BS!E12-[59]유사BS!G12 -> 203348.09 | H9: =[59]GPCM!I14 -> 18754.815 | I9: =D9+E9-F9-G9+H9 -> 2370167.8 | J9: =[59]GPCM!K14 -> 2383953.2 | K9: =[59]GPCM!L14 -> 2661159.3 | L9: =[59]GPCM!M14 -> 247881.36 | M9: =[59]GPCM!N14 -> 184239.24 | N9: =[59]GPCM!O14 -> 432120.6 | O9: =[59]GPCM!P14 -> 172310.08 | P9: =IFERROR(IF(OR(ISERROR(D9/J9),D9/J9<0),"n.a.",D9/J9),"") -> 1.3843356 | Q9: =IFERROR(IF(OR(ISERROR(I9/K9),I9/K9<0),"n.a.",I9/K9),"") -> 0.89065237 | R9: =IFERROR(IF(OR(ISERROR(I9/L9),I9/L9<0),"n.a.",I9/L9),"") -> 9.5617027 | S9: =IFERROR(IF(OR(ISERROR(I9/N9),I9/N9<0),"n.a.",I9/N9),"") -> 5.4849684 | T9: =IFERROR(IF(OR(ISERROR(D9/O9),D9/O9<0),"n.a.",D9/O9),"") -> 19.152631
A10: =INDEX([59]GPCM!$D$6:$D$24,MATCH(B10,[59]GPCM!$B$6:$B$24,0)) -> 1 | B10: Organo Corp | C10: JAPAN | D10: =[59]GPCM!G16 -> 340896.22 | E10: =[59]유사BS!F15 -> 186553.03 | F10: =[59]유사BS!G15 -> 100191.53 | G10: =[59]유사BS!E15-[59]유사BS!G15 -> 16104.567 | H10: =[59]GPCM!I16 -> 1177.8877 | I10: =D10+E10-F10-G10+H10 -> 412331.05 | J10: =[59]GPCM!K16 -> 531887.35 | K10: =[59]GPCM!L16 -> 903197.83 | L10: =[59]GPCM!M16 -> 60383.273 | M10: =[59]GPCM!N16 -> 8939.3952 | N10: =[59]GPCM!O16 -> 69322.668 | O10: =[59]GPCM!P16 -> 41667.348 | P10: =IFERROR(IF(OR(ISERROR(D10/J10),D10/J10<0),"n.a.",D10/J10),"") -> 0.64091808 | Q10: =IFERROR(IF(OR(ISERROR(I10/K10),I10/K10<0),"n.a.",I10/K10),"") -> 0.45652352 | R10: =IFERROR(IF(OR(ISERROR(I10/L10),I10/L10<0),"n.a.",I10/L10),"") -> 6.8285641 | S10: =IFERROR(IF(OR(ISERROR(I10/N10),I10/N10<0),"n.a.",I10/N10),"") -> 5.9479974 | T10: =IFERROR(IF(OR(ISERROR(D10/O10),D10/O10<0),"n.a.",D10/O10),"") -> 8.1813755
A11: =INDEX([59]GPCM!$D$6:$D$24,MATCH(B11,[59]GPCM!$B$6:$B$24,0)) -> 1 | B11: Nihon Trim Co Ltd | C11: JAPAN | D11: =[59]GPCM!G19 -> 270607.98 | E11: =[59]유사BS!F18 -> 15323.486 | F11: =[59]유사BS!G18 -> 112303.89 | G11: =[59]유사BS!E18-[59]유사BS!G18 -> 0 | H11: =[59]GPCM!I19 -> 3023.201 | I11: =D11+E11-F11-G11+H11 -> 176650.77 | J11: =[59]GPCM!K19 -> 175259.99 | K11: =[59]GPCM!L19 -> 150260.11 | L11: =[59]GPCM!M19 -> 19501.694 | M11: =[59]GPCM!N19 -> 2471.7677 | N11: =[59]GPCM!O19 -> 21973.462 | O11: =[59]GPCM!P19 -> 12471.802 | P11: =IFERROR(IF(OR(ISERROR(D11/J11),D11/J11<0),"n.a.",D11/J11),"") -> 1.5440374 | Q11: =IFERROR(IF(OR(ISERROR(I11/K11),I11/K11<0),"n.a.",I11/K11),"") -> 1.1756332 | R11: =IFERROR(IF(OR(ISERROR(I11/L11),I11/L11<0),"n.a.",I11/L11),"") -> 9.058227 | S11: =IFERROR(IF(OR(ISERROR(I11/N11),I11/N11<0),"n.a.",I11/N11),"") -> 8.0392782 | T11: =IFERROR(IF(OR(ISERROR(D11/O11),D11/O11<0),"n.a.",D11/O11),"") -> 21.697585
A12: =INDEX([59]GPCM!$D$6:$D$24,MATCH(B12,[59]GPCM!$B$6:$B$24,0)) -> 1 | B12: AECOM | C12: UNITED STATES | D12: =[59]GPCM!G21 -> 6255156.2 | E12: =[59]유사BS!F20 -> 4365282.1 | F12: =[59]유사BS!G20 -> 933457.66 | G12: =[59]유사BS!E20-[59]유사BS!G20 -> 0 | H12: =[59]GPCM!I21 -> 192224.12 | I12: =D12+E12-F12-G12+H12 -> 9879204.8 | J12: =[59]GPCM!K21 -> 4732895.2 | K12: =[59]GPCM!L21 -> 22321433 | L12: =[59]GPCM!M21 -> 657224.17 | M12: =[59]GPCM!N21 -> 294830.33 | N12: =[59]GPCM!O21 -> 952054.5 | O12: =[59]GPCM!P21 -> 84382.037 | P12: =IFERROR(IF(OR(ISERROR(D12/J12),D12/J12<0),"n.a.",D12/J12),"") -> 1.3216342 | Q12: =IFERROR(IF(OR(ISERROR(I12/K12),I12/K12<0),"n.a.",I12/K12),"") -> 0.44258829 | R12: =IFERROR(IF(OR(ISERROR(I12/L12),I12/L12<0),"n.a.",I12/L12),"") -> 15.031712 | S12: =IFERROR(IF(OR(ISERROR(I12/N12),I12/N12<0),"n.a.",I12/N12),"") -> 10.376722 | T12: =IFERROR(IF(OR(ISERROR(D12/O12),D12/O12<0),"n.a.",D12/O12),"") -> 74.129003
A13: =INDEX([59]GPCM!$D$6:$D$24,MATCH(B13,[59]GPCM!$B$6:$B$24,0)) -> 1 | B13: Xylem Inc/NY | C13: UNITED STATES | D13: =[59]GPCM!G22 -> 5243469.4 | E13: =[59]유사BS!F21 -> 2671577.9 | F13: =[59]유사BS!G21 -> 312897.75 | G13: =[59]유사BS!E21-[59]유사BS!G21 -> 0 | H13: =[59]GPCM!I22 -> 13653.72 | I13: =D13+E13-F13-G13+H13 -> 7615803.2 | J13: =[59]GPCM!K22 -> 3194970.5 | K13: =[59]GPCM!L22 -> 5821639.9 | L13: =[59]GPCM!M22 -> 792999.35 | M13: =[59]GPCM!N22 -> 287350.89 | N13: =[59]GPCM!O22 -> 1080350.2 | O13: =[59]GPCM!P22 -> 611455.96 | P13: =IFERROR(IF(OR(ISERROR(D13/J13),D13/J13<0),"n.a.",D13/J13),"") -> 1.6411636 | Q13: =IFERROR(IF(OR(ISERROR(I13/K13),I13/K13<0),"n.a.",I13/K13),"") -> 1.3081886 | R13: =IFERROR(IF(OR(ISERROR(I13/L13),I13/L13<0),"n.a.",I13/L13),"") -> 9.603795 | S13: =IFERROR(IF(OR(ISERROR(I13/N13),I13/N13<0),"n.a.",I13/N13),"") -> 7.0493835 | T13: =IFERROR(IF(OR(ISERROR(D13/O13),D13/O13<0),"n.a.",D13/O13),"") -> 8.5753835
B16: 주요가정 Summary | M16: 1 | N16: Guideline Public Company Method
B17: [1] MKT Cap : 2019년 3월 31일 기준 3개월 평균 주가 | N17: Multiples | P17: PBR | Q17: EV/Sales | R17: EV/EBIT | S17: EV/EBITDA | T17: PER
B18: [2] Cash : 현금및현금성자산 및 단기금융상품 | N18: Min | P18: =MIN(P8:P14) -> 0.64091808 | Q18: =MIN(Q8:Q14) -> 0.44258829 | R18: =MIN(R8:R14) -> 6.8285641 | S18: =MIN(S8:S14) -> 5.4849684 | T18: =MIN(T8:T14) -> 8.1813755
B19: [3] NOA : 투자자산 | N19: Median | P19: =MEDIAN(P8:P14) -> 1.3529849 | Q19: =MEDIAN(Q8:Q14) -> 1.0331428 | R19: =MEDIAN(R8:R14) -> 9.5827488 | S19: =MEDIAN(S8:S14) -> 7.5443309 | T19: =MEDIAN(T8:T14) -> 14.634292
B20: [4] LTM : 국가별 회계보고일 차이로 대상시점에서 일부차이가 있으며 가장 최신 수치를 반영 | N20: Average | P20: =AVERAGE(P8:P14) -> 1.2174838 | Q20: =AVERAGE(Q8:Q14) -> 1.0916961 | R20: =AVERAGE(R8:R14) -> 9.9502186 | S20: =AVERAGE(S8:S14) -> 7.5246159 | T20: =AVERAGE(T8:T14) -> 23.641988
N21: Max | P21: =MAX(P8:P14) -> 1.6411636 | Q21: =MAX(Q8:Q14) -> 2.2765904 | R21: =MAX(R8:R14) -> 15.031712 | S21: =MAX(S8:S14) -> 10.376722 | T21: =MAX(T8:T14) -> 74.129003
B22: 비교 대상기업의 선정
B23: 1. FACTIVA Dow Jones Industry 분류상 "Water Utilities", "Water Treatment Plant Construction" 산업으로 조회함.
B24: 2. 대상회사는 하수 및 폐수 처리 설비의 설계 및 건축을 주업으로 하는 회사이므로 이와 사업구조가 유사한 회사를 선정
B25: 3. Valuation상 평균 범위대비 이상치(Outliar)에 해당될 수 있는 경우 제외
B28: 2. HiEntech
B29: Guideline Public Company | C29: Country | D29: MKT Cap[1] (백만원) | E29: Debt | F29: Cash[2] | G29: NOA[3] | H29: Accumulated Minority Interest | I29: Enterprise Value | J29: LTM[4] | P29: Multiples
I30: of Equity(MM) | J30: BV | K30: Sales | L30: EBIT | M30: Dep. | N30: EBITDA | O30: Net Income | P30: PBR | Q30: EV/Sales | R30: EV/EBIT | S30: EV/EBITDA | T30: PER
A31: =INDEX([59]GPCM!$D$6:$D$24,MATCH(B31,[59]GPCM!$B$6:$B$24,0)) -> 2 | B31: Kangda International Environmental Co Ltd | C31: =[59]GPCM!E6 -> CHINA | D31: =[59]GPCM!G6 -> 299265.99 | E31: =[59]유사BS!F3 -> 1483794.2 | F31: =[59]유사BS!G3 -> 207448.93 | G31: =[59]유사BS!E3-[59]유사BS!G3 -> 0 | H31: =[59]GPCM!I6 -> 34652.726 | I31: =D31+E31-F31-G31+H31 -> 1610264 | J31: =[59]GPCM!K6 -> 709095.67 | K31: =[59]GPCM!L6 -> 517266.08 | L31: =[59]GPCM!M6 -> 159358.14 | M31: =[59]GPCM!N6 -> 7881.652 | N31: =[59]GPCM!O6 -> 167239.79 | O31: =[59]GPCM!P6 -> 71152.996 | P31: =IFERROR(IF(OR(ISERROR(D31/J31),D31/J31<0),"n.a.",D31/J31),"") -> 0.42203895 | Q31: =IFERROR(IF(OR(ISERROR(I31/K31),I31/K31<0),"n.a.",I31/K31),"") -> 3.1130284 | R31: =IFERROR(IF(OR(ISERROR(I31/L31),I31/L31<0),"n.a.",I31/L31),"") -> 10.104686 | S31: =IFERROR(IF(OR(ISERROR(I31/N31),I31/N31<0),"n.a.",I31/N31),"") -> 9.6284737 | T31: =IFERROR(IF(OR(ISERROR(D31/O31),D31/O31<0),"n.a.",D31/O31),"") -> 4.2059507
A32: =INDEX([59]GPCM!$D$6:$D$24,MATCH(B32,[59]GPCM!$B$6:$B$24,0)) -> 2 | B32: Beijing Enterprises Water Group Ltd | C32: HONG KONG | D32: =[59]GPCM!G9 -> 6217137.7 | E32: =[59]유사BS!F7 -> 7965529.5 | F32: =[59]유사BS!G7 -> 1839355.4 | G32: =[59]유사BS!E7-[59]유사BS!G7 -> 357278.73 | H32: =[59]GPCM!I9 -> 849001.26 | I32: =D32+E32-F32-G32+H32 -> 12835034 | J32: =[59]GPCM!K9 -> 5375781.1 | K32: =[59]GPCM!L9 -> 3453867.9 | L32: =[59]GPCM!M9 -> 1047285.9 | M32: =[59]GPCM!N9 -> 71726.064 | N32: =[59]GPCM!O9 -> 1119012 | O32: =[59]GPCM!P9 -> 662395.67 | P32: =IFERROR(IF(OR(ISERROR(D32/J32),D32/J32<0),"n.a.",D32/J32),"") -> 1.1565087 | Q32: =IFERROR(IF(OR(ISERROR(I32/K32),I32/K32<0),"n.a.",I32/K32),"") -> 3.7161335 | R32: =IFERROR(IF(OR(ISERROR(I32/L32),I32/L32<0),"n.a.",I32/L32),"") -> 12.255521 | S32: =IFERROR(IF(OR(ISERROR(I32/N32),I32/N32<0),"n.a.",I32/N32),"") -> 11.469971 | T32: =IFERROR(IF(OR(ISERROR(D32/O32),D32/O32<0),"n.a.",D32/O32),"") -> 9.3858368
A33: =INDEX([59]GPCM!$D$6:$D$24,MATCH(B33,[59]GPCM!$B$6:$B$24,0)) -> 2 | B33: Jiangxi Hongcheng Waterworks Co Ltd | C33: CHINA | D33: =[59]GPCM!G10 -> 759700.32 | E33: =[59]유사BS!F8 -> 633186.33 | F33: =[59]유사BS!G8 -> 275720.1 | G33: =[59]유사BS!E8-[59]유사BS!G8 -> 0 | H33: =[59]GPCM!I10 -> 57467.286 | I33: =D33+E33-F33-G33+H33 -> 1174633.8 | J33: =[59]GPCM!K10 -> 678998.58 | K33: =[59]GPCM!L10 -> 763157.87 | L33: =[59]GPCM!M10 -> 118122.02 | M33: =[59]GPCM!N10 -> 0 | N33: =[59]GPCM!O10 -> 118122.02 | O33: =[59]GPCM!P10 -> 62173.936 | P33: =IFERROR(IF(OR(ISERROR(D33/J33),D33/J33<0),"n.a.",D33/J33),"") -> 1.1188541 | Q33: =IFERROR(IF(OR(ISERROR(I33/K33),I33/K33<0),"n.a.",I33/K33),"") -> 1.5391754 | R33: =IFERROR(IF(OR(ISERROR(I33/L33),I33/L33<0),"n.a.",I33/L33),"") -> 9.9442412 | S33: =IFERROR(IF(OR(ISERROR(I33/N33),I33/N33<0),"n.a.",I33/N33),"") -> 9.9442412 | T33: =IFERROR(IF(OR(ISERROR(D33/O33),D33/O33<0),"n.a.",D33/O33),"") -> 12.218952
A34: =INDEX([59]GPCM!$D$6:$D$24,MATCH(B34,[59]GPCM!$B$6:$B$24,0)) -> 2 | B34: American Water Works Co Inc | C34: UNITED STATES | D34: =[59]GPCM!G12 -> 19923000 | E34: =[59]유사BS!F10 -> 9588434.6 | F34: =[59]유사BS!G10 -> 144756.3 | G34: =[59]유사BS!E10-[59]유사BS!G10 -> 0 | H34: =[59]GPCM!I12 -> 0 | I34: =D34+E34-F34-G34+H34 -> 29366678 | J34: =[59]GPCM!K12 -> 6529622.6 | K34: =[59]GPCM!L12 -> 3785872.6 | L34: =[59]GPCM!M12 -> 1216101.5 | M34: =[59]GPCM!N12 -> 599796.67 | N34: =[59]GPCM!O12 -> 1815898.2 | O34: =[59]GPCM!P12 -> 624008.65 | P34: =IFERROR(IF(OR(ISERROR(D34/J34),D34/J34<0),"n.a.",D34/J34),"") -> 3.0511717 | Q34: =IFERROR(IF(OR(ISERROR(I34/K34),I34/K34<0),"n.a.",I34/K34),"") -> 7.7569115 | R34: =IFERROR(IF(OR(ISERROR(I34/L34),I34/L34<0),"n.a.",I34/L34),"") -> 24.148213 | S34: =IFERROR(IF(OR(ISERROR(I34/N34),I34/N34<0),"n.a.",I34/N34),"") -> 16.171985 | T34: =IFERROR(IF(OR(ISERROR(D34/O34),D34/O34<0),"n.a.",D34/O34),"") -> 31.927442
A35: =INDEX([59]GPCM!$D$6:$D$24,MATCH(B35,[59]GPCM!$B$6:$B$24,0)) -> 2 | B35: Severn Trent PLC | C35: BRITAIN | D35: =[59]GPCM!G13 -> 6875775 | E35: =[59]유사BS!F11 -> 8212351.7 | F35: =[59]유사BS!G11 -> 119854.53 | G35: =[59]유사BS!E11-[59]유사BS!G11 -> 0 | H35: =[59]GPCM!I13 -> 0 | I35: =D35+E35-F35-G35+H35 -> 14968272 | J35: =[59]GPCM!K13 -> 1615285.9 | K35: =[59]GPCM!L13 -> 2541064.8 | L35: =[59]GPCM!M13 -> 782704.52 | M35: =[59]GPCM!N13 -> 496518.05 | N35: =[59]GPCM!O13 -> 1279222.6 | O35: =[59]GPCM!P13 -> 373824.63 | P35: =IFERROR(IF(OR(ISERROR(D35/J35),D35/J35<0),"n.a.",D35/J35),"") -> 4.2566922 | Q35: =IFERROR(IF(OR(ISERROR(I35/K35),I35/K35<0),"n.a.",I35/K35),"") -> 5.8905511 | R35: =IFERROR(IF(OR(ISERROR(I35/L35),I35/L35<0),"n.a.",I35/L35),"") -> 19.123784 | S35: =IFERROR(IF(OR(ISERROR(I35/N35),I35/N35<0),"n.a.",I35/N35),"") -> 11.701069 | T35: =IFERROR(IF(OR(ISERROR(D35/O35),D35/O35<0),"n.a.",D35/O35),"") -> 18.39305
A36: =INDEX([59]GPCM!$D$6:$D$24,MATCH(B36,[59]GPCM!$B$6:$B$24,0)) -> 2 | B36: Yunnan Water Investment Co Ltd | C36: CHINA | D36: =[59]GPCM!G15 -> 390245.17 | E36: =[59]유사BS!F14 -> 2504288.7 | F36: =[59]유사BS!G14 -> 338279.28 | G36: =[59]유사BS!E14-[59]유사BS!G14 -> 5217.0112 | H36: =[59]GPCM!I15 -> 161412.7 | I36: =D36+E36-F36-G36+H36 -> 2712450.3 | J36: =[59]GPCM!K15 -> 1096014.9 | K36: =[59]GPCM!L15 -> 997344.86 | L36: =[59]GPCM!M15 -> 201577.76 | M36: =[59]GPCM!N15 -> 98306.742 | N36: =[59]GPCM!O15 -> 299884.5 | O36: =[59]GPCM!P15 -> 83324.276 | P36: =IFERROR(IF(OR(ISERROR(D36/J36),D36/J36<0),"n.a.",D36/J36),"") -> 0.35605827 | Q36: =IFERROR(IF(OR(ISERROR(I36/K36),I36/K36<0),"n.a.",I36/K36),"") -> 2.7196714 | R36: =IFERROR(IF(OR(ISERROR(I36/L36),I36/L36<0),"n.a.",I36/L36),"") -> 13.456099 | S36: =IFERROR(IF(OR(ISERROR(I36/N36),I36/N36<0),"n.a.",I36/N36),"") -> 9.0449834 | T36: =IFERROR(IF(OR(ISERROR(D36/O36),D36/O36<0),"n.a.",D36/O36),"") -> 4.683451
A37: =INDEX([59]GPCM!$D$6:$D$24,MATCH(B37,[59]GPCM!$B$6:$B$24,0)) -> 2 | B37: Guangxi Nanning Waterworks Co Ltd | C37: CHINA | D37: =[59]GPCM!G17 -> 761285.92 | E37: =[59]유사BS!F16 -> 686243.56 | F37: =[59]유사BS!G16 -> 180679.74 | G37: =[59]유사BS!E16-[59]유사BS!G16 -> 0 | H37: =[59]GPCM!I17 -> 0 | I37: =D37+E37-F37-G37+H37 -> 1266849.7 | J37: =[59]GPCM!K17 -> 524911.57 | K37: =[59]GPCM!L17 -> 218552.63 | L37: =[59]GPCM!M17 -> 80478.121 | M37: =[59]GPCM!N17 -> 0 | N37: =[59]GPCM!O17 -> 80478.121 | O37: =[59]GPCM!P17 -> 46458.431 | P37: =IFERROR(IF(OR(ISERROR(D37/J37),D37/J37<0),"n.a.",D37/J37),"") -> 1.4503127 | Q37: =IFERROR(IF(OR(ISERROR(I37/K37),I37/K37<0),"n.a.",I37/K37),"") -> 5.7965432 | R37: =IFERROR(IF(OR(ISERROR(I37/L37),I37/L37<0),"n.a.",I37/L37),"") -> 15.741542 | S37: =IFERROR(IF(OR(ISERROR(I37/N37),I37/N37<0),"n.a.",I37/N37),"") -> 15.741542 | T37: =IFERROR(IF(OR(ISERROR(D37/O37),D37/O37<0),"n.a.",D37/O37),"") -> 16.386389
B40: 주요가정 Summary | M40: 1 | N40: Guideline Public Company Method
B41: [1] MKT Cap : 2019년 3월 31일 기준 3개월 평균 주가 | N41: Multiples | P41: PBR | Q41: EV/Sales | R41: EV/EBIT | S41: EV/EBITDA | T41: PER
B42: [2] Cash : 현금및현금성자산 및 단기금융상품 | N42: Min | P42: =MIN(P31:P38) -> 0.35605827 | Q42: =MIN(Q31:Q38) -> 1.5391754 | R42: =MIN(R31:R38) -> 9.9442412 | S42: =MIN(S31:S38) -> 9.0449834 | T42: =MIN(T31:T38) -> 4.2059507
B43: [3] NOA : 투자자산 | N43: Median | P43: =MEDIAN(P31:P38) -> 1.1565087 | Q43: =MEDIAN(Q31:Q38) -> 3.7161335 | R43: =MEDIAN(R31:R38) -> 13.456099 | S43: =MEDIAN(S31:S38) -> 11.469971 | T43: =MEDIAN(T31:T38) -> 12.218952
B44: [4] LTM : 국가별 회계보고일 차이로 대상시점에서 일부차이가 있으며 가장 최신 수치를 반영 | N44: Average | P44: =AVERAGE(P31:P38) -> 1.6873767 | Q44: =AVERAGE(Q31:Q38) -> 4.3617164 | R44: =AVERAGE(R31:R38) -> 14.967727 | S44: =AVERAGE(S31:S38) -> 11.957467 | T44: =AVERAGE(T31:T38) -> 13.885867
N45: Max | P45: =MAX(P31:P38) -> 4.2566922 | Q45: =MAX(Q31:Q38) -> 7.7569115 | R45: =MAX(R31:R38) -> 24.148213 | S45: =MAX(S31:S38) -> 16.171985 | T45: =MAX(T31:T38) -> 31.927442
B46: 비교 대상기업의 선정
B47: 1. FACTIVA Dow Jones Industry 분류상 "Water Utilities", "Water Treatment Plant Construction" 산업으로 조회함.
B48: 2. 대상회사는 하수 및 폐수 처리 설비의 운용을 주업으로 하는 회사이므로 이와 사업구조가 유사한 회사를 선정
...

Sheet Summary
A1: Project All
A2: Trading Multiple - 국내
A3: (Unit : KRW million, unless otherwise noted)
B5: HiEntech | K5: 2018년 12개월 기준 | Q5: Multiples | W5: =U8/W8 -> 42.939168
B6: 백만원 | C6: Price [1] | D6: Outstanding[2] | E6: Market Cap | F6: Debt | G6: Cash[3] | H6: NOA[4] | I6: 비지배지분 | J6: EV | K6: BV | L6: Revenue | M6: EBIT | N6: Depreciation | O6: EBITDA | P6: Net Income | Q6: PBR | R6: EV/Revenue | S6: EV/EBIT | T6: EV/EBITDA | U6: PER | V6: PEG | W6: =U9/W9 -> 55.485763
B7: Target(HiEntech) | C7: N/A | D7: N/A | E7: N/A | F7: 0 | G7: 0 | H7: 0 | I7: 0 | J7: N/A | K7: =하이엔텍_Dart!E47/10^6 -> 35747.682 | L7: =하이엔텍_Dart!J5/10^6 -> 155484.44 | M7: =하이엔텍_Dart!J9/10^6 -> 10219.599 | N7: =SUM(하이엔텍_Dart!J37:J38)/10^3 -> 513.603 | O7: =M7+N7 -> 10733.202 | P7: =하이엔텍_Dart!J16/10^6 -> 8449.3759 | W7: =U10/W10 -> 21.735305
B8: ='모집단 선정(HiEntech)'!D37 -> 와이엔텍 | C8: =와이엔텍!N3 -> 5768.5593 | D8: =와이엔텍!N7/10^3 -> 18199.659 | E8: =(D8*C8)/1000 -> 104985.81 | F8: =와이엔텍!C$6 -> 75272.804 | G8: =와이엔텍!C$3 -> 14407.688 | H8: =와이엔텍!C$10 -> 4096.857 | I8: 0 | J8: =E8+F8-G8-H8+I8 -> 161754.07 | K8: =와이엔텍!C$15 -> 116581.79 | L8: =와이엔텍!H$4 -> 76070.963 | M8: =와이엔텍!H$5 -> 14934.316 | N8: =와이엔텍!H$6 -> 6461.887 | O8: =M8+N8 -> 21396.203 | P8: =와이엔텍!H$8 -> 9033.2051 | Q8: =E8/K8 -> 0.90053358 | R8: =J8/L8 -> 2.1263576 | S8: =J8/M8 -> 10.831033 | T8: =J8/O8 -> 7.5599428 | U8: =E8/P8 -> 11.622211 | V8: =P8/D8*1000000 -> 496339.25 | W8: =RATE(2,0,-'2016'!V8,Summary!V8) -> 0.27066688
B9: ='모집단 선정(HiEntech)'!D38 -> 코엔텍 | C9: =코엔텍!N$3 -> 7877.4576 | D9: =코엔텍!N7/10^3 -> 50000 | E9: =(D9*C9)/1000 -> 393872.88 | F9: =코엔텍!C$6 -> 25805.2 | G9: =코엔텍!C$3 -> 92869.832 | H9: =코엔텍!C$10 -> 1950.9296 | I9: =코엔텍!C66/10^6 -> 7.545629 | J9: =E9+F9-G9-H9+I9 -> 324864.87 | K9: =코엔텍!C$15 -> 148686.38 | L9: =코엔텍!H$4 -> 72239.031 | M9: =코엔텍!H$5 -> 29310.888 | N9: =코엔텍!H$6 -> 10092.323 | O9: =M9+N9 -> 39403.211 | P9: =코엔텍!H$8 -> 24489.206 | Q9: =E9/K9 -> 2.6490179 | R9: =J9/L9 -> 4.4970823 | S9: =J9/M9 -> 11.083419 | T9: =J9/O9 -> 8.2446291 | U9: =E9/P9 -> 16.08353 | V9: =P9/D9*1000000 -> 489784.12 | W9: =RATE(2,0,-'2016'!V9,Summary!V9) -> 0.28986769
B10: ='모집단 선정(HiEntech)'!D39 -> 인선이엔티 | C10: =인선이엔티!O$3 -> 6996.2712 | D10: =인선이엔티!O7/10^3 -> 36605.043 | E10: =(D10*C10)/1000 -> 256098.81 | F10: =인선이엔티!C$6 -> 90603.868 | G10: =인선이엔티!C$3 -> 26968.662 | H10: =인선이엔티!C$10 -> 2785.2241 | I10: =인선이엔티!C46/10^6 -> 4580.8354 | J10: =E10+F10-G10-H10+I10 -> 321529.63 | K10: =인선이엔티!C$15 -> 186940.06 | L10: =인선이엔티!H$4 -> 175954.97 | M10: =인선이엔티!H$5 -> 23853.49 | N10: =인선이엔티!H$6 -> 6459.635 | O10: =M10+N10 -> 30313.125 | P10: =인선이엔티!H$8 -> 19964.863 | Q10: =E10/K10 -> 1.3699514 | R10: =J10/L10 -> 1.8273405 | S10: =J10/M10 -> 13.479353 | T10: =J10/O10 -> 10.606944 | U10: =E10/P10 -> 12.827476 | V10: =P10/D10*1000000 -> 545412.92 | W10: =RATE(2,0,-'2016'!V10,Summary!V10) -> 0.59016774
B13: 주요가정 Summary | O13: 국내 | P13: Mean | Q13: =AVERAGE(Q8:Q10) -> 1.6398343 | R13: =AVERAGE(R8:R10) -> 2.8169268 | S13: =AVERAGE(S8:S10) -> 11.797935 | T13: =AVERAGE(T8:T10) -> 8.8038386 | U13: =AVERAGE(U8:U10) -> 13.511072
B14: [1] 주가 : 2019년 3월 31일 기준 3개월 평균 주가 | P14: Median | Q14: =MEDIAN(Q8:Q10) -> 1.3699514 | R14: =MEDIAN(R8:R10) -> 2.1263576 | S14: =MEDIAN(S8:S10) -> 11.083419 | T14: =MEDIAN(T8:T10,) -> 7.9022859 | U14: =MEDIAN(U8:U10) -> 12.827476
B15: [2] 발행주식수 2019년 3월 31일 발행 주식수 | P15: Max | Q15: =MAX(Q8:Q10) -> 2.6490179 | R15: =MAX(R8:R10) -> 4.4970823 | S15: =MAX(S8:S10) -> 13.479353 | T15: =MAX(T8:T10) -> 10.606944 | U15: =MAX(U8:U10) -> 16.08353
B16: [3] Cash : 2018년말 현금및현금성자산 및 단기금융상품 | P16: Min | Q16: =MIN(Q8:Q10) -> 0.90053358 | R16: =MIN(R8:R10) -> 1.8273405 | S16: =MIN(S8:S10) -> 10.831033 | T16: =MIN(T8:T10) -> 7.5599428 | U16: =MIN(U8:U10) -> 11.622211
B17: [4] NoA : 2018년말 장기금융상품, 관계기업투자, 매도가능증권, 투자부동산, 매각예정자산, 장단기 대여금
B19: 비교 대상기업의 선정
B20: 1. 한국거래소 기업공시채널 KIND 시스템 상 수도, 하수 및 폐기물 처리, 원료 재생업으로 등록된 상장회사로 조회
B21: 2. 대상회사의 전방산업인 하수 처리업으로 분류된 상장회사가 없으므로 대용으로 폐기물 처리업을 영위하는 회사를 선정
B22: 3. 선정된 회사 중 주요 관계기업투자에 인터넷뉴스광고업을 영위하는 회사가 있어 주가 산정이 왜곡 되거나 영업손실이 발생하여 Multiple이 비교 불가능한 회사를 제외
B28: LG-Hitachi Water Solutions | K28: 2018년 12개월 기준 | Q28: Multiples
B29: Guideline Public Company | C29: Price [1] | D29: Outstanding[2] | E29: Market Cap | F29: Debt | G29: Cash[3] | H29: NOA[4] | I29: 비지배지분 | J29: EV | K29: BV | L29: Revenue | M29: EBIT | N29: Depreciation | O29: EBITDA | P29: Net Income | Q29: PBR | R29: EV/Revenue | S29: EV/EBIT | T29: EV/EBITDA | U29: PER
B30: Target(LG-Hitachi Water Solutions) | C30: N/A | D30: N/A | E30: N/A | F30: 0 | G30: 0 | H30: 0 | I30: 0 | J30: N/A | K30: =히타치_Dart!E37/10^6 -> 64527.186 | L30: =히타치_Dart!J5/10^6 -> 417764.4 | M30: =히타치_Dart!J11/10^6 -> 36889.577 | N30: =SUM(히타치_Dart!J61:J62)/10^3 -> 2568.313 | O30: =M30+N30 -> 39457.89 | P30: =히타치_Dart!J18/10^6 -> 20158.968
B31: 웰크론한텍 | C31: =웰크론한텍!T6 -> 2243.2203 | D31: =웰크론한텍!T10/10^3 -> 19362.573 | E31: =(D31*C31)/(10^3) -> 43434.518 | F31: =웰크론한텍!G6/10^6 -> 37145.171 | G31: =웰크론한텍!G3/10^6 -> 37121.01 | H31: =웰크론한텍!G10/10^6 -> 54434.514 | I31: =웰크론한텍!C73/10^6 -> 34084.049 | J31: =E31+F31-G31-H31+I31 -> 23108.213 | K31: =웰크론한텍!G16/10^6 -> 100151.62 | L31: =웰크론한텍!I31/10^6 -> 264346.51 | M31: =웰크론한텍!C5/10^6 -> 3443.4006 | N31: =웰크론한텍!C6/10^6 -> 967.24115 | O31: =웰크론한텍!C7/10^6 -> 4410.6417 | P31: =웰크론한텍!C8/10^6 -> 242.83676 | Q31: =E31/K31 -> 0.43368761 | R31: =J31/L31 -> 0.08741637 | S31: =J31/M31 -> 6.7108697 | T31: =J31/O31 -> 5.2391951 | U31: =E31/P31 -> 178.86303 | V31: =P31/D31*1000000 -> 12541.554 | W31: =RATE(2,0,-'2016'!V31,Summary!V31) -> #NUM!
B32: 삼부토건 | C32: =삼부토건!U3 -> 4904.5763 | D32: =삼부토건!U7/10^3 -> 24803.131 | E32: =(D32*C32)/(10^3) -> 121648.85 | F32: =삼부토건!G6/10^6 -> 106815.59 | G32: =삼부토건!G3/10^6 -> 116268.68 | H32: =삼부토건!G10/10^6 -> 66637.356 | I32: =삼부토건!C99/10^6 -> -6992.4369 | J32: =E32+F32-G32-H32+I32 -> 38565.961 | K32: =삼부토건!G16/10^6 -> 190254.57 | L32: =삼부토건!J25/10^6 -> 177427.23 | M32: =삼부토건!C5/10^6 -> -9369.4995 | N32: =삼부토건!C6/10^6 -> 454.891 | O32: =-삼부토건!C7/10^6 -> 8914.6085 | P32: =삼부토건!C8/10^6 -> -51492.807 | Q32: =E32/K32 -> 0.6394004 | R32: =J32/L32 -> 0.21736213 | S32: =J32/M32 -> -4.1161174 | T32: =J32/O32 -> 4.326153 | U32: =E32/P32 -> -2.3624435 | V32: =P32/D32*1000000 -> -2076060.8 | W32: =RATE(2,0,-'2016'!V32,Summary!V32) -> #NUM!
B33: 우원개발 | C33: =우원개발!X3 -> 5074.8305 | D33: =우원개발!X7/10^3 -> 17124.677 | E33: =(D33*C33)/(10^3) -> 86904.833 | F33: =우원개발!G6/10^6 -> 28869.473 | G33: =우원개발!G3/10^6 -> 25713.787 | H33: =우원개발!G10/10^6 -> 54733.618 | I33: 0 | J33: =E33+F33-G33-H33+I33 -> 35326.901 | K33: =우원개발!G16/10^6 -> 61891.502 | L33: =우원개발!J26/10^6 -> 218641.54 | M33: =우원개발!C5/10^6 -> 1436.2555 | N33: =우원개발!C6/10^6 -> 1314.2825 | O33: =우원개발!C7/10^6 -> 2750.5379 | P33: =우원개발!C8/10^6 -> -1444.6428 | Q33: =E33/K33 -> 1.4041481 | R33: =J33/L33 -> 0.16157452 | S33: =J33/M33 -> 24.59653 | T33: =J33/O33 -> 12.843634 | U33: =E33/P33 -> -60.156622 | V33: =P33/D33*1000000 -> -84360.297 | W33: =RATE(2,0,-'2016'!V33,Summary!V33) -> #NUM!
B34: 태영건설 | C34: =태영건설!O10 -> 12067.797 | D34: =태영건설!O14/10^3 -> 76400 | E34: =(D34*C34)/(10^3) -> 921979.66 | F34: =태영건설!G6 -> 1728674.6 | G34: =태영건설!G3 -> 539369.79 | H34: =태영건설!G11 -> 886059.96 | I34: =(태영건설!$C$85)/(10^6) -> 467916.59 | J34: =E34+F34-G34-H34+I34 -> 1693141.1 | K34: =태영건설!G19 -> 1482288.3 | L34: =태영건설!C4 -> 3850546 | M34: =태영건설!C5 -> 463519.91 | N34: =태영건설!C6 -> 67464.167 | O34: =태영건설!C7 -> 530984.07 | P34: =태영건설!C8 -> 244140.18 | Q34: =E34/K34 -> 0.62199754 | R34: =J34/L34 -> 0.43971454 | S34: =J34/M34 -> 3.6527905 | T34: =J34/O34 -> 3.1886853 | U34: =E34/P34 -> 3.7764355 | V34: =P34/D34*1000000 -> 3195552.1 | W34: =RATE(2,0,-'2016'!V34,Summary!V34) -> 10.603263
B35: 현대건설 | C35: =현대건설!O20 -> 57727.119 | D35: =현대건설!O24/10^3 -> 111355.76 | E35: =(D35*C35)/(10^3) -> 6428247.5 | F35: =현대건설!G6 -> 2400899 | G35: =현대건설!G3 -> 4066143 | H35: =현대건설!G11 -> 1169462 | I35: =현대건설!$C$94 -> 2017762 | J35: =E35+F35-G35-H35+I35 -> 5611303.5 | K35: =현대건설!G19 -> 8291856 | L35: =현대건설!C4 -> 16730894 | M35: =현대건설!C5 -> 839989 | N35: =현대건설!C6 -> 175573 | O35: =현대건설!C7 -> 1015562 | P35: =현대건설!C8 -> 535303 | Q35: =E35/K35 -> 0.77524832 | R35: =J35/L35 -> 0.33538575 | S35: =J35/M35 -> 6.6802106 | T35: =J35/O35 -> 5.5253185 | U35: =E35/P35 -> 12.008615 | V35: =P35/D35*1000000 -> 4807142.2 | W35: =RATE(2,0,-'2016'!V35,Summary!V35) -> -0.14467837
B36: 코오롱글로벌 | C36: =코오롱글로벌!Q20 -> 8598.6441 | D36: =코오롱글로벌!Q24/10^3 -> 25210.438 | E36: =(D36*C36)/(10^3) -> 216775.58 | F36: =코오롱글로벌!G6 -> 711660 | G36: =코오롱글로벌!G3 -> 82722.734 | H36: =코오롱글로벌!G11 -> 511292.84 | I36: =(코오롱글로벌!$C$72)/(10^6) -> 4097.9329 | J36: =E36+F36-G36-H36+I36 -> 338517.95 | K36: =코오롱글로벌!G18 -> 446731.38 | L36: =코오롱글로벌!C4 -> 3358253.4 | M36: =코오롱글로벌!C5 -> 76764.013 | N36: =코오롱글로벌!C6 -> 19458.894 | O36: =코오롱글로벌!C7 -> 96222.907 | P36: =코오롱글로벌!C8 -> 14451.16 | Q36: =E36/K36 -> 0.48524817 | R36: =J36/L36 -> 0.10080179 | S36: =J36/M36 -> 4.4098521 | T36: =J36/O36 -> 3.5180599 | U36: =E36/P36 -> 15.000567 | V36: =P36/D36*1000000 -> 573221.28 | W36: =RATE(2,0,-'2016'!V36,Summary!V36) -> 0.2440395
B37: 진흥기업 | C37: =진흥기업!Q20 -> 2040.7627 | D37: =진흥기업!Q24/10^3 -> 145471.74 | E37: =(D37*C37)/(10^3) -> 296873.31 | F37: =진흥기업!G6 -> 23703.636 | G37: =진흥기업!G3 -> 13320.055 | H37: =진흥기업!G11 -> 111114.32 | I37: 0 | J37: =E37+F37-G37-H37+I37 -> 196142.57 | K37: =진흥기업!G18 -> 78804.146 | L37: =진흥기업!C4 -> 671155.39 | M37: =진흥기업!C5 -> 35051.376 | N37: =진흥기업!C6 -> 397.3 | O37: =진흥기업!C7 -> 35448.676 | P37: =진흥기업!C8 -> 6053.4942 | Q37: =E37/K37 -> 3.7672296 | R37: =J37/L37 -> 0.29224614 | S37: =J37/M37 -> 5.5958594 | T37: =J37/O37 -> 5.5331424 | U37: =E37/P37 -> 49.041645 | V37: =P37/D37*1000000 -> 41612.852 | W37: =RATE(2,0,-'2016'!V37,Summary!V37) -> #NUM!
B38: 남광토건 | C38: =남광토건!Q20 -> 15253.39 | D38: =남광토건!Q24/10^3 -> 9827.396 | E38: =(D38*C38)/(10^3) -> 149901.1 | F38: =남광토건!G6 -> 9245.011 | G38: =남광토건!G3 -> 37821.764 | H38: =남광토건!G11 -> 35752.198 | I38: 0 | J38: =E38+F38-G38-H38+I38 -> 85572.151 | K38: =남광토건!G18 -> 49112.604 | L38: =남광토건!C4 -> 157172.93 | M38: =남광토건!C5 -> 11141.645 | N38: =남광토건!C6 -> 460.759 | O38: =남광토건!C7 -> 11602.404 | P38: =남광토건!C8 -> 5715.6746 | Q38: =E38/K38 -> 3.0521921 | R38: =J38/L38 -> 0.54444586 | S38: =J38/M38 -> 7.6803876 | T38: =J38/O38 -> 7.3753812 | U38: =E38/P38 -> 26.226318 | V38: =P38/D38*1000000 -> 581606.22 | W38: =RATE(2,0,-'2016'!V38,Summary!V38) -> #NUM!
B39: 세보엠이씨 | C39: =세보엠이씨!P69 -> 9984.9153 | D39: =세보엠이씨!P73/10^3 -> 10530 | E39: =(D39*C39)/(10^3) -> 105141.16 | F39: =세보엠이씨!C21 -> 11620 | G39: =세보엠이씨!C18 -> 19185.185 | H39: =세보엠이씨!C25 -> 9975.4092 | I39: =(세보엠이씨!$E$71)/(10^6) -> 529.14652 | J39: =E39+F39-G39-H39+I39 -> 88129.71 | K39: =세보엠이씨!C30 -> 158899.63 | L39: =세보엠이씨!C9 -> 473844.41 | M39: =세보엠이씨!C10 -> 27985.354 | N39: =세보엠이씨!C11 -> 4126.767 | O39: =M39+N39 -> 32112.121 | P39: =세보엠이씨!C13 -> 21156.52 | Q39: =E39/K39 -> 0.66168282 | R39: =J39/L39 -> 0.18598871 | S39: =J39/M39 -> 3.1491369 | T39: =J39/O39 -> 2.7444376 | U39: =E39/P39 -> 4.9696811 | V39: =P39/D39*1000000 -> 2009166.2 | W39: =RATE(2,0,-'2016'!V39,Summary!V39) -> 0.22636941
B42: 주요가정 Summary | O42: 국내 | P42: Mean | Q42: =AVERAGE(Q31:Q39) -> 1.3156483 | R42: =AVERAGE(R31:R39) -> 0.26277065 | S42: =AVERAGE(S31:S39) -> 6.4843911 | T42: =AVERAGE(T31:T39) -> 5.5882229 | U42: =AVERAGE(U31:U39) -> 25.263025
B43: [1] 주가 : 2019년 3월 31일 기준 3개월 평균 주가 | P43: Median | Q43: =MEDIAN(Q31:Q39) -> 0.66168282 | R43: =MEDIAN(R31:R39) -> 0.21736213 | S43: =MEDIAN(S31:S39) -> 5.5958594 | T43: =MEDIAN(T31:T39) -> 5.2391951 | U43: =MEDIAN(U31:U39) -> 12.008615
B44: [2] 발행주식수 2019년 3월 31일 발행 주식수 | P44: Max | Q44: =MAX(Q31:Q39) -> 3.7672296 | R44: =MAX(R31:R39) -> 0.54444586 | S44: =MAX(S31:S39) -> 24.59653 | T44: =MAX(T31:T39) -> 12.843634 | U44: =MAX(U31:U39) -> 178.86303
B45: [3] Cash : 2018년말 현금및현금성자산 및 단기금융상품 | P45: Min | Q45: =MIN(Q31:Q39) -> 0.43368761 | R45: =MIN(R31:R39) -> 0.08741637 | S45: =MIN(S31:S39) -> -4.1161174 | T45: =MIN(T31:T39) -> 2.7444376 | U45: =MIN(U31:U39) -> -60.156622
B46: [4] NoA : 2018년말 장기금융상품, 관계기업투자, 매도가능증권, 투자부동산, 매각예정자산, 장단기 대여금
B48: 비교 대상기업의 선정
B49: 1. 한국거래소 기업공시채널 KIND 시스템 상 제조업으로 등록된 상장회사 중, 주요 제품을 '건설업' 으로 조회. | Q49: 평균 Multiple
B50: 2. 선정회사 중 수처리, 오염저감시설 등 환경설비 건축과 거리가 먼 업종(예: 주택, 실내인테리어, 전기배선 등)회사 제외 | Q50: 구분 | R50: EV/Revenue | S50: EV/EBIT | T50: EV/EBITDA
B51: 3. 주식거래정지, 건설과 무관한 자회사 매출이 주가에 큰영향이 있는 등 비교가능성이 떨어지는 회사 제외 | Q51: HiEntech | R51: =AVERAGE(R8:R10) -> 2.8169268 | S51: =AVERAGE(S8:S10) -> 11.797935 | T51: =AVERAGE(T8:T10) -> 8.8038386
Q52: LHWS | R52: =AVERAGE(R31:R39) -> 0.26277065 | S52: =AVERAGE(S31:S39) -> 6.4843911 | T52: =AVERAGE(T31:T39) -> 5.5882229

Sheet 모집단 선정(HiEntech)
B2: 유사기업 선정
C4: 1. 모집단 선정
C6: 한국거래소 기업공시채널 KIND 시스템 상 수도, 하수 및 폐기물 처리, 원료 재생업으로 등록된 상장회사로 조회함.
D7: - 해당 방법에 따라 조회된 회사는 하기와 같음. | K7: 57.3
D8: > Source : http://kind.krx.co.kr/corpgeneral/corpList.do?method=loadInitPage
D10: 회사명 | E10: 종목코드 | F10: 업종 | G10: 주요제품 | H10: 상장일 | I10: 결산월 | J10: 대표자명 | K10: 홈페이지 | L10: 지역 | M10: 비고
D11: KG ETS | E11: 151860 | F11: 폐기물 처리업 | G11: 집단에너지(스팀), 산화동, 폐기물 소각 | H11: 41479 | I11: 12월 | J11: 엄기민 | K11: http://www.kgets.co.kr | L11: 경기도 | M11: 환경, 에너지 사업, 신소재 사업 바이오 사업으로 구성되며 환경, 에너지 사업부문이 차지하는 매출 비중은 59.4%임.
D12: 와이엔텍 | E12: 067900 | F12: 폐기물 처리업 | G12: 사업장폐기물중간및최종처리,전문건설,골재제조 | H12: 38709 | I12: 12월 | J12: 김연석, 박용하(각자 대표이사) | K12: http://www.y-entec.co.kr | L12: 전라남도 | M12: 서비스업, 운송, 제조업, 건설업으로 사업부문이 구분되어 있으며 이 중 서비스업에 속한 폐기물 처리 관련 매출이 31.8%를 차지함.
D13: 자연과환경 | E13: 043910 | F13: 환경 정화 및 복원업 | G13: 스테인레스파이프, 다공성식생블록,조경원예자재 | H13: 38674 | I13: 12월 | J13: 이병용 | K13: http://www.e-nne.co.kr | L13: 충청남도 | M13: 환경복원, 조경산업, 환경플랜트와 같이 친환경 사업을 주로 하는 회사임.
D14: 제넨바이오 | E14: 072520 | F14: 폐기물 처리업 | G14: 휴대폰윈도우 | H14: 38289 | I14: 12월 | J14: 이홍민, 김성주 | K14: http://gennbio.co.kr | L14: 대구광역시 | M14: 환경 사업부, 바이오 사업부로 구성되어 있으며 환경 사업부에서 제공하는 사업장 일반 및 지정 폐기물 매립 서비스가 매출의 98.2%를 차지함.
D15: 코엔텍 | E15: 029960 | F15: 폐기물 처리업 | G15: 산업폐기물 소각/매립처리 | H15: 38156 | I15: 12월 | J15: 이민석 | K15: http://www.koentec.co.kr | L15: 울산광역시 | M15: 사업부문이 전부 폐기물 처리 관련으로 소각 및 매립 부문으로 나뉘어져 있음.
D16: 인선이엔티 | E16: 060150 | F16: 폐기물 처리업 | G16: 건축폐기물처리 | H16: 37421 | I16: 12월 | J16: 이준길 | K16: http://www.insun.co.kr | L16: 경기도 | M16: 건설폐기물 중간처리, 폐기물 최종처리, 자동차재활용 등으로 사업부문이 구성되어 있으며, 이 중 폐기물 처리 관련 매출이 57.3%를 차지함.
D17: GMR머티리얼즈 | E17: 032860 | F17: 해체, 선별 및 원료 재생업 | G17: 철스크랩 | H17: 35615 | I17: 12월 | J17: 김동은 | K17: http://www.gmrmaterials.com | L17: 충청남도 | M17: 금속 및 비금속 원료재생사업과 방화문 제조, 판매 및 시공사업을 주된 사업으로 영위하고 있음.
D21: 모집단의 수 | E21: =COUNTA(E11:E17) -> 7
C23: 2. 유사회사 선정 기준
C25: 기준 Ⅰ. 전방산업 유사성
C27: 하이엔텍(대상회사) - 대상회사는 수질오염방지시설 및 하수처리시설의 관리, 운영 등을 주목적으로 하는 회사임
D28: - 대상회사의 전방산업인 하수 처리업으로 분류된 상장회사가 없으므로 대용으로 폐기물 처리업을 영위하는 회사를 선정
D29: - 자연과환경(환경 정화 및 복원업), GMR머티리얼즈(해체, 선별 및 원료 재생업)
D30: > 상기 2개 회사 제외
C32: 유사회사 선정 결과
D33: - 최초 모집단의 7개 대상회사에서 전방산업 유사성 및 비교가능성 고려를 통해 5개 회사를 유사회사로 선정함.
D35: 회사명 | E35: 종목코드 | F35: 업종 | G35: 주요제품 | H35: 상장일 | I35: 결산월 | J35: 대표자명 | K35: 홈페이지 | L35: 지역 | M35: 비고
D36: KG ETS | E36: 151860 | F36: 폐기물 처리업 | G36: 집단에너지(스팀), 산화동, 폐기물 소각 | H36: 41479 | I36: 12월 | J36: 엄기민 | K36: http://www.kgets.co.kr | L36: 경기도 | M36: 환경, 에너지 사업, 신소재 사업 바이오 사업으로 구성되며 환경, 에너지 사업부문이 차지하는 매출 비중은 59.4%임.
A37: 추가제외 | D37: 와이엔텍 | E37: 067900 | F37: 폐기물 처리업 | G37: 사업장폐기물중간및최종처리,전문건설,골재제조 | H37: 38709 | I37: 12월 | J37: 김연석, 박용하(각자 대표이사) | K37: http://www.y-entec.co.kr | L37: 전라남도 | M37: 서비스업, 운송, 제조업, 건설업으로 사업부문이 구분되어 있으며 이 중 서비스업에 속한 폐기물 처리 관련 매출이 31.8%를 차지함.
D38: 코엔텍 | E38: 029960 | F38: 폐기물 처리업 | G38: 산업폐기물 소각/매립처리 | H38: 38156 | I38: 12월 | J38: 이민석 | K38: http://www.koentec.co.kr | L38: 울산광역시 | M38: 사업부문이 전부 폐기물 처리 관련으로 소각 및 매립 부문으로 나뉘어져 있음.
D39: 인선이엔티 | E39: 060150 | F39: 폐기물 처리업 | G39: 건축폐기물처리 | H39: 37421 | I39: 12월 | J39: 이준길 | K39: http://www.insun.co.kr | L39: 경기도 | M39: 건설폐기물 중간처리, 폐기물 최종처리, 자동차재활용 등으로 사업부문이 구성되어 있으며, 이 중 폐기물 처리 관련 매출이 57.3%를 차지함.
D40: 제넨바이오 | E40: 072520 | F40: 폐기물 처리업 | G40: 휴대폰윈도우 | H40: 38289 | I40: 12월 | J40: 이홍민, 김성주 | K40: http://gennbio.co.kr | L40: 대구광역시 | M40: 환경 사업부, 바이오 사업부로 구성되어 있으며 환경 사업부에서 제공하는 사업장 일반 및 지정 폐기물 매립 서비스가 매출의 98.2%를 차지함.

Sheet 모집단 선정(LHWS)
B2: 유사기업 선정
C4: 1. 모집단 선정
C6: 한국거래소 기업공시채널 KIND 시스템 상 제조업으로 등록된 상장회사 중, 주요 제품을 '건설업' 으로 조회함.
D7: - 해당 방법에 따라 조회된 회사는 하기와 같음.
D8: > Source : http://kind.krx.co.kr/corpgeneral/corpList.do?method=loadInitPage
D10: 회사명 | E10: 종목코드 | F10: 업종 | G10: 주요제품 | H10: 상장일 | I10: 결산월 | J10: 대표자명 | K10: 홈페이지 | L10: 지역 | M10: 비고
D11: 금호산업 | E11: 002990 | F11: 건물 건설업 | G11: 종합건설/여객운송,관광/부동산 임대,분양 | H11: 27937 | I11: 12월 | J11: 서재환 | K11: http://www.kumhoenc.com | L11: 전라남도 | M11: 금호아시아나의 모회사로 주가가 아시아나항공 실적에 큰영향을 받음
D12: 삼부토건 | E12: 001470 | F12: 토목 건설업 | G12: 토목공사,건축공사,포장공사,건설업,분양사업/건설자재 제조 | H12: 27937 | I12: 12월 | J12: 이응근 | K12: http://www.sambu.co.kr | L12: 서울특별시
D13: 대림산업 | E13: 000210 | F13: 토목 건설업 | G13: 산업플랜트공사,건축,토목,폴리에틸렌,폴리부텐,각종폴리머 제조,기술용역 | H13: 27792 | I13: 12월 | J13: 김상우, 박상신 (각자 대표이사) | K13: http://www.daelim.co.kr | L13: 서울특별시
D14: 대원 | E14: 007680 | F14: 건물 건설업 | G14: 아파트 시행 및 시공 | H14: 43070 | I14: 12월 | J14: 전응식 | K14: http://daewon.co.kr | L14: 충청북도 | M14: 아파트건설업을 주업
D15: 이엑스티 | E15: 226360 | F15: 토목 건설업 | G15: 기업인수합병 | H15: 42299 | I15: 12월 | J15: 강정식 | L15: 서울특별시 | M15: 지질기반공사를 주업
D16: 남화토건 | E16: 091590 | F16: 건물 건설업 | G16: 건축공사, 토목공사 | H16: 40939 | I16: 12월 | J16: 최상준, 최재훈 | K16: http://www.namhwaconst.co.kr | L16: 전라남도 | M16: SOC(도로, 항만) 및 주택 등 토건업을 주업
D17: 웰크론한텍 | E17: 076080 | F17: 건물 건설업 | G17: 에너지절감설비,자동화배합설비,환경설비 | H17: 39647 | I17: 12월 | J17: 이영규, 이기창, 이영식 | K17: http://www.welcronhantec.co.kr | L17: 경기도
D18: 일진파워 | E18: 094820 | F18: 전기 및 통신 공사업 | G18: 열교환기,압력용기 | H18: 39392 | I18: 12월 | J18: 이광섭 | K18: http://ijeng.com | L18: 울산광역시 | M18: 한전등 전력회사 경상정비 및 유지보수 매출 58%, 화공/플랜트 37%
D19: 코드네이처 | E19: 078940 | F19: 전기 및 통신 공사업 | G19: 전기공사업 | H19: 38226 | I19: 12월 | J19: 박상훈 | K19: http://codenature.com | L19: 서울특별시 | M19: 2019년5월8일 현재 거래정지
D20: 에너전트 | E20: 041590 | F20: 건물설비 설치 공사업 | G20: 에너지저장시스템, 액정표시장치 | H20: 37561 | I20: 12월 | J20: 김상재, 최영석(각자대표) | K20: http://www.enerzent.com | L20: 대전광역시 | M20: 냉난방 설비공사 주업
D21: 국보디자인 | E21: 066620 | F21: 실내건축 및 건축마무리 공사업 | G21: 인테리어디자인 | H21: 37504 | I21: 12월 | J21: 황창연 | K21: http://www.ikukbo.com | L21: 서울특별시 | M21: 실내 인테리어업 주업
D22: 우원개발 | E22: 046940 | F22: 기반조성 및 시설물 축조관련 전문공사업 | G22: 토공사 | H22: 37425 | I22: 12월 | J22: 김기영 | K22: http://www.woowonerd.com | L22: 서울특별시
D23: KT서브마린 | E23: 060370 | F23: 전기 및 통신 공사업 | G23: 해저케이블등의 건설 및 유지보수 업무 | H23: 37302 | I23: 12월 | J23: 이철규 | K23: http://www.ktsubmarine.co.kr | L23: 부산광역시 | M23: 해저케이블 등 전기통신공사
D24: 엑사이엔씨 | E24: 054940 | F24: 실내건축 및 건축마무리 공사업 | G24: 고주파고압변성기(FBT : Flyback Transformer) | H24: 37238 | I24: 12월 | J24: 구자극, 원종일 (각자 대표이사) | K24: http://www.exaenc.com | L24: 서울특별시 | M24: 실내건축업
D25: 까뮤이앤씨 | E25: 013700 | F25: 건물 건설업 | G25: 토목공사,건축공사/부동산 임대 | H25: 32842 | I25: 12월 | J25: 손병재 | K25: http://www.camusenc.com | L25: 경기도 | M25: 플랜트x
D26: 태영건설 | E26: 009410 | F26: 토목 건설업 | G26: 종합건설업(토목공사,도로공사,건축공사,관급공사,환경공사,상하수도공사,하수종말처리공사)/부동산 임대,매매 | H26: 32825 | I26: 12월 | J26: 이재규 | K26: http://www.taeyoung.com | L26: 경기도 | M26: 환경 플랜트
D27: 화성산업 | E27: 002460 | F27: 건물 건설업 | G27: 아파트 건설 | H27: 32415 | I27: 12월 | J27: 이홍중,이종원 | K27: http://www.hwasung.com | L27: 대구광역시 | M27: 환경/신재생에너지 플랜트
D28: 범양건영 | E28: 002410 | F28: 건물 건설업 | G28: 토목공사,주택건설,건축공사,난방공사,전기공사,포장공사 | H28: 32288 | I28: 12월 | J28: 강병주 | K28: http://www.iby.co.kr | L28: 충청남도 | M28: 환경 플랜트의 주요사업은 2015년에 종료
D29: 현대건설 | E29: 000720 | F29: 토목 건설업 | G29: 공사수입,주택분양,건설산업부문 설계,감리 등 엔지니어링서비스 | H29: 31038 | I29: 12월 | J29: 박동욱 | K29: http://www.hdec.kr | L29: 서울특별시 | M29: 정유, 가스, 석유화학, 담수 플랜트
D30: GS건설 | E30: 006360 | F30: 건물 건설업 | G30: 토목공사,건축공사,주택공사,산업플랜트공사,리모델링공사,시설물유지관리공사/산업설비설계,감리 용역,수출입/에너지관리 진단,연구개발 | H30: 29801 | I30: 12월 | J30: 허창수, 임병용(각자 대표이사) | K30: http://www.gsconst.co.kr/ | L30: 서울특별시 | M30: 정유, 가스, 석유화학, 환경 플랜트
D31: 고려개발 | E31: 004200 | F31: 토목 건설업 | G31: 도로건설공사,토목공사,건축공사 | H31: 28793 | I31: 12월 | J31: 곽수윤 | K31: http://www.kdc.co.kr | L31: 경기도 | M31: 플랜트x
D32: 동부건설 | E32: 005960 | F32: 토목 건설업 | G32: 건축공사,토목공사,전기공사,기계설비공사/비금속,철구조물 제조,판매/여객,자동차 운송,항만하역 | H32: 28793 | I32: 12월 | J32: 허상희 | K32: http://dbcon.dongbu.co.kr | L32: 서울특별시 | M32: 환경/에너지 등 플랜트
D33: 코오롱글로벌 | E33: 003070 | F33: 토목 건설업 | G33: 토목공사,일반건설,주택건설,해외건설,소각로설비공사/환경플랜트,폐처리기 제조 | H33: 28748 | I33: 12월 | J33: 윤창운 | K33: http://www.kolonglobal.com | L33: 경기도 | M33: 화학 플랜트
D34: 신한 | E34: 005450 | F34: 건물 건설업 | G34: 건축공사,토목공사,전기공사,통신공사,주택건설,기계설비공사,철골공사/철구조물 제조 | H34: 28699 | I34: 12월 | J34: 조경선 | K34: http://www.seco.co.kr | L34: 경기도 | M34: 정유, 담수화, 발전소 플랜트
... D41: 상지카일룸 | E41: 042940 | F41: 건물 건설업 | G41: 정보통신망 구축, DVR, ITS, 기타방송장비 등 | H41: 36818 | I41: 12월 | J41: 최기보 | K41: http://www.sangji.co.kr/ | L41: 서울특별시 | M41: 일부 플랜트 수행
D42: KD건설 | E42: 044180 | F42: 건물 건설업 | G42: 몰드베이스(Mold Base) | H42: 36846 | I42: 12월 | J42: 안태일 | K42: http://dymoldtech.co.kr | L42: 경기도
D43: 이테크건설 | E43: 016250 | F43: 건물 건설업 | G43: 건축공사, 플랜트설비, 토목공사 | H43: 36522 | I43: 12월 | J43: 이복영, 안찬규 | K43: http://www.etecenc.com | L43: 서울특별시 | M43: 일부 플랜트 수행
D44: 서희건설 | E44: 035890 | F44: 건물 건설업 | G44: 토목, 건축, 부동산임대업 | H44: 36518 | I44: 12월 | J44: 곽선기,김팔수 | K44: http://www.seohee.co.kr | L44: 경기도 | M44: 플랜트 매출 미미[1]; 제외
D45: 특수건설 | E45: 026150 | F45: 토목 건설업 | G45: 보링 | H45: 35648 | I45: 12월 | J45: 김중헌, 김도헌 (각자 대표이사) | K45: http://www.tuksu.co.kr | L45: 서울특별시 | M45: TBM Shield 로 일반적인 플랜트가 아님; 제외
D46: 세보엠이씨 | E46: 011560 | F46: 건물설비 설치 공사업 | G46: 건설관련설비, ACESS FLOOR , 소음기 , CHAMMBER , PFP UNIT, BY-PASS UNIT , DUCT , 철구조물 . | H46: 35422 | I46: 12월 | J46: 김우영, 김진호(각자 대표이사) | K46: http://www.sebo21.co.kr | L46: 서울특별시 | M46: 일부 플랜트 수행
D47: 동신건설 | E47: 025950 | F47: 토목 건설업 | G47: 토목 | H47: 34918 | I47: 12월 | J47: 김근한,김동한 | K47: - | L47: 경상북도 | M47: 플랜트 공사 수행하지 아니함; 제외
D48: 동원개발 | E48: 013120 | F48: 건물 건설업 | G48: 도급공사 | H48: 34697 | I48: 12월 | J48: 장복만 | K48: http://www.dongwonapt.co.kr | L48: 부산광역시 | M48: 플랜트 공사 수행하지 아니함; 제외
D49: 신원종합개발 | E49: 017000 | F49: 건물 건설업 | G49: 토건 | H49: 34675 | I49: 12월 | J49: 우진호 | K49: http://www.swc.co.kr | L49: 경기도 | M49: 플랜트 공사 수행하지 아니함; 제외
D50: 이화공영 | E50: 001840 | F50: 건물 건설업 | G50: 도급공사 | H50: 34661 | I50: 12월 | J50: 최삼규,최종찬 | K50: http://www.ee-hwa.co.kr | L50: 서울특별시 | M50: 플랜트 매출 미미[1]; 제외
...

Sheet GPCM
A1: Project All
A2: Guideline Public Company Method
A3: (Unit : KRW million, unless otherwise noted)
B5: HiEntech | P5: 2018년 12개월 기준 | V5: Multiples
B6: 백만원 | C6: 국가 | D6: 산업 | F6: 업종상세 | G6: 상장구분 | H6: Price (*1) | I6: Outstanding | J6: Market Cap | K6: Debt | L6: Cash | M6: NOA | N6: 비지배지분 | O6: EV | P6: BV | Q6: Revenue | R6: EBIT | S6: Depreciation | T6: EBITDA | U6: Net Income | V6: PBR | W6: EV/Revenue | X6: EV/EBIT | Y6: EV/EBITDA | Z6: PER | AA6: 사용여부 | AB6: 제외사유
B7: Target(HiEntech) | C7: 대한민국 | E7: 비상장 | G7: N/A | H7: N/A | I7: N/A | J7: N/A | K7: 0 | L7: 0 | M7: 0 | N7: 0 | O7: N/A | P7: =하이엔텍_Dart!E47/10^6 -> 35747.682 | Q7: =하이엔텍_Dart!J5/10^6 -> 155484.44 | R7: =하이엔텍_Dart!J9/10^6 -> 10219.599 | S7: =SUM(하이엔텍_Dart!J37:J38)/10^3 -> 513.603 | T7: =R7+S7 -> 10733.202 | U7: =하이엔텍_Dart!J16/10^6 -> 8449.3759
B8: ='모집단 선정(HiEntech)'!D36 -> KG ETS | C8: 대한민국 | D8: ='모집단 선정(HiEntech)'!F36 -> 폐기물 처리업 | E8: 상장 | F8: ='모집단 선정(HiEntech)'!G36 -> 집단에너지(스팀), 산화동, 폐기물 소각 | G8: 코스닥 | H8: ='KG ETS'!$N$3 -> 3393.3898 | I8: ='KG ETS'!$V$23/10^3 -> 36000 | J8: =(I8*H8)/1000 -> 122162.03 | K8: ='KG ETS'!$C$6 -> 49214.628 | L8: ='KG ETS'!$C$3 -> 7901.0237 | M8: ='KG ETS'!$C$10 -> 79987.286 | N8: 0 | O8: =J8+K8-L8-M8+N8 -> 83488.353 | P8: ='KG ETS'!$C$15 -> 150131.06 | Q8: ='KG ETS'!$H$4 -> 123739.77 | R8: ='KG ETS'!$H$5 -> 13642.63 | S8: ='KG ETS'!$H$6 -> 8488.226 | T8: =R8+S8 -> 22130.856 | U8: ='KG ETS'!$H$8 -> 11266.355 | V8: =J8/P8 -> 0.81370258 | W8: =O8/Q8 -> 0.67470911 | X8: =O8/R8 -> 6.1196671 | Y8: =O8/T8 -> 3.7724864 | Z8: =J8/U8 -> 10.843084 | AA8: X | AB8: 주요 관계기업투자에 인터넷뉴스(이데일리)광고업을 영위하는 회사가 있어 있어 폐기물 처리업만의 주가 산정에 왜곡
B9: ='모집단 선정(HiEntech)'!D37 -> 와이엔텍 | C9: 대한민국 | D9: ='모집단 선정(HiEntech)'!F37 -> 폐기물 처리업 | E9: 상장 | F9: ='모집단 선정(HiEntech)'!G37 -> 사업장폐기물중간및최종처리,전문건설,골재제조 | G9: 코스닥 | H9: =와이엔텍!$N$3 -> 5768.5593 | I9: =와이엔텍!$V$23/10^3 -> 18199.659 | J9: =(I9*H9)/1000 -> 104985.81 | K9: =와이엔텍!$C$6 -> 75272.804 | L9: =와이엔텍!$C$3 -> 14407.688 | M9: =와이엔텍!$C$10 -> 4096.857 | N9: 0 | O9: =J9+K9-L9-M9+N9 -> 161754.07 | P9: =와이엔텍!$C$15 -> 116581.79 | Q9: =와이엔텍!$H$4 -> 76070.963 | R9: =와이엔텍!$H$5 -> 14934.316 | S9: =와이엔텍!$H$6 -> 6461.887 | T9: =R9+S9 -> 21396.203 | U9: =와이엔텍!$H$8 -> 9033.2051 | V9: =J9/P9 -> 0.90053358 | W9: =O9/Q9 -> 2.1263576 | X9: =O9/R9 -> 10.831033 | Y9: =O9/T9 -> 7.5599428 | Z9: =J9/U9 -> 11.622211 | AA9: O
B10: ='모집단 선정(HiEntech)'!D38 -> 코엔텍 | C10: 대한민국 | D10: ='모집단 선정(HiEntech)'!F38 -> 폐기물 처리업 | E10: 상장 | F10: ='모집단 선정(HiEntech)'!G38 -> 산업폐기물 소각/매립처리 | G10: 코스닥 | H10: =코엔텍!$N$3 -> 7877.4576 | I10: =코엔텍!$V$23/10^3 -> 50000 | J10: =(I10*H10)/1000 -> 393872.88 | K10: =코엔텍!$C$6 -> 25805.2 | L10: =코엔텍!$C$3 -> 92869.832 | M10: =코엔텍!$C$10 -> 1950.9296 | N10: =코엔텍!C66/10^6 -> 7.545629 | O10: =J10+K10-L10-M10+N10 -> 324864.87 | P10: =코엔텍!$C$15 -> 148686.38 | Q10: =코엔텍!$H$4 -> 72239.031 | R10: =코엔텍!$H$5 -> 29310.888 | S10: =코엔텍!$H$6 -> 10092.323 | T10: =R10+S10 -> 39403.211 | U10: =코엔텍!$H$8 -> 24489.206 | V10: =J10/P10 -> 2.6490179 | W10: =O10/Q10 -> 4.4970823 | X10: =O10/R10 -> 11.083419 | Y10: =O10/T10 -> 8.2446291 | Z10: =J10/U10 -> 16.08353 | AA10: O
B11: ='모집단 선정(HiEntech)'!D39 -> 인선이엔티 | C11: 대한민국 | D11: ='모집단 선정(HiEntech)'!F39 -> 폐기물 처리업 | E11: 상장 | F11: ='모집단 선정(HiEntech)'!G39 -> 건축폐기물처리 | G11: 코스닥 | H11: =인선이엔티!$O$3 -> 6996.2712 | I11: =인선이엔티!$W$23/10^3 -> 36605.043 | J11: =(I11*H11)/1000 -> 256098.81 | K11: =인선이엔티!$C$6 -> 90603.868 | L11: =인선이엔티!$C$3 -> 26968.662 | M11: =인선이엔티!$C$10 -> 2785.2241 | N11: =인선이엔티!C46/10^6 -> 4580.8354 | O11: =J11+K11-L11-M11+N11 -> 321529.63 | P11: =인선이엔티!$C$15 -> 186940.06 | Q11: =인선이엔티!$H$4 -> 175954.97 | R11: =인선이엔티!$H$5 -> 23853.49 | S11: =인선이엔티!$H$6 -> 6459.635 | T11: =R11+S11 -> 30313.125 | U11: =인선이엔티!$H$8 -> 19964.863 | V11: =J11/P11 -> 1.3699514 | W11: =O11/Q11 -> 1.8273405 | X11: =O11/R11 -> 13.479353 | Y11: =O11/T11 -> 10.606944 | Z11: =J11/U11 -> 12.827476 | AA11: O
B12: 제넨바이오 | C12: 대한민국 | D12: 폐기물 처리업 | E12: 상장 | F12: 폐기물처리 | G12: 코스닥 | H12: =제넨바이오!$N$3 -> 1730.9322 | I12: =제넨바이오!$V$23/10^3 -> 63794.27 | J12: =(I12*H12)/1000 -> 110423.56 | K12: =제넨바이오!$C$6 -> 25208.694 | L12: =제넨바이오!$C$3 -> 17507.573 | M12: =제넨바이오!$C$10 -> 4776.7662 | N12: =제넨바이오!C66/10^6 -> 304.18004 | O12: =J12+K12-L12-M12+N12 -> 113652.09 | P12: =제넨바이오!$C$15 -> 33349.809 | Q12: =제넨바이오!$H$4 -> 7043.2705 | R12: =제넨바이오!$H$5 -> -2377.1422 | S12: =제넨바이오!$H$6 -> 3492.641 | T12: =R12+S12 -> 1115.4988 | U12: =제넨바이오!$H$8 -> -5104.3844 | V12: =J12/P12 -> 3.3110701 | W12: =O12/Q12 -> 16.136267 | X12: =O12/R12 -> -47.810388 | Y12: =O12/T12 -> 101.88455 | Z12: =J12/U12 -> -21.63308 | AA12: X | AB12: 2018년 영업손실로 멀티플 산정에서 제외
T14: 국내 | U14: Mean | V14: =AVERAGE(V8:V12) -> 1.8088551 | W14: =AVERAGE(W8:W12) -> 5.0523513 | X14: =AVERAGE(X8:X12) -> -1.2593832 | Y14: =AVERAGE(Y8:Y12) -> 26.41371 | Z14: =AVERAGE(Z8:Z12) -> 5.9486441
U15: Median | V15: =MEDIAN(V8:V12) -> 1.3699514 | W15: =MEDIAN(W8:W12) -> 2.1263576 | X15: =MEDIAN(X8:X12) -> 10.831033 | Y15: =MEDIAN(Y8:Y12,) -> 7.9022859 | Z15: =MEDIAN(Z8:Z12) -> 11.622211
U16: Max | V16: =MAX(V8:V12) -> 3.3110701 | W16: =MAX(W8:W12) -> 16.136267 | X16: =MAX(X8:X12) -> 13.479353 | Y16: =MAX(Y8:Y12) -> 101.88455 | Z16: =MAX(Z8:Z12) -> 16.08353
U17: Min | V17: =MIN(V8:V12) -> 0.81370258 | W17: =MIN(W8:W12) -> 0.67470911 | X17: =MIN(X8:X12) -> -47.810388 | Y17: =MIN(Y8:Y12) -> 3.7724864 | Z17: =MIN(Z8:Z12) -> -21.63308
B19: LG-Hitachi Water Solutions | P19: 2018년 12개월 기준 | V19: Multiples
B20: Guideline Public Company | C20: 국가 | D20: 산업 | F20: 업종상세 | G20: 상장구분 | H20: Price (*1) | I20: Outstanding | J20: Market Cap | K20: Debt | L20: Cash | M20: NOA | N20: 비지배지분 | O20: EV | P20: BV | Q20: Revenue | R20: EBIT | S20: Depreciation | T20: EBITDA | U20: Net Income | V20: PBR | W20: EV/Revenue | X20: EV/EBIT | Y20: EV/EBITDA | Z20: PER | AA20: 사용여부 | AB20: 제외사유
B21: Target(LG-Hitachi Water Solutions) | C21: 대한민국 | E21: 비상장 | G21: N/A | H21: N/A | I21: N/A | J21: N/A | K21: 0 | L21: 0 | M21: 0 | N21: 0 | O21: N/A | P21: =히타치_Dart!E37/10^6 -> 64527.186 | Q21: =히타치_Dart!J5/10^6 -> 417764.4 | R21: =히타치_Dart!J11/10^6 -> 36889.577 | S21: =SUM(히타치_Dart!J61:J62)/10^3 -> 2568.313 | T21: =R21+S21 -> 39457.89 | U21: =히타치_Dart!J18/10^6 -> 20158.968
B22: 웰크론한텍 | C22: 대한민국 | D22: 건물 건설업 | E22: 상장 | F22: 에너지절감설비,자동화배합설비,환경설비 | G22: 코스닥 | H22: =웰크론한텍!T2 -> 0 | I22: =웰크론한텍!AB26/10^3 -> 19362.573 | J22: =(I22*H22)/(10^3) -> 0 | K22: =웰크론한텍!G6/10^6 -> 37145.171 | L22: =웰크론한텍!G3/10^6 -> 37121.01 | M22: =웰크론한텍!G10/10^6 -> 54434.514 | N22: =웰크론한텍!C73/10^6 -> 34084.049 | O22: =J22+K22-L22-M22+N22 -> -20326.305 | P22: =웰크론한텍!G16/10^6 -> 100151.62 | Q22: =웰크론한텍!I31/10^6 -> 264346.51 | R22: =웰크론한텍!C5/10^6 -> 3443.4006 | S22: =웰크론한텍!C6/10^6 -> 967.24115 | T22: =웰크론한텍!C7/10^6 -> 4410.6417 | U22: =웰크론한텍!C8/10^6 -> 242.83676 | V22: =J22/P22 -> 0 | W22: =O22/Q22 -> -0.076892654 | X22: =O22/R22 -> -5.9029743 | Y22: =O22/T22 -> -4.6084688 | Z22: =J22/U22 -> 0 | AA22: O
B23: 삼부토건 | C23: 대한민국 | D23: 토목 건설업 | E23: 상장 | F23: 토목공사,건축공사,포장공사,건설업,분양사업/건설자재 제조 | G23: 코스피 | H23: =삼부토건!U6 -> 112854 | I23: =삼부토건!AC21/10^3 -> 24803.131 | J23: =(I23*H23)/(10^3) -> 2799132.5 | K23: =삼부토건!G6/10^6 -> 106815.59 | L23: =삼부토건!G3/10^6 -> 116268.68 | M23: =삼부토건!G10/10^6 -> 66637.356 | N23: =삼부토건!C99/10^6 -> -6992.4369 | O23: =J23+K23-L23-M23+N23 -> 2716049.7 | P23: =삼부토건!G16/10^6 -> 190254.57 | Q23: =삼부토건!J25/10^6 -> 177427.23 | R23: =삼부토건!C5/10^6 -> -9369.4995 | S23: =삼부토건!C6/10^6 -> 454.891 | T23: =-삼부토건!C7/10^6 -> 8914.6085 | U23: =삼부토건!C8/10^6 -> -51492.807 | V23: =J23/P23 -> 14.712564 | W23: =O23/Q23 -> 15.307964 | X23: =O23/R23 -> -289.88204 | Y23: =O23/T23 -> 304.67402 | Z23: =J23/U23 -> -54.359681 | AA23: O
B24: 대림산업 | C24: 대한민국 | D24: 토목 건설업 | E24: 상장 | F24: 산업플랜트공사,건축,토목,폴리에틸렌,폴리부텐,각종폴리머 제조,기술용역 | G24: 코스피 | H24: =대림산업!V3 -> 97396.61 | I24: =대림산업!AD24/10^3 -> 34800 | J24: =(I24*H24)/(10^3) -> 3389402 | K24: =대림산업!G7/10^6 -> 2689205.1 | L24: =대림산업!G4/10^6 -> 2520202.1 | M24: =대림산업!G11/10^6 -> 3001642.5 | N24: =대림산업!E87/10^6 -> 660210.51 | O24: =J24+K24-L24-M24+N24 -> 1216973 | P24: =대림산업!G17/10^6 -> 6050244.1 | Q24: =대림산업!K29/10^6 -> 10984485 | R24: =대림산업!C6/10^6 -> 845358.15 | S24: =대림산업!C7/10^6 -> 127517 | T24: =대림산업!C8/10^6 -> 972875.15 | U24: =대림산업!C9/10^6 -> 678088.77 | V24: =J24/P24 -> 0.56020914 | W24: =O24/Q24 -> 0.11079017 | X24: =O24/R24 -> 1.4395946 | Y24: =O24/T24 -> 1.2509036 | Z24: =J24/U24 -> 4.9984636 | AA24: X | AB24: 투자부동산(1,149억) 및 관계기업투자(1,147억)등 NOA 과다보유(총 3,002억)에 따른 지분가치왜곡
B25: 우원개발 | C25: 대한민국 | D25: 기반조성 및 시설물 축조관련 전문공사업 | E25: 상장 | F25: 토공사 | G25: 코스닥 | H25: =우원개발!X2 -> 4037.4194 | I25: =우원개발!AF21/10^3 -> 17124.677 | J25: =(I25*H25)/(10^3) -> 69139.502 | K25: =우원개발!G6/10^6 -> 28869.473 | L25: =우원개발!G3/10^6 -> 25713.787 | M25: =우원개발!G10/10^6 -> 54733.618 | N25: 0 | O25: =J25+K25-L25-M25+N25 -> 17561.57 | P25: =우원개발!G16/10^6 -> 61891.502 | Q25: =우원개발!J26/10^6 -> 218641.54 | R25: =우원개발!C5/10^6 -> 1436.2555 | S25: =우원개발!C6/10^6 -> 1314.2825 | T25: =우원개발!C7/10^6 -> 2750.5379 | U25: =우원개발!C8/10^6 -> -1444.6428 | V25: =J25/P25 -> 1.1171082 | W25: =O25/Q25 -> 0.08032129 | X25: =O25/R25 -> 12.227331 | Y25: =O25/T25 -> 6.3847766 | Z25: =J25/U25 -> -47.859236 | AA25: O
B26: 태영건설 | C26: 대한민국 | D26: 토목 건설업 | E26: 상장 | F26: 종합건설업(토목공사,도로공사,건축공사,관급공사,환경공사,상하수도공사,하수종말처리공사)/부동산 임대,매매 | G26: 코스피 | H26: =태영건설!O20 -> 12067.797 | I26: =태영건설!P20/10^3 -> 76400 | J26: =(I26*H26)/(10^3) -> 921979.66 | K26: =태영건설!G6 -> 1728674.6 | L26: =태영건설!G3 -> 539369.79 | M26: =태영건설!G11 -> 886059.96 | N26: =(태영건설!$C$85)/(10^6) -> 467916.59 | O26: =J26+K26-L26-M26+N26 -> 1693141.1 | P26: =태영건설!G19 -> 1482288.3 | Q26: =태영건설!C4 -> 3850546 | R26: =태영건설!C5 -> 463519.91 | S26: =태영건설!C6 -> 67464.167 | T26: =태영건설!C7 -> 530984.07 | U26: =태영건설!C8 -> 244140.18 | V26: =J26/P26 -> 0.62199754 | W26: =O26/Q26 -> 0.43971454 | X26: =O26/R26 -> 3.6527905 | Y26: =O26/T26 -> 3.1886853 | Z26: =J26/U26 -> 3.7764355 | AA26: O
