Workbook
Name __10: #REF!
Name __11: #REF!
Name __6: #REF!
Name __7: #REF!
Name __8: #REF!
Name __9: #REF!
Name __DAT1: #REF!
Name __DAT10: #REF!
Name __DAT11: #REF!
Name __DAT12: #REF!
Name __DAT13: #REF!
Name __DAT14: #REF!
Name __DAT15: #REF!
Name __DAT16: #REF!
Name __DAT17: #REF!
Name __DAT18: #REF!
Name __DAT19: #REF!
Name __DAT2: #REF!
Name __DAT3: #REF!
Name __DAT4: #REF!
Name __DAT5: #REF!
Name __DAT6: #REF!
Name __DAT7: #REF!
Name __DAT8: #REF!
Name __DAT9: #REF!
Name _1: #N/A
Name _10: #REF!
Name _11: #REF!
Name _12: #REF!
Name _13: #REF!
Name _14: #REF!
Name _15: #REF!
Name _16: #REF!
Name _17: #REF!
Name _18: #REF!
Name _19: #REF!
Name _2: #N/A
Name _20: #REF!
Name _20020826기본: #REF!
Name _3: #N/A
Name _4: #REF!
Name _5: #REF!
Name _6: #REF!
Name _7: #N/A
Name _8: #REF!
Name _9: #REF!
Name _C: #REF!
Name _DAT1: #REF!
Name _DAT10: #REF!
Name _DAT11: #REF!
Name _DAT12: #REF!
Name _DAT13: #REF!
Name _DAT14: #REF!
Name _DAT15: #REF!
Name _DAT16: #REF!
Name _DAT17: #REF!
Name _DAT18: #REF!
Name _DAT19: #REF!
Name _DAT2: #REF!
Name _DAT3: #REF!

Sheet Title
L5: Project
L6: =Des!C5 -> IT | M6: =L6 -> IT
L10: Financial Model
L11: - Business Valuation

Sheet Des
B1: ="Project"&" "&Title!L6 -> Project IT | C1: =$C$12 -> DRAFT - For Discussion Purposes Only
B2: Description
G4: DRAFT - For Discussion Purposes Only
B5: Project Name | C5: IT | G5: FINAL
B6: Client | C6: GS ITM
B7: Target Company | C7: GS ITM
B8: Valuation Date | C8: 42369
B9: Year End after Valuation Date | C9: =IF(C8=DATE(YEAR(C8),12,31),DATE(YEAR(C8+1),12,31),DATE(YEAR(C8),12,31)) -> 42735
B10: Partial Period Factor | C10: =(C9-C8)/365 -> 1.0027397
B11: Projection Period | C11: 2016/01/01 ~ 2020/12/31, 5년
B12: Work-In-Progress Disclaimer | C12: DRAFT - For Discussion Purposes Only
B13: Currency & Unit | C13: KRW Millions
B15: KPMG Color(기존)
B22: KPMG Color(신규)

Sheet Terms
B2: A | C2: Actual | D2: GPCM | E2: Guideline Public Company Method
B3: AUD | C3: Australian Dollar | D3: IBD | E3: Interest Bearing Debt
B4: CAGR | C4: Compound Annual Growth Rate | D4: JPY | E4: Japanese Yen
B5: CapEx | C5: Capital Expenditure | D5: Kd / Ke | E5: Cost of Debt / Cost of Equity
B6: CNY | C6: Chinese Yuan | D6: KRW | E6: Korean Won
B7: COGS | C7: Cost of Goods Sold | D7: KRX | E7: Korea Exchange
B8: Cont’d | C8: Continued | D8: LTM | E8: Last Twelve Months
B9: DART | C9: Data Analysis, Retrieval and Transfer System | D9: MKT Cap | E9: Market Capitalization
B10: DCF | C10: Discounted Cash Flow | D10: n.a. | E10: Not Applicable
B11: Dep. | C11: Depreciation | D11: n.m | E11: Not Meaningful
B12: DKK | C12: Danish Krone | D12: NOA | E12: Non Operating Asset
B13: E | C13: Estimated | D13: PV | E13: Present Value
... B21: GICS | C21: Global Industry Classification Standard | D21: x | E21: Multiple

Sheet 가정
B1: ="Project"&" "&Title!L6 -> Project IT | H1: DRAFT - For Discussion Purposes Only
B2: Assumption
B4: 구분 | C4: 세부항목 | E4: 가정 | F4: 근거 | G4: Reference | H4: 비고
B5: 매출액
B16: COGS
B27: SG&A
B38: Working Capital
B49: CapEx & Depreciation
B60: Others | C60: Terminal Growth Rate | D60: (%) | E60: 0
C61: 2011년 까지의 법인세율 | D61: (%) | E61: 0.242
C62: 2012년 이후의 법인세율 | D62: 세율 | E62: 0.11 | F62: 과세표준 2억원 이하 | G62: 2011년 12월 28일 제304회 국회(임시회) 제3차 본회의에서 가결된 법인세법 개정내용
D63: 최대 | E63: 200
D64: Extra
D65: 세율 | E65: 0.22 | F65: 과세표준 2억원 초과 200억원 이하
D66: 최대 | E66: 20000
D67: Extra | E67: =200*11% -> 22
D68: 세율 | E68: 0.242 | F68: 과세표준 200억원 초과
D69: 최대
D70: Extra | E70: =39800*11% -> 4378
C71: Market Data 기준일 | E71: 42369

Sheet 인터뷰
B1: =가정!B1 -> Project IT | D1: DRAFT - For Discussion Purposes Only
B2: Questionaire
B4: 구분 | C4: 세부항목 | D4: 비고
B5: 매출액
B28: COGS
B39: SG&A
B50: Working Capital
B61: CapEx & Depreciation

Sheet DCF(KPMG)>>

Sheet _TM_Result(보고서)
A1: Left | B1: Top | C1: Right | D1: Bottom | E1: Ref
A2: 7 | B2: 5 | C2: 12 | D2: 7 | E2: $G$5:$L$7

Sheet _TM_Result
A1: Left | B1: Top | C1: Right | D1: Bottom | E1: Ref
A2: 14 | B2: 17 | C2: 17 | D2: 22 | E2: $N$17:$Q$22

Sheet Result
B1: =WACC!$B$1 -> Project IT
B2: Result
B4: 평가방법 | C4: Low | E4: High | F4: 중간값
B5: GTM | C5: =GTM!R35 -> 135079.2 | D5: =E5-C5 -> 2226.4228 | E5: =GTM!R36 -> 137305.62 | F5: n.a.
B6: GPCM | D6: =E6-C6 -> 0 | F6: n.a.
B7: DCF | C7: =DCF!D36 -> 103789.1 | D7: =E7-C7 -> 35104.219 | E7: =DCF!F36 -> 138893.32
N27: DCF Results
N28: WACC | Q28: =wacc -> 0.091
N29: Terminal Growth Rate | Q29: =g -> 0
N30: Operating Value (a) | O30: 1543.0476 | P30: ~ | Q30: 1724.4334
N31: NOA (b) | Q31: 590.36301
N32: IBD (c) | Q32: 59.320332
N33: 100% Equity Value (d) =(a)+(b)-(c) | O33: =O30+Q31-Q32 -> 2074.0902 | P33: ~ | Q33: =Q30+Q31-Q32 -> 2255.4761

Sheet WACC
B1: ="Project"&" "&Title!L6 -> Project IT | Q1: =Des!$C$12 -> DRAFT - For Discussion Purposes Only | S1: <Tax Rate>
B2: Weighted Average Cost of Capital | S2: Unlevered | U2: 0.242
S3: Re-Levered, Kd | U3: =U2 -> 0.242 | V3: <= Terminal year 기준 EBIT규모에 따름 => 11%(~2억), 22%(~200억), 24.2%(200억~)
B4: Guideline Public Company | E4: Country | G4: Observed | H4: Currency (Millions) | I4: MKT Cap | J4: IBD | K4: Debt | M4: Debt | O4: Tax Rate | P4: Unlevered Beta | Q4: Re-Levered Beta
G5: Beta | K5: Equity | M5: TIC
B6: SAMSUNG SDS CO LTD | E6: SOUTH KOREA | G6: =CHOOSE($X$34,G74,H74,I74) -> 1.245976 | H6: KRW | I6: =CHOOSE($X$47,G102,H102,I102,J102,K102)+J131 -> 20173498 | J6: =G131 -> 14363.157 | K6: =J6/I6 -> 0.00071198148 | M6: =J6/(I6+J6) -> 0.00071147493 | O6: 0.242 | P6: =IF(G6="NA","NA",G6/(1+K6*(1-O6))) -> 1.2453039 | Q6: =P6*(1+($M$47/$M$48)*$E$47) -> 1.2453039
B7: POSCO ICT CO LTD | E7: SOUTH KOREA | G7: =CHOOSE($X$34,G75,H75,I75) -> 0.612323 | H7: KRW | I7: =CHOOSE($X$47,G103,H103,I103,J103,K103)+J132 -> 749314.02 | J7: =G132 -> 40486.304 | K7: =J7/I7 -> 0.054031157 | M7: =J7/(I7+J7) -> 0.051261442 | O7: 0.242 | P7: =IF(G7="NA","NA",G7/(1+K7*(1-O7))) -> 0.58823161 | Q7: =P7*(1+($M$47/$M$48)*$E$47) -> 0.58823161
B8: DONGBU CO LTD | E8: SOUTH KOREA | G8: =CHOOSE($X$34,G76,H76,I76) -> 1.050498 | H8: KRW | I8: =CHOOSE($X$47,G104,H104,I104,J104,K104)+J133 -> 89137.821 | J8: =G133 -> 59995.438 | K8: =J8/I8 -> 0.67306377 | M8: =J8/(I8+J8) -> 0.40229415 | O8: 0.242 | P8: =IF(G8="NA","NA",G8/(1+K8*(1-O8))) -> 0.69561004 | Q8: =P8*(1+($M$47/$M$48)*$E$47) -> 0.69561004
B9: SHINSEGAE INFORMATION & COMM | E9: SOUTH KOREA | G9: =CHOOSE($X$34,G77,H77,I77) -> 0.8844239 | H9: KRW | I9: =CHOOSE($X$47,G105,H105,I105,J105,K105)+J134 -> 168289.72 | J9: =G134 -> 0 | K9: =J9/I9 -> 0 | M9: =J9/(I9+J9) -> 0 | O9: 0.242 | P9: =IF(G9="NA","NA",G9/(1+K9*(1-O9))) -> 0.8844239 | Q9: =P9*(1+($M$47/$M$48)*$E$47) -> 0.8844239
B10: HYUNDAI INFORMATION TECH | E10: SOUTH KOREA | G10: =CHOOSE($X$34,G78,H78,I78) -> 0.2608621 | H10: KRW | I10: =CHOOSE($X$47,G106,H106,I106,J106,K106)+J135 -> 116521.65 | J10: =G135 -> 71570.72 | K10: =J10/I10 -> 0.61422678 | M10: =J10/(I10+J10) -> 0.38050836 | O10: 0.242 | P10: =IF(G10="NA","NA",G10/(1+K10*(1-O10))) -> 0.17799193 | Q10: =P10*(1+($M$47/$M$48)*$E$47) -> 0.17799193
B11: HANIL NETWORKS CO LTD | E11: SOUTH KOREA | G11: =CHOOSE($X$34,G79,H79,I79) -> 0.7077572 | H11: KRW | I11: =CHOOSE($X$47,G107,H107,I107,J107,K107)+J136 -> 34610.335 | J11: =G136 -> 500 | K11: =J11/I11 -> 0.014446552 | M11: =J11/(I11+J11) -> 0.014240821 | O11: 0.242 | P11: =IF(G11="NA","NA",G11/(1+K11*(1-O11))) -> 0.70009086 | Q11: =P11*(1+($M$47/$M$48)*$E$47) -> 0.70009086
B32: Maximum | G32: =MAX(G6:G14) -> 1.245976 | K32: =MAX(K6:K14) -> 0.67306377 | M32: =MAX(M6:M14) -> 0.40229415 | P32: =MAX(P6:P14) -> 1.2453039 | Q32: =MAX(Q6:Q14) -> 1.2453039
B33: Average | G33: =AVERAGE(G6:G14) -> 0.79364003 | K33: =AVERAGE(K6:K14) -> 0.22608004 | M33: =AVERAGE(M6:M14) -> 0.14150271 | P33: =AVERAGE(P6:P14) -> 0.71527538 | Q33: =AVERAGE(Q6:Q14) -> 0.71527538
B34: Median | G34: =MEDIAN(G6:G14) -> 0.79609055 | K34: =MEDIAN(K6:K14) -> 0.034238855 | M34: =MEDIAN(M6:M14) -> 0.032751132 | P34: =MEDIAN(P6:P14) -> 0.69785045 | Q34: =MEDIAN(Q6:Q14) -> 0.69785045 | U34: : 'Beta' Option (기간) | X34: 3
B35: Minimum | G35: =MIN(G6:G14) -> 0.2608621 | K35: =MIN(K6:K14) -> 0 | M35: =MIN(M6:M14) -> 0 | P35: =MIN(P6:P14) -> 0.17799193 | Q35: =MIN(Q6:Q14) -> 0.17799193
B37: Selected | M37: =CHOOSE($X$53,M33,M34,0) -> 0 | P37: =CHOOSE($X$53,P33,P34,P33) -> 0.71527538 | Q37: =P37*(1+($M$47/$M$48)*$E$47) -> 0.71527538
X38: 3 | Z38: KPMG
B39: Cost of Equity (KE) | Z39: Damodaran
U40: : 'Equity Risk Premium' Option (시점) | X40: 2 | Z40: Bloomberg
B41: Risk Free Rate | D41: + | E41: Beta | F41: x | G41: Equity Risk Premium | I41: + | J41: Size Risk Premium | K41: + | M41: Specific Premium | P41: = | Q41: Cost of Equity
B42: =CHOOSE($X$42,G159,G160,G161,G162,G163) -> 0.02065 | E42: =Q37 -> 0.71527538 | G42: =CHOOSE($X$40,H159,H160,H161,H162,H163) -> 0.098446667 | J42: 0 | M42: 0 | Q42: =SUM(B42,(E42*G42),J42,M42,O42) -> 0.091066477 | U42: : 'Risk-free Rate' Option (시점) | X42: 1
B44: After-Tax Cost of Debt (KD) | M44: Weighted Average Cost of Capital | X44: 1 | Z44: 미적용 | AA44: 0
Z45: 3-등급 체계
B46: Pre-Tax Cost of Debt | D46: x | E46: (1 - Tax Rate) | F46: = | G46: After-Tax Cost of Debt | M46: Captial Structure | N46: x | O46: Cost of Capital | P46: = | Q46: Contribution | Z46: 10-등급 체계
B47: =CHOOSE($X$50,$G$180,,$G$182) -> 0.03921 | E47: =1-U3 -> 0.758 | G47: =(B47*E47) -> 0.02972118 | K47: Debt | M47: =M37 -> 0 | O47: =G47 -> 0.02972118 | Q47: =O47*M47 -> 0 | U47: : 'Market Capitalization' Option | X47: 2 | Y47: =X47 -> 2
K48: Equity | M48: =(1-M47) -> 1 | O48: =Q42 -> 0.091066477 | Q48: =O48*M48 -> 0.091066477
O50: WACC | P50: = | Q50: =ROUND(Q47+Q48,3) -> 0.091 | U50: : 'Cost of Debt' Option | X50: 3 | Z50: Kisline 기업평가등급
B51: Notes: | Z51: 회사제시 신용등급
B52: [1] | C52: 대상회사와 유사한 사업을 영위하고 있는 회사를 선정 | Z52: DART 공시 신용등급
B53: [2] | C53: ="2015년 12월 31일 기준, "&CHOOSE($X$34,"5년 Weekly adjusted Beta 적용","5년 Monthly adjusted Beta 적용","2년 Weekly adjusted Beta 적용") -> 2015년 12월 31일 기준, 2년 Weekly adjusted Beta 적용 | U53: : 'Capital Structure' Option | X53: 3 | Z53: Average
B54: [3] | C54: ="2015년 12월 31일 기준, "&CHOOSE($X$47,"사용","과거 1개월 평균 시가총액 적용","과거 3개월 평균 시가총액 적용","과거 6개월 평균 시가총액 적용","과거 12개월 평균 시가총액 적용") -> 2015년 12월 31일 기준, 과거 1개월 평균 시가총액 적용 | Z54: Median
B55: [4] | C55: 2015년 9월 30일 기준 이자발생부채 적용 | Z55: 무부채기업 가정
B56: [5] | C56: 2015년 12월 31일 기준, 과거 1개월 평균 10년 만기 국공채 이자율 적용 (Source: Bloomberg)
B57: [6] | C57: ="2015년 12월 31일 기준, "&CHOOSE($X$40,"사용","과거 1개월 평균 Equity Risk Premium 적용","과거 3개월 평균 Equity Risk Premium 적용","과거 6개월 평균 Equity Risk Premium 적용","과거 12개월 평균 Equity Risk Premium 적용") -> 2015년 12월 31일 기준, 과거 1개월 평균 Equity Risk Premium 적용
B58: [7] | C58: 2015년 12월 31일 기준, 대상회사의 신용등급 A+를 고려한 5년 만기 무보증 공모사채 이자율을 적용(Source: KOFIA BIS)
B59: [8] | C59: 대한민국의 한계 법인세율 24.2%를 적용
B60: [9] | C60: 유사상장회사의 시장가치기준 평균 자본구조 적용
B64: <비교대상 회사 선정 과정>
B66: 유사회사 선정 과정
B67: 1. 국내 IT 서비스업체 중 매출액 기준 상위 32개 사 중 System Integration (SI)를 주요 사업으로 하는 회사 선정 (20개사)
...

Sheet WACC(보고서)
B1: ="Project"&" "&Title!L6 -> Project IT | O1: =Des!$C$12 -> DRAFT - For Discussion Purposes Only | Q1: <Tax Rate>
B2: Weighted Average Cost of Capital | Q2: Unlevered | S2: 0.242
Q3: Re-Levered, Kd | S3: =S2 -> 0.242 | T3: <= Terminal year 기준 EBIT규모에 따름 => 11%(~2억), 22%(~200억), 24.2%(200억~)
B4: Guideline Public Company | D4: Country | F4: Observed | G4: Currency (Millions) | H4: MKT Cap | I4: IBD | J4: Debt | K4: Debt | M4: Tax Rate | N4: Unlevered Beta | O4: Re-Levered Beta
F5: Beta | J5: Equity | K5: TIC
B6: =WACC!B6 -> SAMSUNG SDS CO LTD | D6: =WACC!E6 -> SOUTH KOREA | F6: =WACC!G6 -> 1.245976 | G6: =WACC!H6 -> KRW | H6: =WACC!I6 -> 20173498 | I6: =WACC!J6 -> 14363.157 | J6: =WACC!K6 -> 0.00071198148 | K6: =WACC!M6 -> 0.00071147493 | M6: =WACC!O6 -> 0.242 | N6: =WACC!P6 -> 1.2453039 | O6: =WACC!Q6 -> 1.2453039
B7: =WACC!B7 -> POSCO ICT CO LTD | D7: =WACC!E7 -> SOUTH KOREA | F7: =WACC!G7 -> 0.612323 | G7: =WACC!H7 -> KRW | H7: =WACC!I7 -> 749314.02 | I7: =WACC!J7 -> 40486.304 | J7: =WACC!K7 -> 0.054031157 | K7: =WACC!M7 -> 0.051261442 | M7: =WACC!O7 -> 0.242 | N7: =WACC!P7 -> 0.58823161 | O7: =WACC!Q7 -> 0.58823161
B8: =WACC!B8 -> DONGBU CO LTD | D8: =WACC!E8 -> SOUTH KOREA | F8: =WACC!G8 -> 1.050498 | G8: =WACC!H8 -> KRW | H8: =WACC!I8 -> 89137.821 | I8: =WACC!J8 -> 59995.438 | J8: =WACC!K8 -> 0.67306377 | K8: =WACC!M8 -> 0.40229415 | M8: =WACC!O8 -> 0.242 | N8: =WACC!P8 -> 0.69561004 | O8: =WACC!Q8 -> 0.69561004
B9: =WACC!B9 -> SHINSEGAE INFORMATION & COMM | D9: =WACC!E9 -> SOUTH KOREA | F9: =WACC!G9 -> 0.8844239 | G9: =WACC!H9 -> KRW | H9: =WACC!I9 -> 168289.72 | I9: =WACC!J9 -> 0 | J9: =WACC!K9 -> 0 | K9: =WACC!M9 -> 0 | M9: =WACC!O9 -> 0.242 | N9: =WACC!P9 -> 0.8844239 | O9: =WACC!Q9 -> 0.8844239
B10: =WACC!B10 -> HYUNDAI INFORMATION TECH | D10: =WACC!E10 -> SOUTH KOREA | F10: =WACC!G10 -> 0.2608621 | G10: =WACC!H10 -> KRW | H10: =WACC!I10 -> 116521.65 | I10: =WACC!J10 -> 71570.72 | J10: =WACC!K10 -> 0.61422678 | K10: =WACC!M10 -> 0.38050836 | M10: =WACC!O10 -> 0.242 | N10: =WACC!P10 -> 0.17799193 | O10: =WACC!Q10 -> 0.17799193
B11: =WACC!B11 -> HANIL NETWORKS CO LTD | D11: =WACC!E11 -> SOUTH KOREA | F11: =WACC!G11 -> 0.7077572 | G11: =WACC!H11 -> KRW | H11: =WACC!I11 -> 34610.335 | I11: =WACC!J11 -> 500 | J11: =WACC!K11 -> 0.014446552 | K11: =WACC!M11 -> 0.014240821 | M11: =WACC!O11 -> 0.242 | N11: =WACC!P11 -> 0.70009086 | O11: =WACC!Q11 -> 0.70009086
B12: =WACC!B12 -> 0 | D12: =WACC!E12 -> 0 | F12: =WACC!G12 -> 0 | G12: =WACC!H12 -> 0 | H12: =WACC!I12 -> 0 | I12: =WACC!J12 -> 0 | J12: =WACC!K12 -> 0 | K12: =WACC!M12 -> 0 | M12: =WACC!O12 -> 0 | N12: =WACC!P12 -> 0 | O12: =WACC!Q12 -> 0
B13: =WACC!B13 -> 0 | D13: =WACC!E13 -> 0 | F13: =WACC!G13 -> 0 | G13: =WACC!H13 -> 0 | H13: =WACC!I13 -> 0 | I13: =WACC!J13 -> 0 | J13: =WACC!K13 -> 0 | K13: =WACC!M13 -> 0 | M13: =WACC!O13 -> 0 | N13: =WACC!P13 -> 0 | O13: =WACC!Q13 -> 0
B14: =WACC!B14 -> 0 | D14: =WACC!E14 -> 0 | F14: =WACC!G14 -> 0 | G14: =WACC!H14 -> 0 | H14: =WACC!I14 -> 0 | I14: =WACC!J14 -> 0 | J14: =WACC!K14 -> 0 | K14: =WACC!M14 -> 0 | M14: =WACC!O14 -> 0 | N14: =WACC!P14 -> 0 | O14: =WACC!Q14 -> 0
B15: =WACC!B15 -> 0 | D15: =WACC!E15 -> 0 | F15: =WACC!G15 -> 0 | G15: =WACC!H15 -> 0 | H15: =WACC!I15 -> 0 | I15: =WACC!J15 -> 0 | J15: =WACC!K15 -> 0 | K15: =WACC!M15 -> 0 | M15: =WACC!O15 -> 0 | N15: =WACC!P15 -> 0 | O15: =WACC!Q15 -> 0
B16: =WACC!B16 -> 0 | D16: =WACC!E16 -> 0 | F16: =WACC!G16 -> 0 | G16: =WACC!H16 -> 0 | H16: =WACC!I16 -> 0 | I16: =WACC!J16 -> 0 | J16: =WACC!K16 -> 0 | K16: =WACC!M16 -> 0 | M16: =WACC!O16 -> 0 | N16: =WACC!P16 -> 0 | O16: =WACC!Q16 -> 0
B17: =WACC!B17 -> 0 | D17: =WACC!E17 -> 0 | F17: =WACC!G17 -> 0 | G17: =WACC!H17 -> 0 | H17: =WACC!I17 -> 0 | I17: =WACC!J17 -> 0 | J17: =WACC!K17 -> 0 | K17: =WACC!M17 -> 0 | M17: =WACC!O17 -> 0 | N17: =WACC!P17 -> 0 | O17: =WACC!Q17 -> 0
... B30: =WACC!B30 -> 0 | D30: =WACC!E30 -> 0 | F30: =WACC!G30 -> 0 | G30: =WACC!H30 -> 0 | H30: =WACC!I30 -> 0 | I30: =WACC!J30 -> 0 | J30: =WACC!K30 -> 0 | K30: =WACC!M30 -> 0 | M30: =WACC!O30 -> 0 | N30: =WACC!P30 -> 0 | O30: =WACC!Q30 -> 0
B32: Maximum | F32: =MAX(F6:F14) -> 1.245976 | J32: =MAX(J6:J14) -> 0.67306377 | K32: =MAX(K6:K14) -> 0.40229415 | N32: =MAX(N6:N14) -> 1.2453039 | O32: =MAX(O6:O14) -> 1.2453039
B33: Average | F33: =AVERAGE(F6:F14) -> 0.52909336 | J33: =AVERAGE(J6:J14) -> 0.15072003 | K33: =AVERAGE(K6:K14) -> 0.094335138 | N33: =AVERAGE(N6:N14) -> 0.47685025 | O33: =AVERAGE(O6:O14) -> 0.47685025
B34: Median | F34: =MEDIAN(F6:F14) -> 0.612323 | J34: =MEDIAN(J6:J14) -> 0.00071198148 | K34: =MEDIAN(K6:K14) -> 0.00071147493 | N34: =MEDIAN(N6:N14) -> 0.58823161 | O34: =MEDIAN(O6:O14) -> 0.58823161 | S34: : 'Beta' Option (기간) | V34: 0
B35: Minimum | F35: =MIN(F6:F14) -> 0 | J35: =MIN(J6:J14) -> 0 | K35: =MIN(K6:K14) -> 0 | N35: =MIN(N6:N14) -> 0 | O35: =MIN(O6:O14) -> 0
B37: Selected (Median) | K37: =CHOOSE($V$54,K33,K34,0) -> 0.00071147493 | N37: =CHOOSE($V$54,N33,N34,0) -> 0.58823161 | O37: =N37*(1+($K$47/$K$48)*$D$47) -> 0.58823161
V38: 3 | X38: KPMG
B39: Cost of Equity (KE) | X39: Damodaran
S40: : 'Equity Risk Premium' Option (시점) | V40: 0 | X40: Bloomberg
B41: Risk Free Rate | D41: + | F41: Beta | H41: x | J41: Equity Risk Premium | N41: = | O41: Cost of Equity
B42: =WACC!$B$42 -> 0.02065 | F42: =WACC!$E$42 -> 0.71527538 | J42: =WACC!$G$42 -> 0.098446667 | O42: =WACC!$Q$42 -> 0.091066477 | S42: : 'Risk-free Rate' Option (시점) | V42: 0
B44: After-Tax Cost of Debt (KD) | K44: Weighted Average Cost of Capital | V44: 1 | X44: 미적용 | Y44: 0
X45: 3-등급 체계
B46: Pre-Tax Cost of Debt | C46: x | D46: (1 - Tax Rate) | E46: = | F46: After-Tax Cost of Debt | K46: Captial Structure | L46: x | M46: Cost of Capital | N46: = | O46: Contribution | X46: 10-등급 체계
B47: =WACC!$B$47 -> 0.03921 | D47: =WACC!$E$47 -> 0.758 | F47: =WACC!$G$47 -> 0.02972118 | J47: Debt | K47: =WACC!M47 -> 0 | M47: =WACC!O47 -> 0.02972118 | O47: =WACC!Q47 -> 0 | S47: : 'Market Capitalization' Option | V47: 0
J48: Equity | K48: =WACC!M48 -> 1 | M48: =WACC!O48 -> 0.091066477 | O48: =WACC!Q48 -> 0.091066477
M50: WACC | N50: = | O50: =wacc -> 0.091 | S50: : 'Cost of Debt' Option | V50: 1 | X50: Kisline 기업평가등급
B52: Notes: | X52: 회사제시 신용등급
B53: [1] | C53: =WACC!C52 -> 대상회사와 유사한 사업을 영위하고 있는 회사를 선정 | X53: DART 공시 신용등급
B54: [2] | C54: =WACC!C53 -> 2015년 12월 31일 기준, 2년 Weekly adjusted Beta 적용 | S54: : 'Capital Structure' Option | V54: 2 | X54: Average
B55: [3] | C55: =WACC!C54 -> 2015년 12월 31일 기준, 과거 1개월 평균 시가총액 적용 | X55: Median
B56: [4] | C56: =WACC!C55 -> 2015년 9월 30일 기준 이자발생부채 적용 | X56: 무부채기업 가정
B57: [5] | C57: =WACC!C56 -> 2015년 12월 31일 기준, 과거 1개월 평균 10년 만기 국공채 이자율 적용 (Source: Bloomberg)
...

Sheet _TM_GPCM_Tier1 (2)
A1: Left | B1: Top | C1: Right | D1: Bottom | E1: Ref
A2: 2 | B2: 101 | C2: 7 | D2: 292 | E2: $B$101:$G$292

Sheet _TM_매출액
A1: Left | B1: Top | C1: Right | D1: Bottom | E1: Ref
A2: 2 | B2: 24 | C2: 14 | D2: 24 | E2: $B$24:$N$24

Sheet GTM
B1: ="Project"&" "&Title!L6 -> Project IT | M1: DRAFT - For Discussion Purposes Only
B2: Guideline Transaction Method
B4: Announce Date | C4: Target Company | D4: Bidder Company | E4: Seller Company | F4: Deal Price (KRW Mil) | G4: Acquisition Ratio | H4: Enterprise Value | I4: Equity Value | J4: NI | K4: EBITDA | L4: Multiples | M4: Multiples
G5: Ratio | H5: of Equity(MM) | I5: of Equity(MM) | J5: EV(MM) | K5: EV(MM) | L5: PER | M5: EV/EBITDA
B6: 10/30/2015 | C6: 아남정보기술 | D6: KESS | E6: 유한회사 아남 외 8인 | F6: 15000 | G6: 0.3812 | H6: 37885.917 | I6: 39349.423 | J6: 1237.5475 | K6: -389.07777 | L6: =I6/J6 -> 31.796293 | M6: =IF(OR(ISERROR(H6/K6),H6/K6<0),"n.a.",H6/K6) -> n.a.
B7: 09/30/2015 | C7: 코마스 | D7: 대우정보시스템 | F7: 4432.5366 | G7: 0.1027 | H7: 83274.661 | I7: 43160.045 | J7: 2371.6499 | K7: 7095.7919 | L7: =I7/J7 -> 18.198321 | M7: =IF(OR(ISERROR(H7/K7),H7/K7<0),"n.a.",H7/K7) -> 11.735781
B8: 05/15/2015 | C8: 코마스 | D8: 대우정보시스템 | F8: 20120 | G8: 0.5442 | H8: 77086.318 | I8: 36971.702 | J8: 2371.6499 | K8: 7095.7919 | L8: =I8/J8 -> 15.589022 | M8: =IF(OR(ISERROR(H8/K8),H8/K8<0),"n.a.",H8/K8) -> 10.863667
B9: 04/22/2015 | C9: 대림 I&S | D9: 대림코퍼레이션 | F9: 129866.84 | G9: 1 | H9: 229248.17 | I9: 129866.84 | J9: 15706.014 | K9: 22336.82 | L9: =I9/J9 -> 8.2686058 | M9: =IF(OR(ISERROR(H9/K9),H9/K9<0),"n.a.",H9/K9) -> 10.263241
B10: 09/28/2011 | C10: 코오롱아이넷 | D10: 코오롱건설 | F10: 113666.75 | G10: 1 | H10: 359674.81 | I10: 113666.75 | J10: 16261.359 | K10: 27272.191 | L10: =I10/J10 -> 6.9899907 | M10: =IF(OR(ISERROR(H10/K10),H10/K10<0),"n.a.",H10/K10) -> 13.188335
G12: Guideline Transaction Method
G13: Transaction Multiple | M13: EV/EBITDA
G14: Median | M14: =MEDIAN(M$6:M$10) -> 11.299724
G15: Mean | M15: =AVERAGE(M$6:M$10) -> 11.512756
G17: Comparable Transaction Method
G18: Multiple | M18: EV/EBITDA
G19: Minimum | M19: =MIN(M6:M10) -> 10.263241
G20: Maxamum | M20: =MAX(M6:M10) -> 13.188335
G22: Company Financials | M22: EBITDA
G23: 대상회사 | M23: ='GPCM '!S30 -> 10451.112
G25: Enterprise Value | O25: Enterprise Value
G26: =G19 -> Minimum | M26: =M19*M23 -> 107262.28 | O26: Median | R26: =M14*$M$23 -> 118094.67
G27: =G20 -> Maxamum | M27: =M23*M20 -> 137832.77 | O27: Mean | R27: =M15*$M$23 -> 120321.1
G31: Net Debt | M31: ='GPCM '!S40 -> -16984.526 | O31: Net Debt | R31: =M31 -> -16984.526
G34: 주식가치 | M34: KRW Millions | O34: 주식가치 | R34: KRW Millions
G35: =G26 -> Minimum | M35: =M26-$M$31 -> 124246.8 | O35: Median | R35: =R26-$M$31 -> 135079.2
G36: =G27 -> Maxamum | M36: =M27-$M$31 -> 154817.29 | O36: Mean | R36: =R27-$M$31 -> 137305.62
G41: Guideline Public Company Method | L41: Guideline Public Company Method
G42: Multiple | J42: PER | L42: Multiple | O42: PER
G43: Minimum | J43: =MIN(L6:L10) -> 6.9899907 | L43: Mean | O43: =AVERAGE(L6:L10) -> 16.168446
G44: Maxamum | J44: =MAX(L6:L10) -> 31.796293 | L44: Median | O44: =MEDIAN(L6:L10) -> 15.589022
G47: Company Financials | J47: NI | L47: Company Financials | O47: NI
G48: 대상회사 | J48: =7430802379/1000000 -> 7430.8024 | L48: 대상회사 | O48: =J48 -> 7430.8024
G50: 주식가치 | J50: KRW Millions | L50: 주식가치 | O50: KRW Millions
G51: =G43 -> Minimum | J51: =J43*J48 -> 51941.24 | L51: =L43 -> Mean | O51: =O43*O48 -> 120144.53
G52: =G44 -> Maxamum | J52: =J48*J44 -> 236271.97 | L52: =L44 -> Median | O52: =O48*O44 -> 115838.94

Sheet GPCM 
B1: ="Project"&" "&Title!L6 -> Project IT
B2: Guideline Public Company Method
B4: Guideline Public Company | C4: Ticker | D4: Country | E4: Currency (Millions) | F4: MKT Cap | G4: Minority Interest | H4: Net Debt | I4: Enterprise Value | J4: LTM | P4: Multiples | W4: 2016 Consensus | AA4: Multiples | AF4: 2017 Consensus | AJ4: Multiples
I5: of Equity(MM) | J5: BV | K5: Sales | L5: EBIT | M5: Dep. | N5: EBITDA | O5: Net Income | P5: PBR | Q5: EV/Sales | R5: EV/EBIT | S5: EV/EBITDA | T5: PER | W5: Sales | X5: EBIT | Y5: EBITDA | Z5: Net Income | AA5: EV/Sales | AB5: EV/EBIT | AC5: EV/EBITDA | AD5: PER | AF5: Sales | AG5: EBIT | AH5: EBITDA | AI5: Net Income | AJ5: EV/Sales | AK5: EV/EBIT | AL5: EV/EBITDA | AM5: PER
A6: 1 | B6: =WACC!B6 -> SAMSUNG SDS CO LTD | C6: 018260 KS Equity | D6: SOUTH KOREA | E6: KRW | F6: =IF(B6="","",WACC!I6) -> 20173498 | G6: =유사기업BS!C6 -> 170549.24 | H6: =유사기업BS!C4-유사기업BS!C3 -> -1780558.2 | I6: =F6+G6+H6 -> 18563489 | J6: =유사기업BS!C5 -> 4558746.8 | K6: =유사기업IS!C3 -> 7917776.1 | L6: =유사기업IS!C4 -> 601086.15 | M6: =유사기업IS!C5 -> 387759.73 | N6: =L6+M6 -> 988845.89 | O6: =유사기업IS!C6 -> 463627 | P6: =IF(OR(ISERROR(F6/J6),F6/J6<0),"n.a.",F6/J6) -> 4.4252289 | Q6: =IF(OR(ISERROR(I6/K6),I6/K6<0),"n.a.",I6/K6) -> 2.3445332 | R6: =IF(OR(ISERROR(I6/L6),I6/L6<0),"n.a.",I6/L6) -> 30.883242 | S6: =IF(OR(ISERROR(I6/N6),I6/N6<0),"n.a.",I6/N6) -> 18.772884 | T6: =IF(OR(ISERROR(F6/O6),F6/O6<0),"n.a.",F6/O6) -> 43.512345 | W6: =8674492550000/10^6 -> 8674492.6 | X6: =665470428571.429/10^6 -> 665470.43 | Y6: =1053360500000/10^6 -> 1053360.5 | Z6: =486456190476.19/10^6 -> 486456.19 | AA6: =IF(OR(ISERROR($I6/W6),$I6/W6<0),"n.a.",$I6/W6) -> 2.1400086 | AB6: =IF(OR(ISERROR($I6/X6),$I6/X6<0),"n.a.",$I6/X6) -> 27.895287 | AC6: =IF(OR(ISERROR($I6/Y6),$I6/Y6<0),"n.a.",$I6/Y6) -> 17.623111 | AD6: =IF(OR(ISERROR($F6/Z6),$F6/Z6<0),"n.a.",$F6/Z6) -> 41.470328 | AF6: =9637008578947.37/10^6 -> 9637008.6 | AG6: =740004571428.571/10^6 -> 740004.57 | AH6: =1141142789473.68/10^6 -> 1141142.8 | AI6: =545924900000/10^6 -> 545924.9 | AJ6: =IF(OR(ISERROR($I6/AF6),$I6/AF6<0),"n.a.",$I6/AF6) -> 1.9262709 | AK6: =IF(OR(ISERROR($I6/AG6),$I6/AG6<0),"n.a.",$I6/AG6) -> 25.085641 | AL6: =IF(OR(ISERROR($I6/AH6),$I6/AH6<0),"n.a.",$I6/AH6) -> 16.267455 | AM6: =IF(OR(ISERROR($F6/AI6),$F6/AI6<0),"n.a.",$F6/AI6) -> 36.952881
A7: =A6+1 -> 2 | B7: =WACC!B7 -> POSCO ICT CO LTD | C7: 022100 KS Equity | D7: SOUTH KOREA | E7: KRW | F7: =IF(B7="","",WACC!I7) -> 749314.02 | G7: =유사기업BS!K6 -> 1131.9434 | H7: =유사기업BS!K4-유사기업BS!K3 -> -27378.177 | I7: =F7+G7+H7 -> 723067.79 | J7: =유사기업BS!K5 -> 376233.16 | K7: =유사기업IS!O3 -> 951600.58 | L7: =유사기업IS!O4 -> 38347.109 | M7: =유사기업IS!O5 -> 38482.437 | N7: =L7+M7 -> 76829.546 | O7: =유사기업IS!O6 -> -2601.83 | P7: =IF(OR(ISERROR(F7/J7),F7/J7<0),"n.a.",F7/J7) -> 1.9916214 | Q7: =IF(OR(ISERROR(I7/K7),I7/K7<0),"n.a.",I7/K7) -> 0.75984378 | R7: =IF(OR(ISERROR(I7/L7),I7/L7<0),"n.a.",I7/L7) -> 18.855862 | S7: =IF(OR(ISERROR(I7/N7),I7/N7<0),"n.a.",I7/N7) -> 9.4113245 | T7: =IF(OR(ISERROR(F7/O7),F7/O7<0),"n.a.",F7/O7) -> n.a. | W7: =971000000000/10^6 -> 971000 | X7: n.a. | Y7: =85000000000/10^6 -> 85000 | Z7: =33000000000/10^6 -> 33000 | AA7: =IF(OR(ISERROR($I7/W7),$I7/W7<0),"n.a.",$I7/W7) -> 0.74466301 | AC7: =IF(OR(ISERROR($I7/Y7),$I7/Y7<0),"n.a.",$I7/Y7) -> 8.5066799 | AD7: =IF(OR(ISERROR($F7/Z7),$F7/Z7<0),"n.a.",$F7/Z7) -> 22.706486 | AF7: =1010000000000/10^6 -> 1010000 | AG7: n.a. | AH7: =88000000000/10^6 -> 88000 | AI7: =40000000000/10^6 -> 40000 | AJ7: =IF(OR(ISERROR($I7/AF7),$I7/AF7<0),"n.a.",$I7/AF7) -> 0.7159087 | AL7: =IF(OR(ISERROR($I7/AH7),$I7/AH7<0),"n.a.",$I7/AH7) -> 8.2166794 | AM7: =IF(OR(ISERROR($F7/AI7),$F7/AI7<0),"n.a.",$F7/AI7) -> 18.732851
A8: =A7+1 -> 3 | B8: =WACC!B8 -> DONGBU CO LTD | C8: 012030 KS Equity | D8: SOUTH KOREA | E8: KRW | F8: =IF(B8="","",WACC!I8) -> 89137.821 | G8: =유사기업BS!S6 -> 0 | H8: =유사기업BS!S4-유사기업BS!S3 -> 55162.137 | I8: =F8+G8+H8 -> 144299.96 | J8: =유사기업BS!S5 -> 188299.55 | K8: =유사기업IS!AA3 -> 228679.86 | L8: =유사기업IS!AA4 -> -6547.3502 | M8: =유사기업IS!AA5 -> 4496.6716 | N8: =L8+M8 -> -2050.6787 | O8: =유사기업IS!AA6 -> -30195.535 | P8: =IF(OR(ISERROR(F8/J8),F8/J8<0),"n.a.",F8/J8) -> 0.47338308 | Q8: =IF(OR(ISERROR(I8/K8),I8/K8<0),"n.a.",I8/K8) -> 0.63101296 | R8: =IF(OR(ISERROR(I8/L8),I8/L8<0),"n.a.",I8/L8) -> n.a. | S8: =IF(OR(ISERROR(I8/N8),I8/N8<0),"n.a.",I8/N8) -> n.a. | T8: =IF(OR(ISERROR(F8/O8),F8/O8<0),"n.a.",F8/O8) -> n.a. | W8: n.a. | X8: n.a. | Y8: n.a. | Z8: n.a. | AF8: n.a. | AG8: n.a. | AH8: n.a. | AI8: n.a.
A9: =A8+1 -> 4 | B9: =WACC!B9 -> SHINSEGAE INFORMATION & COMM | C9: 035510 KS Equity | D9: SOUTH KOREA | E9: KRW | F9: =IF(B9="","",WACC!I9) -> 168289.72 | G9: =유사기업BS!AA6 -> 0 | H9: =유사기업BS!AA4-유사기업BS!AA3 -> -94207.52 | I9: =F9+G9+H9 -> 74082.197 | J9: =유사기업BS!AA5 -> 168494.1 | K9: =유사기업IS!AM3 -> 256320 | L9: =유사기업IS!AM4 -> 15541.51 | M9: =유사기업IS!AM5 -> 5762.1324 | N9: =L9+M9 -> 21303.642 | O9: =유사기업IS!AM6 -> 10573.583 | P9: =IF(OR(ISERROR(F9/J9),F9/J9<0),"n.a.",F9/J9) -> 0.99878698 | Q9: =IF(OR(ISERROR(I9/K9),I9/K9<0),"n.a.",I9/K9) -> 0.2890223 | R9: =IF(OR(ISERROR(I9/L9),I9/L9<0),"n.a.",I9/L9) -> 4.766731 | S9: =IF(OR(ISERROR(I9/N9),I9/N9<0),"n.a.",I9/N9) -> 3.4774428 | T9: =IF(OR(ISERROR(F9/O9),F9/O9<0),"n.a.",F9/O9) -> 15.916053 | W9: =268000000000/10^6 -> 268000 | X9: =16100000000/10^6 -> 16100 | Y9: =22900000000/10^6 -> 22900 | Z9: =11600000000/10^6 -> 11600 | AA9: =IF(OR(ISERROR($I9/W9),$I9/W9<0),"n.a.",$I9/W9) -> 0.27642611 | AB9: =IF(OR(ISERROR($I9/X9),$I9/X9<0),"n.a.",$I9/X9) -> 4.6013787 | AC9: =IF(OR(ISERROR($I9/Y9),$I9/Y9<0),"n.a.",$I9/Y9) -> 3.2350304 | AD9: =IF(OR(ISERROR($F9/Z9),$F9/Z9<0),"n.a.",$F9/Z9) -> 14.507734 | AF9: =283000000000/10^6 -> 283000 | AG9: =22700000000/10^6 -> 22700 | AH9: =29600000000/10^6 -> 29600 | AI9: =15800000000/10^6 -> 15800 | AJ9: =IF(OR(ISERROR($I9/AF9),$I9/AF9<0),"n.a.",$I9/AF9) -> 0.26177455 | AK9: =IF(OR(ISERROR($I9/AG9),$I9/AG9<0),"n.a.",$I9/AG9) -> 3.2635329 | AL9: =IF(OR(ISERROR($I9/AH9),$I9/AH9<0),"n.a.",$I9/AH9) -> 2.5027769 | AM9: =IF(OR(ISERROR($F9/AI9),$F9/AI9<0),"n.a.",$F9/AI9) -> 10.651248
A10: =A9+1 -> 5 | B10: =WACC!B10 -> HYUNDAI INFORMATION TECH | C10: 026180 KS Equity | D10: SOUTH KOREA | E10: KRW | F10: =IF(B10="","",WACC!I10) -> 116521.65 | G10: =유사기업BS!AI6 -> 0 | H10: =유사기업BS!AI4-유사기업BS!AI3 -> 68031.374 | I10: =F10+G10+H10 -> 184553.03 | J10: =유사기업BS!AI5 -> 25725.035 | K10: =유사기업IS!AY3 -> 145026.31 | L10: =유사기업IS!AY4 -> -1078.9798 | M10: =유사기업IS!AY5 -> 8540.6252 | N10: =L10+M10 -> 7461.6454 | O10: =유사기업IS!AY6 -> -3956.2171 | P10: =IF(OR(ISERROR(F10/J10),F10/J10<0),"n.a.",F10/J10) -> 4.5295042 | Q10: =IF(OR(ISERROR(I10/K10),I10/K10<0),"n.a.",I10/K10) -> 1.2725487 | R10: =IF(OR(ISERROR(I10/L10),I10/L10<0),"n.a.",I10/L10) -> n.a. | S10: =IF(OR(ISERROR(I10/N10),I10/N10<0),"n.a.",I10/N10) -> 24.733557 | T10: =IF(OR(ISERROR(F10/O10),F10/O10<0),"n.a.",F10/O10) -> n.a. | W10: n.a. | X10: n.a. | Y10: n.a. | Z10: n.a. | AF10: n.a. | AG10: n.a. | AH10: n.a. | AI10: n.a.
A11: =A10+1 -> 6 | B11: =WACC!B11 -> HANIL NETWORKS CO LTD | C11: 046110 KS Equity | D11: SOUTH KOREA | E11: KRW | F11: =IF(B11="","",WACC!I11) -> 34610.335 | G11: =유사기업BS!AQ6 -> 26.040324 | H11: =유사기업BS!AQ4-유사기업BS!AQ3 -> -8787.8654 | I11: =F11+G11+H11 -> 25848.51 | J11: =유사기업BS!AQ5 -> 32002.201 | K11: =유사기업IS!BK3 -> 92527.773 | L11: =유사기업IS!BK4 -> 557.12668 | M11: =유사기업IS!BK5 -> 3634.339 | N11: =L11+M11 -> 4191.4657 | O11: =유사기업IS!BK6 -> 3115.3806 | P11: =IF(OR(ISERROR(F11/J11),F11/J11<0),"n.a.",F11/J11) -> 1.0814986 | Q11: =IF(OR(ISERROR(I11/K11),I11/K11<0),"n.a.",I11/K11) -> 0.27935947 | R11: =IF(OR(ISERROR(I11/L11),I11/L11<0),"n.a.",I11/L11) -> 46.396108 | S11: =IF(OR(ISERROR(I11/N11),I11/N11<0),"n.a.",I11/N11) -> 6.1669381 | T11: =IF(OR(ISERROR(F11/O11),F11/O11<0),"n.a.",F11/O11) -> 11.109505 | W11: n.a. | X11: n.a. | Y11: n.a. | Z11: n.a. | AF11: n.a. | AG11: n.a. | AH11: n.a. | AI11: n.a.
A12: =A11+1 -> 7
A13: =A12+1 -> 8
A14: =A13+1 -> 9
A15: =A14+1 -> 10
A16: =A15+1 -> 11
A17: =A16+1 -> 12
A18: =A17+1 -> 13
A19: =A18+1 -> 14
A20: =A19+1 -> 15
A21: =A20+1 -> 16
A22: =A21+1 -> 17
M24: 1 | N24: Guideline Public Company Method | Y24: Guideline Public Company Method | AH24: Guideline Public Company Method
N25: Multiples | P25: PBR | Q25: EV/Sales | R25: EV/EBIT | S25: EV/EBITDA | T25: PER | Y25: Multiples | AA25: EV/Sales | AB25: EV/EBIT | AC25: EV/EBITDA | AD25: PER | AH25: Multiples | AJ25: EV/Sales | AK25: EV/EBIT | AL25: EV/EBITDA | AM25: PER
N26: Median | P26: =MEDIAN(P6:P11) -> 1.53656 | Q26: =MEDIAN(Q6:Q11) -> 0.69542837 | R26: =MEDIAN(R6:R11) -> 24.869552 | S26: =MEDIAN(S6:S11) -> 9.4113245 | T26: =MEDIAN(T6:T11) -> 15.916053 | Y26: Median | AA26: =MEDIAN(AA6:AA11) -> 0.74466301 | AB26: =MEDIAN(AB6:AB11) -> 16.248333 | AC26: =MEDIAN(AC6:AC11) -> 8.5066799 | AD26: =MEDIAN(AD6:AD11) -> 22.706486 | AH26: Median | AJ26: =MEDIAN(AJ6:AJ11) -> 0.7159087 | AK26: =MEDIAN(AK6:AK11) -> 14.174587 | AL26: =MEDIAN(AL6:AL11) -> 8.2166794 | AM26: =MEDIAN(AM6:AM11) -> 18.732851
N27: Mean | P27: =AVERAGE(P6:P11) -> 2.2500039 | Q27: =AVERAGE(Q6:Q11) -> 0.92938673 | R27: =AVERAGE(R6:R11) -> 25.225486 | S27: =AVERAGE(S6:S11) -> 12.512429 | T27: =AVERAGE(T6:T11) -> 23.512634 | Y27: Mean | AA27: =AVERAGE(AA6:AA11) -> 1.0536992 | AB27: =AVERAGE(AB6:AB11) -> 16.248333 | AC27: =AVERAGE(AC6:AC11) -> 9.7882737 | AD27: =AVERAGE(AD6:AD11) -> 26.228183 | AH27: Mean | AJ27: =AVERAGE(AJ6:AJ11) -> 0.96798471 | AK27: =AVERAGE(AK6:AK11) -> 14.174587 | AL27: =AVERAGE(AL6:AL11) -> 8.9956371 | AM27: =AVERAGE(AM6:AM11) -> 22.112326
N29: Company Financials | P29: Book Value | Q29: Sales | R29: EBIT | S29: EBITDA | T29: Net Income | Y29: Company Financials | AA29: Sales | AB29: EBIT | AC29: EBITDA | AD29: Net Income | AH29: Company Financials | AJ29: Sales | AK29: EBIT | AL29: EBITDA | AM29: Net Income
N30: 대상회사 | P30: =BS!O77 -> 41343.829 | Q30: =IS!O7 -> 214888.12 | R30: =IS!O45 -> 9727.2909 | S30: =IS!O68 -> 10451.112 | T30: =IS!O66 -> 7612.9499 | Y30: 대상회사 | AH30: 대상회사
N32: Enterprise Value | P32: PBR | Q32: EV/Sales | R32: EV/EBIT | S32: EV/EBITDA | T32: PER | Y32: Enterprise Value | AA32: EV/Sales | AB32: EV/EBIT | AC32: EV/EBITDA | AD32: PER | AH32: Enterprise Value | AJ32: EV/Sales | AK32: EV/EBIT | AL32: EV/EBITDA | AM32: PER
N33: Median | P33: n.a. | Q33: =Q26*Q$30 -> 149439.3 | R33: =R26*R$30 -> 241913.37 | S33: =S26*S$30 -> 98358.803 | T33: n.a. | Y33: Median | AA33: =AA26*AA$30 -> 0 | AB33: =AB26*AB$30 -> 0 | AC33: =AC26*AC$30 -> 0 | AD33: n.a. | AH33: Median | AJ33: =AJ26*AJ$30 -> 0 | AK33: =AK26*AK$30 -> 0 | AL33: =AL26*AL$30 -> 0 | AM33: n.a.
N34: Mean | P34: n.a. | Q34: =Q27*Q$30 -> 199714.17 | R34: =R27*R$30 -> 245375.64 | S34: =S27*S$30 -> 130768.79 | T34: n.a. | Y34: Mean | AA34: =AA27*AA$30 -> 0 | AB34: =AB27*AB$30 -> 0 | AC34: =AC27*AC$30 -> 0 | AD34: n.a. | AH34: Mean | AJ34: =AJ27*AJ$30 -> 0 | AK34: =AK27*AK$30 -> 0 | AL34: =AL27*AL$30 -> 0 | AM34: n.a.
N36: NOA | S36: ='NOA&IBD'!E13 -> 16984.526 | Y36: NOA | AH36: NOA
N38: IBD | S38: ='NOA&IBD'!E20 -> 0 | Y38: IBD | AH38: IBD
N40: Net Debt | S40: =S38-S36 -> -16984.526 | Y40: Net Debt | AC40: =AC38-AC36 -> 0 | AH40: Net Debt | AL40: =AL38-AL36 -> 0
N42: Equity Value | P42: PBR | Q42: EV/Sales | R42: EV/EBIT | S42: EV/EBITDA | T42: PER | Y42: Equity Value | AA42: EV/Sales | AB42: EV/EBIT | AC42: EV/EBITDA | AD42: PER | AH42: Equity Value | AJ42: EV/Sales | AK42: EV/EBIT | AL42: EV/EBITDA | AM42: PER
N43: Median | P43: =P26*P$30 -> 63527.274 | Q43: =Q33-$S$40 -> 166423.82 | R43: =R33-$S$40 -> 258897.89 | S43: =S33-$S$40 -> 115343.33 | T43: =T26*T$30 -> 121168.12 | Y43: Median | AA43: =AA33-$S$40 -> 16984.526 | AB43: =AB33-$S$40 -> 16984.526 | AC43: =AC33-$S$40 -> 16984.526 | AD43: =AD26*AD$30 -> 0 | AH43: Median | AJ43: =AJ33-$S$40 -> 16984.526 | AK43: =AK33-$S$40 -> 16984.526 | AL43: =AL33-$S$40 -> 16984.526 | AM43: =AM26*AM$30 -> 0
N44: Mean | P44: =P27*P$30 -> 93023.775 | Q44: =Q34-$S$40 -> 216698.7 | R44: =R34-$S$40 -> 262360.16 | S44: =S34-$S$40 -> 147753.32 | T44: =T27*T$30 -> 179000.51 | Y44: Mean | AA44: =AA34-$S$40 -> 16984.526 | AB44: =AB34-$S$40 -> 16984.526 | AC44: =AC34-$S$40 -> 16984.526 | AD44: =AD27*AD$30 -> 0 | AH44: Mean | AJ44: =AJ34-$S$40 -> 16984.526 | AK44: =AK34-$S$40 -> 16984.526 | AL44: =AL34-$S$40 -> 16984.526 | AM44: =AM27*AM$30 -> 0

Sheet DCF
B1: ="Project"&" "&Title!L6 -> Project IT | N1: =Des!C12 -> DRAFT - For Discussion Purposes Only
B2: Discounted Cash Flow Results
B4: DCF Results | D4: Historical | H4: Forecasted
B5: =unit -> KRW Millions | D5: ='Pro forma'!E5 -> 2012 | E5: ='Pro forma'!F5 -> 2013 | F5: ='Pro forma'!G5 -> 2014 | G5: ='Pro forma'!H5 -> 2015/12A | H5: ='Pro forma'!I5 -> 2015/0E | I5: ='Pro forma'!K5 -> 2016 | J5: ='Pro forma'!L5 -> 2017 | K5: ='Pro forma'!M5 -> 2018 | L5: ='Pro forma'!N5 -> 2019 | M5: ='Pro forma'!O5 -> 2020 | N5: Terminal
B6: 매출액 | D6: ='Pro forma'!E6 -> 182279.27 | E6: ='Pro forma'!F6 -> 211683.37 | F6: ='Pro forma'!G6 -> 251810.75 | G6: ='Pro forma'!H6 -> 214888.12 | I6: ='Pro forma'!K6 -> 247657.65 | J6: ='Pro forma'!L6 -> 256222.03 | K6: ='Pro forma'!M6 -> 265319.19 | L6: ='Pro forma'!N6 -> 274730.7 | M6: ='Pro forma'!O6 -> 284669.53 | N6: =M6*(1+$C$24) -> 284669.53
B7: 매출원가 | D7: ='Pro forma'!E9 -> 165640.96 | E7: ='Pro forma'!F9 -> 194029.19 | F7: ='Pro forma'!G9 -> 233681.98 | G7: ='Pro forma'!H9 -> 193423.41 | I7: ='Pro forma'!K9 -> 225185.42 | J7: ='Pro forma'!L9 -> 233133.63 | K7: ='Pro forma'!M9 -> 241478.05 | L7: ='Pro forma'!N9 -> 250207.65 | M7: ='Pro forma'!O9 -> 259472.68 | N7: =M7*(1+$C$24) -> 259472.68
B8: 매출총이익 | D8: =D6-D7 -> 16638.31 | E8: =E6-E7 -> 17654.178 | F8: =F6-F7 -> 18128.765 | G8: =G6-G7 -> 21464.712 | I8: =I6-I7 -> 22472.232 | J8: =J6-J7 -> 23088.4 | K8: =K6-K7 -> 23841.136 | L8: =L6-L7 -> 24523.055 | M8: =M6-M7 -> 25196.85 | N8: =N6-N7 -> 25196.85
B9: 판매비와관리비 | D9: ='Pro forma'!E17 -> 7996.3669 | E9: ='Pro forma'!F17 -> 8441.2134 | F9: ='Pro forma'!G17 -> 8664.1025 | G9: ='Pro forma'!H17 -> 11711.818 | I9: ='Pro forma'!K17 -> 11720.924 | J9: ='Pro forma'!L17 -> 12255.522 | K9: ='Pro forma'!M17 -> 12744.482 | L9: ='Pro forma'!N17 -> 13187.062 | M9: ='Pro forma'!O17 -> 13753.785 | N9: =M9*(1+$C$24) -> 13753.785
B10: 영업이익 | D10: =D8-D9 -> 8641.9429 | E10: =E8-E9 -> 9212.9645 | F10: =F8-F9 -> 9464.6625 | G10: =G8-G9 -> 9752.8942 | I10: =I8-I9 -> 10751.308 | J10: =J8-J9 -> 10832.877 | K10: =K8-K9 -> 11096.654 | L10: =L8-L9 -> 11335.993 | M10: =M8-M9 -> 11443.066 | N10: =N8-N9 -> 11443.066
B11: 법인세비용 | I11: =IF(I10>200,IF(I10>20000,200*가정!$E$62+(20000-200)*가정!$E$65+(I10-20000)*가정!$E$68,200*가정!$E$62+(I10-200)*가정!$E$65),IF(I10<0,0,I10*가정!$E$62)) -> 2343.2877 | J11: =IF(J10>200,IF(J10>20000,200*가정!$E$62+(20000-200)*가정!$E$65+(J10-20000)*가정!$E$68,200*가정!$E$62+(J10-200)*가정!$E$65),IF(J10<0,0,J10*가정!$E$62)) -> 2361.233 | K11: =IF(K10>200,IF(K10>20000,200*가정!$E$62+(20000-200)*가정!$E$65+(K10-20000)*가정!$E$68,200*가정!$E$62+(K10-200)*가정!$E$65),IF(K10<0,0,K10*가정!$E$62)) -> 2419.264 | L11: =IF(L10>200,IF(L10>20000,200*가정!$E$62+(20000-200)*가정!$E$65+(L10-20000)*가정!$E$68,200*가정!$E$62+(L10-200)*가정!$E$65),IF(L10<0,0,L10*가정!$E$62)) -> 2471.9185 | M11: =IF(M10>200,IF(M10>20000,200*가정!$E$62+(20000-200)*가정!$E$65+(M10-20000)*가정!$E$68,200*가정!$E$62+(M10-200)*가정!$E$65),IF(M10<0,0,M10*가정!$E$62)) -> 2495.4744 | N11: =IF(N10>200,IF(N10>20000,200*가정!$E$62+(20000-200)*가정!$E$65+(N10-20000)*가정!$E$68,200*가정!$E$62+(N10-200)*가정!$E$65),IF(N10<0,0,N10*가정!$E$62)) -> 2495.4744
B12: 세후영업이익 | I12: =I10-I11 -> 8408.0199 | J12: =J10-J11 -> 8471.6443 | K12: =K10-K11 -> 8677.3904 | L12: =L10-L11 -> 8864.0748 | M12: =M10-M11 -> 8947.5911 | N12: =N10-N11 -> 8947.5911
B13: 가산: 감가상각비 | I13: ='CapEx&Dep'!K7 -> 945.31832 | J13: ='CapEx&Dep'!L7 -> 1265.9716 | K13: ='CapEx&Dep'!M7 -> 1562.7974 | L13: ='CapEx&Dep'!N7 -> 1823.8785 | M13: ='CapEx&Dep'!O7 -> 2179.7868 | N13: =CapEx
B14: 차감: 순운전자본의 변동 | I14: =WC!K19 -> -6765.6418 | J14: =WC!L19 -> 388.93767 | K14: =WC!M19 -> 416.56031 | L14: =WC!N19 -> 409.05387 | M14: =WC!O19 -> 421.45988 | N14: =WC!P19 -> 421.45988
B15: 차감: 자본적지출 | I15: ='CapEx&Dep'!K6 -> 1048.6801 | J15: ='CapEx&Dep'!L6 -> 1084.945 | K15: ='CapEx&Dep'!M6 -> 1123.466 | L15: ='CapEx&Dep'!N6 -> 1163.3181 | M15: ='CapEx&Dep'!O6 -> 1205.403 | N15: =Dep
B16: 추정영업현금흐름 (FCFF) | I16: =I12+I13-I14-I15 -> 15070.3 | J16: =J12+J13-J14-J15 -> 8263.7332 | K16: =K12+K13-K14-K15 -> 8700.1614 | L16: =L12+L13-L14-L15 -> 9115.5814 | M16: =M12+M13-M14-M15 -> 9500.515 | N16: =N12-N14 -> 8526.1312
B17: 할인기간 | I17: =ppf -> 1.0027397 | J17: =I17+1 -> 2.0027397 | K17: =J17+1 -> 3.0027397 | L17: =K17+1 -> 4.0027397 | M17: =L17+1 -> 5.0027397 | N17: =M17 -> 5.0027397
B18: 할인계수 | I18: =1/(1+$C$25)^I17 -> 0.9163716 | J18: =1/(1+$C$25)^J17 -> 0.8399373 | K18: =1/(1+$C$25)^K17 -> 0.76987837 | L18: =1/(1+$C$25)^L17 -> 0.70566303 | M18: =1/(1+$C$25)^M17 -> 0.64680388 | N18: =1/(1+$C$25)^N17 -> 0.64680388
B19: FCFF의 현재가치 | I19: =I16*I18 -> 13809.995 | J19: =J16*J18 -> 6941.0177 | K19: =K16*K18 -> 6698.0661 | L19: =L16*L18 -> 6432.5288 | M19: =M16*M18 -> 6144.97 | N19: =N18*N16/(C25-C24) -> 60601.481
B20: 누적현재가치 | I20: =SUM(I19:M19) -> 40026.577
B21: Terminal Value의 현재가치 | I21: =N19 -> 60601.481
B22: Operating Value | I22: =I20+I21 -> 100628.06
B24: Terminal Growth Rate | C24: =g -> 0
B25: WACC | C25: =wacc -> 0.091
B27: Stand-Alone Operating Value
F28: =unit -> KRW Millions
B29: 항목 | D29: 평가결과 | I29: Terminal Growth Rate
D30: 최소값 | E30: 중앙값 | F30: 최대값 | H30: =I22 -> 100628.06 | I30: =J30-CHOOSE($O$33,$P$32,$P$33) -> -0.02 | J30: =K30-CHOOSE($O$33,$P$32,$P$33) -> -0.01 | K30: =g -> 0 | L30: =K30+CHOOSE($O$33,$P$32,$P$33) -> 0.01 | M30: =L30+CHOOSE($O$33,$P$32,$P$33) -> 0.02
B31: 영업가치 (Operating Value) | D31: =J34 -> 86804.575 | E31: =K33 -> 100628.06 | F31: =L32 -> 121908.79 | H31: =H32-CHOOSE($O$33,$P$32,$P$33) -> 0.071 | I31: 109198.71 | J31: 117099.2 | K31: 127225.18 | L31: 140671.15 | M31: 159390.05
B32: 비영업용자산 (Non-operating Asset) | E32: ='NOA&IBD'!E13 -> 16984.526 | H32: =H33-CHOOSE($O$33,$P$32,$P$33) -> 0.081 | I32: 98780.247 | J32: 104795.36 | K32: 112295.69 | L32: 121908.79 | M32: 134673.73 | O32: 민감도 범위 선택 | P32: 0.005
B33: 기업가치 (Enterprise Value) | D33: =D31+$E$32 -> 103789.1 | E33: =E31+$E$32 -> 117612.58 | F33: =F31+$E$32 -> 138893.32 | H33: =wacc -> 0.091 | I33: 90231.93 | J33: 94915.334 | K33: 100628.06 | L33: 107751.33 | M33: 116881.16 | O33: 2 | P33: 0.01
B34: 이자발생부부채 (Interest Bearing Debt) | E34: ='NOA&IBD'!E20 -> 0 | H34: =H33+CHOOSE($O$33,$P$32,$P$33) -> 0.101 | I34: 83090.367 | J34: 86804.575 | K34: 91254.269 | L34: 96681.917 | M34: 103449.73
B35: 비지배지분 | H35: =H34+CHOOSE($O$33,$P$32,$P$33) -> 0.111 | I35: 77033.645 | J35: 80024.891 | K35: 83555.1 | L35: 87784.361 | M35: 92943.129
B36: 주식가치 (Equity Value)_100% 기준 | D36: =D33-$E$34-$E$35 -> 103789.1 | E36: =E33-$E$34-$E$35 -> 117612.58 | F36: =F33-$E$34-$E$35 -> 138893.32
B38: 순자산 BV

Sheet Pro forma
B1: ="Project"&" "&Title!L6 -> Project IT | O1: =Des!C12 -> DRAFT - For Discussion Purposes Only
B2: 추정손익계산서
B4: 추정손익계산서
B5: =unit -> KRW Millions | C5: =D5-1 -> 2010 | D5: =E5-1 -> 2011 | E5: =F5-1 -> 2012 | F5: =G5-1 -> 2013 | G5: =J5-1 -> 2014 | H5: =YEAR(Des!$C$8)&"/"&MONTH(Des!$C$8)&"A" -> 2015/12A | I5: =YEAR(Des!$C$8)&"/"&12-MONTH(Des!$C$8)&"E" -> 2015/0E | J5: =YEAR(Des!C8) -> 2015 | K5: =J5+1 -> 2016 | L5: =K5+1 -> 2017 | M5: =L5+1 -> 2018 | N5: =M5+1 -> 2019 | O5: =N5+1 -> 2020
B6: 매출액 | C6: =매출액!C6 -> 101202.83 | D6: =매출액!D6 -> 120090.95 | E6: =매출액!E6 -> 182279.27 | F6: =매출액!F6 -> 211683.37 | G6: =매출액!G6 -> 251810.75 | H6: =매출액!H6 -> 214888.12 | I6: =매출액!I6 -> 0 | J6: =매출액!J6 -> 214888.12 | ... O6: =매출액!O6 -> 284669.53
B7: % of growth | D7: =D6/C6-1 -> 0.18663626 | F7: =F6/E6-1 -> 0.16131348 | G7: =G6/F6-1 -> 0.18956321 | H7: n.a. | I7: n.a. | J7: =J6/G6-1 -> -0.14662847 | K7: =K6/J6-1 -> 0.15249576 | L7: =L6/K6-1 -> 0.034581504 | M7: =M6/L6-1 -> 0.035505009 | N7: =N6/M6-1 -> 0.035472419 | O7: =O6/N6-1 -> 0.036176613
B9: 매출원가 | C9: =매출원가!C6 -> 86101.883 | D9: =매출원가!D6 -> 106369.5 | E9: =매출원가!E6 -> 165640.96 | F9: =매출원가!F6 -> 194029.19 | G9: =매출원가!G6 -> 233681.98 | H9: =매출원가!H6 -> 193423.41 | I9: =매출원가!I6 -> 0 | J9: =매출원가!J6 -> 193443.28 | ... O9: =매출원가!O6 -> 259472.68
B10: % of growth | D10: =D9/C9-1 -> 0.23539109 | F10: =F9/E9-1 -> 0.17138415 | G10: =G9/F9-1 -> 0.20436508 | H10: n.a. | I10: n.a. | J10: =J9/G9-1 -> -0.1721943 | K10: =K9/J9-1 -> 0.16409019 | L10: =L9/K9-1 -> 0.035296275 | M10: =M9/L9-1 -> 0.035792471 | N10: =N9/M9-1 -> 0.036150675 | O10: =O9/N9-1 -> 0.037029368
B11: % of sales | C11: =C9/C$6 -> 0.85078534 | D11: =D9/D$6 -> 0.88574121 | E11: =E9/E$6 -> 0.90872078 | F11: =F9/F$6 -> 0.91660102 | G11: =G9/G$6 -> 0.92800639 | H11: =H9/H$6 -> 0.90011215 | I11: =I9/I$6 -> #DIV/0! | J11: =J9/J$6 -> 0.90020459 | ... O11: =O9/O$6 -> 0.91148736
B13: 매출총이익 | C13: =C6-C9 -> 15100.945 | D13: =D6-D9 -> 13721.446 | E13: =E6-E9 -> 16638.31 | F13: =F6-F9 -> 17654.178 | G13: =G6-G9 -> 18128.765 | H13: =H6-H9 -> 21464.712 | I13: =I6-I9 -> 0 | J13: =J6-J9 -> 21444.848 | ... O13: =O6-O9 -> 25196.85
B14: % of growth | D14: =D13/C13-1 -> -0.09135184 | F14: =F13/E13-1 -> 0.061055967 | G14: =G13/F13-1 -> 0.026882423 | H14: n.a. | I14: n.a. | J14: =J13/G13-1 -> 0.18291829 | K14: =K13/J13-1 -> 0.047908219 | L14: =L13/K13-1 -> 0.027419064 | M14: =M13/L13-1 -> 0.032602381 | N14: =N13/M13-1 -> 0.028602612 | O14: =O13/N13-1 -> 0.027475993
B15: % of sales | C15: =C13/C$6 -> 0.14921466 | D15: =D13/D$6 -> 0.11425879 | E15: =E13/E$6 -> 0.091279223 | F15: =F13/F$6 -> 0.083398984 | G15: =G13/G$6 -> 0.071993611 | H15: =H13/H$6 -> 0.099887849 | I15: =I13/I$6 -> #DIV/0! | J15: =J13/J$6 -> 0.099795406 | ... O15: =O13/O$6 -> 0.088512636
B17: 판매비와관리비 | C17: ='SG&A'!C6 -> 8937.6962 | D17: ='SG&A'!D6 -> 7198.3637 | E17: ='SG&A'!E6 -> 7996.3669 | F17: ='SG&A'!F6 -> 8441.2134 | G17: ='SG&A'!G6 -> 8664.1025 | H17: ='SG&A'!H6 -> 11711.818 | I17: ='SG&A'!I6 -> 44.614312 | J17: ='SG&A'!J6 -> 11722.521 | ... O17: ='SG&A'!O6 -> 13753.785
B18: % of growth | D18: =D17/C17-1 -> -0.19460636 | F18: =F17/E17-1 -> 0.055631083 | G18: =G17/F17-1 -> 0.026404859 | H18: n.a. | I18: n.a. | J18: =J17/G17-1 -> 0.35299886 | K18: =K17/J17-1 -> -0.00013617951 | L18: =L17/K17-1 -> 0.045610557 | M18: =M17/L17-1 -> 0.039897093 | N18: =N17/M17-1 -> 0.034727172 | O18: =O17/N17-1 -> 0.042975693
B19: % of sales | C19: n.a. | D19: n.a. | E19: =E17/E$6 -> 0.043868768 | F19: =F17/F$6 -> 0.039876602 | G19: =G17/G$6 -> 0.034407199 | H19: =H17/H$6 -> 0.054501933 | I19: =I17/I$6 -> #DIV/0! | J19: =J17/J$6 -> 0.054551739 | K19: =K17/K$6 -> 0.047327124 | L19: =L17/L$6 -> 0.04783165 | ... O19: =O17/O$6 -> 0.048314918
B21: 영업이익 | C21: =C13-C17 -> 6163.2491 | D21: =D13-D17 -> 6523.0825 | E21: =E13-E17 -> 8641.9429 | F21: =F13-F17 -> 9212.9645 | G21: =G13-G17 -> 9464.6625 | H21: =H13-H17 -> 9752.8942 | I21: =I13-I17 -> -44.614312 | J21: =J13-J17 -> 9722.3268 | ... O21: =O13-O17 -> 11443.066
B22: % of growth | D22: =D21/C21-1 -> 0.05838371 | F22: =F21/E21-1 -> 0.066075598 | G22: =G21/F21-1 -> 0.027319982 | H22: n.a. | I22: n.a. | J22: =J21/G21-1 -> 0.027223822 | K22: =K21/J21-1 -> 0.10583689 | L22: =L21/K21-1 -> 0.007586954 | M22: =M21/L21-1 -> 0.02434968 | N22: =N21/M21-1 -> 0.02156857 | O22: =O21/N21-1 -> 0.009445327
B23: % of sales | C23: =C21/C$6 -> 0.06089997 | D23: =D21/D$6 -> 0.054317855 | E23: =E21/E$6 -> 0.047410455 | F23: =F21/F$6 -> 0.043522382 | G23: =G21/G$6 -> 0.037586412 | H23: =H21/H$6 -> 0.045385915 | I23: =I21/I$6 -> #DIV/0! | J23: =J21/J$6 -> 0.045243667 | ... O23: =O21/O$6 -> 0.040197718
B25: 감가상각비 | C25: ='CapEx&Dep'!C7 -> 677.542 | D25: ='CapEx&Dep'!D7 -> 599.583 | E25: ='CapEx&Dep'!E7 -> 554.964 | F25: ='CapEx&Dep'!F7 -> 711.792 | G25: ='CapEx&Dep'!G7 -> 741.121 | H25: ='CapEx&Dep'!H7 -> 712.84854 | I25: ='CapEx&Dep'!I7 -> 64.479145 | J25: ='CapEx&Dep'!J7 -> 775.38114 | ... O25: ='CapEx&Dep'!O7 -> 2179.7868
B26: % of growth | F26: =F25/E25-1 -> 0.2825913 | G26: =G25/F25-1 -> 0.041204453 | H26: n.a. | I26: n.a. | J26: =J25/G25-1 -> 0.046227457 | K26: =K25/J25-1 -> 0.219166 | L26: =L25/K25-1 -> 0.33920139 | M26: =M25/L25-1 -> 0.23446478 | N26: =N25/M25-1 -> 0.16706014 | O26: =O25/N25-1 -> 0.19513814
B27: % of sales | C27: =C25/C$6 -> 0.006694892 | D27: =D25/D$6 -> 0.0049927411 | E27: =E25/E$6 -> 0.003044581 | F27: =F25/F$6 -> 0.0033625315 | G27: =G25/G$6 -> 0.0029431667 | H27: =H25/H$6 -> 0.0033173008 | I27: =I25/I$6 -> #DIV/0! | J27: =J25/J$6 -> 0.0036083015 | ... O27: =O25/O$6 -> 0.0076572536
B29: EBITDA | C29: =C21+C25 -> 6840.7911 | D29: =D21+D25 -> 7122.6655 | E29: =E21+E25 -> 9196.9069 | F29: =F21+F25 -> 9924.7565 | G29: =G21+G25 -> 10205.783 | H29: =H21+H25 -> 10465.743 | I29: =I21+I25 -> 19.864833 | J29: =J21+J25 -> 10497.708 | ... O29: =O21+O25 -> 13622.852
B30: % of growth | D30: =D29/C29-1 -> 0.041204935 | F30: =F29/E29-1 -> 0.079140688 | G30: =G29/F29-1 -> 0.02831576 | H30: n.a. | I30: n.a. | J30: =J29/G29-1 -> 0.028603824 | K30: =K29/J29-1 -> 0.1142076 | L30: =L29/K29-1 -> 0.034387948 | M30: =M29/L29-1 -> 0.046335222 | N30: =N29/M29-1 -> 0.039529367 | O30: =O29/N29-1 -> 0.035181227
B31: % of sales | C31: =C29/C$6 -> 0.067594861 | D31: =D29/D$6 -> 0.059310596 | E31: =E29/E$6 -> 0.050455036 | F31: =F29/F$6 -> 0.046884914 | G31: =G29/G$6 -> 0.040529579 | H31: =H29/H$6 -> 0.048703216 | I31: =I29/I$6 -> #DIV/0! | J31: =J29/J$6 -> 0.048851969 | ... O31: =O29/O$6 -> 0.047854972

Sheet 매출액
B1: ="Project"&" "&Title!L6 -> Project IT | O1: =Des!C12 -> DRAFT - For Discussion Purposes Only
B2: 매출액
B4: 매출액
B5: =unit -> KRW Millions | C5: ='Pro forma'!C$5 -> 2010 | D5: ='Pro forma'!D$5 -> 2011 | E5: ='Pro forma'!E$5 -> 2012 | F5: ='Pro forma'!F$5 -> 2013 | G5: ='Pro forma'!G$5 -> 2014 | H5: ='Pro forma'!H$5 -> 2015/12A | I5: ='Pro forma'!I$5 -> 2015/0E | J5: ='Pro forma'!J$5 -> 2015 | ... O5: ='Pro forma'!O$5 -> 2020
B6: 매출액 | C6: =C9+C13+C17 -> 101202.83 | D6: =D9+D13+D17 -> 120090.95 | E6: =E9+E13+E17 -> 182279.27 | F6: =F9+F13+F17 -> 211683.37 | G6: =G9+G13+G17 -> 251810.75 | H6: =H9+H13+H17 -> 214888.12 | J6: =J9+J13+J17 -> 214888.12 | K6: =K9+K13+K17 -> 247657.65 | L6: =L9+L13+L17 -> 256222.03 | M6: =M9+M13+M17 -> 265319.19 | N6: =N9+N13+N17 -> 274730.7 | O6: =O9+O13+O17 -> 284669.53
B7: % of growth | D7: =D6/C6-1 -> 0.18663626 | E7: =E6/D6-1 -> 0.51784355 | F7: =F6/E6-1 -> 0.16131348 | G7: =G6/F6-1 -> 0.18956321 | J7: =J6/G6-1 -> -0.14662847 | K7: =K6/J6-1 -> 0.15249576 | L7: =L6/K6-1 -> 0.034581504 | M7: =M6/L6-1 -> 0.035505009 | N7: =N6/M6-1 -> 0.035472419 | O7: =O6/N6-1 -> 0.036176613
B9: 상품 | C9: =C71 -> 28667.765 | D9: =D71 -> 33818.96 | E9: =E71 -> 72895.968 | F9: =F71 -> 71774.78 | G9: =G71 -> 69236.769 | H9: =H71 -> 43311.995 | J9: =J71 -> 43311.995 | K9: =K71 -> 52024.746 | L9: =L71 -> 54263.917 | M9: =M71 -> 56179.287 | N9: =N71 -> 58153.964 | O9: =O71 -> 60235.145
B10: % of growth | D10: =D9/C9-1 -> 0.17968598 | E10: =E9/D9-1 -> 1.1554763 | F10: =F9/E9-1 -> -0.015380654 | G10: =G9/F9-1 -> -0.035360773 | J10: =J9/G9-1 -> -0.37443651 | K10: =K9/J9-1 -> 0.20116256 | L10: =L9/K9-1 -> 0.043040493 | M10: =M9/L9-1 -> 0.035297296 | N10: =N9/M9-1 -> 0.035149564 | O10: =O9/N9-1 -> 0.035787434
B11: % of sales | C11: =C9/(C$13+C$17) -> 0.3952263 | D11: =D9/(D$13+D$17) -> 0.39200397 | E11: =E9/(E$13+E$17) -> 0.66642686 | F11: =F9/(F$13+F$17) -> 0.51301197 | G11: =G9/(G$13+G$17) -> 0.37922583 | H11: =H9/(H$13+H$17) -> 0.25243602 | J11: =J9/(J$13+J$17) -> 0.25243602 | K11: =K9/K$6 -> 0.21006719 | L11: =L9/L$6 -> 0.21178475 | M11: =M9/M$6 -> 0.21174227 | N11: =N9/N$6 -> 0.21167625 | O11: =O9/O$6 -> 0.21159674
B13: SI | C13: =C109 -> 32345.633 | D13: =D109 -> 31656.879 | E13: =E109 -> 52687.669 | F13: =F109 -> 60245.229 | G13: =G109 -> 90980.18 | H13: =H109 -> 76214.068 | J13: =J109 -> 76214.068 | K13: =K109 -> 96372.275 | L13: =L109 -> 98768.886 | M13: =M109 -> 102065.25 | N13: =N109 -> 105326.77 | O13: =O109 -> 108650.36
B14: % of growth | D14: =D13/C13-1 -> -0.02129358 | E14: =E13/D13-1 -> 0.66433555 | F14: =F13/E13-1 -> 0.14344077 | G14: =G13/F13-1 -> 0.51016407 | J14: =J13/G13-1 -> -0.16230031 | K14: =K13/J13-1 -> 0.26449456 | L14: =L13/K13-1 -> 0.024868265 | M14: =M13/L13-1 -> 0.033374468 | N14: =N13/M13-1 -> 0.0319553 | O14: =O13/N13-1 -> 0.031554991
B15: % of 매출액 | C15: =C13/C$6 -> 0.31961195 | D15: =D13/D$6 -> 0.26360754 | E15: =E13/E$6 -> 0.28904916 | F15: =F13/F$6 -> 0.28460067 | G15: =G13/G$6 -> 0.3613038 | H15: =H13/H$6 -> 0.35466859 | J15: =J13/J$6 -> 0.35466859 | K15: =K13/K$6 -> 0.38913506 | L15: =L13/L$6 -> 0.38548164 | M15: =M13/M$6 -> 0.38468851 | N15: =N13/N$6 -> 0.38338187 | O15: =O13/O$6 -> 0.38167188
B17: SM | C17: =C170 -> 40189.43 | D17: =D170 -> 54615.106 | E17: =E170 -> 56695.63 | F17: =F170 -> 79663.359 | G17: =G170 -> 91593.798 | H17: =H170 -> 95362.06 | J17: =J170 -> 95362.06 | K17: =K170 -> 99260.63 | L17: =L170 -> 103189.22 | M17: =M170 -> 107074.66 | N17: =N170 -> 111249.97 | O17: =O170 -> 115784.03
B18: % of growth | D18: =D17/C17-1 -> 0.35894204 | E18: =E17/D17-1 -> 0.038094289 | F18: =F17/E17-1 -> 0.40510582 | G18: =G17/F17-1 -> 0.14976068 | J18: =J17/G17-1 -> 0.041141019 | K18: =K17/J17-1 -> 0.040881765 | L18: =L17/K17-1 -> 0.039578552 | M18: =M17/L17-1 -> 0.037653513 | N18: =N17/M17-1 -> 0.038994386 | O18: =O17/N17-1 -> 0.040755606
B19: % of 매출액 | C19: =C17/C$6 -> 0.39711766 | D19: =D17/D$6 -> 0.45478122 | E19: =E17/E$6 -> 0.31103718 | F19: =F17/F$6 -> 0.37633263 | G19: =G17/G$6 -> 0.36374062 | H19: =H17/H$6 -> 0.44377539 | J19: =J17/J$6 -> 0.44377539 | K19: =K17/K$6 -> 0.40079775 | L19: =L17/L$6 -> 0.40273361 | M19: =M17/M$6 -> 0.40356922 | N19: =N17/N$6 -> 0.40494188 | O19: =O17/O$6 -> 0.40673137
B23: change of % | C23: =C$5 -> 2010 | D23: =D$5 -> 2011 | E23: =E$5 -> 2012 | F23: =F$5 -> 2013 | G23: =G$5 -> 2014 | H23: =H$5 -> 2015/12A | I23: =I$5 -> 2015/0E | J23: =J$5 -> 2015 | ... O23: =O$5 -> 2020
B24: Nominal GDP Growth | C24: =Macro!H27/Macro!G27-1 -> 0.098636217 | D24: =Macro!I27/Macro!H27-1 -> 0.053246407 | E24: =Macro!J27/Macro!I27-1 -> 0.033598138 | F24: =Macro!K27/Macro!J27-1 -> 0.037742605 | G24: =Macro!L27/Macro!K27-1 -> 0.03891901 | J24: =Macro!M27/Macro!L27-1 -> 0.023003842 | K24: =Macro!N27/Macro!M27-1 -> 0.037334115 | L24: =Macro!O27/Macro!N27-1 -> 0.028565319 | M24: =Macro!P27/Macro!O27-1 -> 0.039323857 | N24: =Macro!Q27/Macro!P27-1 -> 0.040235567 | O24: =Macro!R27/Macro!Q27-1 -> 0.037923737
B25: Real GDP Growth | C25: =Macro!H7/Macro!G7-1 -> 0.064967852 | D25: =Macro!I7/Macro!H7-1 -> 0.036816889 | E25: =Macro!J7/Macro!I7-1 -> 0.022924056 | F25: =Macro!K7/Macro!J7-1 -> 0.028962124 | G25: =Macro!L7/Macro!K7-1 -> 0.033101476 | J25: =Macro!M7/Macro!L7-1 -> 0.025270579 | K25: =Macro!N7/Macro!M7-1 -> 0.028600364 | L25: =Macro!O7/Macro!N7-1 -> 0.027601128 | M25: =Macro!P7/Macro!O7-1 -> 0.030071592 | N25: =Macro!Q7/Macro!P7-1 -> 0.029194884 | O25: =Macro!R7/Macro!Q7-1 -> 0.030382129
B26: Consumer prices (%) | C26: =Macro!H87/100 -> 0.02938 | D26: =Macro!I87/100 -> 0.04025 | E26: =Macro!J87/100 -> 0.02183 | F26: =Macro!K87/100 -> 0.01301 | G26: =Macro!L87/100 -> 0.01275 | J26: =Macro!M87/100 -> 0.006 | K26: =Macro!N87/100 -> 0.013 | L26: =Macro!O87/100 -> 0.015 | M26: =Macro!P87/100 -> 0.018 | N26: =Macro!Q87/100 -> 0.02 | O26: =Macro!R87/100 -> 0.022
B27: Growth in average wages | C27: =Macro!H90/100 -> 0.06844 | D27: =Macro!I90/100 -> 0.00923 | E27: =Macro!J90/100 -> 0.05371 | F27: =Macro!K90/100 -> 0.03856 | G27: =Macro!L90/100 -> 0.02554 | J27: =Macro!M90/100 -> 0.042 | K27: =Macro!N90/100 -> 0.043 | L27: =Macro!O90/100 -> 0.042 | M27: =Macro!P90/100 -> 0.04 | N27: =Macro!Q90/100 -> 0.042 | O27: =Macro!R90/100 -> 0.044
B28: Growth in real wages | C28: =Macro!H91/100 -> 0.03794 | D28: =Macro!I91/100 -> -0.02982 | E28: =Macro!J91/100 -> 0.0312 | F28: =Macro!K91/100 -> 0.02521 | G28: =Macro!L91/100 -> 0.01263 | J28: =Macro!M91/100 -> 0.035 | K28: =Macro!N91/100 -> 0.03 | L28: =Macro!O91/100 -> 0.027 | M28: =Macro!P91/100 -> 0.022 | N28: =Macro!Q91/100 -> 0.022 | O28: =Macro!R91/100 -> 0.022
B29: 국내 SI 성장률 | G29: 0.036997886 | J29: 0.046551138 | K29: 0.051948052 | L29: 0.018518519 | M29: 0.022727273 | N29: 0.022727273 | O29: 0.022727273 | Q29: source: IDC(2014), http://www.etnews.com/20141023000161
B30: 국내 IT서비스 성장률 | J30: 0.026 | K30: 0.02912779 | L30: 0.025960943 | M30: 0.024251171 | N30: 0.021563373 | O30: 0.021563373 | Q30: source: 한국 IDC, Korea IT Services 2014 Review and 2015-2019 Forecast
B31: 상품/SI+SM매출 | C31: =C71/(C109+C170) -> 0.3952263 | D31: =D71/(D109+D170) -> 0.39200397 | E31: =E71/(E109+E170) -> 0.66642686 | F31: =F71/(F109+F170) -> 0.51301197 | G31: =G71/(G109+G170) -> 0.37922583 | H31: =H71/(H109+H170) -> 0.25243602 | J31: =J71/(J109+J170) -> 0.25243602 | K31: =K71/(K109+K170) -> 0.26593045 | L31: =K31 -> 0.26593045 | M31: =L31 -> 0.26593045 | N31: =M31 -> 0.26593045 | O31: =N31 -> 0.26593045
B32: 대내상품/SI+SM매출 | F32: =F75/(F113+F174) -> 0.30276709 | G32: =G75/(G113+G174) -> 0.22708067 | H32: =H75/(H113+H174) -> 0.22312067
B33: 대외상품/SI+SM매출 | F33: =F96/(F133+F194) -> 1.0435365 | G33: =G96/(G133+G194) -> 0.5733462 | H33: =H96/(H133+H194) -> 0.29244934
B36: 대내외 매출구분
B37: =Des!$C$13 -> KRW Millions | C37: ='Pro forma'!C$5 -> 2010 | D37: ='Pro forma'!D$5 -> 2011 | E37: ='Pro forma'!E$5 -> 2012 | F37: ='Pro forma'!F$5 -> 2013 | G37: ='Pro forma'!G$5 -> 2014 | H37: ='Pro forma'!H$5 -> 2015/12A | I37: ='Pro forma'!I$5 -> 2015/0E | J37: ='Pro forma'!J$5 -> 2015 | ... O37: ='Pro forma'!O$5 -> 2020
B38: 대내 | F38: =F41+F44+F47 -> 130536.98 | G38: =G41+G44+G47 -> 125595.43 | H38: =H41+H44+H47 -> 121120.58 | J38: =J41+J44+J47 -> 121120.58 | K38: =K41+K44+K47 -> 132545.53 | L38: =L41+L44+L47 -> 138547.69 | M38: =M41+M44+M47 -> 143887.43 | N38: =N41+N44+N47 -> 149668.3 | O38: =O41+O44+O47 -> 155927.35
B39: % of growth | D39: =D38/C38-1 -> #DIV/0! | E39: =E38/D38-1 -> #DIV/0! | F39: =F38/E38-1 -> #DIV/0! | G39: =G38/F38-1 -> -0.037855574 | J39: =J38/G38-1 -> -0.035629076 | K39: =K38/J38-1 -> 0.094327033 | L39: =L38/K38-1 -> 0.045283783 | M39: =M38/L38-1 -> 0.038540809 | N39: =N38/M38-1 -> 0.040176337 | O39: =O38/N38-1 -> 0.041819445
B40: % of sales | D40: =D38/D$6 -> 0 | E40: =E38/E$6 -> 0 | F40: =F38/F$6 -> 0.6166615 | G40: =G38/G$6 -> 0.49876915 | H40: =H38/H$6 -> 0.56364484 | J40: =J38/J$6 -> 0.56364484 | K40: =K38/K$6 -> 0.53519658 | L40: =L38/L$6 -> 0.54073295 | M40: =M38/M$6 -> 0.54231822 | N40: =N38/N$6 -> 0.54478185 | O40: =O38/O$6 -> 0.54774863
B41: 상품 | F41: =F75 -> 30337.198 | G41: =G75 -> 23242.396 | H41: =H75 -> 22094.718 | J41: =J75 -> 22094.718 | K41: =K75 -> 25977.718 | L41: =L75 -> 27637.124 | M41: =M75 -> 28702.281 | N41: =N75 -> 29855.433 | O41: =O75 -> 31103.971
B42: % of growth | D42: =D41/C41-1 -> #DIV/0! | E42: =E41/D41-1 -> #DIV/0! | F42: =F41/E41-1 -> #DIV/0! | G42: =G41/F41-1 -> -0.23386478 | J42: =J41/G41-1 -> -0.049378647 | K42: =K41/J41-1 -> 0.17574337 | L42: =L41/K41-1 -> 0.06387804 | M42: =M41/L41-1 -> 0.038540809 | N42: =N41/M41-1 -> 0.040176337 | O42: =O41/N41-1 -> 0.041819445
B43: % of 대내매출 | D43: =D41/D$38 -> #DIV/0! | E43: =E41/E$38 -> #DIV/0! | F43: =F41/F$38 -> 0.23240309 | G43: =G41/G$38 -> 0.18505765 | H43: =H41/H$38 -> 0.18241918 | J43: =J41/J$38 -> 0.18241918 | K43: =K41/K$38 -> 0.19599091 | L43: =L41/L$38 -> 0.19947733 | M43: =M41/M$38 -> 0.19947733 | N43: =N41/N$38 -> 0.19947733 | O43: =O41/O$38 -> 0.19947733
B44: SI | F44: =F113 -> 32703.735 | G44: =G113 -> 26138.877 | H44: =H113 -> 18225.235 | J44: =J113 -> 18225.235 | K44: =K113 -> 22292.753 | L44: =L113 -> 23095.958 | M44: =M113 -> 23857.957 | N44: =N113 -> 24649.932 | O44: =O113 -> 25473.271
B45: % of growth | D45: =D44/C44-1 -> #DIV/0! | E45: =E44/D44-1 -> #DIV/0! | F45: =F44/E44-1 -> #DIV/0! | G45: =G44/F44-1 -> -0.20073727 | J45: =J44/G44-1 -> -0.30275368 | K45: =K44/J44-1 -> 0.22318054 | L45: =L44/K44-1 -> 0.036029862 | M45: =M44/L44-1 -> 0.032992725 | N45: =N44/M44-1 -> 0.033195437 | O45: =O44/N44-1 -> 0.033401249
B46: % of 대내매출 | D46: =D44/D$38 -> #DIV/0! | E46: =E44/E$38 -> #DIV/0! | F46: =F44/F$38 -> 0.25053233 | G46: =G44/G$38 -> 0.20811964 | H46: =H44/H$38 -> 0.15047183 | J46: =J44/J$38 -> 0.15047183 | K46: =K44/K$38 -> 0.1681894 | L46: =L44/L$38 -> 0.16670042 | M46: =M44/M$38 -> 0.16580987 | N46: =N44/N$38 -> 0.16469708 | O46: =O44/O$38 -> 0.16336628
B47: SM | F47: =F174 -> 67496.051 | G47: =G174 -> 76214.159 | H47: =H174 -> 80800.629 | J47: =J174 -> 80800.629 | K47: =K174 -> 84275.056 | L47: =L174 -> 87814.609 | M47: =M174 -> 91327.193 | N47: =N174 -> 95162.935 | O47: =O174 -> 99350.104
B48: % of growth | D48: =D47/C47-1 -> #DIV/0! | E48: =E47/D47-1 -> #DIV/0! | F48: =F47/E47-1 -> #DIV/0! | G48: =G47/F47-1 -> 0.12916471 | J48: =J47/G47-1 -> 0.060178712 | K48: =K47/J47-1 -> 0.043 | L48: =L47/K47-1 -> 0.042 | M48: =M47/L47-1 -> 0.04 | N48: =N47/M47-1 -> 0.042 | O48: =O47/N47-1 -> 0.044
B49: % of 대내매출 | D49: =D47/D$6 -> 0 | E49: =E47/E$6 -> 0 | F49: =F47/F$6 -> 0.31885382 | G49: =G47/G$6 -> 0.30266444 | H49: =H47/H$6 -> 0.37601254 | J49: =J47/J$6 -> 0.37601254 | K49: =K47/K$6 -> 0.34028852 | L49: =L47/L$6 -> 0.34272857 | M49: =M47/M$6 -> 0.34421631 | N49: =N47/N$6 -> 0.34638624 | O49: =O47/O$6 -> 0.34900154
...

Sheet 매출원가
B1: ="Project"&" "&Title!L6 -> Project IT | O1: =Des!C12 -> DRAFT - For Discussion Purposes Only
B2: 매출원가
B4: 매출원가
B5: =unit -> KRW Millions | C5: ='Pro forma'!C$5 -> 2010 | D5: ='Pro forma'!D$5 -> 2011 | E5: ='Pro forma'!E$5 -> 2012 | F5: ='Pro forma'!F$5 -> 2013 | G5: ='Pro forma'!G$5 -> 2014 | H5: ='Pro forma'!H$5 -> 2015/12A | I5: ='Pro forma'!I$5 -> 2015/0E | J5: ='Pro forma'!J$5 -> 2015 | ... O5: ='Pro forma'!O$5 -> 2020
B6: 매출원가 | C6: =SUM(C9,C13,C17) -> 86101.883 | D6: =SUM(D9,D13,D17) -> 106369.5 | E6: =SUM(E9,E13,E17) -> 165640.96 | F6: =SUM(F9,F13,F17) -> 194029.19 | G6: =SUM(G9,G13,G17) -> 233681.98 | H6: =SUM(H9,H13,H17) -> 193423.41 | J6: =SUM(J9,J13,J17) -> 193443.28 | K6: =SUM(K9,K13,K17) -> 225185.42 | L6: =SUM(L9,L13,L17) -> 233133.63 | M6: =SUM(M9,M13,M17) -> 241478.05 | N6: =SUM(N9,N13,N17) -> 250207.65 | O6: =SUM(O9,O13,O17) -> 259472.68
B7: % of growth | D7: =D6/C6-1 -> 0.23539109 | E7: =E6/D6-1 -> 0.55722231 | F7: =F6/E6-1 -> 0.17138415 | G7: =G6/F6-1 -> 0.20436508 | J7: =J6/G6-1 -> -0.1721943 | K7: =K6/J6-1 -> 0.16409019 | L7: =L6/K6-1 -> 0.035296275 | M7: =M6/L6-1 -> 0.035792471 | N7: =N6/M6-1 -> 0.036150675 | O7: =O6/N6-1 -> 0.037029368
B9: 상품 | C9: =C74 -> 27235.239 | D9: =D74 -> 32097.45 | E9: =E74 -> 69801.338 | F9: =F74 -> 69822.706 | G9: =G74 -> 67182.469 | H9: =H74 -> 41356.112 | J9: =J74 -> 41356.112 | K9: =K74 -> 49675.413 | L9: =L74 -> 51813.467 | M9: =M74 -> 53642.342 | N9: =N74 -> 55527.847 | O9: =O74 -> 57515.047
B10: % of growth | D10: =D9/C9-1 -> 0.17852645 | E10: =E9/D9-1 -> 1.1746693 | F10: =F9/E9-1 -> 0.00030612811 | G10: =G9/F9-1 -> -0.037813449 | J10: =J9/G9-1 -> -0.38442108 | K10: =K9/J9-1 -> 0.20116256 | L10: =L9/K9-1 -> 0.043040493 | M10: =M9/L9-1 -> 0.035297296 | N10: =N9/M9-1 -> 0.035149564 | O10: =O9/N9-1 -> 0.035787434
