Workbook
Name _CIR1: [2]VIVENDI단가산정!$EX$11
Name _CTW1: [2]VIVENDI단가산정!$GQ$11
Name _CTW2: [2]VIVENDI단가산정!$FM$11
Name _CTW3: [2]VIVENDI단가산정!$HF$11
Name _DEM1: [2]VIVENDI단가산정!$CP$11
Name _DEM2: [2]VIVENDI단가산정!$DE$11
Name _FXR3: [4]Control!$B$17
Name _FXR4: [4]Control!$B$18
Name _FXR5: [4]Control!$B$19
Name _LD1: '모델별 Mapping'!_LD1
Name _LD1: '모델별 Mapping'!_LD1
Name _POT1: [2]VIVENDI단가산정!$DT$11
Name _POT2: [2]VIVENDI단가산정!$EI$11
Name _pp11: '모델별 Mapping'!_pp11
Name _pp11: '모델별 Mapping'!_pp11
Name _PRE1: [2]VIVENDI단가산정!$AH$11
Name _PRE2: [2]VIVENDI단가산정!$AW$11
Name aaaa: '모델별 Mapping'!aaaa
Name aaaaa: '모델별 Mapping'!aaaaa
Name aaaaa: '모델별 Mapping'!aaaaa
Name aaaaaa: '모델별 Mapping'!aaaaaa
Name aaaaaa: '모델별 Mapping'!aaaaaa
Name aaabbbccc: '모델별 Mapping'!aaabbbccc
Name aaabbbccc: '모델별 Mapping'!aaabbbccc
Name as: '모델별 Mapping'!as
Name as: '모델별 Mapping'!as
Name asd: '모델별 Mapping'!asd
Name asd: '모델별 Mapping'!asd
Name asdf: '모델별 Mapping'!asdf
Name asdf: '모델별 Mapping'!asdf
Name asdfg: '모델별 Mapping'!asdfg
Name asdfg: '모델별 Mapping'!asdfg
Name asxz: '모델별 Mapping'!asxz
Name asxz: '모델별 Mapping'!asxz
Name BASE: [8]생산실적!$O$12
Name bbb: '모델별 Mapping'!bbb
Name bbb: '모델별 Mapping'!bbb
Name bbbbb: '모델별 Mapping'!bbbbb
Name bbbbb: '모델별 Mapping'!bbbbb
Name book: '모델별 Mapping'!book
Name book: '모델별 Mapping'!book
Name book2: '모델별 Mapping'!book2
Name book2: '모델별 Mapping'!book2
Name book3: '모델별 Mapping'!book3
Name book3: '모델별 Mapping'!book3
Name BW: [2]VIVENDI단가산정!$CA$11
Name BZ1_1: '모델별 Mapping'!BZ1_1
Name BZ1_1: '모델별 Mapping'!BZ1_1
Name CASE1: [9]MAIN!$V$16
Name ccc: '모델별 Mapping'!ccc
Name ccc: '모델별 Mapping'!ccc
Name cccccccccccccccccccccc: '모델별 Mapping'!cccccccccccccccccccccc
Name cccccccccccccccccccccc: '모델별 Mapping'!cccccccccccccccccccccc
Name chart2: '모델별 Mapping'!chart2
Name chart2: '모델별 Mapping'!chart2
Name CPG: [11]NCC!$B$144
Name CW: [12]수처리사업!$B$1:$Z$53
Name dd: [13]ECG!$B$34
Name ddd: '모델별 Mapping'!ddd
Name ddd: '모델별 Mapping'!ddd

Sheet Title
L5: Project
L6: =Des!C5 -> SVG1 | M6: =L6 -> SVG1
L10: Financial Model
L11: - Business Valuation

Sheet Des
B1: ="Project"&" "&Title!L6 -> Project SVG1 | C1: =$C$12 -> DRAFT - For Discussion Purposes Only
B2: Description
G4: DRAFT - For Discussion Purposes Only
B5: Project Name | C5: SVG1 | G5: FINAL
B6: Client | C6: 주식회사 동해기계항공
B7: Target Company | C7: 주식회사 동해기계항공 | G7: KPMG Color (신규)
B8: Valuation Date | C8: 43100 | G8: Primary | H8: R | I8: G | J8: B
B9: Year End after Valuation Date | C9: =IF(C8=DATE(YEAR(C8),12,31),DATE(YEAR(C8+1),12,31),DATE(YEAR(C8),12,31)) -> 43465 | G9: KPMG blue | H9: 0 | I9: 51 | J9: 141
B10: Partial Period Factor | C10: =(C9-C8)/365 -> 1 | G10: Medium blue | H10: 0 | I10: 94 | J10: 184
B11: Projection Period | C11: 2017/10/01 ~ 2021/12/31, 4년 3개월 | G11: Light blue | H11: 0 | I11: 145 | J11: 218
B12: Work-In-Progress Disclaimer | C12: DRAFT - For Discussion Purposes Only
B13: Currency & Unit | C13: KRW Million | G13: Secondary
B14: Terminal Growth rate | C14: 0.01 | G14: Violet | H14: 72 | I14: 54 | J14: 152
G15: Purple | H15: 71 | I15: 10 | J15: 104
G16: Light purple | H16: 109 | I16: 32 | J16: 119
G17: Green | H17: 0 | I17: 163 | J17: 161
G19: Tertiary
H20: 0 | I20: 154 | J20: 68
H21: 67 | I21: 176 | J21: 42
H22: 234 | I22: 170 | J22: 0
H23: 246 | I23: 141 | J23: 46
H24: 188 | I24: 32 | J24: 75
H25: 198 | I25: 0 | J25: 126

Sheet WGL
B1: ="Project"&" "&Title!L6 -> Project SVG1
B2: Working Group List
B4: 회사명 | C4: 업무 | D4: 이름 | E4: 부서 | F4: 직급 | G4: 이메일 | H4: 전화번호 | I4: 휴대전화
B5: KPMG 삼정회계법인 | C5: EP | D5: 김이동 | E5: DA5 | F5: 상무 | G5: yidongkim@kr.kpmg.com | H5: 02-2112-0343 | I5: 010-4048-5105
B6: KPMG 삼정회계법인 | C6: EM | D6: 박영걸 | E6: DA5 | F6: 이사 | G6: younggulpark@kr.kpmg.com | H6: 02-2112-0749 | I6: 010-6889-9548
B7: KPMG 삼정회계법인 | C7: ICA | D7: 김양태 | E7: DA5 | F7: 차장 | G7: ykim32@kr.kpmg.com | H7: 02-2112-7585 | I7: 010-5895-9114
B8: KPMG 삼정회계법인 | D8: 권기문 | E8: DA5 | F8: 과장' | G8: kimoonkwon@kr.kpmg.com | H8: 02-2112-6948 | I8: 010-2506-1320

Sheet DCF(KPMG)>>

Sheet _TM_Result(보고서)
A1: Left | B1: Top | C1: Right | D1: Bottom | E1: Ref
A2: 7 | B2: 5 | C2: 12 | D2: 7 | E2: $G$5:$L$7

Sheet _TM_Result
A1: Left | B1: Top | C1: Right | D1: Bottom | E1: Ref
A2: 14 | B2: 17 | C2: 17 | D2: 22 | E2: $N$17:$Q$22

Sheet Result
B1: ="Project"&" "&Title!L6 -> Project SVG1
B2: Result
B4: 평가방법 | C4: Low | E4: High | F4: 중간값
B5: GTM | D5: =E5-C5 -> 0
B6: GPCM | D6: =E6-C6 -> 0
B7: DCF | D7: =E7-C7 -> 0

Sheet DCF
B1: ="Project"&" "&Title!L6 -> Project SVG1 | N1: =Des!C12 -> DRAFT - For Discussion Purposes Only
B2: Discounted Cash Flow Results
B4: DCF Results | D4: Historical | H4: Forecasted
B5: =unit -> KRW Million | D5: ='Pro forma'!D$5 -> 2014 | E5: ='Pro forma'!E$5 -> 2015 | F5: ='Pro forma'!F$5 -> 2016 | G5: ='Pro forma'!G$5 -> 2017 | H5: ='Pro forma'!H$5 -> 2018 | I5: ='Pro forma'!I$5 -> 2019 | J5: ='Pro forma'!J$5 -> 2020 | K5: ='Pro forma'!K$5 -> 2021 | L5: 2022F | M5: Terminal | S5: 세율 | T5: 0.11
B6: Sales | D6: ='Pro forma'!D6 -> 41447.714 | E6: ='Pro forma'!E6 -> 61966.746 | F6: ='Pro forma'!F6 -> 81488.231 | G6: ='Pro forma'!G6 -> 92333.966 | H6: ='Pro forma'!H6 -> 138011.23 | I6: ='Pro forma'!I6 -> 182151.03 | J6: ='Pro forma'!J6 -> 203944.82 | K6: ='Pro forma'!K6 -> 261216.69 | L6: ='Pro forma'!L6 -> 300836.43 | M6: =L6*(1+$C$24) -> 303844.79 | S6: 최대 | T6: 200
B7: COGS | D7: ='Pro forma'!D9 -> 29094.554 | E7: ='Pro forma'!E9 -> 42664.217 | F7: ='Pro forma'!F9 -> 59896.716 | G7: ='Pro forma'!G9 -> 66253.175 | H7: ='Pro forma'!H9 -> 95072.958 | I7: ='Pro forma'!I9 -> 126580.95 | J7: ='Pro forma'!J9 -> 140774.16 | K7: ='Pro forma'!K9 -> 178212.96 | L7: ='Pro forma'!L9 -> 204547.06 | M7: =L7*(1+$C$24) -> 206592.53 | S7: Extra
B8: Gross Profit | D8: =D6-D7 -> 12353.16 | E8: =E6-E7 -> 19302.528 | F8: =F6-F7 -> 21591.515 | G8: =G6-G7 -> 26080.791 | H8: =H6-H7 -> 42938.268 | I8: =I6-I7 -> 55570.08 | J8: =J6-J7 -> 63170.662 | K8: =K6-K7 -> 83003.728 | ... M8: =M6-M7 -> 97252.258 | S8: 세율 | T8: 0.22
B9: SG&A | D9: ='Pro forma'!D17 -> 6260.3832 | E9: ='Pro forma'!E17 -> 7139.8918 | F9: ='Pro forma'!F17 -> 7407.697 | G9: ='Pro forma'!G17 -> 10368.971 | H9: ='Pro forma'!H17 -> 9842.4629 | I9: ='Pro forma'!I17 -> 11618.075 | J9: ='Pro forma'!J17 -> 13319.84 | K9: ='Pro forma'!K17 -> 15631.565 | L9: ='Pro forma'!L17 -> 17765.693 | M9: =L9*(1+$C$24) -> 17943.35 | S9: 최대 | T9: 20000
B10: EBIT | D10: =D8-D9 -> 6092.7769 | E10: =E8-E9 -> 12162.637 | F10: =F8-F9 -> 14183.818 | G10: =G8-G9 -> 15711.82 | H10: =H8-H9 -> 33095.805 | I10: =I8-I9 -> 43952.005 | J10: =J8-J9 -> 49850.822 | K10: =K8-K9 -> 67372.164 | ... M10: =M8-M9 -> 79308.908 | S10: Extra | T10: =200*11% -> 22
B11: Income Tax | H11: =IF(H10<=$T$6,H10*$T$5,IF(H10>$T$9,(H10-$T$9)*$T$11+$T$13,(H10-$T$6)*$T$8+$T$10)) -> 7547.1848 | I11: =IF(I10<=$T$6,I10*$T$5,IF(I10>$T$9,(I10-$T$9)*$T$11+$T$13,(I10-$T$6)*$T$8+$T$10)) -> 10174.385 | J11: =IF(J10<=$T$6,J10*$T$5,IF(J10>$T$9,(J10-$T$9)*$T$11+$T$13,(J10-$T$6)*$T$8+$T$10)) -> 11601.899 | K11: =IF(K10<=$T$6,K10*$T$5,IF(K10>$T$9,(K10-$T$9)*$T$11+$T$13,(K10-$T$6)*$T$8+$T$10)) -> 15842.064 | L11: =IF(L10<=$T$6,L10*$T$5,IF(L10>$T$9,(L10-$T$9)*$T$11+$T$13,(L10-$T$6)*$T$8+$T$10)) -> 18540.728 | M11: =IF(M10<=$T$6,M10*$T$5,IF(M10>$T$9,(M10-$T$9)*$T$11+$T$13,(M10-$T$6)*$T$8+$T$10)) -> 18730.756 | S11: 세율 | T11: 0.242
B12: NOPLAT | H12: =H10-H11 -> 25548.62 | I12: =I10-I11 -> 33777.62 | J12: =J10-J11 -> 38248.923 | K12: =K10-K11 -> 51530.1 | L12: =L10-L11 -> 59982.943 | M12: =M10-M11 -> 60578.152 | S12: 최대
B13: (+) Depreciation | H13: ='CapEx&Dep'!H8 -> 1099.3242 | I13: ='CapEx&Dep'!I8 -> 1174.6995 | J13: ='CapEx&Dep'!J8 -> 1432.5499 | K13: ='CapEx&Dep'!K8 -> 1899.2471 | L13: ='CapEx&Dep'!L8 -> 2179.9706 | M13: =CapEx | S13: Extra | T13: =39800*11% -> 4378
B14: (-) Increase in Net WC | H14: =WC!H23 -> 1658.4995 | I14: =WC!I23 -> 2899.6358 | J14: =WC!J23 -> 1329.8297 | K14: =WC!K23 -> 3505.1515 | L14: =WC!L23 -> 2457.262 | M14: =WC!M23 -> 190.0101
B15: (-) Capital Expenditure | H15: ='CapEx&Dep'!H6 -> 2804.3188 | I15: ='CapEx&Dep'!I6 -> 2263.5366 | J15: ='CapEx&Dep'!J6 -> 14548.685 | K15: ='CapEx&Dep'!K6 -> 5030.1011 | L15: ='CapEx&Dep'!L6 -> 3452.4351 | M15: =Dep
B16: Free Cash Flow to Firm (FCFF) | H16: =H12+H13-H14-H15 -> 22185.126 | I16: =I12+I13-I14-I15 -> 29789.147 | J16: =J12+J13-J14-J15 -> 23802.958 | K16: =K12+K13-K14-K15 -> 44894.095 | L16: =L12+L13-L14-L15 -> 56253.216 | M16: =M12-M14 -> 60388.142
B17: Discount Period | H17: 1 | I17: =H17+1 -> 2 | J17: =I17+1 -> 3 | K17: =J17+1 -> 4 | L17: =K17+1 -> 5 | M17: =L17+1 -> 6
B18: Discount Factor | H18: =1/(1+$C$25)^H17 -> 0.8984726 | I18: =1/(1+$C$25)^I17 -> 0.80725301 | J18: =1/(1+$C$25)^J17 -> 0.72529471 | K18: =1/(1+$C$25)^K17 -> 0.65165742 | L18: =1/(1+$C$25)^L17 -> 0.58549633 | M18: =1/(1+$C$25)^M17 -> 0.52605241
B19: Present Value of FCFF | H19: =H16*H18 -> 19932.728 | I19: =I16*I18 -> 24047.378 | J19: =J16*J18 -> 17264.16 | K19: =K16*K18 -> 29255.57 | L19: =L16*L18 -> 32936.052 | M19: =M16*M18 -> 31767.328
B20: Cumulative Present Value | H20: =SUM(H19:L19) -> 123435.89
B21: Present Value of Terminal Value | H21: =M19 -> 31767.328
B22: Operating Value | H22: =H20+H21 -> 155203.22
B24: Terminal Growth Rate | C24: =g -> 0.01
B25: WACC | C25: =wacc -> 0.113
B27: Stand-Alone Operating Value
F28: =unit -> KRW Million
B29: 항목 | D29: 평가결과 | J29: Terminal Growth Rate
D30: 최소값 | E30: 중앙값 | F30: 최대값 | I30: =H22 -> 155203.22 | J30: =K30-CHOOSE($Q$33,$R$32,$R$33) -> 0 | K30: =L30-CHOOSE($Q$33,$R$32,$R$33) -> 0.005 | L30: 0.01 | M30: =L30+CHOOSE($Q$33,$R$32,$R$33) -> 0.015 | N30: =M30+CHOOSE($Q$33,$R$32,$R$33) -> 0.02
B31: Operating Value | D31: =K34 -> 152423.71 | E31: =H22 -> 155203.22 | F31: =M32 -> 158057.74 | I31: =I32-CHOOSE($Q$33,$R$32,$R$33) -> 0.103 | J31: 160328.73 | K31: 160494 | L31: 160659.27 | M31: 160824.53 | N31: 160989.8
B32: Non-operating Asset | E32: ='NOA&IBD'!E11 -> 46315.428 | I32: =I33-CHOOSE($Q$33,$R$32,$R$33) -> 0.108 | J32: 157575.21 | K32: 157736.05 | L32: 157896.9 | M32: 158057.74 | N32: 158218.58 | Q32: 민감도 범위 선택 | R32: 0.005
B33: Enterprise Value | D33: =D31+$E$32 -> 198739.14 | E33: =E31+$E$32 -> 201518.64 | F33: =F31+$E$32 -> 204373.17 | I33: =wacc -> 0.113 | J33: 154890.1 | K33: 155046.66 | L33: 155203.22 | M33: 155359.77 | N33: 155516.33 | Q33: 1 | R33: 0.01
B34: Interest Bearing Debt | E34: ='NOA&IBD'!E18 -> 0 | I34: =I33+CHOOSE($Q$33,$R$32,$R$33) -> 0.118 | J34: 152271.31 | K34: 152423.71 | L34: 152576.11 | M34: 152728.51 | N34: 152880.92
B35: Stock Option | I35: =I34+CHOOSE($Q$33,$R$32,$R$33) -> 0.123 | J35: 149716.81 | K35: 149865.18 | L35: 150013.56 | M35: 150161.93 | N35: 150310.31
B36: Equity Value | D36: =D33-$E$34-$E$35 -> 198739.14 | E36: =E33-$E$34-$E$35 -> 201518.64 | F36: =F33-$E$34-$E$35 -> 204373.17

Sheet WACC
B1: Bloomberg Template | R1: <Tax Rate>
B2: Weighted Average Cost of Capital | R2: Unlevered | T2: 0.242
R3: Re-Levered, Kd | T3: 0.242 | U3: <= Terminal year 기준 EBIT규모에 따름 => 11%(~2억), 22%(~200억), 24.2%(200억~)
B4: Guideline Public Company | E4: Country | G4: Observed | H4: MKT Cap | I4: IBD | J4: Debt | L4: Debt | N4: Tax Rate | O4: Unlevered Beta | P4: Re-Levered Beta | Y4: =[28]Company!B5 -> 회계 데이터 기준일 | AA4: =TEXT([28]Company!D5,"YYYY년 M월 D일") -> 2017년 9월 29일
G5: Beta | J5: Equity | L5: TIC | Y5: =[28]Company!B6 -> Market Data 기준일 | AA5: =TEXT([28]Company!D6,"YYYY년 M월 D일") -> 2017년 9월 29일
A6: 1 | B6: =IF([28]Raw!AC9="","",[28]Raw!AC9) -> Hyundai Construction Equipment Co Ltd | E6: =IF([28]Raw!AF9="","",[28]Raw!AF9) -> SOUTH KOREA | G6: =IF(B6="","",CHOOSE($W$26,G65,H65,I65)) -> 1.281801 | H6: =IF(B6="","",CHOOSE($W$28,G82,H82,I82,J82,L82)) -> #DIV/0! | I6: =IF(B6="","",G100) -> 615793 | J6: =IF(B6="","",I6/H6) -> #DIV/0! | L6: =IF(B6="","",I6/(H6+I6)) -> #DIV/0! | N6: 0.242 | O6: =IF(B6="","",IF(G6="NA","NA",G6/(1+J6*(1-N6)))) -> #DIV/0! | P6: =IF(B6="","",O6*(1+($L$41/$L$42)*$E$41)) -> #DIV/0!
A7: =A6+1 -> 2 | B7: =IF([28]Raw!AC10="","",[28]Raw!AC10) -> Doosan Bobcat Inc | E7: =IF([28]Raw!AF10="","",[28]Raw!AF10) -> SOUTH KOREA | G7: =IF(B7="","",CHOOSE($W$26,G66,H66,I66)) -> 0.91189 | H7: =IF(B7="","",CHOOSE($W$28,G83,H83,I83,J83,L83)) -> 3664107 | I7: =IF(B7="","",G101) -> 103202.18 | J7: =IF(B7="","",I7/H7) -> 0.02816571 | L7: =IF(B7="","",I7/(H7+I7)) -> 0.027394135 | N7: 0.242 | O7: =IF(B7="","",IF(G7="NA","NA",G7/(1+J7*(1-N7)))) -> 0.89282846 | P7: =IF(B7="","",O7*(1+($L$41/$L$42)*$E$41)) -> 0.97444909 | AA7: =CHOOSE(W26,"5년 평균 Weekly adjusted Beta","5년 평균 Monthly adjusted Beta","2년 평균 Weekly adjusted Beta") -> 5년 평균 Weekly adjusted Beta
A8: =A7+1 -> 3 | B8: =IF([28]Raw!AC11="","",[28]Raw!AC11) -> DY POWER Corp | E8: =IF([28]Raw!AF11="","",[28]Raw!AF11) -> SOUTH KOREA | G8: =IF(B8="","",CHOOSE($W$26,G67,H67,I67)) -> 1.225582 | H8: =IF(B8="","",CHOOSE($W$28,G84,H84,I84,J84,L84)) -> 225802.93 | I8: =[28]디와이파워!D41/10^6 -> 26557.771 | J8: =IF(B8="","",I8/H8) -> 0.11761482 | L8: =IF(B8="","",I8/(H8+I8)) -> 0.10523735 | N8: 0.242 | O8: =IF(B8="","",IF(G8="NA","NA",G8/(1+J8*(1-N8)))) -> 1.1252626 | P8: =IF(B8="","",O8*(1+($L$41/$L$42)*$E$41)) -> 1.2281318
A9: =A8+1 -> 4 | B9: =IF([28]Raw!AC12="","",[28]Raw!AC12) -> Dongil Metal Co Ltd | E9: =IF([28]Raw!AF12="","",[28]Raw!AF12) -> SOUTH KOREA | G9: =IF(B9="","",CHOOSE($W$26,G68,H68,I68)) -> 0.7080026 | H9: =IF(B9="","",CHOOSE($W$28,G85,H85,I85,J85,L85)) -> 52920 | I9: =([28]동일금속!D34+[28]동일금속!D39)/10^6 -> 8234.0778 | J9: =IF(B9="","",I9/H9) -> 0.15559482 | L9: =IF(B9="","",I9/(H9+I9)) -> 0.13464479 | N9: 0.242 | O9: =IF(B9="","",IF(G9="NA","NA",G9/(1+J9*(1-N9)))) -> 0.63330952 | P9: =IF(B9="","",O9*(1+($L$41/$L$42)*$E$41)) -> 0.69120543 | AA9: =CHOOSE(W28,"","과거 1개월 평균 ","과거 3개월 평균 ","과거 6개월 평균 ","과거 12개월 평균 ")
A10: =A9+1 -> 5 | B10: =IF([28]Raw!AC13="","",[28]Raw!AC13) -> HEUNGKUK METALTECH Co Ltd | E10: =IF([28]Raw!AF13="","",[28]Raw!AF13) -> SOUTH KOREA | G10: =IF(B10="","",CHOOSE($W$26,G69,H69,I69)) -> 0.7862841 | H10: =IF(B10="","",CHOOSE($W$28,G86,H86,I86,J86,L86)) -> 43006.209 | I10: =IF(B10="","",G104) -> 8000 | J10: =IF(B10="","",I10/H10) -> 0.18601965 | L10: =IF(B10="","",I10/(H10+I10)) -> 0.15684365 | N10: 0.242 | O10: =IF(B10="","",IF(G10="NA","NA",G10/(1+J10*(1-N10)))) -> 0.68911666 | P10: =IF(B10="","",O10*(1+($L$41/$L$42)*$E$41)) -> 0.75211435
A11: =A10+1 -> 6 | B11: =IF([28]Raw!AC14="","",[28]Raw!AC14) -> Woorim Machinery Co Ltd | E11: =IF([28]Raw!AF14="","",[28]Raw!AF14) -> SOUTH KOREA | G11: =IF(B11="","",CHOOSE($W$26,G70,H70,I70)) -> 0.8332101 | H11: =IF(B11="","",CHOOSE($W$28,G87,H87,I87,J87,L87)) -> 52717.5 | I11: =IF(B11="","",G105) -> 3800 | J11: =IF(B11="","",I11/H11) -> 0.072082326 | L11: =IF(B11="","",I11/(H11+I11)) -> 0.067235812 | N11: 0.242 | O11: =IF(B11="","",IF(G11="NA","NA",G11/(1+J11*(1-N11)))) -> 0.79004339 | P11: =IF(B11="","",O11*(1+($L$41/$L$42)*$E$41)) -> 0.8622676 | AA11: =CHOOSE(W30,"","과거 1개월 평균 ","과거 3개월 평균 ","과거 6개월 평균 ","과거 12개월 평균 ","과거 24개월 평균 ")
A12: =A11+1 -> 7 | B12: =IF([28]Raw!AC15="","",[28]Raw!AC15) -> EVERDIGM Corp | E12: =IF([28]Raw!AF15="","",[28]Raw!AF15) -> SOUTH KOREA | G12: =IF(B12="","",CHOOSE($W$26,G71,H71,I71)) -> 0.8552536 | H12: =IF(B12="","",CHOOSE($W$28,G88,H88,I88,J88,L88)) -> 189909.01 | I12: =([28]애버다임!C38+[28]애버다임!C39+[28]애버다임!C45)/10^6 -> 36121.337 | J12: =IF(B12="","",I12/H12) -> 0.19020339 | L12: =IF(B12="","",I12/(H12+I12)) -> 0.15980747 | N12: 0.242 | O12: =IF(B12="","",IF(G12="NA","NA",G12/(1+J12*(1-N12)))) -> 0.7474855 | P12: =IF(B12="","",O12*(1+($L$41/$L$42)*$E$41)) -> 0.81581915
A13: =A12+1 -> 8 | B13: =IF([28]Raw!AC16="","",[28]Raw!AC16) -> Doosan Infracore Co Ltd | E13: =IF([28]Raw!AF16="","",[28]Raw!AF16) -> SOUTH KOREA | G13: =IF(B13="","",CHOOSE($W$26,G72,H72,I72)) -> 1.561469 | H13: =IF(B13="","",CHOOSE($W$28,G89,H89,I89,J89,L89)) -> 1703208.1 | I13: =IF(B13="","",G107) -> 2564617 | J13: =IF(B13="","",I13/H13) -> 1.5057567 | L13: =IF(B13="","",I13/(H13+I13)) -> 0.60091895 | N13: 0.242 | O13: =IF(B13="","",IF(G13="NA","NA",G13/(1+J13*(1-N13)))) -> 0.72919378 | P13: =IF(B13="","",O13*(1+($L$41/$L$42)*$E$41)) -> 0.79585525 | AA13: =CHOOSE(W32,"","과거 1개월 평균 ","과거 3개월 평균 ","과거 6개월 평균 ","과거 12개월 평균 ","과거 24개월 평균 ")
A14: =A13+1 -> 9 | B14: =IF([28]Raw!AC17="","",[28]Raw!AC17) -> Jinsung T.E.C. | E14: =IF([28]Raw!AF17="","",[28]Raw!AF17) -> SOUTH KOREA | G14: =IF(B14="","",CHOOSE($W$26,G73,H73,I73)) -> 1.013539 | H14: =IF(B14="","",CHOOSE($W$28,G90,H90,I90,J90,L90)) -> 230443.25 | I14: =IF(B14="","",G108) -> 19702.5 | J14: =IF(B14="","",I14/H14) -> 0.085498275 | L14: =IF(B14="","",I14/(H14+I14)) -> 0.078764081 | N14: 0.242 | O14: =IF(B14="","",IF(G14="NA","NA",G14/(1+J14*(1-N14)))) -> 0.95185169 | P14: =IF(B14="","",O14*(1+($L$41/$L$42)*$E$41)) -> 1.0388681
A15: =A14+1 -> 10 | B15: =IF([28]Raw!AC18="","",[28]Raw!AC18) -> Kanglim Co Ltd | E15: =IF([28]Raw!AF18="","",[28]Raw!AF18) -> SOUTH KOREA | G15: =IF(B15="","",CHOOSE($W$26,G74,H74,I74)) -> 1.122415 | H15: =IF(B15="","",CHOOSE($W$28,G91,H91,I91,J91,L91)) -> 193508.96 | I15: =IF(B15="","",G109) -> 35222.923 | J15: =IF(B15="","",I15/H15) -> 0.18202218 | L15: =IF(B15="","",I15/(H15+I15)) -> 0.15399219 | N15: 0.242 | O15: =IF(B15="","",IF(G15="NA","NA",G15/(1+J15*(1-N15)))) -> 0.98632848 | P15: =IF(B15="","",O15*(1+($L$41/$L$42)*$E$41)) -> 1.0764967
A16: =A15+1 -> 11 | B16: =IF([28]Raw!AC19="","",[28]Raw!AC19) -> Soosan Heavy Industries Co Ltd | E16: =IF([28]Raw!AF19="","",[28]Raw!AF19) -> SOUTH KOREA | G16: =IF(B16="","",CHOOSE($W$26,G75,H75,I75)) -> 0.9405083 | H16: =IF(B16="","",CHOOSE($W$28,G92,H92,I92,J92,L92)) -> 80977.745 | I16: =([28]수산중공업!C38+[28]수산중공업!C44)/10^6 -> 2574.0342 | J16: =IF(B16="","",I16/H16) -> 0.031786934 | L16: =IF(B16="","",I16/(H16+I16)) -> 0.030807653 | N16: 0.242 | O16: =IF(B16="","",IF(G16="NA","NA",G16/(1+J16*(1-N16)))) -> 0.91838039 | P16: =IF(B16="","",O16*(1+($L$41/$L$42)*$E$41)) -> 1.0023369
A17: =A16+1 -> 12 | B17: =IF([28]Raw!AC20="","",[28]Raw!AC20) -> Daechang Forging Co Ltd | E17: =IF([28]Raw!AF20="","",[28]Raw!AF20) -> SOUTH KOREA | G17: =IF(B17="","",CHOOSE($W$26,G76,H76,I76)) -> 0.7109918 | H17: =IF(B17="","",CHOOSE($W$28,G93,H93,I93,J93,L93)) -> 116000 | I17: =IF(B17="","",G111) -> 2214.5932 | J17: =IF(B17="","",I17/H17) -> 0.019091321 | L17: =IF(B17="","",I17/(H17+I17)) -> 0.01873367 | N17: 0.242 | O17: =IF(B17="","",IF(G17="NA","NA",G17/(1+J17*(1-N17)))) -> 0.70084965 | P17: =IF(B17="","",O17*(1+($L$41/$L$42)*$E$41)) -> 0.76491995
A18: =A17+1 -> 13 | B18: =IF([28]Raw!AC21="","",[28]Raw!AC21) -> DY Corp | E18: =IF([28]Raw!AF21="","",[28]Raw!AF21) -> SOUTH KOREA | G18: =IF(B18="","",CHOOSE($W$26,G77,H77,I77)) -> 1.187089 | H18: =IF(B18="","",CHOOSE($W$28,G94,H94,I94,J94,L94)) -> 190817.34 | I18: =IF(B18="","",G112) -> 2325 | J18: =IF(B18="","",I18/H18) -> 0.012184427 | L18: =IF(B18="","",I18/(H18+I18)) -> 0.012037754 | N18: 0.242 | O18: =IF(B18="","",IF(G18="NA","NA",G18/(1+J18*(1-N18)))) -> 1.1762256 | P18: =IF(B18="","",O18*(1+($L$41/$L$42)*$E$41)) -> 1.2837539
A19: =A18+1 -> 14 | B19: =IF([28]Raw!AC22="","",[28]Raw!AC22) -> Hae In Corp | E19: =IF([28]Raw!AF22="","",[28]Raw!AF22) -> SOUTH KOREA | G19: =IF(B19="","",CHOOSE($W$26,G78,H78,I78)) -> 0.4925056 | H19: =IF(B19="","",CHOOSE($W$28,G95,H95,I95,J95,L95)) -> 47100.728 | I19: =IF(B19="","",G113) -> 102869.93 | J19: =IF(B19="","",I19/H19) -> 2.1840411 | L19: =IF(B19="","",I19/(H19+I19)) -> 0.68593371 | N19: 0.242 | O19: =IF(B19="","",IF(G19="NA","NA",G19/(1+J19*(1-N19)))) -> 0.18546602 | P19: =IF(B19="","",O19*(1+($L$41/$L$42)*$E$41)) -> 0.20242096
A20: =A19+1 -> 15 | B20: =IF([28]Raw!AC23="","",[28]Raw!AC23) -> 0 | E20: =IF([28]Raw!AF23="","",[28]Raw!AF23) -> 0 | G20: =IF(B20="","",CHOOSE($W$26,#REF!,#REF!,#REF!)) -> #REF! | H20: =IF(B20="","",CHOOSE($W$28,#REF!,#REF!,#REF!,#REF!,#REF!)) -> #REF! | I20: =IF(B20="","",G114) -> 0 | J20: =IF(B20="","",I20/H20) -> #REF! | L20: =IF(B20="","",I20/(H20+I20)) -> #REF! | N20: #N/A | O20: =IF(B20="","",IF(G20="NA","NA",G20/(1+J20*(1-N20)))) -> #REF! | P20: =IF(B20="","",O20*(1+($L$41/$L$42)*$E$41)) -> #REF!
A21: =A20+1 -> 16 | B21: =IF([28]Raw!AC24="","",[28]Raw!AC24) -> 0 | E21: =IF([28]Raw!AF24="","",[28]Raw!AF24) -> 0 | G21: =IF(B21="","",CHOOSE($W$26,#REF!,#REF!,#REF!)) -> #REF! | H21: =IF(B21="","",CHOOSE($W$28,#REF!,#REF!,#REF!,#REF!,#REF!)) -> #REF! | I21: =IF(B21="","",G115) -> 0 | J21: =IF(B21="","",I21/H21) -> #REF! | L21: =IF(B21="","",I21/(H21+I21)) -> #REF! | N21: #N/A | O21: =IF(B21="","",IF(G21="NA","NA",G21/(1+J21*(1-N21)))) -> #REF! | P21: =IF(B21="","",O21*(1+($L$41/$L$42)*$E$41)) -> #REF!
A22: =A21+1 -> 17 | B22: =IF([28]Raw!AC25="","",[28]Raw!AC25) -> 0 | E22: =IF([28]Raw!AF25="","",[28]Raw!AF25) -> 0 | G22: =IF(B22="","",CHOOSE($W$26,#REF!,#REF!,#REF!)) -> #REF! | H22: =IF(B22="","",CHOOSE($W$28,#REF!,#REF!,#REF!,#REF!,#REF!)) -> #REF! | I22: =IF(B22="","",G116) -> 0 | J22: =IF(B22="","",I22/H22) -> #REF! | L22: =IF(B22="","",I22/(H22+I22)) -> #REF! | N22: #N/A | O22: =IF(B22="","",IF(G22="NA","NA",G22/(1+J22*(1-N22)))) -> #REF! | P22: =IF(B22="","",O22*(1+($L$41/$L$42)*$E$41)) -> #REF!
A23: =A22+1 -> 18 | B23: =IF([28]Raw!AC26="","",[28]Raw!AC26) -> 0 | E23: =IF([28]Raw!AF26="","",[28]Raw!AF26) -> 0 | G23: =IF(B23="","",CHOOSE($W$26,#REF!,#REF!,#REF!)) -> #REF! | H23: =IF(B23="","",CHOOSE($W$28,#REF!,#REF!,#REF!,#REF!,#REF!)) -> #REF! | I23: =IF(B23="","",G117) -> 0 | J23: =IF(B23="","",I23/H23) -> #REF! | L23: =IF(B23="","",I23/(H23+I23)) -> #REF! | N23: #N/A | O23: =IF(B23="","",IF(G23="NA","NA",G23/(1+J23*(1-N23)))) -> #REF! | P23: =IF(B23="","",O23*(1+($L$41/$L$42)*$E$41)) -> #REF!
A24: =A23+1 -> 19 | B24: =IF([28]Raw!AC27="","",[28]Raw!AC27) -> 0 | E24: =IF([28]Raw!AF27="","",[28]Raw!AF27) -> 0 | G24: =IF(B24="","",CHOOSE($W$26,#REF!,#REF!,#REF!)) -> #REF! | H24: =IF(B24="","",CHOOSE($W$28,#REF!,#REF!,#REF!,#REF!,#REF!)) -> #REF! | I24: =IF(B24="","",G118) -> 0 | J24: =IF(B24="","",I24/H24) -> #REF! | L24: =IF(B24="","",I24/(H24+I24)) -> #REF! | N24: #N/A | O24: =IF(B24="","",IF(G24="NA","NA",G24/(1+J24*(1-N24)))) -> #REF! | P24: =IF(B24="","",O24*(1+($L$41/$L$42)*$E$41)) -> #REF!
A25: =A24+1 -> 20 | B25: =IF([28]Raw!AC28="","",[28]Raw!AC28) -> 0 | E25: =IF([28]Raw!AF28="","",[28]Raw!AF28) -> 0 | G25: =IF(B25="","",CHOOSE($W$26,#REF!,#REF!,#REF!)) -> #REF! | H25: =IF(B25="","",CHOOSE($W$28,#REF!,#REF!,#REF!,#REF!,#REF!)) -> #REF! | I25: =IF(B25="","",G119) -> 0 | J25: =IF(B25="","",I25/H25) -> #REF! | L25: =IF(B25="","",I25/(H25+I25)) -> #REF! | N25: #N/A | O25: =IF(B25="","",IF(G25="NA","NA",G25/(1+J25*(1-N25)))) -> #REF! | P25: =IF(B25="","",O25*(1+($L$41/$L$42)*$E$41)) -> #REF!
B26: Maximum | G26: =MAX(G8,G9,G12,G16) -> 1.225582 | J26: =MAX(J8,J9,J12,J16) -> 0.19020339 | L26: =MAX(L8,L9,L12,L16) -> 0.15980747 | O26: =MAX(O8,O9,O12,O16) -> 1.1252626 | P26: =MAX(P8,P9,P12,P16) -> 1.2281318 | T26: : 'Beta' Option | W26: 1 | Y26: =CHOOSE(W26,L64,L65,L66) -> 5year, weekly
B27: Average | G27: =AVERAGE(G8,G9,G12,G16) -> 0.93233662 | J27: =AVERAGE(J8,J9,J12,J16) -> 0.12379999 | L27: =AVERAGE(L8,L9,L12,L16) -> 0.10762432 | O27: =AVERAGE(O8,O9,O12,O16) -> 0.85610949 | P27: =AVERAGE(P8,P9,P12,P16) -> 0.93437334
B28: Median | G28: =MEDIAN(G8,G9,G12,G16) -> 0.89788095 | J28: =MEDIAN(J8,J9,J12,J16) -> 0.13660482 | L28: =MEDIAN(L8,L9,L12,L16) -> 0.11994107 | O28: =MEDIAN(O8,O9,O12,O16) -> 0.83293294 | P28: =MEDIAN(P8,P9,P12,P16) -> 0.90907803 | T28: : 'Market Capitalization' Option | W28: 1 | Y28: =CHOOSE($W$28,N81,N82,N83,N84,N85) -> 43007
B29: Minimum | G29: =MIN(G8,G9,G12,G16) -> 0.7080026 | J29: =MIN(J8,J9,J12,J16) -> 0.031786934 | L29: =MIN(L8,L9,L12,L16) -> 0.030807653 | O29: =MIN(O8,O9,O12,O16) -> 0.63330952 | P29: =MIN(P8,P9,P12,P16) -> 0.69120543
T30: : 'Equity Risk Premium' Option | W30: 1 | Y30: =CHOOSE(W30,B123,B124,B125,B126,B127,B128) -> 43007
B31: Selected (Average) | L31: =L27 -> 0.10762432 | O31: =O27 -> 0.85610949 | P31: =O31*(1+($L$41/$L$42)*$E$41) -> 0.93437334
T32: : 'Risk-free Rate' Option | W32: 1 | Y32: =CHOOSE(W32,B123,B124,B125,B126,B127,B128) -> 43007
B33: Cost of Equity (KE)
B35: Risk Free Rate | D35: + | E35: Beta | F35: x | G35: Equity Risk Premium | H35: + | I35: Size Premium | J35: + | L35: Specific Premium | M35: + | N35: Country Risk Premium | O35: = | P35: Cost of Equity
B36: =CHOOSE($W$32,G123,G124,G125,G126,G127,G128) -> 0.0237 | E36: =P31 -> 0.93437334 | G36: =CHOOSE($W$32,I123,I124,I125,I126,I127,I128) -> 0.10614 | I36: 0 | L36: 0 | N36: 0 | P36: =SUM(B36,(E36*G36),I36,L36,N36) -> 0.12287439
B38: After-Tax Cost of Debt (KD) | L38: Weighted Average Cost of Capital
B40: Pre-Tax Cost of Debt | D40: x | E40: (1 - Tax Rate) | F40: = | G40: After-Tax Cost of Debt | L40: Captial Structure | M40: x | N40: Cost of Capital | O40: = | P40: Contribution
B41: =[28]Bond!M16/100 -> 0.0433 | E41: =1-T3 -> 0.758 | G41: =(B41*E41) -> 0.0328214 | J41: Debt | L41: =L31 -> 0.10762432 | N41: =G41 -> 0.0328214 | P41: =N41*L41 -> 0.0035323807
J42: Equity | L42: =(1-L41) -> 0.89237568 | N42: =P36 -> 0.12287439 | P42: =N42*L42 -> 0.10965011
N44: WACC | O44: = | P44: =ROUND(P41+P42,3) -> 0.113
...

Sheet _TM_GPCM_Tier1 (2)
A1: Left | B1: Top | C1: Right | D1: Bottom | E1: Ref
A2: 2 | B2: 101 | C2: 7 | D2: 292 | E2: $B$101:$G$292

Sheet _TM_매출액
A1: Left | B1: Top | C1: Right | D1: Bottom | E1: Ref
A2: 2 | B2: 24 | C2: 14 | D2: 24 | E2: $B$24:$N$24

Sheet Pro forma
B1: ="Project"&" "&Title!L6 -> Project SVG1 | K1: =Des!C12 -> DRAFT - For Discussion Purposes Only
B2: Pro Forma
B4: Pro Forma
B5: =unit -> KRW Million | D5: 2014 | E5: 2015 | F5: =G5-1 -> 2016 | G5: =YEAR(Des!C8) -> 2017 | H5: =G5+1 -> 2018 | I5: =H5+1 -> 2019 | J5: =I5+1 -> 2020 | K5: =J5+1 -> 2021 | L5: =K5+1 -> 2022
B6: Sales | D6: =IS!D5/10^6 -> 41447.714 | E6: =IS!E5/10^6 -> 61966.746 | F6: =IS!F5/10^6 -> 81488.231 | G6: =IS!G5/10^6 -> 92333.966 | H6: ='모델별 Mapping'!Q185/10^6 -> 138011.23 | I6: ='모델별 Mapping'!T185/10^6 -> 182151.03 | J6: ='모델별 Mapping'!W185/10^6 -> 203944.82 | K6: ='모델별 Mapping'!Z185/10^6 -> 261216.69 | L6: ='모델별 Mapping'!AC185/10^6 -> 300836.43 | M6: =RATE(5,0,-H6,L6) -> 0.16864661
B7: % of growth | F7: =F6/E6-1 -> 0.31503163 | G7: =G6/F6-1 -> 0.13309572 | H7: =H6/G6-1 -> 0.49469619 | I7: =I6/H6-1 -> 0.31982767 | J7: =J6/I6-1 -> 0.11964678 | K7: =K6/J6-1 -> 0.28082041 | L7: =L6/K6-1 -> 0.15167386 | O7: 61709.017 | P7: 81447.5 | Q7: 91483.174 | R7: 154181.35 | S7: 194357.52 | T7: 253491.11 | U7: 279502.71 | V7: 307288.73
B9: COGS | D9: =IS!D8/10^6 -> 29094.554 | E9: =IS!E8/10^6 -> 42664.217 | F9: =IS!F8/10^6 -> 59896.716 | G9: =IS!G8/10^6 -> 66253.175 | H9: =매출원가!H6 -> 95072.958 | I9: =매출원가!I6 -> 126580.95 | J9: =매출원가!J6 -> 140774.16 | K9: =매출원가!K6 -> 178212.96 | L9: =매출원가!L6 -> 204547.06
B10: % of growth | F10: =F9/E9-1 -> 0.40390988 | G10: =G9/F9-1 -> 0.10612365 | H10: =H9/G9-1 -> 0.43499476 | I10: =I9/H9-1 -> 0.3314086 | J10: =J9/I9-1 -> 0.11212747 | K10: =K9/J9-1 -> 0.26594938 | L10: =L9/K9-1 -> 0.14776763
B11: % of sales | D11: =D9/D$6 -> 0.70195799 | E11: =E9/E$6 -> 0.68850182 | F11: =F9/F$6 -> 0.73503518 | G11: =G9/G$6 -> 0.71753849 | H11: =H9/H$6 -> 0.68887844 | I11: =I9/I$6 -> 0.69492306 | J11: =J9/J$6 -> 0.69025611 | K11: =K9/K$6 -> 0.68224186 | L11: =L9/L$6 -> 0.67992784
B13: Gross Profit | D13: =D6-D9 -> 12353.16 | E13: =E6-E9 -> 19302.528 | F13: =F6-F9 -> 21591.515 | G13: =G6-G9 -> 26080.791 | H13: =H6-H9 -> 42938.268 | I13: =I6-I9 -> 55570.08 | J13: =J6-J9 -> 63170.662 | K13: =K6-K9 -> 83003.728 | L13: =L6-L9 -> 96289.365
B14: % of growth | F14: =F13/E13-1 -> 0.11858479 | G14: =G13/F13-1 -> 0.20791855 | H14: =H13/G13-1 -> 0.64635605 | I14: =I13/H13-1 -> 0.29418542 | J14: =J13/I13-1 -> 0.1367747 | K14: =K13/J13-1 -> 0.31396009 | L14: =L13/K13-1 -> 0.16006072
B15: % of sales | D15: =D13/D$6 -> 0.29804201 | E15: =E13/E$6 -> 0.31149818 | F15: =F13/F$6 -> 0.26496482 | G15: =G13/G$6 -> 0.28246151 | H15: =H13/H$6 -> 0.31112156 | I15: =I13/I$6 -> 0.30507694 | J15: =J13/J$6 -> 0.30974389 | K15: =K13/K$6 -> 0.31775814 | L15: =L13/L$6 -> 0.32007216
B17: SG&A | D17: =IS!D14/10^6 -> 6260.3832 | E17: =IS!E14/10^6 -> 7139.8918 | F17: =IS!F14/10^6 -> 7407.697 | G17: =IS!G14/10^6 -> 10368.971 | H17: ='SG&A'!H6 -> 9842.4629 | I17: ='SG&A'!I6 -> 11618.075 | J17: ='SG&A'!J6 -> 13319.84 | K17: ='SG&A'!K6 -> 15631.565 | L17: ='SG&A'!L6 -> 17765.693
B18: % of growth | D18: =D17/C17-1 -> #DIV/0! | E18: =E17/D17-1 -> 0.14048799 | F18: =F17/E17-1 -> 0.037508293 | G18: =G17/F17-1 -> 0.39975631 | H18: =H17/G17-1 -> -0.050777237 | I18: =I17/H17-1 -> 0.18040324 | J18: =J17/I17-1 -> 0.1464756 | K18: =K17/J17-1 -> 0.17355501 | L18: =L17/K17-1 -> 0.13652689
B19: % of sales | D19: =D17/D$6 -> 0.15104291 | E19: =E17/E$6 -> 0.11522135 | F19: =F17/F$6 -> 0.090905115 | G19: =G17/G$6 -> 0.11229855 | H19: =H17/H$6 -> 0.071316393 | I19: =I17/I$6 -> 0.063782647 | J19: =J17/J$6 -> 0.065310998 | K19: =K17/K$6 -> 0.059841371 | L19: =L17/L$6 -> 0.059054329
B21: EBIT | D21: =D13-D17 -> 6092.7769 | E21: =E13-E17 -> 12162.637 | F21: =F13-F17 -> 14183.818 | G21: =G13-G17 -> 15711.82 | H21: =H13-H17 -> 33095.805 | I21: =I13-I17 -> 43952.005 | J21: =J13-J17 -> 49850.822 | K21: =K13-K17 -> 67372.164 | L21: =L13-L17 -> 78523.671
B22: % of growth | F22: =F21/E21-1 -> 0.16617952 | G22: =G21/F21-1 -> 0.10772859 | H22: =H21/G21-1 -> 1.1064271 | I22: =I21/H21-1 -> 0.32802345 | J22: =J21/I21-1 -> 0.13421041 | K22: =K21/J21-1 -> 0.35147549 | L22: =L21/K21-1 -> 0.16552099
B23: % of sales | E23: =E21/E$6 -> 0.19627683 | F23: =F21/F$6 -> 0.17405971 | G23: =G21/G$6 -> 0.17016295 | H23: =H21/H$6 -> 0.23980517 | I23: =I21/I$6 -> 0.24129429 | J23: =J21/J$6 -> 0.24443289 | K23: =K21/K$6 -> 0.25791677 | L23: =L21/L$6 -> 0.26101783
B25: Depreciation | F25: ='CapEx&Dep'!F8 -> 1082.779 | G25: ='CapEx&Dep'!G8 -> 1159.6739 | H25: ='CapEx&Dep'!H8 -> 1099.3242 | I25: ='CapEx&Dep'!I8 -> 1174.6995 | J25: ='CapEx&Dep'!J8 -> 1432.5499 | K25: ='CapEx&Dep'!K8 -> 1899.2471 | L25: ='CapEx&Dep'!L8 -> 2179.9706
B26: % of growth | F26: =F25/E25-1 -> #DIV/0! | G26: =G25/F25-1 -> 0.071016235 | H26: =H25/G25-1 -> -0.052040242 | I26: =I25/H25-1 -> 0.068565149 | J26: =J25/I25-1 -> 0.21950326 | K26: =K25/J25-1 -> 0.32578081 | L26: =L25/K25-1 -> 0.14780774
B27: % of sales | F27: =F25/F$6 -> 0.013287551 | G27: =G25/G$6 -> 0.012559559 | H27: =H25/H$6 -> 0.0079654692 | I27: =I25/I$6 -> 0.0064490411 | J27: =J25/J$6 -> 0.0070242034 | K27: =K25/K$6 -> 0.0072707727 | L27: =L25/L$6 -> 0.007246365
B29: EBITDA | F29: =F21+F25 -> 15266.597 | G29: =G21+G25 -> 16871.494 | H29: =H21+H25 -> 34195.129 | I29: =I21+I25 -> 45126.705 | J29: =J21+J25 -> 51283.372 | K29: =K21+K25 -> 69271.411 | L29: =L21+L25 -> 80703.642 | M29: =RATE(5,0,-H29,L29) -> 0.18736919
B30: % of growth | F30: =F29/E29-1 -> #DIV/0! | G30: =G29/F29-1 -> 0.10512478 | H30: =H29/G29-1 -> 1.0267991 | I30: =I29/H29-1 -> 0.31968224 | J30: =J29/I29-1 -> 0.13643068 | K30: =K29/J29-1 -> 0.35075773 | L30: =L29/K29-1 -> 0.16503534
B31: % of sales | F31: =F29/F$6 -> 0.18734726 | G31: =G29/G$6 -> 0.18272251 | H31: =H29/H$6 -> 0.24777064 | I31: =I29/I$6 -> 0.24774333 | J31: =J29/J$6 -> 0.2514571 | K31: =K29/K$6 -> 0.26518754 | L31: =L29/L$6 -> 0.26826419

Sheet 매출액(보고서)
B1: ="Project"&" "&Title!L6 -> Project SVG1 | J1: =Des!C12 -> DRAFT - For Discussion Purposes Only
B2: Sales Forecast
G3: =G6='Pro forma'!H6 -> FALSE | H3: =H6='Pro forma'!I6 -> FALSE | I3: =I6='Pro forma'!J6 -> FALSE | J3: =J6='Pro forma'!K6 -> FALSE | K3: =K6='Pro forma'!L6 -> FALSE
B4: 국내 제품 매출액
B5: KRW, 대수 | D5: ='Pro forma'!E$5 -> 2015 | E5: ='Pro forma'!F$5 -> 2016 | F5: ='Pro forma'!G$5 -> 2017 | G5: ='Pro forma'!H$5 -> 2018 | H5: ='Pro forma'!I$5 -> 2019 | I5: ='Pro forma'!J$5 -> 2020 | J5: ='Pro forma'!K$5 -> 2021 | K5: 2022
B6: 총 매출액 | D6: =IS!E5/10^6 -> 61966.746 | E6: =IS!F5/10^6 -> 81488.231 | F6: =IS!G5/10^6 -> 92333.966 | G6: =G9+G158+G211+G221 -> 149515.7 | H6: =H9+H158+H211+H221 -> 191499.17 | I6: =I9+I158+I211+I221 -> 246627.59 | J6: =J9+J158+J211+J221 -> 273031.19 | K6: =K9+K158+K211+K221 -> 303958.33 | L6: 총 매출액은 국내 제품 매출 /해외제품매출/서비스매출/항공매출로 구성 | P6: 61966.746 | Q6: 81488.231 | R6: 92318.49 | S6: 153587.25 | T6: 193346.24 | U6: 252459.99 | V6: 278172.24 | W6: 306131.28
B7: % of growth | E7: =E6/D6-1 -> 0.31503163 | F7: =F6/E6-1 -> 0.13309572 | G7: =G6/F6-1 -> 0.6192925 | H7: =H6/G6-1 -> 0.28079645 | I7: =I6/H6-1 -> 0.28787806 | J7: =J6/I6-1 -> 0.10705859 | K7: =K6/J6-1 -> 0.1132733
B9: 국내 제품 매출액 | D9: =D11+D57+D98+D139+D141 -> 55129.323 | E9: =E11+E57+E98+E139+E141 -> 74962.145 | F9: =F11+F57+F98+F139+F141 -> 79031.856 | G9: =G11+G57+G98+G139+G141 -> 112042.8 | H9: =H11+H57+H98+H139+H141 -> 142930.2 | I9: =I11+I57+I98+I139+I141 -> 187956.7 | J9: =J11+J57+J98+J139+J141 -> 207998.6 | K9: =K11+K57+K98+K139+K141 -> 226353.9
B11: 고소작업차 | D11: =D15+D22+D29+D36+D43+D50 -> 34316.995 | E11: =E15+E22+E29+E36+E43+E50 -> 43593.833 | F11: =F15+F22+F29+F36+F43+F50 -> 48663.641 | G11: =G15+G22+G29+G36+G43+G50 -> 49040.8 | H11: =H15+H22+H29+H36+H43+H50 -> 62601.7 | I11: =I15+I22+I29+I36+I43+I50 -> 82093.2 | J11: =J15+J22+J29+J36+J43+J50 -> 89632.2 | K11: =K15+K22+K29+K36+K43+K50 -> 96991.9 | O11: 113263800000
B12: % of growth | E12: =E11/D11-1 -> 0.2703278 | F12: =F11/E11-1 -> 0.11629644 | G12: =G11/F11-1 -> 0.0077503272 | H12: =H11/G11-1 -> 0.27652281 | I12: =I11/H11-1 -> 0.31135736 | J12: =J11/I11-1 -> 0.091834646 | K12: =K11/J11-1 -> 0.082110001
B13: % of sales | D13: =D11/D$6 -> 0.55379696 | E13: =E11/E$6 -> 0.53497091 | F13: =F11/F$6 -> 0.52703943 | G13: =G11/G$6 -> 0.32799767 | H13: =H11/H$6 -> 0.32690324 | I13: =I11/I$6 -> 0.33286301 | J13: =J11/J$6 -> 0.32828557 | K13: =K11/K$6 -> 0.31909604
B15: 전기향 매출 | D15: =D18*D20/10^6 -> 5284.0229 | E15: =E18*E20/10^6 -> 13364.807 | F15: =F18*F20/10^6 -> 15325.141 | G15: =G18*G20/10^6 -> 23301.9 | H15: =H18*H20/10^6 -> 26056.9 | I15: =I18*I20/10^6 -> 34826.1 | J15: =J18*J20/10^6 -> 36651.1 | K15: =K18*K20/10^6 -> 38738.7 | L15: 2018년 한전향 단가 계약으로 인한 매출액 발생
B16: % of growth | E16: =E15/D15-1 -> 1.5292863 | F16: =F15/E15-1 -> 0.14667885 | G16: =G15/F15-1 -> 0.52050147 | H16: =H15/G15-1 -> 0.1182307 | I16: =I15/H15-1 -> 0.33654042 | J16: =J15/I15-1 -> 0.052403226 | K16: =K15/J15-1 -> 0.056958727 | L16: =RATE(5,0,-G15,K15) -> 0.10700795
B17: % of 국내 제품 매출 | D17: =D15/D$9 -> 0.095847775 | E17: =E15/E$9 -> 0.17828741 | F17: =F15/F$9 -> 0.19391094 | G17: =G15/G$9 -> 0.2079732 | H17: =H15/H$9 -> 0.18230507 | I17: =I15/I$9 -> 0.18528789 | J17: =J15/J$9 -> 0.1762084 | K17: =K15/K$9 -> 0.17114218 | L17: =G17+G24 -> 0.40296119 | M17: =H17+H24 -> 0.39785294 | N17: =I17+I24 -> 0.39384177 | O17: =J17+J24 -> 0.38305642 | P17: =K17+K24 -> 0.37814635
B18: 수량(Q) | D18: ='2015년 원장 (피벗) '!P10 -> 103 | E18: ='2016년 원장 (피벗)'!P10 -> 175 | F18: 228 | G18: ='사업계획(매출 확정본)'!AI14 -> 476 | H18: ='사업계획(매출 확정본)'!AJ14 -> 508 | I18: ='사업계획(매출 확정본)'!AK14 -> 571 | J18: ='사업계획(매출 확정본)'!AL14 -> 579 | K18: ='사업계획(매출 확정본)'!AM14 -> 584
B19: % of growth | D19: =D18/#REF!-1 -> #REF! | E19: =E18/D18-1 -> 0.69902913 | F19: =F18/E18-1 -> 0.30285714 | G19: =G18/F18-1 -> 1.0877193 | H19: =H18/G18-1 -> 0.067226891 | I19: =I18/H18-1 -> 0.12401575 | J19: =J18/I18-1 -> 0.014010508 | K19: =K18/J18-1 -> 0.0086355786
B20: 단가(P) | D20: ='2015년 원장 (피벗) '!W10 -> 51301193 | E20: ='2016년 원장 (피벗)'!W10 -> 76370325 | F20: 67215532 | G20: ='사업계획(매출 확정본)'!AI15 -> 48953571 | H20: ='사업계획(매출 확정본)'!AJ15 -> 51293110 | I20: ='사업계획(매출 확정본)'!AK15 -> 60991419 | J20: ='사업계획(매출 확정본)'!AL15 -> 63300691 | K20: ='사업계획(매출 확정본)'!AM15 -> 66333390
B21: % of growth | D21: =D20/#REF!-1 -> #REF! | E21: =E20/D20-1 -> 0.48866567 | F21: =F20/E20-1 -> -0.11987369 | G21: =G20/F20-1 -> -0.27169257 | H21: =H20/G20-1 -> 0.047790973 | I21: =I20/H20-1 -> 0.18907624 | J21: =J20/I20-1 -> 0.037862249 | K21: =K20/J20-1 -> 0.047909423
B22: 통신향 매출 | D22: =D25*D27/10^6 -> 24950.095 | E22: =E25*E27/10^6 -> 28258.785 | F22: =F25*F27/10^6 -> 30798.914 | G22: =G25*G27/10^6 -> 21847 | H22: =H25*H27/10^6 -> 30808.3 | I22: =I25*I27/10^6 -> 39199.1 | J22: =J25*J27/10^6 -> 43024.1 | K22: =K25*K27/10^6 -> 46856.2 | L22: KT 매출
B23: % of growth | E23: =E22/D22-1 -> 0.13261235 | F23: =F22/E22-1 -> 0.089888127 | G23: =G22/F22-1 -> -0.29065682 | H23: =H22/G22-1 -> 0.41018446 | I23: =I22/H22-1 -> 0.27235518 | J23: =J22/I22-1 -> 0.097578771 | K23: =K22/J22-1 -> 0.089068685
B24: % of 국내 제품 매출 | D24: =D22/D$9 -> 0.45257394 | E24: =E22/E$9 -> 0.37697407 | F24: =F22/F$9 -> 0.38970253 | G24: =G22/G$9 -> 0.19498799 | H24: =H22/H$9 -> 0.21554787 | I24: =I22/I$9 -> 0.20855389 | J24: =J22/J$9 -> 0.20684803 | K24: =K22/K$9 -> 0.20700416
B25: 수량(Q) | D25: ='2015년 원장 (피벗) '!P11 -> 642 | E25: ='2016년 원장 (피벗)'!P11 -> 780 | F25: 841 | G25: ='사업계획(매출 확정본)'!AI17 -> 606 | H25: ='사업계획(매출 확정본)'!AJ17 -> 782 | I25: ='사업계획(매출 확정본)'!AK17 -> 939 | J25: ='사업계획(매출 확정본)'!AL17 -> 981 | K25: ='사업계획(매출 확정본)'!AM17 -> 1018
B26: % of growth | D26: =D25/#REF!-1 -> #REF! | E26: =E25/D25-1 -> 0.21495327 | F26: =F25/E25-1 -> 0.078205128 | G26: =G25/F25-1 -> -0.27942925 | H26: =H25/G25-1 -> 0.29042904 | I26: =I25/H25-1 -> 0.20076726 | J26: =J25/I25-1 -> 0.044728435 | K26: =K25/J25-1 -> 0.037716616 | L26: =RATE(5,0,-G25,K25) -> 0.10931537
B27: 단가(P) | D27: ='2015년 원장 (피벗) '!W11 -> 38863076 | E27: ='2016년 원장 (피벗)'!W11 -> 36229212 | F27: 36621777 | G27: ='사업계획(매출 확정본)'!AI18 -> 36051155 | H27: ='사업계획(매출 확정본)'!AJ18 -> 39396803 | I27: ='사업계획(매출 확정본)'!AK18 -> 41745580 | J27: ='사업계획(매출 확정본)'!AL18 -> 43857390 | K27: ='사업계획(매출 확정본)'!AM18 -> 46027701
B28: % of growth | D28: =D27/#REF!-1 -> #REF! | E28: =E27/D27-1 -> -0.067772916 | F28: =F27/E27-1 -> 0.0108356 | G28: =G27/F27-1 -> -0.015581492 | H28: =H27/G27-1 -> 0.092802795 | I28: =I27/H27-1 -> 0.059618475 | J28: =J27/I27-1 -> 0.050587631 | K28: =K27/J27-1 -> 0.049485638
B29: 건설향 매출 | D29: =D32*D34/10^6 -> 646.66423 | E29: =E32*E34/10^6 -> 539.00345 | F29: =F32*F34/10^6 -> 373.79489 | G29: =G32*G34/10^6 -> 0 | H29: =H32*H34/10^6 -> 0 | I29: =I32*I34/10^6 -> 0 | J29: =J32*J34/10^6 -> 0 | K29: =K32*K34/10^6 -> 0
B30: % of growth | E30: =E29/D29-1 -> -0.16648636 | F30: =F29/E29-1 -> -0.30650743 | G30: =G29/F29-1 -> -1 | H30: =H29/G29-1 -> #DIV/0! | I30: =I29/H29-1 -> #DIV/0! | J30: =J29/I29-1 -> #DIV/0! | K30: =K29/J29-1 -> #DIV/0! | N30: 55129322651 | O30: 7.4962145e+10 | P30: 7.9031856e+10 | Q30: 113263800000 | R30: 149232200000 | S30: 193517700000 | T30: 215282100000 | U30: 225225800000
B31: % of 국내 제품 매출 | D31: =D29/D$9 -> 0.011729951 | E31: =E29/E$9 -> 0.0071903419 | F31: =F29/F$9 -> 0.0047296737 | G31: =G29/G$9 -> 0 | H31: =H29/H$9 -> 0 | I31: =I29/I$9 -> 0 | J31: =J29/J$9 -> 0 | K31: =K29/K$9 -> 0
B32: 수량(Q) | D32: ='2015년 원장 (피벗) '!P7 -> 32 | E32: ='2016년 원장 (피벗)'!P7 -> 20 | F32: 28 | G32: ='사업계획(매출 확정본)'!AI23 -> 0 | H32: ='사업계획(매출 확정본)'!AJ23 -> 0 | I32: ='사업계획(매출 확정본)'!AK23 -> 0 | J32: ='사업계획(매출 확정본)'!AL23 -> 0 | K32: ='사업계획(매출 확정본)'!AM23 -> 0
B33: % of growth | D33: =D32/#REF!-1 -> #REF! | E33: =E32/D32-1 -> -0.375 | F33: =F32/E32-1 -> 0.4 | G33: =G32/F32-1 -> -1 | H33: =H32/G32-1 -> #DIV/0! | I33: =I32/H32-1 -> #DIV/0! | J33: =J32/I32-1 -> #DIV/0! | K33: =K32/J32-1 -> #DIV/0!
B34: 단가(P) | D34: ='2015년 원장 (피벗) '!W7 -> 20208257 | E34: ='2016년 원장 (피벗)'!W7 -> 26950173 | F34: 13349818 | G34: =IFERROR('사업계획(매출 확정본)'!AI24,) -> 0 | H34: =IFERROR('사업계획(매출 확정본)'!AJ24,) -> 0 | I34: =IFERROR('사업계획(매출 확정본)'!AK24,) -> 0 | J34: =IFERROR('사업계획(매출 확정본)'!AL24,) -> 0 | K34: =IFERROR('사업계획(매출 확정본)'!AM24,) -> 0
B35: % of growth | D35: =D34/#REF!-1 -> #REF! | E35: =E34/D34-1 -> 0.33362182 | F35: =F34/E34-1 -> -0.50464816 | G35: =G34/F34-1 -> -1 | H35: =H34/G34-1 -> #DIV/0! | I35: =I34/H34-1 -> #DIV/0! | J35: =J34/I34-1 -> #DIV/0! | K35: =K34/J34-1 -> #DIV/0!
B36: 관공서향 매출 | D36: =D39*D41/10^6 -> 354.47763 | E36: =E39*E41/10^6 -> 195.69364 | F36: =F39*F41/10^6 -> 361.49866 | G36: =G39*G41/10^6 -> 554.4 | H36: =H39*H41/10^6 -> 970 | I36: =I39*I41/10^6 -> 1528.5 | J36: =J39*J41/10^6 -> 2140 | K36: =K39*K41/10^6 -> 2810
B37: % of growth | E37: =E36/D36-1 -> -0.44793797 | F37: =F36/E36-1 -> 0.84726836 | G37: =G36/F36-1 -> 0.53361563 | H37: =H36/G36-1 -> 0.74963925 | I37: =I36/H36-1 -> 0.5757732 | J37: =J36/I36-1 -> 0.40006542 | K37: =K36/J36-1 -> 0.31308411
B38: % of 국내 제품 매출 | D38: =D36/D$9 -> 0.0064299289 | E38: =E36/E$9 -> 0.0026105661 | F38: =F36/F$9 -> 0.004574088 | G38: =G36/G$9 -> 0.0049481091 | H38: =H36/H$9 -> 0.0067865294 | I38: =I36/I$9 -> 0.0081321921 | J38: =J36/J$9 -> 0.010288531 | K38: =K36/K$9 -> 0.012414189
B39: 수량(Q) | D39: ='2015년 원장 (피벗) '!P8 -> 7 | E39: ='2016년 원장 (피벗)'!P8 -> 2 | F39: 6 | G39: ='사업계획(매출 확정본)'!AI20 -> 6 | H39: ='사업계획(매출 확정본)'!AJ20 -> 10 | I39: ='사업계획(매출 확정본)'!AK20 -> 15 | J39: ='사업계획(매출 확정본)'!AL20 -> 20 | K39: ='사업계획(매출 확정본)'!AM20 -> 25
B40: % of growth | D40: =D39/#REF!-1 -> #REF! | E40: =E39/D39-1 -> -0.71428571 | F40: =F39/E39-1 -> 2 | G40: =G39/F39-1 -> 0 | H40: =H39/G39-1 -> 0.66666667 | I40: =I39/H39-1 -> 0.5 | J40: =J39/I39-1 -> 0.33333333 | K40: =K39/J39-1 -> 0.25
B41: 단가(P) | D41: ='2015년 원장 (피벗) '!W8 -> 50639661 | E41: ='2016년 원장 (피벗)'!W8 -> 97846818 | F41: 60249777 | G41: ='사업계획(매출 확정본)'!AI21 -> 92400000 | H41: ='사업계획(매출 확정본)'!AJ21 -> 97000000 | I41: ='사업계획(매출 확정본)'!AK21 -> 101900000 | J41: ='사업계획(매출 확정본)'!AL21 -> 107000000 | K41: ='사업계획(매출 확정본)'!AM21 -> 112400000
B42: % of growth | D42: =D41/#REF!-1 -> #REF! | E42: =E41/D41-1 -> 0.93221709 | F42: =F41/E41-1 -> -0.38424388 | G42: =G41/F41-1 -> 0.53361563 | H42: =H41/G41-1 -> 0.04978355 | I42: =I41/H41-1 -> 0.050515464 | J42: =J41/I41-1 -> 0.050049068 | K42: =K41/J41-1 -> 0.05046729 | T42: 확정적인건 아닌데, 경매물건이 나와서
B43: 항공향 매출 | D43: =D46*D48/10^6 -> 642.92875 | E43: =E46*E48/10^6 -> 5.572727 | F43: =F46*F48/10^6 -> 13.954545 | G43: =IFERROR(G46*G48/10^6,0) -> 0 | H43: =IFERROR(H46*H48/10^6,0) -> 0 | I43: =IFERROR(I46*I48/10^6,0) -> 0 | J43: =IFERROR(J46*J48/10^6,0) -> 0 | K43: =IFERROR(K46*K48/10^6,0) -> 0 | T43: 부지가 20억, 공장 증설 계획을 세우시는 것 같음
...

Sheet 매출액
B1: ="Project"&" "&Title!L6 -> Project SVG1 | J1: =Des!C12 -> DRAFT - For Discussion Purposes Only
B2: Sales Forecast
G3: ='사업계획(매출 확정본)'!AI114=G6 -> TRUE | H3: ='사업계획(매출 확정본)'!AJ114=H6 -> TRUE | I3: ='사업계획(매출 확정본)'!AK114=I6 -> TRUE | J3: ='사업계획(매출 확정본)'!AL114=J6 -> TRUE | K3: ='사업계획(매출 확정본)'!AM114=K6 -> TRUE
B4: Sales
B5: KRW, 대수 | D5: ='Pro forma'!E$5 -> 2015 | E5: ='Pro forma'!F$5 -> 2016 | F5: ='Pro forma'!G$5 -> 2017 | G5: ='Pro forma'!H$5 -> 2018 | H5: ='Pro forma'!I$5 -> 2019 | I5: ='Pro forma'!J$5 -> 2020 | J5: ='Pro forma'!K$5 -> 2021 | K5: 2022
B6: Sales | D6: =IS!E5 -> 61966745769 | E6: =IS!F5 -> 81488230867 | F6: =IS!G5 -> 92333965525 | G6: =G150+G204+G210+G220 -> 1.495157e+11 | H6: =H150+H204+H210+H220 -> 1.9132417e+11 | I6: =I150+I204+I210+I220 -> 2.4626959e+11 | J6: =J150+J204+J210+J220 -> 2.7248119e+11 | K6: =K150+K204+K210+K220 -> 3.0320433e+11 | L6: 총 매출액은 국내 제품 매출 /해외제품매출/서비스매출/항공매출로 구성
B7: % of growth | D7: =D6/#REF!-1 -> #REF! | E7: =E6/D6-1 -> 0.31503163 | F7: =F6/E6-1 -> 0.13309572 | G7: =G6/F6-1 -> 0.6192925 | H7: =H6/G6-1 -> 0.279626 | I7: =I6/H6-1 -> 0.28718488 | J7: =J6/I6-1 -> 0.10643459 | K7: =K6/J6-1 -> 0.11275327
M8: 61709.017 | N8: 81447.5 | O8: 91483.174 | P8: 154181.35 | Q8: 194357.52 | R8: 253491.11 | S8: 279502.71 | T8: 307288.73
M9: 61709.017 | N9: 81447.5 | O9: 91257.294 | P9: 153587.25 | Q9: 193346.24 | R9: 252459.99 | S9: 278172.24 | T9: 306131.28
B10: 고소작업차 부문 | D10: =D14+D21+D28+D35+D42+D49 -> 34316995394 | E10: =E14+E21+E28+E35+E42+E49 -> 40921440045 | F10: =F14+F21+F28+F35+F42+F49 -> 4.8663641e+10 | G10: =G14+G21+G28+G35+G42+G49 -> 49040800000 | H10: =H14+H21+H28+H35+H42+H49 -> 62601700000 | I10: =I14+I21+I28+I35+I42+I49 -> 82093200000 | J10: =J14+J21+J28+J35+J42+J49 -> 89632200000 | K10: =K14+K21+K28+K35+K42+K49 -> 96991900000 | M10: =M9=D6/10^6 -> FALSE
B11: % of growth | D11: =D10/#REF!-1 -> #REF! | E11: =E10/D10-1 -> 0.19245405 | F11: =F10/E10-1 -> 0.18919669 | G11: =G10/F10-1 -> 0.0077503272 | H11: =H10/G10-1 -> 0.27652281 | I11: =I10/H10-1 -> 0.31135736 | J11: =J10/I10-1 -> 0.091834646 | K11: =K10/J10-1 -> 0.082110001
B12: % of sales | D12: =D10/D$6 -> 0.55379696 | E12: =E10/E$6 -> 0.50217608 | F12: =F10/F$6 -> 0.52703943 | G12: =G10/G$6 -> 0.32799767 | H12: =H10/H$6 -> 0.32720225 | I12: =I10/I$6 -> 0.33334689 | J12: =J10/J$6 -> 0.32894822 | M12: 61966.746 | N12: 81488.231 | O12: 92318.49 | P12: 153587.25 | Q12: 193346.24 | R12: 252459.99 | S12: 278172.24 | T12: 306131.28
B14: 전기향 매출 | D14: =D17*D19 -> 5284022890 | E14: =E17*E19 -> 13364806884 | F14: =F17*F19 -> 1.5325141e+10 | G14: =G17*G19 -> 23301900000 | H14: =H17*H19 -> 26056900000 | I14: =I17*I19 -> 34826100000 | J14: =J17*J19 -> 36651100000 | K14: =K17*K19 -> 38738700000
B15: % of growth | D15: =D14/#REF!-1 -> #REF! | E15: =E14/D14-1 -> 1.5292863 | F15: =F14/E14-1 -> 0.14667885 | G15: =G14/F14-1 -> 0.52050147 | H15: =H14/G14-1 -> 0.1182307 | I15: =I14/H14-1 -> 0.33654042 | J15: =J14/I14-1 -> 0.052403226 | K15: =K14/J14-1 -> 0.056958727
B16: % of 국내 Sales | D16: =D14/D$6 -> 0.085271912 | E16: =E14/E$6 -> 0.16400904 | F16: =F14/F$6 -> 0.16597512 | G16: =G14/G$6 -> 0.15584919 | H16: =H14/H$6 -> 0.13619241 | I16: =I14/I$6 -> 0.14141454 | J16: =J14/J$6 -> 0.13450874
B17: 수량(Q) | D17: 103 | E17: 175 | F17: 228 | G17: ='사업계획(매출 확정본)'!AI14 -> 476 | H17: ='사업계획(매출 확정본)'!AJ14 -> 508 | I17: ='사업계획(매출 확정본)'!AK14 -> 571 | J17: ='사업계획(매출 확정본)'!AL14 -> 579 | K17: ='사업계획(매출 확정본)'!AM14 -> 584
B18: % of growth | D18: =D17/#REF!-1 -> #REF! | E18: =E17/D17-1 -> 0.69902913 | F18: =F17/E17-1 -> 0.30285714 | G18: =G17/F17-1 -> 1.0877193 | H18: =H17/G17-1 -> 0.067226891 | I18: =I17/H17-1 -> 0.12401575 | J18: =J17/I17-1 -> 0.014010508 | K18: =K17/J17-1 -> 0.0086355786
B19: 단가(P) | D19: 51301193 | E19: 76370325 | F19: 67215532 | G19: ='사업계획(매출 확정본)'!AI15 -> 48953571 | H19: ='사업계획(매출 확정본)'!AJ15 -> 51293110 | I19: ='사업계획(매출 확정본)'!AK15 -> 60991419 | J19: ='사업계획(매출 확정본)'!AL15 -> 63300691 | K19: ='사업계획(매출 확정본)'!AM15 -> 66333390
B20: % of growth | D20: =D19/#REF!-1 -> #REF! | E20: =E19/D19-1 -> 0.48866567 | F20: =F19/E19-1 -> -0.11987369 | G20: =G19/F19-1 -> -0.27169257 | H20: =H19/G19-1 -> 0.047790973 | I20: =I19/H19-1 -> 0.18907624 | J20: =J19/I19-1 -> 0.037862249 | K20: =K19/J19-1 -> 0.047909423
B21: 통신향 매출 | D21: =D24*D26 -> 24950094631 | E21: =E24*E26 -> 25586392091 | F21: =F24*F26 -> 3.0798914e+10 | G21: =G24*G26 -> 21847000000 | H21: =H24*H26 -> 30808300000 | I21: =I24*I26 -> 39199100000 | J21: =J24*J26 -> 43024100000 | K21: =K24*K26 -> 46856200000
B22: % of growth | D22: =D21/#REF!-1 -> #REF! | E22: =E21/D21-1 -> 0.025502807 | F22: =F21/E21-1 -> 0.20372245 | G22: =G21/F21-1 -> -0.29065682 | H22: =H21/G21-1 -> 0.41018446 | I22: =I21/H21-1 -> 0.27235518 | J22: =J21/I21-1 -> 0.097578771 | K22: =K21/J21-1 -> 0.089068685
B23: % of 국내 Sales | D23: =D21/D$6 -> 0.40263684 | E23: =E21/E$6 -> 0.3139888 | F23: =F21/F$6 -> 0.33355997 | G23: =G21/G$6 -> 0.14611844 | H23: =H21/H$6 -> 0.1610267 | I23: =I21/I$6 -> 0.1591715 | J23: =J21/J$6 -> 0.15789751
B24: 수량(Q) | D24: 642 | E24: 704 | F24: 841 | G24: ='사업계획(매출 확정본)'!AI17 -> 606 | H24: ='사업계획(매출 확정본)'!AJ17 -> 782 | I24: ='사업계획(매출 확정본)'!AK17 -> 939 | J24: ='사업계획(매출 확정본)'!AL17 -> 981 | K24: ='사업계획(매출 확정본)'!AM17 -> 1018
B25: % of growth | D25: =D24/#REF!-1 -> #REF! | E25: =E24/D24-1 -> 0.096573209 | F25: =F24/E24-1 -> 0.19460227 | G25: =G24/F24-1 -> -0.27942925 | H25: =H24/G24-1 -> 0.29042904 | I25: =I24/H24-1 -> 0.20076726 | J25: =J24/I24-1 -> 0.044728435 | K25: =K24/J24-1 -> 0.037716616
B26: 단가(P) | D26: 38863076 | E26: 36344307 | F26: 36621777 | G26: ='사업계획(매출 확정본)'!AI18 -> 36051155 | H26: ='사업계획(매출 확정본)'!AJ18 -> 39396803 | I26: ='사업계획(매출 확정본)'!AK18 -> 41745580 | J26: ='사업계획(매출 확정본)'!AL18 -> 43857390 | K26: ='사업계획(매출 확정본)'!AM18 -> 46027701
B27: % of growth | D27: =D26/#REF!-1 -> #REF! | E27: =E26/D26-1 -> -0.06481136 | F27: =F26/E26-1 -> 0.0076344854 | G27: =G26/F26-1 -> -0.015581492 | H27: =H26/G26-1 -> 0.092802795 | I27: =I26/H26-1 -> 0.059618475 | J27: =J26/I26-1 -> 0.050587631 | K27: =K26/J26-1 -> 0.049485638
B28: 건설향 매출 | D28: =D31*D33 -> 646664227 | E28: =E31*E33 -> 539003454 | F28: =F31*F33 -> 3.7379489e+08 | G28: =G31*G33 -> 0 | H28: =H31*H33 -> 0 | I28: =I31*I33 -> 0 | J28: =J31*J33 -> 0 | K28: =K31*K33 -> 0
B29: % of growth | D29: =D28/#REF!-1 -> #REF! | E29: =E28/D28-1 -> -0.16648636 | F29: =F28/E28-1 -> -0.30650743 | G29: =G28/F28-1 -> -1 | H29: =H28/G28-1 -> #DIV/0! | I29: =I28/H28-1 -> #DIV/0! | J29: =J28/I28-1 -> #DIV/0! | K29: =K28/J28-1 -> #DIV/0!
B30: % of 국내 Sales | D30: =D28/D$6 -> 0.010435665 | E30: =E28/E$6 -> 0.0066144945 | F30: =F28/F$6 -> 0.0040482924 | G30: =G28/G$6 -> 0 | H30: =H28/H$6 -> 0 | I30: =I28/I$6 -> 0 | J30: =J28/J$6 -> 0
B31: 수량(Q) | D31: 32 | E31: 20 | F31: 28 | G31: ='사업계획(매출 확정본)'!AI23 -> 0 | H31: ='사업계획(매출 확정본)'!AJ23 -> 0 | I31: ='사업계획(매출 확정본)'!AK23 -> 0 | J31: ='사업계획(매출 확정본)'!AL23 -> 0 | K31: ='사업계획(매출 확정본)'!AM23 -> 0
B32: % of growth | D32: =D31/#REF!-1 -> #REF! | E32: =E31/D31-1 -> -0.375 | F32: =F31/E31-1 -> 0.4 | G32: =G31/F31-1 -> -1 | H32: =H31/G31-1 -> #DIV/0! | I32: =I31/H31-1 -> #DIV/0! | J32: =J31/I31-1 -> #DIV/0! | K32: =K31/J31-1 -> #DIV/0!
B33: 단가(P) | D33: 20208257 | E33: 26950173 | F33: 13349818 | G33: =IFERROR('사업계획(매출 확정본)'!AI24,) -> 0 | H33: =IFERROR('사업계획(매출 확정본)'!AJ24,) -> 0 | I33: =IFERROR('사업계획(매출 확정본)'!AK24,) -> 0 | J33: =IFERROR('사업계획(매출 확정본)'!AL24,) -> 0 | K33: =IFERROR('사업계획(매출 확정본)'!AM24,) -> 0
B34: % of growth | D34: =D33/#REF!-1 -> #REF! | E34: =E33/D33-1 -> 0.33362182 | F34: =F33/E33-1 -> -0.50464816 | G34: =G33/F33-1 -> -1 | H34: =H33/G33-1 -> #DIV/0! | I34: =I33/H33-1 -> #DIV/0! | J34: =J33/I33-1 -> #DIV/0! | K34: =K33/J33-1 -> #DIV/0!
B35: 관공서향 매출 | D35: =D38*D40 -> 354477627 | E35: =E38*E40 -> 195693637 | F35: =F38*F40 -> 361498664 | G35: =G38*G40 -> 554400000 | H35: =H38*H40 -> 970000000 | I35: =I38*I40 -> 1528500000 | J35: =J38*J40 -> 2140000000 | K35: =K38*K40 -> 2810000000
B36: % of growth | D36: =D35/#REF!-1 -> #REF! | E36: =E35/D35-1 -> -0.44793797 | F36: =F35/E35-1 -> 0.84726836 | G36: =G35/F35-1 -> 0.53361563 | H36: =H35/G35-1 -> 0.74963925 | I36: =I35/H35-1 -> 0.5757732 | J36: =J35/I35-1 -> 0.40006542 | K36: =K35/J35-1 -> 0.31308411
B37: % of 국내 Sales | D37: =D35/D$6 -> 0.0057204493 | E37: =E35/E$6 -> 0.0024014957 | F37: =F35/F$6 -> 0.0039151212 | G37: =G35/G$6 -> 0.0037079719 | H37: =H35/H$6 -> 0.0050699291 | I37: =I35/I$6 -> 0.006206613 | J37: =J35/J$6 -> 0.0078537532
B38: 수량(Q) | D38: 7 | E38: 2 | F38: 6 | G38: ='사업계획(매출 확정본)'!AI20 -> 6 | H38: ='사업계획(매출 확정본)'!AJ20 -> 10 | I38: ='사업계획(매출 확정본)'!AK20 -> 15 | J38: ='사업계획(매출 확정본)'!AL20 -> 20 | K38: ='사업계획(매출 확정본)'!AM20 -> 25
B39: % of growth | D39: =D38/#REF!-1 -> #REF! | E39: =E38/D38-1 -> -0.71428571 | F39: =F38/E38-1 -> 2 | G39: =G38/F38-1 -> 0 | H39: =H38/G38-1 -> 0.66666667 | I39: =I38/H38-1 -> 0.5 | J39: =J38/I38-1 -> 0.33333333 | K39: =K38/J38-1 -> 0.25
B40: 단가(P) | D40: 50639661 | E40: 97846818 | F40: 60249777 | G40: ='사업계획(매출 확정본)'!AI21 -> 92400000 | H40: ='사업계획(매출 확정본)'!AJ21 -> 97000000 | I40: ='사업계획(매출 확정본)'!AK21 -> 101900000 | J40: ='사업계획(매출 확정본)'!AL21 -> 107000000 | K40: ='사업계획(매출 확정본)'!AM21 -> 112400000
B41: % of growth | D41: =D40/#REF!-1 -> #REF! | E41: =E40/D40-1 -> 0.93221709 | F41: =F40/E40-1 -> -0.38424388 | G41: =G40/F40-1 -> 0.53361563 | H41: =H40/G40-1 -> 0.04978355 | I41: =I40/H40-1 -> 0.050515464 | J41: =J40/I40-1 -> 0.050049068 | K41: =K40/J40-1 -> 0.05046729
...

Sheet Sheet4
A1: 전표번호 | B1: 적요 | C1: 거래처 | D1: 차변 | E1: 대변 | F1: 잔액
A2: 13 | B2: DHS 950L | C2: 선일정보통신 | E2: 36883000 | F2: 36883000
A3: 13 | B3: DHS 950L | C3: (주)애플파워 | E3: 38000000 | F3: 74883000
A4: 13 | B4: DHS 433L | C4: 부여군청 | E4: 12864000 | F4: 87747000
A5: 13 | B5: DHS 950L | C5: 제이에이치정보통신 | E5: 38500000 | F5: 126247000
A6: 13 | B6: DHS433L | C6: 대영 | E6: 13000000 | F6: 139247000
A7: 13 | B7: DHS 1200L | C7: (주)피닉스정보통신 | E7: 41870000 | F7: 181117000
A8: 13 | B8: DHS 433L | C8: (주)태진코리아 | E8: 12880000 | F8: 193997000
A9: 13 | B9: DHS 950L | C9: (유)나노정보통신 | E9: 41818189 | F9: 235815189
A10: 13 | B10: DHS 1200L | C10: (주)세인전력 | E10: 40300000 | F10: 1.5820759e+08
A11: 13 | B11: DHS 1200L | C11: (주)세인전력 | E11: 40300000 | F11: 1.5820759e+08
A12: 13 | B12: 탐헤드 턴 실린더 외 | C12: (주)한진디엔비 | E12: 51580000 | F12: 367995189
A13: 13 | B13: DHS 950L | C13: (유)나노정보통신 | E13: -41818182 | F13: 326177007
... A62: 13 | B62: DHS 1200L | C62: (주)뉴젠스 | E62: 41497000 | F62: 2473939812
A63: 13 | B63: DHS 433L | C63: (주)동해기계항공 | E63: 11603520
A64: 13 | B64: DHS 433L | C64: (주)동해기계항공 | E64: 11603520
A65: 13 | B65: DHS 1800 | C65: (주)동해기계항공 | E65: 36995264 | F65: 2534142116
A66: 13 | B66: DHS 433L | C66: 클린E＆T | E66: 15700000 | F66: 2549842116
A67: 13 | B67: DHS 950L | C67: 다성정보통신 | E67: 38454545 | F67: 2588296661
A68: 13 | B68: DHS 1200L | C68: 삼성디지컴(주) | E68: 41272727 | F68: 2629569388
A69: 13 | B69: DHS 950L | C69: (주)제주네트웍스 | E69: 42727273 | F69: 2672296661
A70: 13 | B70: DHS 950L | C70: 케이피정보통신 | E70: 37727273 | F70: 2710023934
A71: 13 | B71: DHS 950L | C71: (주)아미넷 | E71: 37220000 | F71: 2747243934
A72: 13 | B72: DHS 870 | C72: (주)아미넷 | E72: 35820000 | F72: 2783063934
A73: 13 | B73: DHS 1200L | C73: (주)아진전설 | E73: 44547000 | F73: 2827610934
A74: 13 | B74: DHS 433L | C74: 코오롱워터앤에너지(주) | E74: 13700000 | F74: 2841310934
A75: 13 | B75: DHS 950L | C75: (주)카이젠 | E75: 36483000 | F75: 2877793934
A76: 13 | B76: S3000 | C76: (주)한진디엔비 | E76: 19000000 | F76: 2896793934
... A882: 13 | B882: DHS 105AP | C882: 미래통신 | E882: 39000000 | F882: 32125375450
C884: 거래처 | D884: 차변 | E884: 대변
B885: DHS 950L | E885: 4865982374
B886: DHS 1200L | E886: 3364552525
B887: DHS 15AP | E887: 3352077865
B888: DHS 105AP | E888: 3254377266
B889: DHS 930 | E889: 1515999183
B890: DHS 433L | E890: 1383420902
B891: DHS 17AP | E891: 1303240910
B892: DHT 145S | E892: 1218887274
B893: DHS 185SKY | E893: 901290909
B894: DHS 433M | E894: 853998274
...

Sheet Sheet5
A1: 전표번호 | B1: 적요 | C1: 거래처 | D1: 차변 | E1: 대변 | F1: 잔액
A2: 16 | B2: DHS 534 | C2: 전북마린 | E2: 13545455 | F2: 206288303394
A3: 16 | B3: DHS 433L | C3: 전북마린 | E3: -13545455 | F3: 206274757939
A4: 16 | B4: DHS 433L | C4: 전북마린 | E4: 13545455 | F4: 206288303394
A5: 16 | B5: DHT 170AS | C5: 대흥활선 | E5: 202000000 | F5: 206274757939
A6: 16 | B6: DHS 534MAP | C6: (주)에이스정보통신 | E6: 30909090 | F6: 206072757939
A7: 16 | B7: DHS 1200L | C7: 형제전기통신 | E7: 41000000 | F7: 206041848849
A8: 16 | B8: DHS 930 | C8: 원테크 | E8: 35500000 | F8: 206000848849
A9: 16 | B9: DHT 160AS | C9: 유진활선 | E9: 171950000 | F9: 205965348849
A10: 16 | B10: DHS 950L | C10: (주)하이네트웍 | E10: 18373000 | F10: 205793398849
A11: 16 | B11: DHS 1200L | C11: 오성전력(주) | E11: 40000000 | F11: 205775025849
A12: 16 | B12: DHS 950L | C12: NS정보통신 | E12: 37500000 | F12: 205735025849
A13: 16 | B13: DHS 130SKY | C13: (유)비츠 | E13: 42900000 | F13: 205697525849
... A1464: 16 | B1464: DHS 950L | C1464: 주식회사 수길정보통신 | E1464: 34000000 | F1464: 128197271378
C1466: 거래처 | D1466: 차변 | E1466: 대변
B1467: DHS 950L | E1467: 13249563649
B1468: DHT 105S | E1468: 7719099100
B1469: DHS 1200L | E1469: 6357136815
B1470: DHS 15AP | E1470: 5588614966
B1471: DH SUPER 3000A | E1471: 5584328840
B1472: DHT 160AS | E1472: 4800950000
B1473: DHS 930 | E1473: 4571621271
B1474: DHT 150S | E1474: 3934604545
B1475: DH S3000A | E1475: 3454999968
B1476: DHT 150AS | E1476: 3137409091
B1477: DHT 160S | E1477: 2810677273
B1478: DHS 433L | E1478: 2703566366
... B1554: Limit sensor for boom rest bracket외 | E1554: 605901

Sheet Sheet3
A1: 전표번호 | B1: 적요 | C1: 거래처 | D1: 차변 | E1: 대변 | F1: 잔액
A2: 17 | B2: DHS 1200L | C2: (주)윈투스시스템 | E2: 43500000 | F2: 294718098500
A3: 17 | B3: DHS 15AP | C3: (주)연성 | E3: 52727272 | F3: 294674598500
A4: 17 | B4: DHS 15AP | C4: 선우기업 | E4: 50909090 | F4: 294621871228
A5: 17 | B5: DHS 190SKY | C5: 신림전기 | E5: 61090909 | F5: 294570962138
A6: 17 | B6: DHS 950L | C6: 탑 에이치 정보통신 | E6: 36363637 | F6: 294509871229
A7: 17 | B7: DHS 930 | C7: 지성텔레콤 | E7: 19700000 | F7: 294473507592
A8: 17 | B8: DHS 1200L | C8: 주식회사 중부케이블 | E8: 39090909 | F8: 294453807592
A9: 17 | B9: DHS 1200L | C9: 주식회사 중부케이블 | E9: 39090909 | F9: 294414716683
A10: 17 | B10: DHS 1200L | C10: 주식회사 중부케이블 | E10: 39090909 | F10: 294375625774
A11: 17 | B11: DHS 1200L | C11: 주식회사 중부케이블 | E11: 39090909 | F11: 294336534865
A12: 17 | B12: DHS 15AP | C12: 태성전력 주식회사 | E12: 53000000 | F12: 294297443956
A13: 17 | B13: DHS 17AP | C13: 반도전기 | E13: 56900000 | F13: 294244443956
... A70: 17 | B70: DHT 150S | C70: WAIMEA TRUCK ＆ CRANE LTD | E70: 89306200 | F70: 289260536613
A71: 17 | B71: DHT 150AS | C71: WAIMEA TRUCK ＆ CRANE LTD | E71: 106830908
A72: 17 | B72: DHS 1200L | C72: 제이통신 | E72: 40909091 | F72: 289064399505
A73: 17 | B73: DHS 1200L | C73: 제CI통신 | E73: -40909091 | F73: 289023490414
A74: 17 | B74: DHS 303 | C74: 완도군청 | E74: 17727273 | F74: 289064399505
A75: 17 | B75: DHS 1200L | C75: 드림네트웍스(주) | E75: 42454545 | F75: 289046672232
A76: 17 | B76: DHS 1200L | C76: 드림네트웍스(주) | E76: 42454545 | F76: 289004217687
A77: 17 | B77: DHS 17AP | C77: 대운산전 | E77: 54500000 | F77: 288961763142
A78: 17 | B78: DHS 15AP | C78: (주)건보전기 | E78: 52000000 | F78: 288907263142
A79: 17 | B79: DHS 1200L | C79: 제CI통신 | E79: 40909091 | F79: 288855263142
A80: 17 | B80: DHS 534MAP | C80: 주식회사 바른네트워크 | E80: 31000000 | F80: 288814354051
A81: 17 | B81: DHS 1200L | C81: 코라인이엔티(주) | E81: 43700000 | F81: 288783354051
A82: 17 | B82: DHS 1200L | C82: 코라인이엔티(주) | E82: 43700000 | F82: 288739654051
A83: 17 | B83: DHS 1200L | C83: 코라인이엔티(주) | E83: 43700000 | F83: 288695954051
... A133: 17 | B133: DHS 14 | C133: WAIMEA TRUCK ＆ CRANE LTD | E133: 68487300 | F133: 285956141866
A134: 17 | B134: DHT 150S | C134: WAIMEA TRUCK ＆ CRANE LTD | E134: 91316400
A135: 17 | B135: DHS 950L | C135: 현정보통신 | E135: 38500000 | F135: 285796338166
A136: 17 | B136: DHS 1200L | C136: 한빛통신주식회사 | E136: 41000000 | F136: 285757838166
A137: 17 | B137: DHS 1200L | C137: 대신네트웍스 주식회사 | E137: 42181818 | F137: 285716838166
A138: 17 | B138: DHS 1200L | C138: 신우정보통신(주) | E138: 40000000 | F138: 285674656348
A139: 17 | B139: DHS 930 | C139: 하이눈정보통신 | E139: 36700000 | F139: 285634656348
A140: 17 | B140: DHS 190SKY | C140: 안정심 | E140: 59090910 | F140: 285597956348
A141: 17 | B141: DHS 1200L | C141: IK(아이케이) | E141: 42000000 | F141: 285538865438
A142: 17 | B142: DHT 160AS | C142: 신승전기주식회사 | E142: 177000000 | F142: 285496865438
A143: 17 | B143: DHS 920 | C143: 인천광역시연수구청 | E143: 44400000 | F143: 285319865438
A144: 17 | B144: DHS 1200L | C144: 주식회사 바른네트워크 | E144: 41818182 | F144: 285275465438
A145: 17 | B145: DHS 930 | C145: 은성통신 | E145: 36363637 | F145: 285233647256
...

Sheet Sheet2
A3: 행 레이블 | B3: 합계 : 대변
A4: 13 | B4: 32125375450
A5: 14 | B5: 37735445080
A6: 15 | B6: 58302450848
A7: 16 | B7: 78125032016
A8: 17 | B8: 88429795106
A9: 총합계 | B9: 294718098500

Sheet SG&A
B1: ="Project"&" "&Title!L6 -> Project SVG1 | K1: =Des!C12 -> DRAFT - For Discussion Purposes Only
B2: 판매비와관리비
B4: 판매비와관리비
B5: =unit -> KRW Million | D5: ='Pro forma'!D$5 -> 2014 | E5: ='Pro forma'!E$5 -> 2015 | F5: ='Pro forma'!F$5 -> 2016 | G5: ='Pro forma'!G$5 -> 2017 | H5: ='Pro forma'!H$5 -> 2018 | I5: ='Pro forma'!I$5 -> 2019 | J5: ='Pro forma'!J$5 -> 2020 | K5: ='Pro forma'!K$5 -> 2021 | L5: ='Pro forma'!L$5 -> 2022 | P5: 평균비율' Option | Q5: 2014~2017E (과거 4개년) 평균 | T5: 2
B6: 판매비와관리비 | D6: =D10+D14+D18+D22 -> 6260.3832 | E6: =E10+E14+E18+E22 -> 7139.8918 | F6: =F10+F14+F18+F22 -> 7407.697 | G6: =G10+G14+G18+G22 -> 10368.971 | H6: =H10+H14+H18+H22 -> 9842.4629 | I6: =I10+I14+I18+I22 -> 11618.075 | J6: =J10+J14+J18+J22 -> 13319.84 | K6: =K10+K14+K18+K22 -> 15631.565 | L6: =L10+L14+L18+L22 -> 17765.693 | Q6: 2015~2017E (과거 3개년) 평균
B7: % of growth | E7: =E6/D6-1 -> 0.14048799 | F7: =F6/E6-1 -> 0.037508293 | G7: =G6/F6-1 -> 0.39975631 | H7: =H6/G6-1 -> -0.050777237 | I7: =I6/H6-1 -> 0.18040324 | J7: =J6/I6-1 -> 0.1464756 | K7: =K6/J6-1 -> 0.17355501 | Q7: 2016~2017E (과거 2개년) 평균
B8: % of sales | D8: =D6/D$33 -> 0.15104291 | E8: =E6/E$33 -> 0.11701978 | F8: =F6/F$33 -> 0.091168552 | G8: =G6/G$33 -> 0.11495027 | H8: =H6/H$33 -> 0.071316393 | I8: =I6/I$33 -> 0.063782647 | J8: =J6/J$33 -> 0.065310998 | K8: =K6/K$33 -> 0.059841371 | L8: =L6/L$33 -> 0.059054329
B10: 변동비성 경비 | D10: =D39 -> 893.82739 | E10: =E39 -> 1369.4276 | F10: =F39 -> 662.60552 | G10: =G39 -> 2756.3304 | H10: =H39 -> 1426.8345 | I10: =I39 -> 1887.7546 | J10: =J39 -> 2244.3241 | K10: =K39 -> 2806.0552 | L10: =L39 -> 3300.3064
