Workbook

Sheet Summary
A1: =MID(CELL("filename",A1),FIND("]",CELL("filename",A1))+1,255) -> Summary
B3: 1. Proforma
L5: 2021(A) | M5: 2022(A) | N5: 2023(A) | O5: 24.3m(A) | P5: 24.9m(E) | Q5: 2024(F) | R5: 2025(F) | S5: 2026(F) | T5: 2027(F) | U5: 2028(F)
B6: 매출액 | O6: ='Proforma PL'!O6 -> 89716.379 | P6: ='Proforma PL'!P6 -> 312170.78 | Q6: ='Proforma PL'!Q6 -> 401887.16 | R6: ='Proforma PL'!R6 -> 384025.11 | S6: ='Proforma PL'!S6 -> 433849.88 | T6: ='Proforma PL'!T6 -> 483807.54 | U6: ='Proforma PL'!U6 -> 535532.09
C7: 국내 | O7: ='Proforma PL'!O7 -> 32117.625 | P7: ='Proforma PL'!P7 -> 134103.49 | Q7: ='Proforma PL'!Q7 -> 166221.11 | R7: ='Proforma PL'!R7 -> 162076.51 | S7: ='Proforma PL'!S7 -> 186135.91 | T7: ='Proforma PL'!T7 -> 207378.78 | U7: ='Proforma PL'!U7 -> 232356.82
C8: 미주 | O8: ='Proforma PL'!O8 -> 13939.073 | P8: ='Proforma PL'!P8 -> 52334.224 | Q8: ='Proforma PL'!Q8 -> 66273.296 | R8: ='Proforma PL'!R8 -> 59731.026 | S8: ='Proforma PL'!S8 -> 64926.093 | T8: ='Proforma PL'!T8 -> 69442.616 | U8: ='Proforma PL'!U8 -> 76922.963
C9: 유럽 | O9: ='Proforma PL'!O9 -> 13488.451 | P9: ='Proforma PL'!P9 -> 48793.04 | Q9: ='Proforma PL'!Q9 -> 62281.491 | R9: ='Proforma PL'!R9 -> 59615.67 | S9: ='Proforma PL'!S9 -> 66472.55 | T9: ='Proforma PL'!T9 -> 72281.457 | U9: ='Proforma PL'!U9 -> 78126.589
C10: 중국 | O10: ='Proforma PL'!O10 -> 14020.191 | P10: ='Proforma PL'!P10 -> 36602.449 | Q10: ='Proforma PL'!Q10 -> 50622.64 | R10: ='Proforma PL'!R10 -> 53388.54 | S10: ='Proforma PL'!S10 -> 63265.924 | T10: ='Proforma PL'!T10 -> 76460.228 | U10: ='Proforma PL'!U10 -> 83020.2
C11: 직수출 | O11: ='Proforma PL'!O11 -> 16151.039 | P11: ='Proforma PL'!P11 -> 40337.577 | Q11: ='Proforma PL'!Q11 -> 56488.616 | R11: ='Proforma PL'!R11 -> 49213.365 | S11: ='Proforma PL'!S11 -> 53049.402 | T11: ='Proforma PL'!T11 -> 58244.454 | U11: ='Proforma PL'!U11 -> 65105.515
B12: 매출원가 | O12: ='Proforma PL'!O12 -> 68482.371 | P12: ='Proforma PL'!P12 -> 231123.95 | Q12: ='Proforma PL'!Q12 -> 299606.7 | R12: ='Proforma PL'!R12 -> 279432.09 | S12: ='Proforma PL'!S12 -> 317959.05 | T12: ='Proforma PL'!T12 -> 356180.13 | U12: ='Proforma PL'!U12 -> 393810.57
B13: 매출총이익 | O13: ='Proforma PL'!O13 -> 21234.008 | P13: ='Proforma PL'!P13 -> 81046.822 | Q13: ='Proforma PL'!Q13 -> 102280.45 | R13: ='Proforma PL'!R13 -> 104593.02 | S13: ='Proforma PL'!S13 -> 115890.83 | T13: ='Proforma PL'!T13 -> 127627.4 | U13: ='Proforma PL'!U13 -> 141721.52
B14: % GP | O14: ='Proforma PL'!O14 -> 0.23667928 | P14: ='Proforma PL'!P14 -> 0.25962335 | Q14: ='Proforma PL'!Q14 -> 0.25450042 | R14: ='Proforma PL'!R14 -> 0.27235985 | S14: ='Proforma PL'!S14 -> 0.26712197 | T14: ='Proforma PL'!T14 -> 0.26379788 | U14: ='Proforma PL'!U14 -> 0.26463683
B15: 판매관리비 | O15: ='Proforma PL'!O15 -> 18313.221 | P15: ='Proforma PL'!P15 -> 60236.142 | Q15: ='Proforma PL'!Q15 -> 78549.363 | R15: ='Proforma PL'!R15 -> 79066.553 | S15: ='Proforma PL'!S15 -> 83876.936 | T15: ='Proforma PL'!T15 -> 88454.287 | U15: ='Proforma PL'!U15 -> 93105.563
B16: 영업이익 | O16: ='Proforma PL'!O16 -> 2920.7872 | P16: ='Proforma PL'!P16 -> 20810.68 | Q16: ='Proforma PL'!Q16 -> 23731.088 | R16: ='Proforma PL'!R16 -> 25526.466 | S16: ='Proforma PL'!S16 -> 32013.897 | T16: ='Proforma PL'!T16 -> 39173.116 | U16: ='Proforma PL'!U16 -> 48615.952
B17: % EBIT | O17: ='Proforma PL'!O17 -> 0.032555786 | P17: ='Proforma PL'!P17 -> 0.066664407 | Q17: ='Proforma PL'!Q17 -> 0.059049134 | R17: ='Proforma PL'!R17 -> 0.066470827 | S17: ='Proforma PL'!S17 -> 0.073790263 | T17: ='Proforma PL'!T17 -> 0.080968387 | U17: ='Proforma PL'!U17 -> 0.090780653
B18: D&A | O18: ='Proforma PL'!O26 -> 1114.4191 | P18: ='Proforma PL'!P26 -> 4387.6363 | Q18: ='Proforma PL'!Q26 -> 5502.0555 | R18: ='Proforma PL'!R26 -> 4388.9114 | S18: ='Proforma PL'!S26 -> 4406.3455 | T18: ='Proforma PL'!T26 -> 4431.8656 | U18: ='Proforma PL'!U26 -> 4510.3795
B19: EBITDA | O19: ='Proforma PL'!O27 -> 4035.2064 | P19: ='Proforma PL'!P27 -> 25198.316 | Q19: ='Proforma PL'!Q27 -> 29233.144 | R19: ='Proforma PL'!R27 -> 29915.378 | S19: ='Proforma PL'!S27 -> 36420.242 | T19: ='Proforma PL'!T27 -> 43604.981 | U19: ='Proforma PL'!U27 -> 53126.332
B20: % EBITDA | O20: ='Proforma PL'!O28 -> 0.044977366 | P20: ='Proforma PL'!P28 -> 0.080719651 | Q20: ='Proforma PL'!Q28 -> 0.072739682 | R20: ='Proforma PL'!R28 -> 0.077899536 | S20: ='Proforma PL'!S28 -> 0.083946646 | T20: ='Proforma PL'!T28 -> 0.090128776 | U20: ='Proforma PL'!U28 -> 0.099202892
B22: 2. DCF
L24: 2021(A) | M24: 2022(A) | N24: 2023(A) | O24: 24.3m(A) | P24: 24.9m(E) | Q24: 2024(F) | R24: 2025(F) | S24: 2026(F) | T24: 2027(F) | U24: 2028(F) | V24: Terminal
B25: Revenue | P25: =P6 -> 312170.78 | Q25: =Q6 -> 401887.16 | R25: =R6 -> 384025.11 | S25: =S6 -> 433849.88 | T25: =T6 -> 483807.54 | U25: =U6 -> 535532.09 | V25: =U25*(1+$I$45) -> 538209.75
B26: COGS | P26: =P12 -> 231123.95 | Q26: =Q12 -> 299606.7 | R26: =R12 -> 279432.09 | S26: =S12 -> 317959.05 | T26: =T12 -> 356180.13 | U26: =U12 -> 393810.57 | V26: =U26*(1+$I$45) -> 395779.62
B27: Gross Profit | P27: =P25-P26 -> 81046.822 | Q27: =Q25-Q26 -> 102280.45 | R27: =R25-R26 -> 104593.02 | S27: =S25-S26 -> 115890.83 | T27: =T25-T26 -> 127627.4 | U27: =U25-U26 -> 141721.52 | V27: =V25-V26 -> 142430.12
B28: % of Revenue | P28: =P27/P$25 -> 0.25962335 | Q28: =Q27/Q$25 -> 0.25450042 | R28: =R27/R$25 -> 0.27235985 | S28: =S27/S$25 -> 0.26712197 | T28: =T27/T$25 -> 0.26379788 | U28: =U27/U$25 -> 0.26463683 | V28: =V27/V$25 -> 0.26463683
B29: SG&A | P29: =P15 -> 60236.142 | Q29: =Q15 -> 78549.363 | R29: =R15 -> 79066.553 | S29: =S15 -> 83876.936 | T29: =T15 -> 88454.287 | U29: =U15 -> 93105.563 | V29: =U29*(1+$I$45) -> 93571.091
B30: EBIT | P30: =P27-P29 -> 20810.68 | Q30: =Q27-Q29 -> 23731.088 | R30: =R27-R29 -> 25526.466 | S30: =S27-S29 -> 32013.897 | T30: =T27-T29 -> 39173.116 | U30: =U27-U29 -> 48615.952 | V30: =V27-V29 -> 48859.032
B31: % of Revenue | P31: =P30/P$25 -> 0.066664407 | Q31: =Q30/Q$25 -> 0.059049134 | R31: =R30/R$25 -> 0.066470827 | S31: =S30/S$25 -> 0.073790263 | T31: =T30/T$25 -> 0.080968387 | U31: =U30/U$25 -> 0.090780653 | V31: =V30/V$25 -> 0.090780653
B32: Income Tax | P32: 4303.9005 | R32: 5729.469 | S32: 7118.5538 | T32: 9031.9654 | U32: 11315.372 | V32: 11374.258
B33: EBIT after Tax | P33: =P30-P32 -> 16506.779 | R33: =R30-R32 -> 19796.997 | S33: =S30-S32 -> 24895.343 | T33: =T30-T32 -> 30141.15 | U33: =U30-U32 -> 37300.581 | V33: =V30-V32 -> 37484.774
B34: (+) D&A | P34: =P18 -> 4387.6363 | R34: =R18 -> 4388.9114 | S34: =S18 -> 4406.3455 | T34: =T18 -> 4431.8656 | U34: =U18 -> 4510.3795
B35: (-) CAPEX | P35: =CAPEX_HW!Y6+CAPEX_강소!Y6+Projection_미국!Y274+Projection_중국!Y272+Projection_유럽!Y166 -> 4294.9396 | R35: =CAPEX_HW!AA6+CAPEX_강소!AA6+Projection_미국!AA274+Projection_중국!AA272+Projection_유럽!AA166 -> 4357.0404 | S35: =CAPEX_HW!AB6+CAPEX_강소!AB6+Projection_미국!AB274+Projection_중국!AB272+Projection_유럽!AB166 -> 4375.1867 | T35: =CAPEX_HW!AC6+CAPEX_강소!AC6+Projection_미국!AC274+Projection_중국!AC272+Projection_유럽!AC166 -> 4403.4354 | U35: =CAPEX_HW!AD6+CAPEX_강소!AD6+Projection_미국!AD274+Projection_중국!AD272+Projection_유럽!AD166 -> 4480.7549
B36: (+/-) NWC | P36: =NWC_연결!P6 -> -16257.034 | R36: =NWC_연결!R6 -> -9574.7874 | S36: =NWC_연결!S6 -> 20834.399 | T36: =NWC_연결!T6 -> 20951.381 | U36: =NWC_연결!U6 -> 20590.111 | V36: =NWC_연결!V6 -> 1079.4051
B37: FCFF | P37: =P33+P34-P35-P36 -> 32856.509 | R37: =R33+R34-R35-R36 -> 29403.656 | S37: =S33+S34-S35-S36 -> 4092.1031 | T37: =T33+T34-T35-T36 -> 9218.1993 | U37: =U33+U34-U35-U36 -> 16740.094 | V37: =V33+V34-V35-V36 -> 36405.369
B38: 할인기간 | P38: ='Key Assumption'!$I$9/2 -> 0.37671233 | R38: ='Key Assumption'!$I$9+0.5 -> 1.2534247 | S38: =R38+1 -> 2.2534247 | T38: =S38+1 -> 3.2534247 | U38: =T38+1 -> 4.2534247 | V38: =U38 -> 4.2534247
B39: 할인계수 | P39: =1/(1+$I$46)^P38 -> 0.96144905 | R39: =1/(1+$I$46)^R38 -> 0.87738673 | S39: =1/(1+$I$46)^S38 -> 0.79043849 | T39: =1/(1+$I$46)^T38 -> 0.71210675 | U39: =1/(1+$I$46)^U38 -> 0.64153761 | V39: =U39 -> 0.64153761
B40: PV of FCFF | P40: =P37*P39 -> 31589.86 | R40: =R37*R39 -> 25798.377 | S40: =S37*S39 -> 3234.5558 | T40: =T37*T39 -> 6564.342 | U40: =U37*U39 -> 10739.4 | V40: =V37*V39/(I46-I45) -> 222432.51
B41: 대상기간 누적 현재가치 | P41: =SUM(P40:U40) -> 77926.535
B42: Terminal Value의 현재가치 | P42: =V40 -> 222432.51
B43: 영업가치 | P43: =P42+P41 -> 300359.04
B45: 영구성장률 | I45: 0.005
...

Sheet Proforma BS
A1: =MID(CELL("filename",A1),FIND("]",CELL("filename",A1))+1,255) -> Proforma BS
B3: 1. Consolidated
L5: 2021(A) | M5: 2022(A) | N5: 2023(A) | O5: 24.3m(A) | P5: 24.9m(E) | Q5: 2024(F) | R5: 2025(F) | S5: 2026(F) | T5: 2027(F) | U5: 2028(F)
B6: 유동자산 | L6: 348659.32 | M6: 326604.66 | N6: 261417.96 | O6: 261289.84 | P6: =SUM(P7:P9) -> 290129.7 | Q6: =SUM(Q7:Q9) -> 290129.32 | R6: =SUM(R7:R9) -> 306079.43 | S6: =SUM(S7:S9) -> 338454.86 | T6: =SUM(T7:T9) -> 376176.48 | U6: =SUM(U7:U9) -> 421085.34
C7: 현금및현금성자산 | L7: 49615.27 | M7: 47352.205 | N7: 33949.401 | O7: 32054.35 | P7: ='Proforma CF'!P28 -> 63667.583 | Q7: ='Proforma CF'!Q28 -> 63667.205 | R7: ='Proforma CF'!R28 -> 92904.807 | S7: ='Proforma CF'!S28 -> 96863.437 | T7: ='Proforma CF'!T28 -> 106081.64 | U7: ='Proforma CF'!U28 -> 122821.73
C8: 운전자산 | L8: =NWC_연결!L8 -> 296182.39 | M8: =NWC_연결!M8 -> 275437.12 | N8: =NWC_연결!N8 -> 224805.55 | O8: =NWC_연결!O8 -> 225839.03 | P8: =NWC_연결!P8 -> 223065.66 | Q8: =NWC_연결!Q8 -> 223065.66 | R8: =NWC_연결!R8 -> 209778.16 | S8: =NWC_연결!S8 -> 238194.97 | ... U8: =NWC_연결!U8 -> 294867.15
C9: 기타유동자산 | L9: =L6-SUM(L7:L8) -> 2861.6639 | M9: =M6-SUM(M7:M8) -> 3815.3399 | N9: =N6-SUM(N7:N8) -> 2663.0124 | O9: =O6-SUM(O7:O8) -> 3396.4569 | P9: =O9 -> 3396.4569 | Q9: =P9 -> 3396.4569 | R9: =Q9 -> 3396.4569 | S9: =R9 -> 3396.4569 | T9: =S9 -> 3396.4569 | U9: =T9 -> 3396.4569
B10: 비유동자산 | L10: 48763.271 | M10: 55075.956 | N10: 49991.27 | O10: 49896.044 | P10: =SUM(P11:P12) -> 49803.347 | Q10: =SUM(Q11:Q12) -> 49803.347 | R10: =SUM(R11:R12) -> 49771.476 | S10: =SUM(S11:S12) -> 49740.317 | T10: =SUM(T11:T12) -> 49711.887 | U10: =SUM(U11:U12) -> 49682.262
C11: 유무형자산 | L11: 45847.265 | M11: 44335.772 | N11: 41352.385 | O11: 40759.559 | P11: =O11-'Proforma CF'!P21-'Proforma CF'!P10 -> 40666.862 | Q11: =P11 -> 40666.862 | R11: =Q11-'Proforma CF'!R21-'Proforma CF'!R10 -> 40634.991 | S11: =R11-'Proforma CF'!S21-'Proforma CF'!S10 -> 40603.832 | T11: =S11-'Proforma CF'!T21-'Proforma CF'!T10 -> 40575.402 | U11: =T11-'Proforma CF'!U21-'Proforma CF'!U10 -> 40545.778
C12: 기타비유동자산 | L12: =L10-L11 -> 2916.0068 | M12: =M10-M11 -> 10740.185 | N12: =N10-N11 -> 8638.8845 | O12: =O10-O11 -> 9136.4849 | P12: =O12 -> 9136.4849 | Q12: =P12 -> 9136.4849 | R12: =Q12 -> 9136.4849 | S12: =R12 -> 9136.4849 | T12: =S12 -> 9136.4849 | U12: =T12 -> 9136.4849
B13: 자산총계 | L13: =L6+L10 -> 397422.6 | M13: =M6+M10 -> 381680.62 | N13: =N6+N10 -> 311409.23 | O13: =O6+O10 -> 311185.88 | P13: =P6+P10 -> 339933.05 | Q13: =Q6+Q10 -> 339932.67 | R13: =R6+R10 -> 355850.9 | S13: =S6+S10 -> 388195.18 | ... U13: =U6+U10 -> 470767.6
B14: 유동부채 | L14: 133932.14 | M14: 142933.39 | N14: 76739.878 | O14: 77804.858 | P14: =SUM(P15:P17) -> 91288.523 | Q14: =SUM(Q15:Q17) -> 91288.523 | R14: =SUM(R15:R17) -> 87575.813 | S14: =SUM(S15:S17) -> 95158.221 | T14: =SUM(T15:T17) -> 102710.26 | U14: =SUM(U15:U17) -> 110288.91
C15: 운전부채 | L15: =NWC_연결!L36 -> 78564.102 | M15: =NWC_연결!M36 -> 87002.549 | N15: =NWC_연결!N36 -> 49260.644 | O15: =NWC_연결!O36 -> 46502.089 | P15: =NWC_연결!P36 -> 59985.753 | Q15: =NWC_연결!Q36 -> 59985.753 | R15: =NWC_연결!R36 -> 56273.043 | S15: =NWC_연결!S36 -> 63855.451 | ... U15: =NWC_연결!U36 -> 78986.143
C16: 단기차입금 | L16: 43377.942 | M16: 44481.344 | N16: 15294.991 | O16: 18319.887 | P16: =O16 -> 18319.887 | Q16: =P16 -> 18319.887 | R16: =Q16 -> 18319.887 | S16: =R16 -> 18319.887 | T16: =S16 -> 18319.887 | U16: =T16 -> 18319.887
C17: 기타유동부채 | L17: =L14-SUM(L15:L16) -> 11990.098 | M17: =M14-SUM(M15:M16) -> 11449.502 | N17: =N14-SUM(N15:N16) -> 12184.243 | O17: =O14-SUM(O15:O16) -> 12982.882 | P17: =O17 -> 12982.882 | Q17: =P17 -> 12982.882 | R17: =Q17 -> 12982.882 | S17: =R17 -> 12982.882 | T17: =S17 -> 12982.882 | U17: =T17 -> 12982.882
B18: 비유동부채 | L18: 48887.947 | M18: 13028.576 | N18: 26775.73 | O18: 22430.027 | P18: =SUM(P19:P20) -> 22430.027 | Q18: =SUM(Q19:Q20) -> 22430.027 | R18: =SUM(R19:R20) -> 22430.027 | S18: =SUM(S19:S20) -> 22430.027 | T18: =SUM(T19:T20) -> 22430.027 | U18: =SUM(U19:U20) -> 22430.027
C19: 장기차입금 | L19: 41160.42 | M19: 6756 | N19: 21727.92 | O19: 17010.64 | P19: =O19 -> 17010.64 | Q19: =P19 -> 17010.64 | R19: =Q19 -> 17010.64 | S19: =R19 -> 17010.64 | T19: =S19 -> 17010.64 | U19: =T19 -> 17010.64
C20: 기타비유동부채 | L20: =L18-L19 -> 7727.5269 | M20: =M18-M19 -> 6272.5756 | N20: =N18-N19 -> 5047.8099 | O20: =O18-O19 -> 5419.3869 | P20: =O20 -> 5419.3869 | Q20: =P20 -> 5419.3869 | R20: =Q20 -> 5419.3869 | S20: =R20 -> 5419.3869 | T20: =S20 -> 5419.3869 | U20: =T20 -> 5419.3869
B21: 부채총계 | L21: =L14+L18 -> 182820.09 | M21: =M14+M18 -> 155961.97 | N21: =N14+N18 -> 103515.61 | O21: =O14+O18 -> 100234.89 | P21: =P14+P18 -> 113718.55 | Q21: =Q14+Q18 -> 113718.55 | R21: =R14+R18 -> 110005.84 | S21: =S14+S18 -> 117588.25 | ... U21: =U14+U18 -> 132718.94
B22: 자본총계 | L22: =L13-L21 -> 214602.51 | M22: =M13-M21 -> 225718.65 | N22: =N13-N21 -> 207893.63 | O22: =O13-O21 -> 210950.99 | P22: =P13-P21 -> 226214.5 | Q22: =Q13-Q21 -> 226214.12 | R22: =R13-R21 -> 245845.06 | S22: =S13-S21 -> 270606.93 | ... U22: =U13-U21 -> 338048.66

Sheet Proforma CF
A1: =MID(CELL("filename",A1),FIND("]",CELL("filename",A1))+1,255) -> Proforma CF
B3: 1. Consolidated
L5: 2021(A) | M5: 2022(A) | N5: 2023(A) | O5: 24.3m(A) | P5: 24.9m(E) | Q5: 2024(F) | R5: 2025(F) | S5: 2026(F) | T5: 2027(F) | U5: 2028(F)
B6: 영업활동 현금흐름 | M6: =M7+M8+M17+M18+M19 -> 29526.46 | N6: =N7+N8+N17+N18+N19 -> -2171.758 | O6: =O7+O8+O17+O18+O19 -> 318.92586 | P6: =P7+P8+P17+P18+P19 -> 35908.173 | Q6: =Q7+Q8+Q17+Q18+Q19 -> 36226.72 | R6: =R7+R8+R17+R18+R19 -> 33594.642 | S6: =S7+S8+S17+S18+S19 -> 8333.8172 | T6: =T7+T8+T17+T18+T19 -> 13621.635 | U6: =U7+U8+U17+U18+U19 -> 21220.849
C7: 당기순이익 | M7: ='Proforma PL'!M24 -> -17269.009 | N7: ='Proforma PL'!N24 -> -5710.2659 | O7: ='Proforma PL'!O24 -> 1784.2967 | P7: ='Proforma PL'!P24 -> 15263.503 | Q7: ='Proforma PL'!Q24 -> 17047.421 | R7: ='Proforma PL'!R24 -> 19630.943 | S7: ='Proforma PL'!S24 -> 24761.87 | T7: ='Proforma PL'!T24 -> 30141.15 | U7: ='Proforma PL'!U24 -> 37300.581
C8: 조정 | M8: =SUM(M9:M16) -> 46418.571 | N8: =SUM(N9:N16) -> 3618.9728 | O8: =SUM(O9:O16) -> -1753.8767 | P8: =SUM(P9:P16) -> 26191.846 | Q8: =SUM(Q9:Q16) -> 24437.97 | R8: =SUM(R9:R16) -> 19859.222 | S8: =SUM(S9:S16) -> -9176.0267 | T8: =SUM(T9:T16) -> -7487.55 | U8: =SUM(U9:U16) -> -4764.3605
D9: NWC변동 | M9: =-NWC_연결!M6 -> 29183.721 | N9: =-NWC_연결!N6 -> 12889.66 | O9: =-NWC_연결!O6 -> -3792.0324 | P9: =-NWC_연결!P6 -> 16257.034 | Q9: =-NWC_연결!Q6 -> 12465.001 | R9: =-NWC_연결!R6 -> 9574.7874 | S9: =-NWC_연결!S6 -> -20834.399 | T9: =-NWC_연결!T6 -> -20951.381 | U9: =-NWC_연결!U6 -> -20590.111
D10: D&A | M10: ='Proforma PL'!M26 -> 0 | N10: ='Proforma PL'!N26 -> 0 | O10: ='Proforma PL'!O26 -> 1114.4191 | P10: ='Proforma PL'!P26 -> 4387.6363 | Q10: ='Proforma PL'!Q26 -> 5502.0555 | R10: ='Proforma PL'!R26 -> 4388.9114 | S10: ='Proforma PL'!S26 -> 4406.3455 | T10: ='Proforma PL'!T26 -> 4431.8656 | U10: ='Proforma PL'!U26 -> 4510.3795
D11: 이자수익 | M11: ='Proforma PL'!M19 -> 2387.6219 | N11: ='Proforma PL'!N19 -> 2951.2325 | O11: ='Proforma PL'!O19 -> 605.2542 | P11: 0 | Q11: =O11+P11 -> 605.2542 | R11: 0 | S11: 0 | T11: 0 | U11: 0
D12: 이자비용 | M12: ='Proforma PL'!M20 -> -3903.9999 | N12: ='Proforma PL'!N20 -> -3906.604 | O12: ='Proforma PL'!O20 -> -893.76005 | P12: 0 | Q12: =O12+P12 -> -893.76005 | R12: 0 | S12: 0 | T12: 0 | U12: 0
D13: 법인세비용 | M13: ='Proforma PL'!M23 -> 1139.4799 | N13: ='Proforma PL'!N23 -> 1035.8364 | O13: ='Proforma PL'!O23 -> 0 | P13: ='Proforma PL'!P23 -> 5547.1766 | Q13: ='Proforma PL'!Q23 -> 5547.1766 | R13: ='Proforma PL'!R23 -> 5895.5228 | S13: ='Proforma PL'!S23 -> 7252.0264 | T13: ='Proforma PL'!T23 -> 9031.9654 | U13: ='Proforma PL'!U23 -> 11315.372
D14: 기타부채의 증감 | M14: ='Proforma BS'!M17+'Proforma BS'!M20-'Proforma BS'!L17-'Proforma BS'!L20 -> -1995.5477 | N14: ='Proforma BS'!N17+'Proforma BS'!N20-'Proforma BS'!M17-'Proforma BS'!M20 -> -490.02447 | O14: ='Proforma BS'!O17+'Proforma BS'!O20-'Proforma BS'!N17-'Proforma BS'!N20 -> 1170.216 | P14: ='Proforma BS'!P17+'Proforma BS'!P20-'Proforma BS'!O17-'Proforma BS'!O20 -> 0 | Q14: ='Proforma BS'!Q17+'Proforma BS'!Q20-'Proforma BS'!N17-'Proforma BS'!N20 -> 1170.216 | R14: ='Proforma BS'!R17+'Proforma BS'!R20-'Proforma BS'!Q17-'Proforma BS'!Q20 -> 0 | S14: ='Proforma BS'!S17+'Proforma BS'!S20-'Proforma BS'!R17-'Proforma BS'!R20 -> 0 | T14: ='Proforma BS'!T17+'Proforma BS'!T20-'Proforma BS'!S17-'Proforma BS'!S20 -> 0 | U14: ='Proforma BS'!U17+'Proforma BS'!U20-'Proforma BS'!T17-'Proforma BS'!T20 -> 0
D15: 기타자산의 증감 | M15: =-('Proforma BS'!M9+'Proforma BS'!M12-'Proforma BS'!L9-'Proforma BS'!L12) -> -8777.8538 | N15: =-('Proforma BS'!N9+'Proforma BS'!N12-'Proforma BS'!M9-'Proforma BS'!M12) -> 3253.6276 | O15: =-('Proforma BS'!O9+'Proforma BS'!O12-'Proforma BS'!N9-'Proforma BS'!N12) -> -1231.0449 | P15: =-('Proforma BS'!P9+'Proforma BS'!P12-'Proforma BS'!O9-'Proforma BS'!O12) -> 0 | Q15: =-('Proforma BS'!Q9+'Proforma BS'!Q12-'Proforma BS'!N9-'Proforma BS'!N12) -> -1231.0449 | R15: =-('Proforma BS'!R9+'Proforma BS'!R12-'Proforma BS'!Q9-'Proforma BS'!Q12) -> 0 | S15: =-('Proforma BS'!S9+'Proforma BS'!S12-'Proforma BS'!R9-'Proforma BS'!R12) -> 0 | T15: =-('Proforma BS'!T9+'Proforma BS'!T12-'Proforma BS'!S9-'Proforma BS'!S12) -> 0 | U15: =-('Proforma BS'!U9+'Proforma BS'!U12-'Proforma BS'!T9-'Proforma BS'!T12) -> 0
D16: 기타조정 | M16: ='Proforma CE'!M9 -> 28385.15 | N16: ='Proforma CE'!N9 -> -12114.755 | O16: ='Proforma CE'!O9 -> 1273.0714 | P16: 0 | Q16: =O16+P16 -> 1273.0714 | R16: 0 | S16: 0 | T16: 0 | U16: 0
C17: 이자수취 | M17: =-M11 -> -2387.6219 | N17: =-N11 -> -2951.2325 | O17: =-O11 -> -605.2542 | P17: =-P11 -> 0 | Q17: =-Q11 -> -605.2542 | R17: =-R11 -> 0 | S17: =-S11 -> 0 | T17: =-T11 -> 0 | U17: =-U11 -> 0
C18: 이자지급 | M18: =-M12 -> 3903.9999 | N18: =-N12 -> 3906.604 | O18: =-O12 -> 893.76005 | P18: =-P12 -> 0 | Q18: =-Q12 -> 893.76005 | R18: =-R12 -> 0 | S18: =-S12 -> 0 | T18: =-T12 -> 0 | U18: =-U12 -> 0
C19: 법인세납부 | M19: =-M13 -> -1139.4799 | N19: =-N13 -> -1035.8364 | O19: =-O13 -> 0 | P19: =-P13 -> -5547.1766 | Q19: =-Q13 -> -5547.1766 | R19: =-R13 -> -5895.5228 | S19: =-S13 -> -7252.0264 | T19: =-T13 -> -9031.9654 | U19: =-U13 -> -11315.372
B20: 투자활동 현금흐름 | M20: =SUM(M21:M22) -> 1511.4929 | N20: =SUM(N21:N22) -> 2983.3867 | O20: =SUM(O21:O22) -> -521.59306 | P20: =SUM(P21:P22) -> -4294.9396 | Q20: =SUM(Q21:Q22) -> -4816.5326 | R20: =SUM(R21:R22) -> -4357.0404 | S20: =SUM(S21:S22) -> -4375.1867 | T20: =SUM(T21:T22) -> -4403.4354 | U20: =SUM(U21:U22) -> -4480.7549
C21: CAPEX | M21: =-('Proforma BS'!M11-'Proforma BS'!L11+M10) -> 1511.4929 | N21: =-('Proforma BS'!N11-'Proforma BS'!M11+N10) -> 2983.3867 | O21: =-('Proforma BS'!O11-'Proforma BS'!N11+O10) -> -521.59306 | P21: =-(CAPEX_HW!Y6+CAPEX_강소!Y6+Projection_미국!Y274+Projection_중국!Y272+Projection_유럽!Y166) -> -4294.9396 | Q21: =O21+P21 -> -4816.5326 | R21: =-(CAPEX_HW!AA6+CAPEX_강소!AA6+Projection_미국!AA274+Projection_중국!AA272+Projection_유럽!AA166) -> -4357.0404 | S21: =-(CAPEX_HW!AB6+CAPEX_강소!AB6+Projection_미국!AB274+Projection_중국!AB272+Projection_유럽!AB166) -> -4375.1867 | T21: =-(CAPEX_HW!AC6+CAPEX_강소!AC6+Projection_미국!AC274+Projection_중국!AC272+Projection_유럽!AC166) -> -4403.4354 | U21: =-(CAPEX_HW!AD6+CAPEX_강소!AD6+Projection_미국!AD274+Projection_중국!AD272+Projection_유럽!AD166) -> -4480.7549
C22: 기타 | M22: 0 | N22: 0 | O22: 0 | P22: 0 | Q22: =O22+P22 -> 0 | R22: 0 | S22: 0 | T22: 0 | U22: 0
B23: 재무활동 현금흐름 | M23: =SUM(M24:M25) -> -33301.018 | N23: =SUM(N24:N25) -> -14214.433 | O23: =SUM(O24:O25) -> -1692.3837 | P23: =SUM(P24:P25) -> 0 | Q23: =SUM(Q24:Q25) -> -1692.3837 | R23: =SUM(R24:R25) -> 0 | S23: =SUM(S24:S25) -> 0 | T23: =SUM(T24:T25) -> 0 | U23: =SUM(U24:U25) -> 0
C24: 차입금변동 | M24: =('Proforma BS'!M16+'Proforma BS'!M19)-('Proforma BS'!L16+'Proforma BS'!L19) -> -33301.018 | N24: =('Proforma BS'!N16+'Proforma BS'!N19)-('Proforma BS'!M16+'Proforma BS'!M19) -> -14214.433 | O24: =('Proforma BS'!O16+'Proforma BS'!O19)-('Proforma BS'!N16+'Proforma BS'!N19) -> -1692.3837 | P24: 0 | Q24: =O24+P24 -> -1692.3837 | R24: =('Proforma BS'!R16+'Proforma BS'!R19)-('Proforma BS'!Q16+'Proforma BS'!Q19) -> 0 | S24: =('Proforma BS'!S16+'Proforma BS'!S19)-('Proforma BS'!R16+'Proforma BS'!R19) -> 0 | T24: =('Proforma BS'!T16+'Proforma BS'!T19)-('Proforma BS'!S16+'Proforma BS'!S19) -> 0 | U24: =('Proforma BS'!U16+'Proforma BS'!U19)-('Proforma BS'!T16+'Proforma BS'!T19) -> 0
C25: 기타 | M25: 0 | N25: 0 | O25: 0 | P25: 0 | Q25: =O25+P25 -> 0 | R25: 0 | S25: 0 | T25: 0 | U25: 0
B26: 현금의 증감 | M26: =M6+M20+M23 -> -2263.0651 | N26: =N6+N20+N23 -> -13402.804 | O26: =O6+O20+O23 -> -1895.0509 | P26: =P6+P20+P23 -> 31613.233 | Q26: =Q6+Q20+Q23 -> 29717.804 | R26: =R6+R20+R23 -> 29237.602 | S26: =S6+S20+S23 -> 3958.6305 | T26: =T6+T20+T23 -> 9218.1993 | U26: =U6+U20+U23 -> 16740.094
B27: 기초 현금 | M27: ='Proforma BS'!L7 -> 49615.27 | N27: ='Proforma BS'!M7 -> 47352.205 | O27: ='Proforma BS'!N7 -> 33949.401 | P27: =O28 -> 32054.35 | Q27: ='Proforma BS'!N7 -> 33949.401 | R27: =Q28 -> 63667.205 | S27: =R28 -> 92904.807 | T27: =S28 -> 96863.437 | U27: =T28 -> 106081.64
B28: 기말 현금 | M28: =SUM(M26:M27) -> 47352.205 | N28: =SUM(N26:N27) -> 33949.401 | O28: =SUM(O26:O27) -> 32054.35 | P28: =SUM(P26:P27) -> 63667.583 | Q28: =SUM(Q26:Q27) -> 63667.205 | R28: =SUM(R26:R27) -> 92904.807 | S28: =SUM(S26:S27) -> 96863.437 | T28: =SUM(T26:T27) -> 106081.64 | U28: =SUM(U26:U27) -> 122821.73

Sheet Proforma CE
A1: =MID(CELL("filename",A1),FIND("]",CELL("filename",A1))+1,255) -> Proforma CE
B3: 1. Consolidated
L5: 2021(A) | M5: 2022(A) | N5: 2023(A) | O5: 24.3m(A) | P5: 24.9m(E) | Q5: 2024(F) | R5: 2025(F) | S5: 2026(F) | T5: 2027(F) | U5: 2028(F)
B6: 기초 | M6: 214602.51 | N6: 225718.65 | O6: 207893.63 | P6: =O10 -> 210950.99 | Q6: =O6 -> 207893.63 | R6: =Q10 -> 226214.12 | S6: =R10 -> 245845.06 | T6: =S10 -> 270606.93 | U6: =T10 -> 300748.08
B7: 당기순이익 | M7: ='Proforma PL'!M24 -> -17269.009 | N7: ='Proforma PL'!N24 -> -5710.2659 | O7: ='Proforma PL'!O24 -> 1784.2967 | P7: ='Proforma PL'!P24 -> 15263.503 | Q7: ='Proforma PL'!Q24 -> 17047.421 | R7: ='Proforma PL'!R24 -> 19630.943 | S7: ='Proforma PL'!S24 -> 24761.87 | T7: ='Proforma PL'!T24 -> 30141.15 | U7: ='Proforma PL'!U24 -> 37300.581
B8: 배당 | M8: 0 | N8: 0 | O8: 0 | P8: 0 | Q8: =O8+P8 -> 0 | R8: 0 | S8: 0 | T8: 0 | U8: 0
B9: 해외사업장환산손익 | M9: =-(M6+M7-M10) -> 28385.15 | N9: =-(N6+N7-N10) -> -12114.755 | O9: =-(O6+O7-O10) -> 1273.0714 | P9: =-'Proforma PL'!$X$26 -> 0 | Q9: =O9+P9 -> 1273.0714 | R9: 0 | S9: 0 | T9: 0 | U9: 0
B10: 기말 | M10: 225718.65 | N10: 207893.63 | O10: 210950.99 | P10: =SUM(P6:P9) -> 226214.5 | Q10: =SUM(Q6:Q9) -> 226214.12 | R10: =SUM(R6:R9) -> 245845.06 | S10: =SUM(S6:S9) -> 270606.93 | T10: =SUM(T6:T9) -> 300748.08 | U10: =SUM(U6:U9) -> 338048.66

Sheet Proforma PL
A1: =MID(CELL("filename",A1),FIND("]",CELL("filename",A1))+1,255) -> Proforma PL
B3: 1. Consolidated
L5: 2021(A) | M5: 2022(A) | N5: 2023(A) | O5: 24.3m(A) | P5: 24.9m(E) | Q5: 2024(F) | R5: 2025(F) | S5: 2026(F) | T5: 2027(F) | U5: 2028(F)
B6: 매출액 | L6: 452648.37 | M6: 440670.04 | N6: 424735.38 | O6: =SUM(O34,O59,O81,O103,O125,O147) -> 89716.379 | P6: =SUM(P34,P59,P81,P103,P125,P147) -> 312170.78 | Q6: =SUM(Q34,Q59,Q81,Q103,Q125,Q147) -> 401887.16 | R6: =SUM(R34,R59,R81,R103,R125,R147) -> 384025.11 | S6: =SUM(S34,S59,S81,S103,S125,S147) -> 433849.88 | T6: =SUM(T34,T59,T81,T103,T125,T147) -> 483807.54 | U6: =SUM(U34,U59,U81,U103,U125,U147) -> 535532.09
C7: 국내 | O7: =O35 -> 32117.625 | P7: =P35 -> 134103.49 | Q7: =Q35 -> 166221.11 | R7: =R35 -> 162076.51 | S7: =S35 -> 186135.91 | T7: =T35 -> 207378.78 | U7: =U35 -> 232356.82
C8: 미주 | O8: 13939.073 | P8: =P59 -> 52334.224 | Q8: 66273.296 | R8: =R59 -> 59731.026 | S8: =S59 -> 64926.093 | T8: =T59 -> 69442.616 | U8: =U59 -> 76922.963
C9: 유럽 | O9: 13488.451 | P9: =P81 -> 48793.04 | Q9: 62281.491 | R9: =R81 -> 59615.67 | S9: =S81 -> 66472.55 | T9: =T81 -> 72281.457 | U9: =U81 -> 78126.589
C10: 중국 | O10: 14020.191 | P10: =P103 -> 36602.449 | Q10: 50622.64 | R10: =R103 -> 53388.54 | S10: =S103 -> 63265.924 | T10: =T103 -> 76460.228 | U10: =U103 -> 83020.2
C11: 직수출 | O11: =O36 -> 16151.039 | P11: =P36 -> 40337.577 | Q11: =Q36 -> 56488.616 | R11: =R36 -> 49213.365 | S11: =S36 -> 53049.402 | T11: =T36 -> 58244.454 | U11: =U36 -> 65105.515
B12: 매출원가 | L12: 409694.77 | M12: 360581.46 | N12: 345731 | O12: =SUM(O38,O60,O82,O104,O126,O148) -> 68482.371 | P12: =SUM(P38,P60,P82,P104,P126,P148) -> 231123.95 | Q12: =SUM(Q38,Q60,Q82,Q104,Q126,Q148)+0.378440499999897 -> 299606.7 | R12: =SUM(R38,R60,R82,R104,R126,R148) -> 279432.09 | S12: =SUM(S38,S60,S82,S104,S126,S148) -> 317959.05 | T12: =SUM(T38,T60,T82,T104,T126,T148) -> 356180.13 | U12: =SUM(U38,U60,U82,U104,U126,U148) -> 393810.57
B13: 매출총이익 | L13: =L6-L12 -> 42953.6 | M13: =M6-M12 -> 80088.587 | N13: =N6-N12 -> 79004.376 | O13: =O6-O12 -> 21234.008 | P13: =P6-P12 -> 81046.822 | Q13: =Q6-Q12 -> 102280.45 | R13: =R6-R12 -> 104593.02 | S13: =S6-S12 -> 115890.83 | ... U13: =U6-U12 -> 141721.52
B14: % GP | L14: =L13/L6 -> 0.09489397 | M14: =M13/M6 -> 0.18174275 | N14: =N13/N6 -> 0.18600846 | O14: =O13/O6 -> 0.23667928 | P14: =P13/P6 -> 0.25962335 | Q14: =Q13/Q6 -> 0.25450042 | R14: =R13/R6 -> 0.27235985 | S14: =S13/S6 -> 0.26712197 | ... U14: =U13/U6 -> 0.26463683
B15: 판매관리비 | L15: 100840.94 | M15: 96440.798 | N15: 80346.348 | O15: =SUM(O41,O63,O85,O107,O129,O151) -> 18313.221 | P15: =SUM(P41,P63,P85,P107,P129,P151) -> 60236.142 | Q15: =SUM(Q41,Q63,Q85,Q107,Q129,Q151) -> 78549.363 | R15: =SUM(R41,R63,R85,R107,R129,R151) -> 79066.553 | S15: =SUM(S41,S63,S85,S107,S129,S151) -> 83876.936 | T15: =SUM(T41,T63,T85,T107,T129,T151) -> 88454.287 | U15: =SUM(U41,U63,U85,U107,U129,U151) -> 93105.563
B16: 영업이익 | L16: =L13-L15 -> -57887.344 | M16: =M13-M15 -> -16352.211 | N16: =N13-N15 -> -1341.9724 | O16: =O13-O15 -> 2920.7872 | P16: =P13-P15 -> 20810.68 | Q16: =Q13-Q15 -> 23731.088 | R16: =R13-R15 -> 25526.466 | S16: =S13-S15 -> 32013.897 | ... U16: =U13-U15 -> 48615.952
B17: % EBIT | L17: =L16/L$6 -> -0.1278859 | M17: =M16/M$6 -> -0.037107608 | N17: =N16/N$6 -> -0.0031595493 | O17: =O16/O$6 -> 0.032555786 | P17: =P16/P$6 -> 0.066664407 | Q17: =Q16/Q$6 -> 0.059049134 | R17: =R16/R$6 -> 0.066470827 | S17: =S16/S$6 -> 0.073790263 | ... U17: =U16/U$6 -> 0.090780653
B18: 영업외손익 | L18: -1319.7445 | M18: 222.68274 | N18: -3332.4572 | O18: -1136.4906 | P18: =SUM(P19:P21) -> 0 | Q18: =SUM(Q19:Q21) -> -1136.4906 | R18: =SUM(R19:R21) -> 0 | S18: =SUM(S19:S21) -> 0 | T18: =SUM(T19:T21) -> 0 | U18: =SUM(U19:U21) -> 0
C19: 이자수익 | L19: 2286.8084 | M19: 2387.6219 | N19: 2951.2325 | O19: 605.2542 | P19: 0 | Q19: =O19+P19 -> 605.2542 | R19: =SUM(R45,R67,R89,R111,R133,R155) -> 0 | S19: =SUM(S45,S67,S89,S111,S133,S155) -> 0 | T19: =SUM(T45,T67,T89,T111,T133,T155) -> 0 | U19: =SUM(U45,U67,U89,U111,U133,U155) -> 0
C20: 이자비용 | L20: -4213.3726 | M20: -3903.9999 | N20: -3906.604 | O20: -893.76005 | P20: 0 | Q20: =O20+P20 -> -893.76005 | R20: =SUM(R46,R68,R90,R112,R134,R156) -> 0 | S20: =SUM(S46,S68,S90,S112,S134,S156) -> 0 | T20: =SUM(T46,T68,T90,T112,T134,T156) -> 0 | U20: =SUM(U46,U68,U90,U112,U134,U156) -> 0
C21: 기타영업외손익 | L21: =L18-SUM(L19:L20) -> 606.81979 | M21: =M18-SUM(M19:M20) -> 1739.0608 | N21: =N18-SUM(N19:N20) -> -2377.0857 | O21: =O18-SUM(O19:O20) -> -847.98471 | P21: 0 | Q21: =O21+P21 -> -847.98471 | R21: =SUM(R47,R69,R91,R113,R135,R157) -> 0 | S21: =SUM(S47,S69,S91,S113,S135,S157) -> 0 | T21: =SUM(T47,T69,T91,T113,T135,T157) -> 0 | U21: =SUM(U47,U69,U91,U113,U135,U157) -> 0
B22: 법인세차감전순손익 | L22: =L16+L18 -> -59207.088 | M22: =M16+M18 -> -16129.529 | N22: =N16+N18 -> -4674.4295 | O22: =O16+O18 -> 1784.2967 | P22: =P16+P18 -> 20810.68 | Q22: =Q16+Q18 -> 22594.598 | R22: =R16+R18 -> 25526.466 | S22: =S16+S18 -> 32013.897 | ... U22: =U16+U18 -> 48615.952
B23: 법인세비용 | L23: 309.5015 | M23: 1139.4799 | N23: 1035.8364 | O23: 0 | P23: =Q23-O23 -> 5547.1766 | Q23: =SUM(Q49,Q71,Q93,Q115,Q137,Q159) -> 5547.1766 | R23: =SUM(R49,R71,R93,R115,R137,R159) -> 5895.5228 | S23: =SUM(S49,S71,S93,S115,S137,S159) -> 7252.0264 | T23: =SUM(T49,T71,T93,T115,T137,T159) -> 9031.9654 | U23: =SUM(U49,U71,U93,U115,U137,U159) -> 11315.372
B24: 당기순이익 | L24: =L22-L23 -> -59516.59 | M24: =M22-M23 -> -17269.009 | N24: =N22-N23 -> -5710.2659 | O24: =O22 -> 1784.2967 | P24: =P22-P23 -> 15263.503 | Q24: =Q22-Q23 -> 17047.421 | R24: =R22-R23 -> 19630.943 | S24: =S22-S23 -> 24761.87 | T24: =T22-T23 -> 30141.15 | U24: =U22-U23 -> 37300.581
B25: NI% | L25: =L24/L$6 -> -0.13148526 | M25: =M24/M$6 -> -0.03918807 | N25: =N24/N$6 -> -0.013444291 | O25: =O24/O$6 -> 0.019888193 | P25: =P24/P$6 -> 0.048894721 | Q25: =Q24/Q$6 -> 0.042418428 | R25: =R24/R$6 -> 0.051118906 | S25: =S24/S$6 -> 0.057074743 | ... U25: =U24/U$6 -> 0.06965144
B26: D&A | O26: =SUM(O52,O74,O96,O118,O140)+-0.378440499999897 -> 1114.4191 | P26: =SUM(P52,P74,P96,P118,P140) -> 4387.6363 | Q26: =SUM(Q52,Q74,Q96,Q118,Q140)+-0.378440499999897 -> 5502.0555 | R26: =SUM(R52,R74,R96,R118,R140) -> 4388.9114 | S26: =SUM(S52,S74,S96,S118,S140) -> 4406.3455 | T26: =SUM(T52,T74,T96,T118,T140) -> 4431.8656 | U26: =SUM(U52,U74,U96,U118,U140) -> 4510.3795
B27: EBITDA | O27: =O16+O26 -> 4035.2064 | P27: =P16+P26 -> 25198.316 | Q27: =Q16+Q26 -> 29233.144 | R27: =R16+R26 -> 29915.378 | S27: =S16+S26 -> 36420.242 | T27: =T16+T26 -> 43604.981 | U27: =U16+U26 -> 53126.332
B28: % EBITDA | O28: =O27/O$6 -> 0.044977366 | P28: =P27/P$6 -> 0.080719651 | Q28: =Q27/Q$6 -> 0.072739682 | R28: =R27/R$6 -> 0.077899536 | S28: =S27/S$6 -> 0.083946646 | T28: =T27/T$6 -> 0.090128776 | U28: =U27/U$6 -> 0.099202892
B31: 2. 국내법인
L33: 2021(A) | M33: 2022(A) | N33: 2023(A) | O33: 24.3m(A) | P33: 24.9m(E) | Q33: 2024(F) | R33: 2025(F) | S33: 2026(F) | T33: 2027(F) | U33: 2028(F)
B34: 매출액 | O34: =O35+O36+O37 -> 75922.089 | P34: =P35+P36+P37 -> 256926.5 | Q34: =Q35+Q36+Q37 -> 332848.59 | R34: =R35+R36+R37 -> 313819.47 | S34: =S35+S36+S37 -> 352044.14 | T34: =T35+T36+T37 -> 388249.09 | U34: =U35+U36+U37 -> 431347.15
C35: 국내 | O35: =Revenue_HW!O7 -> 32117.625 | P35: =Revenue_HW!Y7 -> 134103.49 | Q35: =Revenue_HW!Z7 -> 166221.11 | R35: =Revenue_HW!AA7 -> 162076.51 | S35: =Revenue_HW!AB7 -> 186135.91 | T35: =Revenue_HW!AC7 -> 207378.78 | U35: =Revenue_HW!AD7 -> 232356.82
C36: 직수출 | O36: =Revenue_HW!O10 -> 16151.039 | P36: =Revenue_HW!Y10 -> 40337.577 | Q36: =Revenue_HW!Z10 -> 56488.616 | R36: =Revenue_HW!AA10 -> 49213.365 | S36: =Revenue_HW!AB10 -> 53049.402 | T36: =Revenue_HW!AC10 -> 58244.454 | U36: =Revenue_HW!AD10 -> 65105.515
C37: 해외법인 | O37: =Revenue_HW!O11 -> 27653.424 | P37: =Revenue_HW!Y11 -> 82485.436 | Q37: =Revenue_HW!Z11 -> 110138.86 | R37: =Revenue_HW!AA11 -> 102529.6 | S37: =Revenue_HW!AB11 -> 112858.83 | T37: =Revenue_HW!AC11 -> 122625.85 | U37: =Revenue_HW!AD11 -> 133884.82
B38: 매출원가 | O38: =COGS_HW!O6 -> 60294.782 | P38: =COGS_HW!Y6 -> 201130.51 | Q38: =COGS_HW!Z6 -> 261425.29 | R38: =COGS_HW!AA6 -> 238001.56 | S38: =COGS_HW!AB6 -> 269199.45 | T38: =COGS_HW!AC6 -> 298232.32 | U38: =COGS_HW!AD6 -> 331122.8
B39: 매출총이익 | O39: =O34-O38 -> 15627.307 | P39: =P34-P38 -> 55795.987 | Q39: =Q34-Q38 -> 71423.294 | R39: =R34-R38 -> 75817.914 | S39: =S34-S38 -> 82844.691 | T39: =T34-T38 -> 90016.764 | U39: =U34-U38 -> 100224.36
B40: % GP | O40: =IFERROR(O39/O$34,) -> 0.20583347 | P40: =IFERROR(P39/P$34,) -> 0.21716712 | Q40: =IFERROR(Q39/Q$34,) -> 0.21458193 | R40: =IFERROR(R39/R$34,) -> 0.24159722 | S40: =IFERROR(S39/S$34,) -> 0.23532473 | T40: =IFERROR(T39/T$34,) -> 0.23185313 | U40: =IFERROR(U39/U$34,) -> 0.23235196
B41: 판매관리비 | O41: ='SG&A_HW'!O6 -> 11854.107 | P41: ='SG&A_HW'!Y6 -> 39349.784 | Q41: ='SG&A_HW'!Z6 -> 51203.891 | R41: ='SG&A_HW'!AA6 -> 51425.31 | S41: ='SG&A_HW'!AB6 -> 54986.493 | T41: ='SG&A_HW'!AC6 -> 58307.097 | U41: ='SG&A_HW'!AD6 -> 61720.693
B42: 영업이익 | O42: =O39-O41 -> 3773.1998 | P42: =P39-P41 -> 16446.203 | Q42: =Q39-Q41 -> 20219.403 | R42: =R39-R41 -> 24392.604 | S42: =S39-S41 -> 27858.198 | T42: =T39-T41 -> 31709.668 | U42: =U39-U41 -> 38503.663
B43: % EBIT | O43: =IFERROR(O42/O$34,) -> 0.049698315 | P43: =IFERROR(P42/P$34,) -> 0.064011315 | Q43: =IFERROR(Q42/Q$34,) -> 0.060746548 | R43: =IFERROR(R42/R$34,) -> 0.07772814 | S43: =IFERROR(S42/S$34,) -> 0.079132684 | T43: =IFERROR(T42/T$34,) -> 0.081673515 | U43: =IFERROR(U42/U$34,) -> 0.089263747
B44: 영업외손익 | P44: =SUM(P45:P47) -> 0 | Q44: =SUM(Q45:Q47) -> 0 | R44: =SUM(R45:R47) -> 0 | S44: =SUM(S45:S47) -> 0 | T44: =SUM(T45:T47) -> 0 | U44: =SUM(U45:U47) -> 0
C45: 이자수익
...

Sheet DCF
A1: =MID(CELL("filename",A1),FIND("]",CELL("filename",A1))+1,255) -> DCF
B3: 1. Consolidated
L5: 2021(A) | M5: 2022(A) | N5: 2023(A) | O5: 24.3m(A) | P5: 24.9m(E) | Q5: 2024(F) | R5: 2025(F) | S5: 2026(F) | T5: 2027(F) | U5: 2028(F) | V5: Terminal
B6: Revenue | P6: ='Proforma PL'!P6 -> 312170.78 | Q6: ='Proforma PL'!Q6 -> 401887.16 | R6: ='Proforma PL'!R6 -> 384025.11 | S6: ='Proforma PL'!S6 -> 433849.88 | T6: ='Proforma PL'!T6 -> 483807.54 | U6: ='Proforma PL'!U6 -> 535532.09 | V6: =U6*(1+$I$26) -> 538209.75
B7: COGS | P7: ='Proforma PL'!P12 -> 231123.95 | Q7: ='Proforma PL'!Q12 -> 299606.7 | R7: ='Proforma PL'!R12 -> 279432.09 | S7: ='Proforma PL'!S12 -> 317959.05 | T7: ='Proforma PL'!T12 -> 356180.13 | U7: ='Proforma PL'!U12 -> 393810.57 | V7: =U7*(1+$I$26) -> 395779.62
B8: Gross Profit | P8: =P6-P7 -> 81046.822 | Q8: =Q6-Q7 -> 102280.45 | R8: =R6-R7 -> 104593.02 | S8: =S6-S7 -> 115890.83 | T8: =T6-T7 -> 127627.4 | U8: =U6-U7 -> 141721.52 | V8: =V6-V7 -> 142430.12
B9: % of Revenue | P9: =P8/P$6 -> 0.25962335 | Q9: =Q8/Q$6 -> 0.25450042 | R9: =R8/R$6 -> 0.27235985 | S9: =S8/S$6 -> 0.26712197 | T9: =T8/T$6 -> 0.26379788 | U9: =U8/U$6 -> 0.26463683 | V9: =V8/V$6 -> 0.26463683
B10: SG&A | P10: ='Proforma PL'!P15 -> 60236.142 | Q10: ='Proforma PL'!Q15 -> 78549.363 | R10: ='Proforma PL'!R15 -> 79066.553 | S10: ='Proforma PL'!S15 -> 83876.936 | T10: ='Proforma PL'!T15 -> 88454.287 | U10: ='Proforma PL'!U15 -> 93105.563 | V10: =U10*(1+$I$26) -> 93571.091
B11: EBIT | P11: =P8-P10 -> 20810.68 | Q11: =Q8-Q10 -> 23731.088 | R11: =R8-R10 -> 25526.466 | S11: =S8-S10 -> 32013.897 | T11: =T8-T10 -> 39173.116 | U11: =U8-U10 -> 48615.952 | V11: =V8-V10 -> 48859.032
B12: % of Revenue | P12: =P11/P$6 -> 0.066664407 | Q12: =Q11/Q$6 -> 0.059049134 | R12: =R11/R$6 -> 0.066470827 | S12: =S11/S$6 -> 0.073790263 | T12: =T11/T$6 -> 0.080968387 | U12: =U11/U$6 -> 0.090780653 | V12: =V11/V$6 -> 0.090780653
B13: Income Tax | P13: 4303.9005 | R13: 5729.469 | S13: 7118.5538 | T13: 9031.9654 | U13: 11315.372 | V13: 11374.258
B14: EBIT after Tax | P14: =P11-P13 -> 16506.779 | R14: =R11-R13 -> 19796.997 | S14: =S11-S13 -> 24895.343 | T14: =T11-T13 -> 30141.15 | U14: =U11-U13 -> 37300.581 | V14: =V11-V13 -> 37484.774
B15: (+) D&A | P15: ='Proforma PL'!P26 -> 4387.6363 | R15: ='Proforma PL'!R26 -> 4388.9114 | S15: ='Proforma PL'!S26 -> 4406.3455 | T15: ='Proforma PL'!T26 -> 4431.8656 | U15: ='Proforma PL'!U26 -> 4510.3795
B16: (-) CAPEX | P16: =CAPEX_HW!Y6+CAPEX_강소!Y6+Projection_미국!Y274+Projection_중국!Y272+Projection_유럽!Y166 -> 4294.9396 | R16: =CAPEX_HW!AA6+CAPEX_강소!AA6+Projection_미국!AA274+Projection_중국!AA272+Projection_유럽!AA166 -> 4357.0404 | S16: =CAPEX_HW!AB6+CAPEX_강소!AB6+Projection_미국!AB274+Projection_중국!AB272+Projection_유럽!AB166 -> 4375.1867 | T16: =CAPEX_HW!AC6+CAPEX_강소!AC6+Projection_미국!AC274+Projection_중국!AC272+Projection_유럽!AC166 -> 4403.4354 | U16: =CAPEX_HW!AD6+CAPEX_강소!AD6+Projection_미국!AD274+Projection_중국!AD272+Projection_유럽!AD166 -> 4480.7549
B17: (+/-) NWC | P17: =NWC_연결!P6 -> -16257.034 | R17: =NWC_연결!R6 -> -9574.7874 | S17: =NWC_연결!S6 -> 20834.399 | T17: =NWC_연결!T6 -> 20951.381 | U17: =NWC_연결!U6 -> 20590.111 | V17: =NWC_연결!V6 -> 1079.4051
B18: FCFF | P18: =P14+P15-P16-P17 -> 32856.509 | R18: =R14+R15-R16-R17 -> 29403.656 | S18: =S14+S15-S16-S17 -> 4092.1031 | T18: =T14+T15-T16-T17 -> 9218.1993 | U18: =U14+U15-U16-U17 -> 16740.094 | V18: =V14+V15-V16-V17 -> 36405.369
B19: 할인기간 | P19: ='Key Assumption'!$I$9/2 -> 0.37671233 | R19: ='Key Assumption'!$I$9+0.5 -> 1.2534247 | S19: =R19+1 -> 2.2534247 | T19: =S19+1 -> 3.2534247 | U19: =T19+1 -> 4.2534247 | V19: =U19 -> 4.2534247
B20: 할인계수 | P20: =1/(1+$I$27)^P19 -> 0.96144905 | R20: =1/(1+$I$27)^R19 -> 0.87738673 | S20: =1/(1+$I$27)^S19 -> 0.79043849 | T20: =1/(1+$I$27)^T19 -> 0.71210675 | U20: =1/(1+$I$27)^U19 -> 0.64153761 | V20: =U20 -> 0.64153761
B21: PV of FCFF | P21: =P18*P20 -> 31589.86 | R21: =R18*R20 -> 25798.377 | S21: =S18*S20 -> 3234.5558 | T21: =T18*T20 -> 6564.342 | U21: =U18*U20 -> 10739.4 | V21: =V18*V20/(I27-I26) -> 222432.51
B22: 대상기간 누적 현재가치 | P22: =SUM(P21:U21) -> 77926.535
B23: Terminal Value의 현재가치 | P23: =V21 -> 222432.51
B24: 영업가치 | P24: =P23+P22 -> 300359.04
B26: 영구성장률 | I26: 0.005
B27: WACC | I27: 0.11 | T27: 영구성장률
Q28: =$I$34 -> 303168.4 | R28: 0 | S28: 0.0025 | T28: 0.005 | U28: 0.0075 | V28: 0.01
B29: DCF Results | Q29: =Q30-0.5% -> 0.1 | R29: 330117.76 | S29: 333624.88 | T29: 337316.58 | U29: 341207.83 | V29: 345315.27
B30: 영업가치 | I30: =P24 -> 300359.04 | Q30: =Q31-0.5% -> 0.105 | R30: 313228.53 | S30: 316217.97 | T30: 319356.87 | U30: 322656.74 | V30: 326130.29
B31: NOA | I31: 38139.886 | P31: WACC | Q31: 0.11 | R31: 297935.42 | S31: 300491.06 | T31: 303168.4 | U31: 305976.35 | V31: 308924.69
B32: 기업가치 | I32: =I30+I31 -> 338498.93 | Q32: =Q31+0.5% -> 0.115 | R32: 284028.51 | S32: 286218.45 | T32: 288507.93 | U32: 290903.9 | V32: 293413.96
B33: IBD | I33: 35330.527 | Q33: =Q32+0.5% -> 0.12 | R33: 271332.94 | S33: 273212.88 | T33: 275174.55 | U33: 277223.41 | V33: 279365.4
B34: 지분가치 | I34: =I32-I33 -> 303168.4
I36: GPCM | J36: GTM
B37: 2024 EBITDA | I37: ='Proforma PL'!Q27 -> 29233.144 | J37: =I37 -> 29233.144
B38: Multiple
C39: Min | I39: 4 | J39: 8
C40: Max | I40: 6 | J40: 10
B41: EV
C42: Min | I42: =I$37*I39 -> 116932.58 | J42: =J$37*J39 -> 233865.15
C43: Max | I43: =I$37*I40 -> 175398.86 | J43: =J$37*J40 -> 292331.44
B44: Net Debt | I44: =I33-I31 -> -2809.3584 | J44: =I44 -> -2809.3584
...

Sheet Key Assumption
A1: =MID(CELL("filename",A1),FIND("]",CELL("filename",A1))+1,255) -> Key Assumption
B3: 0. General
B5: Key Base Factors
B6: Valuation Date | I6: 45382
B7: Market Data Date | I7: =I6 -> 45382
B8: Year End after Valuation Date | I8: 45657
B9: Partial Period Factor | I9: =(I8-I7)/365 -> 0.75342466
B11: Macro Indicators(from EIU) | L11: 2021A | M11: 2022A | N11: 2023A | O11: 1월 | P11: 2월 | Q11: 3월 | R11: 4월 | S11: 5월 | T11: 6월 | U11: 7월 | V11: 8월 | W11: 9월 | X11: 10월 | Y11: 11월 | Z11: 12월 | AA11: 2024F | AB11: 2025F | AC11: 2026F | AD11: 2027F | AE11: 2028F
B12: 한국
C13: 소비자물가지수 (avg.) | L13: 0.025 | M13: 0.05089 | N13: 0.03591 | AA13: 0.021 | AB13: 0.016 | AC13: 0.02 | AD13: 0.017 | AE13: 0.018
C14: 생산자물가지수 (avg.) | L14: 0.06379 | M14: 0.08376 | N14: 0.01609 | AA14: 0.022 | AB14: 0.019 | AC14: 0.016 | AD14: 0.02 | AE14: 0.018
C15: 평균명목임금상승률 | L15: 0.05024 | M15: 0.04897 | N15: 0.025 | AA15: 0.032 | AB15: 0.028 | AC15: 0.041 | AD15: 0.034 | AE15: 0.035
B16: 일본
C17: 소비자물가지수 (avg.) | L17: -0.00233 | M17: 0.02498 | N17: 0.03268 | AA17: 0.023 | AB17: 0.014 | AC17: 0.013 | AD17: 0.014 | AE17: 0.012
C18: 생산자물가지수 (avg.) | L18: 0.04608 | M18: 0.09814 | N18: 0.04178 | AA18: 0.016 | AB18: 0.011 | AC18: 0.013 | AD18: 0.012 | AE18: 0.014
C19: 평균명목임금상승률 | L19: 0.00901 | M19: 0.02999 | N19: 0.01883 | AA19: 0.03 | AB19: 0.018 | AC19: 0.017 | AD19: 0.017 | AE19: 0.016
B20: 미국
C21: 소비자물가지수 (avg.) | L21: 0.04682 | M21: 0.07992 | N21: 0.04128 | AA21: 0.025 | AB21: 0.021 | AC21: 0.023 | AD21: 0.023 | AE21: 0.024
C22: 생산자물가지수 (avg.) | L22: 0.06979 | M22: 0.09479 | N22: 0.02024 | AA22: 0.015 | AB22: 0.019 | AC22: 0.022 | AD22: 0.02 | AE22: 0.02
C23: 평균명목임금상승률 | L23: 0.04955 | M23: 0.06391 | N23: 0.04964 | AA23: 0.029 | AB23: 0.025 | AC23: 0.029 | AD23: 0.029 | AE23: 0.031
B24: 중국
C25: 소비자물가지수 (avg.) | L25: 0.00851 | M25: 0.01878 | N25: 0.00333 | AA25: 0.01 | AB25: 0.013 | AC25: 0.015 | AD25: 0.016 | AE25: 0.018
C26: 생산자물가지수 (avg.) | L26: 0.08126 | M26: 0.03955 | N26: -0.03009 | AA26: 0.02 | AB26: 0.016 | AC26: 0.01 | AD26: 0.015 | AE26: 0.007
C27: 평균명목임금상승률 | L27: 0.09713 | M27: 0.06732 | N27: 0.073 | AA27: 0.064 | AB27: 0.06 | AC27: 0.055 | AD27: 0.05 | AE27: 0.047
B28: 유럽
C29: 소비자물가지수 (avg.) | L29: 0.03212 | M29: 0.08658 | N29: 0.06016 | AA29: 0.021 | AB29: 0.019 | AC29: 0.019 | AD29: 0.02 | AE29: 0.02
C30: 생산자물가지수 (avg.) | L30: 0.09693 | M30: 0.33282 | N30: -0.02044 | AA30: -0.002 | AB30: 0.015 | AC30: 0.011 | AD30: 0.01 | AE30: 0.009
C31: 평균명목임금상승률 | L31: 0.01518 | M31: 0.02642 | N31: 0.04 | AA31: 0.024 | AB31: 0.029 | AC31: 0.026 | AD31: 0.027 | AE31: 0.027
H33: 1. 블룸버그 / 2. EIU / 3. 평균치
I34: 2018A | J34: 2019A | K34: 2020A | L34: 2021A | M34: 2022A | N34: 2023A | O34: 1월 | P34: 2월 | Q34: 3월 | R34: 4월 | S34: 5월 | T34: 6월 | U34: 7월 | V34: 8월 | W34: 9월 | X34: 10월 | Y34: 11월 | Z34: 12월 | AA34: 2024F | AB34: 2025F | AC34: 2026F | AD34: 2027F | AE34: 2028F
B35: KRW/USD | H35: 2 | I35: =CHOOSE($H$35,I36,I37) -> 1100.1633 | J35: =CHOOSE($H$35,J36,J37) -> 1165.3575 | K35: =CHOOSE($H$35,K36,K37) -> 1180.2658 | L35: =CHOOSE($H$35,L36,L37) -> 1143.9583 | M35: =CHOOSE($H$35,M36,M37) -> 1291.4467 | N35: =CHOOSE($H$35,N36,N37) -> 1305.6625 | O35: =CHOOSE($H35,O36,O37,AVERAGE(O36:O37)) -> 1330.6 | P35: =CHOOSE($H35,P36,P37,AVERAGE(P36:P37)) -> 1330.6 | Q35: =CHOOSE($H35,Q36,Q37,AVERAGE(Q36:Q37)) -> 1330.6 | R35: =CHOOSE($H35,R36,R37,AVERAGE(R36:R37)) -> 1308.6 | S35: =CHOOSE($H35,S36,S37,AVERAGE(S36:S37)) -> 1308.6 | T35: =CHOOSE($H35,T36,T37,AVERAGE(T36:T37)) -> 1308.6 | U35: =CHOOSE($H35,U36,U37,AVERAGE(U36:U37)) -> 1289.8 | V35: =CHOOSE($H35,V36,V37,AVERAGE(V36:V37)) -> 1289.8 | ... AE35: =CHOOSE($H35,AE36,AE37,AVERAGE(AE36:AE37)) -> 1212
C36: 블룸버그 | I36: 1100.1633 | J36: 1165.3575 | K36: 1180.2658 | L36: 1143.9583 | M36: 1291.4467 | N36: 1305.6625 | O36: 1270 | P36: 1270 | Q36: 1270 | R36: 1369.863 | S36: =R36 -> 1369.863 | T36: =S36 -> 1369.863 | U36: 1351.3514 | V36: =U36 -> 1351.3514 | W36: =V36 -> 1351.3514 | X36: 1333.3333 | Y36: =X36 -> 1333.3333 | Z36: =Y36 -> 1333.3333 | AA36: =Z36 -> 1333.3333 | AB36: 1265.8228 | AC36: 1234.5679 | AD36: 1282.0513 | AE36: =AD36 -> 1282.0513
C37: EIU | I37: =I36 -> 1100.1633 | J37: =J36 -> 1165.3575 | K37: =K36 -> 1180.2658 | L37: =L36 -> 1143.9583 | M37: =M36 -> 1291.4467 | N37: =N36 -> 1305.6625 | O37: =P37 -> 1330.6 | P37: =Q37 -> 1330.6 | Q37: 1330.6 | R37: =S37 -> 1308.6 | S37: =T37 -> 1308.6 | T37: 1308.6 | U37: =V37 -> 1289.8 | V37: =W37 -> 1289.8 | W37: 1289.8 | X37: =Y37 -> 1259.9 | Y37: =Z37 -> 1259.9 | Z37: 1259.9 | AA37: 1289.2 | AB37: 1214.2 | AC37: 1201.8 | AD37: 1199.3 | AE37: 1212
B38: KRW/JPY | H38: 2 | I38: =CHOOSE($H$35,I39,I40) -> 9.96239 | J38: =CHOOSE($H$35,J39,J40) -> 10.688575 | K38: =CHOOSE($H$35,K39,K40) -> 11.054715 | L38: =CHOOSE($H$35,L39,L40) -> 10.421174 | M38: =CHOOSE($H$35,M39,M40) -> 9.8236886 | N38: =CHOOSE($H$35,N39,N40) -> 9.2937433 | O38: =CHOOSE($H38,O39,O40,AVERAGE(O39:O40)) -> 8.9422043 | P38: =CHOOSE($H38,P39,P40,AVERAGE(P39:P40)) -> 8.9422043 | Q38: =CHOOSE($H38,Q39,Q40,AVERAGE(Q39:Q40)) -> 8.9422043 | R38: =CHOOSE($H38,R39,R40,AVERAGE(R39:R40)) -> 9.2025316 | S38: =CHOOSE($H38,S39,S40,AVERAGE(S39:S40)) -> 9.2025316 | T38: =CHOOSE($H38,T39,T40,AVERAGE(T39:T40)) -> 9.2025316 | U38: =CHOOSE($H38,U39,U40,AVERAGE(U39:U40)) -> 9.6110283 | V38: =CHOOSE($H38,V39,V40,AVERAGE(V39:V40)) -> 9.6110283 | ... AE38: =CHOOSE($H38,AE39,AE40,AVERAGE(AE39:AE40)) -> 11.564885
C39: 블룸버그 | I39: 9.96239 | J39: 10.688575 | K39: 11.054715 | L39: 10.421174 | M39: 9.8236886 | N39: 9.2937433 | O39: 9.538 | P39: 9.538 | Q39: 9.538 | R39: 11.1 | S39: 11.1 | T39: 11.1 | U39: 11 | V39: 11 | W39: 11 | X39: 11 | Y39: 11 | Z39: 11 | AA39: =Z39 -> 11 | AB39: 11 | AC39: 10.6 | AD39: 9.6 | AE39: =AD39 -> 9.6
C40: EIU | I40: =I39 -> 9.96239 | J40: =J39 -> 10.688575 | K40: =K39 -> 11.054715 | L40: =L39 -> 10.421174 | M40: =M39 -> 9.8236886 | N40: =N39 -> 9.2937433 | O40: =P40 -> 8.9422043 | P40: =Q40 -> 8.9422043 | Q40: 8.9422043 | R40: =S40 -> 9.2025316 | S40: =T40 -> 9.2025316 | T40: 9.2025316 | U40: =V40 -> 9.6110283 | V40: =W40 -> 9.6110283 | W40: 9.6110283 | X40: =Y40 -> 9.6470138 | Y40: =Z40 -> 9.6470138 | Z40: 9.6470138 | AA40: 9.2748201 | AB40: 10.413379 | AC40: 11.148423 | AD40: 11.389364 | AE40: 11.564885
B41: KRW/EUR | H41: 2 | I41: =CHOOSE($H$35,I42,I43) -> 1299.8318 | J41: =CHOOSE($H$35,J42,J43) -> 1304.7315 | K41: =CHOOSE($H$35,K42,K43) -> 1347.0156 | L41: =CHOOSE($H$35,L42,L43) -> 1353.9058 | M41: =CHOOSE($H$35,M42,M43) -> 1361.0264 | N41: =CHOOSE($H$35,N42,N43) -> 1413.3789 | O41: =CHOOSE($H41,O42,O43,AVERAGE(O42:O43)) -> 1444.734 | P41: =CHOOSE($H41,P42,P43,AVERAGE(P42:P43)) -> 1444.734 | Q41: =CHOOSE($H41,Q42,Q43,AVERAGE(Q42:Q43)) -> 1444.734 | R41: =CHOOSE($H41,R42,R43,AVERAGE(R42:R43)) -> 1426.4225 | S41: =CHOOSE($H41,S42,S43,AVERAGE(S42:S43)) -> 1426.4225 | T41: =CHOOSE($H41,T42,T43,AVERAGE(T42:T43)) -> 1426.4225 | U41: =CHOOSE($H41,U42,U43,AVERAGE(U42:U43)) -> 1431.6794 | V41: =CHOOSE($H41,V42,V43,AVERAGE(V42:V43)) -> 1431.6794 | ... AE41: =CHOOSE($H41,AE42,AE43,AVERAGE(AE42:AE43)) -> 1418.0414
C42: 블룸버그 | I42: 1299.8318 | J42: 1304.7315 | K42: 1347.0156 | L42: 1353.9058 | M42: 1361.0264 | N42: 1413.3789 | O42: 1401 | P42: 1401 | Q42: 1401 | R42: 1466.2757 | S42: 1466.2757 | T42: 1466.2757 | U42: 1445.0867 | V42: 1445.0867 | W42: 1445.0867 | X42: 1449.2754 | Y42: 1449.2754 | Z42: 1449.2754 | AA42: 1401 | AB42: 1422.4751 | AC42: 1390.8206 | AD42: 1466.2757 | AE42: =AD42 -> 1466.2757
C43: EIU | I43: =I42 -> 1299.8318 | J43: =J42 -> 1304.7315 | K43: =K42 -> 1347.0156 | L43: =L42 -> 1353.9058 | M43: =M42 -> 1361.0264 | N43: =N42 -> 1413.3789 | O43: =P43 -> 1444.734 | P43: =Q43 -> 1444.734 | Q43: 1444.734 | R43: =S43 -> 1426.4225 | S43: =T43 -> 1426.4225 | T43: 1426.4225 | U43: =V43 -> 1431.6794 | V43: =W43 -> 1431.6794 | W43: 1431.6794 | X43: =Y43 -> 1398.4904 | Y43: =Z43 -> 1398.4904 | Z43: 1398.4904 | AA43: 1418.1058 | AB43: 1381.1853 | AC43: 1388.0804 | AD43: 1397.1342 | AE43: 1418.0414
B44: KRW/CNY | H44: 2 | I44: =CHOOSE($H$35,I45,I46) -> 166.28829 | J44: =CHOOSE($H$35,J45,J46) -> 168.68662 | K44: =CHOOSE($H$35,K45,K46) -> 171.03443 | L44: =CHOOSE($H$35,L45,L46) -> 177.38767 | M44: =CHOOSE($H$35,M45,M46) -> 191.69226 | N44: =CHOOSE($H$35,N45,N46) -> 184.31148 | O44: =CHOOSE($H44,O45,O46,AVERAGE(O45:O46)) -> 185.26873 | P44: =CHOOSE($H44,P45,P46,AVERAGE(P45:P46)) -> 185.26873 | Q44: =CHOOSE($H44,Q45,Q46,AVERAGE(Q45:Q46)) -> 185.26873 | R44: =CHOOSE($H44,R45,R46,AVERAGE(R45:R46)) -> 182.15479 | S44: =CHOOSE($H44,S45,S46,AVERAGE(S45:S46)) -> 182.15479 | T44: =CHOOSE($H44,T45,T46,AVERAGE(T45:T46)) -> 182.15479 | U44: =CHOOSE($H44,U45,U46,AVERAGE(U45:U46)) -> 180.89762 | V44: =CHOOSE($H44,V45,V46,AVERAGE(V45:V46)) -> 180.89762 | ... AE44: =CHOOSE($H44,AE45,AE46,AVERAGE(AE45:AE46)) -> 178.682
...

Sheet Revenue_HW
A1: =MID(CELL("filename",A1),FIND("]",CELL("filename",A1))+1,255) -> Revenue_HW
B3: 1. Summary
L5: 2021A | M5: 2022A | N5: 2023A | O5: 24.3m(A) | P5: 4월 | Q5: 5월 | R5: 6월 | S5: 7월 | T5: 8월 | U5: 9월 | V5: 10월 | W5: 11월 | X5: 12월 | Y5: 24.9m(E) | Z5: 2024F | AA5: 2025F | AB5: 2026F | AC5: 2027F | AD5: 2028F
B6: Revenue | O6: =SUM(O7,O10:O11) -> 75922.089 | P6: =SUM(P7,P10:P11) -> 31185.781 | Q6: =SUM(Q7,Q10:Q11) -> 28388.615 | R6: =SUM(R7,R10:R11) -> 30236.481 | S6: =SUM(S7,S10:S11) -> 27502.329 | T6: =SUM(T7,T10:T11) -> 29479.607 | U6: =SUM(U7,U10:U11) -> 28030.159 | V6: =SUM(V7,V10:V11) -> 27965.981 | ... AD6: =SUM(AD7,AD10:AD11) -> 431347.15
C7: 국내 | O7: =O8+O9 -> 32117.625 | P7: =P8+P9 -> 16095.789 | Q7: =Q8+Q9 -> 16190.455 | R7: =R8+R9 -> 16128.559 | S7: =S8+S9 -> 13851.138 | T7: =T8+T9 -> 15176.667 | U7: =U8+U9 -> 14644.102 | V7: =V8+V9 -> 14837.581 | ... AD7: =AD8+AD9 -> 232356.82
D8: Captive | O8: =O32 -> 2474.7736 | P8: =P32 -> 8168.4689 | Q8: =Q32 -> 8227.6115 | R8: =R32 -> 8150.1619 | S8: =S32 -> 7159.766 | T8: =T32 -> 7813.6521 | U8: =U32 -> 7407.2577 | V8: =V32 -> 7550.3174 | ... AD8: =AD32 -> 102379.18
D9: Non-Captive | O9: =O39 -> 29642.852 | P9: =P39 -> 7927.3197 | Q9: =Q39 -> 7962.8439 | R9: =R39 -> 7978.3976 | S9: =S39 -> 6691.3716 | T9: =T39 -> 7363.0147 | U9: =U39 -> 7236.8438 | V9: =V39 -> 7287.2639 | ... AD9: =AD39 -> 129977.64
C10: 직수출 | O10: =O167 -> 16151.039 | P10: =P167 -> 4029.1142 | Q10: =Q167 -> 3985.546 | R10: =R167 -> 5271.1354 | S10: =S167 -> 4023.8946 | T10: =T167 -> 3887.8392 | U10: =U167 -> 4352.3323 | V10: =V167 -> 3853.2827 | ... AD10: =AD167 -> 65105.515
C11: 이전 | O11: =O395 -> 27653.424 | P11: =P395 -> 11060.878 | Q11: =Q395 -> 8212.613 | R11: =R395 -> 8836.7858 | S11: =S395 -> 9627.2965 | T11: =T395 -> 10415.101 | U11: =U395 -> 9033.7251 | V11: =V395 -> 9275.117 | ... AD11: =AD395 -> 133884.82
L13: 2021A | M13: 2022A | N13: 2023A | O13: 24.3m(A) | P13: 4월 | Q13: 5월 | R13: 6월 | S13: 7월 | T13: 8월 | U13: 9월 | V13: 10월 | W13: 11월 | X13: 12월 | Y13: 24.9m(E) | Z13: 2024F | AA13: 2025F | AB13: 2026F | AC13: 2027F | AD13: 2028F
B14: 판매수량 | O14: =SUM(O15:O19) -> 642 | P14: =SUM(P15:P19) -> 272 | Q14: =SUM(Q15:Q19) -> 254 | R14: =SUM(R15:R19) -> 257 | S14: =SUM(S15:S19) -> 251 | T14: =SUM(T15:T19) -> 257 | U14: =SUM(U15:U19) -> 239 | V14: =SUM(V15:V19) -> 251 | ... AD14: =SUM(AD15:AD19) -> 3822
C15: 5축 | O15: =SUM(Revenue_HW!O51,Revenue_HW!O178,Revenue_HW!O221,Revenue_HW!O264,Revenue_HW!O307,Revenue_HW!O350,Revenue_HW!O399,Revenue_HW!O437,Revenue_HW!O475,Revenue_HW!O513) -> 4 | P15: =SUM(Revenue_HW!P51,Revenue_HW!P178,Revenue_HW!P221,Revenue_HW!P264,Revenue_HW!P307,Revenue_HW!P350,Revenue_HW!P399,Revenue_HW!P437,Revenue_HW!P475,Revenue_HW!P513) -> 3 | Q15: =SUM(Revenue_HW!Q51,Revenue_HW!Q178,Revenue_HW!Q221,Revenue_HW!Q264,Revenue_HW!Q307,Revenue_HW!Q350,Revenue_HW!Q399,Revenue_HW!Q437,Revenue_HW!Q475,Revenue_HW!Q513) -> 7 | R15: =SUM(Revenue_HW!R51,Revenue_HW!R178,Revenue_HW!R221,Revenue_HW!R264,Revenue_HW!R307,Revenue_HW!R350,Revenue_HW!R399,Revenue_HW!R437,Revenue_HW!R475,Revenue_HW!R513) -> 7 | S15: =SUM(Revenue_HW!S51,Revenue_HW!S178,Revenue_HW!S221,Revenue_HW!S264,Revenue_HW!S307,Revenue_HW!S350,Revenue_HW!S399,Revenue_HW!S437,Revenue_HW!S475,Revenue_HW!S513) -> 5 | T15: =SUM(Revenue_HW!T51,Revenue_HW!T178,Revenue_HW!T221,Revenue_HW!T264,Revenue_HW!T307,Revenue_HW!T350,Revenue_HW!T399,Revenue_HW!T437,Revenue_HW!T475,Revenue_HW!T513) -> 3 | U15: =SUM(Revenue_HW!U51,Revenue_HW!U178,Revenue_HW!U221,Revenue_HW!U264,Revenue_HW!U307,Revenue_HW!U350,Revenue_HW!U399,Revenue_HW!U437,Revenue_HW!U475,Revenue_HW!U513) -> 6 | V15: =SUM(Revenue_HW!V51,Revenue_HW!V178,Revenue_HW!V221,Revenue_HW!V264,Revenue_HW!V307,Revenue_HW!V350,Revenue_HW!V399,Revenue_HW!V437,Revenue_HW!V475,Revenue_HW!V513) -> 5 | ... AD15: =SUM(Revenue_HW!AD51,Revenue_HW!AD178,Revenue_HW!AD221,Revenue_HW!AD264,Revenue_HW!AD307,Revenue_HW!AD350,Revenue_HW!AD399,Revenue_HW!AD437,Revenue_HW!AD475,Revenue_HW!AD513) -> 103
C16: 선반 | O16: =SUM(O56,O184,O227,O270,O313,O356,O404,O442,O480,O518) -> 387 | P16: =SUM(P56,P184,P227,P270,P313,P356,P404,P442,P480,P518) -> 167 | Q16: =SUM(Q56,Q184,Q227,Q270,Q313,Q356,Q404,Q442,Q480,Q518) -> 144 | R16: =SUM(R56,R184,R227,R270,R313,R356,R404,R442,R480,R518) -> 149 | S16: =SUM(S56,S184,S227,S270,S313,S356,S404,S442,S480,S518) -> 152 | T16: =SUM(T56,T184,T227,T270,T313,T356,T404,T442,T480,T518) -> 149 | U16: =SUM(U56,U184,U227,U270,U313,U356,U404,U442,U480,U518) -> 141 | V16: =SUM(V56,V184,V227,V270,V313,V356,V404,V442,V480,V518) -> 154 | ... AD16: =SUM(AD56,AD184,AD227,AD270,AD313,AD356,AD404,AD442,AD480,AD518) -> 2184
C17: VMC | O17: =SUM(O61,O190,O233,O276,O319,O362,O409,O447,O485,O523) -> 209 | P17: =SUM(P61,P190,P233,P276,P319,P362,P409,P447,P485,P523) -> 77 | Q17: =SUM(Q61,Q190,Q233,Q276,Q319,Q362,Q409,Q447,Q485,Q523) -> 81 | R17: =SUM(R61,R190,R233,R276,R319,R362,R409,R447,R485,R523) -> 80 | S17: =SUM(S61,S190,S233,S276,S319,S362,S409,S447,S485,S523) -> 82 | T17: =SUM(T61,T190,T233,T276,T319,T362,T409,T447,T485,T523) -> 80 | U17: =SUM(U61,U190,U233,U276,U319,U362,U409,U447,U485,U523) -> 67 | V17: =SUM(V61,V190,V233,V276,V319,V362,V409,V447,V485,V523) -> 69 | ... AD17: =SUM(AD61,AD190,AD233,AD276,AD319,AD362,AD409,AD447,AD485,AD523) -> 1412
C18: HMC | O18: =SUM(O66,O196,O239,O282,O325,O368,O414,O452,O490,O528) -> 9 | P18: =SUM(P66,P196,P239,P282,P325,P368,P414,P452,P490,P528) -> 10 | Q18: =SUM(Q66,Q196,Q239,Q282,Q325,Q368,Q414,Q452,Q490,Q528) -> 8 | R18: =SUM(R66,R196,R239,R282,R325,R368,R414,R452,R490,R528) -> 11 | S18: =SUM(S66,S196,S239,S282,S325,S368,S414,S452,S490,S528) -> 6 | T18: =SUM(T66,T196,T239,T282,T325,T368,T414,T452,T490,T528) -> 12 | U18: =SUM(U66,U196,U239,U282,U325,U368,U414,U452,U490,U528) -> 9 | V18: =SUM(V66,V196,V239,V282,V325,V368,V414,V452,V490,V528) -> 8 | ... AD18: =SUM(AD66,AD196,AD239,AD282,AD325,AD368,AD414,AD452,AD490,AD528) -> 123
C19: 단종 | O19: =SUM(O71,O202,O245,O288,O331,O374,O419,O457,O495,O533) -> 33 | P19: =SUM(P71,P202,P245,P288,P331,P374,P419,P457,P495,P533) -> 15 | Q19: =SUM(Q71,Q202,Q245,Q288,Q331,Q374,Q419,Q457,Q495,Q533) -> 14 | R19: =SUM(R71,R202,R245,R288,R331,R374,R419,R457,R495,R533) -> 10 | S19: =SUM(S71,S202,S245,S288,S331,S374,S419,S457,S495,S533) -> 6 | T19: =SUM(T71,T202,T245,T288,T331,T374,T419,T457,T495,T533) -> 13 | U19: =SUM(U71,U202,U245,U288,U331,U374,U419,U457,U495,U533) -> 16 | V19: =SUM(V71,V202,V245,V288,V331,V374,V419,V457,V495,V533) -> 15 | ... AD19: =SUM(AD71,AD202,AD245,AD288,AD331,AD374,AD419,AD457,AD495,AD533) -> 0
B21: 2. 국내
AA22: =AA24/Z24-1 -> -0.024934293 | AB22: =AB24/AA24-1 -> 0.14844475 | AC22: =AC24/AB24-1 -> 0.11412558 | AD22: =AD24/AC24-1 -> 0.12044644
L23: 2021A | M23: 2022A | N23: 2023A | O23: 24.3m(A) | P23: 4월 | Q23: 5월 | R23: 6월 | S23: 7월 | T23: 8월 | U23: 9월 | V23: 10월 | W23: 11월 | X23: 12월 | Y23: 24.9m(E) | Z23: 2024F | AA23: 2025F | AB23: 2026F | AC23: 2027F | AD23: 2028F
B24: 국내매출 | O24: =O25 -> 32117.625 | P24: =P25 -> 16095.789 | Q24: =Q25 -> 16190.455 | R24: =R25 -> 16128.559 | S24: =S25 -> 13851.138 | T24: =T25 -> 15176.667 | U24: =U25 -> 14644.102 | V24: =V25 -> 14837.581 | ... AD24: =AD25 -> 232356.82
C25: 전체 | O25: =O26+O27+O28+O29+O30+O31 -> 32117.625 | P25: =P26+P27+P28+P29+P30+P31 -> 16095.789 | Q25: =Q26+Q27+Q28+Q29+Q30+Q31 -> 16190.455 | R25: =R26+R27+R28+R29+R30+R31 -> 16128.559 | S25: =S26+S27+S28+S29+S30+S31 -> 13851.138 | T25: =T26+T27+T28+T29+T30+T31 -> 15176.667 | U25: =U26+U27+U28+U29+U30+U31 -> 14644.102 | V25: =V26+V27+V28+V29+V30+V31 -> 14837.581 | ... AD25: =AD26+AD27+AD28+AD29+AD30+AD31 -> 232356.82
D26: 5축 | O26: =O50 -> 643 | P26: =P50 -> 905.21086 | Q26: =Q50 -> 905.21086 | R26: =R50 -> 1206.9478 | S26: =S50 -> 603.4739 | T26: =T50 -> 603.4739 | U26: =U50 -> 905.21086 | V26: =V50 -> 905.21086 | ... X26: =X50 -> 301.73695 | Y26: =SUM(P26:X26) -> 7241.6869 | Z26: =Z50 -> 7884.6869 | AA26: =AA50 -> 9989.4504 | AB26: =AB50 -> 12683.212 | AC26: =AC50 -> 13646.676 | AD26: =AD50 -> 17051.241
D27: 선반 | O27: =O55 -> 10464.138 | P27: =P55 -> 4927.9832 | Q27: =Q55 -> 5042.5875 | R27: =R55 -> 4927.9832 | S27: =S55 -> 4756.0768 | T27: =T55 -> 4756.0768 | U27: =U55 -> 4469.5662 | V27: =V55 -> 4756.0768 | ... X27: =X55 -> 4297.6598 | Y27: =SUM(P27:X27) -> 42518.181 | Z27: =Z55 -> 52982.318 | AA27: =AA55 -> 56254.374 | AB27: =AB55 -> 61988.76 | AC27: =AC55 -> 67506.077 | AD27: =AD55 -> 72226.305
D28: VMC | O28: =O60 -> 9894.2026 | P28: =P60 -> 4793.1204 | Q28: =Q60 -> 4874.3597 | R28: =R60 -> 4955.599 | S28: =S60 -> 4793.1204 | T28: =T60 -> 4955.599 | U28: =U60 -> 4143.2057 | V28: =V60 -> 4224.4451 | ... X28: =X60 -> 3980.7271 | Y28: =SUM(P28:X28) -> 40863.382 | Z28: =Z60 -> 50757.585 | AA28: =AA60 -> 54340.235 | AB28: =AB60 -> 65297.874 | AC28: =AC60 -> 75555.377 | AD28: =AD60 -> 87028.299
D29: HMC | O29: =O65 -> 963.45 | P29: =P65 -> 1556.6361 | Q29: =Q65 -> 1556.6361 | R29: =R65 -> 1816.0754 | S29: =S65 -> 1297.1967 | T29: =T65 -> 1556.6361 | U29: =U65 -> 1556.6361 | V29: =V65 -> 1816.0754 | ... X29: =X65 -> 1297.1967 | Y29: =SUM(P29:X29) -> 14009.725 | Z29: =Z65 -> 14973.175 | AA29: =AA65 -> 16109.204 | AB29: =AB65 -> 17014.816 | AC29: =AC65 -> 18192.498 | AD29: =AD65 -> 19660.94
D30: 단종 | O30: =O70 -> 2416.508 | P30: =P70 -> 1392.0329 | Q30: =Q70 -> 1276.0302 | R30: =R70 -> 696.01645 | S30: =S70 -> 232.00548 | T30: =T70 -> 928.02193 | U30: =U70 -> 1276.0302 | V30: =V70 -> 812.01919 | ... X30: =X70 -> 928.02193 | Y30: =SUM(P30:X30) -> 8468.2001 | Z30: =Z70 -> 10884.708 | AA30: =AA70 -> 0 | AB30: =AB70 -> 0 | AC30: =AC70 -> 0 | AD30: =AD70 -> 0
D31: 기타 | O31: =O75 -> 7736.3271 | P31: =P75 -> 2520.8052 | Q31: =Q75 -> 2535.6312 | R31: =R75 -> 2525.9375 | S31: =S75 -> 2169.2643 | T31: =T75 -> 2376.859 | U31: =U75 -> 2293.4525 | V31: =V75 -> 2323.7539 | ... X31: =X75 -> 2006.497 | Y31: =SUM(P31:X31) -> 21002.311 | Z31: =Z75 -> 28738.639 | AA31: =AA75 -> 25383.242 | AB31: =AB75 -> 29151.251 | AC31: =AC75 -> 32478.155 | AD31: =AD75 -> 36390.033
C32: Captive | O32: =SUM(O33:O38) -> 2474.7736 | P32: =SUM(P33:P38) -> 8168.4689 | Q32: =SUM(Q33:Q38) -> 8227.6115 | R32: =SUM(R33:R38) -> 8150.1619 | S32: =SUM(S33:S38) -> 7159.766 | T32: =SUM(T33:T38) -> 7813.6521 | U32: =SUM(U33:U38) -> 7407.2577 | V32: =SUM(V33:V38) -> 7550.3174 | ... AD32: =SUM(AD33:AD38) -> 102379.18
D33: 5축 | O33: =O88 -> 0 | P33: =P88 -> 238.73789 | Q33: =Q88 -> 238.73789 | R33: =R88 -> 318.31719 | S33: =S88 -> 159.15859 | T33: =T88 -> 159.15859 | U33: =U88 -> 238.73789 | V33: =V88 -> 238.73789 | ... X33: =X88 -> 79.579297 | Y33: =SUM(P33:X33) -> 1909.9031 | Z33: =Z88 -> 1909.9031 | AA33: =AA88 -> 2401.3468 | AB33: =AB88 -> 3139.3732 | AC33: =AC88 -> 3401.4385 | AD33: =AD88 -> 4150.8203
D34: 선반 | O34: =O93 -> 641.644 | P34: =P93 -> 2600.6302 | Q34: =Q93 -> 2661.11 | R34: =R93 -> 2600.6302 | S34: =S93 -> 2509.9106 | T34: =T93 -> 2509.9106 | U34: =U93 -> 2358.7111 | V34: =V93 -> 2509.9106 | ... X34: =X93 -> 2267.9915 | Y34: =SUM(P34:X34) -> 22437.996 | Z34: =Z93 -> 23079.64 | AA34: =AA93 -> 24470.901 | AB34: =AB93 -> 27312.228 | AC34: =AC93 -> 29957.899 | AD34: =AD93 -> 32136.794
D35: VMC | O35: =O98 -> 923.456 | P35: =P98 -> 2553.239 | Q35: =Q98 -> 2596.5142 | R35: =R98 -> 2639.7895 | S35: =S98 -> 2553.239 | T35: =T98 -> 2639.7895 | U35: =U98 -> 2207.0371 | V35: =V98 -> 2250.3123 | ... X35: =X98 -> 2120.4866 | Y35: =SUM(P35:X35) -> 21767.444 | Z35: =Z98 -> 22690.9 | AA35: =AA98 -> 24282.373 | AB35: =AB98 -> 29498.343 | AC35: =AC98 -> 34380.41 | AD35: =AD98 -> 39752.259
D36: HMC | O36: =O103 -> 0 | P36: =P103 -> 850.07721 | Q36: =Q103 -> 850.07721 | R36: =R103 -> 991.75674 | S36: =S103 -> 708.39767 | T36: =T103 -> 850.07721 | U36: =U103 -> 850.07721 | V36: =V103 -> 991.75674 | ... X36: =X103 -> 708.39767 | Y36: =SUM(P36:X36) -> 7650.6949 | Z36: =Z103 -> 7650.6949 | AA36: =AA103 -> 8237.3594 | AB36: =AB103 -> 8820.1543 | AC36: =AC103 -> 9423.8049 | AD36: =AD103 -> 10305.428
D37: 단종 | O37: =O108 -> 96.65 | P37: =P108 -> 646.4985 | Q37: =Q108 -> 592.62362 | R37: =R108 -> 323.24925 | S37: =S108 -> 107.74975 | T37: =T108 -> 430.999 | U37: =U108 -> 592.62362 | V37: =V108 -> 377.12412 | ... X37: =X108 -> 430.999 | Y37: =SUM(P37:X37) -> 3932.8658 | Z37: =Z108 -> 4029.5158 | AA37: =AA108 -> 0 | AB37: =AB108 -> 0 | AC37: =AC108 -> 0 | AD37: =AD108 -> 0
D38: 기타 | O38: =O113 -> 813.0236 | P38: =P113 -> 1279.2861 | Q38: =Q113 -> 1288.5486 | R38: =R113 -> 1276.419 | S38: =S113 -> 1121.3104 | T38: =T113 -> 1223.7173 | U38: =U113 -> 1160.0708 | V38: =V113 -> 1182.4757 | ... X38: =X113 -> 1041.2756 | Y38: =SUM(P38:X38) -> 10714.392 | Z38: =Z113 -> 11527.416 | AA38: =AA113 -> 11028.788 | AB38: =AB113 -> 12770.257 | AC38: =AC113 -> 14328.878 | AD38: =AD113 -> 16033.882
