Workbook

Sheet for IM
B2: FCF Conversion
C4: 구분 | D4: 25H1 | E4: 억환산 | H4: CAPEX | I4: 25H1
C5: 매출액 | D5: =E81 -> 33392.893 | E5: =D5/100 -> 333.92893 | H5: Titan | I5: =TITAN!M103 -> 42.7038
C6: 영업비용 | D6: =-E85 -> -24315.748 | E6: =D6/100 -> -243.15748 | H6: Class | I6: =CLASS!M103 -> 115.6239
C7: D&A | D7: =E93 -> 57.174702 | E7: =D7/100 -> 0.57174702 | H7: Nova | I7: =NOVA!M79 -> 28.309429
C8: EBITDA | D8: =E94 -> 9134.3195 | E8: =D8/100 -> 91.343195 | F8: =E8/E5 -> 0.27354082 | H8: TTA | I8: =TTA!M87 -> 10.438546
C9: CAPEX | D9: =-SUM(I5:I8) -> -197.07568 | E9: =D9/100 -> -1.9707568
C10: △NWC | D10: =-'Pro forma BS'!M58 -> -2408.5126 | E10: =D10/100 -> -24.085126
C11: FCF | D11: =D8+D9+D10 -> 6528.7312 | E11: =D11/100 -> 65.287312 | F11: =E11/E8 -> 0.71474741
B13: Business Plan Overview
J14: >> 값복사
C15: Year | D15: 강의매출 | E15: 솔루션매출 | F15: 기타매출 | G15: 합계 | H15: EBITDA율 | J15: Year | K15: 강의매출 | L15: 솔루션매출 | M15: 기타매출 | N15: 합계 | O15: EBITDA율
C16: 2024A | D16: =D82/100 -> 111.92304 | F16: =D84 -> 31.054544 | G16: =D81/100 -> 112.23359 | H16: =D95 -> 0.19212933 | J16: 2024A | K16: 111.92304 | M16: 31.054544 | N16: 112.23359 | O16: 0.19212933
C17: 2025E | D17: {=TRANSPOSE(F82:K83)/100} -> 747.53703 | E17: 25.707433 | G17: {=TRANSPOSE(F81:K81)/100} -> 773.24447 | H17: {=TRANSPOSE(F95:K95)} -> 0.29740087 | J17: 2025E | K17: 747.53703 | L17: 25.707433 | N17: 773.24447 | O17: 0.29740087
C18: 2026F | D18: 860.73301 | E18: 71.962766 | G18: 932.69577 | H18: 0.37983296 | J18: 2026F | K18: 860.73301 | L18: 71.962766 | N18: 932.69577 | O18: 0.37983296
C19: 2027F | D19: 941.09021 | E19: 94.261391 | G19: 1035.3516 | H19: 0.42053463 | J19: 2027F | K19: 941.09021 | L19: 94.261391 | N19: 1035.3516 | O19: 0.42053463
C20: 2028F | D20: 1027.0793 | E20: 119.24423 | G20: 1146.3235 | H20: 0.42991681 | J20: 2028F | K20: 1027.0793 | L20: 119.24423 | N20: 1146.3235 | O20: 0.42991681
C21: 2029F | D21: 1114.0782 | E21: 146.53889 | G21: 1260.6171 | H21: 0.43864079 | J21: 2029F | K21: 1114.0782 | L21: 146.53889 | N21: 1260.6171 | O21: 0.43864079
C22: 2030F | D22: 1204.6789 | E22: 176.54417 | G22: 1381.2231 | H22: 0.44670162 | J22: 2030F | K22: 1204.6789 | L22: 176.54417 | N22: 1381.2231 | O22: 0.44670162
B24: KPI
H25: >> 값복사
C26: Year | D26: 부업 강의 | E26: 투자 강의 | F26: 합계 | H26: Year | I26: 부업 강의 | J26: 투자 강의 | K26: 합계
C27: 2024A | D27: =SUM(D36:F36) -> 65 | F27: =D27+E27 -> 65 | H27: 2024A | I27: 65 | K27: 65
C28: 2025E | D28: =SUM(D37:F37) -> 235.1 | E28: {=TRANSPOSE('Key Assumption'!O32:T32)} -> 11 | F28: =D28+E28 -> 246.1 | H28: 2025E | I28: 235.1 | J28: 11 | K28: 246.1
C29: 2026F | D29: =SUM(D38:F38) -> 256.08 | E29: 11 | F29: =D29+E29 -> 267.08 | H29: 2026F | I29: 256.08 | J29: 11 | K29: 267.08
C30: 2027F | D30: =SUM(D39:F39) -> 277.06 | E30: 11 | F30: =D30+E30 -> 288.06 | H30: 2027F | I30: 277.06 | J30: 11 | K30: 288.06
C31: 2028F | D31: =SUM(D40:F40) -> 298.04 | E31: 11 | F31: =D31+E31 -> 309.04 | H31: 2028F | I31: 298.04 | J31: 11 | K31: 309.04
C32: 2029F | D32: =SUM(D41:F41) -> 319.02 | E32: 11 | F32: =D32+E32 -> 330.02 | H32: 2029F | I32: 319.02 | J32: 11 | K32: 330.02
C33: 2030F | D33: =SUM(D42:F42) -> 340 | E33: 11 | F33: =D33+E33 -> 351 | H33: 2030F | I33: 340 | J33: 11 | K33: 351
D35: 부업-Titan | E35: 부업-Class | F35: 부업-TTA
C36: 2024A | D36: ='Key Assumption'!L23 -> 65
C37: 2025E | D37: {=TRANSPOSE('Key Assumption'!O23:T23)} -> 92.2 | E37: {=TRANSPOSE('Key Assumption'!O28:T28)} -> 93.4 | F37: {=TRANSPOSE('Key Assumption'!O37:T37)} -> 49.5
C38: 2026F | D38: 97.76 | E38: 98.72 | F38: 59.6
C39: 2027F | D39: 103.32 | E39: 104.04 | F39: 69.7
C40: 2028F | D40: 108.88 | E40: 109.36 | F40: 79.8
C41: 2029F | D41: 114.44 | E41: 114.68 | F41: 89.9
C42: 2030F | D42: 120 | E42: 120 | F42: 100
H44: >> 값복사
C45: Year | D45: 구축관리형 플랫폼 | E45: 구축형 플랫폼 | F45: 합계 | H45: Year | I45: 부업 강의 | J45: 투자 강의 | K45: 합계
C46: 2024A | H46: 2024A
...

Sheet DCF
A1: DCF
A3: 1. Consolidated
O4: =O6/L6 -> 6.8895993
L5: 2024A | M5: 2025 1H | N5: 2025 2H | O5: 2025E | P5: 2026F | Q5: 2027F | R5: 2028F | S5: 2029F | T5: 2030F
B6: Revenue | L6: ='Pro forma PL'!L6 -> 11223.359 | M6: ='Pro forma PL'!M6 -> 33392.893 | N6: ='Pro forma PL'!N6 -> 43931.553 | O6: ='Pro forma PL'!O6 -> 77324.447 | P6: ='Pro forma PL'!P6 -> 93269.577 | Q6: ='Pro forma PL'!Q6 -> 103535.16 | R6: ='Pro forma PL'!R6 -> 114632.35 | S6: ='Pro forma PL'!S6 -> 126061.71 | T6: ='Pro forma PL'!T6 -> 138122.31
B7: Operating Expense | L7: ='Pro forma PL'!L7 -> 7882.2028 | M7: ='Pro forma PL'!M7 -> 19480.857 | N7: ='Pro forma PL'!N7 -> 30151.488 | O7: ='Pro forma PL'!O7 -> 49632.346 | P7: ='Pro forma PL'!P7 -> 57986.595 | Q7: ='Pro forma PL'!Q7 -> 60124.892 | R7: ='Pro forma PL'!R7 -> 65467.261 | S7: ='Pro forma PL'!S7 -> 70872.351 | T7: ='Pro forma PL'!T7 -> 76518.723
B8: EBIT | L8: =L6-L7 -> 3341.1562 | M8: =M6-M7 -> 13912.036 | N8: =N6-N7 -> 13780.065 | O8: =O6-O7 -> 27692.101 | P8: =P6-P7 -> 35282.982 | Q8: =Q6-Q7 -> 43410.268 | R8: =R6-R7 -> 49165.087 | S8: =S6-S7 -> 55189.358 | T8: =T6-T7 -> 61603.584
B9: margin % | L9: =L8/L$6 -> 0.29769663 | M9: =M8/M$6 -> 0.41661666 | N9: =N8/N$6 -> 0.31367125 | O9: =O8/O$6 -> 0.35812867 | P9: =P8/P$6 -> 0.37829036 | Q9: =Q8/Q$6 -> 0.41928044 | R9: =R8/R$6 -> 0.42889366 | S9: =S8/S$6 -> 0.43779636 | T9: =T8/T$6 -> 0.44600749
B10: Income Tax | N10: =SUM(N48,N93,N128,N161) -> 3485.8775 | P10: =SUM(P48,P93,P128,P161) -> 9311.7412 | Q10: =SUM(Q48,Q93,Q128,Q161) -> 11456.751 | R10: =SUM(R48,R93,R128,R161) -> 12975.312 | S10: =SUM(S48,S93,S128,S161) -> 14564.865 | T10: =SUM(T48,T93,T128,T161) -> 16259.129
B11: EBIT after Tax | N11: =N8-N10 -> 10294.188 | P11: =P8-P10 -> 25971.241 | Q11: =Q8-Q10 -> 31953.516 | R11: =R8-R10 -> 36189.775 | S11: =S8-S10 -> 40624.493 | T11: =T8-T10 -> 45344.454
B12: (+) D&A | N12: ='Pro forma PL'!N21 -> 81.972752 | P12: ='Pro forma PL'!P21 -> 143.8773 | Q12: ='Pro forma PL'!Q21 -> 129.85259 | R12: ='Pro forma PL'!R21 -> 117.28632 | S12: ='Pro forma PL'!S21 -> 106.45002 | T12: ='Pro forma PL'!T21 -> 95.874855
B13: (-) CAPEX | N13: =SUM(N51,N96,N131,N164) -> -74.922948 | P13: =SUM(P51,P96,P131,P164) -> -122.01725 | Q13: =SUM(Q51,Q96,Q131,Q164) -> -112.45919 | R13: =SUM(R51,R96,R131,R164) -> -104.52159 | S13: =SUM(S51,S96,S131,S164) -> -98.582786 | T13: =SUM(T51,T96,T131,T164) -> -86.635555
B14: (+/-) NWC | N14: =SUM(N52,N97,N132,N165) -> 1487.6571 | P14: =SUM(P52,P97,P132,P165) -> -1004.2223 | Q14: =SUM(Q52,Q97,Q132,Q165) -> -620.98453 | R14: =SUM(R52,R97,R132,R165) -> -760.89675 | S14: =SUM(S52,S97,S132,S165) -> -782.99139 | T14: =SUM(T52,T97,T132,T165) -> -825.58487
B15: FCFF | N15: =SUM(N11:N14) -> 11788.895 | P15: =SUM(P11:P14) -> 24988.878 | Q15: =SUM(Q11:Q14) -> 31349.925 | R15: =SUM(R11:R14) -> 35441.643 | S15: =SUM(S11:S14) -> 39849.369 | T15: =SUM(T11:T14) -> 44528.109
B16: 할인기간 | N16: =N54 -> 0.25205479 | P16: =P54 -> 1 | Q16: =Q54 -> 2 | R16: =R54 -> 3 | S16: =S54 -> 4 | T16: =T54 -> 5
B17: 할인계수 | N17: =1/(1+$J$24)^N16 -> 0.9653856 | P17: =1/(1+$J$24)^P16 -> 0.86956522 | Q17: =1/(1+$J$24)^Q16 -> 0.75614367 | R17: =1/(1+$J$24)^R16 -> 0.65751623 | S17: =1/(1+$J$24)^S16 -> 0.57175325 | T17: =1/(1+$J$24)^T16 -> 0.49717674
B18: PV of FCFF | N18: =N17*N15 -> 11380.829 | P18: =P17*P15 -> 21729.46 | Q18: =Q17*Q15 -> 23705.047 | R18: =R17*R15 -> 23303.456 | S18: =S17*S15 -> 22784.006 | T18: =T17*T15 -> 22138.34
B19: 대상기간 누적 현재가치 | N19: =SUM(N18:T18) -> 125041.14
B20: Terminal Value의 현재가치 | N20: =SUM(N58,N103,N138,N171) -> 162240.69
B21: 영업가치 | N21: =SUM(N19:N20) -> 287281.83
B23: 영구성장률 | J23: 0.01
B24: WACC | J24: 0.15
B27: 영업가치 | J27: =N21 -> 287281.83
B28: 비영업용자산 | J28: =SUM(J29:J31) -> 7516.3069
C29: 현금및현금성자산등 | J29: =SUM(J67,J68,J69,J112,J147,J180) -> 6556.3069
C30: 투자부동산 | J30: =J113 -> 650
C31: 투자주식 | J31: =J114+J74 -> 310
B32: 기업가치 | J32: =J28+J27 -> 294798.14
B33: 비지배지분 | J33: =SUM(J34:J36) -> 9435.2177
C34: 클래스어라운드 | J34: =J118*(1-I81) -> 0
C35: 시스템노바 | J35: =J151*(1-I82) -> 9435.2177
C36: 티티에이컴퍼니 | J36: =J184*(1-I83) -> 0
B37: IBD | J37: =SUM(J77,J117,J150,J183) -> 692.297
B38: 지분가치 | J38: =J32-J33-J37 -> 284670.62 | K38: =ROUND(J38,)=ROUND(J78,) -> TRUE
A41: 2. TITAN
L43: 2024A | M43: 2025 1H | N43: 2025 2H | O43: 2025E | P43: 2026F | Q43: 2027F | R43: 2028F | S43: 2029F | T43: 2030F | U43: Terminal
B44: Revenue | L44: =TITAN!L6 -> 11203.459 | M44: =TITAN!M6 -> 17504.878 | N44: =TITAN!N6 -> 17577.197 | O44: =TITAN!O6 -> 35082.076 | P44: =TITAN!P6 -> 37812.47 | Q44: =TITAN!Q6 -> 40682.35 | R44: =TITAN!R6 -> 43771.909 | S44: =TITAN!S6 -> 46881.275 | T44: =TITAN!T6 -> 50120.726 | U44: =T44*(1+$J$61) -> 50621.934
B45: Operating Expense | L45: =TITAN!L7 -> 7805.3692 | M45: =TITAN!M7 -> 10871.796 | N45: =TITAN!N7 -> 12636.466 | O45: =TITAN!O7 -> 23508.262 | P45: =TITAN!P7 -> 25900.887 | Q45: =TITAN!Q7 -> 26116.725 | R45: =TITAN!R7 -> 27996.971 | S45: =TITAN!S7 -> 29882.534 | T45: =TITAN!T7 -> 31848.718 | U45: =T45*(1+$J$61) -> 32167.205
B46: EBIT | L46: =L44-L45 -> 3398.0897 | M46: =M44-M45 -> 6633.0824 | N46: =N44-N45 -> 4940.7319 | O46: =O44-O45 -> 11573.814 | P46: =P44-P45 -> 11911.583 | Q46: =Q44-Q45 -> 14565.625 | R46: =R44-R45 -> 15774.938 | S46: =S44-S45 -> 16998.741 | ... U46: =U44-U45 -> 18454.728
B47: margin % | L47: =L46/L44 -> 0.3033072 | M47: =M46/M44 -> 0.37892765 | N47: =N46/N44 -> 0.28108758 | O47: =O46/O44 -> 0.32990677 | P47: =P46/P44 -> 0.31501732 | Q47: =Q46/Q44 -> 0.35803303 | R47: =R46/R44 -> 0.36038954 | S47: =S46/S44 -> 0.36259127 | ... U47: =U46/U44 -> 0.36455992
...

Sheet Pro forma BS
A1: Pro forma BS
A3: 1. Consolidated
L5: 2024A | M5: 2025 1H | N5: 2025 2H | O5: 2025E | P5: 2026F | Q5: 2027F | R5: 2028F | S5: 2029F | T5: 2030F
B6: 유동자산 | L6: =연결정산표!G5/10^6 -> 3393.8404 | M6: =연결정산표_우모건제외!M7/10^6 -> 16785.728 | N6: =SUM(N7:N11) -> 31203.336 | O6: =SUM(O7:O11) -> 31203.336 | P6: =SUM(P7:P11) -> 60135.704 | Q6: =SUM(Q7:Q11) -> 94831.636 | R6: =SUM(R7:R11) -> 133268.42 | S6: =SUM(S7:S11) -> 176251.04 | T6: =SUM(T7:T11) -> 224112.67
C7: 현금및현금성자산 | L7: =SUM(연결정산표!G7:G9)/10^6 -> 1161.7762 | M7: =SUM(연결정산표_우모건제외!M9:M11)/10^6 -> 5089.6527 | N7: ='Pro forma CF'!N25 -> 20525.78 | O7: ='Pro forma CF'!O25 -> 20525.78 | P7: ='Pro forma CF'!P25 -> 48056.268 | Q7: ='Pro forma CF'!Q25 -> 81999.842 | R7: ='Pro forma CF'!R25 -> 119449.09 | S7: ='Pro forma CF'!S25 -> 161417.02 | T7: ='Pro forma CF'!T25 -> 208210.25
C8: 단기대여금 | L8: =연결정산표!G17/10^6 -> 0 | M8: =연결정산표_우모건제외!M19/10^6 -> 1200 | N8: =M8 -> 1200 | O8: =N8 -> 1200 | P8: =O8 -> 1200 | Q8: =P8 -> 1200 | R8: =Q8 -> 1200 | S8: =R8 -> 1200 | T8: =S8 -> 1200
C9: 운전자산 | L9: =SUM(연결정산표!G11,연결정산표!G13)/10^6 -> 1641.1379 | M9: =연결정산표_우모건제외!M13/10^6+연결정산표_우모건제외!M15/10^6-연결정산표_우모건제외!G15/10^6 -> 8174.6202 | N9: =SUM(TITAN!N148,CLASS!N155,NOVA!N109,TTA!N117) -> 7156.1012 | O9: =SUM(TITAN!O148,CLASS!O155,NOVA!O109,TTA!O117) -> 7156.1012 | P9: =SUM(TITAN!P148,CLASS!P155,NOVA!P109,TTA!P117) -> 8557.9806 | Q9: =SUM(TITAN!Q148,CLASS!Q155,NOVA!Q109,TTA!Q117) -> 9310.3382 | R9: =SUM(TITAN!R148,CLASS!R155,NOVA!R109,TTA!R117) -> 10297.883 | S9: =SUM(TITAN!S148,CLASS!S155,NOVA!S109,TTA!S117) -> 11312.562 | T9: =SUM(TITAN!T148,CLASS!T155,NOVA!T109,TTA!T117) -> 12380.965
C10: 주임종단기채권 | L10: =연결정산표!J18/10^6 -> 369.18887 | M10: =연결정산표_우모건제외!M20/10^6 -> 1991.9156 | N10: =M10 -> 1991.9156 | O10: =N10 -> 1991.9156 | P10: =O10 -> 1991.9156 | Q10: =P10 -> 1991.9156 | R10: =Q10 -> 1991.9156 | S10: =R10 -> 1991.9156 | T10: =S10 -> 1991.9156
C11: 기타유동자산 | L11: =L6-L7-L8-L9-L10 -> 221.73735 | M11: =M6-M7-M8-M9-M10 -> 329.53993 | N11: =M11 -> 329.53993 | O11: =N11 -> 329.53993 | P11: =O11 -> 329.53993 | Q11: =P11 -> 329.53993 | R11: =Q11 -> 329.53993 | S11: =R11 -> 329.53993 | T11: =S11 -> 329.53993
B12: 비유동자산 | L12: =연결정산표!J21/10^6 -> 1137.2261 | M12: =연결정산표_우모건제외!M23/10^6 -> 1856.4592 | N12: =SUM(N13:N15) -> 1849.4094 | O12: =SUM(O13:O15) -> 1849.4094 | P12: =SUM(P13:P15) -> 1827.5494 | Q12: =SUM(Q13:Q15) -> 1810.156 | R12: =SUM(R13:R15) -> 1797.3912 | S12: =SUM(S13:S15) -> 1789.524 | T12: =SUM(T13:T15) -> 1780.2847
C13: 투자주식 | L13: 0 | M13: =연결정산표_우모건제외!M24/10^6 -> 310 | N13: =M13 -> 310 | O13: =N13 -> 310 | P13: =O13 -> 310 | Q13: =P13 -> 310 | R13: =Q13 -> 310 | S13: =R13 -> 310 | T13: =S13 -> 310
C14: 유무형자산 | L14: =연결정산표!J31/10^6 -> 987.43582 | M14: =연결정산표_우모건제외!M33/10^6 -> 1080.9109 | N14: =M14-'Pro forma PL'!N21-DCF!N13 -> 1073.8611 | O14: =N14 -> 1073.8611 | P14: =O14-'Pro forma PL'!P21-DCF!P13 -> 1052.001 | Q14: =P14-'Pro forma PL'!Q21-DCF!Q13 -> 1034.6076 | R14: =Q14-'Pro forma PL'!R21-DCF!R13 -> 1021.8429 | S14: =R14-'Pro forma PL'!S21-DCF!S13 -> 1013.9757 | T14: =S14-'Pro forma PL'!T21-DCF!T13 -> 1004.7364
C15: 기타비유동자산 | L15: =L12-L13-L14 -> 149.79032 | M15: =M12-M13-M14 -> 465.54832 | N15: =M15 -> 465.54832 | O15: =N15 -> 465.54832 | P15: =O15 -> 465.54832 | Q15: =P15 -> 465.54832 | R15: =Q15 -> 465.54832 | S15: =R15 -> 465.54832 | T15: =S15 -> 465.54832
B16: 자산총계 | L16: =L12+L6 -> 4531.0665 | M16: =M12+M6 -> 18642.188 | N16: =N12+N6 -> 33052.746 | O16: =O12+O6 -> 33052.746 | P16: =P12+P6 -> 61963.253 | Q16: =Q12+Q6 -> 96641.792 | R16: =R12+R6 -> 135065.82 | S16: =S12+S6 -> 178040.56 | T16: =T12+T6 -> 225892.96
B17: 유동부채 | L17: =연결정산표!J52/10^6 -> 1203.7292 | M17: =연결정산표_우모건제외!M54/10^6 -> 1631.8687 | N17: =SUM(N18:N21) -> 9281.87 | O17: =SUM(O18:O21) -> 9281.87 | P17: =SUM(P18:P21) -> 11810.405 | Q17: =SUM(Q18:Q21) -> 14086.788 | R17: =SUM(R18:R21) -> 15831.997 | S17: =SUM(S18:S21) -> 17653.238 | T17: =SUM(T18:T21) -> 19590.32
C18: 단기차입금 | L18: =연결정산표!J62/10^6 -> 100 | M18: =연결정산표_우모건제외!M64/10^6 -> 100 | N18: =M18 -> 100 | O18: =N18 -> 100 | P18: =O18 -> 100 | Q18: =P18 -> 100 | R18: =Q18 -> 100 | S18: =R18 -> 100 | T18: =S18 -> 100
C19: 운전부채 | L19: =연결정산표!J53/10^6 -> 437.91273 | M19: =연결정산표_우모건제외!M55/10^6 -> 1040.6891 | N19: =SUM(TITAN!N155,CLASS!N162,NOVA!N113,TTA!N124) -> 1509.8272 | O19: =SUM(TITAN!O155,CLASS!O162,NOVA!O113,TTA!O124) -> 1509.8272 | P19: =SUM(TITAN!P155,CLASS!P162,NOVA!P113,TTA!P124) -> 1907.4843 | Q19: =SUM(TITAN!Q155,CLASS!Q162,NOVA!Q113,TTA!Q124) -> 2038.8573 | R19: =SUM(TITAN!R155,CLASS!R162,NOVA!R113,TTA!R124) -> 2265.5051 | S19: =SUM(TITAN!S155,CLASS!S162,NOVA!S113,TTA!S124) -> 2497.1929 | T19: =SUM(TITAN!T155,CLASS!T162,NOVA!T113,TTA!T124) -> 2740.0109
C20: 미지급법인세 | L20: =연결정산표!G60/10^6 -> 596.78793 | M20: =연결정산표_우모건제외!M62/10^6 -> 336.46338 | N20: =M20+'Pro forma PL'!N18+'Pro forma CF'!N15 -> 7517.3267 | O20: =N20 -> 7517.3267 | P20: =O20+'Pro forma PL'!P18+'Pro forma CF'!P15 -> 9648.2045 | Q20: =P20+'Pro forma PL'!Q18+'Pro forma CF'!Q15 -> 11793.215 | R20: =Q20+'Pro forma PL'!R18+'Pro forma CF'!R15 -> 13311.775 | S20: =R20+'Pro forma PL'!S18+'Pro forma CF'!S15 -> 14901.329 | T20: =S20+'Pro forma PL'!T18+'Pro forma CF'!T15 -> 16595.593
C21: 기타유동부채 | L21: =L17-L18-L19-L20 -> 69.028535 | M21: =M17-M18-M19-M20 -> 154.71614 | N21: =M21 -> 154.71614 | O21: =N21 -> 154.71614 | P21: =O21 -> 154.71614 | Q21: =P21 -> 154.71614 | R21: =Q21 -> 154.71614 | S21: =R21 -> 154.71614 | T21: =S21 -> 154.71614
B22: 비유동부채 | L22: =연결정산표!J63/10^6 -> 575.19028 | M22: =연결정산표_우모건제외!M65/10^6 -> 611.75831 | N22: =N23+N24 -> 773.11313 | O22: =O23+O24 -> 773.11313 | P22: =P23+P24 -> 1183.8449 | Q22: =Q23+Q24 -> 1632.4845 | R22: =R23+R24 -> 2121.524 | S22: =S23+S24 -> 2650.5397 | T22: =T23+T24 -> 3221.396
C23: 장기차입금 | L23: =연결정산표!J66/10^6 -> 542 | M23: =연결정산표_우모건제외!M68/10^6 -> 542 | N23: =M23 -> 542 | O23: =N23 -> 542 | P23: =O23 -> 542 | Q23: =P23 -> 542 | R23: =Q23 -> 542 | S23: =R23 -> 542 | T23: =S23 -> 542
C24: 기타비유동부채 | L24: =L22-L23 -> 33.190278 | M24: =M22-M23 -> 69.75831 | N24: =M24+'Pro forma CF'!N11 -> 231.11313 | O24: =N24 -> 231.11313 | P24: =O24+'Pro forma CF'!P11 -> 641.84495 | Q24: =P24+'Pro forma CF'!Q11 -> 1090.4845 | R24: =Q24+'Pro forma CF'!R11 -> 1579.524 | S24: =R24+'Pro forma CF'!S11 -> 2108.5397 | T24: =S24+'Pro forma CF'!T11 -> 2679.396
B25: 부채총계 | L25: =L22+L17 -> 1778.9195 | M25: =M22+M17 -> 2243.627 | N25: =N22+N17 -> 10054.983 | O25: =O22+O17 -> 10054.983 | P25: =P22+P17 -> 12994.25 | Q25: =Q22+Q17 -> 15719.273 | R25: =R22+R17 -> 17953.521 | S25: =S22+S17 -> 20303.777 | T25: =T22+T17 -> 22811.716
B26: 자본총계 | L26: =L16-L25 -> 2752.1471 | M26: =M16-M25 -> 16398.561 | N26: =N16-N25 -> 22997.762 | O26: =O16-O25 -> 22997.762 | P26: =P16-P25 -> 48969.003 | Q26: =Q16-Q25 -> 80922.519 | R26: =R16-R25 -> 117112.29 | S26: =S16-S25 -> 157736.79 | T26: =T16-T25 -> 203081.24
L27: =연결정산표!J89/10^6=L26 -> TRUE | M27: ='Pro forma CE'!M11=M26 -> TRUE | N27: =ROUND('Pro forma CE'!N11,)=ROUND(N26,) -> TRUE | O27: =ROUND('Pro forma CE'!O11,)=ROUND(O26,) -> TRUE | P27: =ROUND('Pro forma CE'!P11,)=ROUND(P26,) -> TRUE | Q27: =ROUND('Pro forma CE'!Q11,)=ROUND(Q26,) -> TRUE | R27: =ROUND('Pro forma CE'!R11,)=ROUND(R26,) -> TRUE | S27: =ROUND('Pro forma CE'!S11,)=ROUND(S26,) -> TRUE | T27: =ROUND('Pro forma CE'!T11,)=ROUND(T26,) -> TRUE
A29: 2. Normalization 기준 BS
L31: 2024A | M31: 2025 1H | N31: 2025 2H | O31: 2025E | P31: 2026F | Q31: 2027F | R31: 2028F | S31: 2029F | T31: 2030F
B32: 유동자산 | L32: =SUM(L33:L37) -> 3393.8404 | M32: =SUM(M33:M37) -> 15473.031 | N32: =SUM(N33:N37) -> 23214.434 | O32: =SUM(O33:O37) -> 23214.434 | P32: =SUM(P33:P37) -> 42605.176 | Q32: =SUM(Q33:Q37) -> 59586.579 | R32: =SUM(R33:R37) -> 77108.596 | S32: =SUM(S33:S37) -> 95870.9 | T32: =SUM(T33:T37) -> 115971.17
C33: 현금및현금성자산 | L33: =L7 -> 1161.7762 | M33: ='Pro forma CF'!M50 -> 3776.9549 | N33: ='Pro forma CF'!N50 -> 12536.878 | O33: ='Pro forma CF'!O50 -> 12536.878 | P33: ='Pro forma CF'!P50 -> 30525.74 | Q33: ='Pro forma CF'!Q50 -> 46754.786 | R33: ='Pro forma CF'!R50 -> 63289.258 | S33: ='Pro forma CF'!S50 -> 81036.882 | T33: ='Pro forma CF'!T50 -> 100068.75
C34: 단기대여금 | L34: =L8 -> 0 | M34: =M8 -> 1200 | N34: =M34 -> 1200 | O34: =N34 -> 1200 | P34: =O34 -> 1200 | Q34: =P34 -> 1200 | R34: =Q34 -> 1200 | S34: =R34 -> 1200 | T34: =S34 -> 1200
C35: 운전자산 | L35: =L9 -> 1641.1379 | M35: =M9 -> 8174.6202 | N35: =N9 -> 7156.1012 | O35: =O9 -> 7156.1012 | P35: =P9 -> 8557.9806 | Q35: =Q9 -> 9310.3382 | R35: =R9 -> 10297.883 | S35: =S9 -> 11312.562 | T35: =T9 -> 12380.965
C36: 주임종단기채권 | L36: =L10 -> 369.18887 | M36: =M10 -> 1991.9156 | N36: =M36 -> 1991.9156 | O36: =N36 -> 1991.9156 | P36: =O36 -> 1991.9156 | Q36: =P36 -> 1991.9156 | R36: =Q36 -> 1991.9156 | S36: =R36 -> 1991.9156 | T36: =S36 -> 1991.9156
C37: 기타유동자산 | L37: =L11 -> 221.73735 | M37: =M11 -> 329.53993 | N37: =M37 -> 329.53993 | O37: =N37 -> 329.53993 | P37: =O37 -> 329.53993 | Q37: =P37 -> 329.53993 | R37: =Q37 -> 329.53993 | S37: =R37 -> 329.53993 | T37: =S37 -> 329.53993
B38: 비유동자산 | L38: =SUM(L39:L41) -> 1137.2261 | M38: =SUM(M39:M41) -> 1856.4592 | N38: =SUM(N39:N41) -> 1849.4094 | O38: =SUM(O39:O41) -> 1849.4094 | P38: =SUM(P39:P41) -> 1827.5494 | Q38: =SUM(Q39:Q41) -> 1810.156 | R38: =SUM(R39:R41) -> 1797.3912 | S38: =SUM(S39:S41) -> 1789.524 | T38: =SUM(T39:T41) -> 1780.2847
C39: 투자주식 | L39: =L13 -> 0 | M39: =M13 -> 310 | N39: =M39 -> 310 | O39: =N39 -> 310 | P39: =O39 -> 310 | Q39: =P39 -> 310 | R39: =Q39 -> 310 | S39: =R39 -> 310 | T39: =S39 -> 310
C40: 유무형자산 | L40: =L14 -> 987.43582 | M40: =M14 -> 1080.9109 | N40: =N14 -> 1073.8611 | O40: =O14 -> 1073.8611 | P40: =P14 -> 1052.001 | Q40: =Q14 -> 1034.6076 | R40: =R14 -> 1021.8429 | S40: =S14 -> 1013.9757 | T40: =T14 -> 1004.7364
C41: 기타비유동자산 | L41: =L15 -> 149.79032 | M41: =M15 -> 465.54832 | N41: =M41 -> 465.54832 | O41: =N41 -> 465.54832 | P41: =O41 -> 465.54832 | Q41: =P41 -> 465.54832 | R41: =Q41 -> 465.54832 | S41: =R41 -> 465.54832 | T41: =S41 -> 465.54832
B42: 자산총계 | L42: =L38+L32 -> 4531.0665 | M42: =M38+M32 -> 17329.49 | N42: =N38+N32 -> 25063.844 | O42: =O38+O32 -> 25063.844 | P42: =P38+P32 -> 44432.726 | Q42: =Q38+Q32 -> 61396.735 | R42: =R38+R32 -> 78905.987 | S42: =S38+S32 -> 97660.424 | T42: =T38+T32 -> 117751.46
B43: 유동부채 | L43: =L44+L45+L46+L47 -> 1203.7292 | M43: =M44+M45+M46+M47 -> 6466.7597 | N43: =SUM(N44:N47) -> 7266.716 | O43: =SUM(O44:O47) -> 7266.716 | P43: =SUM(P44:P47) -> 7841.884 | Q43: =SUM(Q44:Q47) -> 8226.6176 | R43: =SUM(R44:R47) -> 9012.9826 | S43: =SUM(S44:S47) -> 9811.4643 | T43: =SUM(T44:T47) -> 10643.901
C44: 단기차입금 | L44: =L18 -> 100 | M44: =M18 -> 100 | N44: =M44 -> 100 | O44: =N44 -> 100 | P44: =O44 -> 100 | Q44: =P44 -> 100 | R44: =Q44 -> 100 | S44: =R44 -> 100 | T44: =S44 -> 100
...

Sheet Pro forma CF
A1: Pro forma CF
A3: 1. Consolidated
L5: 2024A | M5: 2025 1H | N5: 2025 2H | O5: 2025E | P5: 2026F | Q5: 2027F | R5: 2028F | S5: 2029F | T5: 2030F
B6: 영업활동현금흐름 | M6: =SUM(M7:M15) -> 7596.7369 | N6: =SUM(N7:N15) -> 15511.05 | O6: =SUM(O7:O15) -> 23107.787 | P6: =SUM(P7:P15) -> 27652.505 | Q6: =SUM(Q7:Q15) -> 34056.034 | R6: =SUM(R7:R15) -> 37553.765 | S6: =SUM(S7:S15) -> 42066.52 | T6: =SUM(T7:T15) -> 46879.865
C7: 당기순이익 | M7: ='Pro forma PL'!M19 -> 13640.685 | N7: ='Pro forma PL'!N19 -> 6599.2018 | O7: =N7+M7 -> 20239.887 | P7: ='Pro forma PL'!P19 -> 25971.241 | Q7: ='Pro forma PL'!Q19 -> 31953.516 | R7: ='Pro forma PL'!R19 -> 36189.775 | S7: ='Pro forma PL'!S19 -> 40624.493 | T7: ='Pro forma PL'!T19 -> 45344.454
C8: 법인세비용 | M8: ='Pro forma PL'!M18 -> 0 | N8: ='Pro forma PL'!N18 -> 7180.8633 | O8: =N8+M8 -> 7180.8633 | P8: ='Pro forma PL'!P18 -> 9311.7412 | Q8: ='Pro forma PL'!Q18 -> 11456.751 | R8: ='Pro forma PL'!R18 -> 12975.312 | S8: ='Pro forma PL'!S18 -> 14564.865 | T8: ='Pro forma PL'!T18 -> 16259.129
C9: 단기매매증권평가이익 | M9: =연결정산표_우모건제외!AF102/10^6 -> -29.554816 | N9: 0 | O9: =N9+M9 -> -29.554816 | P9: 0 | Q9: 0 | R9: 0 | S9: 0 | T9: 0
C10: 무형자산처분이익 | M10: =연결정산표_우모건제외!AF103/10^6 -> -4.545455 | N10: 0 | O10: =N10+M10 -> -4.545455 | P10: 0 | Q10: 0 | R10: 0 | S10: 0 | T10: 0
C11: 퇴직급여 | M11: =연결정산표_우모건제외!AF98/10^6 -> 36.568032 | N11: =SUM(TITAN!N56,CLASS!N56,NOVA!N53,TTA!N47) -> 161.35482 | O11: =N11+M11 -> 197.92286 | P11: =SUM(TITAN!P56,CLASS!P56,NOVA!P53,TTA!P47) -> 410.73182 | Q11: =SUM(TITAN!Q56,CLASS!Q56,NOVA!Q53,TTA!Q47) -> 448.63958 | R11: =SUM(TITAN!R56,CLASS!R56,NOVA!R53,TTA!R47) -> 489.03945 | S11: =SUM(TITAN!S56,CLASS!S56,NOVA!S53,TTA!S47) -> 529.01573 | T11: =SUM(TITAN!T56,CLASS!T56,NOVA!T53,TTA!T47) -> 570.85625
C12: 감가상각비 | M12: ='Pro forma PL'!M21 -> 57.174702 | N12: ='Pro forma PL'!N21 -> 81.972752 | O12: =N12+M12 -> 139.14745 | P12: ='Pro forma PL'!P21 -> 143.8773 | Q12: ='Pro forma PL'!Q21 -> 129.85259 | R12: ='Pro forma PL'!R21 -> 117.28632 | S12: ='Pro forma PL'!S21 -> 106.45002 | T12: ='Pro forma PL'!T21 -> 95.874855
C13: 운전자본변동 | M13: =SUM(연결정산표_우모건제외!AF106,연결정산표_우모건제외!AF108,연결정산표_우모건제외!AF112)/10^6 -> -5930.7586 | N13: =DCF!N14 -> 1487.6571 | O13: =N13+M13 -> -4443.1015 | P13: =DCF!P14 -> -1004.2223 | Q13: =DCF!Q14 -> -620.98453 | R13: =DCF!R14 -> -760.89675 | S13: =DCF!S14 -> -782.99139 | T13: =DCF!T14 -> -825.58487
C14: 기타자산부채증감 | M14: =SUM(연결정산표_우모건제외!AF118:AF119,연결정산표_우모건제외!AF114:AF116,연결정산표_우모건제외!AF113,연결정산표_우모건제외!AF109:AF111,연결정산표_우모건제외!AF107)/10^6 -> 87.492542 | N14: 0 | O14: =N14+M14 -> 87.492542 | P14: 0 | Q14: 0 | R14: 0 | S14: 0 | T14: 0
C15: 법인세납부 | M15: =연결정산표_우모건제외!AF117/10^6 -> -260.32455 | N15: 0 | O15: =N15+M15 -> -260.32455 | P15: =-O8 -> -7180.8633 | Q15: =-P8 -> -9311.7412 | R15: =-Q8 -> -11456.751 | S15: =-R8 -> -12975.312 | T15: =-S8 -> -14564.865
B16: 투자활동현금흐름 | M16: =연결정산표_우모건제외!AG120/10^6 -> -3640.289 | N16: =N17+N18+N19 -> -74.922948 | O16: =O17+O18+O19 -> -3715.212 | P16: =P17+P18+P19 -> -122.01725 | Q16: =Q17+Q18+Q19 -> -112.45919 | R16: =R17+R18+R19 -> -104.52159 | S16: =S17+S18+S19 -> -98.582786 | T16: =T17+T18+T19 -> -86.635555
C17: 유무형자산취득처분 | M17: =(연결정산표_우모건제외!AF124+연결정산표_우모건제외!AF130+연결정산표_우모건제외!AF131+연결정산표_우모건제외!AF132+연결정산표_우모건제외!AF135)/10^6 -> -146.10431 | N17: =DCF!N13 -> -74.922948 | O17: =N17+M17 -> -221.02726 | P17: =DCF!P13 -> -122.01725 | Q17: =DCF!Q13 -> -112.45919 | R17: =DCF!R13 -> -104.52159 | S17: =DCF!S13 -> -98.582786 | T17: =DCF!T13 -> -86.635555
C18: 대여금증감 | M18: =연결정산표_우모건제외!AF122/10^6+연결정산표_우모건제외!AF128/10^6 -> -2822.7267 | N18: 0 | O18: =N18+M18 -> -2822.7267 | P18: 0 | Q18: 0 | R18: 0 | S18: 0 | T18: 0
C19: 기타 | M19: =M16-M17-M18 -> -671.458 | N19: 0 | O19: =N19+M19 -> -671.458 | P19: 0 | Q19: 0 | R19: 0 | S19: 0 | T19: 0
B20: 재무활동현금흐름 | M20: =M21+M22 -> -28.571429 | N20: =N21+N22 -> 0 | O20: =O21+O22 -> -28.571429 | P20: =P21+P22 -> 0 | Q20: =Q21+Q22 -> 0 | R20: =R21+R22 -> 0 | S20: =S21+S22 -> 0 | T20: =T21+T22 -> 0
C21: 차입금변동 | M21: 0 | N21: 0 | O21: =N21+M21 -> 0 | P21: 0 | Q21: 0 | R21: 0 | S21: 0 | T21: 0
C22: 배당금지급 | M22: =연결정산표_우모건제외!AF142/10^6 -> -28.571429 | N22: 0 | O22: =N22+M22 -> -28.571429 | P22: 0 | Q22: 0 | R22: 0 | S22: 0 | T22: 0
B23: 현금증감 | M23: =M20+M16+M6 -> 3927.8765 | N23: =N20+N16+N6 -> 15436.127 | O23: =N23+M23 -> 19364.003 | P23: =P20+P16+P6 -> 27530.488 | Q23: =Q20+Q16+Q6 -> 33943.575 | R23: =R20+R16+R6 -> 37449.243 | S23: =S20+S16+S6 -> 41967.938 | T23: =T20+T16+T6 -> 46793.229
B24: 기초현금 | M24: ='Pro forma BS'!L7 -> 1161.7762 | N24: =M25 -> 5089.6527 | O24: =M24 -> 1161.7762 | P24: =O25 -> 20525.78 | Q24: =P25 -> 48056.268 | R24: =Q25 -> 81999.842 | S24: =R25 -> 119449.09 | T24: =S25 -> 161417.02
B25: 기말현금 | M25: =M24+M23 -> 5089.6527 | N25: =N24+N23 -> 20525.78 | O25: =O24+O23 -> 20525.78 | P25: =P24+P23 -> 48056.268 | Q25: =Q24+Q23 -> 81999.842 | R25: =R24+R23 -> 119449.09 | S25: =S24+S23 -> 161417.02 | T25: =T24+T23 -> 208210.25
A28: 2. Nomalization 기준
L30: 2024A | M30: 2025 1H | N30: 2025 2H | O30: 2025E | P30: 2026F | Q30: 2027F | R30: 2028F | S30: 2029F | T30: 2030F
B31: 영업활동현금흐름 | M31: =SUM(M32:M40) -> 6284.0391 | N31: =SUM(N32:N40) -> 8759.9227 | O31: =SUM(O32:O40) -> 15043.962 | P31: =SUM(P32:P40) -> 17988.863 | Q31: =SUM(Q32:Q40) -> 16229.045 | R31: =SUM(R32:R40) -> 16534.472 | S31: =SUM(S32:S40) -> 17747.624 | T31: =SUM(T32:T40) -> 19031.872
C32: 당기순이익 | M32: =M7-'Pro forma BS'!M65 -> 8805.794 | N32: ='Pro forma PL'!N44 -> 0.11086279 | O32: =N32+M32 -> 8805.9049 | P32: ='Pro forma PL'!P44 -> 0.23185275 | Q32: ='Pro forma PL'!Q44 -> 0.26351231 | R32: ='Pro forma PL'!R44 -> 0.2652467 | S32: ='Pro forma PL'!S44 -> 0.26686718 | T32: ='Pro forma PL'!T44 -> 0.2683161
C33: 법인세비용 | M33: =M8 -> 0 | N33: ='Pro forma PL'!N43 -> 1948.6572 | O33: =N33+M33 -> 1948.6572 | P33: ='Pro forma PL'!P43 -> 8766.9251 | Q33: ='Pro forma PL'!Q43 -> 10720.3 | R33: ='Pro forma PL'!R43 -> 11610.354 | S33: ='Pro forma PL'!S43 -> 12511.073 | T33: ='Pro forma PL'!T43 -> 13448.198
C34: 단기매매증권평가이익 | M34: =M9 -> -29.554816 | N34: 0 | O34: =N34+M34 -> -29.554816 | P34: 0 | Q34: 0 | R34: 0 | S34: 0 | T34: 0
C35: 무형자산처분이익 | M35: =M10 -> -4.545455 | N35: 0 | O35: =N35+M35 -> -4.545455 | P35: 0 | Q35: 0 | R35: 0 | S35: 0 | T35: 0
C36: 퇴직급여 | M36: =M11 -> 36.568032 | N36: =SUM(TITAN!N81,CLASS!N81,NOVA!N78,TTA!N72) -> 1.4319605 | O36: =N36+M36 -> 37.999992 | P36: =SUM(TITAN!P81,CLASS!P81,NOVA!P78,TTA!P72) -> 0.75 | Q36: =SUM(TITAN!Q81,CLASS!Q81,NOVA!Q78,TTA!Q72) -> 0.5 | R36: =SUM(TITAN!R81,CLASS!R81,NOVA!R78,TTA!R72) -> 0.5 | S36: =SUM(TITAN!S81,CLASS!S81,NOVA!S78,TTA!S72) -> 0.5 | T36: =SUM(TITAN!T81,CLASS!T81,NOVA!T78,TTA!T72) -> 0.5
C37: 감가상각비 | M37: =M12 -> 57.174702 | N37: ='Pro forma PL'!N46 -> 4991.3582 | O37: =N37+M37 -> 5048.5329 | P37: ='Pro forma PL'!P46 -> 11996.556 | Q37: ='Pro forma PL'!Q46 -> 14642.794 | R37: ='Pro forma PL'!R46 -> 15845.097 | S37: ='Pro forma PL'!S46 -> 17062.603 | T37: ='Pro forma PL'!T46 -> 18330.213
C38: 운전자본변동 | M38: =M13+'Pro forma BS'!M65-'Pro forma BS'!L65 -> -2408.5653 | N38: =N13+'Pro forma BS'!N65-'Pro forma BS'!M65 -> 1818.3644 | O38: =N38+M38 -> -590.20091 | P38: =P13+'Pro forma BS'!P65-'Pro forma BS'!O65 -> -826.94325 | Q38: =Q13+'Pro forma BS'!Q65-'Pro forma BS'!P65 -> -367.88749 | R38: =R13+'Pro forma BS'!R65-'Pro forma BS'!Q65 -> -201.44474 | S38: =S13+'Pro forma BS'!S65-'Pro forma BS'!R65 -> -216.46442 | T38: =T13+'Pro forma BS'!T65-'Pro forma BS'!S65 -> -236.23396
C39: 기타자산부채증감 | M39: =M14 -> 87.492542 | N39: 0 | O39: =N39+M39 -> 87.492542 | P39: 0 | Q39: 0 | R39: 0 | S39: 0 | T39: 0
C40: 법인세납부 | M40: =M15 -> -260.32455 | N40: 0 | O40: =N40+M40 -> -260.32455 | P40: =-O33 -> -1948.6572 | Q40: =-P33 -> -8766.9251 | R40: =-Q33 -> -10720.3 | S40: =-R33 -> -11610.354 | T40: =-S33 -> -12511.073
B41: 투자활동현금흐름 | M41: =M16 -> -3640.289 | N41: =N42+N43+N44 -> 0 | O41: =O42+O43+O44 -> -3640.289 | P41: =P42+P43+P44 -> 0 | Q41: =Q42+Q43+Q44 -> 0 | R41: =R42+R43+R44 -> 0 | S41: =S42+S43+S44 -> 0 | T41: =T42+T43+T44 -> 0
C42: 유무형자산취득처분 | M42: =M17 -> -146.10431 | N42: =DCF!N38 -> 0 | O42: =N42+M42 -> -146.10431 | P42: =DCF!P38 -> 0 | Q42: =DCF!Q38 -> 0 | R42: =DCF!R38 -> 0 | S42: =DCF!S38 -> 0 | T42: =DCF!T38 -> 0
C43: 대여금증감 | M43: =M18 -> -2822.7267 | N43: 0 | O43: =N43+M43 -> -2822.7267 | P43: 0 | Q43: 0 | R43: 0 | S43: 0 | T43: 0
C44: 기타 | M44: =M19 -> -671.458 | N44: 0 | O44: =N44+M44 -> -671.458 | P44: 0 | Q44: 0 | R44: 0 | S44: 0 | T44: 0
B45: 재무활동현금흐름 | M45: =M20 -> -28.571429 | N45: =N46+N47 -> 0 | O45: =O46+O47 -> -28.571429 | P45: =P46+P47 -> 0 | Q45: =Q46+Q47 -> 0 | R45: =R46+R47 -> 0 | S45: =S46+S47 -> 0 | T45: =T46+T47 -> 0
...

Sheet Pro forma CE
A1: Pro forma CE
A3: 1. Consolidated
L5: 2024A | M5: 2025 1H | N5: 2025 2H | O5: 2025E | P5: 2026F | Q5: 2027F | R5: 2028F | S5: 2029F | T5: 2030F
B6: 기초 | L6: =L11-L7 -> 376.32503 | M6: =L11 -> 2752.1471 | N6: =M11 -> 16398.561 | O6: =L11 -> 2752.1471 | P6: =O11 -> 22997.762 | Q6: =P11 -> 48969.003 | R6: =Q11 -> 80922.519 | S6: =R11 -> 117112.29 | T6: =S11 -> 157736.79
C7: 당기순이익 | L7: ='Pro forma PL'!L19 -> 2375.822 | M7: ='Pro forma PL'!M19 -> 13640.685 | N7: ='Pro forma PL'!N19 -> 6599.2018 | O7: ='Pro forma PL'!O19 -> 20239.887 | P7: ='Pro forma PL'!P19 -> 25971.241 | Q7: ='Pro forma PL'!Q19 -> 31953.516 | R7: ='Pro forma PL'!R19 -> 36189.775 | S7: ='Pro forma PL'!S19 -> 40624.493 | T7: ='Pro forma PL'!T19 -> 45344.454
C8: 배당 | M8: =연결정산표_우모건제외!J87/10^6 -> -31.428572 | N8: 0 | O8: =SUM(M8:N8) -> -31.428572 | P8: 0 | Q8: 0 | R8: 0 | S8: 0 | T8: 0
C9: 전기오류수정 | M9: =연결정산표_우모건제외!J88/10^6 -> -56.931671 | N9: 0 | O9: =SUM(M9:N9) -> -56.931671 | P9: 0 | Q9: 0 | R9: 0 | S9: 0 | T9: 0
C10: 기타 | M10: =M11-M9-M8-M7-M6 -> 94.088814 | N10: 0 | O10: =SUM(M10:N10) -> 94.088814 | P10: 0 | Q10: 0 | R10: 0 | S10: 0 | T10: 0
B11: 기말 | L11: =연결정산표_우모건제외!P91/10^6 -> 2752.1471 | M11: =연결정산표_우모건제외!M91/10^6 -> 16398.561 | N11: =SUM(N6:N10) -> 22997.762 | O11: =SUM(O6:O10) -> 22997.762 | P11: =SUM(P6:P10) -> 48969.003 | Q11: =SUM(Q6:Q10) -> 80922.519 | R11: =SUM(R6:R10) -> 117112.29 | S11: =SUM(S6:S10) -> 157736.79 | T11: =SUM(T6:T10) -> 203081.24

Sheet Pro forma PL
A1: Pro forma PL
A3: 1. Consolidated
L5: 2024A | M5: 2025 1H | N5: 2025 2H | O5: 2025E | P5: 2026F | Q5: 2027F | R5: 2028F | S5: 2029F | T5: 2030F
B6: 매출액 | L6: =SUM(L30,L54,L78,L102,L126) -> 11223.359 | M6: =SUM(M30,M54,M78,M102,M126) -> 33392.893 | N6: =SUM(N30,N54,N78,N102,N126) -> 43931.553 | O6: =SUM(O30,O54,O78,O102,O126) -> 77324.447 | P6: =SUM(P30,P54,P78,P102,P126) -> 93269.577 | Q6: =SUM(Q30,Q54,Q78,Q102,Q126) -> 103535.16 | R6: =SUM(R30,R54,R78,R102,R126) -> 114632.35 | S6: =SUM(S30,S54,S78,S102,S126) -> 126061.71 | T6: =SUM(T30,T54,T78,T102,T126) -> 138122.31
B7: 영업비용 | L7: =SUM(L8:L10) -> 7882.2028 | M7: =SUM(M8:M10) -> 19480.857 | N7: =SUM(N8:N10) -> 30151.488 | O7: =SUM(O8:O10) -> 49632.346 | P7: =SUM(P8:P10) -> 57986.595 | Q7: =SUM(Q8:Q10) -> 60124.892 | R7: =SUM(R8:R10) -> 65467.261 | S7: =SUM(S8:S10) -> 70872.351 | T7: =SUM(T8:T10) -> 76518.723
C8: 인건비 | L8: =SUM(L32,L56,L80,L104,L128) -> 664.89449 | M8: =SUM(M32,M56,M80,M104,M128) -> 988.67775 | N8: =SUM(N32,N56,N80,N104,N128) -> 1806.2283 | O8: =SUM(O32,O56,O80,O104,O128) -> 2794.906 | P8: =SUM(P32,P56,P80,P104,P128) -> 5597.9335 | Q8: =SUM(Q32,Q56,Q80,Q104,Q128) -> 6113.6151 | R8: =SUM(R32,R56,R80,R104,R128) -> 6662.5778 | S8: =SUM(S32,S56,S80,S104,S128) -> 7205.6801 | T8: =SUM(T32,T56,T80,T104,T128) -> 7774.0943
C9: 변동비 | L9: =SUM(L33,L57,L81,L105,L129) -> 6290.7849 | M9: =SUM(M33,M57,M81,M105,M129) -> 17029.245 | N9: =SUM(N33,N57,N81,N105,N129) -> 26851.976 | O9: =SUM(O33,O57,O81,O105,O129) -> 43881.221 | P9: =SUM(P33,P57,P81,P105,P129) -> 49380.844 | Q9: =SUM(Q33,Q57,Q81,Q105,Q129) -> 50965.933 | R9: =SUM(R33,R57,R81,R105,R129) -> 55710.68 | S9: =SUM(S33,S57,S81,S105,S129) -> 60526.946 | T9: =SUM(T33,T57,T81,T105,T129) -> 65556.135
C10: 고정비 | L10: =SUM(L34,L58,L82,L106,L130) -> 926.52339 | M10: =SUM(M34,M58,M82,M106,M130) -> 1462.9347 | N10: =SUM(N34,N58,N82,N106,N130) -> 1493.2841 | O10: =SUM(O34,O58,O82,O106,O130) -> 2956.2189 | P10: =SUM(P34,P58,P82,P106,P130) -> 3007.8182 | Q10: =SUM(Q34,Q58,Q82,Q106,Q130) -> 3045.3445 | R10: =SUM(R34,R58,R82,R106,R130) -> 3094.0035 | S10: =SUM(S34,S58,S82,S106,S130) -> 3139.7249 | T10: =SUM(T34,T58,T82,T106,T130) -> 3188.4931
B11: 영업이익 | L11: =L6-L7 -> 3341.1562 | M11: =M6-M7 -> 13912.036 | N11: =N6-N7 -> 13780.065 | O11: =O6-O7 -> 27692.101 | P11: =P6-P7 -> 35282.982 | Q11: =Q6-Q7 -> 43410.268 | R11: =R6-R7 -> 49165.087 | S11: =S6-S7 -> 55189.358 | T11: =T6-T7 -> 61603.584
B12: 영업이익률% | L12: =L11/L6 -> 0.29769663 | M12: =M11/M6 -> 0.41661666 | N12: =N11/N6 -> 0.31367125 | O12: =O11/O6 -> 0.35812867 | P12: =P11/P6 -> 0.37829036 | Q12: =Q11/Q6 -> 0.41928044 | R12: =R11/R6 -> 0.42889366 | S12: =S11/S6 -> 0.43779636 | T12: =T11/T6 -> 0.44600749
B13: 영업외손익 | L13: =SUM(L14:L16) -> -159.16174 | M13: =SUM(M14:M16) -> -271.35077 | N13: =SUM(N14:N16) -> 0 | O13: =SUM(O14:O16) -> -271.35077 | P13: =SUM(P14:P16) -> 0 | Q13: =SUM(Q14:Q16) -> 0 | R13: =SUM(R14:R16) -> 0 | S13: =SUM(S14:S16) -> 0 | T13: =SUM(T14:T16) -> 0
C14: 이자수익 | L14: =SUM(L38,L62,L86,L110,L134) -> 0.154836 | M14: =SUM(M38,M62,M86,M110,M134) -> 0.407191 | N14: =SUM(N38,N62,N86,N110,N134) -> 0 | O14: =SUM(O38,O62,O86,O110,O134) -> 0.407191 | P14: =SUM(P38,P62,P86,P110,P134) -> 0 | Q14: =SUM(Q38,Q62,Q86,Q110,Q134) -> 0 | R14: =SUM(R38,R62,R86,R110,R134) -> 0 | S14: =SUM(S38,S62,S86,S110,S134) -> 0 | T14: =SUM(T38,T62,T86,T110,T134) -> 0
C15: 이자비용 | L15: =SUM(L39,L63,L87,L111,L135) -> -36.830795 | M15: =SUM(M39,M63,M87,M111,M135) -> -15.001928 | N15: =SUM(N39,N63,N87,N111,N135) -> 0 | O15: =SUM(O39,O63,O87,O111,O135) -> -15.001928 | P15: =SUM(P39,P63,P87,P111,P135) -> 0 | Q15: =SUM(Q39,Q63,Q87,Q111,Q135) -> 0 | R15: =SUM(R39,R63,R87,R111,R135) -> 0 | S15: =SUM(S39,S63,S87,S111,S135) -> 0 | T15: =SUM(T39,T63,T87,T111,T135) -> 0
C16: 기타 | L16: =SUM(L40,L64,L88,L112,L136) -> -122.48578 | M16: =SUM(M40,M64,M88,M112,M136) -> -256.75603 | N16: =SUM(N40,N64,N88,N112,N136) -> 0 | O16: =SUM(O40,O64,O88,O112,O136) -> -256.75603 | P16: =SUM(P40,P64,P88,P112,P136) -> 0 | Q16: =SUM(Q40,Q64,Q88,Q112,Q136) -> 0 | R16: =SUM(R40,R64,R88,R112,R136) -> 0 | S16: =SUM(S40,S64,S88,S112,S136) -> 0 | T16: =SUM(T40,T64,T88,T112,T136) -> 0
B17: 법인세차감전순이익 | L17: =L11+L13 -> 3181.9944 | M17: =M11+M13 -> 13640.685 | N17: =N11+N13 -> 13780.065 | O17: =O11+O13 -> 27420.75 | P17: =P11+P13 -> 35282.982 | Q17: =Q11+Q13 -> 43410.268 | R17: =R11+R13 -> 49165.087 | S17: =S11+S13 -> 55189.358 | T17: =T11+T13 -> 61603.584
B18: 법인세비용 | L18: =SUM(L42,L66,L90,L114,L138) -> 806.1724 | M18: =SUM(M42,M66,M90,M114,M138) -> 0 | N18: =SUM(N42,N66,N90,N114,N138) -> 7180.8633 | O18: =SUM(O42,O66,O90,O114,O138) -> 7180.8633 | P18: =SUM(P42,P66,P90,P114,P138) -> 9311.7412 | Q18: =SUM(Q42,Q66,Q90,Q114,Q138) -> 11456.751 | R18: =SUM(R42,R66,R90,R114,R138) -> 12975.312 | S18: =SUM(S42,S66,S90,S114,S138) -> 14564.865 | T18: =SUM(T42,T66,T90,T114,T138) -> 16259.129
B19: 당기순이익 | L19: =L17-L18 -> 2375.822 | M19: =M17-M18 -> 13640.685 | N19: =N17-N18 -> 6599.2018 | O19: =O17-O18 -> 20239.887 | P19: =P17-P18 -> 25971.241 | Q19: =Q17-Q18 -> 31953.516 | R19: =R17-R18 -> 36189.775 | S19: =S17-S18 -> 40624.493 | T19: =T17-T18 -> 45344.454
B20: 당기순이익률% | L20: =L19/L$6 -> 0.21168547 | M20: =M19/M$6 -> 0.40849066 | N20: =N19/N$6 -> 0.15021554 | O20: =O19/O$6 -> 0.26175275 | P20: =P19/P$6 -> 0.27845351 | Q20: =Q19/Q$6 -> 0.30862478 | R20: =R19/R$6 -> 0.31570299 | S20: =S19/S$6 -> 0.32225878 | T20: =T19/T$6 -> 0.32829204
B21: D&A | L21: =SUM(L45,L69,L93,L117,L141) -> 127.87806 | M21: =SUM(M45,M69,M93,M117,M141) -> 57.174702 | N21: =SUM(N45,N69,N93,N117,N141) -> 81.972752 | O21: =SUM(O45,O69,O93,O117,O141) -> 139.14745 | P21: =SUM(P45,P69,P93,P117,P141) -> 143.8773 | Q21: =SUM(Q45,Q69,Q93,Q117,Q141) -> 129.85259 | R21: =SUM(R45,R69,R93,R117,R141) -> 117.28632 | S21: =SUM(S45,S69,S93,S117,S141) -> 106.45002 | T21: =SUM(T45,T69,T93,T117,T141) -> 95.874855
B22: EBITDA | L22: =L21+L11 -> 3469.0342 | M22: =M21+M11 -> 13969.211 | N22: =N21+N11 -> 13862.038 | O22: =O21+O11 -> 27831.248 | P22: =P21+P11 -> 35426.859 | Q22: =Q21+Q11 -> 43540.12 | R22: =R21+R11 -> 49282.373 | S22: =S21+S11 -> 55295.808 | T22: =T21+T11 -> 61699.458
B23: EBITDA% | L23: =L22/L$6 -> 0.30909055 | M23: =M22/M$6 -> 0.41832885 | N23: =N22/N$6 -> 0.31553717 | O23: =O22/O$6 -> 0.35992819 | P23: =P22/P$6 -> 0.37983296 | Q23: =Q22/Q$6 -> 0.42053463 | R23: =R22/R$6 -> 0.42991681 | S23: =S22/S$6 -> 0.43864079 | T23: =T22/T$6 -> 0.44670162
B24: Normalized EBITDA | L24: =SUM(L48,L72,L96,L120,L142) -> 2156.3364 | M24: =SUM(M48,M72,M96,M120,M142) -> 9134.3195 | N24: =SUM(N48,N72,N96,N120,N142) -> 13862.038 | O24: =SUM(O48,O72,O96,O120,O142) -> 22996.357 | P24: =SUM(P48,P72,P96,P120,P142) -> 35426.859 | Q24: =SUM(Q48,Q72,Q96,Q120,Q142) -> 43540.12 | R24: =SUM(R48,R72,R96,R120,R142) -> 49282.373 | S24: =SUM(S48,S72,S96,S120,S142) -> 55295.808 | T24: =SUM(T48,T72,T96,T120,T142) -> 61699.458
B25: Norm. EBITDA% | L25: =L24/L6 -> 0.19212933 | M25: =M24/M6 -> 0.27354082 | N25: =N24/N6 -> 0.31553717 | O25: =O24/O6 -> 0.29740087 | P25: =P24/P6 -> 0.37983296 | Q25: =Q24/Q6 -> 0.42053463 | R25: =R24/R6 -> 0.42991681 | S25: =S24/S6 -> 0.43864079 | T25: =T24/T6 -> 0.44670162
A27: 2. TITAN
L29: 2024A | M29: 2025 1H | N29: 2025 2H | O29: 2025E | P29: 2026F | Q29: 2027F | R29: 2028F | S29: 2029F | T29: 2030F
B30: 매출액 | L30: =TITAN!L6 -> 11203.459 | M30: =TITAN!M6 -> 17504.878 | N30: =TITAN!N6 -> 17577.197 | O30: =TITAN!O6 -> 35082.076 | P30: =TITAN!P6 -> 37812.47 | Q30: =TITAN!Q6 -> 40682.35 | R30: =TITAN!R6 -> 43771.909 | S30: =TITAN!S6 -> 46881.275 | T30: =TITAN!T6 -> 50120.726
B31: 영업비용 | L31: =TITAN!L7 -> 7805.3692 | M31: =TITAN!M7 -> 10871.796 | N31: =TITAN!N7 -> 12636.466 | O31: =TITAN!O7 -> 23508.262 | P31: =TITAN!P7 -> 25900.887 | Q31: =TITAN!Q7 -> 26116.725 | R31: =TITAN!R7 -> 27996.971 | S31: =TITAN!S7 -> 29882.534 | T31: =TITAN!T7 -> 31848.718
C32: 인건비 | L32: =TITAN!L43 -> 646.27145 | M32: =TITAN!M43 -> 581.34672 | N32: =TITAN!N43 -> 643.12573 | O32: =TITAN!O43 -> 1224.4724 | P32: =TITAN!P43 -> 1995.7352 | Q32: =TITAN!Q43 -> 2143.1634 | R32: =TITAN!R43 -> 2312.8469 | S32: =TITAN!S43 -> 2479.1937 | T32: =TITAN!T43 -> 2653.0773
C33: 변동비 | L33: =TITAN!L44 -> 6247.7291 | M33: =TITAN!M44 -> 9389.8284 | N33: =TITAN!N44 -> 11088.007 | O33: =TITAN!O44 -> 20477.835 | P33: =TITAN!P44 -> 22082.324 | Q33: =TITAN!Q44 -> 22127.256 | R33: =TITAN!R44 -> 23807.677 | S33: =TITAN!S44 -> 25498.871 | T33: =TITAN!T44 -> 27260.819
C34: 고정비 | L34: =L31-L32-L33 -> 911.36869 | M34: =M31-M32-M33 -> 900.62095 | N34: =N31-N32-N33 -> 905.33322 | O34: =O31-O32-O33 -> 1805.9542 | P34: =P31-P32-P33 -> 1822.8277 | Q34: =Q31-Q32-Q33 -> 1846.3053 | R34: =R31-R32-R33 -> 1876.447 | S34: =S31-S32-S33 -> 1904.4692 | T34: =T31-T32-T33 -> 1934.8223
B35: 영업이익 | L35: =L30-L31 -> 3398.0897 | M35: =M30-M31 -> 6633.0824 | N35: =N30-N31 -> 4940.7319 | O35: =O30-O31 -> 11573.814 | P35: =P30-P31 -> 11911.583 | Q35: =Q30-Q31 -> 14565.625 | R35: =R30-R31 -> 15774.938 | S35: =S30-S31 -> 16998.741 | T35: =T30-T31 -> 18272.008
B36: 영업이익률% | L36: =L35/L30 -> 0.3033072 | M36: =M35/M30 -> 0.37892765 | N36: =N35/N30 -> 0.28108758 | O36: =O35/O30 -> 0.32990677 | P36: =P35/P30 -> 0.31501732 | Q36: =Q35/Q30 -> 0.35803303 | R36: =R35/R30 -> 0.36038954 | S36: =S35/S30 -> 0.36259127 | T36: =T35/T30 -> 0.36455992
B37: 영업외손익 | L37: =연결정산표!F139/10^6-연결정산표!F146/10^6 -> -159.16364 | M37: =연결정산표!U139/10^6-연결정산표!U146/10^6+연결정산표!W140/10^6 -> -240.19787 | N37: =SUM(N38:N40) -> 0 | O37: =SUM(O38:O40) -> -240.19787 | P37: =SUM(P38:P40) -> 0 | Q37: =SUM(Q38:Q40) -> 0 | R37: =SUM(R38:R40) -> 0 | S37: =SUM(S38:S40) -> 0 | T37: =SUM(T38:T40) -> 0
C38: 이자수익 | L38: =연결정산표!G140/10^6 -> 0.152929 | M38: =연결정산표!U140/10^6-연결정산표!W140/10^6 -> 0.308253 | N38: 0 | O38: =N38+M38 -> 0.308253 | P38: 0 | Q38: 0 | R38: 0 | S38: 0 | T38: 0
C39: 이자비용 | L39: =-연결정산표!F147/10^6 -> -36.830795 | M39: =-연결정산표!U147/10^6 -> -14.810261 | N39: 0 | O39: =N39+M39 -> -14.810261 | P39: 0 | Q39: 0 | R39: 0 | S39: 0 | T39: 0
C40: 기타 | L40: =L37-L38-L39 -> -122.48577 | M40: =M37-M38-M39 -> -225.69587 | N40: 0 | O40: =N40+M40 -> -225.69587 | P40: 0 | Q40: 0 | R40: 0 | S40: 0 | T40: 0
B41: 법인세차감전순이익 | L41: =L35+L37 -> 3238.9261 | M41: =M35+M37 -> 6392.8845 | N41: =N35+N37 -> 4940.7319 | O41: =O35+O37 -> 11333.616 | P41: =P35+P37 -> 11911.583 | Q41: =Q35+Q37 -> 14565.625 | R41: =R35+R37 -> 15774.938 | S41: =S35+S37 -> 16998.741 | T41: =T35+T37 -> 18272.008
B42: 법인세비용 | L42: =연결정산표!F154/10^6 -> 806.1724 | M42: 0 | N42: =O42 -> 2992.0747 | O42: =IF(O41<0,0,IF(O41<2,O41*9%*1.1,IF(O41<200,O41*19%*1.1,IF(O41<3000,O41*21%*1.1,O41*24%*1.1)))) -> 2992.0747 | P42: =IF(P41<0,0,IF(P41<2,P41*9%*1.1,IF(P41<200,P41*19%*1.1,IF(P41<3000,P41*21%*1.1,P41*24%*1.1)))) -> 3144.6579 | Q42: =IF(Q41<0,0,IF(Q41<2,Q41*9%*1.1,IF(Q41<200,Q41*19%*1.1,IF(Q41<3000,Q41*21%*1.1,Q41*24%*1.1)))) -> 3845.325 | R42: =IF(R41<0,0,IF(R41<2,R41*9%*1.1,IF(R41<200,R41*19%*1.1,IF(R41<3000,R41*21%*1.1,R41*24%*1.1)))) -> 4164.5837 | S42: =IF(S41<0,0,IF(S41<2,S41*9%*1.1,IF(S41<200,S41*19%*1.1,IF(S41<3000,S41*21%*1.1,S41*24%*1.1)))) -> 4487.6676 | T42: =IF(T41<0,0,IF(T41<2,T41*9%*1.1,IF(T41<200,T41*19%*1.1,IF(T41<3000,T41*21%*1.1,T41*24%*1.1)))) -> 4823.8101
B43: 당기순이익 | L43: =L41-L42 -> 2432.7537 | M43: =M41-M42 -> 6392.8845 | N43: =N41-N42 -> 1948.6572 | O43: =O41-O42 -> 8341.5417 | P43: =P41-P42 -> 8766.9251 | Q43: =Q41-Q42 -> 10720.3 | R43: =R41-R42 -> 11610.354 | S43: =S41-S42 -> 12511.073 | T43: =T41-T42 -> 13448.198
B44: 당기순이익률% | L44: =L43/L$30 -> 0.21714309 | M44: =M43/M$30 -> 0.36520588 | N44: =N43/N$30 -> 0.11086279 | O44: =O43/O$30 -> 0.23777218 | P44: =P43/P$30 -> 0.23185275 | Q44: =Q43/Q$30 -> 0.26351231 | R44: =R43/R$30 -> 0.2652467 | S44: =S43/S$30 -> 0.26686718 | T44: =T43/T$30 -> 0.2683161
...

Sheet Key Assumption
A1: Key Assumption
A3: 1. General
B5: Key Base Factors
B6: Valuation Date | L6: 45838
B7: Market Data Date | L7: 45838
B8: Year End after Valuation Date | L8: 46022
B9: Partial Period Factor | L9: 0.50410959
B11: Macro Indicators(from EIU) | O11: 2025E | P11: 2026F | Q11: 2027F | R11: 2028F | S11: 2029F | T11: 2030F
B12: 소비자물가지수 (avg.) | O12: =EIU!R11/100 -> 0.01913561 | P12: =EIU!S11/100 -> 0.016637681 | Q12: =EIU!T11/100 -> 0.018 | R12: =EIU!U11/100 -> 0.021 | S12: =EIU!V11/100 -> 0.019 | T12: =EIU!W11/100 -> 0.019564128
B13: 생산자물가지수 (avg.) | O13: =EIU!R12/100 -> 0.010711003 | P13: =EIU!S12/100 -> 0.013083958 | Q13: =EIU!T12/100 -> 0.017 | R13: =EIU!U12/100 -> 0.019 | S13: =EIU!V12/100 -> 0.022 | T13: =S13 -> 0.022
B14: 평균명목임금상승률 | O14: =EIU!R10/100 -> 0.016078204 | P14: =EIU!S10/100 -> 0.018670956 | Q14: =EIU!T10/100 -> 0.026144 | R14: =EIU!U10/100 -> 0.033252 | S14: =EIU!V10/100 -> 0.028171 | T14: =S14 -> 0.028171
A17: 2. Key Assumption
B19: 1. .강의 수 / 결제 건수
L20: 2024A | M20: 2025 1H | N20: 2025 2H | O20: 2025E | P20: 2026F | Q20: 2027F | R20: 2028F | S20: 2029F | T20: 2030F
B21: TITAN
C22: 부업
D23: 강의수 | I23: 120 | L23: =TITAN!L23 -> 65 | M23: =TITAN!M23 -> 46 | N23: =COUNTA(타이탄_하반기!B244:B584)/5*6-3 -> 46.2 | O23: =N23+M23 -> 92.2 | P23: =O23+($T23-$O23)/5 -> 97.76 | Q23: =P23+($T23-$O23)/5 -> 103.32 | R23: =Q23+($T23-$O23)/5 -> 108.88 | S23: =R23+($T23-$O23)/5 -> 114.44 | T23: =I23 -> 120 | U23: 플랫폼 추가 및 확장하며 2030년까지 강의 120개 오픈 | AA23: =COUNTIFS(클래스매출!$C$70:$C$117,"부업")/(("2025-11-11"-"2025-07-01")/(31+31+30+31+30+31)) -> 65.022556
D24: 강의당 유입 인원 수(톡방) | I24: =M24 -> 4473.8696 | L24: =TITAN!L25 -> 2085.0067 | M24: =TITAN!M25 -> 4473.8696 | N24: =M24 -> 4473.8696 | O24: =N24 -> 4473.8696 | P24: =$I24 -> 4473.8696 | Q24: =$I24 -> 4473.8696 | R24: =$I24 -> 4473.8696 | S24: =$I24 -> 4473.8696 | T24: =$I24 -> 4473.8696
D25: 유료전환율 | I25: =M25 -> 0.032721406 | L25: =TITAN!L27 -> 0.029529513 | M25: =TITAN!M27 -> 0.032721406 | N25: =M25 -> 0.032721406 | O25: =N25 -> 0.032721406 | P25: =$I25 -> 0.032721406 | Q25: =$I25 -> 0.032721406 | R25: =$I25 -> 0.032721406 | S25: =$I25 -> 0.032721406 | T25: =$I25 -> 0.032721406
B26: CLASS
C27: 부업
D28: 강의수 | I28: 120 | M28: =CLASS!M24 -> 37 | N28: =COUNTIFS(클래스매출!$C$70:$C$117,"부업")/5*6 -> 56.4 | O28: =N28+M28 -> 93.4 | P28: =O28+($T28-$O28)/5 -> 98.72 | Q28: =P28+($T28-$O28)/5 -> 104.04 | R28: =Q28+($T28-$O28)/5 -> 109.36 | S28: =R28+($T28-$O28)/5 -> 114.68 | T28: =I28 -> 120 | U28: 플랫폼 추가 및 확장하며 2030년까지 강의 120개 오픈
D29: 강의당 유입 인원 수(톡방) | I29: =I24 -> 4473.8696 | M29: =CLASS!M26 -> 2944.1892 | N29: =I29 -> 4473.8696 | O29: =CLASS!O26 -> 3867.8934 | P29: =$I29 -> 4473.8696 | Q29: =$I29 -> 4473.8696 | R29: =$I29 -> 4473.8696 | S29: =$I29 -> 4473.8696 | T29: =$I29 -> 4473.8696
D30: 유료전환율 | I30: =M30 -> 0.02703447 | J30: =I30 -> 0.02703447 | M30: =CLASS!M27 -> 0.02703447 | N30: =$I30 -> 0.02703447 | O30: =$I30 -> 0.02703447 | P30: =O30+($T30-$O30)/5 -> 0.02703447 | Q30: =P30+($T30-$O30)/5 -> 0.02703447 | R30: =Q30+($T30-$O30)/5 -> 0.02703447 | S30: =R30+($T30-$O30)/5 -> 0.02703447 | T30: =J30 -> 0.02703447
C31: 투자
D32: 강의수 | I32: =O32 -> 11 | L32: =CLASS!L31 -> 0 | M32: =CLASS!M31 -> 10 | N32: 1 | O32: =N32+M32 -> 11 | P32: =O32+($T32-$O32)/5 -> 11 | Q32: =P32+($T32-$O32)/5 -> 11 | R32: =Q32+($T32-$O32)/5 -> 11 | S32: =R32+($T32-$O32)/5 -> 11 | T32: =I32 -> 11 | U32: 현수준 유지 가정(부업 주력)
D33: 강의당 유입 인원 수(톡방) | I33: =M33 -> 3237.7 | M33: =CLASS!M33 -> 3237.7 | N33: =I33 -> 3237.7 | O33: =CLASS!O33 -> 3237.7 | P33: =$I33 -> 3237.7 | Q33: =$I33 -> 3237.7 | R33: =$I33 -> 3237.7 | S33: =$I33 -> 3237.7 | T33: =$I33 -> 3237.7
D34: 유료전환율 | I34: =M34 -> 0.031009667 | M34: =CLASS!M34 -> 0.031009667 | N34: =$I34 -> 0.031009667 | O34: =$I34 -> 0.031009667 | P34: =$I34 -> 0.031009667 | Q34: =$I34 -> 0.031009667 | R34: =$I34 -> 0.031009667 | S34: =$I34 -> 0.031009667 | T34: =$I34 -> 0.031009667
B35: TTA
C36: 부업
D37: 강의수 | I37: 100 | M37: =TTA!M23 -> 15 | N37: =(COUNTA(티티에이매출v2!$F$18:$F$43)-3)/4*6 -> 34.5 | O37: =N37+M37 -> 49.5 | P37: =O37+($T37-$O37)/5 -> 59.6 | Q37: =P37+($T37-$O37)/5 -> 69.7 | R37: =Q37+($T37-$O37)/5 -> 79.8 | S37: =R37+($T37-$O37)/5 -> 89.9 | T37: =I37 -> 100
D38: 강의당 유입 인원 수(톡방) | I38: =$O38 -> 3742.5866 | M38: =TTA!M25 -> 5200 | N38: =SUM(티티에이매출v2!$K$19:$K$46)/COUNTA(티티에이매출v2!$K$19:$K$46) -> 3108.9286 | O38: =TTA!O25 -> 3742.5866 | P38: =$I38 -> 3742.5866 | Q38: =$I38 -> 3742.5866 | R38: =$I38 -> 3742.5866 | S38: =$I38 -> 3742.5866 | T38: =$I38 -> 3742.5866
D39: 유료전환율 | I39: =M39 -> 0.028846154 | M39: =TTA!M26 -> 0.028846154 | N39: =$I39 -> 0.028846154 | O39: =$I39 -> 0.028846154 | P39: =$I39 -> 0.028846154 | Q39: =$I39 -> 0.028846154 | R39: =$I39 -> 0.028846154 | S39: =$I39 -> 0.028846154 | T39: =$I39 -> 0.028846154
B41: 2. NOVA - 관리 플랫폼 수 / 플랫폼당 월 매출액 / 수수료율
L42: 2024A | M42: 2025 1H | N42: 2025 2H | O42: 2025E | P42: 2026F | Q42: 2027F | R42: 2028F | S42: 2029F | T42: 2030F
B43: 구축관리형
C44: 평균 플랫폼 수 | I44: =시스템노바매출!N21 -> 8 | J44: 12 | M44: =NOVA!M22 -> 1 | N44: =AVERAGE(시스템노바매출!I21:N21) -> 6.6666667 | O44: =NOVA!O22 -> 5.25 | P44: =I44 -> 8 | Q44: =P44+($T44-$P44)/4 -> 9 | R44: =Q44+($T44-$P44)/4 -> 10 | S44: =R44+($T44-$P44)/4 -> 11 | T44: =J44 -> 12
C45: 플랫폼당 월매출액 | M45: =NOVA!M23 -> 1217.3985 | N45: =NOVA!N23 -> 653.50932 | O45: =NOVA!O23 -> 629.90363 | P45: =O45*(1+P$12) -> 640.38377 | Q45: =P45*(1+Q$12) -> 651.91068 | R45: =Q45*(1+R$12) -> 665.6008 | S45: =R45*(1+S$12) -> 678.24722 | T45: =S45*(1+T$12) -> 691.51653 | U45: 물가상승률 수준 상승 가정
C46: 수수료율 | I46: 0.15 | M46: =NOVA!M26 -> 0.097247237 | N46: =M46 -> 0.097247237 | O46: =N46 -> 0.097247237 | P46: =O46+($T46-$O46)/5 -> 0.10779779 | Q46: =P46+($T46-$O46)/5 -> 0.11834834 | R46: =Q46+($T46-$O46)/5 -> 0.12889889 | S46: =R46+($T46-$O46)/5 -> 0.13944945 | T46: =I46 -> 0.15
B47: 구축형
...

Sheet TITAN
A1: TITAN
A3: 1. Summary
L5: 2024A | M5: 2025 1H | N5: 2025 2H | O5: 2025E | P5: 2026F | Q5: 2027F | R5: 2028F | S5: 2029F | T5: 2030F
B6: Revenue | L6: =L19 -> 11203.459 | M6: =M19 -> 17504.878 | N6: =N19 -> 17577.197 | O6: =O19 -> 35082.076 | P6: =P19 -> 37812.47 | Q6: =Q19 -> 40682.35 | R6: =R19 -> 43771.909 | S6: =S19 -> 46881.275 | T6: =T19 -> 50120.726
B7: Operating Expense | L7: =L41 -> 7805.3692 | M7: =M41 -> 10871.796 | N7: =N41 -> 12636.466 | O7: =O41 -> 23508.262 | P7: =P41 -> 25900.887 | Q7: =Q41 -> 26116.725 | R7: =R41 -> 27996.971 | S7: =S41 -> 29882.534 | T7: =T41 -> 31848.718
B8: EBIT | L8: =L6-L7 -> 3398.0897 | M8: =M6-M7 -> 6633.0824 | N8: =N6-N7 -> 4940.7319 | O8: =O6-O7 -> 11573.814 | P8: =P6-P7 -> 11911.583 | Q8: =Q6-Q7 -> 14565.625 | R8: =R6-R7 -> 15774.938 | S8: =S6-S7 -> 16998.741 | T8: =T6-T7 -> 18272.008
B9: EBIT % | L9: =L8/L6 -> 0.3033072 | M9: =M8/M6 -> 0.37892765 | N9: =N8/N6 -> 0.28108758 | O9: =O8/O6 -> 0.32990677 | P9: =P8/P6 -> 0.31501732 | Q9: =Q8/Q6 -> 0.35803303 | R9: =R8/R6 -> 0.36038954 | S9: =S8/S6 -> 0.36259127 | T9: =T8/T6 -> 0.36455992
B10: D&A | L10: =L109 -> 127.87806 | M10: =M109 -> 45.914015 | N10: =N109 -> 50.626289 | O10: =O109 -> 96.540304 | P10: =P109 -> 84.973118 | Q10: =Q109 -> 77.169324 | R10: =R109 -> 70.15918 | S10: =S109 -> 63.861971 | T10: =T109 -> 58.205191
B11: EBITDA | L11: =L10+L8 -> 3525.9678 | M11: =M10+M8 -> 6678.9964 | N11: =N10+N8 -> 4991.3582 | O11: =O10+O8 -> 11670.355 | P11: =P10+P8 -> 11996.556 | Q11: =Q10+Q8 -> 14642.794 | R11: =R10+R8 -> 15845.097 | S11: =S10+S8 -> 17062.603 | T11: =T10+T8 -> 18330.213
B12: EBITDA % | L12: =L11/L6 -> 0.31472136 | M12: =M11/M6 -> 0.38155057 | N12: =N11/N6 -> 0.28396781 | O12: =O11/O6 -> 0.33265861 | P12: =P11/P6 -> 0.31726454 | Q12: =Q11/Q6 -> 0.3599299 | R12: =R11/R6 -> 0.36199237 | S12: =S11/S6 -> 0.36395348 | T12: =T11/T6 -> 0.36572122
B13: Normalized EBITDA | L13: =L11-L82 -> 2213.27 | M13: =M11-M82 -> 5264.701 | N13: =N11-N82 -> 4991.3582 | O13: =O11-O82 -> 10256.059 | P13: =P11-P82 -> 11996.556 | Q13: =Q11-Q82 -> 14642.794 | R13: =R11-R82 -> 15845.097 | S13: =S11-S82 -> 17062.603 | T13: =T11-T82 -> 18330.213
B14: Norm EBITDA % | L14: =L13/L6 -> 0.19755238 | M14: =M13/M6 -> 0.30075622 | N14: =N13/N6 -> 0.28396781 | O14: =O13/O6 -> 0.29234471 | P14: =P13/P6 -> 0.31726454 | Q14: =Q13/Q6 -> 0.3599299 | R14: =R13/R6 -> 0.36199237 | S14: =S13/S6 -> 0.36395348 | T14: =T13/T6 -> 0.36572122
M15: =M8=연결정산표_우모건제외!I140/10^6 -> TRUE | V15: =(연결정산표!F98/10^6-(SUMIFS(타이탄매출!$N:$N,타이탄매출!$B:$B,TITAN!L$18,타이탄매출!$C:$C,TITAN!$D21)/10^6+SUMIFS(클래스매출!$J:$J,클래스매출!$A:$A,TITAN!L$18,클래스매출!$C:$C,TITAN!$D21)/10^6)-(SUMIFS(타이탄매출!$N:$N,타이탄매출!$B:$B,TITAN!L$18,타이탄매출!$C:$C,TITAN!$D29)/10^6+SUMIFS(클래스매출!$J:$J,클래스매출!$A:$A,TITAN!L$18,클래스매출!$C:$C,TITAN!$D29)/10^6))*(SUMIFS(타이탄매출!$N:$N,타이탄매출!$B:$B,TITAN!L$18,타이탄매출!$C:$C,TITAN!$D21)/10^6+SUMIFS(클래스매출!$J:$J,클래스매출!$A:$A,TITAN!L$18,클래스매출!$C:$C,TITAN!$D21)/10^6)/((SUMIFS(타이탄매출!$N:$N,타이탄매출!$B:$B,TITAN!L$18,타이탄매출!$C:$C,TITAN!$D21)/10^6+SUMIFS(클래스매출!$J:$J,클래스매출!$A:$A,TITAN!L$18,클래스매출!$C:$C,TITAN!$D21)/10^6)+(SUMIFS(타이탄매출!$N:$N,타이탄매출!$B:$B,TITAN!L$18,타이탄매출!$C:$C,TITAN!$D29)/10^6+SUMIFS(클래스매출!$J:$J,클래스매출!$A:$A,TITAN!L$18,클래스매출!$C:$C,TITAN!$D29)/10^6)) -> -359.22244
A16: 2. Revenue | V16: =(연결정산표!F98/10^6-(SUMIFS(타이탄매출!$N:$N,타이탄매출!$B:$B,TITAN!L$18,타이탄매출!$C:$C,TITAN!$D21)/10^6+SUMIFS(클래스매출!$J:$J,클래스매출!$A:$A,TITAN!L$18,클래스매출!$C:$C,TITAN!$D21)/10^6)-(SUMIFS(타이탄매출!$N:$N,타이탄매출!$B:$B,TITAN!L$18,타이탄매출!$C:$C,TITAN!$D29)/10^6+SUMIFS(클래스매출!$J:$J,클래스매출!$A:$A,TITAN!L$18,클래스매출!$C:$C,TITAN!$D29)/10^6))*(SUMIFS(타이탄매출!$N:$N,타이탄매출!$B:$B,TITAN!L$18,타이탄매출!$C:$C,TITAN!$D29)/10^6+SUMIFS(클래스매출!$J:$J,클래스매출!$A:$A,TITAN!L$18,클래스매출!$C:$C,TITAN!$D29)/10^6)/((SUMIFS(타이탄매출!$N:$N,타이탄매출!$B:$B,TITAN!L$18,타이탄매출!$C:$C,TITAN!$D21)/10^6+SUMIFS(클래스매출!$J:$J,클래스매출!$A:$A,TITAN!L$18,클래스매출!$C:$C,TITAN!$D21)/10^6)+(SUMIFS(타이탄매출!$N:$N,타이탄매출!$B:$B,TITAN!L$18,타이탄매출!$C:$C,TITAN!$D29)/10^6+SUMIFS(클래스매출!$J:$J,클래스매출!$A:$A,TITAN!L$18,클래스매출!$C:$C,TITAN!$D29)/10^6)) -> -106.17016
L17: =L20-L21-L29 -> 0
L18: 2024A | M18: 2025 1H | N18: 2025 2H | O18: 2025E | P18: 2026F | Q18: 2027F | R18: 2028F | S18: 2029F | T18: 2030F
B19: Revenue | L19: =L20+L34+L35 -> 11203.459 | M19: =M20+M34+M35 -> 17504.878 | N19: =N20+N34+N35 -> 17577.197 | O19: =O20+O34+O35 -> 35082.076 | P19: =P20+P34+P35 -> 37812.47 | Q19: =Q20+Q34+Q35 -> 40682.35 | R19: =R20+R34+R35 -> 43771.909 | S19: =S20+S34+S35 -> 46881.275 | T19: =T20+T34+T35 -> 50120.726
C20: 용역매출(강의매출) | L20: =연결정산표!F98/10^6 -> 11192.304 | M20: =M21+M29 -> 17501.106 | N20: =N21+N29 -> 17577.197 | O20: =O21+O29 -> 35078.303 | P20: =P21+P29 -> 37812.47 | Q20: =Q21+Q29 -> 40682.35 | R20: =R21+R29 -> 43771.909 | S20: =S21+S29 -> 46881.275 | T20: =T21+T29 -> 50120.726
D21: 부업 | L21: =SUMIFS(타이탄매출!$N:$N,타이탄매출!$B:$B,TITAN!L$18,타이탄매출!$C:$C,TITAN!$D21)/10^6+SUMIFS(클래스매출!$K:$K,클래스매출!$A:$A,TITAN!L$18,클래스매출!$C:$C,TITAN!$D21)/10^6+(연결정산표!F98/10^6-(SUMIFS(타이탄매출!$N:$N,타이탄매출!$B:$B,TITAN!L$18,타이탄매출!$C:$C,TITAN!$D21)/10^6+SUMIFS(클래스매출!$K:$K,클래스매출!$A:$A,TITAN!L$18,클래스매출!$C:$C,TITAN!$D21)/10^6)-(SUMIFS(타이탄매출!$N:$N,타이탄매출!$B:$B,TITAN!L$18,타이탄매출!$C:$C,TITAN!$D29)/10^6+SUMIFS(클래스매출!$K:$K,클래스매출!$A:$A,TITAN!L$18,클래스매출!$C:$C,TITAN!$D29)/10^6))*(SUMIFS(타이탄매출!$N:$N,타이탄매출!$B:$B,TITAN!L$18,타이탄매출!$C:$C,TITAN!$D21)/10^6+SUMIFS(클래스매출!$K:$K,클래스매출!$A:$A,TITAN!L$18,클래스매출!$C:$C,TITAN!$D21)/10^6)/((SUMIFS(타이탄매출!$N:$N,타이탄매출!$B:$B,TITAN!L$18,타이탄매출!$C:$C,TITAN!$D21)/10^6+SUMIFS(클래스매출!$K:$K,클래스매출!$A:$A,TITAN!L$18,클래스매출!$C:$C,TITAN!$D21)/10^6)+(SUMIFS(타이탄매출!$N:$N,타이탄매출!$B:$B,TITAN!L$18,타이탄매출!$C:$C,TITAN!$D29)/10^6+SUMIFS(클래스매출!$K:$K,클래스매출!$A:$A,TITAN!L$18,클래스매출!$C:$C,TITAN!$D29)/10^6)) -> 8654.2413 | M21: =연결정산표!U98/10^6 -> 17501.106 | N21: =N22*N28 -> 17577.197 | O21: =O22*O28 -> 35078.303 | P21: =P22*P28 -> 37812.47 | Q21: =Q22*Q28 -> 40682.35 | R21: =R22*R28 -> 43771.909 | S21: =S22*S28 -> 46881.275 | T21: =T22*T28 -> 50120.726
E22: 결제 건수 | L22: =SUMIFS(타이탄매출!$L$4:$L$131,타이탄매출!$B$4:$B$131,TITAN!L$18,타이탄매출!$C$4:$C$131,TITAN!$D21)+SUMIFS(클래스매출!$T:$T,클래스매출!$A:$A,TITAN!L$18,클래스매출!$C:$C,TITAN!$D21) -> 4002 | M22: =SUMIFS(타이탄매출!$L$4:$L$131,타이탄매출!$B$4:$B$131,TITAN!M$18,타이탄매출!$C$4:$C$131,TITAN!$D21) -> 6734 | N22: =N23*N24 -> 6763.2783 | O22: =N22+M22 -> 13497.278 | P22: =P23*P24 -> 14311.214 | Q22: =Q23*Q24 -> 15125.15 | R22: =R23*R24 -> 15939.085 | S22: =S23*S24 -> 16753.021 | T22: =T23*T24 -> 17566.957
F23: 강의 수 | L23: =COUNTIFS(타이탄매출!$B$4:$B$131,L$18,타이탄매출!$C$4:$C$131,$D21)+COUNTIFS(클래스매출!$A:$A,TITAN!L$18,클래스매출!$C:$C,TITAN!$D21) -> 65 | M23: =COUNTIFS(타이탄매출!$B$4:$B$131,M$18,타이탄매출!$C$4:$C$131,$D21) -> 46 | N23: ='Key Assumption'!N23 -> 46.2 | O23: =N23+M23 -> 92.2 | P23: ='Key Assumption'!P23 -> 97.76 | Q23: ='Key Assumption'!Q23 -> 103.32 | R23: ='Key Assumption'!R23 -> 108.88 | S23: ='Key Assumption'!S23 -> 114.44 | T23: ='Key Assumption'!T23 -> 120
F24: 강의당 결제건수 | L24: =L22/L23 -> 61.569231 | M24: =M22/M23 -> 146.3913 | N24: =N25*N27 -> 146.3913 | O24: =O22/O23 -> 146.3913 | P24: =P25*P27 -> 146.3913 | Q24: =Q25*Q27 -> 146.3913 | R24: =R25*R27 -> 146.3913 | S24: =S25*S27 -> 146.3913 | T24: =T25*T27 -> 146.3913
G25: 강의당 신규 유입 수(톡방) | L25: =SUMIFS(타이탄매출!$J:$J,타이탄매출!$B:$B,TITAN!L$18,타이탄매출!$C:$C,TITAN!$D21)/COUNTIFS(타이탄매출!$B:$B,TITAN!L$18,타이탄매출!$C:$C,TITAN!D$21,타이탄매출!$J:$J,">0")+SUMIFS(클래스매출!$R:$R,클래스매출!$A:$A,TITAN!L$18,클래스매출!$C:$C,TITAN!$D21)/COUNTIFS(클래스매출!$A:$A,TITAN!L$18,클래스매출!$C:$C,TITAN!$D21,클래스매출!$R:$R,">0") -> 2085.0067 | M25: =SUMIFS(타이탄매출!$J:$J,타이탄매출!$B:$B,TITAN!M$18,타이탄매출!$C:$C,TITAN!$D21)/COUNTIFS(타이탄매출!$B:$B,TITAN!M$18,타이탄매출!$J:$J,">0",타이탄매출!$C:$C,TITAN!$D21) -> 4473.8696 | N25: ='Key Assumption'!N24 -> 4473.8696 | O25: ='Key Assumption'!O24 -> 4473.8696 | P25: ='Key Assumption'!P24 -> 4473.8696 | Q25: ='Key Assumption'!Q24 -> 4473.8696 | R25: ='Key Assumption'!R24 -> 4473.8696 | S25: ='Key Assumption'!S24 -> 4473.8696 | T25: ='Key Assumption'!T24 -> 4473.8696
G26: CPM | L26: =L75 -> 8.2386225 | M26: =M75 -> 10.364051 | N26: =N75 -> 10.364051 | O26: =O75 -> 10.364051 | P26: =P75 -> 10.536485 | Q26: =Q75 -> 10.726142 | R26: =R75 -> 10.951391 | S26: =S75 -> 11.159467 | T26: =T75 -> 11.377792
G27: 유료 전환율 | L27: =L24/(L25) -> 0.029529513 | M27: =M24/(M25) -> 0.032721406 | N27: ='Key Assumption'!N25 -> 0.032721406 | O27: ='Key Assumption'!O25 -> 0.032721406 | P27: ='Key Assumption'!P25 -> 0.032721406 | Q27: ='Key Assumption'!Q25 -> 0.032721406 | R27: ='Key Assumption'!R25 -> 0.032721406 | S27: ='Key Assumption'!S25 -> 0.032721406 | T27: ='Key Assumption'!T25 -> 0.032721406
E28: 건당결제액 | L28: =L21/L22 -> 2.1624791 | M28: =M21/M22 -> 2.5989168 | N28: =M28 -> 2.5989168 | O28: =N28 -> 2.5989168 | P28: =O28*(1+'Key Assumption'!P$12) -> 2.6421567 | Q28: =P28*(1+'Key Assumption'!Q$12) -> 2.6897156 | R28: =Q28*(1+'Key Assumption'!R$12) -> 2.7461996 | S28: =R28*(1+'Key Assumption'!S$12) -> 2.7983774 | T28: =S28*(1+'Key Assumption'!T$12) -> 2.8531252
D29: 투자 | L29: =SUMIFS(타이탄매출!$N:$N,타이탄매출!$B:$B,TITAN!L$18,타이탄매출!$C:$C,TITAN!$D29)/10^6+SUMIFS(클래스매출!$K:$K,클래스매출!$A:$A,TITAN!L$18,클래스매출!$C:$C,TITAN!$D29)/10^6+(연결정산표!F98/10^6-(SUMIFS(타이탄매출!$N:$N,타이탄매출!$B:$B,TITAN!L$18,타이탄매출!$C:$C,TITAN!$D21)/10^6+SUMIFS(클래스매출!$K:$K,클래스매출!$A:$A,TITAN!L$18,클래스매출!$C:$C,TITAN!$D21)/10^6)-(SUMIFS(타이탄매출!$N:$N,타이탄매출!$B:$B,TITAN!L$18,타이탄매출!$C:$C,TITAN!$D29)/10^6+SUMIFS(클래스매출!$K:$K,클래스매출!$A:$A,TITAN!L$18,클래스매출!$C:$C,TITAN!$D29)/10^6))*(SUMIFS(타이탄매출!$N:$N,타이탄매출!$B:$B,TITAN!L$18,타이탄매출!$C:$C,TITAN!$D29)/10^6+SUMIFS(클래스매출!$K:$K,클래스매출!$A:$A,TITAN!L$18,클래스매출!$C:$C,TITAN!$D29)/10^6)/((SUMIFS(타이탄매출!$N:$N,타이탄매출!$B:$B,TITAN!L$18,타이탄매출!$C:$C,TITAN!$D21)/10^6+SUMIFS(클래스매출!$K:$K,클래스매출!$A:$A,TITAN!L$18,클래스매출!$C:$C,TITAN!$D21)/10^6)+(SUMIFS(타이탄매출!$N:$N,타이탄매출!$B:$B,TITAN!L$18,타이탄매출!$C:$C,TITAN!$D29)/10^6+SUMIFS(클래스매출!$K:$K,클래스매출!$A:$A,TITAN!L$18,클래스매출!$C:$C,TITAN!$D29)/10^6)) -> 2538.0631 | U29: 클래스 일부 타이탄 인식
E30: 결제 건수 | L30: =SUMIFS(클래스매출!$T:$T,클래스매출!$A:$A,TITAN!L$18,클래스매출!$C:$C,TITAN!$D29) -> 911
F31: 강의 수 | L31: =COUNTIFS(클래스매출!$A:$A,TITAN!L$18,클래스매출!$C:$C,TITAN!$D29) -> 10
F32: 강의당 결제건수 | L32: =L30/L31 -> 91.1
E33: 건당결제액 | L33: =L29/L30 -> 2.7860188
C34: 상품매출 | L34: =연결정산표!F97/10^6 -> 11.154544 | M34: 0 | N34: 0 | O34: =N34+M34 -> 0 | P34: 0 | Q34: 0 | R34: 0 | S34: 0 | T34: 0
C35: 임대료매출 | L35: 0 | M35: =연결정산표!U100/10^6 -> 3.772728 | N35: 0 | O35: =N35+M35 -> 3.772728 | P35: 0 | Q35: 0 | R35: 0 | S35: 0 | T35: 0 | U35: 향후 미발생
A38: 3. Operating Expense
L40: 2024A | M40: 2025 1H | N40: 2025 2H | O40: 2025E | P40: 2026F | Q40: 2027F | R40: 2028F | S40: 2029F | T40: 2030F
B41: Operating Expense | L41: =L43+L44+L45+L46 -> 7805.3692 | M41: =M43+M44+M45+M46 -> 10871.796 | N41: =N43+N44+N45+N46 -> 12636.466 | O41: =O43+O44+O45+O46 -> 23508.262 | P41: =P43+P44+P45+P46 -> 25900.887 | Q41: =Q43+Q44+Q45+Q46 -> 26116.725 | R41: =R43+R44+R45+R46 -> 27996.971 | S41: =S43+S44+S45+S46 -> 29882.534 | T41: =T43+T44+T45+T46 -> 31848.718
B42: % of Revenue | L42: =L41/L$19 -> 0.6966928 | M42: =M41/M$19 -> 0.62107235 | N42: =N41/N$19 -> 0.71891242 | O42: =O41/O$19 -> 0.67009323 | P42: =P41/P$19 -> 0.68498268 | Q42: =Q41/Q$19 -> 0.64196697 | R42: =R41/R$19 -> 0.63961046 | S42: =S41/S$19 -> 0.63740873 | T42: =T41/T$19 -> 0.63544008
C43: 인건비 | L43: =L49 -> 646.27145 | M43: =M49 -> 581.34672 | N43: =N49 -> 643.12573 | O43: =O49 -> 1224.4724 | P43: =P49 -> 1995.7352 | Q43: =Q49 -> 2143.1634 | R43: =R49 -> 2312.8469 | S43: =S49 -> 2479.1937 | T43: =T49 -> 2653.0773
C44: 변동비 | L44: =L62 -> 6247.7291 | M44: =M62 -> 9389.8284 | N44: =N62 -> 11088.007 | O44: =O62 -> 20477.835 | P44: =P62 -> 22082.324 | Q44: =Q62 -> 22127.256 | R44: =R62 -> 23807.677 | S44: =S62 -> 25498.871 | T44: =T62 -> 27260.819
C45: 고정비 | L45: =L86 -> 902.64485 | M45: =M86 -> 900.62095 | N45: =N86 -> 905.33322 | O45: =O86 -> 1805.9542 | P45: =P86 -> 1822.8277 | Q45: =Q86 -> 1846.3053 | R45: =R86 -> 1876.447 | S45: =S86 -> 1904.4692 | T45: =T86 -> 1934.8223
...

Sheet CLASS
A1: CLASS
A3: 1. Summary
L5: 2024A | M5: 2025 1H | N5: 2025 2H | O5: 2025E | P5: 2026F | Q5: 2027F | R5: 2028F | S5: 2029F | T5: 2030F
