Workbook

Sheet Report
B2: 적용환율 : | D2: 1 USD k = | E2: =1131.6/10^3 -> 1.1316
B3: Multiples based on available LTM financials; EV/EBIT over 40x, EV/EBITDA over 30x, P/E over 30x are classified as outliers and excluded from calculation of mean and median
B5: 1. 하이엔텍
B7: (USD m) | G7: Implied EV | H7: Implied Equity Value | J7: Historic
B8: Date | C8: Target | D8: Bidder | E8: Deal Value | F8: % Stake | J8: EV/EBITDA | K8: P/E | L8: P/B
B9: Korea
B10: =Transaction!D7 -> 2016.05 | C10: =Transaction!C7 -> 코오롱워터앤에너지 | D10: =Transaction!G7 -> SC PE | E10: =Transaction!M7/$E$2 -> 124361.27 | F10: =Transaction!L7 -> 0.6298 | G10: =Transaction!P7/$E$2 -> 72238.236 | H10: =Transaction!M7/$E$2 -> 124361.27 | J10: =Transaction!AA7 -> 6.6280923 | K10: =Transaction!AE7 -> 18.828503 | L10: =Transaction!AF7 -> 1.606883
B11: =Transaction!D8 -> 2018.06 | C11: =Transaction!C8 -> TSK워터 | D11: =Transaction!G8 -> 태영건설 | E11: =Transaction!M8/$E$2 -> 441852.24 | F11: =Transaction!L8 -> 0.24999876 | G11: =Transaction!P8/$E$2 -> 515981.19 | H11: =Transaction!M8/$E$2 -> 441852.24 | J11: =Transaction!AA8 -> 7.1405148 | K11: =Transaction!AE8 -> 14.443424 | L11: =Transaction!AF8 -> 2.7755315
B12: =Transaction!D15 -> 2018.12 | C12: =Transaction!C15 -> WIK그린 | D12: =Transaction!G15 -> SC PE | E12: =Transaction!M15/$E$2 -> 66277.837 | F12: =Transaction!L15 -> 1 | G12: =Transaction!P15/$E$2 -> 63880.4 | H12: =Transaction!M15/$E$2 -> 66277.837 | J12: =Transaction!AA15 -> 13.273734 | K12: =Transaction!AE15 -> 19.627495 | L12: =Transaction!AF15 -> 2.0439125
B13: =Transaction!D16 -> 2019.05 | C13: =Transaction!C16 -> 인선이엔티 | D13: =Transaction!G16 -> IS 동서 | E13: =Transaction!M16/$E$2 -> 370825.9 | F13: =Transaction!L16 -> 0.2383 | G13: =Transaction!P16/$E$2 -> 408401.99 | H13: =Transaction!M16/$E$2 -> 370825.9 | J13: =Transaction!AA16 -> 15.245795 | K13: =Transaction!AE16 -> 21.018255 | L13: =Transaction!AF16 -> 2.2447119
B14: =Transaction!D17 -> 2019.04 | C14: =Transaction!C17 -> 창원에너텍 | D14: =Transaction!G17 -> SK증권 PE | E14: =Transaction!M17/$E$2 -> 60091.905 | F14: =Transaction!L17 -> 1 | G14: =Transaction!P17/$E$2 -> 91267.19 | H14: =Transaction!M17/$E$2 -> 60091.905 | J14: =Transaction!AA17 -> 16.918537 | K14: NA | L14: =Transaction!AF17 -> 6.1887813
B15: =Transaction!D18 -> 2017.11 | C15: =Transaction!C18 -> 삼우그린 | D15: =Transaction!G18 -> 앵커 PE | E15: =Transaction!M18/$E$2 -> 50371.156 | F15: =Transaction!L18 -> 1 | G15: =Transaction!P18/$E$2 -> 35622.234 | H15: =Transaction!M18/$E$2 -> 50371.156 | J15: =Transaction!AA18 -> 11.17719 | K15: =Transaction!AE18 -> 22.239133 | L15: =Transaction!AF18 -> 2.9686205
B16: Mean | J16: =AVERAGE(J10:J15) -> 11.730644 | K16: =AVERAGE(K10:K15) -> 19.231362 | L16: =AVERAGE(L10:L15) -> 2.9714068
B17: Median | J17: =MEDIAN(J10:J15) -> 12.225462 | K17: =MEDIAN(K10:K15) -> 19.627495 | L17: =MEDIAN(L10:L15) -> 2.5101217
B18: Global
B19: =Transaction!D10 -> 2018.03 | C19: =Transaction!C10 -> FCC Aqualia | D19: =Transaction!G10 -> IFM Investors | E19: =Transaction!M10/$E$2 -> 2272.383 | F19: =Transaction!L10 -> 0.49 | G19: =Transaction!P10 -> 3156.8947 | H19: =Transaction!M10 -> 2571.4286 | J19: =Transaction!AA10 -> 10.905504 | K19: =Transaction!AE10 -> 0 | L19: =Transaction!AF10 -> 0
B20: =Transaction!D11 -> 2017.12 | C20: =Transaction!C11 -> Anglian Water Group | D20: =Transaction!G11 -> Dalmore Capital | E20: =Transaction!M11/$E$2 -> 3116.5312 | F20: =Transaction!L11 -> 0.15 | G20: =Transaction!P11 -> 13016.432 | H20: =Transaction!M11 -> 3526.6667 | J20: =Transaction!AA11 -> 15.521123 | K20: =Transaction!AE11 -> 0 | L20: =Transaction!AF11 -> 0
B21: =Transaction!D12 -> 2017.05 | C21: =Transaction!C12 -> Affinity Water | D21: =Transaction!G12 -> Allianz Capital Partners | E21: =Transaction!M12/$E$2 -> 886350.84 | F21: =Transaction!L12 -> 1 | G21: =Transaction!P12/$E$2 -> 1995169.4 | H21: =Transaction!M12/$E$2 -> 886350.84 | J21: =Transaction!AA12 -> 12.285164 | K21: =Transaction!AE12 -> 23.184433 | L21: =Transaction!AF12 -> 3.3057958
B22: =Transaction!D13 -> 2012.06 | C22: =Transaction!C13 -> Veolia Water Central | D22: =Transaction!G13 -> Morgan Stanley | E22: =Transaction!M13/$E$2 -> 2180714 | F22: =Transaction!L13 -> 0.9 | G22: =Transaction!P13/$E$2 -> 2923051.2 | H22: =Transaction!M13/$E$2 -> 2180714 | J22: =Transaction!AA13 -> 13.105763 | K22: NA | L22: =Transaction!AF13 -> 3.8815522
B23: Mean | J23: =AVERAGE(J19:J22) -> 12.954388 | K23: =AVERAGE(K19:K22) -> 7.7281443 | L23: =AVERAGE(L19:L22) -> 1.796837
B24: Median | J24: =MEDIAN(J19:J22) -> 12.695463 | K24: =MEDIAN(K19:K22) -> 0 | L24: =MEDIAN(L19:L22) -> 1.6528979
B26: Mean | J26: =AVERAGE(J19:J22,J10:J15) -> 12.220142 | K26: =AVERAGE(K19:K22,K10:K15) -> 14.917655 | L26: =AVERAGE(L19:L22,L10:L15) -> 2.5015789
B27: Median | J27: =MEDIAN(J19:J22,J10:J15) -> 12.695463 | K27: =MEDIAN(K19:K22,K10:K15) -> 19.227999 | L27: =MEDIAN(L19:L22,L10:L15) -> 2.5101217
B29: Merger Market에서“Industrial products and services ” 산업분류內 최근5개년간(2014.01.01 ~ 현재) 국내외 거래사례 중 수처리장 운영회사(또는 유관회사) 내에서, 재무정보가 공개되지 않은 사례, 영업이익 및 EBITDA가 (-)인 사례를 제외함.
B31: 2. 히타치
B33: (USD m) | G33: Implied EV | H33: Implied Equity Value | J33: Historic
B34: Date | C34: Target | D34: Bidder | E34: Deal Value | F34: % Stake | J34: EV/EBITDA | K34: P/E | L34: P/B
B35: Korea
B36: =Transaction!D26 -> 2017.09 | C36: =Transaction!C26 -> 한국종합기술 | D36: =Transaction!G26 -> 한국종합기술홀딩스 | E36: =Transaction!M26/$E$2 -> 86082.715 | F36: =Transaction!L26 -> 0.5201 | G36: =Transaction!P26/$E$2 -> 46230.297 | H36: =Transaction!M26/$E$2 -> 86082.715 | J36: =Transaction!AA26 -> 8.2963934 | K36: =Transaction!AE26 -> NA | L36: =Transaction!AF26 -> 0.85162015
B37: =Transaction!D27 -> 2014.10 | C37: =Transaction!C27 -> 휴비스워터 | D37: =Transaction!G27 -> 휴비스 | E37: =Transaction!M27/$E$2 -> 122253.36 | F37: =Transaction!L27 -> 0.9527 | G37: =Transaction!P27/$E$2 -> 101596.36 | H37: =Transaction!M27/$E$2 -> 122253.36 | J37: =Transaction!AA27 -> 9.2611499 | K37: NA | L37: =Transaction!AF27 -> 2.0536668
B38: Mean | J38: =AVERAGE(J36:J37) -> 8.7787717 | K38: NA | L38: =AVERAGE(L36:L37) -> 1.4526435
B39: Median | J39: =MEDIAN(J36:J37) -> 8.7787717 | K39: NA | L39: =MEDIAN(L36:L37) -> 1.4526435
B40: Global
B41: =Transaction!D29 -> 2017.09 | C41: =Transaction!C29 -> Trility | D41: =Transaction!G29 -> Beijing Enterprises Water | E41: =Transaction!M29 -> 200 | F41: =Transaction!L29 -> 1 | G41: =Transaction!P29 -> 200 | H41: =Transaction!M29 -> 200 | J41: =Transaction!AA29 -> 9.371193
B42: =Transaction!D30 -> 2017.03 | C42: =Transaction!C30 -> Suez Water Technologies & Solutions | D42: =Transaction!G30 -> Suez | E42: =Transaction!M30 -> 3379 | F42: =Transaction!L30 -> 1 | G42: =Transaction!P30 -> 3379 | H42: =Transaction!M30 -> 3379 | J42: =Transaction!AA30 -> 9.9337447
B43: Mean | J43: =AVERAGE(J41:J42) -> 9.6524688 | K43: NA | L43: =AVERAGE(L41:L42) -> #DIV/0!
B44: Median | J44: =MEDIAN(J41:J42) -> 9.6524688 | K44: NA | L44: =MEDIAN(L41:L42) -> #NUM!
B46: Mean | J46: =AVERAGE(J41:J42,J36:J37) -> 9.2156202 | K46: =AVERAGE(K41:K42,K36:K37) -> #DIV/0! | L46: =AVERAGE(L41:L42,L36:L37) -> 1.4526435
B47: Median | J47: =MEDIAN(J41:J42,J36:J37) -> 9.3161714 | K47: =MEDIAN(K41:K42,K36:K37) -> #NUM! | L47: =MEDIAN(L41:L42,L36:L37) -> 1.4526435
B49: Merger Market에서“Utillities(others) ” 산업분류內 최근5개년간(2014.01.01 ~ 현재) 국내외 거래사례 중 수처리장 EPC 회사(또는 유관회사) 내에서, 재무정보가 공개되지 않은 사례, 영업이익 및 EBITDA가 (-)인 사례를 제외함.

Sheet Transaction
B2: Transaction Multiple_하이엔텍
K3: 거래정보 | Q3: 재무정보 | Z3: Multiple
D4: Announce | K4: 거래 | L4: 취득 | M4: Equity | N4: Net | P4: Enterprise | Q4: Fiscal | Z4: EV/ | AA4: EV/ | AB4: EV/ | AE4: PER | AF4: PBR
B5: Target | D5: Date | F5: 산업 | G5: Major Bidder | H5: Seller | I5: 국가 | J5: 단위 | K5: 가격 | L5: 지분율 | M5: Value | N5: Debt (*1) | O5: NOA (*2) | P5: Vaule | Q5: Year (*3) | R5: BV | S5: Sales | T5: EBITDA | U5: EBIT | V5: NI | W5: PBR | X5: Net margin | Y5: BV | Z5: Sales | AA5: EBITDA | AB5: EBIT | AC5: PER | AD5: Source
B6: Tier 1 / 수처리 국내
C7: 코오롱워터앤에너지 | D7: 2016.05 | E7: -2000년 민영화 이후 2007년 코오롱 건설이 100% 취득 -2009년 SCPE 40% 취득 -2016년 5월 SCPE 62.98% 추가 취득(거래 전 지분율 35%) | F7: 수처리 운영관리업 | G7: SC PE | H7: 코오롱 인더스트리 | I7: 한국 | J7: KRW m | K7: 88630 | L7: 0.6298 | M7: =K7/L7 -> 140727.21 | N7: =환경관리!B4 -> -8095.1262 | O7: =환경관리!C4 -> 50887.301 | P7: =M7+N7-O7 -> 81744.788 | Q7: FY2015 | R7: =환경관리!F4 -> 87577.76 | S7: =환경관리!G4 -> 226423.01 | T7: =환경관리!H4 -> 12333.079 | U7: =환경관리!I4 -> 8938.5028 | V7: =환경관리!J4 -> 7474.1583 | W7: =IFERROR(IF(P7/R7<0,"NA",P7/R7),"NA") -> 0.93339665 | X7: =환경관리!J4 -> 7474.1583 | Y7: =환경관리!F4 -> 87577.76 | Z7: =IFERROR(IF(P7/S7<0,"NA",P7/S7),"NA") -> 0.36102686 | AA7: =IFERROR(IF(P7/T7<0,"NA",P7/T7),"NA") -> 6.6280923 | AB7: =IFERROR(IF(P7/U7<0,"NA",P7/U7),"NA") -> 9.1452439 | AC7: =IFERROR(IF(P7/V7<0,"NA",P7/V7),"NA") -> 10.936989 | AD7: http://www.investchosun.com/2016/05/23/3194607 | AE7: =IFERROR(IF(M7/X7<0,"NA",M7/X7),"NA") -> 18.828503 | AF7: =IFERROR(IF(M7/Y7<0,"NA",M7/Y7),"NA") -> 1.606883 | AG7: Majority 추가취득
C8: TSK워터 | D8: 2018.06 | E8: -2004년 태영건설 100% 설립 -2010년 SK계열사로부터 합작사업약정계약 (지분율 50대50) -2018년 6월 SK계열사 지분 25% 인수(Implied EquityValue 5천억) -2018년 10월 TSK워터 물적분할(존속법인 TSK코퍼레이션, 신설법인 TSK워터) -2019년 1월 휴비스워터 100% 자회사 편입 완료(주식교환, Implied EquityValue 6천억) - 태영건설 윤석민 회장과 SK디스커버리 최창원 회장은 절친한 사이, 기타 특수관계는 확인되지 않음. | F8: 수처리 운영관리업 | G8: 태영건설 | H8: SK디스커버리, SK건설 | I8: 한국 | J8: KRW m | K8: 124999.38 | L8: 0.24999876 | M8: =K8/L8 -> 500000 | N8: =티에스케이코퍼레이션!B4 -> 117925.29 | O8: =티에스케이코퍼레이션!C4 -> 34040.969 | P8: =M8+N8-O8 -> 583884.32 | Q8: FY2017 | R8: =티에스케이코퍼레이션!F4 -> 180145.67 | S8: =티에스케이코퍼레이션!G4 -> 421868.93 | T8: =티에스케이코퍼레이션!H4 -> 81770.619 | U8: =티에스케이코퍼레이션!I4 -> 51166.931 | V8: =티에스케이코퍼레이션!J4 -> 34617.831 | W8: =IFERROR(IF(P8/R8<0,"NA",P8/R8),"NA") -> 3.2411787 | X8: =티에스케이코퍼레이션!J4 -> 34617.831 | Y8: =티에스케이코퍼레이션!F4 -> 180145.67 | Z8: =IFERROR(IF(P8/S8<0,"NA",P8/S8),"NA") -> 1.384042 | AA8: =IFERROR(IF(P8/T8<0,"NA",P8/T8),"NA") -> 7.1405148 | AB8: =IFERROR(IF(P8/U8<0,"NA",P8/U8),"NA") -> 11.411361 | AC8: =IFERROR(IF(P8/V8<0,"NA",P8/V8),"NA") -> 16.866577 | AD8: https://www.thebell.co.kr/free/content/ArticleView.asp?key=201806290100048700002980&lcode=00 | AE8: =IFERROR(IF(M8/X8<0,"NA",M8/X8),"NA") -> 14.443424 | AF8: =IFERROR(IF(M8/Y8<0,"NA",M8/Y8),"NA") -> 2.7755315
B9: Tier 2 / 수처리 해외
C10: FCC Aqualia | D10: 2018.03 | F10: 수자원 공급업무 및 수처리업 | G10: IFM Investors | H10: Fomento de Construcciones | I10: 스페인 | J10: USD m | K10: =MergerMarket!S8 -> 1260 | L10: 0.49 | M10: =K10/L10 -> 2571.4286 | N10: =MergerMarket!L8 -> 585.4661 | O10: 0 | P10: =M10+N10-O10 -> 3156.8947 | Q10: FY2017 | R10: 439.3 | S10: =MergerMarket!O8 -> 1242.252 | T10: =MergerMarket!P8 -> 289.4772 | U10: =MergerMarket!Q8 -> 178.5612 | V10: 88.9 | W10: =IFERROR(IF(P10/R10<0,"NA",P10/R10),"NA") -> 7.1861932 | Z10: =IFERROR(IF(P10/S10<0,"NA",P10/S10),"NA") -> 2.5412675 | AA10: =IFERROR(IF(P10/T10<0,"NA",P10/T10),"NA") -> 10.905504 | AB10: =IFERROR(IF(P10/U10<0,"NA",P10/U10),"NA") -> 17.679623 | AC10: =IFERROR(IF(P10/V10<0,"NA",P10/V10),"NA") -> 35.510626 | AD10: https://www.ifminvestors.com/about-us/media-centre/!news/2018/03/18/ifm-investors-to-invest-in-fcc-aqualia-with-49-stake
C11: Anglian Water Group | D11: 2017.12 | F11: 수자원 공급업무 및 수처리업 | G11: Dalmore Capital | H11: 3i Infrastructure | I11: 영국 | J11: USD m | K11: =MergerMarket!S9 -> 529 | L11: 0.15 | M11: =K11/L11 -> 3526.6667 | N11: =MergerMarket!L9 -> 9489.765 | O11: 0 | P11: =M11+N11-O11 -> 13016.432 | Q11: FY2016 | R11: 1121.3 | S11: =MergerMarket!O9 -> 1682.6232 | T11: =MergerMarket!P9 -> 838.6269 | U11: =MergerMarket!Q9 -> 446.7849 | V11: -16.8 | W11: =IFERROR(IF(P11/R11<0,"NA",P11/R11),"NA") -> 11.60834 | Z11: =IFERROR(IF(P11/S11<0,"NA",P11/S11),"NA") -> 7.7357971 | AA11: =IFERROR(IF(P11/T11<0,"NA",P11/T11),"NA") -> 15.521123 | AB11: =IFERROR(IF(P11/U11<0,"NA",P11/U11),"NA") -> 29.133553 | AC11: =IFERROR(IF(P11/V11<0,"NA",P11/V11),"NA") -> NA | AD11: https://www.3i-infrastructure.com/newsroom/press-releases/2017/3i-infrastructure-plc-sells-its-stake-in-anglian-water-group/
C12: Affinity Water | D12: 2017.05 | F12: 수자원 공급업무 및 수처리업 | G12: Allianz Capital Partners | H12: Veolia Water, Morgan Stanley | I12: 영국 | J12: KRW m | K12: 1002994.6 | L12: 1 | M12: =K12/L12 -> 1002994.6 | N12: =Affinity!M6-Affinity!M3 -> 1254823.1 | O12: =Affinity!M10 -> 84.000301 | P12: =M12+N12-O12 -> 2257733.7 | Q12: FY2016 | R12: =Affinity!M16 -> 303404.89 | S12: =Affinity!C3 -> 432128.35 | T12: =Affinity!D3 -> 183777.26 | U12: =Affinity!E3 -> 112764.8 | V12: =Affinity!F3 -> 43261.555 | W12: =IFERROR(IF(P12/R12<0,"NA",P12/R12),"NA") -> 7.4413228 | X12: =Affinity!F3 -> 43261.555 | Y12: =Affinity!M16 -> 303404.89 | Z12: =IFERROR(IF(P12/S12<0,"NA",P12/S12),"NA") -> 5.2246832 | AA12: =IFERROR(IF(P12/T12<0,"NA",P12/T12),"NA") -> 12.285164 | AB12: =IFERROR(IF(P12/U12<0,"NA",P12/U12),"NA") -> 20.021617 | AC12: =IFERROR(IF(P12/V12<0,"NA",P12/V12),"NA") -> 52.187993 | AD12: https://www.allianz.com/en/press/news/financials/stakes_investments/170502-allianz-invests-in-affinity-water-in-uk.html | AE12: =IFERROR(IF(M12/X12<0,"NA",M12/X12),"NA") -> 23.184433 | AF12: =IFERROR(IF(M12/Y12<0,"NA",M12/Y12),"NA") -> 3.3057958
C13: Veolia Water Central | D13: 2012.06 | F13: 수자원 공급업무 및 수처리업 | G13: Morgan Stanley | H13: Veolia Environnement | I13: 영국 | J13: KRW m | K13: 2220926.4 | L13: 0.9 | M13: =K13/L13 -> 2467696 | N13: =Affinity!L6-Affinity!L3 -> 840119.35 | O13: =Affinity!L10 -> 90.57168 | P13: =M13+N13-O13 -> 3307724.8 | Q13: FY2011 | R13: =Affinity!L16 -> 635749.79 | S13: =Affinity!C4 -> 458365.16 | T13: =Affinity!D4 -> 252387.04 | U13: =Affinity!E4 -> 116757.76 | V13: =Affinity!F4 -> 65010.54 | W13: =IFERROR(IF(P13/R13<0,"NA",P13/R13),"NA") -> 5.202872 | X13: =Affinity!F4 -> 65010.54 | Y13: =Affinity!L16 -> 635749.79 | Z13: =IFERROR(IF(P13/S13<0,"NA",P13/S13),"NA") -> 7.216353 | AA13: =IFERROR(IF(P13/T13<0,"NA",P13/T13),"NA") -> 13.105763 | AB13: =IFERROR(IF(P13/U13<0,"NA",P13/U13),"NA") -> 28.329806 | AC13: =IFERROR(IF(P13/V13<0,"NA",P13/V13),"NA") -> 50.879823 | AD13: https://www.bbc.com/news/business-18621952 | AE13: =IFERROR(IF(M13/X13<0,"NA",M13/X13),"NA") -> 37.958399 | AF13: =IFERROR(IF(M13/Y13<0,"NA",M13/Y13),"NA") -> 3.8815522
B14: Tier 3 / 폐기물처리
C15: WIK그린 | D15: 2018.12 | F15: 폐기물 처리업 | G15: SC PE | H15: 맥쿼리 | I15: 한국 | J15: KRW m | K15: 75000 | L15: 1 | M15: =K15/L15 -> 75000 | N15: =WIK그린!B4 -> -2654.192 | O15: =WIK그린!C4 -> 58.747546 | P15: =M15+N15-O15 -> 72287.06 | Q15: FY2017 | R15: =WIK그린!F4 -> 36694.33 | S15: =WIK그린!G4 -> 12535.804 | T15: =WIK그린!H4 -> 5445.8721 | U15: =WIK그린!I4 -> 3709.3191 | V15: =WIK그린!J4 -> 3821.1703 | W15: =IFERROR(IF(P15/R15<0,"NA",P15/R15),"NA") -> 1.969979 | X15: =WIK그린!J4 -> 3821.1703 | Y15: =WIK그린!F4 -> 36694.33 | Z15: =IFERROR(IF(P15/S15<0,"NA",P15/S15),"NA") -> 5.7664477 | AA15: =IFERROR(IF(P15/T15<0,"NA",P15/T15),"NA") -> 13.273734 | AB15: =IFERROR(IF(P15/U15<0,"NA",P15/U15),"NA") -> 19.487959 | AC15: =IFERROR(IF(P15/V15<0,"NA",P15/V15),"NA") -> 18.917519 | AD15: https://www.thebell.co.kr/free/Content/ArticleView.asp?key=201903150100028040001799&svccode=01 | AE15: =IFERROR(IF(M15/X15<0,"NA",M15/X15),"NA") -> 19.627495 | AF15: =IFERROR(IF(M15/Y15<0,"NA",M15/Y15),"NA") -> 2.0439125
C16: 인선이엔티 | D16: 2019.05 | F16: 폐기물 처리업 | G16: IS 동서 | H16: E&F PE | I16: 한국 | J16: KRW m | K16: 99997.015 | L16: 0.2383 | M16: =K16/L16 -> 419626.58 | N16: =인선이엔티!C6-인선이엔티!C3 -> 45306.328 | O16: =인선이엔티!C10 -> 2785.2241 | P16: =M16+N16-O16 -> 462147.69 | Q16: FY2018 | R16: =인선이엔티!C16 -> 186940.06 | S16: =인선이엔티!H4 -> 175954.97 | T16: =인선이엔티!H7 -> 30313.125 | U16: =인선이엔티!H5 -> 23853.49 | V16: =인선이엔티!H8 -> 19964.863 | W16: =IFERROR(IF(P16/R16<0,"NA",P16/R16),"NA") -> 2.4721704 | X16: =인선이엔티!H8 -> 19964.863 | Y16: =인선이엔티!C16 -> 186940.06 | Z16: =IFERROR(IF(P16/S16<0,"NA",P16/S16),"NA") -> 2.6265112 | AA16: =IFERROR(IF(P16/T16<0,"NA",P16/T16),"NA") -> 15.245795 | AB16: =IFERROR(IF(P16/U16<0,"NA",P16/U16),"NA") -> 19.374426 | AC16: =IFERROR(IF(P16/V16<0,"NA",P16/V16),"NA") -> 23.148052 | AD16: http://dart.fss.or.kr/dsaf001/main.do?rcpNo=20190503900734 | AE16: =IFERROR(IF(M16/X16<0,"NA",M16/X16),"NA") -> 21.018255 | AF16: =IFERROR(IF(M16/Y16<0,"NA",M16/Y16),"NA") -> 2.2447119
C17: 창원에너텍 | D17: 2019.04 | F17: 폐기물 처리업 | G17: SK증권 PE | H17: KC환경서비스 | I17: 한국 | J17: KRW m | K17: 68000 | L17: 1 | M17: =K17/L17 -> 68000 | N17: =창원에너텍!B5 -> 35786.697 | O17: =창원에너텍!C5 -> 508.74475 | P17: =M17+N17-O17 -> 103277.95 | Q17: FY2018 | R17: =창원에너텍!F5 -> 10987.624 | S17: =창원에너텍!G5 -> 14685.915 | T17: =창원에너텍!H5 -> 6104.4256 | U17: =창원에너텍!I5 -> 2059.2282 | V17: =창원에너텍!J5 -> 767.8966 | W17: =IFERROR(IF(P17/R17<0,"NA",P17/R17),"NA") -> 9.3994804 | X17: =창원에너텍!J5 -> 767.8966 | Y17: =창원에너텍!F5 -> 10987.624 | Z17: =IFERROR(IF(P17/S17<0,"NA",P17/S17),"NA") -> 7.0324492 | AA17: =IFERROR(IF(P17/T17<0,"NA",P17/T17),"NA") -> 16.918537 | AB17: =IFERROR(IF(P17/U17<0,"NA",P17/U17),"NA") -> 50.15372 | AC17: =IFERROR(IF(P17/V17<0,"NA",P17/V17),"NA") -> 134.49461 | AD17: https://www.thebell.co.kr/free/Content/ArticleView.asp?key=201904300100057530003569&svccode=01 | AE17: =IFERROR(IF(M17/X17<0,"NA",M17/X17),"NA") -> 88.553589 | AF17: =IFERROR(IF(M17/Y17<0,"NA",M17/Y17),"NA") -> 6.1887813
C18: 삼우그린 | D18: 2017.11 | F18: 폐기물 처리업 | G18: 앵커 PE | H18: - | I18: 한국 | J18: KRW m | K18: 57000 | L18: 1 | M18: =K18/L18 -> 57000 | N18: =삼우그린!B5 -> 152.01951 | O18: =삼우그린!C5 -> 16841.9 | P18: =M18+N18-O18 -> 40310.12 | Q18: FY2016 | R18: =삼우그린!F5 -> 22114.32 | S18: =삼우그린!G5 -> 8007.8196 | T18: =삼우그린!H5 -> 3606.4627 | U18: =삼우그린!I5 -> 3110.421 | V18: =삼우그린!J5 -> 2913.4828 | W18: =IFERROR(IF(P18/R18<0,"NA",P18/R18),"NA") -> 1.8228062 | X18: =삼우그린!J4 -> 2563.0496 | Y18: =삼우그린!F4 -> 19200.838 | Z18: =IFERROR(IF(P18/S18<0,"NA",P18/S18),"NA") -> 5.0338446 | AA18: =IFERROR(IF(P18/T18<0,"NA",P18/T18),"NA") -> 11.17719 | AB18: =IFERROR(IF(P18/U18<0,"NA",P18/U18),"NA") -> 12.959699 | AC18: =IFERROR(IF(P18/V18<0,"NA",P18/V18),"NA") -> 13.835716 | AD18: https://www.thebell.co.kr/free/content/ArticleView.asp?key=201711160100031120001918&lcode=00 | AE18: =IFERROR(IF(M18/X18<0,"NA",M18/X18),"NA") -> 22.239133 | AF18: =IFERROR(IF(M18/Y18<0,"NA",M18/Y18),"NA") -> 2.9686205
C19: 코엔텍 | D19: 2017.04 | F19: 폐기물 처리업 | G19: 맥쿼리 | H19: 후성HDS 외 | I19: 한국 | J19: KRW m | K19: 79500 | L19: 0.3363 | M19: =K19/L19 -> 236396.07 | N19: =코엔텍!B4 -> -13359.281 | O19: =코엔텍!C4 -> 3123.8873 | P19: =M19+N19-O19 -> 219912.91 | Q19: FY2016 | R19: =코엔텍!F4 -> 110624.03 | S19: =코엔텍!G4 -> 55095.779 | T19: =코엔텍!H4 -> 22232.954 | U19: =코엔텍!I4 -> 15475.622 | V19: =코엔텍!J4 -> 14719.206 | W19: =IFERROR(IF(P19/R19<0,"NA",P19/R19),"NA") -> 1.9879306 | X19: =코엔텍!J4 -> 14719.206 | Y19: =코엔텍!F4 -> 110624.03 | Z19: =IFERROR(IF(P19/S19<0,"NA",P19/S19),"NA") -> 3.9914656 | AA19: =IFERROR(IF(P19/T19<0,"NA",P19/T19),"NA") -> 9.8913042 | AB19: =IFERROR(IF(P19/U19<0,"NA",P19/U19),"NA") -> 14.210279 | AC19: =IFERROR(IF(P19/V19<0,"NA",P19/V19),"NA") -> 14.940542 | AD19: https://www.mk.co.kr/news/stock/view/2017/11/740560/ | AE19: =IFERROR(IF(M19/X19<0,"NA",M19/X19),"NA") -> 16.060382 | AF19: =IFERROR(IF(M19/Y19<0,"NA",M19/Y19),"NA") -> 2.1369323
B21: Transaction Multiple_엘지히타치워터솔루션
K22: 거래정보 | Q22: 재무정보 | W22: Multiple | Z22: Multiple
D23: Announce | K23: 거래 | L23: 취득 | M23: Equity | N23: Net | P23: Enterprise | Q23: Fiscal | Z23: EV/ | AA23: EV/ | AB23: EV/
B24: Target | D24: Date | F24: 산업 | G24: Major Bidder | H24: Seller | I24: 국가 | J24: 단위 | K24: 가격 | L24: 지분율 | M24: Value | N24: Debt (*1) | O24: NOA (*2) | P24: Vaule | Q24: Year (*3) | R24: BV | S24: Sales | T24: EBITDA | U24: EBIT | V24: NI | W24: PBR | Z24: Sales | AA24: EBITDA | AB24: EBIT | AC24: PER | AD24: Source
B25: Tier 1 / EPC 국내
C26: 한국종합기술 | D26: 2017.09 | F26: 환경 및 플랜트 EPC | G26: 한국종합기술홀딩스 | H26: 한진중공업 홀딩스 | I26: 한국 | J26: KRW m | K26: 50663.565 | L26: 0.5201 | M26: =K26/L26 -> 97411.2 | N26: =한국종합기술!C6-한국종합기술!C3 -> 18639.086 | O26: =한국종합기술!C10 -> 63736.082 | P26: =M26+N26-O26 -> 52314.204 | Q26: FY2016 | R26: =한국종합기술!C17 -> 122403.97 | S26: =한국종합기술!G4 -> 199370.93 | T26: =한국종합기술!H4 -> 6305.6561 | U26: =한국종합기술!I4 -> 4236.7241 | V26: =한국종합기술!J4 -> 3063.3867 | W26: =IFERROR(IF(P26/R26<0,"NA",P26/R26),"NA") -> 0.42738977 | X26: =한국종합기술!J3 -> -7815.611 | Y26: =한국종합기술!D17 -> 114383.39 | Z26: =IFERROR(IF(P26/S26<0,"NA",P26/S26),"NA") -> 0.26239635 | AA26: =IFERROR(IF(P26/T26<0,"NA",P26/T26),"NA") -> 8.2963934 | AB26: =IFERROR(IF(P26/U26<0,"NA",P26/U26),"NA") -> 12.347796 | AC26: =IFERROR(IF(P26/V26<0,"NA",P26/V26),"NA") -> 17.077245 | AD26: http://dart.fss.or.kr/dsaf001/main.do?rcpNo=20171212800646 | AE26: =IFERROR(IF(M26/X26<0,"NA",M26/X26),"NA") -> NA | AF26: =IFERROR(IF(M26/Y26<0,"NA",M26/Y26),"NA") -> 0.85162015 | AG26: Majority, 우리사주조합
C27: 휴비스워터 | D27: 2014.10 | E27: -2014년 10월 KDB-JKL로부터 95.3% 지분인수(4.7% 우리사주조합, Implied EquityValue 1383억) -2019년 1월 TSK코퍼레이션 100% 자회사편입(Implied EquityValue 1188억) | F27: 수처리설비 제조 및 EPC | G27: 휴비스 | H27: JKL, KDB캐피탈 | I27: 한국 | J27: KRW m | K27: 131798.33 | L27: 0.9527 | M27: =K27/L27 -> 138341.91 | N27: ='휴비스워터_''14'!C6-'휴비스워터_''14'!C3 -> -22440.338 | O27: ='휴비스워터_''14'!C10 -> 935.12711 | P27: =M27+N27-O27 -> 114966.44 | Q27: FY2013 | R27: ='휴비스워터_''14'!C16 -> 65687.151 | S27: ='휴비스워터_''14'!G4 -> 105760.54 | T27: ='휴비스워터_''14'!H4 -> 12413.841 | U27: ='휴비스워터_''14'!I4 -> 10841.688 | V27: ='휴비스워터_''14'!J4 -> 8364.5223 | W27: =IFERROR(IF(P27/R27<0,"NA",P27/R27),"NA") -> 1.750212 | X27: ='휴비스워터_''18'!J5 -> 959.72901 | Y27: ='휴비스워터_''18'!C17 -> 67363.364 | Z27: =IFERROR(IF(P27/S27<0,"NA",P27/S27),"NA") -> 1.0870447 | AA27: =IFERROR(IF(P27/T27<0,"NA",P27/T27),"NA") -> 9.2611499 | AB27: =IFERROR(IF(P27/U27<0,"NA",P27/U27),"NA") -> 10.604109 | AC27: =IFERROR(IF(P27/V27<0,"NA",P27/V27),"NA") -> 13.744532 | AD27: http://dart.fss.or.kr/dsaf001/main.do?rcpNo=20141124000274 | AE27: =IFERROR(IF(M27/X27<0,"NA",M27/X27),"NA") -> 144.14684 | AF27: =IFERROR(IF(M27/Y27<0,"NA",M27/Y27),"NA") -> 2.0536668 | AG27: Majority
B28: Tier 2 / EPC 해외
C29: Trility | D29: 2017.09 | F29: 수처리설비 제조 및 EPC | G29: Beijing Enterprises Water | H29: Mitsubishi, JGC | I29: 호주 | J29: USD m | K29: =MergerMarket!S10 -> 200 | L29: 1 | M29: =K29/L29 -> 200 | N29: 0 | O29: 0 | P29: =M29+N29-O29 -> 200 | Q29: FY2017 | S29: =MergerMarket!O10 -> 63.1394 | T29: =MergerMarket!P10 -> 21.342 | U29: =MergerMarket!Q10 -> 12.9031 | W29: =IFERROR(IF(P29/R29<0,"NA",P29/R29),"NA") -> NA | Z29: =IFERROR(IF(P29/S29<0,"NA",P29/S29),"NA") -> 3.1675942 | AA29: =IFERROR(IF(P29/T29<0,"NA",P29/T29),"NA") -> 9.371193 | AB29: =IFERROR(IF(P29/U29<0,"NA",P29/U29),"NA") -> 15.500151 | AC29: =IFERROR(IF(P29/V29<0,"NA",P29/V29),"NA") -> NA | AD29: https://www.afr.com/street-talk/beijing-enterprises-water-buys-trility-group-20170913-gygb36 | AG29: Majority
C30: Suez Water Technologies & Solutions | D30: 2017.03 | F30: 수처리설비 제조 및 EPC | G30: Suez | H30: General Electric | I30: 미국 | J30: USD m | K30: =MergerMarket!S5 -> 3379 | L30: 1 | M30: =K30/L30 -> 3379 | N30: 0 | O30: 0 | P30: =M30+N30-O30 -> 3379 | Q30: FY2016 | S30: =MergerMarket!O5 -> 2091.7226 | T30: =MergerMarket!P5 -> 340.1537 | U30: =MergerMarket!Q5 -> 0 | W30: =IFERROR(IF(P30/R30<0,"NA",P30/R30),"NA") -> NA | Z30: =IFERROR(IF(P30/S30<0,"NA",P30/S30),"NA") -> 1.615415 | AA30: =IFERROR(IF(P30/T30<0,"NA",P30/T30),"NA") -> 9.9337447 | AB30: =IFERROR(IF(P30/U30<0,"NA",P30/U30),"NA") -> NA | AC30: =IFERROR(IF(P30/V30<0,"NA",P30/V30),"NA") -> NA | AD30: https://www.suez.com/en/news/press-releases/suez-finalizes-the-acquisition-of-ge-water-and-process-technologies | AG30: Spin-off
B32: Note | T32: 하이엔텍 평균값
B33: (*1) Net Debt = 현금및현금성자산 + 단기금융상품 - 장단기차입금 및 사채 | T33: 구분 | Z33: EV/Sales | AA33: EV/EBITDA | AB33: EV/EBIT
B34: (*2) NOA = 투자부동산 + 장기금융상품 + 대여금 + 매도/만기보유증권 + 관계기업투자주식 | T34: Tier 1 only | Z34: =AVERAGE(Z7:Z8) -> 0.87253443 | AA34: =AVERAGE(AA7:AA8) -> 6.8843036 | AB34: =AVERAGE(AB7:AB8) -> 10.278302
B35: (*3) Fiscal Year는 Announce date 기준의 직전 회계연도임. | T35: Tier 2 only | Z35: =AVERAGE(Z10:Z13) -> 5.6795252 | AA35: =AVERAGE(AA10:AA13) -> 12.954388 | AB35: =AVERAGE(AB10:AB13) -> 23.79115
T36: Tier 1/2 | Z36: =AVERAGE(Z7:Z8,Z10:Z13) -> 4.0771949 | AA36: =AVERAGE(AA7:AA8,AA10:AA13) -> 10.931027 | AB36: =AVERAGE(AB7:AB8,AB10:AB13) -> 19.286867
T37: Tier 1/3 | Z37: =AVERAGE(Z7:Z8,Z15:Z19) -> 3.7422553 | AA37: =AVERAGE(AA7:AA8,AA15:AA19) -> 11.467881 | AB37: =AVERAGE(AB7:AB8,AB15:AB19) -> 19.53467
T38: Tier 1/2/3 | Z38: =AVERAGE(Z7:Z8,Z10:Z13,Z15:Z19) -> 4.4467171 | AA38: =AVERAGE(AA7:AA8,AA10:AA13,AA15:AA19) -> 12.008429 | AB38: =AVERAGE(AB7:AB8,AB10:AB13,AB15:AB19) -> 21.082481
T40: 엘지히타치워터솔루션 평균값
T41: 구분 | Z41: EV/Sales | AA41: EV/EBITDA | AB41: EV/EBIT
T42: Tier 1 only | Z42: =AVERAGE(Z26:Z27) -> 0.67472053 | AA42: =AVERAGE(AA26:AA27) -> 8.7787717 | AB42: =AVERAGE(AB26:AB27) -> 11.475952
T43: Tier 2 only | Z43: =AVERAGE(Z29:Z30) -> 2.3915046 | AA43: =AVERAGE(AA29:AA30) -> 9.6524688 | AB43: =AVERAGE(AB29:AB30) -> 15.500151
T44: Tier 1/2 | Z44: =AVERAGE(Z26:Z27,Z29:Z30) -> 1.5331126 | AA44: =AVERAGE(AA26:AA27,AA29:AA30) -> 9.2156202 | AB44: =AVERAGE(AB26:AB27,AB29:AB30) -> 12.817352

Sheet Affinity
B2: 구분 | C2: Sales | D2: EBITDA | E2: EBIT | F2: NI | G2: D&A | K2: BS | L2: FY2011 | M2: FY2016
B3: FY2016 | C3: =I24 -> 432128.35 | D3: =I81 -> 183777.26 | E3: =I83 -> 112764.8 | F3: =I54 -> 43261.555 | G3: =D3-E3 -> 71012.454 | K3: Cash | L3: =SUM(L4:L5) -> 1291.5522 | M3: =SUM(M4:M5) -> 63180.826
B4: FY2011 | C4: =D24 -> 458365.16 | D4: =D81 -> 252387.04 | E4: =D83 -> 116757.76 | F4: =D54 -> 65010.54 | G4: =D4-E4 -> 135629.28 | K4: 현금및현금성자산 | L4: =M24 -> 1291.5522 | M4: =R24 -> 63180.826
K5: 단기금융상품
K6: Debt | L6: =SUM(L7:L9) -> 841410.91 | M6: =SUM(M7:M9) -> 1318003.9
K7: 단기차입금 | L7: =M48+M49 -> 84876.533 | M7: 0
K8: 장기차입금 | L8: =M56 -> 756534.37 | M8: =R56 -> 1318003.9
K9: 사채
K10: NOA | L10: =SUM(L11:L15) -> 90.57168 | M10: =SUM(M11:M15) -> 84.000301
K11: 장기금융상품 | L11: =M41 -> 90.57168 | M11: =R41 -> 84.000301
K12: 투자부동산
K13: 관계기업투자
K14: 매도가능증권
K15: 장단기대여금
K16: BV | L16: =M71 -> 635749.79 | M16: =R71 -> 303404.89
B18: Source : Capital IQ
B20: Income Statement | K20: Balance Sheet
B21: For the Fiscal Period Ending | C21: 12 months Mar-31-2011 | D21: 12 months Mar-31-2012 | E21: 12 months Mar-31-2013 | F21: 12 months Mar-31-2014 | G21: Restated 12 months Mar-31-2015 | H21: 12 months Mar-31-2016 | I21: 12 months Mar-31-2017 | K21: Balance Sheet as of: | L21: 40633 | M21: 40999 | N21: 41364 | O21: Restated Mar-31-2014 | P21: Restated Mar-31-2015 | Q21: 42460 | R21: 42825
B22: Currency | C22: KRW | D22: KRW | E22: KRW | F22: KRW | G22: KRW | H22: KRW | I22: KRW | K22: Currency | L22: KRW | M22: KRW | N22: KRW | O22: KRW | P22: KRW | Q22: KRW | R22: KRW
K23: ASSETS
B24: Revenue | C24: 421379.47 | D24: 458365.16 | E24: 472141.56 | F24: 516015.62 | G24: 487466.67 | H24: 495449.27 | I24: 432128.35 | K24: Cash And Equivalents | L24: 2530.2426 | M24: 1291.5522 | N24: 60445.892 | O24: 29797.684 | P24: 97000.823 | Q24: 152985.45 | R24: 63180.826
B25: Other Revenue | C25: - | D25: - | E25: - | F25: - | G25: - | H25: - | I25: -
B26: Total Revenue | C26: 421379.47 | D26: 458365.16 | E26: 472141.56 | F26: 516015.62 | G26: 487466.67 | H26: 495449.27 | I26: 432128.35 | K26: Accounts Receivable | L26: 80016.505 | M26: 92294.353 | N26: 115490.7 | O26: 127820.48 | P26: 117377.78 | Q26: 115598.61 | R26: 102009.96
K27: Other Receivables | L27: 10968.488 | M27: 12154.719 | N27: 11244.804 | O27: 6212.4256 | P27: 6212.3457 | Q27: 5694.1417 | R27: 14736.453
B28: Fuel & Purchased Power | C28: - | D28: - | E28: - | F28: - | G28: - | H28: - | I28: - | K28: Accounts Receivable, Total | L28: 90984.993 | M28: 104449.07 | N28: 126735.5 | O28: 134032.91 | P28: 123590.12 | Q28: 121292.75 | R28: 116746.42
B29: Ops. and Maintenance | C29: - | D29: - | E29: - | F29: - | G29: - | H29: - | I29: -
B30: Selling General & Admin Exp. | C30: 70700.852 | D30: 74015.177 | E30: 65566.535 | F30: 69346.113 | G30: 75206.584 | H30: 86708.779 | I30: 76115.472 | K30: Inventory | L30: 1496.3422 | M30: 1724.4848 | N30: 2662.5318 | O30: 2500.5544 | P30: 2077.3663 | Q30: 2000.6444 | R30: 2002.0072
B31: Depreciation & Amort. | C31: - | D31: - | E31: - | F31: - | G31: - | H31: - | I31: - | K31: Prepaid Exp. | L31: 4038.8932 | M31: 4436.2009 | N31: 4547.9287 | O31: 9773.7677 | P31: 9040.3292 | Q31: 9520.2513 | R31: 8808.8315
B32: Other Operating Exp. | C32: 260783.79 | D32: 267592.22 | E32: 275950.47 | F32: 296014.64 | G32: 251122.63 | H32: 271344.35 | I32: 243248.07 | K32: Other Current Assets | L32: - | M32: 3798.5763 | N32: - | O32: - | P32: - | Q32: - | R32: -
B33: Total Operating Exp. | C33: 331484.64 | D33: 341607.39 | E33: 341517.01 | F33: 365360.76 | G33: 326329.22 | H33: 358053.13 | I33: 319363.54 | K33: Total Current Assets | L33: 99050.471 | M33: 115699.89 | N33: 194391.85 | O33: 176104.91 | P33: 231708.64 | Q33: 285799.09 | R33: 190738.08
B35: Operating Income | C35: 89894.826 | D35: 116757.76 | E35: 130624.55 | F35: 150654.86 | G35: 161137.45 | H35: 137396.14 | I35: 112764.8 | K35: Gross Property, Plant & Equipment | L35: 2993101.2 | M35: 3191887.3 | N35: 3579633.8 | O35: 3937811.9 | P35: 2842538.3 | Q35: 2942510.8 | R35: 2672198
K36: Accumulated Depreciation | L36: -1386252.9 | M36: -1549743 | N36: -1572905.9 | O36: -1791509.1 | P36: -809769.5 | Q36: -880427.6 | R36: -823082.5
B37: Interest Expense, Total | C37: -33633.4 | D37: -34618.3 | E37: -40015.7 | F37: -71019.6 | G37: -62223.9 | H37: -63328.1 | I37: -62471 | K37: Net Property, Plant & Equipment | L37: 1606848.3 | M37: 1642144.3 | N37: 2006727.9 | O37: 2146302.7 | P37: 2032768.7 | Q37: 2062083.2 | R37: 1849115.4
B38: Interest and Invest. Income | C38: 226.82509 | D38: 219.18347 | E38: 20.273085 | F38: 610.97116 | G38: 274.89712 | H38: 638.50353 | I38: 410.20147
B39: Net Interest Exp. | C39: -33406.6 | D39: -34399.1 | E39: -39995.4 | F39: -70408.7 | G39: -61949 | H39: -62689.6 | I39: -62060.8 | K39: Goodwill | L39: 11742.154 | M39: 12096.754 | N39: 26055.982 | O39: 26494.897 | P39: 24627.16 | Q39: 24493.978 | R39: 20945.475
K40: Other Intangibles | L40: - | M40: - | N40: - | O40: - | P40: 37190.123 | Q40: 46943.107 | R40: 51419.384
B41: Other Non-Operating Inc. (Exp.) | C41: -1306.4 | D41: -1686.4 | E41: -1623.5 | F41: -1926.8 | G41: - | H41: - | I41: - | K41: Long-term Investments | L41: 87.9167 | M41: 90.57168 | N41: 103.05485 | O41: 108.02679 | P41: 98.765432 | Q41: 98.231312 | R41: 84.000301
B42: EBT Excl. Unusual Items | C42: 55181.796 | D42: 80672.195 | E42: 89005.6 | F42: 78319.42 | G42: 99188.477 | H42: 74706.55 | I42: 50703.981 | K42: Other Long-Term Assets | L42: - | M42: - | N42: - | O42: - | P42: 74235.391 | Q42: 118840.24 | R42: 102196.17
K43: Total Assets | L43: 1717728.8 | M43: 1770031.5 | N43: 2227278.8 | O43: 2349010.6 | P43: 2400628.8 | Q43: 2538257.8 | R43: 2214498.5
B44: Impairment of Goodwill | C44: - | D44: - | E44: - | F44: - | G44: - | H44: - | I44: -
...

Sheet 휴비스워터-TSK
B3: TSK코퍼레이션-휴비스워터 주식교환 | G3: 과거 거래
B4: 주, 백만원 | C4: 주식수 | D4: Implied Equity Value | I4: 거래 | J4: 취득 | K4: Equity
B5: 거래전 지분가치 | I5: 가격 | J5: 지분율 | K5: Value
B6: TSK코퍼레이션 | C6: 800000 | D6: =K17 -> 500000 | G6: (1)TSK코퍼레이션 | H6: 2018.06 | I6: =Transaction!K8 -> 124999.38 | J6: =Transaction!L8 -> 0.24999876 | K6: =Transaction!M8 -> 500000
B7: 휴비스워터 | C7: 8775440 | D7: 98973 | E7: >>역산 | G7: (2)휴비스워터 | H7: 2014.10 | I7: =Transaction!K27 -> 131798.33 | J7: =Transaction!L27 -> 0.9527 | K7: =Transaction!M27 -> 138341.91
B8: 합병시너지 | D8: =K22-D6-D7 -> 119794.44 | G8: (3)TSK-휴비스워터 주식교환 | H8: 2018.11 | I8: =118767698990/10^6 -> 118767.7 | J8: 1 | K8: =J8*I8 -> 118767.7
B9: TSK코퍼레이션 | D9: =$D$8*D6/($D$6+$D$7) -> 99999.868
B10: 휴비스워터 | D10: =$D$8*D7/($D$6+$D$7) -> 19794.574
B11: 시너지 배분 후 가격 | D11: =SUM(D12:D13) -> 718767.44
B12: TSK코퍼레이션 | D12: =D6+D9 -> 599999.87
B13: 휴비스워터 | D13: =D7+D10 -> 118767.57
G16: (1)주식교환 이후 | I16: 주식수 | J16: 지분율 | K16: 지분가치
G17: TSK코퍼레이션 | I17: 800000 | J17: =I17/$I$17 -> 1 | K17: =K6 -> 500000
G18: 태영건설 | I18: =I23 -> 600000 | J18: =I18/$I$17 -> 0.75 | K18: =$K$6*J18 -> 375000
G19: SK디스커버리 | I19: =I24 -> 159999 | J19: =I19/$I$17 -> 0.19999875 | K19: =$K$6*J19 -> 99999.375
G20: SK건설 | I20: =I25 -> 40001 | J20: =I20/$I$17 -> 0.05000125 | K20: =$K$6*J20 -> 25000.625
G21: (3)주식교환 이후
G22: TSK코퍼레이션 | I22: 958357 | J22: =I22/$I$22 -> 1 | K22: =I8*I22/158357 -> 718767.44
D23: =I8-D13 -> 0.12521427 | G23: 태영건설 | I23: 600000 | J23: =I23/$I$22 -> 0.6260715 | K23: =K22*I23/$I$22 -> 449999.81
G24: SK디스커버리 | I24: 159999 | J24: =I24/$I$22 -> 0.16695136 | K24: =K23*I24/$I$22 -> 75128.078
G25: SK건설 | I25: 40001 | J25: =I25/$I$22 -> 0.041739143 | K25: =K24*I25/$I$22 -> 3135.7816
G26: 휴비스 | I26: 158357 | J26: =I26/$I$22 -> 0.16523801 | K26: =K25*I26/$I$22 -> 518.1503

Sheet 유사거래 FS>

Sheet 환경관리
B2: Net | D2: Enterprise | E2: Fiscal | N2: Source : Dart
B3: Debt | C3: NOA | D3: Vaule | E3: Year | F3: BV | G3: Salse | H3: EBITDA | I3: EBIT | J3: NI
B4: =C14 -> -8095.1262 | C4: =C17 -> 50887.301 | E4: 2015 | F4: =O48/10^6 -> 87577.76 | G4: =C30 -> 226423.01 | H4: =C34 -> 12333.079 | I4: =C33 -> 8938.5028 | J4: =O79/10^6 -> 7474.1583 | N4: 연 결 재 무 상 태 표 | R4: 연 결 현 금 흐 름 표 | V4: 7. 사용이 제한된 예금
B5: =D14 -> -19879.392 | C5: =D17 -> 40757.898 | E5: 2016 | F5: =P48/10^6 -> 94568.671 | G5: =D30 -> 210609.73 | H5: =D34 -> 10217.156 | I5: =D33 -> 7766.0377 | J5: =P79/10^6 -> 7090.1836 | N5: 환경관리주식회사와 그 종속기업(구, 코오롱워터앤에너지 주식회사와 그 종속기업) | P5: (단위 : 원) | R5: 환경관리주식회사와 그 종속기업(구, 코오롱워터앤에너지 주식회사와 그 종속기업) | T5: (단위 : 원) | V5: 당기말과 전기말 현재 사용이 제한된 예금은 다음과 같습니다.
N6: 과 목 | O6: 2015 | P6: 2016 | R6: 과 목 | S6: 2015 | T6: 2016 | V6: (단위:천원)
N7: 자 산 | R7: Ⅰ. 영업활동으로 인한 순현금흐름 | S7: 1923153634 | T7: 1069370482 | V7: 계정과목 | W7: 전기말 | X7: 당기말 | Y7: 사용제한내용
N8: Ⅰ. 유동자산 | O8: 65534271872 | P8: 62715628803 | R8: (1) 당기순이익 | S8: 7474158340 | T8: 7090183637 | V8: 현금및현금성자산 | W8: 318991 | X8: - | Y8: 프로젝트금융 질권설정
C9: 2015년 | D9: 2016년 | N9: 현금및현금성자산(주6,7,17,31,38) | O9: 21240657688 | P9: 25561149435 | R9: (2) 조정 | S9: 14506139728 | T9: 8938936726 | V9: 단기금융상품 | W9: 4884358 | X9: 5631078 | Y9: 대수선비적립금
B10: 백만원 | C10: 12월31일 | D10: 12월31일 | N10: 매출채권(주8,31,33,38) | O10: 19544584936 | P10: 15364315189 | R10: 외화환산손실 | S10: 88304682 | T10: 26885568 | W10: 576916 | X10: 1031264 | Y10: 프로젝트금융 질권설정
B11: 차입금 | C11: =(O30+O35)/10^6 -> 18606.806 | D11: =(P30+P35)/10^6 -> 12344.1 | N11: 기타수취채권(주9,32,34,34,38) | O11: 10646061132 | P11: 4574905199 | R11: 대손상각비(환입) | S11: -130298185 | T11: 30992391 | V11: 장기금융상품 | W11: 2000 | X11: 2000 | Y11: 당좌개설보증금
B12: 현금및현금성자산 | C12: =O9/10^6 -> 21240.658 | D12: =P9/10^6 -> 25561.149 | N12: 기타유동자산(주10) | O12: 7281040412 | P12: 9642337741 | R12: 기타의대손상각비 | S12: 1065778356 | T12: 4224442 | V12: 합 계 | W12: 5782265 | X12: 6664342
B13: 단기금융상품 | C13: =O13/10^6 -> 5461.2745 | D13: =P13/10^6 -> 6662.3422 | N13: 단기금융자산(주7,11,31,38) | O13: 5461274468 | P13: 6662342199 | R13: 감가상각비 | S13: 1726835306 | T13: 1056027008
B14: Net Debt | C14: =-SUM(C12:C13)+C11+C15 -> -8095.1262 | D14: =-SUM(D12:D13)+D11+D15 -> -19879.392 | N14: 재고자산(주12) | O14: 1360653236 | P14: 910579040 | R14: 운휴자산상각비 | S14: 29362895 | T14: 23003312
N15: Ⅱ. 비유동자산 | O15: 85830871652 | P15: 74304106502 | R15: 유형자산처분손실 | S15: 32439929 | T15: 17507637
N16: 매출채권(주8,31,33,38) | O16: - | P16: 66168923 | R16: 투자부동산감가상각비 | S16: 45446037 | T16: 32213070 | V16: 9. 기타수취채권
B17: NOA | C17: =SUM(C18:C22) -> 50887.301 | D17: =SUM(D18:D22) -> 40757.898 | N17: 장기금융자산(주7,13,31,38) | O17: 15175561796 | P17: 13645537600 | R17: 매도가능금융자산처분손실 | S17: 16514114 | T17: - | V17: 당기말과 전기말 현재 기타수취채권의 내역은 다음과 같습니다.
B18: 장기금융상품 | C18: =W48/10^3 -> 2 | D18: =X48/10^3 -> 2 | N18: 관계기업투자(주14) | O18: 20011786352 | P18: 21492107897 | R18: 무형자산상각비 | S18: 1667741160 | T18: 1395091290 | V18: (단위:천원)
B19: 투자부동산 | C19: =O19/10^6 -> 5655.4686 | D19: =P19/10^6 -> 5600.2522 | N19: 투자부동산(주15) | O19: 5655468629 | P19: 5600252247 | R19: 무형자산손상차손 | S19: - | T19: 1162338997 | V19: 구 분 | W19: 전기말 | Y19: 당기말
B20: 관계기업투자 | C20: =O18/10^6 -> 20011.786 | D20: =P18/10^6 -> 21492.108 | N20: 유형자산(주16,17) | O20: 9035480404 | P20: 2628029379 | R20: 무형자산처분손실 | S20: - | T20: 439866526 | W20: 유동 | X20: 비유동 | Y20: 유동 | Z20: 비유동
B21: 매도가능증권 | C21: =O17/10^6-C18 -> 15173.562 | D21: =P17/10^6-D18 -> 13643.538 | N21: 영업권및무형자산(주17,18) | O21: 18795663701 | P21: 24993868951 | R21: 영업권손상차손 | S21: 446578757 | T21: - | V21: 미수금 | W21: 9978385 | X21: - | Y21: 3627563 | Z21: 1830920
B22: 장단기대여금 | C22: =SUM(W25,X29)/10^3 -> 10044.484 | D22: =SUM(Y25,Z29)/10^3 -> 20 | N22: 기타수취채권(주9,31,38) | O22: 15522770350 | P22: 5780403724 | R22: 법인세비용 | S22: 4259215432 | T22: 1987442857 | V22: 대손충당금 | W22: -933323 | X22: - | Y22: -49040 | Z22: -728433
N23: 이연법인세자산(주36) | O23: 1634140420 | P23: 97737781 | R23: 퇴직급여 | S23: 7657508463 | T23: 5106958599 | V23: 현재가치할인차금 | W23: - | X23: - | Y23: - | Z23: -123719
N24: 자 산 총 계 | O24: 151365143524 | P24: 137019735305 | R24: 이자비용 | S24: 1389476004 | T24: 539571253 | V24: 미수수익 | W24: 189583 | X24: - | Y24: 73601 | Z24: -
N25: 부 채 | R25: 하자보수충당부채전입액 | S25: 176718651 | T25: 123985063 | V25: 단기대여금 | W25: 44500 | X25: - | Y25: 20000 | Z25: -
N26: Ⅰ. 유동부채 | O26: 46220512180 | P26: 23575921173 | R26: 공사손실충당부채전입액 | S26: 1235508429 | T26: 231013621 | V26: 미청구공사 | W26: 1364715 | X26: - | Y26: 769739 | Z26: -
N27: 매입채무(주31,33,38) | O27: 8745162202 | P27: 6132163585 | R27: 외화환산이익 | S27: -115653664 | T27: -11711851 | V27: 미수법인세환급액 | W27: 2201 | X27: - | Y27: 133042 | Z27: -
C28: 2015년 | D28: 2016년 | N28: 기타지급채무(주20,31,33,38) | O28: 16900634711 | P28: 10545482601 | R28: 이자수익 | S28: -416108154 | T28: -836120505 | V28: 보증금 | W28: - | X28: 5522786 | Y28: - | Z28: 4801636
B29: 백만원 | C29: 12개월 | D29: 12개월 | N29: 기타부채(주21,34) | O29: 10312009349 | P29: 6201344987 | R29: 유형자산처분이익 | S29: -105113805 | T29: -121262530 | V29: 장기대여금 | W29: - | X29: 9999984 | Y29: - | Z29: -
B30: 매출액 | C30: =O56/10^6 -> 226423.01 | D30: =P56/10^6 -> 210609.73 | N30: 단기금융부채(주22,31,35,38) | O30: 10262705918 | P30: 696930000 | R30: 투자부동산처분이익 | S30: -249281209 | T30: - | V30: 합 계 | W30: 10646061 | X30: 15522770 | Y30: 4574905 | Z30: 5780404
B31: 매출총이익 | C31: =O66/10^6 -> 25824.019 | D31: =P66/10^6 -> 24618.764 | N31: Ⅱ. 비유동부채 | O31: 17566871442 | P31: 18875143107 | R31: 지분법이익 | S31: -2917064288 | T31: -2214167874
B32: 판관비 | C32: =O67/10^6 -> 16885.516 | D32: =P67/10^6 -> 16852.727 | N32: 매입채무(주31,33,38) | O32: - | P32: 2149062956 | R32: 매도가능금융자산처분이익 | S32: -488861255 | T32: -
B33: 영업이익 | C33: =O68/10^6 -> 8938.5028 | D33: =P68/10^6 -> 7766.0377 | N33: 순확정급여부채(주23) | O33: 3626954249 | P33: 387725644 | R33: 염가매수차익 | S33: -205363520 | T33: - | V33: 11. 단기금융자산
B34: EBITDA | C34: =C33+C36 -> 12333.079 | D34: =D33+D36 -> 10217.156 | N34: 기타지급채무(주20,31,33,38) | O34: 1721878935 | P34: 2338596097 | R34: 하자보수충당부채환입 | S34: -298437407 | T34: - | V34: 당기말과 전기말 현재 단기금융자산의 내역은 다음과 같습니다.
N35: 장기금융부채(주22,31,35,38) | O35: 8344100000 | P35: 11647170000 | R35: 배당금수익 | S35: -405107000 | T35: -54922148 | V35: (단위:천원)
B36: D&A | C36: =SUM(S13,S18)/10^6 -> 3394.5765 | D36: =SUM(T13,T18)/10^6 -> 2451.1183 | N36: 기타부채(주21,35) | O36: 1786051947 | P36: 1019498028 | R36: (3) 운전자본의 변동 | S36: -15350335333 | T36: -12474744155 | V36: 구 분 | W36: 내역 | X36: 전기말 | Y36: 당기말
N37: 충당부채(주24,35) | O37: 633935886 | P37: 702531158 | R37: 정부보조금의 증가(감소) | S37: -326104439 | T37: -595233454 | V37: 단기금융상품 | W37: 정기적금 | X37: 742000 | Y37: 213600
N38: 이연법인세부채(주36) | O38: 1453950425 | P38: 630559224 | R38: 매출채권의 감소(증가) | S38: 14033249866 | T38: 4922959334 | W38: 정기예금 | X38: 4719274 | Y38: 6448742
N39: 부 채 총 계 | O39: 63787383622 | P39: 42451064280 | R39: 미수금의 감소(증가) | S39: 2394949075 | T39: 4730379154 | V39: 합 계 | X39: 5461274 | Y39: 6662342
N40: 자 본 | R40: 미청구공사의 감소(증가) | S40: -9472925632 | T40: 594975144
N41: Ⅰ. 지배기업소유주지분 | O41: 86093788786 | P41: 93091855726 | R41: 선급금의 감소(증가) | S41: -632589878 | T41: -1658201187
...

Sheet 티에스케이코퍼레이션
B2: Net | D2: Enterprise | E2: Fiscal | N2: Source : Dart
B3: Debt | C3: NOA | D3: Vaule | E3: Year | F3: BV | G3: Salse | H3: EBITDA | I3: EBIT | J3: NI
B4: =C13 -> 117925.29 | C4: =SUM(C17:C21) -> 34040.969 | E4: FY2017 | F4: =P55/10^6 -> 180145.67 | G4: =C29 -> 421868.93 | H4: =C33 -> 81770.619 | I4: =C32 -> 51166.931 | J4: =U20/10^6 -> 34617.831 | N4: 연결 재무상태표 | S4: 연 결 포 괄 손 익 계 산 서 | X4: 6. 사용이 제한되어 있거나 담보로 제공된 금융자산
B5: =D13 -> 48381.328 | C5: =SUM(D17:D21) -> 22468.547 | E5: FY2018 | F5: =Q55/10^6 -> 209037.43 | G5: =D29 -> 504407.15 | H5: =D33 -> 113382.4 | I5: =D32 -> 83868.907 | J5: =V20/10^6 -> 31015.337 | N5: 주식회사 티에스케이코퍼레이션과 그외 종속기업 | S5: 주식회사 티에스케이코퍼레이션과 그외 종속기업
O6: (단위: 원) | T6: (단위: 원) | X6: 당기말 및 전기말 현재 사용이 제한되어 있거나 부채나 우발부채에 대한 담보로 제공된 금융자산의 내역은 다음과 같습니다. | AG6: 1) 당기말 및 전기말 현재 매출채권 및 기타채권의 내역은 다음과 같습니다.
N7: 과 목 | O7: 주석 | P7: 2017 | Q7: 2018 | S7: 과 목 | T7: 주석 | U7: 2017 | V7: 2018 | X7: (단위 : 천원) | AG7: (단위 : 천원)
C8: 2017년 | D8: 2018년 | N8: 자 산 | S8: I. 매출액 | T8: 4,27,37 | U8: 421868931793 | V8: 504407145313 | X8: 구 분 | Y8: 거래처 | Z8: 2017 | AA8: 2018 | AB8: 제한내용 | AG8: 구 분 | AH8: 당기말 | AJ8: 전기말
B9: 백만원 | C9: 12월31일 | D9: 12월31일 | N9: I. 유동자산 | P9: 124194152060 | Q9: 169099918165 | S9: II. 매출원가 | T9: 28 | U9: -344104363460 | V9: -389532097445 | X9: 보통예금 | Y9: 산업은행 | Z9: 5018198 | AA9: 5209987 | AB9: 질권설정 | AH9: 유동 | AI9: 비유동 | AJ9: 유동 | AK9: 비유동
B10: 차입금 | C10: =(P37+P38+P43)/1000000 -> 178156.23 | D10: =(Q37+Q38+Q43)/1000000 -> 129223.68 | N10: 현금및현금성자산 | O10: 5,6,36,37 | P10: 47409986738 | Q10: 49901946228 | S10: III. 매출총이익 | U10: 77764568333 | V10: 114875047868 | Y10: 기업은행 | Z10: - | AA10: 108621 | AB10: 질권설정 | AG10: 매출채권 | AH10: 58178470 | AI10: 3162924 | AJ10: 45385177 | AK10: 3528510
B11: 현금및현금성자산 | C11: =(P10)/1000000 -> 47409.987 | D11: =(Q10)/1000000 -> 49901.946 | N11: 기타유동금융자산 | O11: 6,11,36 | P11: 12820957644 | Q11: 30940409433 | S11: 판매비와관리비 | T11: 28 | U11: -26597637227 | V11: -31006140620 | Y11: KEB하나은행 | Z11: 6299793 | AA11: - | AB11: 질권설정 | AG11: (현재가치할인차금) | AH11: - | AI11: -533859 | AJ11: -6745 | AK11: -649463
B12: 단기금융상품 | C12: =P11/10^6 -> 12820.958 | D12: =Q11/10^6 -> 30940.409 | N12: 매출채권및기타채권 | O12: 7,36 | P12: 54846834052 | Q12: 72802261449 | S12: IV. 영업이익 | U12: 51166931106 | V12: 83868907248 | Z12: 188804 | AA12: - | AB12: Escrow | AG12: (대손충당금) | AH12: -1616449 | AI12: - | AJ12: -2832043 | AK12: -
B13: Net Debt | C13: =C10-C11-C12+C14 -> 117925.29 | D13: =D10-D11-D12+D14 -> 48381.328 | N13: 유동성만기보유금융자산 | O13: 10,36 | P13: 1328145000 | Q13: - | S13: 금융수익 | T13: 29 | U13: 1201367544 | V13: 1516428042 | X13: 단기금융상품 | Y13: 우리은행 | Z13: 859017 | AA13: - | AB13: 김포BTO 대수선비 적립 공동명의 계좌 | AG13: 미수금 | AH13: 17004457 | AI13: - | AJ13: 12127149 | AK13: -
N14: 유동상각후원가측정금융자산 | O14: 10,36 | P14: - | Q14: 1366675000 | S14: 금융비용 | T14: 30 | U14: -7162028646 | V14: -6465775563 | Y14: KEB하나은행 | Z14: 967743 | AA14: - | AB14: KEB하나은행 장기차입금관련 질권설정 | AG14: (대손충당금) | AH14: -1191408 | AI14: - | AJ14: -244984 | AK14: -
N15: 재고자산 | O15: 12 | P15: 692026605 | Q15: 232030401 | S15: 기타영업외수익 | T15: 31 | U15: 2132416279 | V15: 477803891 | Z15: 6012623 | AA15: 6076782 | AB15: 동대문 대수선비 적립 계좌 | AG15: 미수수익 | AH15: 427191 | AI15: - | AJ15: 418280 | AK15: -
B16: NOA | N16: 미청구공사 | P16: 3126114439 | Q16: 6526338135 | S16: 기타영업외비용 | T16: 32 | U16: -3847275491 | V16: -10260149259 | Z16: 547678 | AA16: 596376 | AB16: 대천 대수선비 공동명의 계좌 | AG16: 대여금 | AH16: - | AI16: 2174054 | AJ16: - | AK16: 2373000
B17: 장기금융상품 | C17: =SUM(P25:P26)/10^6+P21/10^6+SUM(P13:P14)/10^6 -> 7203.725 | D17: =SUM(Q25:Q26)/10^6+Q21/10^6+SUM(Q13:Q14)/10^6 -> 7580.33 | N17: 기타유동자산 | O17: 13 | P17: 3953771794 | Q17: 7319153429 | S17: 관계기업투자손실 | T17: 33 | U17: -164220085 | V17: -14198394162 | Z17: 4697 | AA17: - | AB17: 선수금 질권설정 | AG17: 보증금 | AH17: - | AI17: 12971699 | AJ17: - | AK17: 8814485
B18: 투자부동산 | C18: 0 | D18: 0 | N18: 당기법인세자산 | P18: 16315788 | Q18: 11104090 | S18: V. 법인세차감전순이익 | U18: 43327190707 | V18: 54938820197 | Z18: 726330 | AA18: 762264 | AB18: 울산BTL1단계 대수선비 적립계좌 | AG18: 합 계 | AH18: 72802261 | AI18: 17774818 | AJ18: 54846834 | AK18: 14066532
B19: 관계기업투자 | C19: =P28/10^6 -> 17279.739 | D19: =Q28/10^6 -> 3083.1213 | N19: II. 비유동자산 | P19: 339040848740 | Q19: 306558237579 | S19: VI. 법인세비용 | T19: 34 | U19: -8709359988 | V19: -23923483476 | Z19: 291214 | AA19: 278613 | AB19: 울산BTL2단계 대수선비 적립계좌
B20: 매도가능증권 | C20: =SUM(P22:P24)/10^6 -> 7184.5053 | D20: =SUM(Q22:Q24)/10^6 -> 9631.0414 | N20: 매출채권및기타채권 | O20: 7,36,37 | P20: 14066532717 | Q20: 17774817980 | S20: VII. 연결당기순이익 | U20: 34617830719 | V20: 31015336721 | Y20: 신한은행 | Z20: 1907262 | AA20: - | AB20: 질권설정
B21: 장기대여금 | C21: =AK16/10^3 -> 2373 | D21: =AI16/10^3 -> 2174.054 | N21: 기타비유동금융자산 | O21: 11 | P21: 3900000 | Q21: 0 | S21: 지배기업소유지분 | U21: 33807014813 | V21: 27970498704 | Z21: - | AA21: 61619 | AB21: 선수금 질권설정
N22: 매도가능금융자산 | O22: 6,8,9,36 | P22: 7184505310 | Q22: - | S22: 비지배지분 | U22: 810815906 | V22: 3044838017 | Y22: 기업은행 | Z22: 1023805 | AA22: 1255444 | AB22: PF질권설정
N23: 비유동당기손익인식공정가치측정금융자산 | O23: 6,8,36 | P23: - | Q23: 9355382798 | S23: VIII. 기타포괄손익 | U23: -1572592158 | V23: -1814960120 | X23: 장기금융상품 | Y23: 산업은행 | Z23: 2000 | AA23: - | AB23: 당좌개설보증금
N24: 비유동기타포괄손익인식공정가치측정금융자산 | O24: 9,36 | P24: - | Q24: 275658580 | S24: 후속적으로 당기손익으로 재분류되지 않는 항목 | U24: -1572953173 | V24: -1814960120 | Y24: 부산은행 | Z24: 1900 | AA24: - | AB24: 당좌개설보증금
N25: 만기보유금융자산 | O25: 10,36 | P25: 5871680000 | Q25: - | S25: 확정급여제도의 재측정요소 | U25: -2016606632 | V25: -2327001588 | X25: 매도가능증권 | Y25: 전문건설공제조합 | Z25: 676712 | AA25: - | AB25: 융자약정한도 담보제공
N26: 비유동상각후원가측정금융자산 | O26: 10,36 | P26: - | Q26: 6213655000 | S26: 공정가치측정금융자산의 평가 | U26: - | V26: 101119 | X26: 당기손익인식공정가치측정금융자산 | Y26: 전문건설공제조합 | Z26: - | AA26: 678926 | AB26: 융자약정한도 담보제공
C27: 2017년 | D27: 2018년 | N27: 이연법인세자산 | O27: 34 | P27: 13494599063 | Q27: 11021338563 | S27: 법인세효과 | U27: 443653459 | V27: 511940349 | Y27: 엔지니어링공제조합 | Z27: - | AA27: 1767073 | AB27: 이행보증
B28: 백만원 | C28: 12개월 | D28: 12개월 | N28: 관계기업투자 | O28: 14 | P28: 17279739170 | Q28: 3083121254 | S28: 후속적으로 당기손익으로 재분류되는 항목 | U28: 361015 | V28: -
B29: 매출액 | C29: =(U8)/1000000 -> 421868.93 | D29: =(V8)/1000000 -> 504407.15 | N29: 유형자산 | O29: 15 | P29: 233264266819 | Q29: 221617025256 | S29: 매도가능증권평가이익 | U29: 361015 | V29: -
B30: 매출총이익 | C30: =(U10)/1000000 -> 77764.568 | D30: =(V10)/1000000 -> 114875.05 | N30: 무형자산 | O30: 16 | P30: 40487045676 | Q30: 30363441292 | S30: IX. 총포괄이익 | U30: 33045238561 | V30: 29200376601
B31: 판관비 | C31: =-(U11)/1000000 -> 26597.637 | D31: =-(V11)/1000000 -> 31006.141 | N31: 기타비유동자산 | O31: 13 | P31: 7388579985 | Q31: 6853796856 | S31: X. 연결총포괄이익의 귀속
B32: 영업이익 | C32: =(U12)/1000000 -> 51166.931 | D32: =(V12)/1000000 -> 83868.907 | N32: 자 산 총 계 | P32: 463235000800 | Q32: 475658155744 | S32: 지배기업 소유주지분 | U32: 32234422655 | V32: 26164613915
B33: EBITDA | C33: =C32+C35 -> 81770.619 | D33: =D32+D35 -> 113382.4 | N33: 부 채 | S33: 비지배지분 | U33: 810815906 | V33: 3035762686 | X33: 10. 상각후원가측정유가증권 및 만기보유금융자산
N34: I. 유동부채 | P34: 97750350959 | Q34: 133896828143 | S34: XI. 지배기업 소유주지분에 대한 주당이익 | AG34: 8. 당기손익-공정가치측정금융자산
B35: D&A | C35: =SUM(U48:U49)/10^3 -> 30603.688 | D35: =SUM(V48:V49)/10^3 -> 29513.492 | N35: 매입채무및기타채무 | O35: 17,36,37 | P35: 53321744101 | Q35: 68736228532 | S35: 기본 주당순이익 | T35: 35 | U35: 42259 | V35: 34963 | X35: (1) 당기말 현재 상각후원가측정유가증권 및 전기말 현재 만기보유금융자산의 내역은 다음과 같습니다.
N36: 초과청구공사 | P36: 2967927793 | Q36: 1986152544 | S36: 주석 참조 | X36: (단위: 천원) | AG36: 당기말 현재 당기손익-공정가치측정 금융자산의 내역은 다음과 같습니다.
N37: 단기차입금 | O37: 18,36,39 | P37: 10110000000 | Q37: 28326005004 | X37: 구 분 | Y37: 2017 | Z37: 2018 | AG37: (단위: 천원)
N38: 유동성장기차입금 | O38: 18,36,39 | P38: 24633464210 | Q38: 19030499646 | Y38: 유동 | Z38: 유동 | AG38: 구 분 | AH38: 2017 | AI38: 2018
N39: 당기법인세부채 | O39: 34 | P39: 6247408549 | Q39: 15371263894 | X39: 국공채 | Y39: 1328145 | Z39: 1366675 | AG39: 당기손익-공정가치측정항목 | AH39: - | AI39: 9355383
N40: 기타유동부채 | O40: 19,22 | P40: 469806306 | Q40: 446678523 | Y40: 비유동 | Z40: 비유동 | AG40: 비상장주식 등 (주1) | AH40: - | AI40: -
N41: II. 비유동부채 | P41: 185338975083 | Q41: 132723897337 | Y41: 5871680 | Z41: 6213655 | AG41: 합 계 | AH41: 0 | AI41: 9355383
...

Sheet WIK그린
B2: Net | D2: Enterprise | E2: Fiscal | N2: Source : Dart
B3: Debt | C3: NOA | D3: Vaule | E3: Year | F3: BV | G3: Salse | H3: EBITDA | I3: EBIT | J3: NI | N3: 재무상태표 | S3: (3) 당기말 및 전기말 현재 금융자산과 금융부채의 범주별 장부금액은 다음과 같습니다.
B4: =C14 -> -2654.192 | C4: =C17 -> 58.747546 | E4: FY2017 | F4: =P33/10^6 -> 36694.33 | G4: =C30 -> 12535.804 | H4: =C34 -> 5445.8721 | I4: =C33 -> 3709.3191 | J4: =P52/10^6 -> 3821.1703 | S4: (단위: 천원)
B5: =D14 -> -1909.4167 | C5: =D17 -> 37933.968 | E5: FY2018 | F5: =Q33/10^6 -> 36191.307 | G5: =D30 -> 12556.757 | H5: =D34 -> 5887.3167 | I5: =D33 -> 4393.2167 | J5: =Q52/10^6 -> 4490.7528 | N5: 더블유아이케이그린 주식회사 | O5: (단위: 원) | S5: 구 분 | T5: 당기말 | V5: 전기말
N6: 과 목 | O6: 주석 | P6: 2017 | Q6: 2018 | T6: 상각후원가 | U6: 상각후원가 | V6: 대여금및수취채권 | W6: 상각후원
N7: 자 산 | T7: 측정 금융자산 | U7: 측정 금융부채 | W7: 측정 금융부채
N8: I. 유 동 자 산 | P8: 3976612716 | Q8: 2822801833 | S8: (금융자산)
C9: 2017년 | D9: 2018년 | N9: 현금및현금성자산 | O9: 26 | P9: 1654192012 | Q9: 1909416695 | S9: 현금및현금성자산 | T9: 1909417 | U9: - | V9: 1654192 | W9: -
B10: 백만원 | C10: 12월31일 | D10: 12월31일 | N10: 단기금융상품 | O10: 26 | P10: 1000000000 | Q10: 0 | S10: 매출채권 | T10: 852526 | U10: - | V10: 1035029 | W10: -
B11: 차입금 | C11: 0 | D11: 0 | N11: 매출채권 | O11: 5,26 | P11: 1035029359 | Q11: 852525828 | S11: 단기금융상품 | T11: - | U11: - | V11: 1000000 | W11: -
B12: 현금및현금성자산 | C12: =P9/10^6 -> 1654.192 | D12: =Q9/10^6 -> 1909.4167 | N12: 기타유동금융자산 | O12: 6, 26 | P12: 35628823 | Q12: 550000 | S12: 기타유동금융자산 | T12: 550 | U12: - | V12: 35629 | W12: -
B13: 단기금융상품 | C13: =P10/10^6 -> 1000 | D13: =Q10/10^6 -> 0 | N13: 기타유동자산 | O13: 11 | P13: 67939022 | Q13: 58618360 | S13: 기타비유동금융자산 | T13: 58548 | U13: - | V13: 58748 | W13: -
B14: Net Debt | C14: =-SUM(C12:C13)+C11 -> -2654.192 | D14: =-SUM(D12:D13)+D11 -> -1909.4167 | N14: 당기법인세자산 | P14: 183823500 | Q14: 1690950 | S14: 합계 | T14: 2821041 | U14: - | V14: 3783598 | W14: -
N15: II. 비 유 동 자 산 | P15: 33957354995 | Q15: 34345704163 | S15: (금융부채)
N16: 유형자산 | O16: 7 | P16: 22716548172 | Q16: 23005878522 | S16: 매입채무및기타채무 | T16: - | U16: 630186 | V16: - | W16: 787280
B17: NOA | C17: =SUM(C18:C22) -> 58.747546 | D17: =SUM(D18:D22) -> 37933.968 | N17: 무형자산 | O17: 8,9 | P17: 11022480969 | Q17: 11022480969
B18: 장기금융상품 | C18: =P18/10^6 -> 58.747546 | D18: =P20/10^6 -> 37933.968 | N18: 기타비유동금융자산 | O18: 6, 26 | P18: 58747546 | Q18: 58547977
B19: 투자부동산 | C19: 0 | D19: 0 | N19: 이연법인세자산 | O19: 20 | P19: 159578308 | Q19: 258796695
B20: 관계기업투자 | C20: 0 | D20: 0 | N20: 자 산 총 계 | P20: 37933967711 | Q20: 37168505996
B21: 매도가능증권 | C21: 0 | D21: =P21/10^6 -> 0 | N21: 부 채 | S21: (1) 당기 및 전기의 영업활동 현금흐름 중 조정 및 순운전자본의 변동은 다음과 같습니다
B22: 장단기대여금 | C22: 0 | D22: =SUM(W25,X29)/10^3 -> 0 | N22: I. 유 동 부 채 | P22: 917647084 | Q22: 966377871 | S22: (단위: 천원)
N23: 매입채무및기타채무 | O23: 10, 27 | P23: 787279948 | Q23: 630186091 | S23: 구 분 | T23: 금 액
N24: 기타유동부채 | O24: 11 | P24: 130367136 | Q24: 336191780 | T24: 2017 | U24: 2018
N25: II. 비 유 동 부 채 | P25: 321990162 | Q25: 10821405 | S25: 조정: | T25: 1752290 | U25: 1670321
N26: 기타비유동부채 | O26: 11 | P26: 299893266 | Q26: - | S26: 퇴직급여 | T26: 80937 | U26: 68759
N27: 순확정급여부채 | O27: 12 | P27: 22096896 | Q27: 10821405 | S27: 대손상각비환입 | T27: - | U27: -7061
C28: 2017년 | D28: 2018년 | N28: 부 채 총 계 | P28: 1239637246 | Q28: 977199276 | S28: 감가상각비 | T28: 1735959 | U28: 1494100
B29: 백만원 | C29: 12개월 | D29: 12개월 | N29: 자 본 | S29: 무형자산상각비 | T29: 594 | U29: -
B30: 매출액 | C30: =P42/10^6 -> 12535.804 | D30: =Q42/10^6 -> 12556.757 | N30: I. 자본금 | O30: 13 | P30: 632000000 | Q30: 632000000 | S30: 유형자산처분손실 | T30: 1922 | U30: -
B31: 매출총이익 | N31: II. 기타불입자본 | O31: 14 | P31: 28108000000 | Q31: 28108000000 | S31: 기타충당부채전입액 | T31: - | U31: 209357
B32: 판관비 | N32: III. 이익잉여금 | O32: 15 | P32: 7954330465 | Q32: 7451306720 | S32: 이자수익 | T32: -17433 | U32: -10981
B33: 영업이익 | C33: =P46/10^6 -> 3709.3191 | D33: =Q46/10^6 -> 4393.2167 | N33: 자 본 총 계 | P33: 36694330465 | Q33: 36191306720 | S33: 유형자산처분이익 | T33: -9931 | U33: -
B34: EBITDA | C34: =C33+C36 -> 5445.8721 | D34: =D33+D36 -> 5887.3167 | N34: 부 채 및 자 본 총 계 | P34: 37933967711 | Q34: 37168505996 | S34: 법인세비용(수익) | T34: -39758 | U34: -83853
S35: 순운전자본의 변동: | T35: 424081 | U35: -376233
B36: D&A | C36: =SUM(T28:T29)/10^3 -> 1736.553 | D36: =SUM(U28:U29)/10^3 -> 1494.1 | N36: 주석 참조 | S36: 매출채권의 감소 | T36: 505768 | U36: 189564
S37: 선급비용의 감소 | T37: 5930 | U37: 2083
N38: 포괄손익계산서 | S38: 선급금의 감소(증가) | T38: -10566 | U38: 7237
S39: 미수금의 감소(증가) | T39: -35629 | U39: 35079
N40: 더블유아이케이그린 주식회사 | O40: (단위: 원) | S40: 보증금의 감소 | T40: - | U40: 200
N41: 과 목 | O41: 주석 | P41: 2017 | Q41: 2018 | S41: 외상매입금의 증가(감소) | T41: 92164 | U41: -196564
...

Sheet 인선이엔티
B2: BS | C2: 2018.12.31 | G2: PL | H2: 2018
B3: Cash | C3: =C4+C5 -> 26968.662 | H3: 12mths
B4: 현금및현금성자산 | C4: =C41/10^6 -> 24061.062 | G4: Revenue | H4: =I26/10^6 -> 175954.97
B5: 단기금융상품 | C5: =N27/10^3 -> 2907.6 | G5: EBIT | H5: =I30/10^6 -> 23853.49
B6: Debt | C6: =SUM(C7:C8) -> 72274.99 | G6: Dep | H6: =SUM(I65:I66)/10^3 -> 6459.635
B7: 단기차입금 | C7: =SUM(C61:C62)/10^6 -> 72274.99 | G7: EBITDA | H7: =(H5+H6) -> 30313.125
B8: 장기차입금 | C8: 0 | G8: NI(Loss) | H8: =I36/10^6 -> 19964.863
B9: 사채 | C9: =C63/10^6 -> 18328.878
B10: NOA | C10: =SUM(C11:C15) -> 2785.2241
B11: 장기금융상품 | C11: =O28/10^3 -> 662.857
B12: 매도가능금융자산 | C12: =O29/10^3 -> 1421.074
B13: 투자부동산 | C13: 0
B14: 관계기업투자 | C14: =C31/10^6 -> 217.32705
B15: 장단기대여금 | C15: =SUM(N30:O31)/10^3 -> 483.966
B16: BV | C16: =C50/10^6 -> 186940.06
B18: Source : Dart
B20: 연결 재무상태표 | G20: 연결 포괄손익계산서
B21: 제 22 기 2018.12.31 현재 | G21: 제 22 기 2018.01.01 부터 2018.12.31 까지
B22: 제 21 기 2017.12.31 현재 | G22: 제 21 기 2017.01.01 부터 2017.12.31 까지
B23: 제 20 기 2016.12.31 현재 | G23: 제 20 기 2016.01.01 부터 2016.12.31 까지
B24: (단위 : 원) | G24: (단위 : 원)
C25: 제 22 기 | D25: 제 21 기 | E25: 제 20 기 | I25: 제 22 기 | J25: 제 21 기 | K25: 제 20 기 | M25: 구 분 | N25: 당 기 말 | P25: 전 기 말
B26: 자산 | G26: 매출액 | I26: 175954965244 | J26: 160280182183 | K26: 135518950239 | N26: 유 동 | O26: 비 유 동 | P26: 유 동 | Q26: 비 유 동
B27: 비유동자산 | C27: 246540218177 | D27: 244197069564 | E27: 245154928672 | G27: 매출원가 | I27: 135494696794 | J27: 121392406280 | K27: 101462555546 | M27: 단기금융상품 (*1) | N27: 2907600 | O27: - | P27: 2607600 | Q27: -
B28: 유형자산 | C28: 229775553893 | D28: 220172721125 | E28: 208912572083 | G28: 매출총이익 | I28: 40460268450 | J28: 38887775903 | K28: 34056394693 | M28: 장기금융상품 (*2) | N28: - | O28: 662857 | P28: - | Q28: 7920317
B29: 영업권 | C29: 2019841407 | D29: 2019841407 | E29: 2019841407 | G29: 판매비와관리비 | I29: 16606777982 | J29: 16973112972 | K29: 15992451697 | M29: 매도가능금융자산 | N29: - | O29: 1421074 | P29: - | Q29: 507473
B30: 무형자산 | C30: 115612498 | D30: 423315836 | E30: 713753670 | G30: 영업이익(손실) | I30: 23853490468 | J30: 21914662931 | K30: 18063942996 | M30: 대여금 | N30: 1167863 | O30: 471103 | P30: 1824863 | Q30: 437956
B31: 관계기업투자 | C31: 217327052 | D31: 556166223 | E31: 6526768408 | G31: 기타이익 | I31: 341074920 | J31: 1255730117 | K31: 352110868 | M31: (대손충당금) | N31: -1115000 | O31: -40000 | P31: -1185000 | Q31: -180000
B32: 장기매출채권 및 기타채권 | C32: 10195896412 | D32: 10626643520 | E32: 22199645869 | G32: 기타비용 | I32: 1567814262 | J32: 9802594236 | K32: 6191340311 | M32: 합 계 | N32: 2960463 | O32: 2515034 | P32: 3247463 | Q32: 8685746
B33: 기타비유동금융자산 | C33: 2515034246 | D33: 8685745901 | E33: 2453960193 | G33: 금융수익 | I33: 1598390513 | J33: 141953494 | K33: 1816252101
B34: 이연법인세자산 | C34: 1700952669 | D34: 1712635552 | E34: 2328387042 | G34: 금융원가 | I34: 3921438989 | J34: 5193370975 | K34: 7135913606
B35: 유동자산 | C35: 69081354677 | D35: 54148067907 | E35: 55892016899 | G35: 투자손익 | I35: -338839171 | J35: -5615695985 | K35: 578306614
B36: 재고자산 | C36: 11722277279 | D36: 13231722336 | E36: 15958428488 | G36: 법인세비용차감전순이익(손실) | I36: 19964863479 | J36: 2700685346 | K36: 7483358662
B37: 매출채권 및 기타유동채권 | C37: 27274253842 | D37: 27724131942 | E37: 28330035580 | G37: 법인세비용 | I37: 4489603960 | J37: -450506666 | K37: 6122292143
B38: 기타유동금융자산 | C38: 2960463410 | D38: 3247463410 | E38: 4219216410 | G38: 계속영업이익(손실) | I38: 15475259519 | J38: 3151192012 | K38: 1361066519
B39: 당기법인세자산 | C39: 64515 | D39: 318838324 | E39: 347870 | G39: 중단영업이익(손실) | K39: -888599696
B40: 기타유동자산 | C40: 3063233781 | D40: 3966785287 | E40: 3502342995 | G40: 당기순이익(손실) | I40: 15475259519 | J40: 3151192012 | K40: 472466823
B41: 현금및현금성자산 | C41: 24061061850 | D41: 5659126608 | E41: 3881645556 | G41: 기타포괄손익 | I41: -832658382 | J41: 157599567 | K41: 722521040
B42: 자산총계 | C42: 315621572854 | D42: 298345137471 | E42: 301046945571 | G42: 당기손익으로 재분류될 수 있는 항목(세후기타포괄손익)
B43: 자본 | G43: 해외사업장환산외환차이(세후기타포괄손익) | I43: -649411462 | J43: 292174939 | K43: 692479246
...

Sheet 창원에너텍
B2: Net | D2: Enterprise | E2: Fiscal | N2: Source : Dart
B3: Debt | C3: NOA | D3: Vaule | E3: Year | F3: BV | G3: Salse | H3: EBITDA | I3: EBIT | J3: NI
B4: =C14 -> 40797.741 | C4: =C17 -> 411.16225 | E4: FY2017 | F4: =O66/10^6 -> 10223.491 | G4: =C30 -> 11812.948 | H4: =C34 -> 4549.2593 | I4: =C33 -> 941.82406 | J4: =O120/10^6 -> -17.681055 | N4: 재 무 상 태 표 | R4: 현 금 흐 름 표
B5: =D14 -> 35786.697 | C5: =D17 -> 508.74475 | E5: FY2018 | F5: =P66/10^6 -> 10987.624 | G5: =D30 -> 14685.915 | H5: =D34 -> 6104.4256 | I5: =D33 -> 2059.2282 | J5: =P120/10^6 -> 767.8966 | N5: 주식회사 창원에너텍 | P5: (단위 : 원) | R5: 주식회사 창원에너텍 | T5: (단위 : 원)
N6: 과 목 | O6: 제 4(전) 기 | P6: 제 5(당) 기 | R6: 과 목 | S6: 제 4(전) 기 | T6: 제 5(당) 기
N7: 자산 | R7: Ⅰ.영업활동으로 인한 현금흐름 | S7: 3769956298 | T7: 5170081145 | V7: 계정과목 | W7: 예금종류 | X7: 예입처 | Y7: 금액 | AA7: 사용제한내용
N8: Ⅰ.유동자산 | O8: 5280052361 | P8: 8050684741 | R8: 1.당기순이익(손실) | S8: -17681055 | T8: 767896604 | Y8: 당기 | Z8: 전기
C9: 2017년 | D9: 2018년 | N9: (1)당좌자산 | O9: 5280052361 | P9: 8050684741 | R9: 2.현금의 유출이 없는 비용등의 가산 | S9: 4033685146 | T9: 4386718315 | V9: 현금및현금성자산 | W9: 보통예금 | X9: KEB하나은행 | Y9: 5047297 | Z9: 2339630 | AA9: 질권설정
B10: 백만원 | C10: 12월31일 | D10: 12월31일 | N10: 1.현금및현금성자산(주석3,7) | O10: 3202259192 | P10: 6213303093 | R10: (1)퇴직급여 | S10: 189345110 | T10: 313605630
B11: 차입금 | C11: =(O49+O51)/10^6 -> 44000 | D11: =(P49+P51)/10^6 -> 42000 | N11: 2.매출채권 | O11: 1869941391 | P11: 1495077325 | R11: (2)감가상각비 | S11: 3607408472 | T11: 4044876289
B12: 현금및현금성자산 | C12: =O10/10^6 -> 3202.2592 | D12: =P10/10^6 -> 6213.3031 | N12: 대손충당금 | O12: -64317561 | P12: -17277505 | R12: (3)무형자산상각비 | S12: 26766 | T12: 321200
B13: 단기금융상품 | C13: 0 | D13: 0 | N13: 3.미수금 | O13: 177488854 | P13: 286330633 | R13: (4)유형자산처분손실 | S13: 258760360 | T13: -
B14: Net Debt | C14: =-SUM(C12:C13)+C11+C15 -> 40797.741 | D14: =-SUM(D12:D13)+D11+D15 -> 35786.697 | N14: 4.선급금 | O14: 18395000 | P14: - | R14: (5)대손상각비 | S14: -21855562 | T14: 1726230
N15: 5.선급비용 | O15: 75852855 | P15: 72430565 | R15: (6)이자비용 | S15: - | T15: 26188966
N16: 6.당기법인세자산 | O16: 432630 | P16: 820630 | R16: 3.현금의 유입이 없는 수익등의 차감 | S16: -4148095 | T16: -3272596
B17: NOA | C17: =SUM(C18:C22) -> 411.16225 | D17: =SUM(D18:D22) -> 508.74475 | N17: (2)재고자산 | O17: - | P17: - | R17: (1)유형자산처분이익 | S17: -4148095 | T17: -
B18: 장기금융상품 | C18: =O20/10^6 -> 379.3982 | D18: =P20/10^6 -> 508.74475 | N18: Ⅱ.비유동자산 | O18: 52527311246 | P18: 52377292084 | R18: (2)매도가능증권처분이익 | S18: - | T18: 3272596
B19: 투자부동산 | C19: 0 | D19: 0 | N19: (1)투자자산 | O19: 411162251 | P19: 508744748 | R19: 4.영업활동으로 인한 자산부채의 변동 | S19: -241899698 | T19: 18738822
B20: 관계기업투자 | C20: 0 | D20: 0 | N20: 1.장기금융상품 | O20: 379398200 | P20: 508744748 | R20: (1)매출채권의 감소(증가) | S20: -676875045 | T20: 326097780
B21: 매도가능증권 | C21: =O21/10^6 -> 31.764051 | D21: =P21/10^6 -> 0 | N21: 2.매도가능증권(주석4) | O21: 31764051 | P21: 0 | R21: (2)미수금의 감소(증가) | S21: -155847745 | T21: -108841779
B22: 장단기대여금 | C22: 0 | D22: 0 | N22: (2)유형자산(주석5) | O22: 52055583779 | P22: 51822803320 | R22: (3)선급금의 감소(증가) | S22: 73425000 | T22: 18395000
N23: 1.토지 | O23: 6910803678 | P23: 6910803678 | R23: (4)선급비용의 감소(증가) | S23: -40678583 | T23: 3422290
N24: 2.건물 | O24: 6006958551 | P24: 6475297230 | R24: (5)부가세대급금의 감소(증가) | S24: 233061226 | T24: -
N25: 감가상각누계액 | O25: -313909527 | P25: -616208863 | R25: (6)당기법인세자산의 감소(증가) | S25: 301620 | T25: -388000
N26: 3.구축물 | O26: 15195635032 | P26: 15239744621 | R26: (7)매입채무의 증가(감소) | S26: 95115763 | T26: 70679096
